{"event":"subscribe","arg":{"channel":"books","instId":"BTC-USDT"},"connId":"28dcd5bb"}
{"arg":{"channel":"books","instId":"BTC-USDT"},"action":"snapshot","data":[{"asks":[["104308.1","0.61866799","0","14"],["104310","0.00002","0","1"],["104310.7","0.11206046","0","1"],["104310.8","0.29193486","0","1"],["104312","0.0816","0","1"],["104313.8","0.00001","0","1"],["104314","0.08665638","0","2"],["104314.6","0.03734377","0","1"],["104314.9","0.00182925","0","1"],["104315","0.36908178","0","1"],["104315.1","0.25635276","0","1"],["104315.2","0.19242972","0","1"],["104315.5","0.29193486","0","1"],["104315.9","0.00045","0","1"],["104316","0.0816","0","1"],["104316.2","0.098245","0","1"],["104316.4","0.0893782","0","1"],["104317","0.00479229","0","1"],["104317.1","0.09851188","0","1"],["104317.8","0.00001","0","1"],["104317.9","0.30020792","0","1"],["104318.1","0.0903626","0","1"],["104318.6","0.16934573","0","3"],["104319","0.000015","0","1"],["104320","0.00030006","0","2"],["104320.1","0.05738293","0","2"],["104320.4","0.02915595","0","1"],["104320.6","0.005","0","1"],["104321.1","0.00093","0","1"],["104321.6","0.16733727","0","2"],["104321.7","0.00001","0","1"],["104321.9","0.15159156","0","1"],["104322","0.0816","0","1"],["104322.1","0.15513565","0","1"],["104322.2","0.02915544","0","1"],["104322.8","0.03834936","0","1"],["104323","0.57116459","0","3"],["104323.7","0.02650099","0","1"],["104323.9","0.00479349","0","1"],["104324","0.1780651","0","1"],["104324.8","0.69125292","0","2"],["104325.1","0.036","0","1"],["104325.3","0.24329903","0","1"],["104325.7","0.00001","0","1"],["104326.1","0.05985381","0","1"],["104326.2","0.25665877","0","3"],["104326.4","0.00093","0","1"],["104326.5","0.01","0","1"],["104326.6","0.04","0","1"],["104326.7","0.00191706","0","1"],["104327","0.00479219","0","1"],["104327.1","0.26634068","0","1"],["104327.4","0.25605028","0","1"],["104328.1","0.29193486","0","1"],["104328.9","0.45978525","0","1"],["104329.4","0.00479349","0","1"],["104329.5","0.000015","0","1"],["104329.7","0.13899001","0","2"],["104329.8","0.77866876","0","1"],["104330","0.08190006","0","3"],["104330.1","0.60308178","0","2"],["104330.7","0.03952046","0","1"],["104331.1","0.25725861","0","2"],["104331.6","0.00191","0","1"],["104331.9","0.1780651","0","1"],["104332.2","0.0001303","0","1"],["104332.4","0.002","0","1"],["104332.9","0.00005","0","1"],["104333.1","0.0705","0","3"],["104333.3","0.00153697","0","1"],["104333.6","0.36853767","0","2"],["104334.1","0.005","0","1"],["104334.2","0.1780651","0","1"],["104335.8","0.54594","0","1"],["104336.6","0.036","0","1"],["104336.8","0.00191","0","1"],["104337.2","0.036","0","1"],["104337.6","0.00001","0","1"],["104337.9","0.19242972","0","1"],["104338","0.1780651","0","1"],["104338.2","0.1780651","0","1"],["104339","0.45011924","0","3"],["104339.5","0.00287","0","1"],["104340","0.00323344","0","5"],["104340.5","0.0022","0","1"],["104340.6","0.03","0","1"],["104340.7","0.063","0","2"],["104340.9","0.00958588","0","1"],["104341.5","0.00001","0","1"],["104343.1","0.36908178","0","1"],["104343.2","0.77866876","0","1"],["104343.7","0.09587","0","1"],["104343.9","0.05006411","0","1"],["104344.4","0.02396331","0","1"],["104344.9","0.002","0","1"],["104345.4","1.55037238","0","3"],["104345.5","2.41394","0","2"],["104346","0.00958201","0","1"],["104346.8","0.00014304","0","1"],["104346.9","0.1780651","0","1"],["104347.1","0.1780651","0","1"],["104347.7","1.37854809","0","1"],["104348","1","0","1"],["104348.5","0.26084374","0","2"],["104348.6","0.19242972","0","1"],["104349.1","0.234","0","1"],["104349.5","0.00001","0","1"],["104350","0.00317006","0","3"],["104350.5","0.00001501","0","1"],["104351.9","0.04729397","0","1"],["104352.8","0.07298372","0","1"],["104353.4","0.00001","0","1"],["104353.8","0.77866876","0","1"],["104354.5","0.61817704","0","1"],["104354.6","0.26864","0","1"],["104355.8","2.4257","0","1"],["104356.1","0.36908178","0","1"],["104356.8","0.02875918","0","1"],["104356.9","0.45193678","0","1"],["104357.4","0.00001","0","1"],["104357.5","0.0022","0","1"],["104357.8","0.555397","0","1"],["104359.4","0.19242972","0","1"],["104360","0.00221843","0","3"],["104360.2","0.00047934","0","1"],["104360.4","0.00287","0","1"],["104361","0.00001501","0","1"],["104361.2","0.02265242","0","1"],["104361.3","0.00056666","0","1"],["104361.4","0.00001","0","1"],["104361.8","0.234","0","1"],["104362","0.33","0","6"],["104362.8","0.1","0","1"],["104363","0.16499999","0","3"],["104364","0.02876094","0","1"],["104365.1","0.09582","0","1"],["104365.3","0.00001","0","1"],["104365.9","0.1780651","0","1"],["104366.2","0.11498","0","1"],["104367.1","0.00004974","0","1"],["104367.5","0.00017476","0","1"],["104367.8","0.77866876","0","1"],["104367.9","0.36908178","0","1"],["104368.2","0.29193486","0","1"],["104368.8","0.14372","0","1"],["104369.1","0.00958328","0","2"],["104369.3","0.00001","0","1"],["104369.8","0.42833407","0","2"],["104369.9","0.19242972","0","1"],["104370","0.00028006","0","1"],["104370.5","0.0008017","0","1"],["104370.7","0.02230591","0","1"],["104371.5","0.000015","0","1"],["104372.1","0.12455603","0","2"],["104372.3","0.000015","0","1"],["104372.6","0.234","0","1"],["104373.3","0.00001","0","1"],["104373.6","0.06711","0","1"],["104374.3","0.01801577","0","1"],["104376","0.49439815","0","1"],["104377.2","0.00001","0","1"],["104377.8","0.0004975","0","1"],["104378.7","0.77866876","0","1"],["104379","2.72616239","0","2"],["104379.2","0.36908178","0","1"],["104380","0.00221843","0","3"],["104380.7","0.19242972","0","1"],["104381.2","0.00001","0","1"],["104381.5","0.00080396","0","1"],["104381.6","0.01917396","0","1"],["104382","0.00001501","0","1"],["104383.1","0.00845802","0","1"],["104383.7","0.01438047","0","1"],["104384.8","0.00958698","0","1"],["104385.2","0.00001","0","1"],["104386.1","0.234","0","1"],["104387.2","0.02214","0","1"],["104389.1","0.00001","0","1"],["104389.5","6.03744167","0","1"],["104390","0.00987704","0","3"],["104390.2","0.77866876","0","1"],["104391.1","0.10071838","0","1"],["104391.2","0.5615115","0","2"],["104392.3","0.01054335","0","1"],["104392.5","0.000015","0","1"],["104393.1","0.00001","0","1"],["104395","0.01059514","0","1"],["104395.2","0.01059531","0","1"],["104395.9","0.06991","0","1"],["104396","0.26274137","0","1"],["104396.4","0.83283","0","1"],["104397.1","0.00001","0","1"],["104398","1","0","1"],["104398.2","0.09739466","0","3"],["104399.5","0.01059541","0","1"],["104399.7","0.06711","0","1"],["104399.9","0.01116796","0","2"],["104400","0.00225861","0","4"],["104401","0.00001","0","1"],["104401.4","0.01099524","0","1"],["104401.5","0.01059541","0","1"],["104401.6","0.04217248","0","4"],["104401.9","0.77866876","0","1"],["104402.1","0.27234557","0","2"],["104402.6","0.01059541","0","1"],["104403","0.00001501","0","1"],["104403.8","0.01099524","0","1"],["104404.1","0.5615115","0","2"],["104404.8","0.01059541","0","1"],["104405","0.00001","0","1"],["104405.6","0.01054345","0","1"],["104405.7","0.01099524","0","1"],["104406.9","0.04789","0","1"],["104407.1","0.01917282","0","1"],["104407.4","0.02153869","0","2"],["104407.5","0.03178586","0","3"],["104407.9","0.06806514","0","2"],["104408.3","0.0022","0","1"],["104409","0.00001","0","1"],["104409.8","0.01056","0","1"],["104410","0.00028006","0","1"],["104410.7","0.07183","0","1"],["104410.8","0.01054345","0","1"],["104410.9","0.01059541","0","1"],["104411","0.01054345","0","1"],["104411.6","0.01054345","0","1"],["104411.7","0.01099524","0","1"],["104412.5","0.02746942","0","1"],["104412.9","0.00001","0","1"],["104413","0.832656","0","1"],["104413.5","0.000015","0","1"],["104414","0.01054345","0","1"],["104414.1","0.01054345","0","1"],["104414.2","0.02119082","0","2"],["104414.3","0.02153841","0","2"],["104414.4","0.77866876","0","1"],["104414.5","0.07886","0","1"],["104414.9","0.01054345","0","1"],["104415","0.60308178","0","2"],["104415.4","0.00009191","0","1"],["104415.5","0.29193486","0","1"],["104415.7","0.01054345","0","1"],["104415.8","0.01059541","0","1"],["104415.9","0.03","0","1"],["104416.9","0.00001","0","1"],["104418.1","0.01054345","0","1"],["104419","0.00095767","0","1"],["104419.6","0.0210869","0","2"],["104419.7","0.0210868","0","2"],["104419.8","0.01059514","0","1"],["104419.9","0.01054312","0","1"],["104420","0.00219843","0","2"],["104420.9","0.00001","0","1"],["104422","0.02873814","0","1"],["104422.2","0.01054345","0","1"],["104422.3","0.01054312","0","1"],["104422.4","0.0879652","0","8"],["104422.8","0.00094804","0","1"],["104423","0.01054345","0","1"],["104423.1","0.01054312","0","1"],["104423.6","0.12","0","1"],["104424","0.00001501","0","1"],["104424.6","0.000015","0","1"],["104424.8","0.00001","0","1"],["104424.9","0.01059512","0","1"],["104425","0.01099524","0","1"],["104425.1","0.03","0","1"],["104425.2","0.03","0","1"],["104425.7","0.01054312","0","1"],["104425.8","0.01099565","0","1"],["104425.9","0.0001","0","1"],["104426.8","0.00017476","0","1"],["104426.9","0.01099448","0","1"],["104427.5","0.77866876","0","1"],["104428.1","0.01099565","0","1"],["104428.8","0.00001","0","1"],["104429.2","0.0215376","0","2"],["104429.3","0.09","0","3"],["104430","0.00028006","0","1"],["104431","0.01059561","0","1"],["104431.5","0.02113873","0","2"],["104431.6","0.234","0","1"],["104431.7","0.07298372","0","1"],["104432.6","0.07945934","0","3"],["104432.7","0.00478967","0","1"],["104433.7","0.02113873","0","2"],["104434.5","0.000015","0","1"],["104436.7","0.00001","0","1"],["104436.8","0.0579344","0","1"],["104438.1","1.25507","0","1"],["104438.6","0.01059468","0","1"],["104439.3","0.01099565","0","1"],["104439.4","0.78926437","0","2"],["104439.6","0.07298372","0","1"],["104439.7","0.12","0","1"],["104440","0.01531398","0","5"],["104440.9","0.02199089","0","2"],["104441","0.0025","0","1"],["104441.1","0.12","0","1"],["104442.1","0.230047","0","1"],["104443.2","0.0134716","0","1"],["104444.7","0.00001","0","1"],["104445","0.000015","0","1"],["104446.1","0.234","0","1"],["104447.3","0.00126018","0","1"],["104449.8","0.01059514","0","1"],["104449.9","0.77866876","0","1"],["104450","0.00032024","0","2"],["104450.6","0.00004789","0","1"],["104451.2","0.01059581","0","1"],["104451.3","0.01059561","0","1"],["104453.2","0.01054132","0","1"],["104453.3","0.26274137","0","1"],["104453.9","0.01407439","0","1"],["104454.2","0.06892959","0","2"],["104455.5","0.000015","0","1"],["104456.6","0.00001","0","1"],["104457","0.01099524","0","1"],["104457.1","0.01064132","0","2"],["104457.2","0.234","0","1"],["104457.3","0.08216586","0","1"],["104458.7","0.01099524","0","1"],["104458.8","0.01166","0","1"],["104459.9","0.01099524","0","1"],["104460","0.00219843","0","2"],["104460.8","0.77866876","0","1"],["104461.9","0.04634752","0","1"],["104464","0.01407579","0","1"],["104464.5","0.00001","0","1"],["104465.4","0.01054022","0","1"],["104466","0.00001501","0","1"],["104466.6","0.000173","0","1"],["104468","0.00089902","0","1"],["104468.1","0.234","0","1"],["104469.2","0.26274137","0","1"],["104470","0.00028006","0","1"],["104473","0.01059555","0","1"],["104473.1","0.77866876","0","1"],["104474.4","0.00478967","0","1"],["104475.6","0.03","0","1"],["104476.3","0.06985","0","1"],["104476.4","0.00001","0","1"],["104476.5","0.000015","0","1"],["104476.9","0.000015","0","1"],["104479","0.3518","0","1"],["104479.8","2.88986","0","1"],["104480","0.00220843","0","3"],["104480.1","0.234","0","1"],["104480.2","0.00479317","0","1"],["104482.7","0.160966","0","1"],["104483.4","0.01450356","0","1"],["104483.9","0.01099448","0","1"],["104484.4","0.00001","0","1"],["104485.1","0.77866876","0","1"],["104485.7","2.49448596","0","2"],["104486.1","0.00017476","0","1"],["104486.3","0.02862","0","1"],["104487","0.000015","0","1"],["104488.3","0.00373804","0","2"],["104490","0.00076621","0","2"],["104490.2","0.33503544","0","2"],["104491.9","0.234","0","1"],["104492.6","0.00007302","0","1"],["104495.2","0.07298372","0","1"],["104495.7","0.0008","0","1"],["104496","0.06","0","2"],["104496.3","0.00001","0","1"],["104497.2","0.77866876","0","1"],["104497.5","0.00001501","0","1"],["104500","0.00321287","0","6"],["104500.1","0.03","0","1"],["104500.2","0.06","0","2"],["104501","0.00958634","0","2"],["104501.9","0.00001946","0","1"],["104503.9","0.00041858","0","1"],["104504.2","0.00001","0","1"],["104505","0.07298372","0","1"],["104505.9","0.00239627","0","1"],["104506","0.00006","0","1"],["104507","0.234","0","1"],["104508","0.000015","0","1"],["104508.1","0.00004378","0","1"],["104509.5","0.77866876","0","1"],["104510","0.00028006","0","1"],["104510.5","0.06983","0","1"],["104512.1","0.0079625","0","1"],["104512.2","0.0001","0","1"],["104513.3","0.00007315","0","1"],["104516.1","0.00001","0","1"],["104517.5","0.234","0","1"],["104518.5","0.00001501","0","1"],["104520","0.00330992","0","4"],["104520.2","0.0002898","0","1"],["104520.5","0.00123203","0","1"],["104520.6","0.29193486","0","1"],["104523.3","0.01298","0","1"],["104523.8","2.88132","0","1"],["104524.1","0.00001","0","1"],["104524.5","0.77921549","0","2"],["104528","0.234","0","1"]],"bids":[["104308","1.15174599","0","19"],["104307.9","0.0008431","0","1"],["104307.7","0.03834936","0","1"],["104307.6","0.00021527","0","3"],["104307.4","0.00004553","0","1"],["104307.2","0.00002334","0","1"],["104307.1","0.00009066","0","2"],["104307","0.00012463","0","1"],["104306.7","0.00016009","0","2"],["104306.6","0.0485889","0","3"],["104306.5","0.02760443","0","1"],["104306","0.08161","0","2"],["104305.9","0.00002688","0","2"],["104305.8","0.01","0","2"],["104305.6","0.00917734","0","1"],["104305.3","0.00002638","0","1"],["104305","0.00001","0","1"],["104304.6","0.03292191","0","3"],["104304.3","0.00003764","0","2"],["104304.1","0.000048","0","1"],["104304","0.00027736","0","4"],["104303.5","0.00035761","0","4"],["104303.4","0.00261623","0","1"],["104303.1","0.00006358","0","1"],["104302.9","0.00001032","0","1"],["104302.7","0.00001016","0","1"],["104302.6","0.00005058","0","5"],["104302.3","0.00050557","0","2"],["104302.2","0.00003272","0","1"],["104301.9","0.00120818","0","1"],["104301.8","0.00025607","0","2"],["104301.4","0.00397407","0","3"],["104301.2","0.00032901","0","4"],["104301.1","0.00005572","0","1"],["104300.3","0.03278843","0","1"],["104300.2","0.01008619","0","2"],["104300.1","0.03239275","0","2"],["104300","0.04150745","0","41"],["104299.9","0.00537333","0","4"],["104299.8","0.00108768","0","1"],["104299.3","0.01917172","0","1"],["104299.2","0.00002042","0","2"],["104299.1","0.00010104","0","1"],["104298.9","0.00009981","0","2"],["104298.8","0.00001469","0","1"],["104298.5","0.1286653","0","1"],["104298.4","0.00542256","0","5"],["104298","0.00001","0","1"],["104297.9","0.00026259","0","1"],["104297.7","0.00012217","0","2"],["104297.6","0.18852779","0","3"],["104297.5","0.234","0","1"],["104297.4","0.00001024","0","1"],["104297.3","0.00014981","0","1"],["104296.5","0.00001917","0","1"],["104296.1","0.09704481","0","1"],["104296","0.00003578","0","3"],["104295.8","0.00001193","0","1"],["104295.7","0.00005177","0","1"],["104295.4","0.09803142","0","2"],["104295.1","0.00521119","0","2"],["104295","0.00098","0","1"],["104294.9","0.00011319","0","1"],["104294.7","0.19242972","0","1"],["104294.6","0.05424548","0","5"],["104294.4","0.16282888","0","2"],["104294.2","0.19157237","0","3"],["104294.1","0.14491513","0","4"],["104293.7","0.00001113","0","1"],["104293.6","0.00500158","0","9"],["104293.3","0.01","0","2"],["104293","0.17820185","0","3"],["104292.8","0.00001177","0","1"],["104292.6","0.14962991","0","1"],["104292.5","0.00002543","0","2"],["104292.3","0.00549174","0","9"],["104292.1","0.00003021","0","2"],["104292","0.00001069","0","1"],["104291.9","0.00008723","0","1"],["104291.7","0.00009425","0","2"],["104291.6","0.00100678","0","2"],["104291","0.56885112","0","2"],["104290.9","0.77868638","0","2"],["104290.7","0.0000442","0","1"],["104290.5","0.00003811","0","1"],["104290.4","0.00046945","0","6"],["104290.3","0.26121934","0","2"],["104290.1","0.01027843","0","2"],["104290","0.00081019","0","4"],["104289.8","0.15683332","0","1"],["104289.7","0.1790451","0","2"],["104289.5","0.06062293","0","2"],["104289.4","0.00139512","0","1"],["104289.3","0.00001978","0","1"],["104288.9","0.00034826","0","1"],["104288.8","0.00022162","0","5"],["104288.7","0.00005551","0","1"],["104288.6","0.00011027","0","2"],["104288.1","0.06001676","0","3"],["104287.6","0.23745407","0","4"],["104287.5","0.00863698","0","3"],["104287.4","0.00033146","0","1"],["104286.9","0.00089399","0","4"],["104286.8","0.07301005","0","2"],["104286.6","0.00002053","0","2"],["104286.5","0.00010371","0","1"],["104286.4","0.1780651","0","1"],["104286.3","0.00001032","0","1"],["104286.2","0.00031695","0","2"],["104286","0.0037542","0","1"],["104285.8","0.00001017","0","1"],["104285.7","0.01187812","0","39"],["104285.6","0.00114331","0","3"],["104285.5","0.34918524","0","2"],["104285.1","0.00003999","0","2"],["104285","0.03925105","0","1"],["104284.5","0.0019204","0","2"],["104284.4","0.29487727","0","2"],["104284.3","0.0000142","0","1"],["104283.9","0.126","0","4"],["104283.8","0.00001527","0","1"],["104283.6","0.25154524","0","1"],["104283.5","0.00001212","0","1"],["104283.4","0.2340125","0","2"],["104283.3","0.00091331","0","1"],["104283.1","0.00002604","0","1"],["104283","0.00023593","0","1"],["104282.9","0.04","0","1"],["104282.8","0.00020234","0","1"],["104282.4","0.19242972","0","1"],["104282.2","0.00006924","0","5"],["104281.8","0.13898001","0","1"],["104281.7","0.0625875","0","1"],["104281.6","0.00384601","0","2"],["104281.4","0.0000125","0","1"],["104281.3","0.00001888","0","1"],["104281.2","0.04001019","0","2"],["104281","0.00002601","0","1"],["104280.8","0.00001015","0","1"],["104280.5","0.04217037","0","3"],["104280.3","0.30126742","0","2"],["104280.2","0.77866876","0","1"],["104280","0.004027","0","14"],["104279.6","0.00026802","0","1"],["104279.5","0.00001392","0","1"],["104279.4","0.00021285","0","4"],["104279.3","0.00191","0","1"],["104279.1","0.00039358","0","2"],["104279","0.00009722","0","1"],["104278.6","0.00010262","0","1"],["104278.4","0.000015","0","1"],["104278.3","0.00079787","0","1"],["104278.2","0.00001","0","1"],["104278","0.00001","0","1"],["104277.8","0.00083674","0","1"],["104277.7","0.00002552","0","1"],["104277.6","0.00017517","0","3"],["104277.4","0.00010004","0","3"],["104277.2","0.00001034","0","1"],["104277.1","0.00001917","0","1"],["104276.9","0.00015431","0","1"],["104276.6","0.00001015","0","1"],["104276.5","0.00001","0","1"],["104276.3","0.00001008","0","1"],["104276.1","0.00001736","0","1"],["104276","0.00005734","0","2"],["104275.9","0.00001015","0","1"],["104275.5","0.17834719","0","2"],["104275.4","0.00018093","0","1"],["104275.2","0.07307919","0","2"],["104275.1","0.0000125","0","1"],["104275","0.00005802","0","2"],["104274.8","0.00005355","0","1"],["104274.6","0.21984764","0","1"],["104274.3","0.00005483","0","3"],["104274.1","0.02889336","0","2"],["104274","0.00001007","0","1"],["104273.7","0.17826212","0","3"],["104273.2","0.071875","0","1"],["104273","0.00036","0","1"],["104272.9","0.23403136","0","2"],["104272.7","0.00025768","0","6"],["104272.3","0.00001222","0","1"],["104272.2","0.00033769","0","1"],["104272","0.00086241","0","4"],["104271.9","0.00004632","0","2"],["104271.8","0.0000102","0","1"],["104271.7","0.19242972","0","1"],["104271.5","0.00030759","0","1"],["104271.1","0.02509029","0","2"],["104270.8","0.00022348","0","1"],["104270.5","0.00012512","0","2"],["104270.3","0.00003386","0","2"],["104270","0.00038892","0","2"],["104269.9","0.36916028","0","3"],["104269.6","0.00001237","0","1"],["104269.3","0.2525147","0","1"],["104269.2","0.17833476","0","6"],["104269","0.00005407","0","1"],["104268.9","0.00001021","0","1"],["104268.8","0.00001159","0","1"],["104268.7","0.098245","0","1"],["104268.4","0.00039895","0","2"],["104268.3","0.00018565","0","4"],["104268.2","0.02875758","0","1"],["104268.1","0.00711203","0","1"],["104268","0.00012514","0","3"],["104267.9","0.1780651","0","1"],["104267.2","0.00001019","0","1"],["104267","0.26275247","0","2"],["104266.9","0.00002057","0","2"],["104266.8","0.00001005","0","1"],["104266.6","0.03545728","0","13"],["104266.3","0.00001","0","1"],["104266.2","0.00032044","0","1"],["104266.1","0.00005665","0","1"],["104265.9","0.00162451","0","1"],["104265.6","0.00001295","0","1"],["104265.5","0.00653561","0","3"],["104265.2","0.00021979","0","2"],["104265","0.00050654","0","1"],["104264.7","0.00289795","0","2"],["104264.6","0.30991941","0","1"],["104264.5","0.77866876","0","1"],["104264.4","0.00013173","0","3"],["104264.3","0.00001003","0","1"],["104264","1.39410574","0","1"],["104263.9","0.00004885","0","1"],["104263.1","0.00001405","0","1"],["104263","0.00001048","0","1"],["104262.7","0.0001396","0","3"],["104262.5","0.00311464","0","1"],["104262.4","0.23402834","0","3"],["104262.3","0.00006","0","1"],["104262.2","0.00025264","0","1"],["104261.4","0.00002208","0","1"],["104261.2","0.00045833","0","3"],["104261","0.00004759","0","3"],["104260.9","0.00001209","0","1"],["104260.8","0.00001587","0","1"],["104260.7","0.00002072","0","1"],["104260.6","0.00006287","0","1"],["104260.4","0.00001164","0","1"],["104260.3","0.00036649","0","1"],["104260","0.00868238","0","6"],["104259.7","0.0000404","0","3"],["104259.5","0.00001006","0","1"],["104259.2","0.00033277","0","5"],["104258.9","0.00004795","0","1"],["104258.8","0.00023865","0","1"],["104258.5","0.00001498","0","1"],["104258.4","0.00001","0","1"],["104258.2","0.08783891","0","1"],["104258.1","0.19242972","0","1"],["104258","0.04884594","0","1"],["104257.7","0.00006669","0","6"],["104257.6","0.000015","0","1"],["104257.2","0.00001023","0","1"],["104257.1","0.00018558","0","3"],["104257","0.04211337","0","3"],["104256.9","0.0002102","0","4"],["104256.7","0.00073041","0","2"],["104256.4","0.00001118","0","1"],["104256.1","0.00479319","0","1"],["104256","0.00001589","0","1"],["104255.9","0.0001191","0","1"],["104255.8","0.00047934","0","1"],["104255.7","0.00067617","0","4"],["104255.5","0.00015758","0","2"],["104255.4","0.00019543","0","2"],["104255.2","0.00002044","0","2"],["104255.1","0.00002471","0","1"],["104255","0.00001116","0","1"],["104254.8","0.00168502","0","2"],["104254.6","0.00349257","0","7"],["104254.5","0.00001","0","1"],["104254.4","0.00008712","0","1"],["104254.2","0.00015963","0","2"],["104254","0.48336314","0","3"],["104253.5","0.5124704","0","1"],["104253.4","0.36908178","0","1"],["104253.3","0.0001","0","1"],["104252.7","0.00019306","0","2"],["104252.5","0.00016788","0","11"],["104252.2","0.00002113","0","1"],["104252","0.0000192","0","1"],["104251.7","0.00001009","0","1"],["104251.4","0.00001785","0","1"],["104251.3","0.26274137","0","1"],["104250.8","0.00007333","0","1"],["104250.7","0.0001085","0","1"],["104250.5","0.00001","0","1"],["104250.4","0.00024111","0","2"],["104250.1","0.77866876","0","1"],["104250","0.22814664","0","58"],["104249.9","0.00010278","0","4"],["104249.8","0.00001162","0","1"],["104249.6","0.0001901","0","2"],["104249.3","0.00003836","0","1"],["104248.9","0.00017476","0","1"],["104248.7","0.00011268","0","3"],["104248.4","0.00006707","0","1"],["104248.3","0.00008351","0","3"],["104248.2","0.00555057","0","4"],["104248","0.0479311","0","1"],["104247.9","0.00001103","0","1"],["104247.8","0.00011504","0","1"],["104247.3","0.01528331","0","4"],["104247.2","0.000015","0","1"],["104246.9","0.00001188","0","1"],["104246.5","0.00044255","0","2"],["104246.4","0.58708","0","1"],["104246.3","0.00001008","0","1"],["104246.2","0.00010986","0","3"],["104246.1","0.00179533","0","4"],["104245.8","0.00001035","0","1"],["104245.5","0.0230165","0","2"],["104245.4","0.00019008","0","4"],["104245.3","0.00030156","0","3"],["104245.2","0.00001066","0","1"],["104244.8","0.61358","0","1"],["104244.2","0.00086432","0","1"],["104244","0.00108617","0","1"],["104243.9","0.00078223","0","2"],["104243.8","0.00014625","0","3"],["104243.7","0.00193776","0","2"],["104243.5","0.00058346","0","1"],["104243.3","0.00001394","0","1"],["104243.2","0.00014339","0","1"],["104243","0.0022","0","1"],["104242.9","0.27779","0","1"],["104242.6","0.00001","0","1"],["104242.5","0.00012939","0","2"],["104242.4","0.00001603","0","1"],["104242.1","0.00022573","0","1"],["104241.6","0.00242017","0","1"],["104241.5","0.0002931","0","3"],["104241.3","0.0004402","0","6"],["104241.2","0.00058606","0","1"],["104241.1","0.00002745","0","1"],["104240.8","0.00001846","0","1"],["104240.6","0.00004021","0","3"],["104240.5","0.00077167","0","1"],["104240.4","0.00005511","0","1"],["104240.3","0.36910049","0","2"],["104240","0.00276525","0","17"],["104239.9","0.00018343","0","4"],["104239.7","0.00003318","0","2"],["104239.6","0.00001039","0","1"],["104239.3","0.00028077","0","1"],["104239.1","0.00007703","0","2"],["104238.6","0.00049446","0","3"],["104238.4","0.00001664","0","1"],["104238","0.0003141","0","2"],["104237.8","0.41470703","0","6"],["104237.6","0.00001032","0","1"],["104237.3","0.00001","0","1"],["104237.2","0.00030715","0","6"],["104237.1","0.00006296","0","2"],["104237","0.00012393","0","2"],["104236.8","0.00004441","0","3"],["104236.6","0.556042","0","1"],["104236.5","0.00001169","0","1"],["104236.4","0.00012145","0","1"],["104236.3","0.00009916","0","2"],["104236","0.00071497","0","2"],["104235.8","0.00002059","0","1"],["104235.7","0.00002333","0","1"],["104235.6","0.26274137","0","1"],["104235.4","0.00005065","0","1"],["104235.1","0.32484","0","1"],["104235","0.00086255","0","2"],["104234.9","0.00024984","0","5"],["104234.8","0.00061782","0","1"],["104234.6","0.00199229","0","3"],["104234.5","0.00003076","0","2"],["104234.4","0.77963354","0","2"],["104234.3","0.00028121","0","5"],["104234","0.00002831","0","2"],["104233.7","0.00003837","0","1"],["104233.3","0.00482005","0","1"],["104233","0.00003083","0","1"],["104232.9","0.00005458","0","1"],["104232.7","2.56557971","0","2"],["104232.5","0.00954475","0","1"],["104232.4","0.00045226","0","2"],["104232","0.01056164","0","2"],["104231.8","0.00364827","0","1"],["104231.7","0.00025117","0","2"],["104231.5","0.00004581","0","2"],["104231.3","0.00027353","0","4"],["104231.1","0.00001089","0","1"],["104230.7","0.01111263","0","9"],["104230.2","0.00005187","0","1"],["104230.1","0.00105325","0","4"],["104230","0.00136575","0","3"],["104229.8","0.00057456","0","4"],["104229.4","0.01054502","0","1"],["104229","0.03834765","0","1"],["104228.8","0.00071241","0","4"]],"ts":"1747170714601","checksum":-148765853,"seqId":54226501207,"prevSeqId":-1}]}
{"arg":{"channel":"books","instId":"BTC-USDT"},"action":"update","data":[{"asks":[["104337","0.002","0","2"],["104338","0.1790651","0","2"],["104339","0.44811924","0","1"],["104340","0.00223344","0","4"],["104360","0.33221843","0","9"],["104361","0.165015","0","4"],["104362","0","0","0"],["104363","0","0","0"],["104389.5","5.99908961","0","1"],["104529.2","0.00001501","0","1"]],"bids":[],"ts":"1747170714701","checksum":-148765853,"seqId":54226501239,"prevSeqId":54226501207}]}
{"arg":{"channel":"books","instId":"BTC-USDT"},"action":"update","data":[{"asks":[["104318.6","0.40334573","0","4"],["104328.8","0.13898082","0","1"],["104329.7","0.00001","0","1"],["104337","0","0","0"],["104338","0.1780651","0","1"],["104339","0.45011924","0","3"],["104340","0.00323344","0","5"],["104360","0.00221843","0","3"],["104361","0.00001501","0","1"],["104362","0.33","0","6"],["104363","0.16499999","0","3"],["104528","0","0","0"],["104529.2","0","0","0"]],"bids":[["104308","0.91774599","0","18"],["104281.8","0","0","0"],["104280.6","0.13898082","0","1"],["104238.1","0.00002968","0","1"],["104228.8","0","0","0"]],"ts":"1747170714801","checksum":-758155818,"seqId":54226501274,"prevSeqId":54226501239}]}
{"arg":{"channel":"books","instId":"BTC-USDT"},"action":"update","data":[{"asks":[["104308.1","0.65417759","0","16"],["104316.1","0.0047923","0","1"],["104317","0","0","0"],["104326","0.00479219","0","1"],["104327","0","0","0"],["104327.3","0.13898237","0","1"],["104328.8","0","0","0"],["104337","0.002","0","2"],["104338","0.1790651","0","2"],["104339","0.44811924","0","1"],["104340","0.00223344","0","4"],["104360","0.26221843","0","7"],["104361","0.130015","0","3"],["104362","0.07","0","2"],["104363","0.035","0","1"],["104524.5","0","0","0"]],"bids":[["104308","0.75854237","0","18"],["104307.7","0","0","0"],["104307.6","0.00011443","0","2"],["104306.6","0.00003361","0","2"],["104306.1","0.04177396","0","1"],["104295.1","0.000419","0","1"],["104294.2","0.19636456","0","4"],["104280.6","0","0","0"],["104275.6","0.13898237","0","1"],["104251.9","0.234","0","1"],["104229","0","0","0"]],"ts":"1747170714901","checksum":975471386,"seqId":54226501375,"prevSeqId":54226501274}]}
{"arg":{"channel":"books","instId":"BTC-USDT"},"action":"update","data":[{"asks":[["104308.1","0.65394631","0","15"],["104315.9","0.00524232","0","2"],["104316.1","0","0","0"],["104320.5","0.01","0","1"],["104323.6","0.00479219","0","1"],["104326","0","0","0"],["104326.5","0","0","0"],["104327.3","0","0","0"],["104328","0.13898114","0","1"],["104330.1","0.61151599","0","3"],["104360","0.33221842","0","9"],["104361","0.165015","0","4"],["104362","0","0","0"],["104363","0","0","0"],["104524.5","0.77921549","0","2"],["104528","0.234","0","1"],["104529.2","0.00001501","0","1"]],"bids":[["104308","0.79689173","0","19"],["104294.7","0","0","0"],["104294.2","0.19157237","0","3"],["104291.7","0.00488644","0","3"],["104280.6","0.13898114","0","1"],["104275.6","0","0","0"],["104229","0.03834765","0","1"]],"ts":"1747170715001","checksum":1284035841,"seqId":54226501425,"prevSeqId":54226501375}]}
{"arg":{"channel":"books","instId":"BTC-USDT"},"action":"update","data":[{"asks":[["104308.1","0.85797333","0","15"],["104315.8","0.00479232","0","1"],["104315.9","0.00045","0","1"],["104321.7","0.00958383","0","2"],["104323","0.56159076","0","2"],["104323.6","0","0","0"],["104324.7","0.00479219","0","1"],["104327","0.13898244","0","1"],["104328","0","0","0"],["104529.2","0","0","0"]],"bids":[["104308","0.81288038","0","20"],["104294.5","0.19242972","0","1"],["104292.7","0.00479219","0","1"],["104291.7","0.00009425","0","2"],["104280.6","0","0","0"],["104275.6","0.13898244","0","1"],["104229.4","0","0","0"],["104229","0","0","0"]],"ts":"1747170715101","checksum":-524333085,"seqId":54226501457,"prevSeqId":54226501425}]}
{"arg":{"channel":"books","instId":"BTC-USDT"},"action":"update","data":[{"asks":[["104308.1","0.61797333","0","14"],["104310.7","0.02448","0","1"],["104310.8","0","0","0"],["104314.6","0","0","0"],["104315.8","0","0","0"],["104317","0.00479229","0","1"],["104318.6","0.16934573","0","3"],["104320.4","0","0","0"],["104323.4","0.02992532","0","1"],["104324.7","0","0","0"],["104326","0.00479219","0","1"],["104327","0","0","0"],["104328.8","0.13898014","0","1"],["104337","0","0","0"],["104338","0.1780651","0","1"],["104339","0.45011924","0","3"],["104340","0.00323344","0","5"],["104360","0.00221843","0","3"],["104361","0.00001501","0","1"],["104362","0.33","0","6"],["104363","0.16499999","0","3"],["104389.5","0","0","0"],["104396.3","5.99908961","0","1"],["104415.4","0","0","0"],["104415.7","0.01063552","0","2"],["104529.2","0.00001501","0","1"],["104529.4","0.00002902","0","1"]],"bids":[["104308","1.04688038","0","21"],["104294.7","0.03708834","0","1"],["104293.7","0.00480332","0","2"],["104292.7","0","0","0"],["104285","0","0","0"],["104284.4","0.26707503","0","1"],["104281.3","0.13899902","0","2"],["104275.6","0","0","0"],["104264.6","0.68734555","0","2"],["104229.4","0.01054502","0","1"],["104229","0.03834765","0","1"]],"ts":"1747170715201","checksum":1663128535,"seqId":54226501558,"prevSeqId":54226501457}]}
{"arg":{"channel":"books","instId":"BTC-USDT"},"action":"update","data":[{"asks":[["104321.8","0.039371","0","1"],["104324.7","0.00479219","0","1"],["104326","0","0","0"],["104336","0.002","0","2"],["104337","0.001","0","1"],["104339","0.44811924","0","1"],["104340","0.00223344","0","4"],["104359","0.16","0","2"],["104360","0.18221842","0","6"],["104361","0.05001501","0","2"],["104362","0.07","0","2"],["104363","0.035","0","1"],["104415.7","0.01054345","0","1"],["104468","0","0","0"],["104528","0","0","0"],["104529.2","0","0","0"],["104529.4","0","0","0"]],"bids":[["104308","0.81288038","0","20"],["104293.9","0.02780224","0","1"],["104293.7","0.00001113","0","1"],["104292.7","0.00479219","0","1"],["104229.4","0","0","0"],["104229","0","0","0"]],"ts":"1747170715301","checksum":-1842731754,"seqId":54226501601,"prevSeqId":54226501558}]}
{"arg":{"channel":"books","instId":"BTC-USDT"},"action":"update","data":[{"asks":[["104318.6","0.40334573","0","4"],["104327.3","0.13898224","0","1"],["104328.8","0","0","0"],["104359","0.33","0","6"],["104360","0.16721842","0","6"],["104361","0.00001501","0","1"],["104362","0","0","0"],["104363","0","0","0"],["104528","0.234","0","1"],["104529.2","0.00001501","0","1"]],"bids":[["104308","0.81133038","0","19"],["104281.3","0.00001888","0","1"],["104275.7","0.13898228","0","1"],["104233","0.00086083","0","2"],["104229.8","0","0","0"]],"ts":"1747170715401","checksum":-71535888,"seqId":54226501627,"prevSeqId":54226501601}]}
{"arg":{"channel":"books","instId":"BTC-USDT"},"action":"update","data":[{"asks":[["104327.3","0","0","0"],["104328.8","0.13898103","0","1"],["104336","0","0","0"],["104337","0.002","0","2"],["104338","0.1790651","0","2"],["104359","0","0","0"],["104360","0.33221842","0","9"],["104361","0.165015","0","4"],["104389.5","5.99908961","0","1"],["104396.3","0","0","0"],["104529.4","0.00002902","0","1"],["104529.5","0.07298372","0","1"]],"bids":[["104280.6","0.13898103","0","1"],["104275.7","0","0","0"]],"ts":"1747170715501","checksum":-71535888,"seqId":54226501650,"prevSeqId":54226501627}]}
{"arg":{"channel":"books","instId":"BTC-USDT"},"action":"update","data":[{"asks":[["104415.4","0.00009135","0","1"],["104529.5","0","0","0"]],"bids":[["104299.3","0","0","0"],["104229.8","0.00057456","0","4"]],"ts":"1747170715601","checksum":-71535888,"seqId":54226501654,"prevSeqId":54226501650}]}
{"arg":{"channel":"books","instId":"BTC-USDT"},"action":"update","data":[{"asks":[["104310.7","0","0","0"],["104318.6","0.16934573","0","3"],["104324.7","0","0","0"],["104326","0.00479219","0","1"],["104328.8","0","0","0"],["104330.6","0.13897771","0","1"],["104359","0.1","0","2"],["104360","0.28221842","0","8"],["104361","0.115015","0","3"]],"bids":[["104308","1.05074504","0","21"],["104293.7","0.00480332","0","2"],["104292.7","0","0","0"],["104283.5","0.13898983","0","2"],["104280.6","0","0","0"],["104229.4","0.01054502","0","1"],["104229","0.03834765","0","1"]],"ts":"1747170715701","checksum":1327499726,"seqId":54226501672,"prevSeqId":54226501654}]}
{"arg":{"channel":"books","instId":"BTC-USDT"},"action":"update","data":[{"asks":[["104308.1","0.49847333","0","13"],["104359","0","0","0"],["104360","0.33221842","0","9"],["104361","0.165015","0","4"],["104415.4","0","0","0"],["104529.5","0.07298372","0","1"],["104530","0.00028006","0","1"]],"bids":[],"ts":"1747170715801","checksum":-49141122,"seqId":54226501698,"prevSeqId":54226501672}]}
{"arg":{"channel":"books","instId":"BTC-USDT"},"action":"update","data":[{"asks":[["104311.9","0.02448","0","1"],["104328.8","0.13898017","0","1"],["104330.6","0","0","0"],["104530","0","0","0"]],"bids":[["104308","1.05210504","0","22"],["104283.5","0.00001212","0","1"],["104281.3","0.13899905","0","2"],["104279.1","0.00038358","0","1"]],"ts":"1747170715901","checksum":-223194283,"seqId":54226501708,"prevSeqId":54226501698}]}
{"arg":{"channel":"books","instId":"BTC-USDT"},"action":"update","data":[{"asks":[["104311.7","0.09648","0","1"],["104311.8","0.24","0","1"],["104311.9","0","0","0"],["104335.5","0.00287533","0","1"],["104529.4","0","0","0"],["104529.5","0","0","0"]],"bids":[],"ts":"1747170716001","checksum":-1574142369,"seqId":54226501714,"prevSeqId":54226501708}]}
{"arg":{"channel":"books","instId":"BTC-USDT"},"action":"update","data":[{"asks":[["104308.1","0.49408423","0","13"],["104317","0","0","0"],["104317.7","0.00479231","0","1"],["104320.5","0","0","0"],["104328.8","0.13898107","0","1"],["104332.2","0","0","0"],["104332.3","0.0001303","0","1"],["104415.4","0.00009294","0","1"]],"bids":[["104294.8","0.29067952","0","1"],["104294.2","0.00001937","0","1"],["104281.3","0.00001888","0","1"],["104280.6","0.1389813","0","1"],["104229.4","0","0","0"],["104229","0","0","0"]],"ts":"1747170716101","checksum":1507180188,"seqId":54226501760,"prevSeqId":54226501714}]}
{"arg":{"channel":"books","instId":"BTC-USDT"},"action":"update","data":[{"asks":[["104320.4","0.00957383","0","1"],["104321.7","0.00001","0","1"],["104324.7","0.00479219","0","1"],["104326","0","0","0"],["104328.8","0.13898097","0","1"],["104450.4","0.161008","0","1"],["104482.7","0","0","0"],["104529.2","0","0","0"]],"bids":[["104293.7","0.00001113","0","1"],["104293.1","0.00479219","0","1"],["104280.6","0.13898097","0","1"],["104229.8","0","0","0"]],"ts":"1747170716201","checksum":1507180188,"seqId":54226501800,"prevSeqId":54226501760}]}
{"arg":{"channel":"books","instId":"BTC-USDT"},"action":"update","data":[{"asks":[["104328.8","0.13898092","0","1"],["104333.3","0","0","0"],["104336","0.002","0","2"],["104337","0.001","0","1"],["104338","0.1780651","0","1"],["104359","0.33","0","6"],["104360","0.16721842","0","6"],["104361","0.00001501","0","1"],["104468","0.00091013","0","1"],["104524.5","0","0","0"],["104528","0","0","0"]],"bids":[["104280.6","0.13898092","0","1"]],"ts":"1747170716301","checksum":1507180188,"seqId":54226501827,"prevSeqId":54226501800}]}
{"arg":{"channel":"books","instId":"BTC-USDT"},"action":"update","data":[{"asks":[["104317","0.00479233","0","1"],["104317.7","0","0","0"],["104318.6","0.40334573","0","4"],["104320.6","0.03846567","0","2"],["104323.4","0","0","0"],["104336","0","0","0"],["104337","0.002","0","2"],["104338","0.1790651","0","2"],["104359","0","0","0"],["104360","0.33221842","0","9"],["104361","0.165015","0","4"],["104524.5","0.77921549","0","2"],["104529.2","0.00001501","0","1"],["104529.4","0.00002902","0","1"]],"bids":[["104308","0.77975568","0","20"],["104306.1","0","0","0"],["104293.1","0","0","0"],["104292.7","0.00479219","0","1"],["104229.8","0.00057456","0","4"]],"ts":"1747170716401","checksum":763342199,"seqId":54226501866,"prevSeqId":54226501827}]}
{"arg":{"channel":"books","instId":"BTC-USDT"},"action":"update","data":[{"asks":[["104318.6","0.16934573","0","3"],["104327.3","0.13898231","0","1"],["104328.8","0","0","0"],["104330.1","0.60308178","0","2"],["104336","0.002","0","2"],["104337","0.001","0","1"],["104338","0.1780651","0","1"],["104359","0.33","0","6"],["104360","0.16721842","0","6"],["104361","0.00001501","0","1"],["104529.2","0","0","0"],["104529.4","0","0","0"]],"bids":[["104308","1.05210504","0","22"],["104306.1","0.04177396","0","1"],["104294.9","0.19254291","0","2"],["104294.5","0","0","0"],["104280.6","0","0","0"],["104280.3","0.44024951","0","3"],["104229.4","0.01054502","0","1"]],"ts":"1747170716501","checksum":1051925259,"seqId":54226501900,"prevSeqId":54226501866}]}
{"arg":{"channel":"books","instId":"BTC-USDT"},"action":"update","data":[{"asks":[["104308.1","0.42220923","0","12"],["104311.7","0","0","0"],["104311.8","0","0","0"],["104312","0","0","0"],["104314","0.00505638","0","1"],["104315","0","0","0"],["104315.1","0","0","0"],["104315.5","0","0","0"],["104316.2","0","0","0"],["104317","0","0","0"],["104317.7","0.00479232","0","1"],["104317.9","0","0","0"],["104320.6","0.005","0","1"],["104324.7","0","0","0"],["104326","0.00479219","0","1"],["104327.3","0","0","0"],["104329.7","0.13898997","0","2"],["104333.2","0.04159803","0","1"],["104336","0","0","0"],["104337","0.002","0","2"],["104338","0.1790651","0","2"],["104347.7","0","0","0"],["104359","0","0","0"],["104360","0.33221842","0","9"],["104361","0.165015","0","4"],["104361.2","0","0","0"],["104379","0.19161","0","1"],["104389.5","0","0","0"],["104528","0.234","0","1"],["104529.2","0.00001501","0","1"],["104529.4","0.00002902","0","1"],["104529.5","0.07298372","0","1"],["104530","0.00028006","0","1"],["104531.4","0.00209352","0","1"],["104532","0.00001","0","1"],["104533.3","0.000173","0","1"],["104533.9","0.03","0","1"],["104534.7","0.00094804","0","1"],["104535.6","0.00002193","0","1"],["104535.8","0.77866876","0","1"],["104536.1","0.0152","0","1"]],"bids":[["104293.7","0.00480332","0","2"],["104292.7","0","0","0"],["104281.8","0.13897997","0","1"],["104280.3","0.30126742","0","2"],["104264.6","0.30991941","0","1"],["104264","0","0","0"],["104232.7","0.0000103","0","1"],["104229","0.03834765","0","1"]],"ts":"1747170716601","checksum":-1744540629,"seqId":54226501964,"prevSeqId":54226501900}]}
{"arg":{"channel":"books","instId":"BTC-USDT"},"action":"update","data":[{"asks":[["104308.1","0.48258523","0","12"],["104314.9","0","0","0"],["104315.2","0","0","0"],["104315.9","0.00227925","0","2"],["104317.3","0.097946","0","1"],["104317.7","0","0","0"],["104318.5","0.25271557","0","1"],["104319.9","0.00479219","0","1"],["104322.2","0","0","0"],["104322.8","0","0","0"],["104326","0","0","0"],["104326.2","0.22842972","0","2"],["104326.7","0.04026642","0","2"],["104328.5","0.00479219","0","1"],["104328.6","0.03346311","0","1"],["104329.7","0.00001","0","1"],["104329.8","0","0","0"],["104331.8","0.13897624","0","1"],["104332.3","0","0","0"],["104337","0","0","0"],["104338","0.1780651","0","1"],["104339","0.45011924","0","3"],["104340","0.00323344","0","5"],["104343.7","0","0","0"],["104345.4","1.45450238","0","2"],["104347.7","1.43364932","0","1"],["104348.5","0.16497374","0","1"],["104350.1","0.0384875","0","1"],["104354.5","0.80932179","0","2"],["104360","0.00221843","0","3"],["104361","0.00001501","0","1"],["104362","0.33","0","6"],["104363","0.16499999","0","3"],["104365.1","0","0","0"],["104366.2","0","0","0"],["104368.8","0","0","0"],["104370.7","0","0","0"],["104372.1","0.02874603","0","1"],["104373.6","0","0","0"],["104379","2.59522893","0","1"],["104397.1","0.0958","0","2"],["104397.6","0.11495","0","1"],["104399.7","0","0","0"],["104406.9","0","0","0"],["104407.9","0.01059514","0","1"],["104410.4","0.19155","0","1"],["104410.7","0","0","0"],["104420","5.90702071","0","3"],["104536.2","0.076","0","5"],["104536.3","0.076","0","5"],["104536.4","0.00002296","0","1"],["104537.6","7.7801487","0","1"],["104538.4","0.07298372","0","1"],["104538.5","0.234","0","1"]],"bids":[["104305.1","0.04802379","0","1"],["104301.5","0.4005071","0","1"],["104301.4","0.78264283","0","4"],["104298.5","0","0","0"],["104296.2","0.00479219","0","1"],["104293.7","0.00001113","0","1"],["104284.5","0.14089664","0","3"],["104283.5","0.3690939","0","2"],["104281.8","0","0","0"],["104280.5","0.00013618","0","2"],["104264.6","0.68755474","0","2"],["104262.9","1.39480304","0","1"],["104260.1","0.47673283","0","1"],["104231.6","2.49342325","0","1"],["104230","0","0","0"],["104229.8","0","0","0"],["104229.4","0","0","0"],["104229","0","0","0"]],"ts":"1747170716701","checksum":745777992,"seqId":54226502117,"prevSeqId":54226501964}]}
{"arg":{"channel":"books","instId":"BTC-USDT"},"action":"update","data":[{"asks":[["104308.1","0.49409023","0","13"],["104315.8","0.00182925","0","1"],["104315.9","0.08129702","0","2"],["104319.9","0","0","0"],["104320.3","0.00479219","0","1"],["104326.3","0.03346385","0","1"],["104326.7","0.00191706","0","1"],["104332.1","0.03834936","0","1"],["104343.9","0","0","0"],["104415.4","0","0","0"],["104468","0","0","0"]],"bids":[["104283.5","0.00001212","0","1"],["104268.1","0","0","0"],["104230","0.00136575","0","3"]],"ts":"1747170716801","checksum":342878806,"seqId":54226502148,"prevSeqId":54226502117}]}
{"arg":{"channel":"books","instId":"BTC-USDT"},"action":"update","data":[{"asks":[["104315.8","0.24182925","0","2"],["104327.9","0.73642171","0","1"],["104328","0.77866876","0","1"],["104328.9","0","0","0"],["104332.3","0.0001303","0","1"],["104343.7","0.09587","0","1"],["104346.9","0.2739351","0","2"],["104537.6","0","0","0"],["104538.4","0","0","0"],["104538.5","0","0","0"]],"bids":[["104308","1.05074504","0","21"],["104266.3","0.00712203","0","2"]],"ts":"1747170716901","checksum":-2112764784,"seqId":54226502176,"prevSeqId":54226502148}]}
{"arg":{"channel":"books","instId":"BTC-USDT"},"action":"update","data":[{"asks":[["104308.1","0.42220923","0","12"],["104315.6","0.00182925","0","1"],["104315.7","0.19242972","0","1"],["104315.8","0.24","0","1"],["104317.3","0","0","0"],["104328.5","0","0","0"],["104329.3","0.00479206","0","1"],["104331.8","0","0","0"],["104335.7","0.13897197","0","1"],["104363.6","0.06711","0","1"],["104369.8","0.57205407","0","3"],["104372.9","0.09581","0","1"],["104389.6","0.06711","0","1"],["104536.1","0","0","0"],["104536.2","0","0","0"],["104536.3","0","0","0"],["104536.4","0","0","0"]],"bids":[["104287.7","0.13897197","0","1"],["104284.5","0.0019204","0","2"],["104230","0","0","0"]],"ts":"1747170717001","checksum":-815951422,"seqId":54226502209,"prevSeqId":54226502176}]}
{"arg":{"channel":"books","instId":"BTC-USDT"},"action":"update","data":[{"asks":[["104309.9","0.071881","0","1"],["104319","0.097961","0","2"],["104319.2","0.00957383","0","1"],["104319.9","0.00479217","0","1"],["104320.3","0","0","0"],["104320.4","0","0","0"],["104326.3","0","0","0"],["104326.8","0.03346369","0","1"],["104330.7","0","0","0"],["104333.5","0.13897428","0","1"],["104335.7","0","0","0"],["104338.7","0.04159587","0","1"],["104396.3","5.90482228","0","1"],["104415.4","0.00009477","0","1"],["104420","0.00219843","0","2"],["104534.7","0","0","0"],["104535.6","0","0","0"],["104535.8","0","0","0"]],"bids":[["104287.7","0","0","0"],["104285.6","0.14011759","0","4"],["104230","0.00136575","0","3"]],"ts":"1747170717101","checksum":492098435,"seqId":54226502231,"prevSeqId":54226502209}]}
{"arg":{"channel":"books","instId":"BTC-USDT"},"action":"update","data":[{"asks":[["104332.4","0","0","0"],["104344.9","0","0","0"],["104411.6","0.08237345","0","2"],["104468","0.00090874","0","1"],["104534.7","0.00094804","0","1"]],"bids":[],"ts":"1747170717201","checksum":492098435,"seqId":54226502235,"prevSeqId":54226502231}]}
{"arg":{"channel":"books","instId":"BTC-USDT"},"action":"update","data":[{"asks":[["104366.2","0.11498","0","1"],["104366.3","0.09582","0","1"],["104379.1","0.19161","0","1"],["104397.1","0.00001","0","1"],["104397.6","0","0","0"],["104410.4","0","0","0"],["104534.7","0","0","0"]],"bids":[["104238.1","0","0","0"],["104229.8","0.00057456","0","4"]],"ts":"1747170717301","checksum":492098435,"seqId":54226502247,"prevSeqId":54226502235}]}
{"arg":{"channel":"books","instId":"BTC-USDT"},"action":"update","data":[{"asks":[["104315.6","0","0","0"],["104315.7","0.00182925","0","1"],["104315.9","0.00045","0","1"],["104318.5","0.28209936","0","1"],["104324.8","0.14798292","0","1"],["104327.9","0.44871112","0","1"],["104328","0","0","0"],["104332.1","0","0","0"],["104332.3","0","0","0"],["104332.8","0.0001303","0","1"],["104339","0.44811924","0","1"],["104340","0.00223344","0","4"],["104341","0.002","0","2"],["104342","0.001","0","1"],["104346.8","0.54341304","0","2"],["104362","0","0","0"],["104363","0.22999999","0","4"],["104364","0.24376093","0","5"],["104365","0.05","0","1"],["104386","0.01107413","0","1"],["104392.9","5.90482228","0","1"],["104396.3","0","0","0"]],"bids":[["104308","1.05212504","0","22"],["104238.1","0.00002968","0","1"],["104229.8","0","0","0"]],"ts":"1747170717401","checksum":-550927665,"seqId":54226502287,"prevSeqId":54226502247}]}
{"arg":{"channel":"books","instId":"BTC-USDT"},"action":"update","data":[{"asks":[["104315.6","0.00182925","0","1"],["104315.7","0.19242972","0","1"],["104327.9","0.62622286","0","2"],["104329.9","0.77866876","0","1"],["104330","0.12024942","0","4"],["104339","0.45011924","0","3"],["104340","0.00323344","0","5"],["104341","0","0","0"],["104342","0","0","0"],["104359","0.26","0","4"],["104360","0.13221842","0","5"],["104363","0.07","0","2"],["104364","0.06376094","0","2"],["104365","0","0","0"],["104392.9","0","0","0"],["104396.3","5.90482228","0","1"]],"bids":[["104238.1","0","0","0"],["104229.8","0.00057456","0","4"]],"ts":"1747170717501","checksum":-1721739819,"seqId":54226502333,"prevSeqId":54226502287}]}
{"arg":{"channel":"books","instId":"BTC-USDT"},"action":"update","data":[{"asks":[["104315.5","0.00182925","0","1"],["104315.6","0.21071094","0","1"],["104336","0.002","0","2"],["104337","0.001","0","1"],["104339","0.44811924","0","1"],["104340","0.00223344","0","4"],["104392.9","5.90482228","0","1"],["104396.3","0","0","0"],["104450.6","0","0","0"],["104533.3","0","0","0"],["104533.9","0","0","0"]],"bids":[["104238.1","0.00002968","0","1"],["104229.8","0","0","0"]],"ts":"1747170717601","checksum":-1901145813,"seqId":54226502347,"prevSeqId":54226502333}]}
{"arg":{"channel":"books","instId":"BTC-USDT"},"action":"update","data":[{"asks":[["104319.9","0","0","0"],["104320.5","0.00479217","0","1"],["104359","0.33","0","6"],["104360","0.16721842","0","6"],["104363","0","0","0"],["104364","0.02876094","0","1"],["104408","0.10536","0","2"]],"bids":[],"ts":"1747170717701","checksum":259456730,"seqId":54226502357,"prevSeqId":54226502347}]}
{"arg":{"channel":"books","instId":"BTC-USDT"},"action":"update","data":[{"asks":[["104325.1","0.06946422","0","2"],["104338.7","0","0","0"],["104533.3","0.000173","0","1"]],"bids":[],"ts":"1747170717801","checksum":259456730,"seqId":54226502363,"prevSeqId":54226502357}]}
{"arg":{"channel":"books","instId":"BTC-USDT"},"action":"update","data":[{"asks":[["104315.4","0.00182925","0","1"],["104315.5","0.24","0","1"],["104320.5","0.00679217","0","2"],["104333","0.002","0","1"],["104532","0","0","0"],["104533.3","0","0","0"]],"bids":[["104305.7","0.002","0","1"],["104293.2","0.002","0","1"],["104230.1","0","0","0"],["104230","0","0","0"]],"ts":"1747170717901","checksum":-545065153,"seqId":54226502373,"prevSeqId":54226502363}]}
{"arg":{"channel":"books","instId":"BTC-USDT"},"action":"update","data":[{"asks":[["104315.9","0.07343372","0","2"],["104318.6","0.17891956","0","4"],["104319.2","0","0","0"],["104320.4","0.00479217","0","1"],["104320.5","0.002","0","1"],["104331.8","0.13897655","0","1"],["104333.5","0","0","0"]],"bids":[["104285.6","0.00114331","0","3"],["104284","0.13897655","0","1"],["104230.2","0","0","0"]],"ts":"1747170718101","checksum":1485022047,"seqId":54226502390,"prevSeqId":54226502373}]}
{"arg":{"channel":"books","instId":"BTC-USDT"},"action":"update","data":[{"asks":[["104326.1","0.06464587","0","2"],["104329.3","0","0","0"],["104331.2","0.13897693","0","1"],["104331.3","0.036","0","1"],["104331.8","0","0","0"],["104335.5","0.06587533","0","3"],["104336.6","0","0","0"],["104340.7","0.033","0","1"],["104532","0.00001","0","1"]],"bids":[["104296.2","0","0","0"],["104294.7","0.0418804","0","2"],["104230.2","0.00005187","0","1"]],"ts":"1747170718201","checksum":1485022047,"seqId":54226502409,"prevSeqId":54226502390}]}
{"arg":{"channel":"books","instId":"BTC-USDT"},"action":"update","data":[{"asks":[["104309.9","0","0","0"],["104315.4","0.37091103","0","2"],["104319","0.000015","0","1"],["104320.4","0","0","0"],["104321","0.00479217","0","1"],["104325.1","0.036","0","1"],["104326.1","0.05985381","0","1"],["104326.3","0.00479206","0","1"],["104326.8","0","0","0"],["104329.7","0.03336382","0","2"],["104331.2","0","0","0"],["104333","0.14097472","0","2"],["104338.9","0.04187607","0","1"],["104340.7","0","0","0"],["104533.3","0.000173","0","1"],["104533.9","0.03","0","1"]],"bids":[["104294.8","0.29547158","0","2"],["104294.7","0.03708834","0","1"],["104285.6","0.14011803","0","4"],["104284","0","0","0"],["104230.1","0.00105325","0","4"]],"ts":"1747170718301","checksum":-51380099,"seqId":54226502431,"prevSeqId":54226502409}]}
{"arg":{"channel":"books","instId":"BTC-USDT"},"action":"update","data":[{"asks":[["104310.3","0.071881","0","1"],["104315.4","0.19425897","0","2"],["104315.7","0","0","0"],["104319.2","0.097946","0","1"],["104326.1","0.06464587","0","2"],["104326.3","0","0","0"],["104327","0.03121008","0","1"],["104329.7","0.00001","0","1"],["104330","0.08190006","0","3"],["104331","0.13897767","0","1"],["104333","0.002","0","1"],["104338.9","0","0","0"],["104533.9","0","0","0"]],"bids":[["104308","1.05074504","0","21"],["104285.6","0.00114331","0","3"],["104283","0.1392141","0","2"],["104278","0","0","0"],["104230","0.00136575","0","3"]],"ts":"1747170718401","checksum":-694683348,"seqId":54226502512,"prevSeqId":54226502431}]}
{"arg":{"channel":"books","instId":"BTC-USDT"},"action":"update","data":[{"asks":[["104315.3","0.00182925","0","1"],["104315.4","0.19242972","0","1"],["104329.7","0.03835936","0","2"],["104533.3","0","0","0"]],"bids":[],"ts":"1747170718501","checksum":-1758236279,"seqId":54226502515,"prevSeqId":54226502512}]}
{"arg":{"channel":"books","instId":"BTC-USDT"},"action":"update","data":[{"asks":[],"bids":[["104301.4","0.00397407","0","3"]],"ts":"1747170718601","checksum":-1758236279,"seqId":54226502516,"prevSeqId":54226502515}]}
{"arg":{"channel":"books","instId":"BTC-USDT"},"action":"update","data":[{"asks":[["104308.1","0.42218431","0","12"],["104314","0.08665638","0","2"],["104326.1","0.05985381","0","1"],["104327.8","0.00479206","0","1"],["104532","0","0","0"]],"bids":[["104308","1.29074504","0","22"],["104301.5","0.16690648","0","1"],["104296.2","0.00479206","0","1"],["104294.8","0.29067952","0","1"],["104230","0","0","0"]],"ts":"1747170718701","checksum":-225673002,"seqId":54226502530,"prevSeqId":54226502516}]}
{"arg":{"channel":"books","instId":"BTC-USDT"},"action":"update","data":[{"asks":[["104321","0","0","0"],["104321.5","0.00479218","0","1"],["104419","0","0","0"],["104532","0.00001","0","1"]],"bids":[["104308","1.29212504","0","23"]],"ts":"1747170718801","checksum":-286029379,"seqId":54226502538,"prevSeqId":54226502530}]}
{"arg":{"channel":"books","instId":"BTC-USDT"},"action":"update","data":[{"asks":[["104315.2","0.00182925","0","1"],["104315.3","0.24","0","1"],["104320.5","0.00679218","0","2"],["104321.5","0","0","0"],["104461.9","0.0473048","0","2"],["104507","1.20664328","0","2"]],"bids":[["104308","1.05212504","0","22"],["104307.7","0.00016403","0","1"],["104230.1","0","0","0"]],"ts":"1747170718901","checksum":1433114507,"seqId":54226502554,"prevSeqId":54226502538}]}
{"arg":{"channel":"books","instId":"BTC-USDT"},"action":"update","data":[{"asks":[["104326.3","0.00479206","0","1"],["104327.8","0","0","0"],["104330.6","0.00850935","0","1"],["104335.4","0.03","0","1"],["104340.6","0","0","0"],["104532","0","0","0"]],"bids":[["104296.2","0","0","0"],["104294.9","0.19733497","0","3"],["104230.1","0.00105325","0","4"]],"ts":"1747170719001","checksum":1433114507,"seqId":54226502596,"prevSeqId":54226502554}]}
{"arg":{"channel":"books","instId":"BTC-USDT"},"action":"update","data":[{"asks":[["104315.1","0.00182925","0","1"],["104315.2","0.36908178","0","1"],["104320.4","0.00479218","0","1"],["104320.5","0.002","0","1"],["104331","0","0","0"],["104331.8","0.13897661","0","1"],["104530","0","0","0"],["104531.4","0","0","0"]],"bids":[["104284","0.13897685","0","1"],["104283","0.00023593","0","1"],["104230.1","0","0","0"]],"ts":"1747170719101","checksum":823153893,"seqId":54226502611,"prevSeqId":54226502596}]}
{"arg":{"channel":"books","instId":"BTC-USDT"},"action":"update","data":[{"asks":[["104320.4","0","0","0"],["104321","0.00479218","0","1"],["104333.6","0.20711658","0","2"],["104335.8","0","0","0"],["104353.2","0.54594","0","1"]],"bids":[],"ts":"1747170719201","checksum":1267733104,"seqId":54226502617,"prevSeqId":54226502611}]}
{"arg":{"channel":"books","instId":"BTC-USDT"},"action":"update","data":[{"asks":[["104315.3","0","0","0"],["104315.5","0","0","0"],["104315.6","0","0","0"],["104315.8","0","0","0"],["104326.3","0","0","0"],["104326.9","0.00479206","0","1"],["104330.9","0.13897788","0","1"],["104331.8","0","0","0"],["104332.8","0","0","0"],["104392.9","0","0","0"],["104399.7","5.91725868","0","1"],["104530","0.00028006","0","1"],["104531.4","0.00209352","0","1"],["104532","0.00001","0","1"],["104533.3","0.000173","0","1"],["104533.9","0.03","0","1"]],"bids":[["104295.1","0.00521106","0","2"],["104294.9","0.19254291","0","2"],["104284","0","0","0"],["104283","0.13921381","0","2"],["104230.1","0.00105325","0","4"]],"ts":"1747170719301","checksum":1196199709,"seqId":54226502647,"prevSeqId":54226502617}]}
{"arg":{"channel":"books","instId":"BTC-USDT"},"action":"update","data":[{"asks":[["104321","0","0","0"],["104321.5","0.00479218","0","1"],["104330.9","0","0","0"],["104332.8","0.0001303","0","1"],["104333","0.14097576","0","2"]],"bids":[["104284.5","0.14089616","0","3"],["104283","0.00023593","0","1"]],"ts":"1747170719401","checksum":1954506468,"seqId":54226502681,"prevSeqId":54226502647}]}
{"arg":{"channel":"books","instId":"BTC-USDT"},"action":"update","data":[{"asks":[["104332.8","0","0","0"],["104534.7","0.00094804","0","1"]],"bids":[],"ts":"1747170719501","checksum":1954506468,"seqId":54226502691,"prevSeqId":54226502681}]}
{"arg":{"channel":"books","instId":"BTC-USDT"},"action":"update","data":[{"asks":[["104332.8","0.0001303","0","1"],["104392.9","5.91725868","0","1"],["104399.7","0","0","0"],["104534.7","0","0","0"]],"bids":[],"ts":"1747170719601","checksum":1954506468,"seqId":54226502697,"prevSeqId":54226502691}]}
{"arg":{"channel":"books","instId":"BTC-USDT"},"action":"update","data":[{"asks":[],"bids":[["104308","1.05074504","0","21"]],"ts":"1747170719801","checksum":-202364469,"seqId":54226502702,"prevSeqId":54226502697}]}
{"arg":{"channel":"books","instId":"BTC-USDT"},"action":"update","data":[{"asks":[["104315","0.00182925","0","1"],["104315.1","0.24","0","1"],["104315.9","0.00045","0","1"],["104326","0.00479206","0","1"],["104326.9","0","0","0"],["104347.7","0","0","0"],["104379","0","0","0"],["104392.9","5.89523108","0","1"],["104534.7","0.00094804","0","1"]],"bids":[["104295.1","0.000419","0","1"],["104294.5","0.00479206","0","1"],["104264.6","0.30991941","0","1"],["104262.9","0","0","0"],["104231.6","0","0","0"],["104230","0.00136575","0","3"]],"ts":"1747170719901","checksum":-1484902253,"seqId":54226502720,"prevSeqId":54226502702}]}
{"arg":{"channel":"books","instId":"BTC-USDT"},"action":"update","data":[{"asks":[["104321","0.00479218","0","1"],["104321.5","0","0","0"],["104349.7","1.37154618","0","1"],["104381","2.47529784","0","1"],["104533.9","0","0","0"],["104534.7","0","0","0"]],"bids":[["104264.6","0.83981095","0","2"],["104264","1.42559092","0","1"],["104232.7","2.63956827","0","2"],["104230","0","0","0"]],"ts":"1747170720001","checksum":-1257837950,"seqId":54226502727,"prevSeqId":54226502720}]}
{"arg":{"channel":"books","instId":"BTC-USDT"},"action":"update","data":[{"asks":[["104324.6","0.03121081","0","1"],["104327","0","0","0"],["104331","0.1389778","0","1"],["104333","0.002","0","1"],["104336","0","0","0"],["104337","0.002","0","2"],["104338","0.1790651","0","2"],["104359","0","0","0"],["104360","0.33221842","0","9"],["104361","0.165015","0","4"],["104533.9","0.03","0","1"]],"bids":[["104284.5","0.0019204","0","2"],["104283.5","0.13898986","0","2"],["104266.3","0.00001","0","1"]],"ts":"1747170720101","checksum":-1257837950,"seqId":54226502780,"prevSeqId":54226502727}]}
{"arg":{"channel":"books","instId":"BTC-USDT"},"action":"update","data":[{"asks":[["104308.1","0.38729299","0","11"],["104326","0","0","0"],["104329.3","0.00479206","0","1"],["104331","0","0","0"],["104331.8","0.13897629","0","1"]],"bids":[["104298.9","0.07308353","0","3"],["104297.6","0.19331985","0","4"],["104294.5","0","0","0"],["104284.5","0.14089601","0","3"],["104283.5","0.00001212","0","1"],["104230","0.00136575","0","3"]],"ts":"1747170720201","checksum":-2142626550,"seqId":54226502970,"prevSeqId":54226502780}]}
{"arg":{"channel":"books","instId":"BTC-USDT"},"action":"update","data":[{"asks":[["104331.8","0","0","0"],["104333","0.14097545","0","2"],["104348.5","0.68717965","0","2"],["104354.5","0.61817704","0","1"],["104386","0","0","0"],["104534.7","0.00094804","0","1"],["104535.6","0.00002193","0","1"]],"bids":[["104308","1.05214504","0","22"]],"ts":"1747170720301","checksum":-1661950154,"seqId":54226502979,"prevSeqId":54226502970}]}
{"arg":{"channel":"books","instId":"BTC-USDT"},"action":"update","data":[{"asks":[["104320.4","0.00479221","0","1"],["104321","0","0","0"],["104321.6","0.16233727","0","1"],["104332.9","0.13902592","0","2"],["104333","0.002","0","1"],["104334.1","0","0","0"],["104535.8","0.77866876","0","1"]],"bids":[["104305.8","0.005","0","1"],["104293.3","0.005","0","1"],["104266.8","0.00712208","0","2"]],"ts":"1747170720401","checksum":228713348,"seqId":54226502990,"prevSeqId":54226502979}]}
{"arg":{"channel":"books","instId":"BTC-USDT"},"action":"update","data":[{"asks":[],"bids":[["104297.7","0.00491423","0","3"],["104297.6","0.18852779","0","3"]],"ts":"1747170720501","checksum":228713348,"seqId":54226502994,"prevSeqId":54226502990}]}
{"arg":{"channel":"books","instId":"BTC-USDT"},"action":"update","data":[{"asks":[["104308.1","0.38636764","0","11"]],"bids":[["104297.7","0.00012217","0","2"],["104296.2","0.00479206","0","1"],["104230","0","0","0"]],"ts":"1747170720601","checksum":318124582,"seqId":54226503000,"prevSeqId":54226502994}]}
{"arg":{"channel":"books","instId":"BTC-USDT"},"action":"update","data":[{"asks":[["104320","0.00509228","0","3"],["104320.4","0","0","0"],["104536.1","0.0152","0","1"]],"bids":[["104296.3","0.00479206","0","1"],["104296.2","0","0","0"]],"ts":"1747170720701","checksum":1668924929,"seqId":54226503008,"prevSeqId":54226503000}]}
{"arg":{"channel":"books","instId":"BTC-USDT"},"action":"update","data":[{"asks":[["104332.9","0.00005","0","1"],["104333.5","0.13897395","0","1"],["104536.1","0","0","0"]],"bids":[["104285.6","0.14011726","0","4"],["104284.5","0.0019204","0","2"]],"ts":"1747170720901","checksum":1668924929,"seqId":54226503016,"prevSeqId":54226503008}]}
{"arg":{"channel":"books","instId":"BTC-USDT"},"action":"update","data":[{"asks":[["104333","0.14097547","0","2"],["104333.5","0","0","0"],["104536.1","0.0152","0","1"]],"bids":[["104285.6","0.00114331","0","3"],["104284.5","0.14089587","0","3"]],"ts":"1747170721001","checksum":1668924929,"seqId":54226503020,"prevSeqId":54226503016}]}
{"arg":{"channel":"books","instId":"BTC-USDT"},"action":"update","data":[{"asks":[["104322.5","0.02829391","0","1"],["104328.5","0.00479206","0","1"],["104329.3","0","0","0"],["104331.8","0.13897613","0","1"],["104333","0.002","0","1"],["104535.8","0","0","0"],["104536.1","0","0","0"]],"bids":[["104296.3","0","0","0"],["104296.2","0.00479206","0","1"]],"ts":"1747170721101","checksum":1668924929,"seqId":54226503041,"prevSeqId":54226503020}]}
{"arg":{"channel":"books","instId":"BTC-USDT"},"action":"update","data":[{"asks":[["104315","0","0","0"],["104315.1","0.00182925","0","1"],["104321.6","0.16733727","0","2"],["104331.8","0","0","0"],["104332.8","0","0","0"],["104333","0.14097593","0","2"],["104334.1","0.005","0","1"],["104535.8","0.77866876","0","1"],["104536.1","0.0152","0","1"]],"bids":[["104305.8","0.01","0","2"],["104293.3","0.01","0","2"],["104266.8","0.00001005","0","1"]],"ts":"1747170721201","checksum":366059490,"seqId":54226503061,"prevSeqId":54226503041}]}
{"arg":{"channel":"books","instId":"BTC-USDT"},"action":"update","data":[{"asks":[["104332.8","0.0001303","0","1"],["104389.5","5.89523108","0","1"],["104392.9","0","0","0"],["104536.1","0","0","0"]],"bids":[["104266.3","0.00712203","0","2"]],"ts":"1747170721301","checksum":366059490,"seqId":54226503067,"prevSeqId":54226503061}]}
{"arg":{"channel":"books","instId":"BTC-USDT"},"action":"update","data":[{"asks":[["104327.8","0.00479206","0","1"],["104328.5","0","0","0"],["104332.8","0","0","0"],["104333","0.002","0","1"],["104334.1","0.14397364","0","2"],["104389.5","0","0","0"],["104396.3","5.87881972","0","1"],["104536.1","0.0152","0","1"]],"bids":[["104296.2","0","0","0"],["104295.5","0.00479206","0","1"],["104286.5","0.13907735","0","2"],["104284.5","0.0019204","0","2"],["104266.3","0.00001","0","1"]],"ts":"1747170721401","checksum":366059490,"seqId":54226503081,"prevSeqId":54226503067}]}
{"arg":{"channel":"books","instId":"BTC-USDT"},"action":"update","data":[{"asks":[["104308.1","0","0","0"],["104310","0","0","0"],["104310.3","0","0","0"],["104313.8","0","0","0"],["104314","0.00505638","0","1"],["104315.2","0","0","0"],["104315.4","0","0","0"],["104316","0","0","0"],["104318.5","0","0","0"],["104318.6","0.13891956","0","3"],["104319","0","0","0"],["104319.2","0","0","0"],["104320","0.00030006","0","2"],["104321","0.00479222","0","1"],["104322","0","0","0"],["104322.5","0","0","0"],["104323","0","0","0"],["104324.6","0","0","0"],["104325.1","0","0","0"],["104325.8","0.04","0","1"],["104326.2","0.19242972","0","1"],["104326.7","0","0","0"],["104327.8","0","0","0"],["104329.9","0","0","0"],["104330.1","0.36908178","0","1"],["104331.1","0.25014658","0","1"],["104332.8","0.0001303","0","1"],["104332.9","0.00484206","0","2"],["104343.7","0","0","0"],["104344.4","0","0","0"],["104346.9","0.1780651","0","1"],["104363.6","0","0","0"],["104366.2","0","0","0"],["104366.3","0","0","0"],["104369.8","0.42833407","0","2"],["104372.9","0","0","0"],["104375.9","0.02265242","0","1"],["104379.1","0","0","0"],["104389.6","0","0","0"],["104396.3","0","0","0"],["104408","0","0","0"],["104411.6","0.01054345","0","1"],["104433.4","0.00001","0","1"],["104536.2","0.076","0","5"],["104536.3","0.076","0","5"],["104536.4","0.00002296","0","1"],["104537.6","7.78674232","0","1"],["104538.4","0.07298372","0","1"],["104540","0.00330186","0","4"],["104541.2","0.00009506","0","1"],["104541.4","0.0001","0","1"],["104541.9","0.00003805","0","1"],["104542","0.00002848","0","1"],["104544.2","0.4","0","1"],["104545.4","0.00021056","0","2"],["104546","0.03186","0","1"],["104546.1","0.00037885","0","1"],["104546.3","0.77866876","0","1"],["104547","0.00957224","0","1"],["104547.3","0.03","0","1"],["104547.7","0.00002452","0","1"],["104547.9","0.00001","0","1"],["104549.2","0.29193486","0","1"],["104550","0.00057004","0","3"],["104551.2","0.00005067","0","1"],["104551.9","0.00001","0","1"]],"bids":[["104313.9","0.75218584","0","18"],["104313.7","0.52754001","0","4"],["104313.2","0.234","0","1"],["104312","0.0816","0","1"],["104310.2","0.30967152","0","11"],["104310","0.0816","0","1"],["104309.9","0.00009","0","1"],["104308.8","0.1195","0","1"],["104308.5","0.09875","0","1"],["104308.1","0.92187985","0","6"],["104308","1.28885504","0","21"],["104305.1","0","0","0"],["104304.6","0.00013482","0","2"],["104300.4","0.00479206","0","1"],["104295.5","0","0","0"],["104285.6","0.07302631","0","4"],["104273.2","0","0","0"],["104266.4","0.00711203","0","1"],["104232","0","0","0"],["104231.8","0","0","0"],["104231.7","0","0","0"],["104231.5","0","0","0"],["104231.3","0","0","0"],["104231.1","0","0","0"],["104230.7","0","0","0"],["104230.2","0","0","0"],["104230.1","0","0","0"]],"ts":"1747170721501","checksum":-1566072419,"seqId":54226503280,"prevSeqId":54226503081}]}
{"arg":{"channel":"books","instId":"BTC-USDT"},"action":"update","data":[{"asks":[["104314","0","0","0"],["104315.1","0","0","0"],["104315.9","0","0","0"],["104316.4","0","0","0"],["104317.1","0","0","0"],["104317.8","0","0","0"],["104318.1","0","0","0"],["104318.6","0","0","0"],["104320","0","0","0"],["104320.1","0","0","0"],["104320.5","0.01619383","0","6"],["104321","0","0","0"],["104321.1","0","0","0"],["104321.6","0.005","0","1"],["104321.8","0","0","0"],["104321.9","0","0","0"],["104322.1","0","0","0"],["104323.9","0","0","0"],["104324","0","0","0"],["104324.8","0","0","0"],["104325.3","0","0","0"],["104325.4","0.00263379","0","1"],["104325.8","0","0","0"],["104326","0.17136859","0","2"],["104326.1","0","0","0"],["104326.2","0","0","0"],["104326.4","0","0","0"],["104326.6","0","0","0"],["104326.9","0.01916919","0","1"],["104327.1","0","0","0"],["104327.4","0","0","0"],["104327.9","0","0","0"],["104328.1","0","0","0"],["104328.6","0","0","0"],["104329.1","0.04","0","1"],["104329.3","0.00182925","0","1"],["104329.4","0.04479349","0","2"],["104329.7","0.13586121","0","2"],["104329.8","0.02984193","0","1"],["104330.1","0","0","0"],["104330.5","0.039371","0","1"],["104330.6","0","0","0"],["104330.7","0.03833983","0","1"],["104331","0.16729695","0","1"],["104331.1","0","0","0"],["104331.3","0","0","0"],["104331.6","0","0","0"],["104331.8","0.0949816","0","1"],["104331.9","0","0","0"],["104332.8","0","0","0"],["104332.9","0.00005","0","1"],["104333.1","0.1105","0","4"],["104333.2","0","0","0"],["104333.4","0.09518053","0","1"],["104333.6","0.32510439","0","3"],["104334","0.08972664","0","1"],["104334.1","0.005","0","1"],["104334.2","0","0","0"],["104334.5","0.02829065","0","1"],["104335.4","0","0","0"],["104335.5","0","0","0"],["104335.9","0.00479179","0","1"],["104336","0.27040148","0","1"],["104336.4","0.03045939","0","1"],["104336.8","0","0","0"],["104336.9","0.14826995","0","1"],["104337","0","0","0"],["104337.3","0.15477015","0","1"],["104337.6","0.05986381","0","2"],["104338","0.1780651","0","1"],["104339","0.24914293","0","1"],["104339.5","0","0","0"],["104340.2","0.1609475","0","1"],["104340.7","0.23156188","0","1"],["104340.8","0.00479206","0","1"],["104340.9","0.1780651","0","1"],["104342","0.04253217","0","1"],["104342.8","0.26654868","0","1"],["104343.2","0","0","0"],["104345.4","0","0","0"],["104345.5","0.00001","0","1"],["104346.3","0.1389577","0","1"],["104346.4","0.1780651","0","1"],["104346.5","0.26530338","0","1"],["104346.7","0.3232825","0","1"],["104347","0.002","0","2"],["104348","0.00811203","0","2"],["104348.1","0.1780651","0","1"],["104351.9","0","0","0"],["104354.5","0.64713293","0","2"],["104356.8","0","0","0"],["104357.8","0","0","0"],["104359","0.04786951","0","1"],["104360","0.00221843","0","3"],["104360.2","0","0","0"],["104361","0.00001501","0","1"],["104362.8","0","0","0"],["104367.1","0","0","0"],["104367.5","0.02467326","0","2"],["104368.7","0.1","0","1"],["104369","0.33","0","6"],["104370","0.16528005","0","4"],["104375.2","0.00004975","0","1"],["104375.9","0","0","0"],["104377.1","2.41393","0","1"],["104390.1","0.44179723","0","1"],["104392.6","0.00287","0","1"],["104432.8","0.00001","0","1"],["104436.7","0","0","0"],["104440.3","5.87881972","0","1"],["104538.5","0.234","0","1"],["104549","0.234","0","1"],["104552.4","0.00004887","0","1"],["104552.6","0.0152","0","1"],["104553.7","0.00002373","0","1"],["104554.1","0.29193486","0","1"],["104556.9","0.04782","0","1"],["104557.3","0.77866876","0","1"],["104558.2","0.00001105","0","1"],["104558.9","0.00040805","0","13"],["104559.4","0.00002482","0","1"],["104559.5","0.234","0","1"],["104560","0.00222145","0","4"],["104560.3","0.00011389","0","1"],["104560.9","0.00023767","0","1"]],"bids":[["104320.4","1.29298808","0","13"],["104320.1","0.119163","0","1"],["104320","0.10966495","0","3"],["104318.8","0.02542817","0","1"],["104318","0.0816","0","1"],["104317.7","0.234","0","1"],["104316","0.0816","0","1"],["104314.2","0.04026351","0","1"],["104314.1","0.28973366","0","1"],["104314","0.24522335","0","2"],["104313.9","0.31356618","0","5"],["104313.8","0.00019173","0","1"],["104313.7","0.234","0","1"],["104313.2","0","0","0"],["104312.9","0.09388414","0","1"],["104311.5","0.08838656","0","1"],["104310.8","0.10028936","0","1"],["104310.7","0.09117956","0","1"],["104310.2","0","0","0"],["104310","0.08189006","0","3"],["104309.8","0.15155763","0","1"],["104309.6","0.00001501","0","1"],["104309.4","0.15791787","0","2"],["104309.3","0.07298372","0","1"],["104308.8","0","0","0"],["104308.5","0","0","0"],["104308.1","0","0","0"],["104308","0.14771138","0","13"],["104307.7","0","0","0"],["104306.5","0.09508733","0","1"],["104306.1","0.40833894","0","2"],["104305.7","0.24243833","0","2"],["104305.5","0.19242972","0","1"],["104305.2","0.18372131","0","2"],["104304.6","0.03722316","0","3"],["104304.4","0.01126324","0","1"],["104303.4","0","0","0"],["104302.9","0.77867908","0","2"],["104301.5","0.46429182","0","3"],["104300.9","0.00098","0","1"],["104300.6","0.002877","0","1"],["104300.4","0","0","0"],["104300.3","0","0","0"],["104300.2","0.00958619","0","1"],["104299.8","0.25202329","0","2"],["104299.2","0.00003543","0","3"],["104299","0.24595441","0","1"],["104297.6","0.16896946","0","3"],["104296.6","0.01126324","0","1"],["104296.5","0.26237014","0","2"],["104296.1","0","0","0"],["104295.6","0.00098","0","1"],["104295.4","0.00001943","0","1"],["104295.1","0.030419","0","2"],["104295","0","0","0"],["104294.8","0","0","0"],["104294.7","0","0","0"],["104294.4","0.00020507","0","1"],["104294.1","0.04097922","0","4"],["104294","0.00383531","0","1"],["104293.9","0","0","0"],["104293.4","0.03","0","1"],["104293.2","0.035","0","2"],["104292.6","0","0","0"],["104292.1","0.03003021","0","3"],["104291.9","0.03308723","0","2"],["104290.4","0.18044455","0","8"],["104290.3","0.00005072","0","1"],["104290.1","0.00001","0","1"],["104289.8","0","0","0"],["104289.7","0.1780651","0","1"],["104288.1","0.03001676","0","2"],["104287.6","0.00007438","0","3"],["104286.5","0.00010371","0","1"],["104285.5","0.22125618","0","1"],["104285.2","0.00191","0","1"],["104284.5","0.0000104","0","1"],["104284.4","0","0","0"],["104283.9","0.06","0","2"],["104283.6","0","0","0"],["104282.9","0","0","0"],["104281.6","0.00001024","0","1"],["104280.4","0.36908178","0","1"],["104279.3","0","0","0"],["104271.2","0.00479322","0","1"],["104270","0.29722036","0","3"],["104269.3","0","0","0"],["104269.2","0.00026966","0","5"],["104268.4","0.58747895","0","3"],["104266.7","0.04963798","0","1"],["104264.7","0.00002095","0","1"],["104261.8","0.00047932","0","1"],["104260","0.00388889","0","5"],["104258","0","0","0"],["104256.1","0","0","0"],["104255.8","0","0","0"],["104251.7","0.01632711","0","2"],["104246.8","0.01597047","0","1"],["104246.4","0","0","0"],["104239.2","0.00954291","0","1"],["104236.6","0","0","0"],["104234.4","0","0","0"],["104234.3","0","0","0"],["104234","0","0","0"],["104233.7","0","0","0"],["104233.3","0","0","0"],["104233","0","0","0"],["104232.9","0","0","0"],["104232.7","0","0","0"],["104232.5","0","0","0"],["104232.4","0","0","0"]],"ts":"1747170721601","checksum":244889570,"seqId":54226504276,"prevSeqId":54226503280}]}
{"arg":{"channel":"books","instId":"BTC-USDT"},"action":"update","data":[{"asks":[["104320.5","0.01628383","0","7"],["104321.8","0.071883","0","1"],["104323.7","0","0","0"],["104325.9","0.19242972","0","1"],["104326","0.20386815","0","3"],["104329.3","0","0","0"],["104329.4","0.00479349","0","1"],["104329.7","0.00183925","0","2"],["104330.3","0.097949","0","1"],["104330.5","0.04","0","1"],["104330.7","0","0","0"],["104331.1","0.09285909","0","1"],["104331.8","0","0","0"],["104332.7","0.09127746","0","1"],["104333.3","0.09195529","0","1"],["104333.4","0","0","0"],["104333.9","0.00479153","0","1"],["104334","0","0","0"],["104334.5","0","0","0"],["104335.8","0.039371","0","1"],["104335.9","0","0","0"],["104336.2","0.15169672","0","1"],["104336.4","0","0","0"],["104336.5","0.07298372","0","1"],["104336.6","0.15937581","0","1"],["104336.9","0","0","0"],["104337","0.03833768","0","1"],["104337.3","0","0","0"],["104337.8","0.03045901","0","1"],["104339","0.57110205","0","1"],["104339.1","0.00479206","0","1"],["104339.2","0.0304586","0","1"],["104339.5","0.15410609","0","1"],["104340","0.24019569","0","5"],["104340.2","0","0","0"],["104340.4","0.77866876","0","1"],["104340.5","0","0","0"],["104340.7","0","0","0"],["104340.8","0","0","0"],["104342.1","0.25403983","0","1"],["104342.8","0","0","0"],["104343.4","0.00287499","0","1"],["104345.8","0.26006911","0","1"],["104346.3","0","0","0"],["104346.5","0","0","0"],["104346.8","0.54327","0","1"],["104347","0","0","0"],["104348","0.00711203","0","1"],["104348.5","0.82613345","0","3"],["104349","0.002","0","2"],["104350","0.00130006","0","3"],["104354.5","0.02895589","0","1"],["104355.8","0","0","0"],["104357.5","0","0","0"],["104358.5","0.0022","0","1"],["104359.4","0.28828972","0","2"],["104362.5","0.09586","0","1"],["104368.7","0","0","0"],["104369","0","0","0"],["104370","0.00028006","0","1"],["104372","0.32999999","0","6"],["104372.7","0.00047929","0","1"],["104373","0.16499999","0","3"],["104375.2","0.10004975","0","2"],["104375.8","0.0022","0","1"],["104407.1","0","0","0"],["104415.4","0","0","0"],["104423.1","0.02971483","0","2"],["104440.3","0","0","0"],["104450.4","6.04059634","0","2"],["104461.9","0.04634752","0","1"],["104468","0","0","0"]],"bids":[["104312.9","0","0","0"],["104312.2","0.08782611","0","1"],["104311.5","0","0","0"],["104310.8","0.09734804","0","1"],["104310.7","0.20658148","0","2"],["104310.1","0.09067433","0","1"],["104309.9","0","0","0"],["104309.8","0","0","0"],["104309.4","0","0","0"],["104309.1","0.15383329","0","1"],["104308.7","0.14530686","0","1"],["104308.6","0.02805801","0","1"],["104306.6","0.00482567","0","3"],["104306.2","0.19242972","0","1"],["104306.1","0.41594698","0","3"],["104305.7","0.002","0","1"],["104305.5","0","0","0"],["104305.2","0.02734772","0","1"],["104305","0.25486177","0","2"],["104304.5","0.1508342","0","1"],["104300.2","0.14853999","0","2"],["104299.8","0.00108768","0","1"],["104299.1","0.26294655","0","2"],["104299","0","0","0"],["104298.3","0.26028159","0","1"],["104297.6","0.03001176","0","2"],["104285.5","0","0","0"],["104283.9","0","0","0"],["104261.8","0","0","0"],["104259","0.00002967","0","1"],["104240.1","0.00954761","0","1"],["104238.1","0","0","0"],["104234.4","0.77963354","0","2"]],"ts":"1747170721701","checksum":-1544647086,"seqId":54226504575,"prevSeqId":54226504276}]}
{"arg":{"channel":"books","instId":"BTC-USDT"},"action":"update","data":[{"asks":[["104320.5","0.18362383","0","10"],["104324","0.0816","0","1"],["104324.4","0.03108988","0","1"],["104326","0.11409956","0","2"],["104328.3","0.00045","0","1"],["104329","0.00182925","0","1"],["104329.4","0.10407665","0","2"],["104329.7","0.00001","0","1"],["104329.8","0","0","0"],["104329.9","0.36908178","0","1"],["104330","0.17216283","0","4"],["104330.5","0","0","0"],["104331","0.3283175","0","2"],["104331.1","0","0","0"],["104331.6","0.08851624","0","1"],["104332.7","0","0","0"],["104332.8","0.0047916","0","1"],["104333.1","0.0715","0","3"],["104333.3","0","0","0"],["104333.5","0.00093","0","1"],["104333.6","0.3262836","0","3"],["104333.9","0","0","0"],["104334.5","0.20227077","0","2"],["104334.9","0.16134577","0","1"],["104335","0.16545612","0","1"],["104335.6","0.02829037","0","1"],["104336","0","0","0"],["104336.2","0","0","0"],["104336.6","0","0","0"],["104337.2","0","0","0"],["104337.8","0.19054986","0","2"],["104338.3","0.22988251","0","1"],["104338.6","0.02984193","0","1"],["104338.8","0.00093","0","1"],["104339","0.42175257","0","1"],["104339.2","0","0","0"],["104339.5","0","0","0"],["104340","0.25436402","0","5"],["104340.2","0.036","0","1"],["104340.4","1.02403829","0","2"],["104340.7","0.039","0","1"],["104342.1","0","0","0"],["104344.1","0.24451627","0","1"],["104344.3","0.13896109","0","1"],["104344.4","0.093","0","3"],["104344.5","0.50348957","0","1"],["104345.8","0","0","0"],["104346.7","0","0","0"],["104348.5","0.68717965","0","2"],["104359.3","0.00014348","0","1"],["104365.8","0.0001303","0","1"],["104371.2","0.555326","0","1"],["104372","0","0","0"],["104373","0","0","0"],["104374","0.33","0","6"],["104375","0.16499999","0","3"],["104386.2","2.4257","0","1"],["104386.5","0.0958","0","1"],["104424.8","0.00096762","0","2"],["104450.4","0.161008","0","1"],["104553.7","0","0","0"],["104554.1","0","0","0"],["104556.9","0","0","0"],["104557.3","0","0","0"],["104558.2","0","0","0"],["104558.9","0","0","0"],["104559.4","0","0","0"],["104559.5","0","0","0"],["104560","0","0","0"],["104560.3","0","0","0"],["104560.9","0","0","0"]],"bids":[["104320.4","1.09009472","0","14"],["104312.6","0.0005","0","1"],["104312.2","0","0","0"],["104310.8","0","0","0"],["104310.7","0.30016992","0","2"],["104310.5","0.1896269","0","2"],["104310.1","0","0","0"],["104309.1","0.09743706","0","1"],["104308.7","0","0","0"],["104308.4","0.100323","0","1"],["104308","0.14519138","0","10"],["104307.4","0.16907233","0","3"],["104307","0.15288889","0","2"],["104306.5","0","0","0"],["104306.1","0.42458627","0","2"],["104305.5","0.15019904","0","1"],["104305","0.00001","0","1"],["104304.5","0","0","0"],["104303.3","0.26096378","0","1"],["104302.8","0.16295987","0","1"],["104302.1","0.00098","0","1"],["104301.5","0.26693092","0","2"],["104300.9","0","0","0"],["104300.5","0.26182373","0","1"],["104300.2","0.00958619","0","1"],["104299.1","0.00010104","0","1"],["104298.3","0","0","0"],["104297.4","0.24484311","0","2"],["104296.6","0.27405505","0","2"],["104296.5","0.00001917","0","1"],["104295.6","0","0","0"],["104295.3","0.13896109","0","1"],["104295.2","0.04","0","1"],["104291.1","0.36908178","0","1"],["104288.1","0.00001676","0","1"],["104281.2","0.00001019","0","1"],["104271.3","0.00002967","0","1"],["104266.7","0","0","0"],["104259","0","0","0"],["104250.2","0.55597","0","1"],["104234.5","0","0","0"],["104234.4","0","0","0"]],"ts":"1747170721801","checksum":-1232370350,"seqId":54226504873,"prevSeqId":54226504575}]}
{"arg":{"channel":"books","instId":"BTC-USDT"},"action":"update","data":[{"asks":[["104316.1","1.89462265","0","19"],["104317.9","0.00091462","0","1"],["104318","0.69372097","0","3"],["104318.1","0.47946178","0","2"],["104318.2","0.29193486","0","1"],["104319.5","0.00479215","0","1"],["104320","0.32162","0","3"],["104320.1","0.25917064","0","2"],["104320.5","0.512","0","4"],["104322","0.0816","0","1"],["104322.7","0.07298372","0","1"],["104323","0.08950077","0","1"],["104323.5","0.00479206","0","1"],["104323.6","0.27322841","0","1"],["104323.7","0.10119478","0","1"],["104324","0.120971","0","2"],["104324.1","0.02829347","0","1"],["104324.7","0.08555632","0","1"],["104325.2","0.09332204","0","1"],["104325.4","0.04263379","0","2"],["104326.5","0.02984193","0","1"],["104326.8","0.13898336","0","1"],["104326.9","0","0","0"],["104328.2","0.16360284","0","1"],["104328.5","0.16716461","0","1"],["104328.7","0.16217277","0","1"],["104329","0","0","0"],["104329.1","0","0","0"],["104329.4","0","0","0"],["104329.5","0.03836436","0","2"],["104329.7","0.56410127","0","2"],["104329.8","0.81700924","0","2"],["104330","0.08190006","0","3"],["104331","0.234","0","1"],["104331.5","0.16300939","0","1"],["104331.6","0","0","0"],["104331.9","0.23410367","0","1"],["104332.8","0","0","0"],["104333.6","0.30349033","0","3"],["104333.7","0.26870987","0","1"],["104334","0.24795466","0","1"],["104334.5","0.04","0","1"],["104334.9","0","0","0"],["104335","0","0","0"],["104335.6","0","0","0"],["104335.8","0","0","0"],["104335.9","0.01","0","1"],["104337","0","0","0"],["104337.6","0.00001","0","1"],["104337.7","0.26086708","0","1"],["104337.8","0.03045901","0","1"],["104338.3","0","0","0"],["104338.6","0","0","0"],["104339.1","0","0","0"],["104339.9","0.05985381","0","1"],["104340","0.00223344","0","4"],["104340.4","0.77866876","0","1"],["104342","0","0","0"],["104344.1","0","0","0"],["104344.3","0","0","0"],["104344.9","0.036","0","1"],["104346","0.01158201","0","3"],["104347","0.001","0","1"],["104349","0","0","0"],["104350","0.00030006","0","2"],["104350.1","0","0","0"],["104350.6","0.02265242","0","1"],["104359.4","0.19242972","0","1"],["104362.5","0","0","0"],["104369","0.15999999","0","2"],["104369.6","0.02230591","0","1"],["104370","0.08028005","0","2"],["104371.2","0","0","0"],["104374","0.17","0","4"],["104375","0.085","0","2"],["104375.2","0.00004975","0","1"],["104386.5","0","0","0"],["104412.3","0.11493","0","1"],["104428","0.00009726","0","1"],["104545.4","0","0","0"],["104546","0","0","0"],["104546.1","0","0","0"],["104546.3","0","0","0"],["104547","0","0","0"],["104547.3","0","0","0"],["104547.7","0","0","0"],["104547.9","0","0","0"],["104549","0","0","0"],["104549.2","0","0","0"],["104550","0","0","0"],["104551.2","0","0","0"],["104551.9","0","0","0"],["104552.4","0","0","0"],["104552.6","0","0","0"]],"bids":[["104320.4","0","0","0"],["104320.1","0","0","0"],["104320","0","0","0"],["104318.8","0","0","0"],["104318","0","0","0"],["104317.7","0","0","0"],["104314.2","0","0","0"],["104314.1","0","0","0"],["104314","0.08682335","0","2"],["104313.9","0.02183149","0","3"],["104313.7","0","0","0"],["104312.6","0","0","0"],["104311.6","0.0280572","0","1"],["104310.7","0","0","0"],["104310.5","0","0","0"],["104310.1","0.07528994","0","1"],["104309.6","0","0","0"],["104309.3","0","0","0"],["104309.1","0","0","0"],["104308.4","0","0","0"],["104308","0.1386844","0","8"],["104307.4","0.00004553","0","1"],["104307","0.00012463","0","1"],["104306.6","0.00003361","0","2"],["104306.2","0","0","0"],["104306.1","0.1680316","0","2"],["104305.5","0","0","0"],["104305.2","0","0","0"],["104304.9","0.0467682","0","1"],["104304.6","0.00013482","0","2"],["104304.4","0","0","0"],["104304.2","0.18954407","0","2"],["104303.3","0","0","0"],["104302.9","0.00001032","0","1"],["104302.8","0","0","0"],["104302.7","0.09099085","0","2"],["104302.1","0","0","0"],["104302","0.09119445","0","1"],["104301.5","0.36572875","0","2"],["104301","0.14982554","0","1"],["104300.7","0.16271031","0","1"],["104300.6","0","0","0"],["104300.5","0","0","0"],["104299.2","0.14953503","0","4"],["104298.9","0.00009981","0","2"],["104297.4","0.00001024","0","1"],["104296.9","0.25868834","0","1"],["104296.6","0.01126324","0","1"],["104296.5","0.16423936","0","2"],["104295.4","0.17904455","0","2"],["104295.3","0","0","0"],["104295.2","0","0","0"],["104294.9","0.00011319","0","1"],["104294.8","0.06061265","0","1"],["104294.2","0.264867","0","2"],["104294","0","0","0"],["104291.1","0","0","0"],["104291","0.4657426","0","3"],["104290.9","0.00001762","0","1"],["104290.2","0.24747602","0","1"],["104289.5","0.00001028","0","1"],["104288.9","0.04034826","0","2"],["104288.5","0.0492945","0","1"],["104283.5","0.14718149","0","2"],["104280.4","0","0","0"],["104275.6","0.13898336","0","1"],["104266.4","0","0","0"],["104264.6","0.30991941","0","1"],["104264","0","0","0"],["104262.3","0.002937","0","2"],["104260.1","0","0","0"],["104251.7","0.00001009","0","1"],["104250.2","0","0","0"],["104246.8","0","0","0"],["104234.5","0.00003076","0","2"],["104234.4","0.77963354","0","2"],["104234.3","0.00028121","0","5"],["104234","0.00002831","0","2"],["104233.7","0.00003837","0","1"],["104233.3","0.00482005","0","1"],["104233","0.00086083","0","2"],["104232.9","0.00005458","0","1"],["104232.7","0.0000103","0","1"],["104232.5","0.00954475","0","1"],["104232.4","0.00045226","0","2"],["104232.2","0.00024748","0","1"],["104232.1","0.00083445","0","2"],["104232","0.01056164","0","2"],["104231.8","0.00364827","0","1"],["104231.7","0.00025117","0","2"],["104231.5","0.00004581","0","2"],["104231.3","0.00027353","0","4"],["104231.1","0.00001089","0","1"],["104230.7","0.01111263","0","9"],["104230.2","0.00005187","0","1"],["104230.1","0.00105325","0","4"],["104230","0.00136575","0","3"]],"ts":"1747170721901","checksum":-1403455092,"seqId":54226505461,"prevSeqId":54226504873}]}
{"arg":{"channel":"books","instId":"BTC-USDT"},"action":"update","data":[{"asks":[["104318","0.69280635","0","2"],["104323","0","0","0"],["104323.5","0","0","0"],["104323.7","0","0","0"],["104323.9","0.09788642","0","2"],["104324.1","0","0","0"],["104324.5","0.0906704","0","1"],["104324.7","0","0","0"],["104325.2","0","0","0"],["104325.5","0.08682727","0","1"],["104326.1","0.09199578","0","1"],["104326.6","0.02829279","0","1"],["104328.2","0","0","0"],["104328.3","0","0","0"],["104328.5","0.00479206","0","1"],["104328.7","0","0","0"],["104329","0.15188483","0","1"],["104329.1","0.00093","0","1"],["104329.4","0.15757278","0","1"],["104329.5","0.19088222","0","3"],["104331.5","0","0","0"],["104331.9","0","0","0"],["104332.3","0.15638192","0","1"],["104332.8","0.22781527","0","1"],["104333.5","0","0","0"],["104333.7","0","0","0"],["104334","0","0","0"],["104334.4","0.00093","0","1"],["104334.5","0.29054768","0","2"],["104334.9","0.24274603","0","1"],["104337.7","0","0","0"],["104338.6","0.24171076","0","1"],["104338.8","0","0","0"],["104343.2","0.00287511","0","1"],["104343.4","0","0","0"],["104356","0.0001435","0","1"],["104359.3","0","0","0"],["104365.8","0","0","0"],["104368","0.16","0","2"],["104369","0.07999999","0","1"],["104370","0.00028006","0","1"],["104389.6","0.0671","0","1"],["104393.1","5.87959834","0","2"],["104407.3","0.00006189","0","1"],["104409.5","0.09586","0","1"],["104412.6","0.09586","0","1"],["104415.7","0.07764345","0","2"],["104544.2","0","0","0"]],"bids":[["104316","0.20439","0","4"],["104315.3","0.00013043","0","1"],["104311.6","0.0561144","0","2"],["104310.1","0.07478456","0","1"],["104308.2","0.0005","0","1"],["104308","0.13540747","0","5"],["104306.1","0.16082408","0","2"],["104305","0.19061078","0","3"],["104304.2","0","0","0"],["104303.6","0.09717433","0","1"],["104303","0.00098","0","1"],["104302.9","0.09086739","0","2"],["104302.7","0.00001016","0","1"],["104302","0","0","0"],["104301.9","0.16360108","0","2"],["104301.5","0.42967569","0","3"],["104301","0","0","0"],["104300.7","0","0","0"],["104300","0.20756343","0","42"],["104299.2","0.00003543","0","3"],["104297.8","0.24659063","0","1"],["104297.7","0.00110217","0","3"],["104297.3","0.16505417","0","2"],["104296.9","0","0","0"],["104296.8","0.03708834","0","1"],["104296.7","0.00479206","0","1"],["104296.5","0.00001917","0","1"],["104296.1","0.02734772","0","1"],["104295.4","0.25135866","0","3"],["104295","0.25956157","0","1"],["104294.6","0.00007879","0","4"],["104294.2","0.00001937","0","1"],["104293.1","0.19242972","0","1"],["104291.9","0.27486514","0","3"],["104291.2","0.52269451","0","1"],["104291.1","1.04332654","0","2"],["104291","0.00009588","0","1"],["104290.2","0","0","0"],["104271.3","0","0","0"],["104269.9","1.73999026","0","4"],["104262.3","0.00006","0","1"],["104238.6","2.50480405","0","4"],["104233.6","0.002877","0","1"],["104231.3","0","0","0"],["104231.1","0","0","0"],["104230.7","0","0","0"],["104230.2","0","0","0"],["104230.1","0","0","0"],["104230","0","0","0"]],"ts":"1747170722001","checksum":-351435061,"seqId":54226505640,"prevSeqId":54226505461}]}
{"arg":{"channel":"books","instId":"BTC-USDT"},"action":"update","data":[{"asks":[["104316.1","1.88920799","0","19"],["104318.1","0.36908178","0","1"],["104319.5","0","0","0"],["104321.5","0.00479215","0","1"],["104326.8","0","0","0"],["104328.5","0","0","0"],["104328.9","0.00479206","0","1"],["104329.6","0.00479312","0","1"],["104329.8","0.82700924","0","3"],["104330.9","0.13897816","0","1"],["104339.5","0.00479312","0","1"],["104339.6","0.00191","0","1"],["104344.8","0.00191","0","1"],["104350","0.00317006","0","3"],["104361.3","0","0","0"],["104364","0.58412494","0","2"],["104370.8","0.1","0","1"],["104389.7","0.00056666","0","1"],["104403.7","0.00006192","0","1"],["104407.3","0","0","0"],["104409.5","0","0","0"],["104412.6","0","0","0"],["104418.9","0.07183","0","1"],["104423.5","0.00009581","0","1"],["104428","0","0","0"],["104442.9","0.00056666","0","1"],["104540","0","0","0"],["104541.2","0","0","0"],["104541.4","0","0","0"],["104541.9","0","0","0"],["104542","0","0","0"]],"bids":[["104313.9","0.01943488","0","2"],["104310.3","0.03834936","0","1"],["104309.6","0.00056666","0","1"],["104308.1","0.00002966","0","1"],["104308","0.13322285","0","3"],["104296.7","0","0","0"],["104295.5","0.00479206","0","1"],["104282.5","0.13897915","0","1"],["104275.6","0","0","0"],["104274.6","0.22464067","0","2"],["104263.8","0.00047931","0","1"],["104256.4","0.00057784","0","2"],["104242.9","0.833799","0","2"],["104232","0","0","0"],["104231.8","0","0","0"],["104231.7","0","0","0"],["104231.5","0","0","0"]],"ts":"1747170722101","checksum":1864950898,"seqId":54226505733,"prevSeqId":54226505640}]}
{"arg":{"channel":"books","instId":"BTC-USDT"},"action":"update","data":[{"asks":[["104323.6","0.19554434","0","1"],["104323.9","0.00045","0","1"],["104324.5","0","0","0"],["104325.5","0","0","0"],["104326.1","0","0","0"],["104329","0.02829216","0","1"],["104329.4","0","0","0"],["104329.5","0.03836436","0","2"],["104332","0.04870594","0","1"],["104332.3","0","0","0"],["104332.8","0","0","0"],["104333.6","0.28909698","0","3"],["104334.5","0.04","0","1"],["104334.9","0","0","0"],["104338.6","0","0","0"],["104359.4","0.28828972","0","2"],["104360.4","0.04976932","0","2"],["104362.5","0.09586","0","1"],["104367.8","0.77879906","0","2"],["104368","0.26","0","4"],["104369","0.12999999","0","2"],["104374","0.07","0","2"],["104375","0.035","0","1"],["104377.2","0.14372","0","2"],["104383.2","0.0958","0","1"],["104403.7","0","0","0"],["104404.6","0.09578","0","1"],["104538.5","0","0","0"],["104540","0.00330186","0","4"],["104541.2","0.00009506","0","1"],["104541.4","0.0001","0","1"],["104541.9","0.00003805","0","1"],["104542","0.00002848","0","1"],["104544.2","0.4","0","1"]],"bids":[["104316","0.08169","0","2"],["104313.7","0.0313128","0","1"],["104311.6","0.0280572","0","1"],["104310.3","0","0","0"],["104310.1","0","0","0"],["104308.1","0","0","0"],["104306.1","0.25025564","0","2"],["104305","0.00001","0","1"],["104303.6","0","0","0"],["104302.9","0.00001032","0","1"],["104301.9","0.00120818","0","1"],["104301.5","0.27429962","0","2"],["104300","0.04150745","0","41"],["104297.8","0","0","0"],["104297.3","0.00014981","0","1"],["104295","0","0","0"],["104291.9","0.03308723","0","2"],["104291.1","0.77866876","0","1"],["104282.5","0.13897787","0","1"],["104270.1","0.47272125","0","1"],["104266.4","0.04617706","0","1"],["104232","0.01056164","0","2"],["104231.8","0.00364827","0","1"],["104231.7","0.00025117","0","2"]],"ts":"1747170722201","checksum":1033316840,"seqId":54226505871,"prevSeqId":54226505733}]}
{"arg":{"channel":"books","instId":"BTC-USDT"},"action":"update","data":[{"asks":[["104316.1","1.96429542","0","21"],["104319.9","0.00479219","0","1"],["104321.5","0","0","0"],["104323","0.09509556","0","1"],["104323.1","0.0280322","0","1"],["104323.7","0.09114475","0","1"],["104324.7","0.09749445","0","1"],["104325.2","0.09437112","0","1"],["104325.3","0.03834936","0","1"],["104328.1","0.00479206","0","1"],["104328.2","0.15898129","0","1"],["104328.5","0.17012445","0","1"],["104328.7","0.15034923","0","1"],["104328.9","0","0","0"],["104329","0","0","0"],["104329.5","0.000015","0","1"],["104330.9","0","0","0"],["104331.3","0.13897716","0","1"],["104331.4","0.16471797","0","1"],["104331.9","0.25092918","0","1"],["104333.6","0.29083284","0","3"],["104333.7","0.24589622","0","1"],["104334","0.26791483","0","1"],["104337.7","0.25791151","0","1"],["104346.2","0.04813821","0","1"],["104359","0","0","0"],["104535.8","0","0","0"],["104536.1","0","0","0"],["104536.2","0","0","0"],["104536.3","0","0","0"],["104536.4","0","0","0"],["104537.6","0","0","0"],["104538.4","0","0","0"],["104540","0","0","0"],["104541.2","0","0","0"],["104541.4","0","0","0"],["104541.9","0","0","0"],["104542","0","0","0"],["104544.2","0","0","0"]],"bids":[["104316","0.08742","0","4"],["104313.7","0","0","0"],["104311.6","0","0","0"],["104308.6","0","0","0"],["104308.3","0.03131445","0","1"],["104306.1","0","0","0"],["104304.9","0","0","0"],["104304.2","0.18902854","0","2"],["104302.7","0.09594954","0","2"],["104302","0.09589011","0","1"],["104301.5","0.41413107","0","3"],["104301","0.16078375","0","1"],["104300.7","0.14566977","0","1"],["104299.2","0.15579861","0","4"],["104296.9","0.22996035","0","1"],["104296.4","0.16463957","0","1"],["104295.5","0","0","0"],["104295.2","0.00479206","0","1"],["104294.2","0.24551735","0","2"],["104291","0.25498691","0","2"],["104290.2","0.25581039","0","1"],["104283.6","0.13897716","0","1"],["104282.5","0","0","0"],["104273.8","0.00002967","0","1"],["104232.1","0","0","0"],["104232","0","0","0"],["104231.8","0","0","0"],["104231.7","0","0","0"]],"ts":"1747170722301","checksum":-1785866980,"seqId":54226506041,"prevSeqId":54226505871}]}
{"arg":{"channel":"books","instId":"BTC-USDT"},"action":"update","data":[{"asks":[["104316.1","1.97429542","0","22"],["104323","0.09957022","0","1"],["104323.1","0","0","0"],["104323.7","0.09226794","0","1"],["104324.7","0.09468033","0","1"],["104325.2","0.09373849","0","1"],["104328.2","0.16338858","0","1"],["104328.5","0.15581809","0","1"],["104328.7","0.15142177","0","1"],["104329.8","0.81700924","0","2"],["104331.3","0","0","0"],["104331.4","0.14564639","0","1"],["104331.9","0.23736446","0","1"],["104333","0.1409759","0","2"],["104333.6","0.35945171","0","3"],["104333.7","0.24390536","0","1"],["104334","0.25150405","0","1"],["104337.7","0.25914649","0","1"],["104346","0.00958201","0","1"],["104347","0.002","0","2"],["104348","0.00811203","0","2"],["104366","0.16","0","2"],["104367","0.07999999","0","1"],["104368","0","0","0"],["104369","0.1","0","2"],["104370","0.05028006","0","2"],["104440.6","0.0013452","0","1"],["104451","0.0026904","0","1"],["104475.5","0.00090788","0","1"],["104534.7","0","0","0"],["104535.6","0","0","0"]],"bids":[["104316","0.08422","0","3"],["104313.9","0.00026531","0","1"],["104311.6","0.03131343","0","1"],["104311.5","0.03408833","0","1"],["104310.2","0.03834936","0","1"],["104308.3","0","0","0"],["104304.2","0.18156685","0","2"],["104302.7","0.09965774","0","2"],["104302","0.09223251","0","1"],["104301.5","0.41853139","0","3"],["104301","0.1517317","0","1"],["104300.7","0.14344439","0","1"],["104299.2","0.16979383","0","4"],["104296.9","0.26158339","0","1"],["104296.6","0","0","0"],["104296.4","0.15976359","0","1"],["104294.2","0.24394761","0","2"],["104291","0.25259419","0","2"],["104290.2","0.26069102","0","1"],["104232.2","0","0","0"]],"ts":"1747170722401","checksum":788714682,"seqId":54226506196,"prevSeqId":54226506041}]}
{"arg":{"channel":"books","instId":"BTC-USDT"},"action":"update","data":[{"asks":[["104316.1","1.89925592","0","21"],["104326.5","0.03463399","0","2"],["104328.1","0","0","0"],["104346","0.01158201","0","3"],["104347","0.001","0","1"],["104348","0.00711203","0","1"],["104366","0","0","0"],["104367","0","0","0"],["104368","0.33","0","6"],["104369","0.16499999","0","3"],["104370","0.00028006","0","1"],["104374","0","0","0"],["104375","0","0","0"],["104534.7","0.00094804","0","1"],["104535.6","0.00002193","0","1"],["104535.8","0.77866876","0","1"],["104536.1","0.0152","0","1"]],"bids":[["104316","0.08426793","0","4"]],"ts":"1747170722501","checksum":-164765391,"seqId":54226506250,"prevSeqId":54226506196}]}
{"arg":{"channel":"books","instId":"BTC-USDT"},"action":"update","data":[{"asks":[["104363","1","0","1"],["104443.2","0.0134816","0","2"],["104536.1","0","0","0"]],"bids":[],"ts":"1747170722601","checksum":-164765391,"seqId":54226506258,"prevSeqId":54226506250}]}
{"arg":{"channel":"books","instId":"BTC-USDT"},"action":"update","data":[{"asks":[["104319.9","0","0","0"],["104320.4","0.00479212","0","1"],["104323","0","0","0"],["104323.7","0","0","0"],["104323.8","0.09930846","0","1"],["104324.5","0.09584229","0","1"],["104324.7","0","0","0"],["104325.2","0","0","0"],["104325.5","0.08959969","0","1"],["104326","0.20675189","0","3"],["104326.4","0.00479206","0","1"],["104326.5","0.02984193","0","1"],["104328.2","0","0","0"],["104328.5","0","0","0"],["104328.7","0","0","0"],["104329","0.1622669","0","1"],["104329.3","0.15470428","0","1"],["104329.5","0.1700728","0","2"],["104331.4","0","0","0"],["104331.9","0","0","0"],["104332.3","0.15184317","0","1"],["104332.7","0.22984845","0","1"],["104333.6","0.20711658","0","2"],["104333.7","0","0","0"],["104334","0","0","0"],["104334.5","0.30033485","0","2"],["104334.8","0.25754486","0","1"],["104335.1","0.11501","0","1"],["104337.7","0","0","0"],["104338.5","0.26388901","0","1"],["104344","0.002","0","2"],["104345","0.001","0","1"],["104346","0.00958201","0","1"],["104347","0","0","0"],["104348.5","0.16497374","0","1"],["104349.7","0","0","0"],["104366","0.16","0","2"],["104366.4","0.11498","0","1"],["104367","0.17999999","0","3"],["104368","0.12","0","3"],["104369","0.035","0","1"],["104373.2","0.09581","0","1"],["104381","0","0","0"],["104404.6","0","0","0"],["104412.3","0","0","0"]],"bids":[["104316","0.20376793","0","5"],["104311.6","0.11827112","0","2"],["104305","0.18052564","0","3"],["104304.4","0.11335031","0","1"],["104304.3","0.19246736","0","3"],["104304.2","0","0","0"],["104303.5","0.09556404","0","5"],["104302.8","0.09111294","0","1"],["104302.7","0.00001016","0","1"],["104302","0","0","0"],["104301.8","0.15701736","0","3"],["104301.5","0.3723786","0","3"],["104301","0","0","0"],["104300.7","0","0","0"],["104300","0.2006836","0","42"],["104299.2","0.00003543","0","3"],["104297.7","0.24406385","0","4"],["104297.3","0.15967508","0","2"],["104296.9","0","0","0"],["104296.4","0","0","0"],["104295.2","0","0","0"],["104295","0.26623168","0","1"],["104294.3","0.00479206","0","1"],["104294.2","0.00001937","0","1"],["104291.8","0.26156018","0","1"],["104291","0.2398382","0","2"],["104290.2","0","0","0"],["104289.7","0.18812093","0","2"],["104283.7","0.13897492","0","1"],["104283.6","0","0","0"],["104269.9","0.36916028","0","3"],["104238.6","0.00049446","0","3"],["104232.2","0.00024748","0","1"],["104232.1","0.00083445","0","2"],["104232","0.01056164","0","2"]],"ts":"1747170722701","checksum":1471567221,"seqId":54226506391,"prevSeqId":54226506258}]}
{"arg":{"channel":"books","instId":"BTC-USDT"},"action":"update","data":[{"asks":[["104323.6","0.26966582","0","2"],["104333.6","0.32295186","0","3"],["104365.7","1.35993997","0","1"],["104389.8","0.19159","0","1"],["104397","2.49587416","0","1"],["104534.7","0","0","0"],["104535.6","0","0","0"],["104535.8","0","0","0"]],"bids":[["104305.1","0.21600259","0","1"],["104304.4","0","0","0"],["104301.5","0.46805721","0","4"],["104264.8","1.44024002","0","1"],["104233.5","2.63181458","0","1"],["104232.1","0","0","0"],["104232","0","0","0"]],"ts":"1747170722801","checksum":1673680191,"seqId":54226506401,"prevSeqId":54226506391}]}
{"arg":{"channel":"books","instId":"BTC-USDT"},"action":"update","data":[{"asks":[["104317.9","0","0","0"],["104318","0.44222772","0","2"],["104320","0.08162","0","2"],["104320.1","0.01917064","0","1"],["104320.4","0.00662137","0","2"],["104320.5","0.272","0","3"],["104323.1","0.0919983","0","1"],["104323.6","0.19554434","0","1"],["104323.7","0.10109828","0","1"],["104323.8","0","0","0"],["104324.5","0","0","0"],["104324.7","0.09279243","0","1"],["104325.3","0.12858024","0","2"],["104325.5","0","0","0"],["104326","0.11409956","0","2"],["104328.2","0.14998939","0","1"],["104328.6","0.15724364","0","1"],["104328.7","0.15898036","0","1"],["104329","0","0","0"],["104329.3","0","0","0"],["104329.5","0.000015","0","1"],["104331.5","0.15485981","0","1"],["104332","0.28290803","0","2"],["104332.3","0","0","0"],["104332.7","0","0","0"],["104333.6","0.39209548","0","3"],["104333.7","0.2596055","0","1"],["104334.1","0.25326927","0","2"],["104334.5","0.04","0","1"],["104334.8","0","0","0"],["104337.8","0.27094269","0","2"],["104338.5","0","0","0"],["104366","0.23","0","4"],["104367","0.21499999","0","4"],["104368","0.05","0","1"],["104369","0","0","0"],["104534.7","0.00094804","0","1"],["104535.6","0.00002193","0","1"],["104535.8","0.77866876","0","1"]],"bids":[["104316","0.08426793","0","4"],["104311.6","0.03131343","0","1"],["104306.1","0.19126195","0","2"],["104305.1","0","0","0"],["104305","0.00001","0","1"],["104304.2","0.18107874","0","2"],["104303.5","0.00035761","0","4"],["104302.8","0.09913065","0","1"],["104302.1","0.09548412","0","1"],["104301.8","0.00025607","0","2"],["104301.5","0.42206402","0","3"],["104301.1","0.17047237","0","2"],["104300.7","0.15115151","0","1"],["104300","0.04150745","0","41"],["104299.2","0.15877938","0","4"],["104297.7","0.00110217","0","3"],["104297.3","0.00014981","0","1"],["104297","0.24048166","0","1"],["104296.5","0.15670403","0","2"],["104295","0","0","0"],["104294.2","0.25516239","0","2"],["104291.8","0","0","0"],["104291.1","1.03620403","0","2"],["104291","0.00009588","0","1"],["104290.3","0.24938355","0","2"],["104232.4","0","0","0"],["104232.2","0","0","0"]],"ts":"1747170722901","checksum":1900007689,"seqId":54226506482,"prevSeqId":54226506401}]}
{"arg":{"channel":"books","instId":"BTC-USDT"},"action":"update","data":[{"asks":[["104323.1","0.09704801","0","1"],["104325.3","0.12700369","0","2"],["104328.6","0.16748822","0","1"],["104331.5","0.14575889","0","1"],["104332","0.29294162","0","2"],["104333.6","0.32103237","0","3"],["104334.1","0.24760545","0","2"],["104337.8","0.28233494","0","2"]],"bids":[["104311.6","0.11827112","0","2"],["104302.8","0.09828403","0","1"],["104302.1","0.10106774","0","1"],["104301.5","0.41151526","0","3"],["104301.1","0.16508501","0","2"],["104297","0.26035529","0","1"],["104296.5","0.15127205","0","2"],["104291.1","1.04551809","0","2"],["104290.3","0.23851361","0","2"]],"ts":"1747170723001","checksum":35905734,"seqId":54226506517,"prevSeqId":54226506482}]}
{"arg":{"channel":"books","instId":"BTC-USDT"},"action":"update","data":[{"asks":[["104320.3","0.00479212","0","1"],["104320.4","0.00182925","0","1"],["104323.1","0","0","0"],["104323.2","0.09007454","0","1"],["104323.7","0","0","0"],["104323.8","0.08906585","0","1"],["104324.7","0","0","0"],["104324.8","0.12744961","0","2"],["104325.3","0.08865433","0","1"],["104328.2","0","0","0"],["104328.3","0.16319672","0","1"],["104328.6","0","0","0"],["104328.7","0.1557951","0","1"],["104328.8","0.15479992","0","1"],["104329.5","0.03836436","0","2"],["104331.5","0","0","0"],["104331.6","0.1502967","0","1"],["104332","0.04870594","0","1"],["104332.1","0.25727048","0","1"],["104333.7","0","0","0"],["104333.8","0.27258446","0","1"],["104334.1","0.005","0","1"],["104334.2","0.24452237","0","1"],["104389.4","0.00056666","0","1"],["104389.7","0","0","0"],["104408.3","0.05967","0","2"],["104415.1","0.04789","0","1"],["104442.6","0.00056666","0","1"],["104442.9","0","0","0"],["104533.9","0","0","0"],["104534.7","0","0","0"],["104535.6","0","0","0"],["104535.8","0","0","0"]],"bids":[["104313.4","0.0313129","0","1"],["104311.5","0","0","0"],["104309.6","0","0","0"],["104309.3","0.00056666","0","1"],["104306.1","0.08977588","0","1"],["104304.3","0.37786356","0","5"],["104304.2","0","0","0"],["104302.2","0.09848512","0","2"],["104302.1","0","0","0"],["104301.5","0.20971631","0","2"],["104301.2","0.15218513","0","5"],["104301.1","0.00005572","0","1"],["104300.8","0.15355037","0","1"],["104300.7","0","0","0"],["104299.3","0.16227813","0","1"],["104299.2","0.00003543","0","3"],["104297.1","0.2406199","0","1"],["104297","0","0","0"],["104296.6","0.14631466","0","1"],["104296.5","0.00001917","0","1"],["104294.3","0.26099316","0","2"],["104294.2","0.00001937","0","1"],["104291.2","0.78545693","0","2"],["104291.1","0.77866876","0","1"],["104256.4","0.00001118","0","1"],["104256","0.00058255","0","2"]],"ts":"1747170723101","checksum":1210604347,"seqId":54226506576,"prevSeqId":54226506517}]}
{"arg":{"channel":"books","instId":"BTC-USDT"},"action":"update","data":[{"asks":[["104323.2","0.09729406","0","1"],["104323.8","0.10058839","0","1"],["104324.8","0.12175585","0","2"],["104325.3","0.09941443","0","1"],["104326.4","0","0","0"],["104328.3","0.15934829","0","1"],["104328.7","0.17101938","0","1"],["104328.8","0.16148968","0","1"],["104329","0.00479206","0","1"],["104331.6","0.15597397","0","1"],["104332.1","0.23402609","0","1"],["104333","0.002","0","1"],["104333.5","0.13897396","0","1"],["104333.6","0.20711658","0","2"],["104333.8","0.25055442","0","1"],["104334.2","0.27027281","0","1"],["104335.9","0","0","0"],["104337.8","0.28917476","0","2"]],"bids":[["104304.3","0.38770156","0","5"],["104302.8","0.09364153","0","1"],["104302.2","0.09312264","0","2"],["104301.2","0.15578926","0","5"],["104300.8","0.16059087","0","1"],["104299.3","0.16890032","0","1"],["104297.1","0.23555232","0","1"],["104296.6","0.15721059","0","1"],["104295.2","0.00479206","0","1"],["104294.3","0.25212533","0","1"],["104291.2","0.52269451","0","1"],["104290.3","0.24021233","0","2"],["104285.7","0.15085288","0","40"],["104283.7","0","0","0"]],"ts":"1747170723201","checksum":-268954523,"seqId":54226506698,"prevSeqId":54226506576}]}
{"arg":{"channel":"books","instId":"BTC-USDT"},"action":"update","data":[{"asks":[["104320.3","0.00479209","0","1"],["104328.2","0.00479206","0","1"],["104329","0","0","0"],["104333","0.14097576","0","2"],["104333.5","0","0","0"],["104333.6","0.39845084","0","3"],["104386.1","6.11358834","0","2"],["104393.1","0.00001","0","1"],["104533.9","0.03","0","1"]],"bids":[["104306.1","0.19314359","0","2"],["104301.5","0.41412878","0","3"],["104291.2","0.78805935","0","2"],["104285.7","0.15085264","0","40"]],"ts":"1747170723301","checksum":526168322,"seqId":54226506733,"prevSeqId":54226506698}]}
{"arg":{"channel":"books","instId":"BTC-USDT"},"action":"update","data":[{"asks":[["104333","0.002","0","1"],["104334.4","0.13990296","0","2"],["104365.6","1.08661719","0","1"],["104533.9","0","0","0"]],"bids":[["104316","0.20376793","0","5"],["104286.9","0.13986695","0","5"],["104285.7","0.01187812","0","39"],["104273.8","0","0","0"],["104264.9","0.73863779","0","1"],["104264.6","0","0","0"],["104232.4","0.00045226","0","2"]],"ts":"1747170723401","checksum":-58137868,"seqId":54226506747,"prevSeqId":54226506733}]}
{"arg":{"channel":"books","instId":"BTC-USDT"},"action":"update","data":[{"asks":[["104320.3","0","0","0"],["104320.4","0.00662134","0","2"],["104323.2","0","0","0"],["104323.8","0","0","0"],["104324.8","0.03346622","0","1"],["104325.3","0","0","0"],["104326.5","0.03463399","0","2"],["104328.2","0","0","0"],["104328.3","0","0","0"],["104328.7","0","0","0"],["104328.8","0","0","0"],["104331.6","0","0","0"],["104332.1","0","0","0"],["104333","0.14097447","0","2"],["104333.6","0.35857503","0","3"],["104333.8","0","0","0"],["104334.2","0","0","0"],["104334.4","0.00093","0","1"],["104337.8","0.03045901","0","1"],["104396.3","0.03386594","0","1"],["104533.9","0.03","0","1"],["104534.7","0.00094804","0","1"],["104535.6","0.00002193","0","1"],["104535.8","0.77866876","0","1"],["104536.1","0.0152","0","1"],["104536.2","0.076","0","5"],["104536.3","0.076","0","5"],["104536.4","0.00002296","0","1"],["104537.6","7.78674232","0","1"],["104538.4","0.07298372","0","1"],["104540","0.00330186","0","4"]],"bids":[["104316","0.08746793","0","5"],["104306.1","0.18482006","0","1"],["104304.3","0.19246736","0","3"],["104302.8","0","0","0"],["104302.2","0.00003272","0","1"],["104301.5","0.31427082","0","3"],["104301.2","0.00032901","0","4"],["104300.8","0","0","0"],["104299.3","0","0","0"],["104297.1","0","0","0"],["104296.6","0","0","0"],["104294.3","0","0","0"],["104291.2","0.52269451","0","1"],["104290.3","0.00005072","0","1"],["104286.9","0.00089399","0","4"],["104285.7","0.15085259","0","40"],["104232.2","0.00024748","0","1"],["104232.1","0.00083445","0","2"],["104232","0.01056164","0","2"],["104231.8","0.00364827","0","1"],["104231.7","0.00025117","0","2"],["104231.5","0.00004581","0","2"]],"ts":"1747170723501","checksum":-2016626439,"seqId":54226506873,"prevSeqId":54226506747}]}
{"arg":{"channel":"books","instId":"BTC-USDT"},"action":"update","data":[{"asks":[["104319.9","0.00479211","0","1"],["104320.4","0.00182925","0","1"],["104323.1","0.09670126","0","1"],["104323.7","0.09887423","0","1"],["104324.7","0.09116907","0","1"],["104325.3","0.09058766","0","1"],["104326.5","0.02984193","0","1"],["104328.1","0.00479206","0","1"],["104328.2","0.15612281","0","1"],["104328.6","0.15135104","0","1"],["104328.7","0.15143118","0","1"],["104331.5","0.16087238","0","1"],["104332","0.30465146","0","2"],["104333","0.002","0","1"],["104333.6","0.38729103","0","3"],["104333.7","0.26202418","0","1"],["104334.1","0.25145899","0","2"],["104334.4","0.13990304","0","2"],["104337.8","0.26431946","0","2"],["104533.9","0","0","0"],["104534.7","0","0","0"],["104535.6","0","0","0"],["104535.8","0","0","0"],["104536.1","0","0","0"],["104536.2","0","0","0"],["104536.3","0","0","0"],["104536.4","0","0","0"],["104537.6","0","0","0"],["104538.4","0","0","0"],["104540","0","0","0"]],"bids":[["104316","0.08426793","0","4"],["104313.4","0","0","0"],["104309.9","0.00001","0","1"],["104309.6","0.03408896","0","1"],["104306.6","0.03134857","0","3"],["104306.1","0.18828983","0","2"],["104304.2","0.18369417","0","2"],["104302.8","0.0906385","0","1"],["104302.1","0.09145379","0","1"],["104301.5","0.4116015","0","3"],["104301.1","0.16943614","0","2"],["104300.7","0.16301737","0","1"],["104299.2","0.15059365","0","4"],["104297","0.23790197","0","1"],["104296.5","0.14845126","0","2"],["104294.2","0.24367454","0","2"],["104291.1","1.02288238","0","2"],["104290.3","0.24394572","0","2"],["104286.9","0.13986703","0","5"],["104285.7","0.01187812","0","39"],["104232.2","0","0","0"],["104232.1","0","0","0"],["104232","0","0","0"],["104231.8","0","0","0"],["104231.7","0","0","0"],["104231.5","0","0","0"]],"ts":"1747170723601","checksum":1319192229,"seqId":54226506983,"prevSeqId":54226506873}]}
{"arg":{"channel":"books","instId":"BTC-USDT"},"action":"update","data":[{"asks":[["104333","0.14097452","0","2"],["104334.4","0.00093","0","1"]],"bids":[["104316","0.08173793","0","3"],["104286.9","0.00089399","0","4"],["104283.6","0.13897492","0","1"],["104273.8","0.00002967","0","1"],["104232.5","0","0","0"],["104232.4","0","0","0"]],"ts":"1747170723701","checksum":-2143448907,"seqId":54226506992,"prevSeqId":54226506983}]}
{"arg":{"channel":"books","instId":"BTC-USDT"},"action":"update","data":[{"asks":[],"bids":[["104310.8","0.02976451","0","1"],["104232.7","0","0","0"]],"ts":"1747170723801","checksum":-1149217184,"seqId":54226506995,"prevSeqId":54226506992}]}
{"arg":{"channel":"books","instId":"BTC-USDT"},"action":"update","data":[{"asks":[["104350.6","0","0","0"],["104363.8","0.02265242","0","1"]],"bids":[],"ts":"1747170724001","checksum":-1149217184,"seqId":54226507000,"prevSeqId":54226506995}]}
{"arg":{"channel":"books","instId":"BTC-USDT"},"action":"update","data":[{"asks":[["104316.1","1.89898559","0","21"],["104320.4","0","0","0"],["104323.1","0","0","0"],["104323.5","0.00182925","0","1"],["104323.7","0","0","0"],["104323.8","0.09475068","0","1"],["104324.5","0.10164574","0","1"],["104324.7","0","0","0"],["104325.3","0","0","0"],["104325.5","0.09157914","0","1"],["104326","0.20498774","0","3"],["104328.1","0","0","0"],["104328.2","0","0","0"],["104328.6","0","0","0"],["104328.7","0","0","0"],["104329","0.15559899","0","2"],["104329.3","0.16577273","0","1"],["104329.5","0.20808805","0","3"],["104331.5","0","0","0"],["104332","0.04870594","0","1"],["104332.3","0.14864001","0","1"],["104332.7","0.23147071","0","1"],["104333.6","0.20711658","0","2"],["104333.7","0","0","0"],["104334.1","0.005","0","1"],["104334.5","0.27726257","0","2"],["104334.8","0.23928201","0","1"],["104337.8","0.03045901","0","1"],["104338.5","0.26493701","0","1"],["104389","0.00056666","0","1"],["104389.4","0","0","0"],["104442.3","0.00056666","0","1"],["104442.6","0","0","0"],["104533.9","0.03","0","1"]],"bids":[["104316","0.20123793","0","4"],["104309.3","0","0","0"],["104309","0.00056666","0","1"],["104306.1","0.08977588","0","1"],["104305","0.18844763","0","3"],["104304.2","0","0","0"],["104303.5","0.0941351","0","5"],["104302.8","0.09571939","0","1"],["104302.1","0","0","0"],["104301.8","0.157227","0","3"],["104301.5","0.37059146","0","3"],["104301.1","0.00005572","0","1"],["104300.7","0","0","0"],["104300","0.19966803","0","42"],["104299.2","0.00003543","0","3"],["104297.7","0.23855201","0","4"],["104297.6","0.03480382","0","3"],["104297.3","0.15341045","0","2"],["104297","0","0","0"],["104296.5","0.00001917","0","1"],["104295.2","0","0","0"],["104295","0.25566871","0","1"],["104294.2","0.00001937","0","1"],["104291.8","0.27030583","0","1"],["104291.1","0.77866876","0","1"],["104291","0.25579955","0","2"],["104290.3","0.00005072","0","1"],["104283.6","0.13897573","0","1"],["104256","0.00001589","0","1"],["104255.7","0.00124283","0","5"],["104232.7","0.0000103","0","1"],["104232.5","0.00954475","0","1"],["104232.4","0.00045226","0","2"]],"ts":"1747170724101","checksum":-197838136,"seqId":54226507089,"prevSeqId":54226507000}]}
{"arg":{"channel":"books","instId":"BTC-USDT"},"action":"update","data":[{"asks":[["104318.2","0.29693486","0","2"],["104319.9","0","0","0"],["104320.4","0.0047921","0","1"],["104320.6","0","0","0"],["104323.8","0","0","0"],["104323.9","0.09791803","0","2"],["104328.9","0.00479206","0","1"],["104329","0.15080693","0","1"],["104329.3","0","0","0"],["104329.4","0.1494509","0","1"],["104330.7","0.005","0","1"],["104332.3","0.15322906","0","1"],["104332.7","0","0","0"],["104332.8","0.24516235","0","1"],["104333.1","0.0665","0","2"],["104333.6","0.30755132","0","3"],["104334.8","0","0","0"],["104334.9","0.25316635","0","1"],["104424.8","0.00001","0","1"],["104443.2","0.00001","0","1"],["104520.5","0","0","0"],["104534.7","0.00094804","0","1"]],"bids":[["104316","0.20653793","0","6"],["104313.8","0.00519173","0","2"],["104306.1","0.2336952","0","2"],["104305.8","0.005","0","1"],["104302.9","0.09965475","0","2"],["104302.8","0","0","0"],["104301.9","0.17146237","0","2"],["104301.8","0.00025607","0","2"],["104301.5","0.47778856","0","4"],["104301.3","0.005","0","1"],["104297.8","0.22815905","0","1"],["104297.7","0.00110217","0","3"],["104297.6","0.03001176","0","2"],["104297.3","0.15399047","0","2"],["104296.9","0.00479206","0","1"],["104293.3","0.005","0","1"],["104291.9","0.28958648","0","3"],["104291.8","0","0","0"],["104232.4","0","0","0"]],"ts":"1747170724201","checksum":256650800,"seqId":54226507152,"prevSeqId":54226507089}]}
{"arg":{"channel":"books","instId":"BTC-USDT"},"action":"update","data":[{"asks":[["104320.4","0","0","0"],["104321.5","0.00479209","0","1"],["104323.9","0.09604522","0","2"],["104324.5","0.09677602","0","1"],["104325.5","0.08655404","0","1"],["104326","0.2132087","0","3"],["104328.9","0","0","0"],["104329","0.16507673","0","2"],["104329.4","0.15188086","0","1"],["104329.5","0.20207659","0","3"],["104332.3","0.16368281","0","1"],["104332.8","0.26105085","0","1"],["104333","0.14097454","0","2"],["104333.6","0.30980225","0","3"],["104334.5","0.2792741","0","2"],["104334.9","0.24477358","0","1"],["104338.5","0.23473039","0","1"],["104418.7","0.01347308","0","1"],["104418.8","0.00095768","0","1"],["104496","0.06123222","0","3"],["104534.7","0","0","0"]],"bids":[["104316","0.20333793","0","5"],["104306.1","0.24278076","0","2"],["104305","0.18664414","0","3"],["104303.5","0.09951712","0","5"],["104302.9","0.09953124","0","2"],["104301.9","0.15938189","0","2"],["104301.5","0.46276354","0","4"],["104300","0.19086501","0","42"],["104297.8","0.25540957","0","1"],["104297.3","0.1503418","0","2"],["104296.9","0","0","0"],["104295.2","0.00479206","0","1"],["104295","0.25168668","0","1"],["104291.9","0.27985675","0","3"],["104291","0.26402157","0","2"],["104285.7","0.15085266","0","40"],["104283.6","0","0","0"],["104232.4","0.00045226","0","2"]],"ts":"1747170724301","checksum":444831753,"seqId":54226507300,"prevSeqId":54226507152}]}
{"arg":{"channel":"books","instId":"BTC-USDT"},"action":"update","data":[{"asks":[["104323.9","0.08998816","0","2"],["104324.5","0.09053951","0","1"],["104325.5","0.09624138","0","1"],["104326","0.11409956","0","2"],["104326.1","0.09476298","0","1"],["104329","0.15112458","0","2"],["104329.4","0.16887894","0","1"],["104329.5","0.19712302","0","3"],["104332.3","0.16435884","0","1"],["104332.8","0.23835654","0","1"],["104333","0.002","0","1"],["104334.4","0.13990345","0","2"],["104334.5","0.28191347","0","2"],["104334.9","0.27055825","0","1"],["104338.5","0","0","0"],["104338.6","0.24601837","0","1"],["104361.7","0.58099121","0","1"],["104423","0.01063474","0","2"],["104423.5","0","0","0"],["104533.9","0","0","0"]],"bids":[["104313.2","0.03061087","0","1"],["104309.6","0","0","0"],["104306.1","0.20563526","0","2"],["104305","0.18240085","0","3"],["104303.6","0.09425834","0","1"],["104303.5","0.00035761","0","4"],["104302.9","0.10195598","0","2"],["104301.9","0.15068638","0","2"],["104301.5","0.46223152","0","4"],["104300","0.19967645","0","42"],["104297.8","0.25146763","0","1"],["104297.3","0.16290011","0","2"],["104295","0.25673098","0","1"],["104291.9","0.30216002","0","3"],["104291.1","1.02131567","0","2"],["104291","0.00009588","0","1"],["104286.5","0.13907716","0","2"],["104285.7","0.01187812","0","39"],["104270","0.44795994","0","4"],["104232.4","0","0","0"]],"ts":"1747170724401","checksum":-177439947,"seqId":54226507432,"prevSeqId":54226507300}]}
{"arg":{"channel":"books","instId":"BTC-USDT"},"action":"update","data":[{"asks":[],"bids":[["104262","0.48324487","0","1"],["104254","0.00011827","0","2"],["104232.5","0","0","0"]],"ts":"1747170724501","checksum":-177439947,"seqId":54226507436,"prevSeqId":54226507432}]}
{"arg":{"channel":"books","instId":"BTC-USDT"},"action":"update","data":[{"asks":[["104316.1","1.52423559","0","18"],["104320.5","0.038","0","2"],["104323.9","0.00045","0","1"],["104324.4","0.12399182","0","2"],["104324.5","0","0","0"],["104325.1","0.09964956","0","1"],["104325.5","0","0","0"],["104326.1","0.0875414","0","1"],["104326.6","0.12506921","0","2"],["104329","0.00479206","0","1"],["104329.4","0","0","0"],["104329.5","0.03836436","0","2"],["104329.6","0.16346184","0","2"],["104329.9","0.5207251","0","2"],["104330.1","0.16950612","0","1"],["104332.3","0","0","0"],["104332.8","0.16369977","0","1"],["104333.3","0.25911135","0","1"],["104333.6","0.35917227","0","3"],["104334.3","0.13897277","0","1"],["104334.4","0.00093","0","1"],["104334.5","0.04","0","1"],["104334.9","0","0","0"],["104335.1","0.35927817","0","2"],["104335.4","0.2653735","0","1"],["104338.6","0","0","0"],["104339.1","0.25800086","0","1"],["104396.3","0","0","0"],["104423","0.01054345","0","1"],["104533.9","0.03","0","1"]],"bids":[["104316","0.56283431","0","10"],["104306.1","0.28006631","0","2"],["104305.6","0.19568227","0","3"],["104305","0.00001","0","1"],["104304.1","0.09262903","0","2"],["104303.6","0","0","0"],["104303.4","0.09718883","0","1"],["104302.9","0.00001032","0","1"],["104302.4","0.1661068","0","1"],["104302.1","0.14513264","0","1"],["104301.9","0.00120818","0","1"],["104301.5","0.31985782","0","3"],["104300.6","0.15033679","0","1"],["104300","0.04150745","0","41"],["104298.3","0.25727428","0","1"],["104297.8","0.15086675","0","1"],["104297.3","0.00014981","0","1"],["104295.7","0.00484383","0","2"],["104295.6","0.24652405","0","1"],["104295.2","0","0","0"],["104295","0","0","0"],["104292.4","0.2456742","0","1"],["104291.9","0.03308723","0","2"],["104291.6","0.26393567","0","3"],["104291.1","0.77866876","0","1"],["104286.9","0.13986549","0","5"],["104286.5","0.00010371","0","1"],["104280.4","0.36908178","0","1"],["104233.5","0","0","0"],["104233.3","0","0","0"],["104233","0","0","0"],["104232.9","0","0","0"],["104232.7","0","0","0"]],"ts":"1747170724601","checksum":1888888570,"seqId":54226507532,"prevSeqId":54226507436}]}
{"arg":{"channel":"books","instId":"BTC-USDT"},"action":"update","data":[{"asks":[],"bids":[["104316","0.56284431","0","11"]],"ts":"1747170724701","checksum":1680340118,"seqId":54226507535,"prevSeqId":54226507532}]}
{"arg":{"channel":"books","instId":"BTC-USDT"},"action":"update","data":[{"asks":[["104321.5","0","0","0"],["104321.9","0.00479207","0","1"]],"bids":[["104306.1","0.49312249","0","1"],["104302.5","0.77866876","0","1"],["104270.1","0","0","0"],["104250.9","0.45534757","0","1"],["104233.6","0","0","0"]],"ts":"1747170724801","checksum":1100997255,"seqId":54226507547,"prevSeqId":54226507535}]}
{"arg":{"channel":"books","instId":"BTC-USDT"},"action":"update","data":[{"asks":[["104333.5","0.13897393","0","1"],["104334.3","0","0","0"]],"bids":[["104286.9","0.00089399","0","4"],["104285.7","0.15085205","0","40"]],"ts":"1747170724901","checksum":1100997255,"seqId":54226507556,"prevSeqId":54226507547}]}
{"arg":{"channel":"books","instId":"BTC-USDT"},"action":"update","data":[{"asks":[["104316.1","1.15486089","0","15"],["104321.9","0","0","0"],["104322.6","0.00479207","0","1"],["104331","0","0","0"],["104333.5","0","0","0"],["104335.3","0.13897172","0","1"],["104367.8","0.77866876","0","1"],["104386.1","0.234","0","1"],["104426.7","5.92559035","0","1"]],"bids":[["104316","1.04084431","0","14"],["104314.5","0.03834936","0","1"],["104310.2","0","0","0"],["104296.9","0.00479206","0","1"],["104295.7","0.00005177","0","1"],["104286.9","0.13986719","0","5"],["104285.7","0.01187812","0","39"],["104233.7","0","0","0"]],"ts":"1747170725001","checksum":-789795787,"seqId":54226507581,"prevSeqId":54226507556}]}
{"arg":{"channel":"books","instId":"BTC-USDT"},"action":"update","data":[{"asks":[["104316.1","0.42835176","0","9"],["104318","0","0","0"],["104318.1","0","0","0"],["104318.2","0.005","0","1"],["104320","0.00002","0","1"],["104320.1","0","0","0"],["104320.5","0.002","0","1"],["104322","0","0","0"],["104322.6","0","0","0"],["104322.7","0","0","0"],["104323.5","0","0","0"],["104323.6","0","0","0"],["104323.9","0.00227925","0","2"],["104324.8","0","0","0"],["104325.6","0.01916962","0","1"],["104325.9","0","0","0"],["104326.6","0.09677642","0","1"],["104329","0.00479199","0","1"],["104329.5","0.000015","0","1"],["104329.7","0.21242163","0","2"],["104329.8","0.03834048","0","1"],["104329.9","0.15164332","0","1"],["104332","0","0","0"],["104333","0.02806896","0","2"],["104334.3","0.00479206","0","1"],["104335.3","0","0","0"],["104337.1","0.234","0","1"],["104337.8","0","0","0"],["104339.3","0.04557317","0","1"],["104340.3","0.13896483","0","1"],["104340.4","0","0","0"],["104344","0","0","0"],["104345","0","0","0"],["104349","0.002","0","2"],["104350","0.00417006","0","4"],["104352.8","0.11907186","0","2"],["104363.8","0","0","0"],["104366","0","0","0"],["104367","0","0","0"],["104367.8","0.77879906","0","2"],["104368","0","0","0"],["104369.6","0","0","0"],["104371","0.33","0","6"],["104372","0.16499999","0","3"],["104378.5","0.02265242","0","1"],["104388.6","0.00056666","0","1"],["104389","0","0","0"],["104426.6","0.15173659","0","1"],["104426.7","0","0","0"],["104441.9","0.00056666","0","1"],["104442.3","0","0","0"],["104443.6","5.93836624","0","1"],["104534.7","0.00094804","0","1"],["104535.6","0.00002193","0","1"],["104535.8","0.77866876","0","1"],["104536.1","0.0152","0","1"],["104536.2","0.076","0","5"],["104536.3","0.076","0","5"],["104536.4","0.00002296","0","1"],["104537.6","7.78674232","0","1"],["104538.4","0.07298372","0","1"],["104538.5","0.234","0","1"],["104540","0.00330186","0","4"]],"bids":[["104315.2","0.0306103","0","1"],["104314.1","0.06134738","0","1"],["104312.1","0.01916962","0","1"],["104309","0","0","0"],["104308.6","0.00056666","0","1"],["104302.6","0.00484264","0","6"],["104301.8","0.07323979","0","3"],["104301.5","0.26986771","0","2"],["104296.9","0","0","0"],["104295.4","0.35722204","0","2"],["104293.2","0.17396483","0","3"],["104291.3","0.36908178","0","1"],["104286.9","0.00089399","0","4"],["104277.2","0.00288734","0","2"],["104274.9","0.00711203","0","1"],["104255.7","0.00067617","0","4"],["104255.3","0.00056666","0","1"],["104240.1","0.0190931","0","2"],["104234.6","0","0","0"],["104234.5","0","0","0"],["104234.4","0","0","0"],["104234.3","0","0","0"],["104234","0","0","0"]],"ts":"1747170725101","checksum":251101917,"seqId":54226507790,"prevSeqId":54226507581}]}
{"arg":{"channel":"books","instId":"BTC-USDT"},"action":"update","data":[{"asks":[["104316.1","0.42155176","0","9"],["104324.3","0.18411423","0","1"],["104330.7","0.03581577","0","2"],["104332.7","0.00479206","0","1"],["104334.3","0","0","0"],["104334.8","0.02606849","0","1"],["104337.1","0.27234936","0","2"],["104338.9","0.13896748","0","1"],["104340.3","0","0","0"],["104343.3","0.77866876","0","1"],["104346.2","0","0","0"],["104367.8","0.77866876","0","1"],["104538.5","0","0","0"],["104540","0","0","0"]],"bids":[["104303.6","0.012","0","1"],["104302.6","0.00005058","0","5"],["104300.7","0.00479206","0","1"],["104293.2","0.035","0","2"],["104291.3","0","0","0"],["104291.2","0.66166199","0","2"],["104289.7","0.1780651","0","1"],["104248.3","0.01107914","0","4"],["104245.6","0.01099563","0","1"],["104243.9","0.01177786","0","3"],["104241.7","0.01099563","0","1"],["104237.9","0.02199126","0","2"],["104235.1","0","0","0"],["104235","0","0","0"],["104234.9","0","0","0"],["104234.8","0","0","0"]],"ts":"1747170725201","checksum":-973004355,"seqId":54226507849,"prevSeqId":54226507790}]}
{"arg":{"channel":"books","instId":"BTC-USDT"},"action":"update","data":[{"asks":[["104316.1","0.53785176","0","9"],["104321.8","0","0","0"],["104322","0.0816","0","1"],["104324.1","0.31348067","0","1"],["104324.2","0.19242972","0","1"],["104324.3","0","0","0"],["104325.3","0.00479173","0","1"],["104329","0.03081627","0","1"],["104330.3","0","0","0"],["104333","0.002","0","1"],["104339","0.29921892","0","1"],["104347","0.002","0","2"],["104348","0.00811203","0","2"],["104349","0","0","0"],["104350","0.00317006","0","3"],["104369","0.16","0","2"],["104370","0.18028005","0","4"],["104371","0.12","0","3"],["104372","0.035","0","1"],["104475.5","0","0","0"],["104538.4","0","0","0"]],"bids":[["104316","0.88330095","0","15"],["104300.7","0","0","0"],["104298.5","0.00479206","0","1"]],"ts":"1747170725301","checksum":-2049754565,"seqId":54226507917,"prevSeqId":54226507849}]}
{"arg":{"channel":"books","instId":"BTC-USDT"},"action":"update","data":[{"asks":[["104319.4","0.071884","0","1"],["104326.6","0.33077642","0","2"],["104329.7","0.40076845","0","3"],["104331.7","0.09795","0","1"],["104332.6","0.36908178","0","1"],["104332.7","0.78346082","0","2"],["104346","0.01158201","0","3"],["104347","0.001","0","1"],["104348","0.00711203","0","1"],["104353.7","0.56120425","0","1"],["104354.5","0","0","0"],["104367.8","0.77879906","0","2"],["104368","0.16","0","2"],["104369","0.24999999","0","5"],["104370","0.08528006","0","3"],["104371","0","0","0"],["104372","0","0","0"],["104406.4","5.93836624","0","1"],["104443.6","0","0","0"],["104536.4","0","0","0"],["104537.6","0","0","0"]],"bids":[["104316","0.8832896","0","15"]],"ts":"1747170725401","checksum":1731955155,"seqId":54226507952,"prevSeqId":54226507917}]}
{"arg":{"channel":"books","instId":"BTC-USDT"},"action":"update","data":[{"asks":[["104337.8","0.13896858","0","1"],["104338.9","0","0","0"],["104368","0.23","0","4"],["104369","0.21499999","0","4"],["104370","0.05028006","0","2"],["104396.3","5.85957946","0","1"],["104406.4","0","0","0"]],"bids":[["104291.2","0.52269451","0","1"],["104289.8","0.13896858","0","1"],["104235.4","0","0","0"]],"ts":"1747170725501","checksum":1731955155,"seqId":54226507964,"prevSeqId":54226507952}]}
{"arg":{"channel":"books","instId":"BTC-USDT"},"action":"update","data":[{"asks":[["104327.3","0.03081678","0","1"],["104330","0.08669212","0","4"],["104330.7","0.005","0","1"],["104332.7","0.77866876","0","1"],["104377.5","0.02230591","0","1"],["104423.5","0.00009742","0","1"],["104536.1","0","0","0"],["104536.2","0","0","0"],["104536.3","0","0","0"]],"bids":[["104316","0.6492896","0","14"],["104306.1","0.26229635","0","1"],["104304.3","0.00003764","0","2"],["104302.5","0","0","0"],["104280.4","0","0","0"],["104235.4","0.00005065","0","1"],["104235.1","0.32484","0","1"]],"ts":"1747170725601","checksum":-1508056821,"seqId":54226507978,"prevSeqId":54226507964}]}
{"arg":{"channel":"books","instId":"BTC-USDT"},"action":"update","data":[{"asks":[["104320","0.08162","0","2"],["104324.3","0.00479177","0","1"],["104325.1","0.17263328","0","2"],["104325.3","0","0","0"],["104328.9","0.00479206","0","1"],["104330","0.08190006","0","3"],["104336.4","0.13897127","0","1"],["104337.8","0","0","0"],["104535.8","0","0","0"]],"bids":[["104316","0.6493796","0","15"],["104298.5","0","0","0"],["104296.9","0.00479206","0","1"],["104289.8","0","0","0"],["104286.9","0.13986526","0","5"],["104235","0.00086255","0","2"]],"ts":"1747170725701","checksum":725399315,"seqId":54226507991,"prevSeqId":54226507978}]}
{"arg":{"channel":"books","instId":"BTC-USDT"},"action":"update","data":[{"asks":[["104319.3","0.24","0","1"],["104475.5","0.00090665","0","1"],["104534.7","0","0","0"],["104535.6","0","0","0"]],"bids":[["104315.2","0","0","0"],["104303.2","0.05688421","0","1"]],"ts":"1747170725801","checksum":-1392796686,"seqId":54226507997,"prevSeqId":54226507991}]}
{"arg":{"channel":"books","instId":"BTC-USDT"},"action":"update","data":[{"asks":[["104346","0.00958201","0","1"],["104347","0.002","0","2"],["104348","0.00811203","0","2"],["104368","0","0","0"],["104369","0.22999999","0","4"],["104370","0.21528005","0","5"],["104371","0.05","0","1"]],"bids":[],"ts":"1747170725901","checksum":-1392796686,"seqId":54226508014,"prevSeqId":54226507997}]}
{"arg":{"channel":"books","instId":"BTC-USDT"},"action":"update","data":[{"asks":[["104328.9","0","0","0"],["104330.6","0.00479206","0","1"]],"bids":[["104306.1","0.53790411","0","2"],["104303.6","0.20442972","0","2"],["104302.5","0.77866876","0","1"],["104298.5","0.00479206","0","1"],["104296.9","0","0","0"],["104277.2","0.00001034","0","1"],["104248.9","0.00305176","0","2"],["104235","0","0","0"]],"ts":"1747170726001","checksum":-1361657170,"seqId":54226508025,"prevSeqId":54226508014}]}
{"arg":{"channel":"books","instId":"BTC-USDT"},"action":"update","data":[{"asks":[["104319.3","0","0","0"],["104324.3","0.00479192","0","1"],["104336.4","0.13897132","0","1"],["104388.3","0.00056666","0","1"],["104388.6","0","0","0"],["104441.5","0.00056666","0","1"],["104441.9","0","0","0"],["104534.7","0.00094804","0","1"]],"bids":[["104308.6","0","0","0"],["104308.2","0.00106666","0","2"],["104255.3","0","0","0"],["104255","0.00057782","0","2"],["104235","0.00086255","0","2"],["104234.9","0.00024984","0","5"]],"ts":"1747170726101","checksum":2029061174,"seqId":54226508053,"prevSeqId":54226508025}]}
{"arg":{"channel":"books","instId":"BTC-USDT"},"action":"update","data":[{"asks":[["104324.3","0","0","0"],["104325","0.00479192","0","1"],["104336.4","0.13897099","0","1"]],"bids":[["104314.5","0","0","0"],["104288.6","0.13908126","0","3"],["104286.9","0.00089399","0","4"],["104234.8","0.00061782","0","1"]],"ts":"1747170726201","checksum":-1815518225,"seqId":54226508074,"prevSeqId":54226508053}]}
{"arg":{"channel":"books","instId":"BTC-USDT"},"action":"update","data":[{"asks":[["104330.6","0","0","0"],["104332.9","0.00484206","0","2"],["104535.6","0.00002193","0","1"]],"bids":[["104316","0.68772896","0","16"],["104301.4","0.00876613","0","4"],["104298.5","0","0","0"],["104289","0.13897005","0","1"],["104288.6","0.00011027","0","2"],["104273.8","0","0","0"],["104234.6","0.00199229","0","3"]],"ts":"1747170726301","checksum":-267431568,"seqId":54226508090,"prevSeqId":54226508074}]}
{"arg":{"channel":"books","instId":"BTC-USDT"},"action":"update","data":[{"asks":[["104324.3","0.00479192","0","1"],["104325","0","0","0"],["104336.4","0.13897103","0","1"],["104348.5","0.30777228","0","2"],["104426.6","0","0","0"],["104535.8","0.77866876","0","1"]],"bids":[["104289","0","0","0"],["104287","0.13897112","0","1"]],"ts":"1747170726401","checksum":2054874371,"seqId":54226508137,"prevSeqId":54226508090}]}
{"arg":{"channel":"books","instId":"BTC-USDT"},"action":"update","data":[{"asks":[["104330.6","0.00479206","0","1"],["104332.9","0.00005","0","1"],["104535.8","0","0","0"]],"bids":[["104301.4","0.00397407","0","3"],["104298.5","0.00479206","0","1"],["104234.6","0","0","0"]],"ts":"1747170726501","checksum":2054874371,"seqId":54226508149,"prevSeqId":54226508137}]}
{"arg":{"channel":"books","instId":"BTC-USDT"},"action":"update","data":[{"asks":[["104330","0.08669212","0","4"],["104330.6","0","0","0"],["104334.4","0.13990264","0","2"],["104336.4","0","0","0"],["104372","0.14871187","0","1"],["104391.1","0","0","0"],["104535.8","0.77866876","0","1"],["104536.1","0.0152","0","1"]],"bids":[["104287","0","0","0"],["104286.9","0.13986663","0","5"],["104234.6","0.00199229","0","3"]],"ts":"1747170726601","checksum":2054874371,"seqId":54226508157,"prevSeqId":54226508149}]}
{"arg":{"channel":"books","instId":"BTC-USDT"},"action":"update","data":[{"asks":[["104325.6","0.0471349","0","2"],["104329.7","0.40556051","0","4"],["104330","0.08190006","0","3"],["104339.3","0","0","0"],["104346","0.01158201","0","3"],["104347","0.001","0","1"],["104348","0.00711203","0","1"],["104368","0.23","0","4"],["104369","0.21499999","0","4"],["104370","0.05028006","0","2"],["104371","0","0","0"],["104536.2","0.076","0","5"]],"bids":[["104316","0.6493796","0","15"],["104298.5","0","0","0"],["104297.9","0.00505465","0","2"],["104273.8","0.00002967","0","1"],["104244.3","0.03","0","1"],["104234.6","0","0","0"]],"ts":"1747170726701","checksum":-347952218,"seqId":54226508185,"prevSeqId":54226508157}]}
{"arg":{"channel":"books","instId":"BTC-USDT"},"action":"update","data":[{"asks":[["104319.3","0.24","0","1"],["104329.7","0.40076845","0","3"],["104330.6","0.00479206","0","1"],["104371.4","0.14871187","0","1"],["104372","0","0","0"],["104536.1","0","0","0"],["104536.2","0","0","0"]],"bids":[["104316","0.6503796","0","16"],["104298.5","0.00479206","0","1"],["104297.9","0.00026259","0","1"],["104234.8","0","0","0"]],"ts":"1747170726801","checksum":498658629,"seqId":54226508197,"prevSeqId":54226508185}]}
{"arg":{"channel":"books","instId":"BTC-USDT"},"action":"update","data":[{"asks":[["104330.6","0","0","0"],["104332.5","0.00479206","0","1"],["104334.4","0.00093","0","1"],["104334.7","0.13897218","0","1"],["104535.8","0","0","0"]],"bids":[["104316","0.68872896","0","17"],["104300.7","0.00479206","0","1"],["104298.5","0","0","0"],["104286.9","0.13986617","0","5"]],"ts":"1747170726901","checksum":-1607311411,"seqId":54226508212,"prevSeqId":54226508197}]}
{"arg":{"channel":"books","instId":"BTC-USDT"},"action":"update","data":[{"asks":[["104319.3","0","0","0"],["104367.8","0.77866876","0","1"],["104535.8","0.77866876","0","1"]],"bids":[["104275.5","0.18054719","0","3"],["104258.2","0.09003891","0","2"],["104243","0","0","0"],["104234.8","0.00061782","0","1"]],"ts":"1747170727001","checksum":-1562716572,"seqId":54226508221,"prevSeqId":54226508212}]}
{"arg":{"channel":"books","instId":"BTC-USDT"},"action":"update","data":[{"asks":[["104334.7","0","0","0"],["104335.3","0.13897144","0","1"],["104387.9","0.00056666","0","1"],["104388.3","0","0","0"],["104441.1","0.12056666","0","2"],["104441.5","0","0","0"],["104536.1","0.0152","0","1"]],"bids":[["104308.2","0.0005","0","1"],["104307.8","0.00056666","0","1"],["104255","0.00001116","0","1"],["104254.6","0.00405923","0","8"],["104234.8","0","0","0"]],"ts":"1747170727101","checksum":1399038950,"seqId":54226508233,"prevSeqId":54226508221}]}
{"arg":{"channel":"books","instId":"BTC-USDT"},"action":"update","data":[{"asks":[["104316.1","0.54935676","0","10"],["104324.1","0.31827261","0","2"],["104324.3","0","0","0"],["104536.2","0.076","0","5"]],"bids":[],"ts":"1747170727201","checksum":1393364018,"seqId":54226508242,"prevSeqId":54226508233}]}
{"arg":{"channel":"books","instId":"BTC-USDT"},"action":"update","data":[{"asks":[["104324","0.12576295","0","3"],["104324.1","0.31348067","0","1"],["104367.8","0.77879906","0","2"]],"bids":[["104300.7","0","0","0"],["104300.3","0.00479206","0","1"]],"ts":"1747170727301","checksum":1879951856,"seqId":54226508254,"prevSeqId":54226508242}]}
{"arg":{"channel":"books","instId":"BTC-USDT"},"action":"update","data":[{"asks":[["104323.8","0.00479196","0","1"],["104324","0.120971","0","2"],["104346","0.00958201","0","1"],["104347","0.002","0","2"],["104348","0.00811203","0","2"],["104368","0","0","0"],["104369","0.22999999","0","4"],["104370","0.21528005","0","5"],["104371","0.05","0","1"],["104392.9","5.88108482","0","1"],["104396.3","0","0","0"],["104536.2","0","0","0"]],"bids":[],"ts":"1747170727401","checksum":-744402858,"seqId":54226508279,"prevSeqId":54226508254}]}
{"arg":{"channel":"books","instId":"BTC-USDT"},"action":"update","data":[{"asks":[["104323.8","0","0","0"],["104324","0.12576296","0","3"],["104536.2","0.076","0","5"]],"bids":[["104316","0.68772896","0","16"]],"ts":"1747170727501","checksum":-1721362736,"seqId":54226508284,"prevSeqId":54226508279}]}
{"arg":{"channel":"books","instId":"BTC-USDT"},"action":"update","data":[{"asks":[["104316.1","0.53685176","0","9"]],"bids":[],"ts":"1747170727601","checksum":-500472641,"seqId":54226508288,"prevSeqId":54226508284}]}
{"arg":{"channel":"books","instId":"BTC-USDT"},"action":"update","data":[{"asks":[["104316.1","0.92614814","0","11"],["104318","0.0816","0","1"],["104319.3","0.0726342","0","1"],["104323.6","0.02796582","0","1"],["104324.1","0.32086081","0","2"],["104324.4","0.03108988","0","1"],["104324.8","0.09389747","0","1"],["104325.1","0.07298372","0","1"],["104325.8","0.09445665","0","1"],["104326.1","0","0","0"],["104326.3","0.09679698","0","1"],["104326.6","0.234","0","1"],["104327.3","0","0","0"],["104329.3","0.14804756","0","1"],["104329.6","0.16049139","0","2"],["104329.8","0.20110173","0","2"],["104329.9","0","0","0"],["104330.1","0","0","0"],["104331.6","0.00479206","0","1"],["104332.5","0.13897518","0","1"],["104332.6","0.53600688","0","2"],["104332.8","0","0","0"],["104333","0.25711291","0","2"],["104333.3","0","0","0"],["104334.8","0.28741348","0","2"],["104335.1","0.38555087","0","2"],["104335.3","0","0","0"],["104335.4","0","0","0"],["104338.8","0.24718723","0","1"],["104339","0.20814671","0","1"],["104339.1","0","0","0"],["104346","0.01158201","0","3"],["104347","0.001","0","1"],["104348","0.00711203","0","1"],["104368","0.23","0","4"],["104369","0.21499999","0","4"],["104370","0.05028006","0","2"],["104371","0","0","0"]],"bids":[["104316","0.25393258","0","12"],["104314.1","0","0","0"],["104313.2","0","0","0"],["104311.6","0","0","0"],["104309.7","0.02808062","0","1"],["104306.1","0.07310734","0","1"],["104305.6","0.00917734","0","1"],["104305.3","0.18751021","0","3"],["104304.1","0.000048","0","1"],["104303.8","0.09545052","0","1"],["104303.6","0.012","0","1"],["104303.4","0","0","0"],["104303.1","0.09686389","0","2"],["104302.5","0","0","0"],["104302.4","0","0","0"],["104302.1","0.16110004","0","1"],["104301.8","0.23403779","0","4"],["104301.5","0.1597262","0","1"],["104300.6","0","0","0"],["104300.3","0.16124074","0","1"],["104299.7","0.04946032","0","1"],["104298.5","0.00479206","0","1"],["104298.3","0","0","0"],["104298","0.25603576","0","2"],["104297.8","0","0","0"],["104297.6","0.18419615","0","3"],["104295.6","0","0","0"],["104295.4","0.19436833","0","2"],["104292.4","0","0","0"],["104291.6","0.00100678","0","2"],["104291.3","0.23497226","0","1"],["104286.9","0.00089399","0","4"],["104283.6","0.13897518","0","1"],["104234.8","0.00061782","0","1"],["104234.6","0.00199229","0","3"],["104234.5","0.00003076","0","2"],["104234.4","0.77963354","0","2"],["104234.3","0.00028121","0","5"]],"ts":"1747170727801","checksum":710420615,"seqId":54226508409,"prevSeqId":54226508288}]}
{"arg":{"channel":"books","instId":"BTC-USDT"},"action":"update","data":[{"asks":[["104323.5","0.0047921","0","1"],["104324","0.120971","0","2"],["104324.1","0.22926705","0","1"],["104324.4","0.12254664","0","2"],["104324.8","0","0","0"],["104325.1","0.169284","0","2"],["104325.8","0","0","0"],["104326.1","0.09262361","0","1"],["104326.3","0","0","0"],["104326.6","0.32576772","0","2"],["104329.3","0","0","0"],["104329.6","0.15009123","0","2"],["104329.7","0.56288796","0","2"],["104329.8","0.03834048","0","1"],["104329.9","0.16594077","0","1"],["104330.1","0.16699103","0","1"],["104331.6","0","0","0"],["104332.5","0.00479206","0","1"],["104332.6","0.40743114","0","2"],["104332.7","0.91764364","0","2"],["104332.8","0.15725293","0","1"],["104333","0.002","0","1"],["104333.3","0.25421381","0","1"],["104333.6","0.38484878","0","3"],["104334.8","0.02606849","0","1"],["104335.1","0.37706899","0","2"],["104335.4","0.24253431","0","1"],["104337.1","0.234","0","1"],["104338.8","0","0","0"],["104339.1","0.24448245","0","1"],["104369.7","0.11621867","0","1"],["104535.8","0","0","0"],["104536.1","0","0","0"],["104536.2","0","0","0"]],"bids":[["104316","0.52843258","0","14"],["104311.4","0.03430046","0","1"],["104310.1","0.08207777","0","1"],["104306.1","0.25840887","0","2"],["104305.6","0.1994542","0","3"],["104305.3","0.00002638","0","1"],["104304.1","0.09425935","0","2"],["104303.8","0","0","0"],["104303.4","0.09369149","0","1"],["104303.2","0","0","0"],["104303.1","0.00006358","0","1"],["104302.4","0.16333787","0","1"],["104302.1","0.16349978","0","1"],["104301.8","0.07323979","0","3"],["104301.5","0.2883718","0","2"],["104300.6","0.15994535","0","1"],["104300.3","0.00479206","0","1"],["104298.5","0","0","0"],["104298.3","0.24653925","0","1"],["104298","0.00001","0","1"],["104297.8","0.15942114","0","1"],["104297.6","0.03001176","0","2"],["104295.7","0.34159927","0","2"],["104295.6","0.25687552","0","1"],["104295.4","0.00001943","0","1"],["104292.4","0.25678801","0","1"],["104291.6","0.23479326","0","3"],["104291.3","0","0","0"],["104285.7","0.150853","0","40"],["104283.6","0","0","0"],["104234.6","0","0","0"],["104234.5","0","0","0"],["104234.4","0","0","0"],["104234.3","0","0","0"]],"ts":"1747170727901","checksum":988157735,"seqId":54226508513,"prevSeqId":54226508409}]}
{"arg":{"channel":"books","instId":"BTC-USDT"},"action":"update","data":[{"asks":[["104316.8","0.07298372","0","1"],["104323.5","0","0","0"],["104323.6","0","0","0"],["104323.8","0.00479207","0","1"],["104328.9","0.00479206","0","1"],["104332.5","0.13897607","0","1"],["104332.7","0.77866876","0","1"],["104336","0.0444277","0","1"],["104390.1","0","0","0"],["104535.6","0","0","0"]],"bids":[["104316","0.37343258","0","13"],["104314.1","0.057915","0","1"],["104313.1","0.0342999","0","1"],["104309.7","0","0","0"],["104301.8","0.00025607","0","2"],["104300.3","0","0","0"],["104296.9","0.00479206","0","1"],["104285.7","0.01187812","0","39"],["104283.6","0.13897607","0","1"],["104234.9","0","0","0"],["104234.8","0","0","0"]],"ts":"1747170728001","checksum":772345756,"seqId":54226508540,"prevSeqId":54226508513}]}
{"arg":{"channel":"books","instId":"BTC-USDT"},"action":"update","data":[{"asks":[["104320.5","0","0","0"],["104321.5","0.00479209","0","1"],["104323.8","0","0","0"],["104323.9","0.03605248","0","3"],["104324.4","0.03108988","0","1"],["104325.1","0.07298372","0","1"],["104326.1","0","0","0"],["104326.6","0.234","0","1"],["104329.6","0.00479312","0","1"],["104329.8","0","0","0"],["104329.9","0","0","0"],["104330.1","0","0","0"],["104332.5","0.13897514","0","1"],["104332.8","0","0","0"],["104333","0","0","0"],["104333.3","0","0","0"],["104335.1","0.11501","0","1"],["104335.4","0","0","0"],["104336","0.03834041","0","1"],["104339.1","0","0","0"],["104387.7","0.00056666","0","1"],["104387.9","0","0","0"],["104441","0.00306666","0","2"],["104441.1","0.12","0","1"],["104535.6","0.00002193","0","1"],["104535.8","0.77866876","0","1"],["104536.1","0.0152","0","1"],["104536.2","0.076","0","5"],["104536.3","0.076","0","5"],["104536.4","0.00002296","0","1"],["104538.4","0.07298372","0","1"],["104540","0.00330186","0","4"],["104541.2","0.00009506","0","1"],["104541.4","0.0001","0","1"]],"bids":[["104316","0.25393258","0","12"],["104313.1","0","0","0"],["104311.4","0","0","0"],["104309.9","0.02966541","0","2"],["104307.8","0","0","0"],["104307.6","0.00068109","0","3"],["104305.7","0","0","0"],["104305.6","0.00917734","0","1"],["104304.1","0.000048","0","1"],["104303.4","0","0","0"],["104302.4","0","0","0"],["104302.1","0","0","0"],["104300.6","0","0","0"],["104299.2","0.05579995","0","4"],["104298.3","0","0","0"],["104297.8","0","0","0"],["104296.9","0","0","0"],["104295.8","0.00480399","0","2"],["104295.6","0","0","0"],["104293.2","0.033","0","1"],["104292.4","0","0","0"],["104291.6","0.00100678","0","2"],["104283.6","0.13897514","0","1"],["104254.6","0.00349257","0","7"],["104254.4","0.00065378","0","2"],["104234.9","0.00024984","0","5"],["104234.8","0.00061782","0","1"],["104234.6","0.00199229","0","3"],["104234.5","0.00003076","0","2"],["104234.4","0.77963354","0","2"],["104234.3","0.00028121","0","5"],["104234","0.00002831","0","2"],["104233.7","0.00003837","0","1"],["104233.5","2.63181458","0","1"],["104233.3","0.00482005","0","1"],["104233","0.00086083","0","2"],["104232.9","0.00005458","0","1"],["104232.7","0.0000103","0","1"]],"ts":"1747170728101","checksum":-26358146,"seqId":54226508607,"prevSeqId":54226508540}]}
{"arg":{"channel":"books","instId":"BTC-USDT"},"action":"update","data":[{"asks":[["104316.1","1.02489814","0","12"],["104317.9","0.10958395","0","1"],["104319.3","0","0","0"],["104321.5","0","0","0"],["104321.6","0.00979218","0","2"],["104323.8","0.00182925","0","1"],["104323.9","0.03422323","0","2"],["104325.4","0.06732093","0","3"],["104325.6","0.01916962","0","1"],["104329.5","0.62888937","0","2"],["104329.7","0.00001","0","1"],["104332.5","0","0","0"],["104332.7","0.91764361","0","2"],["104333.6","0.39428974","0","3"],["104345","0.002","0","2"],["104346","0.01058201","0","2"],["104347","0","0","0"],["104359.4","0.31094214","0","3"],["104378.5","0","0","0"],["104541.9","0.00003805","0","1"],["104542","0.00002848","0","1"]],"bids":[["104316","0.19958322","0","10"],["104314.1","0","0","0"],["104312.1","0","0","0"],["104310.8","0","0","0"],["104309.9","0.00001","0","1"],["104309.5","0.02965551","0","1"],["104306.1","0.24056228","0","2"],["104301.5","0.30781653","0","2"],["104299.2","0.00003543","0","3"],["104298.5","0.05576488","0","1"],["104295.8","0.00001193","0","1"],["104295.7","0.32009073","0","3"],["104295.2","0.00479206","0","1"],["104285.7","0.15085297","0","40"],["104283.6","0","0","0"],["104274.9","0","0","0"],["104232.5","0.00954475","0","1"],["104232.4","0.00045226","0","2"]],"ts":"1747170728201","checksum":1586409560,"seqId":54226508819,"prevSeqId":54226508607}]}
{"arg":{"channel":"books","instId":"BTC-USDT"},"action":"update","data":[{"asks":[["104321.5","0.00479221","0","1"],["104321.6","0.005","0","1"],["104323.6","0.10117703","0","1"],["104325.2","0.08852668","0","1"],["104325.4","0.04263379","0","2"],["104325.5","0.02468713","0","1"],["104328.6","0.00479206","0","1"],["104328.7","0.14401036","0","1"],["104328.9","0","0","0"],["104329.1","0.16352383","0","2"],["104329.5","0.45443038","0","2"],["104332","0.15158056","0","1"],["104332.5","0.13897558","0","1"],["104332.7","0.77866876","0","1"],["104333.6","0.39687492","0","3"],["104334.6","0.25546815","0","1"],["104338.1","0.34075934","0","1"],["104339","0","0","0"],["104536.3","0","0","0"],["104536.4","0","0","0"],["104538.4","0","0","0"],["104540","0","0","0"],["104541.2","0","0","0"],["104541.4","0","0","0"],["104541.9","0","0","0"],["104542","0","0","0"]],"bids":[["104316","0.16358322","0","9"],["104311.2","0.02787471","0","1"],["104306.1","0.1874527","0","2"],["104304.7","0.09095094","0","1"],["104302.6","0.09967215","0","6"],["104301.6","0.15452485","0","1"],["104301.5","0.33793482","0","2"],["104301.2","0.16135795","0","5"],["104298.5","0","0","0"],["104297","0.1614345","0","1"],["104295.7","0.32414178","0","3"],["104291.6","0.24442702","0","3"],["104285.7","0.01187812","0","39"],["104283.6","0.13897558","0","1"],["104232.9","0","0","0"],["104232.7","0","0","0"],["104232.5","0","0","0"],["104232.4","0","0","0"]],"ts":"1747170728301","checksum":2113789112,"seqId":54226508985,"prevSeqId":54226508819}]}
{"arg":{"channel":"books","instId":"BTC-USDT"},"action":"update","data":[{"asks":[["104323.6","0","0","0"],["104323.7","0.08963651","0","1"],["104324.3","0.0931501","0","1"],["104325.2","0","0","0"],["104325.3","0.08935398","0","1"],["104325.8","0.09818261","0","1"],["104328.7","0","0","0"],["104328.8","0.15615211","0","1"],["104329.1","0.00093","0","1"],["104329.2","0.15125042","0","1"],["104329.3","0.15923407","0","1"],["104332","0","0","0"],["104332.1","0.15726944","0","1"],["104332.6","0.65279002","0","3"],["104334.3","0.25036642","0","1"],["104334.6","0","0","0"],["104334.7","0.25226399","0","1"],["104338.3","0.24655528","0","1"],["104365.6","0","0","0"],["104365.7","0","0","0"],["104397","0","0","0"],["104412.9","0.67364954","0","2"],["104535.8","0","0","0"],["104536.1","0","0","0"],["104536.2","0","0","0"]],"bids":[["104316","0.28308322","0","10"],["104312.9","0.03834936","0","1"],["104306.1","0.17993559","0","2"],["104304.8","0.18559087","0","2"],["104304.7","0","0","0"],["104303.3","0.09209316","0","1"],["104302.7","0.09308511","0","2"],["104302.6","0.00005058","0","5"],["104301.7","0.15481546","0","1"],["104301.6","0","0","0"],["104301.5","0.33296512","0","2"],["104301.3","0.16215454","0","2"],["104301.2","0.00032901","0","4"],["104299.8","0.16274315","0","2"],["104297.6","0.27246232","0","3"],["104297.1","0.15808162","0","1"],["104297","0","0","0"],["104294.8","0.32028079","0","2"],["104291.7","0.24917028","0","3"],["104291.6","0.00100678","0","2"],["104290.8","0.25476019","0","1"],["104264.9","0.45153925","0","1"],["104264.8","0","0","0"],["104233.5","0","0","0"],["104233","0","0","0"]],"ts":"1747170728401","checksum":-1765028917,"seqId":54226509056,"prevSeqId":54226508985}]}
{"arg":{"channel":"books","instId":"BTC-USDT"},"action":"update","data":[{"asks":[["104323.7","0","0","0"],["104324.1","0.31690304","0","2"],["104324.2","0.29339041","0","2"],["104324.3","0","0","0"],["104324.9","0.10003163","0","1"],["104325.3","0","0","0"],["104325.8","0","0","0"],["104325.9","0.08980096","0","1"],["104326.4","0.10013276","0","1"],["104328.6","0","0","0"],["104328.8","0","0","0"],["104328.9","0.00479206","0","1"],["104329.2","0","0","0"],["104329.3","0","0","0"],["104329.4","0.14396493","0","1"],["104329.7","0.15518514","0","2"],["104329.9","0.16443404","0","1"],["104332.1","0","0","0"],["104332.6","0.55419685","0","3"],["104333.1","0.32437727","0","3"],["104333.6","0.32203348","0","3"],["104334.3","0","0","0"],["104334.7","0","0","0"],["104334.9","0.25686857","0","1"],["104335.2","0.27095361","0","1"],["104338.3","0","0","0"],["104338.9","0.26642301","0","1"],["104356.6","1.39038393","0","1"],["104387.9","2.47466348","0","1"],["104535.8","0.77866876","0","1"]],"bids":[["104306.1","0.2718564","0","1"],["104305.4","0.18376646","0","2"],["104304.8","0","0","0"],["104304","0.19270708","0","5"],["104303.9","0.09045079","0","1"],["104303.3","0","0","0"],["104303.2","0.10017129","0","1"],["104302.7","0.00001016","0","1"],["104302.2","0.15346123","0","2"],["104301.9","0.15337648","0","2"],["104301.7","0","0","0"],["104301.5","0.29071167","0","2"],["104301.3","0.005","0","1"],["104300.4","0.15847082","0","1"],["104299.8","0.00108768","0","1"],["104298.1","0.26019158","0","1"],["104297.6","0.18505465","0","3"],["104297.1","0","0","0"],["104296.2","0.00479206","0","1"],["104295.7","0.31273836","0","3"],["104295.4","0.24262959","0","2"],["104295.2","0","0","0"],["104294.8","0.06061265","0","1"],["104292.2","0.25153932","0","1"],["104291.7","0.00009425","0","2"],["104291.4","0.23455808","0","1"],["104290.8","0","0","0"],["104265.1","1.36496106","0","1"],["104234","0","0","0"],["104233.7","0","0","0"],["104233.3","0","0","0"]],"ts":"1747170728501","checksum":-1665962123,"seqId":54226509135,"prevSeqId":54226509056}]}
{"arg":{"channel":"books","instId":"BTC-USDT"},"action":"update","data":[{"asks":[["104332.5","0","0","0"],["104332.6","0.69317182","0","4"],["104333","0.52651407","0","1"],["104333.6","0.00001","0","1"]],"bids":[["104283.6","0.13897497","0","1"]],"ts":"1747170728601","checksum":-1665962123,"seqId":54226509150,"prevSeqId":54226509135}]}
{"arg":{"channel":"books","instId":"BTC-USDT"},"action":"update","data":[{"asks":[["104332.6","0.55419685","0","3"],["104334.4","0.13990438","0","2"]],"bids":[["104285.7","0.1508525","0","40"],["104283.6","0","0","0"],["104234","0.00002831","0","2"]],"ts":"1747170728701","checksum":-1665962123,"seqId":54226509155,"prevSeqId":54226509150}]}
{"arg":{"channel":"books","instId":"BTC-USDT"},"action":"update","data":[{"asks":[],"bids":[["104316","0.28307211","0","10"]],"ts":"1747170728801","checksum":-1607403845,"seqId":54226509158,"prevSeqId":54226509155}]}
{"arg":{"channel":"books","instId":"BTC-USDT"},"action":"update","data":[{"asks":[["104318.3","0.002","0","1"],["104330.8","0.002","0","1"],["104535.6","0","0","0"],["104535.8","0","0","0"]],"bids":[["104313.7","0.002","0","1"],["104301.2","0.00232901","0","5"],["104234","0","0","0"]],"ts":"1747170728901","checksum":1096545108,"seqId":54226509162,"prevSeqId":54226509158}]}
{"arg":{"channel":"books","instId":"BTC-USDT"},"action":"update","data":[{"asks":[],"bids":[["104302.3","0.77917433","0","3"],["104266.4","0","0","0"],["104234","0.00002831","0","2"]],"ts":"1747170729001","checksum":1096545108,"seqId":54226509164,"prevSeqId":54226509162}]}
{"arg":{"channel":"books","instId":"BTC-USDT"},"action":"update","data":[{"asks":[["104387.7","0","0","0"],["104388.4","0.00056666","0","1"],["104441","0.0025","0","1"],["104441.6","0.00056666","0","1"],["104534.7","0","0","0"]],"bids":[["104308.3","0.00056666","0","1"],["104307.6","0.00011443","0","2"],["104306.1","0.49489006","0","2"],["104264.3","0.04836266","0","2"],["104255.1","0.00059137","0","2"],["104254.4","0.00008712","0","1"],["104234","0","0","0"]],"ts":"1747170729101","checksum":-1237671111,"seqId":54226509174,"prevSeqId":54226509164}]}
{"arg":{"channel":"books","instId":"BTC-USDT"},"action":"update","data":[{"asks":[["104319.9","0.00479223","0","1"],["104321.5","0","0","0"],["104324.2","0.19242972","0","1"],["104324.9","0","0","0"],["104325.9","0","0","0"],["104326.4","0","0","0"],["104328.9","0","0","0"],["104329.4","0","0","0"],["104329.7","0.00001","0","1"],["104329.9","0","0","0"],["104330.6","0.00479206","0","1"],["104332.6","0.40743114","0","2"],["104333.1","0.0665","0","2"],["104334.9","0","0","0"],["104335.2","0","0","0"],["104338.9","0","0","0"],["104534.7","0.00094804","0","1"],["104535.6","0.00002193","0","1"],["104535.8","0.77866876","0","1"],["104536.1","0.0152","0","1"],["104536.2","0.076","0","5"],["104536.3","0.076","0","5"],["104536.4","0.00002296","0","1"],["104538.4","0.07298372","0","1"]],"bids":[["104316","0.16357211","0","9"],["104305.4","0","0","0"],["104303.9","0","0","0"],["104303.2","0","0","0"],["104302.2","0.00003272","0","1"],["104301.9","0.00120818","0","1"],["104300.4","0","0","0"],["104298.5","0.00479206","0","1"],["104298.1","0","0","0"],["104297.6","0.03001176","0","2"],["104296.2","0","0","0"],["104295.4","0.00001943","0","1"],["104292.2","0","0","0"],["104291.4","0","0","0"],["104234","0.00002831","0","2"],["104233.8","2.49295191","0","1"],["104233.7","0.00003837","0","1"],["104233.3","0.00482005","0","1"],["104233","0.00086083","0","2"],["104232.9","0.00005458","0","1"],["104232.7","0.0000103","0","1"]],"ts":"1747170729301","checksum":1654953435,"seqId":54226509207,"prevSeqId":54226509174}]}
{"arg":{"channel":"books","instId":"BTC-USDT"},"action":"update","data":[{"asks":[["104323.6","0.00182925","0","1"],["104323.7","0.0942386","0","1"],["104323.8","0","0","0"],["104324.1","0.22926705","0","1"],["104324.3","0.09990003","0","1"],["104325.3","0.0857335","0","1"],["104325.8","0.0938772","0","1"],["104328.7","0.00479206","0","1"],["104328.8","0.15480893","0","1"],["104329.2","0.1659349","0","1"],["104329.3","0.15787077","0","1"],["104330.6","0","0","0"],["104332.1","0.16395998","0","1"],["104332.6","0.63867149","0","3"],["104333","0.33249655","0","1"],["104334.2","0.13897381","0","1"],["104334.3","0.24421345","0","1"],["104334.4","0.00093","0","1"],["104334.7","0.26132192","0","1"],["104338.3","0.26255623","0","1"],["104531.4","0","0","0"],["104532","0","0","0"],["104533.3","0","0","0"],["104533.9","0","0","0"],["104534.7","0","0","0"],["104535.6","0","0","0"],["104535.8","0","0","0"],["104536.1","0","0","0"],["104536.2","0","0","0"],["104536.3","0","0","0"],["104536.4","0","0","0"],["104538.4","0","0","0"]],"bids":[["104316","0.28307211","0","10"],["104306.1","0.45493793","0","2"],["104304.8","0.18907019","0","2"],["104303.3","0.09496848","0","1"],["104302.7","0.09933709","0","2"],["104301.7","0.16344599","0","1"],["104301.5","0.33540146","0","2"],["104301.3","0.16295263","0","2"],["104299.8","0.16178582","0","2"],["104298.5","0","0","0"],["104297.6","0.28468308","0","3"],["104297.1","0.14734916","0","1"],["104295.8","0.00480399","0","2"],["104295.7","0.32169982","0","3"],["104294.8","0.29857391","0","2"],["104291.7","0.26917278","0","3"],["104290.8","0.26309434","0","1"],["104286.5","0.13907752","0","2"],["104285.7","0.01187812","0","39"],["104233.3","0","0","0"],["104233","0","0","0"],["104232.9","0","0","0"],["104232.7","0","0","0"]],"ts":"1747170729401","checksum":-136721141,"seqId":54226509263,"prevSeqId":54226509207}]}
{"arg":{"channel":"books","instId":"BTC-USDT"},"action":"update","data":[{"asks":[["104323.6","0","0","0"],["104323.7","0","0","0"],["104323.8","0.00182925","0","1"],["104324.1","0.31594382","0","2"],["104324.2","0.2949782","0","2"],["104324.3","0","0","0"],["104324.9","0.09640792","0","1"],["104325.3","0","0","0"],["104325.8","0","0","0"],["104325.9","0.09544784","0","1"],["104326.4","0.09332443","0","1"],["104328.8","0","0","0"],["104329.2","0","0","0"],["104329.3","0","0","0"],["104329.4","0.14370392","0","1"],["104329.7","0.15414301","0","2"],["104329.9","0.15887352","0","1"],["104332.1","0","0","0"],["104332.6","0.55721616","0","3"],["104333","0.51871276","0","2"],["104333.1","0.30788675","0","3"],["104334.3","0","0","0"],["104334.7","0","0","0"],["104334.9","0.26912282","0","1"],["104335.2","0.24875193","0","1"],["104338.3","0","0","0"],["104338.9","0.23463289","0","1"],["104367.7","0.56831969","0","1"],["104396.3","0.16968822","0","1"],["104412.9","0.00001","0","1"],["104531.4","0.00209352","0","1"]],"bids":[["104306.1","0.50287328","0","2"],["104305.4","0.18501953","0","2"],["104304.8","0","0","0"],["104303.9","0.09144375","0","1"],["104303.3","0","0","0"],["104303.2","0.10092951","0","1"],["104302.7","0.00001016","0","1"],["104302.2","0.16696423","0","2"],["104301.9","0.16347996","0","2"],["104301.7","0","0","0"],["104301.5","0.28295182","0","2"],["104301.3","0.005","0","1"],["104300.4","0.15205718","0","1"],["104299.8","0.00108768","0","1"],["104298.1","0.24418091","0","1"],["104297.6","0.18440485","0","3"],["104297.1","0","0","0"],["104295.7","0.31386293","0","3"],["104295.4","0.25136394","0","2"],["104294.8","0.06061265","0","1"],["104292.2","0.24305329","0","1"],["104291.7","0.00009425","0","2"],["104291.4","0.23786353","0","1"],["104290.8","0","0","0"],["104265.2","0.87590511","0","3"],["104264.9","0","0","0"],["104233.7","0","0","0"]],"ts":"1747170729501","checksum":-852038284,"seqId":54226509328,"prevSeqId":54226509263}]}
{"arg":{"channel":"books","instId":"BTC-USDT"},"action":"update","data":[{"asks":[["104316.1","0.84114814","0","11"],["104319.9","0","0","0"],["104321.5","0.00479221","0","1"],["104324.1","0.22926705","0","1"],["104324.2","0.19242972","0","1"],["104324.4","0.13191797","0","2"],["104324.9","0","0","0"],["104325.1","0.17203644","0","2"],["104325.9","0","0","0"],["104326.1","0.09219472","0","1"],["104326.4","0","0","0"],["104326.6","0.32253354","0","2"],["104329.4","0","0","0"],["104329.6","0.14960508","0","2"],["104329.7","0.00001","0","1"],["104329.9","0.15408615","0","1"],["104330.1","0.15658535","0","1"],["104332.6","0.40743114","0","2"],["104332.8","0.14985163","0","1"],["104333","0.51813827","0","2"],["104333.1","0.0665","0","2"],["104333.3","0.25271578","0","1"],["104334.2","0","0","0"],["104334.9","0","0","0"],["104335.1","0.36800095","0","2"],["104335.2","0","0","0"],["104335.4","0.25164187","0","1"],["104335.9","0.13897176","0","1"],["104338.9","0","0","0"],["104339.1","0.24081376","0","1"],["104392.9","0","0","0"],["104396.3","6.11746882","0","2"],["104532","0.00001","0","1"],["104533.3","0.000173","0","1"]],"bids":[["104316","0.44836849","0","12"],["104312.8","0.02787427","0","1"],["104309.5","0","0","0"],["104306.1","0.49677743","0","2"],["104305.6","0.19682393","0","3"],["104305.4","0","0","0"],["104304.1","0.09580665","0","2"],["104303.9","0","0","0"],["104303.4","0.09540977","0","1"],["104303.2","0","0","0"],["104302.4","0.15164461","0","1"],["104302.2","0.00003272","0","1"],["104302.1","0.15581696","0","1"],["104301.9","0.00120818","0","1"],["104301.5","0.28919707","0","2"],["104300.6","0.16203755","0","1"],["104300.4","0","0","0"],["104298.3","0.24298094","0","1"],["104298.1","0","0","0"],["104297.8","0.16643021","0","1"],["104297.6","0.03001176","0","2"],["104295.7","0.32582815","0","3"],["104295.6","0.26668359","0","1"],["104295.4","0.00001943","0","1"],["104292.4","0.2581942","0","1"],["104292.2","0","0","0"],["104291.6","0.26361347","0","3"],["104291.4","0","0","0"],["104286.9","0.13986575","0","5"],["104286.5","0.00010371","0","1"],["104280.4","0.36908178","0","1"],["104234","0","0","0"],["104233.8","0","0","0"]],"ts":"1747170729601","checksum":-373503199,"seqId":54226509405,"prevSeqId":54226509328}]}
{"arg":{"channel":"books","instId":"BTC-USDT"},"action":"update","data":[{"asks":[["104328.7","0","0","0"],["104329","0.03560833","0","2"],["104392.9","5.9477806","0","1"],["104396.3","0.16968822","0","1"],["104423.5","0","0","0"],["104475.5","0","0","0"],["104533.9","0.03","0","1"],["104534.7","0.00094804","0","1"]],"bids":[["104297.6","0.03480382","0","3"],["104295.8","0.00001193","0","1"]],"ts":"1747170729701","checksum":-373503199,"seqId":54226509417,"prevSeqId":54226509405}]}
{"arg":{"channel":"books","instId":"BTC-USDT"},"action":"update","data":[{"asks":[["104316.1","1.08114814","0","12"]],"bids":[],"ts":"1747170729801","checksum":-930992116,"seqId":54226509418,"prevSeqId":54226509417}]}
{"arg":{"channel":"books","instId":"BTC-USDT"},"action":"update","data":[{"asks":[["104319.9","0.00479221","0","1"],["104321.5","0","0","0"]],"bids":[["104263.8","0.00049131","0","2"]],"ts":"1747170729901","checksum":1546300613,"seqId":54226509424,"prevSeqId":54226509418}]}
{"arg":{"channel":"books","instId":"BTC-USDT"},"action":"update","data":[{"asks":[["104423.5","0.00009732","0","1"],["104534.7","0","0","0"]],"bids":[],"ts":"1747170730001","checksum":1546300613,"seqId":54226509426,"prevSeqId":54226509424}]}
{"arg":{"channel":"books","instId":"BTC-USDT"},"action":"update","data":[{"asks":[["104316.1","1.08111803","0","12"],["104324.1","0.31658401","0","2"],["104325","0.09455613","0","1"],["104325.1","0.07298372","0","1"],["104326","0.20842929","0","3"],["104326.1","0","0","0"],["104326.5","0.12999061","0","2"],["104326.6","0.234","0","1"],["104328.9","0.00479206","0","1"],["104329","0.03081627","0","1"],["104329.5","0.61220011","0","3"],["104329.6","0.00479312","0","1"],["104330","0.24580234","0","4"],["104330.1","0","0","0"],["104334.4","0.1399037","0","2"],["104335","0.27228844","0","1"],["104335.1","0.11501","0","1"],["104335.9","0","0","0"],["104339","0.24939534","0","1"],["104339.1","0","0","0"],["104388.4","0","0","0"],["104389","0.00056666","0","1"],["104389.6","6.05319388","0","2"],["104392.9","0","0","0"],["104441.6","0","0","0"],["104442.3","0.00056666","0","1"],["104534.7","0.00094804","0","1"]],"bids":[["104316","0.32886849","0","11"],["104308.9","0.00056666","0","1"],["104308.3","0","0","0"],["104305.6","0.00917734","0","1"],["104305.5","0.18741294","0","2"],["104304.1","0.000048","0","1"],["104304","0.28172448","0","6"],["104302.1","0","0","0"],["104302","0.14556025","0","1"],["104300.6","0","0","0"],["104300.5","0.15384031","0","1"],["104297.6","0.03001176","0","2"],["104296.2","0.00479206","0","1"],["104295.6","0","0","0"],["104295.5","0.25899492","0","1"],["104291.6","0.00100678","0","2"],["104291.5","0.24628729","0","1"],["104286.9","0.00089399","0","4"],["104286.5","0.13907741","0","2"],["104255.7","0.00124283","0","5"],["104255.1","0.00002471","0","1"],["104234.5","0","0","0"],["104234.4","0","0","0"],["104234.3","0","0","0"]],"ts":"1747170730101","checksum":572819635,"seqId":54226509506,"prevSeqId":54226509426}]}
{"arg":{"channel":"books","instId":"BTC-USDT"},"action":"update","data":[{"asks":[["104345","0","0","0"],["104346","0.01158201","0","3"],["104347","0.001","0","1"],["104475.5","0.0009076","0","1"],["104534.7","0","0","0"]],"bids":[],"ts":"1747170730201","checksum":572819635,"seqId":54226509513,"prevSeqId":54226509506}]}
{"arg":{"channel":"books","instId":"BTC-USDT"},"action":"update","data":[{"asks":[["104316.1","1.09262203","0","13"],["104334.4","0.13990298","0","2"]],"bids":[["104286.9","0.13986697","0","5"],["104286.5","0.00010371","0","1"]],"ts":"1747170730301","checksum":714664070,"seqId":54226509525,"prevSeqId":54226509513}]}
{"arg":{"channel":"books","instId":"BTC-USDT"},"action":"update","data":[{"asks":[["104321.4","0.02698094","0","1"],["104328.9","0","0","0"],["104329","0","0","0"],["104330.6","0.00479206","0","1"]],"bids":[["104298.5","0.00479206","0","1"],["104296.2","0","0","0"],["104254.6","0.41754257","0","8"],["104237.8","0.00072803","0","5"]],"ts":"1747170730401","checksum":-1032998431,"seqId":54226509537,"prevSeqId":54226509525}]}
{"arg":{"channel":"books","instId":"BTC-USDT"},"action":"update","data":[{"asks":[["104316.1","1.08111803","0","12"],["104325","0","0","0"],["104325.1","0.17154314","0","2"],["104326","0.11409956","0","2"],["104326.1","0.09744521","0","1"],["104326.5","0.02984193","0","1"],["104326.6","0.32591727","0","2"],["104329.5","0.45443038","0","2"],["104329.6","0.16601471","0","2"],["104330","0.08190006","0","3"],["104330.1","0.1585988","0","1"],["104335","0","0","0"],["104335.1","0.37535753","0","2"],["104339","0","0","0"],["104339.1","0.24847553","0","1"],["104353.7","0.90816889","0","2"]],"bids":[["104316","0.48436849","0","13"],["104305.6","0.20614675","0","3"],["104305.5","0","0","0"],["104304.1","0.08991541","0","2"],["104304","0.19270708","0","5"],["104302.1","0.15500387","0","1"],["104302","0","0","0"],["104300.6","0.15197486","0","1"],["104300.5","0","0","0"],["104295.6","0.26654369","0","1"],["104295.5","0","0","0"],["104291.6","0.25124256","0","3"],["104291.5","0","0","0"],["104234.5","0.00003076","0","2"],["104234.4","0.77963354","0","2"]],"ts":"1747170730501","checksum":316433974,"seqId":54226509570,"prevSeqId":54226509537}]}
{"arg":{"channel":"books","instId":"BTC-USDT"},"action":"update","data":[{"asks":[["104334.4","0.00093","0","1"],["104335","0.13897181","0","1"],["104421.5","0.0143","0","1"],["104423.1","0.01054312","0","1"],["104533.3","0","0","0"],["104533.9","0","0","0"]],"bids":[],"ts":"1747170730601","checksum":316433974,"seqId":54226509574,"prevSeqId":54226509570}]}
{"arg":{"channel":"books","instId":"BTC-USDT"},"action":"update","data":[{"asks":[["104319.9","0","0","0"],["104321.3","0.0047922","0","1"]],"bids":[],"ts":"1747170730701","checksum":-219164235,"seqId":54226509579,"prevSeqId":54226509574}]}
{"arg":{"channel":"books","instId":"BTC-USDT"},"action":"update","data":[{"asks":[["104325","0.10100768","0","1"],["104325.1","0.07298372","0","1"],["104326","0.21148572","0","3"],["104326.1","0","0","0"],["104326.5","0.12101902","0","2"],["104326.6","0.234","0","1"],["104329.5","0.61788272","0","3"],["104329.6","0.00479312","0","1"],["104330","0.24733769","0","4"],["104330.1","0","0","0"],["104335","0.40635759","0","2"],["104335.1","0.11501","0","1"],["104339","0.25130065","0","1"],["104339.1","0","0","0"],["104533.3","0.000173","0","1"]],"bids":[["104316","0.33507211","0","12"],["104305.6","0.00917734","0","1"],["104305.5","0.19250298","0","2"],["104304.1","0.000048","0","1"],["104304","0.29289877","0","6"],["104302.1","0","0","0"],["104302","0.14388785","0","1"],["104300.6","0","0","0"],["104300.5","0.16768986","0","1"],["104295.6","0","0","0"],["104295.5","0.26186628","0","1"],["104291.6","0.00100678","0","2"],["104291.5","0.23612518","0","1"],["104234.5","0","0","0"],["104234.4","0","0","0"]],"ts":"1747170730801","checksum":-1107838418,"seqId":54226509609,"prevSeqId":54226509579}]}
{"arg":{"channel":"books","instId":"BTC-USDT"},"action":"update","data":[{"asks":[["104316.1","0.84111803","0","11"]],"bids":[["104316","0.33287211","0","9"],["104310.8","0.03038473","0","1"],["104234.6","0","0","0"]],"ts":"1747170731001","checksum":366843167,"seqId":54226509617,"prevSeqId":54226509609}]}
{"arg":{"channel":"books","instId":"BTC-USDT"},"action":"update","data":[{"asks":[["104382.8","0.00056666","0","1"],["104389","0","0","0"],["104436.1","0.00056666","0","1"],["104442.3","0","0","0"]],"bids":[["104308.9","0","0","0"],["104302.8","0.00056666","0","1"],["104263.8","0.00047931","0","1"],["104255.7","0.00067617","0","4"],["104249.5","0.00056666","0","1"],["104234.8","0","0","0"]],"ts":"1747170731101","checksum":5379398,"seqId":54226509627,"prevSeqId":54226509617}]}
{"arg":{"channel":"books","instId":"BTC-USDT"},"action":"update","data":[{"asks":[["104353.7","0.56120425","0","1"],["104356.6","0","0","0"],["104387.9","0","0","0"],["104533.9","0.03","0","1"],["104534.7","0.00094804","0","1"]],"bids":[["104265.2","0.46641679","0","3"],["104265.1","0","0","0"],["104234.8","0.00061782","0","1"]],"ts":"1747170731201","checksum":5379398,"seqId":54226509634,"prevSeqId":54226509627}]}
{"arg":{"channel":"books","instId":"BTC-USDT"},"action":"update","data":[{"asks":[["104316.1","0.85262203","0","12"],["104356.6","1.44145715","0","1"],["104387.9","2.66277173","0","1"],["104389.5","5.98609388","0","1"],["104389.6","0.0671","0","1"],["104418.7","0","0","0"],["104418.8","0","0","0"],["104496","0.06","0","2"],["104534.7","0","0","0"]],"bids":[["104273.8","0","0","0"],["104266.2","1.40825265","0","2"],["104234.9","2.48005018","0","6"],["104234.6","0.00199229","0","3"]],"ts":"1747170731301","checksum":1458138373,"seqId":54226509650,"prevSeqId":54226509634}]}
{"arg":{"channel":"books","instId":"BTC-USDT"},"action":"update","data":[{"asks":[["104423.5","0","0","0"],["104475.5","0","0","0"],["104476.3","0.07075614","0","2"],["104534.7","0.00094804","0","1"],["104535.6","0.00002193","0","1"]],"bids":[],"ts":"1747170731401","checksum":1458138373,"seqId":54226509664,"prevSeqId":54226509650}]}
{"arg":{"channel":"books","instId":"BTC-USDT"},"action":"update","data":[{"asks":[["104316.1","0.84111803","0","11"],["104334.4","0.13990395","0","2"],["104335","0.26738578","0","1"],["104353.7","0.92349086","0","2"],["104389.5","0","0","0"],["104396.3","6.19128759","0","2"],["104535.8","0.77866876","0","1"]],"bids":[["104316","0.33484211","0","10"],["104286.9","0.00089399","0","4"],["104285.7","0.15085207","0","40"],["104273.8","0.00002967","0","1"],["104234.6","0","0","0"]],"ts":"1747170731501","checksum":-1122300777,"seqId":54226509676,"prevSeqId":54226509664}]}
{"arg":{"channel":"books","instId":"BTC-USDT"},"action":"update","data":[{"asks":[["104420.8","0.0134728","0","1"],["104420.9","0.00096766","0","2"],["104423.9","0.00009228","0","1"],["104498","0.00123221","0","1"],["104534.7","0","0","0"],["104535.6","0","0","0"],["104535.8","0","0","0"]],"bids":[["104282","0.00036","0","1"],["104234.8","0","0","0"]],"ts":"1747170731601","checksum":-1122300777,"seqId":54226509684,"prevSeqId":54226509676}]}
{"arg":{"channel":"books","instId":"BTC-USDT"},"action":"update","data":[{"asks":[["104316.1","0.85111803","0","12"],["104321.3","0","0","0"],["104321.5","0.0047922","0","1"],["104392.9","6.02159937","0","1"],["104396.3","0.16968822","0","1"],["104533.9","0","0","0"]],"bids":[["104303.6","0","0","0"],["104234.8","0.00061782","0","1"]],"ts":"1747170731701","checksum":1040220318,"seqId":54226509696,"prevSeqId":54226509684}]}
{"arg":{"channel":"books","instId":"BTC-USDT"},"action":"update","data":[{"asks":[["104316.1","1.09111803","0","13"],["104420.8","0","0","0"],["104420.9","0.00001","0","1"],["104498","0","0","0"],["104533.9","0.03","0","1"],["104534.7","0.00094804","0","1"]],"bids":[["104281","0.00038601","0","2"]],"ts":"1747170731801","checksum":-1274079062,"seqId":54226509704,"prevSeqId":54226509696}]}
{"arg":{"channel":"books","instId":"BTC-USDT"},"action":"update","data":[{"asks":[["104316.1","1.10262203","0","14"],["104329","0.00479206","0","1"],["104330.6","0","0","0"]],"bids":[["104300.1","0.04392056","0","3"],["104298.5","0","0","0"],["104296.2","0.00479206","0","1"]],"ts":"1747170732001","checksum":336059309,"seqId":54226509713,"prevSeqId":54226509704}]}
{"arg":{"channel":"books","instId":"BTC-USDT"},"action":"update","data":[{"asks":[["104324","0.21036558","0","3"],["104324.1","0.22926705","0","1"],["104324.4","0.03108988","0","1"],["104324.6","0.09952149","0","1"],["104325","0","0","0"],["104325.6","0.11146787","0","2"],["104326","0.11409956","0","2"],["104326.1","0.08741256","0","1"],["104326.5","0.02984193","0","1"],["104329.1","0.16251506","0","2"],["104329.5","0.61964784","0","3"],["104329.6","0.15521532","0","2"],["104329.9","0","0","0"],["104330","0.08190006","0","3"],["104332.4","0.15774035","0","1"],["104332.8","0","0","0"],["104332.9","0.22866859","0","2"],["104333","0.47147099","0","2"],["104333.3","0","0","0"],["104334.4","0.00093","0","1"],["104334.6","0.25304028","0","1"],["104335","0.27140489","0","1"],["104335.4","0","0","0"],["104338.6","0.24148162","0","1"],["104339","0","0","0"],["104382.8","0","0","0"],["104385.6","0.00056666","0","1"],["104421.4","0.01347272","0","1"],["104421.5","0.01525765","0","2"],["104436.1","0","0","0"],["104438.9","0.00056666","0","1"],["104498.6","0.0012322","0","1"],["104534.7","0","0","0"]],"bids":[["104316","0.21534211","0","9"],["104306.1","0.2718564","0","1"],["104305.6","0.009744","0","2"],["104305.5","0","0","0"],["104305.1","0.1873913","0","2"],["104304","0.19270708","0","5"],["104303.6","0.09942646","0","1"],["104303.4","0","0","0"],["104303","0.09414884","0","2"],["104302.8","0","0","0"],["104302.4","0","0","0"],["104302","0.16270106","0","1"],["104301.6","0.14961432","0","1"],["104301.5","0.1597262","0","1"],["104300.5","0","0","0"],["104300.1","0.20644333","0","4"],["104298.3","0","0","0"],["104297.9","0.24394993","0","2"],["104297.8","0","0","0"],["104297.4","0.15033945","0","2"],["104296.2","0","0","0"],["104295.7","0.19380067","0","2"],["104295.5","0","0","0"],["104295.2","0.00479206","0","1"],["104295.1","0.28997797","0","3"],["104292.4","0","0","0"],["104292","0.25255488","0","2"],["104291.5","0","0","0"],["104291.1","1.04209771","0","2"],["104285.7","0.15085214","0","40"],["104252.3","0.00056666","0","1"],["104249.5","0","0","0"],["104234.6","0.00199229","0","3"],["104234.5","0.00003076","0","2"],["104234.4","0.77963354","0","2"],["104234.3","0.00028121","0","5"],["104234","0.00002831","0","2"],["104233.7","0.00003837","0","1"],["104233.3","0.00482005","0","1"]],"ts":"1747170732101","checksum":-1664861115,"seqId":54226509799,"prevSeqId":54226509713}]}
{"arg":{"channel":"books","instId":"BTC-USDT"},"action":"update","data":[{"asks":[["104318.2","0.01","0","2"],["104321.3","0.00479233","0","1"],["104321.5","0","0","0"],["104321.6","0","0","0"],["104330.7","0.01","0","2"],["104334.1","0","0","0"],["104476.2","0.00090987","0","1"],["104476.3","0.06985","0","1"],["104534.7","0.00094804","0","1"]],"bids":[["104313.8","0.01019173","0","3"],["104306.1","0.49515505","0","2"],["104305.8","0","0","0"],["104301.5","0.2881826","0","2"],["104301.3","0.01","0","2"],["104295.7","0.32465645","0","3"],["104293.3","0","0","0"],["104233","0.00086083","0","2"],["104232.9","0.00005458","0","1"]],"ts":"1747170732201","checksum":-674003608,"seqId":54226509838,"prevSeqId":54226509799}]}
{"arg":{"channel":"books","instId":"BTC-USDT"},"action":"update","data":[{"asks":[["104333","0.33249655","0","1"],["104334.4","0.13990442","0","2"]],"bids":[],"ts":"1747170732301","checksum":-674003608,"seqId":54226509843,"prevSeqId":54226509838}]}
{"arg":{"channel":"books","instId":"BTC-USDT"},"action":"update","data":[{"asks":[["104316.1","1.20137203","0","15"],["104334.4","0.13990398","0","2"]],"bids":[["104296.2","0.00479206","0","1"],["104295.2","0","0","0"],["104285.7","0.1508521","0","40"]],"ts":"1747170732401","checksum":585643114,"seqId":54226509855,"prevSeqId":54226509843}]}
{"arg":{"channel":"books","instId":"BTC-USDT"},"action":"update","data":[{"asks":[["104316.1","1.10262203","0","14"],["104329","0","0","0"],["104330.6","0.00479206","0","1"]],"bids":[["104298.5","0.00479206","0","1"],["104296.2","0","0","0"],["104285.7","0.15085218","0","40"],["104270","0.83764404","0","3"]],"ts":"1747170732501","checksum":-674003608,"seqId":54226509869,"prevSeqId":54226509855}]}
{"arg":{"channel":"books","instId":"BTC-USDT"},"action":"update","data":[{"asks":[["104316.1","0.86262203","0","13"],["104330.6","0","0","0"],["104331.6","0.00479206","0","1"]],"bids":[["104316","0.33484211","0","10"]],"ts":"1747170732601","checksum":-219643209,"seqId":54226509873,"prevSeqId":54226509869}]}
{"arg":{"channel":"books","instId":"BTC-USDT"},"action":"update","data":[{"asks":[["104319.6","0.02875596","0","1"],["104320.2","0.01917081","0","1"],["104321.3","0","0","0"],["104321.6","0.00479233","0","1"],["104323.9","0.28564111","0","3"],["104324","0.120971","0","2"],["104324.1","0","0","0"],["104324.4","0.12430246","0","2"],["104324.6","0","0","0"],["104325","0.09482794","0","1"],["104325.5","0","0","0"],["104325.6","0","0","0"],["104326","0.19957912","0","3"],["104326.1","0","0","0"],["104326.5","0.12920579","0","2"],["104329.1","0.00093","0","1"],["104329.5","0.61425863","0","3"],["104329.6","0.00479312","0","1"],["104329.9","0.16945486","0","1"],["104330","0.24090816","0","4"],["104330.3","0.03834162","0","1"],["104332.4","0","0","0"],["104332.8","0.15384293","0","1"],["104332.9","0.00005","0","1"],["104333","0.50820431","0","2"],["104333.3","0.24228748","0","1"],["104334.4","0.13990419","0","2"],["104334.6","0","0","0"],["104335","0.25926294","0","1"],["104335.4","0.26602295","0","1"],["104336","0","0","0"],["104338.6","0","0","0"],["104339","0.25962011","0","1"]],"bids":[["104312.8","0","0","0"],["104311.2","0","0","0"],["104310.8","0","0","0"],["104309.5","0.03383682","0","1"],["104306.1","0.49418878","0","2"],["104305.5","0.19553844","0","2"],["104305.1","0","0","0"],["104304","0.2869576","0","6"],["104303.6","0","0","0"],["104303.4","0.09123235","0","1"],["104303","0.00098","0","1"],["104302.4","0.15004846","0","1"],["104302","0.16301132","0","1"],["104301.6","0","0","0"],["104301.5","0.22922239","0","2"],["104300.5","0.15955464","0","1"],["104300.1","0.04392056","0","3"],["104299.9","0.01016539","0","5"],["104299.2","0.03981206","0","4"],["104298.5","0","0","0"],["104298.3","0.23709154","0","1"],["104297.9","0.00026259","0","1"],["104297.8","0.14578668","0","1"],["104297.4","0.00001024","0","1"],["104295.7","0.40070219","0","3"],["104295.5","0.26354489","0","1"],["104295.1","0.030419","0","2"],["104292.4","0.27296732","0","1"],["104292","0.00001069","0","1"],["104291.5","0.23886879","0","1"],["104291.1","0.77866876","0","1"],["104285.7","0.15085231","0","40"],["104250.9","0","0","0"],["104246.1","0.46652973","0","5"],["104233","0","0","0"],["104232.9","0","0","0"]],"ts":"1747170732701","checksum":764773552,"seqId":54226510074,"prevSeqId":54226509873}]}
{"arg":{"channel":"books","instId":"BTC-USDT"},"action":"update","data":[{"asks":[["104316.1","1.10262203","0","14"],["104330.7","0.01479206","0","3"],["104331.6","0","0","0"],["104392.9","6.06790972","0","1"],["104535.6","0.00002193","0","1"]],"bids":[["104299.9","0.00537333","0","4"],["104299.3","0.03977659","0","1"],["104299.2","0.00003543","0","3"],["104298.5","0.00479206","0","1"],["104274.2","0.00711203","0","1"],["104234","0","0","0"],["104233.7","0","0","0"],["104233.3","0","0","0"]],"ts":"1747170732801","checksum":-2110547620,"seqId":54226510094,"prevSeqId":54226510074}]}
{"arg":{"channel":"books","instId":"BTC-USDT"},"action":"update","data":[{"asks":[["104316.1","1.20137203","0","15"],["104320.1","0.00479233","0","1"],["104321.6","0","0","0"],["104324.4","0.03108988","0","1"],["104325","0","0","0"],["104326","0.11409956","0","2"],["104326.1","0.09653232","0","1"],["104326.5","0.02984193","0","1"],["104329.5","0.45443038","0","2"],["104329.9","0","0","0"],["104330","0.08190006","0","3"],["104332.5","0.1389751","0","1"],["104332.8","0","0","0"],["104333","0.33249655","0","1"],["104333.3","0","0","0"],["104334.4","0.00093","0","1"],["104335","0","0","0"],["104335.4","0","0","0"],["104338.6","0.26179525","0","1"],["104339","0","0","0"],["104535.8","0.77866876","0","1"],["104536.1","0.0152","0","1"],["104536.2","0.076","0","5"],["104536.3","0.076","0","5"]],"bids":[["104316","0.19614211","0","7"],["104311.3","0.02678818","0","1"],["104306.1","0.50280471","0","2"],["104305.5","0","0","0"],["104304","0.19270708","0","5"],["104303.6","0.0926952","0","1"],["104303.4","0","0","0"],["104302.4","0","0","0"],["104302","0","0","0"],["104301.5","0.29079436","0","2"],["104300.5","0","0","0"],["104299.7","0","0","0"],["104298.3","0","0","0"],["104297.8","0","0","0"],["104295.7","0.32224439","0","3"],["104295.5","0","0","0"],["104292.4","0","0","0"],["104291.5","0","0","0"],["104291.1","1.03436701","0","2"],["104285.7","0.01187812","0","39"],["104283.6","0.1389751","0","1"],["104273.8","0","0","0"],["104234","0.00002831","0","2"],["104233.7","0.00003837","0","1"],["104233.3","0.00482005","0","1"],["104233","0.00086083","0","2"],["104232.9","0.00005458","0","1"],["104232.7","0.0000103","0","1"],["104232.5","0.00954475","0","1"],["104232.4","0.00045226","0","2"],["104232.2","0.00024748","0","1"]],"ts":"1747170732901","checksum":-1832834990,"seqId":54226510195,"prevSeqId":54226510094}]}
{"arg":{"channel":"books","instId":"BTC-USDT"},"action":"update","data":[{"asks":[["104323.9","0.38195071","0","4"],["104324.5","0.09421451","0","1"],["104325.5","0.09594497","0","1"],["104326","0.21448763","0","3"],["104326.1","0","0","0"],["104329","0.15390367","0","1"],["104329.4","0.15857979","0","1"],["104329.5","0.611338","0","3"],["104332.3","0.16692555","0","1"],["104332.5","0","0","0"],["104332.7","0.91764367","0","2"],["104332.8","0.25623871","0","1"],["104334.5","0.3066071","0","2"],["104334.9","0.26565186","0","1"],["104338.5","0.26491277","0","1"],["104338.6","0","0","0"],["104419.7","0.03455974","0","3"],["104421.4","0","0","0"],["104421.5","0.0143","0","1"],["104496.9","0.0012322","0","1"],["104498.6","0","0","0"],["104525.9","0.00037885","0","1"],["104535.6","0","0","0"],["104535.8","0","0","0"],["104536.1","0","0","0"],["104536.2","0","0","0"],["104536.3","0","0","0"]],"bids":[["104316","0.19737211","0","7"],["104306.1","0.41653941","0","2"],["104305","0.18218227","0","3"],["104303.6","0","0","0"],["104303.5","0.09506973","0","5"],["104302.9","0.09714855","0","2"],["104301.9","0.15714754","0","2"],["104301.5","0.44970076","0","3"],["104300","0.20321857","0","42"],["104297.8","0.25971663","0","1"],["104297.3","0.16555491","0","2"],["104295.7","0.32049217","0","3"],["104295","0.26199872","0","1"],["104291.9","0.27910277","0","3"],["104291.1","0.77866876","0","1"],["104291","0.26276977","0","2"],["104285.7","0.15085303","0","40"],["104283.6","0","0","0"],["104274.2","0","0","0"],["104273.8","0.00002967","0","1"]],"ts":"1747170733001","checksum":1146561816,"seqId":54226510265,"prevSeqId":54226510195}]}
{"arg":{"channel":"books","instId":"BTC-USDT"},"action":"update","data":[{"asks":[["104319.9","0.00479234","0","1"],["104320.1","0","0","0"],["104330.2","0.00479206","0","1"],["104330.7","0.01","0","2"],["104332.7","0.77866876","0","1"],["104334.4","0.13990419","0","2"],["104385.6","0","0","0"],["104386.2","2.42626666","0","2"],["104417.9","0.00095769","0","1"],["104438.9","0","0","0"],["104439.5","0.00056666","0","1"],["104534.7","0","0","0"]],"bids":[["104306.2","0.00056666","0","1"],["104305.6","0.00917734","0","1"],["104285.7","0.15085288","0","40"],["104274.2","0.00711203","0","1"],["104252.9","0.00056666","0","1"],["104252.3","0","0","0"],["104232.4","0","0","0"],["104232.2","0","0","0"]],"ts":"1747170733101","checksum":1752827083,"seqId":54226510296,"prevSeqId":54226510265}]}
{"arg":{"channel":"books","instId":"BTC-USDT"},"action":"update","data":[{"asks":[["104323.9","0.28564111","0","3"],["104324.3","0.10249545","0","1"],["104324.5","0","0","0"],["104325","0.09922781","0","1"],["104325.5","0","0","0"],["104326","0.20622445","0","3"],["104326.5","0.12753399","0","2"],["104329","0","0","0"],["104329.4","0","0","0"],["104329.5","0.60156797","0","3"],["104329.8","0.14989397","0","1"],["104330","0.23962823","0","4"],["104332.3","0","0","0"],["104332.7","0.92564239","0","2"],["104332.8","0","0","0"],["104333","0.50386538","0","2"],["104333.2","0.24553376","0","1"],["104334.5","0.04","0","1"],["104334.9","0","0","0"],["104335","0.24138983","0","1"],["104335.3","0.26618668","0","1"],["104338.5","0","0","0"],["104339","0.26720643","0","1"],["104340.7","0.049","0","2"],["104534.7","0.00094804","0","1"]],"bids":[["104316","0.31687211","0","8"],["104305.5","0.18694238","0","2"],["104305","0.00001","0","1"],["104304","0.28389027","0","6"],["104303.5","0.00035761","0","4"],["104303.3","0.08940178","0","1"],["104302.9","0.00001032","0","1"],["104302.3","0.94818246","0","4"],["104302","0.15432525","0","1"],["104301.9","0.00120818","0","1"],["104301.5","0.29334691","0","2"],["104300.5","0.16825471","0","1"],["104300","0.04150745","0","41"],["104298.2","0.25791396","0","1"],["104297.8","0","0","0"],["104297.7","0.14857886","0","4"],["104297.3","0.00014981","0","1"],["104295.7","0.38925364","0","3"],["104295.5","0.24568402","0","1"],["104295","0","0","0"],["104292.3","0.25302268","0","10"],["104291.9","0.03308723","0","2"],["104291.5","0.2440042","0","1"],["104291","0.00009588","0","1"],["104233.3","0","0","0"],["104233","0","0","0"],["104232.9","0","0","0"],["104232.7","0","0","0"],["104232.5","0","0","0"]],"ts":"1747170733201","checksum":-605645280,"seqId":54226510353,"prevSeqId":54226510296}]}
{"arg":{"channel":"books","instId":"BTC-USDT"},"action":"update","data":[{"asks":[["104319.9","0","0","0"],["104320.1","0.00479233","0","1"]],"bids":[],"ts":"1747170733301","checksum":-1834818828,"seqId":54226510363,"prevSeqId":54226510353}]}
{"arg":{"channel":"books","instId":"BTC-USDT"},"action":"update","data":[{"asks":[["104319.9","0.00479233","0","1"],["104320.1","0","0","0"],["104323.9","0.37687711","0","4"],["104324.3","0","0","0"],["104324.5","0.0892346","0","1"],["104325","0","0","0"],["104325.5","0.0949835","0","1"],["104326","0.2085775","0","3"],["104326.5","0.02984193","0","1"],["104328.9","0.00479206","0","1"],["104329","0.15510814","0","1"],["104329.4","0.15239278","0","1"],["104329.5","0.60768576","0","3"],["104329.8","0","0","0"],["104330","0.08190006","0","3"],["104330.2","0","0","0"],["104332.3","0.15959392","0","1"],["104332.7","0.77866876","0","1"],["104332.8","0.24863341","0","1"],["104333","0.33249655","0","1"],["104333.2","0","0","0"],["104334.4","0.13990386","0","2"],["104334.5","0.28381266","0","2"],["104334.9","0.26192449","0","1"],["104335","0","0","0"],["104335.3","0","0","0"],["104338.5","0.26542406","0","1"],["104339","0","0","0"],["104534.7","0","0","0"]],"bids":[["104316","0.19737211","0","7"],["104305.5","0","0","0"],["104305","0.19040144","0","3"],["104304","0.19270708","0","5"],["104303.5","0.08846474","0","5"],["104303.3","0","0","0"],["104302.9","0.10261962","0","2"],["104302.3","0.77917433","0","3"],["104302","0","0","0"],["104301.9","0.16643749","0","2"],["104301.5","0.44075233","0","3"],["104300.5","0","0","0"],["104300","0.19247212","0","42"],["104298.5","0","0","0"],["104298.2","0","0","0"],["104297.8","0.25817752","0","1"],["104297.7","0.00110217","0","3"],["104297.3","0.16219389","0","2"],["104296.9","0.00479206","0","1"],["104295.7","0.31940672","0","3"],["104295.5","0","0","0"],["104295","0.25783338","0","1"],["104292.3","0.00549174","0","9"],["104291.9","0.27964996","0","3"],["104291.5","0","0","0"],["104291","0.23887504","0","2"],["104285.7","0.15085198","0","40"],["104273.8","0","0","0"],["104233.3","0.00482005","0","1"],["104233","0.00086083","0","2"],["104232.9","0.00005458","0","1"],["104232.7","0.0000103","0","1"],["104232.5","0.00954475","0","1"],["104232.4","0.00045226","0","2"]],"ts":"1747170733401","checksum":1822044498,"seqId":54226510455,"prevSeqId":54226510363}]}
{"arg":{"channel":"books","instId":"BTC-USDT"},"action":"update","data":[{"asks":[["104326","0.11409956","0","2"],["104326.1","0.09177756","0","1"],["104338.5","0","0","0"],["104338.6","0.2655704","0","1"],["104533.9","0","0","0"]],"bids":[["104316","0.19907211","0","8"],["104303.6","0.09188344","0","1"],["104303.5","0.00035761","0","4"],["104291.1","1.01855531","0","2"],["104291","0.00009588","0","1"],["104273.8","0.00002967","0","1"],["104232.5","0","0","0"],["104232.4","0","0","0"]],"ts":"1747170733501","checksum":1694186214,"seqId":54226510472,"prevSeqId":54226510455}]}
{"arg":{"channel":"books","instId":"BTC-USDT"},"action":"update","data":[{"asks":[["104319.6","0","0","0"],["104319.9","0","0","0"],["104320.1","0.00479227","0","1"],["104323.9","0.38159373","0","4"],["104324.4","0.13187619","0","2"],["104324.5","0","0","0"],["104325","0.0978323","0","1"],["104325.5","0","0","0"],["104326","0.20429242","0","3"],["104326.1","0","0","0"],["104326.4","0.05042096","0","1"],["104326.5","0.1262708","0","2"],["104328.9","0","0","0"],["104329","0","0","0"],["104329.4","0","0","0"],["104329.5","0.59811175","0","3"],["104329.9","0.15587401","0","1"],["104330","0.24788801","0","4"],["104331.6","0.00479206","0","1"],["104332.3","0","0","0"],["104332.8","0.15002291","0","1"],["104333","0.50161656","0","2"],["104333.3","0.24968781","0","1"],["104334.4","0.00093","0","1"],["104334.5","0.04","0","1"],["104334.9","0","0","0"],["104335","0.23986078","0","1"],["104335.4","0.2560689","0","1"],["104336.4","0.13897092","0","1"],["104338.6","0","0","0"],["104339","0.2553617","0","1"],["104533.9","0.03","0","1"]],"bids":[["104316","0.33457211","0","10"],["104305.5","0.19221646","0","2"],["104305","0.00001","0","1"],["104304","0.2877143","0","6"],["104303.6","0","0","0"],["104303.4","0.09597241","0","1"],["104302.9","0.00001032","0","1"],["104302.4","0.15432198","0","1"],["104302","0.16354562","0","1"],["104301.9","0.00120818","0","1"],["104301.5","0.28878224","0","2"],["104300.5","0.16629902","0","1"],["104300","0.04150745","0","41"],["104299.4","0.00479206","0","1"],["104298.3","0.23783498","0","1"],["104297.8","0.15429578","0","1"],["104297.3","0.00014981","0","1"],["104296.9","0","0","0"],["104295.7","0.38371303","0","3"],["104295.5","0.24381536","0","1"],["104295","0","0","0"],["104292.4","0.24615339","0","1"],["104291.9","0.03308723","0","2"],["104291.5","0.23340833","0","1"],["104291.1","0.77866876","0","1"],["104286.9","0.13986505","0","5"],["104285.7","0.01187812","0","39"],["104273.8","0","0","0"],["104234","0","0","0"],["104233.7","0","0","0"],["104233.3","0","0","0"],["104233","0","0","0"],["104232.9","0","0","0"],["104232.7","0","0","0"]],"ts":"1747170733601","checksum":-665709524,"seqId":54226510568,"prevSeqId":54226510472}]}
{"arg":{"channel":"books","instId":"BTC-USDT"},"action":"update","data":[{"asks":[["104316.1","1.10262203","0","14"],["104330.6","0.00479206","0","1"],["104331.6","0","0","0"]],"bids":[["104314.1","0.06576893","0","1"],["104299.4","0","0","0"],["104298.5","0.00479206","0","1"],["104273.8","0.00002967","0","1"],["104234.4","0","0","0"],["104234.3","0","0","0"]],"ts":"1747170733701","checksum":1199848707,"seqId":54226510579,"prevSeqId":54226510568}]}
{"arg":{"channel":"books","instId":"BTC-USDT"},"action":"update","data":[{"asks":[],"bids":[["104314.1","0","0","0"],["104234.4","0.77963354","0","2"]],"ts":"1747170733801","checksum":1912341184,"seqId":54226510581,"prevSeqId":54226510579}]}
{"arg":{"channel":"books","instId":"BTC-USDT"},"action":"update","data":[{"asks":[],"bids":[["104310.1","0","0","0"],["104234.3","0.00028121","0","5"]],"ts":"1747170733901","checksum":1886319472,"seqId":54226510584,"prevSeqId":54226510581}]}
{"arg":{"channel":"books","instId":"BTC-USDT"},"action":"update","data":[{"asks":[["104316.1","1.20137203","0","15"],["104323.9","0.48415469","0","5"],["104324.4","0.03108988","0","1"],["104324.5","0.09570169","0","1"],["104325","0","0","0"],["104325.5","0.09654835","0","1"],["104326","0.11409956","0","2"],["104326.1","0.09893305","0","1"],["104326.5","0.02984193","0","1"],["104329","0.14802179","0","2"],["104329.4","0.15296571","0","1"],["104329.5","0.62307895","0","3"],["104329.9","0","0","0"],["104330","0.08190006","0","3"],["104330.6","0","0","0"],["104332.3","0.14649093","0","1"],["104332.8","0.24669958","0","1"],["104333.2","0.13897428","0","1"],["104333.3","0","0","0"],["104334.5","0.29381811","0","2"],["104334.9","0.25064435","0","1"],["104335","0","0","0"],["104335.4","0","0","0"],["104336.4","0","0","0"],["104338.6","0.26195139","0","1"],["104339","0","0","0"],["104353.7","0.56120425","0","1"],["104356.6","0","0","0"],["104387.9","0","0","0"],["104389.5","6.06790972","0","1"],["104392.9","0","0","0"],["104534.7","0.00094804","0","1"]],"bids":[["104316","0.19908211","0","9"],["104310.1","0.07521043","0","1"],["104305.5","0","0","0"],["104305","0.186435","0","3"],["104304","0.19270708","0","5"],["104303.6","0.08973132","0","1"],["104303.4","0","0","0"],["104302.9","0.09162799","0","2"],["104302.4","0","0","0"],["104302","0","0","0"],["104301.9","0.15209246","0","2"],["104301.5","0.44401674","0","3"],["104300.5","0","0","0"],["104300","0.20450757","0","42"],["104298.5","0","0","0"],["104298.3","0","0","0"],["104297.8","0.24705264","0","1"],["104297.3","0.16368959","0","2"],["104296.9","0.00479206","0","1"],["104295.7","0.32474427","0","3"],["104295.5","0","0","0"],["104295","0.27057964","0","1"],["104292.4","0","0","0"],["104291.9","0.28469554","0","3"],["104291.5","0","0","0"],["104291.1","1.02964915","0","2"],["104286.9","0.00089399","0","4"],["104285.7","0.1508524","0","40"],["104270","0.47121075","0","3"],["104266.2","0.00032044","0","1"],["104234.9","0.00024984","0","5"],["104234","0.00002831","0","2"],["104233.7","0.00003837","0","1"],["104233.3","0.00482005","0","1"],["104233","0.00086083","0","2"],["104232.9","0.00005458","0","1"],["104232.7","0.0000103","0","1"]],"ts":"1747170734001","checksum":-1600270541,"seqId":54226510665,"prevSeqId":54226510584}]}
{"arg":{"channel":"books","instId":"BTC-USDT"},"action":"update","data":[{"asks":[["104319.9","0.00479237","0","1"],["104320.1","0","0","0"],["104329","0.14322973","0","1"],["104329.5","0.62787101","0","4"],["104333.2","0","0","0"],["104334.4","0.13990443","0","2"],["104353.7","0.92195075","0","2"],["104356.6","1.43632344","0","1"],["104386.2","2.4257","0","1"],["104386.8","0.00056666","0","1"],["104387.9","2.56236927","0","1"],["104439.5","0","0","0"],["104440.1","0.00056666","0","1"],["104533.9","0","0","0"],["104534.7","0","0","0"]],"bids":[["104306.8","0.00056666","0","1"],["104306.2","0","0","0"],["104297.9","0.00505465","0","2"],["104296.9","0","0","0"],["104285.7","0.15085299","0","40"],["104265.2","1.89667483","0","4"],["104253.5","0.51303706","0","2"],["104252.9","0","0","0"],["104233.9","2.62046286","0","1"],["104232.5","0.00954475","0","1"]],"ts":"1747170734101","checksum":-1632661676,"seqId":54226510721,"prevSeqId":54226510665}]}
{"arg":{"channel":"books","instId":"BTC-USDT"},"action":"update","data":[{"asks":[["104334.3","0.1389744","0","1"],["104334.4","0.00093","0","1"],["104423.9","0","0","0"],["104475.5","0.00090776","0","1"],["104476.2","0","0","0"]],"bids":[["104273.8","0","0","0"],["104232.4","0.00045226","0","2"]],"ts":"1747170734201","checksum":-1632661676,"seqId":54226510732,"prevSeqId":54226510721}]}
{"arg":{"channel":"books","instId":"BTC-USDT"},"action":"update","data":[{"asks":[["104319.8","0.03448168","0","1"],["104323.9","0.45038146","0","4"],["104337.3","0.01","0","1"],["104340.7","0.039","0","1"],["104532","0","0","0"],["104533.3","0","0","0"]],"bids":[],"ts":"1747170734301","checksum":-1596825690,"seqId":54226510743,"prevSeqId":54226510732}]}
{"arg":{"channel":"books","instId":"BTC-USDT"},"action":"update","data":[{"asks":[["104316.1","1.20087076","0","15"],["104329.5","0.62307895","0","3"],["104329.9","0.00479206","0","1"],["104531.4","0","0","0"]],"bids":[["104298","0.00480206","0","2"],["104297.9","0.00026259","0","1"]],"ts":"1747170734401","checksum":870873049,"seqId":54226510753,"prevSeqId":54226510743}]}
{"arg":{"channel":"books","instId":"BTC-USDT"},"action":"update","data":[{"asks":[],"bids":[["104273.8","0.00002967","0","1"],["104232.4","0","0","0"]],"ts":"1747170734501","checksum":870873049,"seqId":54226510756,"prevSeqId":54226510753}]}
