{"arg":{"channel":"books","instId":"BTC-USDT"},"action":"update","data":[{"asks":[["104509.7","0.13874025","0","1"],["104510.7","0.075","0","2"],["104552.8","0","0","0"],["104553.3","0.00056666","0","1"],["104628.6","0","0","0"]],"bids":[["104463.4","0","0","0"],["104460","0.14094982","0","4"],["104459","0.00955772","0","1"],["104457.5","0","0","0"],["104423.9","0.00056666","0","1"],["104423.4","0.03598865","0","1"],["104337.9","0.00056666","0","1"],["104337.4","0","0","0"]],"ts":"1747171005101","checksum":-1533604415,"seqId":54226721991,"prevSeqId":54226721973}]}
{"arg":{"channel":"books","instId":"BTC-USDT"},"action":"update","data":[{"asks":[["104488","0.49124043","0","12"],["104496.1","0","0","0"],["104496.8","0","0","0"],["104497.7","0.36908178","0","1"],["104498.3","0.00851559","0","1"],["104501.2","0","0","0"],["104501.6","0","0","0"],["104501.8","0","0","0"],["104504.5","0","0","0"],["104505","0.0599306","0","1"],["104506.8","0.03827676","0","1"],["104507.1","0","0","0"],["104509.7","0.1387418","0","1"],["104510.8","0","0","0"],["104537","1.02869923","0","2"],["104628.6","0.0001","0","1"],["104628.7","0.00001176","0","1"],["104628.8","0.07298372","0","1"],["104629.5","0.00010997","0","1"],["104629.6","0.000096","0","1"],["104629.9","0.02300636","0","1"],["104630","0.00039338","0","2"],["104630.2","0.0004067","0","2"]],"bids":[["104487.9","0.40373515","0","10"],["104477.3","0","0","0"],["104477.2","0","0","0"],["104475.8","0","0","0"],["104475.1","0","0","0"],["104474.1","0","0","0"],["104473.7","0","0","0"],["104472.3","0","0","0"],["104470","0.09349006","0","3"],["104469.5","0.17829353","0","1"],["104469.3","0.00478424","0","1"],["104468.1","0","0","0"],["104467.3","0","0","0"],["104464.1","0","0","0"],["104463.3","0.0537761","0","1"],["104460","0.14095023","0","4"],["104295.3","0.001844","0","1"],["104295.1","0.000419","0","1"],["104294.1","0.00001","0","1"],["104291.4","0.77866876","0","1"],["104290.3","0.00005072","0","1"],["104290","0.00028006","0","1"],["104289.4","0.00139512","0","1"],["104288.8","0.000015","0","1"],["104288.6","0.0001","0","1"]],"ts":"1747171005201","checksum":1031392978,"seqId":54226722032,"prevSeqId":54226721991}]}
{"arg":{"channel":"books","instId":"BTC-USDT"},"action":"update","data":[{"asks":[["104496","0","0","0"],["104496.2","0.00011435","0","1"],["104496.3","0.09239678","0","2"],["104497","0.09913482","0","2"],["104498","0.09703429","0","1"],["104498.5","0.32382745","0","2"],["104500.7","0","0","0"],["104501.4","0.00478424","0","1"],["104501.5","0.15492744","0","1"],["104501.8","0.14903801","0","1"],["104502","0.16701003","0","1"],["104504.7","0.14989581","0","1"],["104504.9","0.25659653","0","2"],["104505.2","0.24474383","0","1"],["104507","0.24425625","0","1"],["104507.3","0.247365","0","1"],["104509.7","0.13874104","0","1"],["104511","0.24365142","0","1"],["104537","0.02869923","0","1"],["104627.8","0","0","0"],["104628.6","0","0","0"],["104628.7","0","0","0"],["104628.8","0","0","0"],["104629.5","0","0","0"],["104629.6","0","0","0"],["104629.9","0","0","0"],["104630","0","0","0"],["104630.2","0","0","0"]],"bids":[["104487.9","0.42153515","0","11"],["104478.3","0.21098042","0","2"],["104477.5","0.18202335","0","2"],["104476","0.09408742","0","2"],["104475.3","0.08963542","0","1"],["104474.3","0.17163437","0","2"],["104474","0.14435319","0","1"],["104472.5","0.18103258","0","2"],["104470.2","0.24607632","0","1"],["104469.7","0.16001263","0","2"],["104469.3","0","0","0"],["104467.8","0.31690768","0","2"],["104467.5","0.24426387","0","1"],["104464.3","0.27277355","0","1"],["104463.5","0.25160316","0","1"],["104462","0.13874104","0","1"],["104460","0.00220843","0","3"],["104295.1","0","0","0"],["104294.1","0","0","0"],["104291.4","0","0","0"],["104290.3","0","0","0"],["104290","0","0","0"],["104289.4","0","0","0"],["104288.8","0","0","0"],["104288.6","0","0","0"]],"ts":"1747171005301","checksum":674139157,"seqId":54226722092,"prevSeqId":54226722032}]}
{"arg":{"channel":"books","instId":"BTC-USDT"},"action":"update","data":[{"asks":[["104498.9","0.00478424","0","1"],["104501","0","0","0"],["104501.4","0","0","0"],["104509.7","0","0","0"],["104512.3","0.13873814","0","1"],["104627.8","0.00001104","0","1"]],"bids":[["104469.7","0.15522839","0","1"],["104466.9","0.00478424","0","1"],["104463.7","0.13873814","0","1"],["104462","0","0","0"],["104295.3","0","0","0"]],"ts":"1747171005401","checksum":-462150386,"seqId":54226722101,"prevSeqId":54226722092}]}
{"arg":{"channel":"books","instId":"BTC-USDT"},"action":"update","data":[{"asks":[["104488","0.45841267","0","11"],["104496.2","0.19254407","0","2"],["104497.6","0","0","0"],["104498.9","0","0","0"],["104500.7","0.00478424","0","1"],["104500.9","0.26376353","0","1"],["104512.3","0","0","0"],["104514.7","0.13873506","0","1"],["104518.5","0.000015","0","1"],["104525.8","0.00711203","0","1"]],"bids":[["104487.9","0.43753515","0","12"],["104480.1","0.0022149","0","2"],["104479.4","0","0","0"],["104468.6","0.00479424","0","2"],["104466.9","0","0","0"],["104466.1","0.13873506","0","1"],["104463.7","0","0","0"],["104295.3","0.001844","0","1"],["104295.1","0.000419","0","1"]],"ts":"1747171005501","checksum":615388079,"seqId":54226722123,"prevSeqId":54226722101}]}
{"arg":{"channel":"books","instId":"BTC-USDT"},"action":"update","data":[{"asks":[["104496.1","0.00011435","0","1"],["104496.2","0.19242972","0","1"],["104499.7","0.00478424","0","1"],["104500.7","0","0","0"],["104513.2","0.13873581","0","1"],["104514.7","0","0","0"],["104627.8","0","0","0"]],"bids":[["104468.6","0.00001","0","1"],["104467.9","0.00478424","0","1"],["104466.1","0","0","0"],["104464.4","0.14064581","0","2"]],"ts":"1747171005601","checksum":-1391693748,"seqId":54226722135,"prevSeqId":54226722123}]}
{"arg":{"channel":"books","instId":"BTC-USDT"},"action":"update","data":[{"asks":[["104494.1","0.03113727","0","1"],["104497.9","0","0","0"],["104498.9","0.00478424","0","1"],["104499.7","0","0","0"],["104500.9","0.46439372","0","2"],["104501.4","0.77866876","0","1"],["104524.6","0","0","0"],["104527.7","0","0","0"],["104539","0.16004416","0","3"],["104540","0.73775085","0","10"],["104541","0.05","0","1"],["104542","0.07002848","0","3"],["104543","0.035","0","1"],["104547.6","0","0","0"],["104553.1","0","0","0"],["104572.2","5.72712018","0","1"],["104573.7","0","0","0"],["104592.4","0","0","0"],["104627.8","0.00001104","0","1"],["104628.6","0.0001","0","1"],["104628.7","0.00001176","0","1"],["104628.8","0.07298372","0","1"],["104629.5","0.00010997","0","1"]],"bids":[["104482.6","0","0","0"],["104480.1","0.0005","0","1"],["104479.4","0.0017149","0","1"],["104467.9","0","0","0"],["104466.9","0.00478424","0","1"]],"ts":"1747171005701","checksum":-957815620,"seqId":54226722220,"prevSeqId":54226722135}]}
{"arg":{"channel":"books","instId":"BTC-USDT"},"action":"update","data":[{"asks":[["104494.1","0","0","0"],["104497.4","0.02381239","0","1"],["104502.1","0.00001","0","1"],["104505.6","0.00478556","0","1"],["104509.4","0.01023574","0","2"],["104518","0.002","0","2"],["104519","0.001","0","1"],["104520","0.00330992","0","4"],["104521","0","0","0"],["104540","0.80775085","0","12"],["104541","0.085","0","2"],["104542","0.00002848","0","1"],["104543","0","0","0"]],"bids":[["104487.9","0.41973515","0","11"],["104482.5","0","0","0"],["104480.9","0.06391","0","3"],["104479.7","0.03861361","0","1"],["104476.4","0","0","0"],["104475.9","0.012","0","1"],["104467.8","0.53991883","0","1"],["104464.5","0.36908178","0","1"],["104295.1","0","0","0"]],"ts":"1747171005801","checksum":-1201319948,"seqId":54226722250,"prevSeqId":54226722220}]}
{"arg":{"channel":"books","instId":"BTC-USDT"},"action":"update","data":[{"asks":[["104493.3","0.01913909","0","1"],["104494.6","0.0311371","0","1"],["104497.4","0","0","0"],["104499","0","0","0"],["104500.7","0.77866876","0","1"],["104500.9","0.26376353","0","1"],["104501.2","0.03827818","0","1"],["104501.4","0","0","0"],["104506.8","0","0","0"],["104524.6","0.0957","0","1"],["104527.7","0.0957","0","1"],["104628.8","0","0","0"],["104629.5","0","0","0"]],"bids":[["104483","0.02642564","0","1"],["104479.4","0","0","0"],["104479.3","0","0","0"],["104478.4","0.0017149","0","1"],["104473.8","0","0","0"],["104295.1","0.000419","0","1"]],"ts":"1747171005901","checksum":524904060,"seqId":54226722288,"prevSeqId":54226722250}]}
{"arg":{"channel":"books","instId":"BTC-USDT"},"action":"update","data":[{"asks":[["104488","0.69241267","0","12"],["104496","0.00011435","0","1"],["104496.1","0.38750877","0","1"],["104496.2","0.28531176","0","2"],["104496.3","0.00001","0","1"],["104496.8","0.09068294","0","1"],["104497","0.005","0","1"],["104497.4","0.0047838","0","1"],["104497.5","0","0","0"],["104497.8","0.08996087","0","1"],["104498","0","0","0"],["104498.4","0.09735396","0","1"],["104498.5","0.234","0","1"],["104498.9","0","0","0"],["104500.6","0.37611752","0","1"],["104500.9","0","0","0"],["104501.3","0.1540786","0","3"],["104501.4","0.0383585","0","1"],["104501.5","0","0","0"],["104501.7","0.15476158","0","1"],["104501.8","0.16947458","0","1"],["104502","0","0","0"],["104504.6","0.15606416","0","1"],["104504.7","0","0","0"],["104504.9","0.32480115","0","2"],["104505.1","0.23501498","0","1"],["104505.2","0","0","0"],["104505.7","0.01","0","1"],["104506.8","0.24987055","0","1"],["104507","0","0","0"],["104507.2","0.25974006","0","1"],["104507.3","0","0","0"],["104510.9","0.24665682","0","2"],["104511","0","0","0"],["104520.7","0.0022","0","1"],["104524.6","0","0","0"],["104527.7","0","0","0"],["104538.1","0.0022","0","1"],["104546.2","0.10700298","0","2"],["104546.8","0.00080324","0","1"],["104552.6","0","0","0"],["104590.4","0","0","0"]],"bids":[["104487.9","0.27929853","0","9"],["104479.1","0.0017149","0","1"],["104478.4","0","0","0"],["104478.3","0.25812766","0","2"],["104477.5","0","0","0"],["104477.3","0.2549118","0","3"],["104476","0.000015","0","1"],["104475.9","0.11072319","0","2"],["104475.3","0","0","0"],["104475.2","0.09248024","0","1"],["104474.3","0.1054087","0","2"],["104474.2","0.15348378","0","1"],["104474","0","0","0"],["104473.8","0.15280738","0","1"],["104472.5","0.02929425","0","1"],["104472.3","0.15378649","0","1"],["104470.2","0","0","0"],["104470.1","1.01103361","0","2"],["104469.7","0","0","0"],["104469.6","0.15881698","0","2"],["104467.8","0.52959061","0","2"],["104467.5","0","0","0"],["104467.3","0.25358091","0","1"],["104466.9","0","0","0"],["104465.6","0.0047988","0","2"],["104464.3","0","0","0"],["104464.2","0.3221321","0","2"],["104463.5","0","0","0"],["104463.4","0.24483113","0","1"],["104294.1","0.00001","0","1"],["104291.4","0.77866876","0","1"]],"ts":"1747171006001","checksum":125698534,"seqId":54226722393,"prevSeqId":54226722288}]}
{"arg":{"channel":"books","instId":"BTC-USDT"},"action":"update","data":[{"asks":[["104487.7","0.9003886","0","22"],["104487.8","0.2049467","0","1"],["104488","0.37925","0","8"],["104490.6","0.02600886","0","1"],["104491.5","0.07298372","0","1"],["104492.5","0.00478449","0","1"],["104493.3","0","0","0"],["104495.2","0.00011435","0","1"],["104495.3","0.03828032","0","1"],["104496","0.0383585","0","1"],["104496.1","0.26620993","0","1"],["104496.2","0.19242972","0","1"],["104496.4","0","0","0"],["104496.8","0","0","0"],["104497.4","0","0","0"],["104497.8","0","0","0"],["104498.4","0","0","0"],["104499.2","0","0","0"],["104500.6","0.54556007","0","2"],["104501.2","0","0","0"],["104501.3","0.00009573","0","2"],["104501.4","0","0","0"],["104501.7","0","0","0"],["104501.8","0","0","0"],["104502.5","0.1387521","0","1"],["104504","0.07299898","0","2"],["104504.6","0","0","0"],["104504.9","0.18237532","0","2"],["104505.1","0","0","0"],["104506.8","0","0","0"],["104507.2","0","0","0"],["104509","0.03","0","1"],["104510.9","0.00956633","0","1"],["104513.2","0","0","0"],["104520.4","0.21334084","0","2"],["104520.5","0.4184789","0","2"],["104524.6","0.09571","0","1"],["104525.6","0","0","0"],["104527.6","0","0","0"],["104527.7","0.09571","0","1"],["104529.3","0.00013934","0","1"],["104530.3","0","0","0"],["104540","0.18332185","0","9"],["104541","0.05","0","1"],["104542","0.07002848","0","3"],["104542.4","0","0","0"],["104542.7","0","0","0"],["104543","0.035","0","1"],["104547.9","0.00001","0","1"],["104553.3","0","0","0"],["104553.4","0.00056666","0","1"],["104582.2","0.23360063","0","1"],["104588.9","0.04781","0","1"],["104595.4","0.04146842","0","1"],["104597.9","0","0","0"],["104628.8","0.07298372","0","1"],["104629.5","0.00010997","0","1"],["104629.6","0.000096","0","1"],["104629.9","0.02300636","0","1"],["104630","0.00039338","0","2"],["104630.2","0.0004067","0","2"],["104631.1","0.00001258","0","1"]],"bids":[["104487.9","0","0","0"],["104486.1","0","0","0"],["104486","0","0","0"],["104485.8","0","0","0"],["104484.3","0","0","0"],["104484","0","0","0"],["104483.3","0","0","0"],["104483.1","0","0","0"],["104483","0","0","0"],["104482.3","0.00063489","0","1"],["104482","0","0","0"],["104480.9","0","0","0"],["104479.7","0","0","0"],["104479.5","0.0383585","0","1"],["104479.1","0","0","0"],["104479","0","0","0"],["104478.3","0.05210487","0","1"],["104477.3","0","0","0"],["104475.9","0.012","0","1"],["104475.2","0","0","0"],["104474.3","0.0087017","0","1"],["104474.2","0","0","0"],["104473.8","0","0","0"],["104473.2","0.19242972","0","1"],["104472.7","0","0","0"],["104472.5","0","0","0"],["104472.3","0","0","0"],["104472.2","0.0017149","0","1"],["104472","0.14803423","0","2"],["104471","0","0","0"],["104470.1","0.77866876","0","1"],["104469.6","0.00097","0","1"],["104467.8","0.31740448","0","2"],["104467.3","0","0","0"],["104466.8","0","0","0"],["104465.6","0.000015","0","1"],["104464.5","0","0","0"],["104464.4","0.00191","0","1"],["104464.2","0.07298372","0","1"],["104463.4","0","0","0"],["104461.2","0.00382917","0","1"],["104460.1","0.00478449","0","1"],["104460","0.01176606","0","4"],["104459","0","0","0"],["104453.4","0.13879996","0","2"],["104452.1","1.05442736","0","3"],["104449.1","0","0","0"],["104447.4","0","0","0"],["104445","0.00478519","0","1"],["104441.5","0","0","0"],["104440.9","0","0","0"],["104434","0","0","0"],["104424.5","0.35841135","0","2"],["104424","0.00058166","0","2"],["104423.9","0","0","0"],["104423.2","0.58887","0","1"],["104419.2","2.52218777","0","2"],["104418.7","0","0","0"],["104417.4","0.63816","0","1"],["104415.4","0.45755481","0","2"],["104386.1","0","0","0"],["104380.8","0.0138","0","1"],["104338","0.00056666","0","1"],["104337.9","0","0","0"],["104290.3","0.00005072","0","1"],["104290","0.00028006","0","1"],["104289.4","0.00139512","0","1"],["104288.8","0.000015","0","1"],["104288.6","0.0001","0","1"],["104286.9","0.0008","0","1"],["104286.2","0.00031695","0","2"],["104285.7","0.00020198","0","3"],["104283.3","0.01408652","0","1"],["104282.4","0.07193","0","1"],["104282","0.00009535","0","2"],["104281.6","3.43394024","0","2"],["104281.4","0.00095894","0","1"],["104281.3","0.00001888","0","1"],["104281.2","0.00001019","0","1"],["104281","0.00002601","0","1"],["104280.8","0.00001015","0","1"],["104280.5","0.77880494","0","3"],["104280","0.00451315","0","15"],["104279.6","0.00026802","0","1"],["104279.5","0.00001392","0","1"],["104279.4","0.00021285","0","4"],["104279.1","0.00038358","0","1"],["104279","0.00009722","0","1"],["104278.6","0.00010262","0","1"],["104278.4","0.000015","0","1"]],"ts":"1747171006101","checksum":2067316485,"seqId":54226722947,"prevSeqId":54226722393}]}
{"arg":{"channel":"books","instId":"BTC-USDT"},"action":"update","data":[{"asks":[["104481.1","0.59888348","0","19"],["104481.9","0.09875","0","1"],["104482","0.0932","0","1"],["104482.2","0.57342027","0","1"],["104482.4","0.42108178","0","3"],["104483.4","0.19242972","0","1"],["104484","0.0932","0","1"],["104485.3","0.09474674","0","1"],["104486","0.09256687","0","1"],["104486.1","0.02600996","0","1"],["104487","0.09106404","0","1"],["104487.4","0.02467551","0","1"],["104487.5","0.10005117","0","1"],["104487.6","0.00011435","0","1"],["104487.7","0.04990533","0","3"],["104487.8","0","0","0"],["104489.4","0.02832415","0","1"],["104489.9","0.09594728","0","1"],["104490.2","0.00245","0","2"],["104490.4","0.0383585","0","1"],["104490.5","0.15647324","0","1"],["104490.6","0","0","0"],["104490.8","0.1686073","0","1"],["104491","0.16731125","0","1"],["104491.2","0.01262746","0","2"],["104491.9","0.00478449","0","1"],["104492.3","0.00001","0","1"],["104492.5","0","0","0"],["104493.1","0.04","0","1"],["104493.7","0.154928","0","1"],["104494.2","0.22959016","0","1"],["104495.2","0","0","0"],["104495.5","0.00093","0","1"],["104495.8","0","0","0"],["104496","0.26370204","0","1"],["104496.3","0.2482968","0","2"],["104496.9","0","0","0"],["104497.5","0.000015","0","1"],["104497.6","0.13875764","0","1"],["104499.5","0.04","0","1"],["104499.8","0","0","0"],["104500","0.24606551","0","10"],["104500.4","0.37502163","0","1"],["104500.6","0","0","0"],["104500.7","0.77959876","0","2"],["104501.1","0","0","0"],["104502.5","0","0","0"],["104504.9","0.164596","0","2"],["104505.7","0","0","0"],["104505.9","0.00191","0","1"],["104506.3","0","0","0"],["104507.8","0","0","0"],["104509.1","0.036","0","1"],["104511.1","0.00191","0","1"],["104511.5","0.00287055","0","1"],["104511.9","0.00001","0","1"],["104512.6","0.80030923","0","2"],["104515","0.00204786","0","3"],["104516","0.001","0","1"],["104516.7","0","0","0"],["104518","0","0","0"],["104519","0","0","0"],["104530.5","0.55448","0","1"],["104531.2","0","0","0"],["104537","0.18869922","0","3"],["104538","0.07999999","0","1"],["104539","0.10004416","0","3"],["104540","0.05332186","0","7"],["104541","0","0","0"],["104542.4","0.1","0","1"],["104547.6","0.06699","0","1"],["104562","5.79694018","0","2"],["104572.2","0","0","0"],["104573.7","0.06699","0","1"],["104580.8","0.01059606","0","1"],["104604.6","0.27228449","0","2"],["104610.2","0","0","0"],["104625","0","0","0"],["104625.4","0","0","0"],["104625.6","0","0","0"],["104625.7","0","0","0"],["104625.8","0","0","0"],["104626","0","0","0"],["104626.1","0","0","0"],["104626.8","0","0","0"],["104627.2","0","0","0"],["104627.8","0","0","0"],["104628.6","0","0","0"],["104628.7","0","0","0"],["104628.8","0","0","0"],["104629.5","0","0","0"],["104629.6","0","0","0"],["104629.9","0","0","0"],["104630","0","0","0"],["104630.2","0","0","0"],["104631.1","0","0","0"]],"bids":[["104487.6","0","0","0"],["104482.3","0","0","0"],["104480.5","0","0","0"],["104480.1","0","0","0"],["104480","0.00001","0","1"],["104479.5","0","0","0"],["104478.3","0","0","0"],["104478","0","0","0"],["104476.5","0","0","0"],["104475.9","0","0","0"],["104474.8","0","0","0"],["104474.7","0.01356051","0","1"],["104474.6","0","0","0"],["104474.5","0.0005","0","1"],["104473.5","0.036","0","1"],["104473.2","0","0","0"],["104472.6","0.0017249","0","2"],["104472.2","0","0","0"],["104472.1","0.13125781","0","1"],["104472","0.0932","0","1"],["104471.9","0.036","0","1"],["104471.5","0.02862887","0","1"],["104470.1","0","0","0"],["104469.6","0","0","0"],["104469.5","0","0","0"],["104469.2","0.01716463","0","2"],["104468.8","0.05191","0","2"],["104467.8","0.18065063","0","1"],["104466.5","0.1821711","0","2"],["104465","0.09478007","0","1"],["104464.4","0","0","0"],["104464.3","0.10001452","0","1"],["104464","0.00097","0","1"],["104463.6","0","0","0"],["104463.3","0.22172359","0","2"],["104463","0.14379317","0","1"],["104462.1","0.02929425","0","1"],["104462","0.05483948","0","1"],["104461.5","0.15530575","0","1"],["104461.2","0","0","0"],["104459.2","1.0266025","0","2"],["104458.8","0.00191","0","1"],["104458.7","0.15318734","0","2"],["104456.5","0.26988489","0","1"],["104454","0.17829353","0","1"],["104453.6","0.00191","0","1"],["104453.4","0.00004786","0","1"],["104453.3","0.62349438","0","2"],["104452.5","0.2556345","0","1"],["104449.6","0.33118736","0","2"],["104445","0","0","0"],["104424.6","0","0","0"],["104409.1","0.555134","0","2"],["104402.4","0.234","0","1"],["104368.3","0","0","0"],["104368.1","0.01137149","0","2"],["104365.9","0","0","0"],["104364.8","0.00001","0","1"],["104361.5","0","0","0"],["104357","0.01788979","0","1"],["104340.7","0","0","0"],["104340.6","0","0","0"],["104332.9","0","0","0"],["104331.5","0.05793435","0","1"],["104278.3","0.00079787","0","1"],["104277.8","0.01492147","0","2"],["104277.7","0.00002552","0","1"],["104277.6","0.00017517","0","3"],["104277.4","0.00010004","0","3"],["104277.2","0.00001034","0","1"],["104277.1","0.00001917","0","1"]],"ts":"1747171006201","checksum":867009250,"seqId":54226723515,"prevSeqId":54226722947}]}
{"arg":{"channel":"books","instId":"BTC-USDT"},"action":"update","data":[{"asks":[["104481.1","0.58638348","0","19"],["104482.2","0.35855675","0","1"],["104482.4","0.42968348","0","4"],["104485.3","0","0","0"],["104486","0","0","0"],["104487","0","0","0"],["104487.5","0","0","0"],["104487.7","0.04981533","0","2"],["104489.9","0.23213744","0","2"],["104490.3","0.00478449","0","1"],["104490.5","0","0","0"],["104490.8","0","0","0"],["104491","0","0","0"],["104491.2","0.00262746","0","1"],["104491.9","0","0","0"],["104493.7","0","0","0"],["104494.2","0","0","0"],["104495.9","0.40526555","0","2"],["104496","0","0","0"],["104496.1","0","0","0"],["104496.3","0.00001","0","1"],["104497.6","0","0","0"],["104499.4","0.13875527","0","1"],["104500","0.00330988","0","9"],["104502.5","0.036","0","1"],["104506.6","0.033","0","1"],["104506.7","0.03","0","1"],["104510.6","0.00287065","0","1"],["104510.7","0.036","0","1"],["104511.5","0","0","0"],["104513","0.002","0","2"],["104514","0.001","0","1"],["104514.8","0.40489007","0","3"],["104514.9","0.033","0","1"],["104515","0.00004786","0","1"],["104516","0","0","0"],["104527","1","0","1"],["104527.7","0","0","0"],["104529.3","0","0","0"],["104533.3","0.0059691","0","5"],["104535","0.16","0","2"],["104536","0.08000999","0","2"],["104537","0.02869923","0","1"],["104537.1","0.1","0","1"],["104538","0","0","0"],["104540.3","0","0","0"],["104542.4","0","0","0"],["104547.2","0.14348","0","1"],["104548.6","0.09565","0","1"],["104562","0.06982","0","1"],["104581.9","0.04888089","0","2"],["104604.6","0.234","0","1"],["104625","0.0000103","0","1"],["104625.4","0.00037568","0","2"],["104625.7","0.0001","0","1"],["104625.8","0.00009579","0","1"],["104626","0.01099591","0","1"],["104626.1","0.01488","0","1"]],"bids":[["104481","0.00777545","0","2"],["104478.1","0.09841175","0","1"],["104478","0.0932","0","1"],["104476","0.093215","0","2"],["104474.7","0","0","0"],["104473.7","0.071775","0","1"],["104473.6","0.02464745","0","1"],["104472.6","0.00001","0","1"],["104472.5","0.0383585","0","1"],["104472.2","0.0017149","0","1"],["104472.1","0.1905009","0","2"],["104471.4","0.096707","0","1"],["104470.6","0.02862911","0","1"],["104470.5","0.234","0","1"],["104468","0.0932","0","1"],["104467.8","0.26658509","0","2"],["104466.5","0","0","0"],["104465","0","0","0"],["104464.3","0","0","0"],["104463.3","0","0","0"],["104463","0","0","0"],["104462.6","0.52535184","0","2"],["104461.5","0","0","0"],["104460.2","0.03909025","0","1"],["104460.1","0","0","0"],["104459.2","0.77866876","0","1"],["104458.8","0.00669449","0","2"],["104458.7","0.005","0","1"],["104457.4","0.40869571","0","2"],["104456.5","0","0","0"],["104454.6","0.00382941","0","1"],["104453.3","0.36908178","0","1"],["104452.5","0","0","0"],["104450.7","0.13875527","0","1"],["104449.6","0.37072325","0","2"],["104435.7","0","0","0"],["104428.7","0.00047855","0","1"],["104424.5","0.35844098","0","3"],["104389.3","0","0","0"],["104374","0","0","0"],["104368.3","0.00064003","0","1"],["104368.1","0.01053113","0","1"],["104361","0.00084039","0","1"],["104337.3","0","0","0"],["104277.1","0","0","0"]],"ts":"1747171006301","checksum":-448601154,"seqId":54226723881,"prevSeqId":54226723515}]}
{"arg":{"channel":"books","instId":"BTC-USDT"},"action":"update","data":[{"asks":[["104481.1","0.54048924","0","17"],["104484.3","0.01","0","1"],["104488.7","0.09191101","0","1"],["104489.3","0.0983482","0","1"],["104489.9","0.19606063","0","2"],["104490.3","0.09774184","0","1"],["104490.8","0.0996577","0","1"],["104493","0.00478449","0","1"],["104493.8","0.16105149","0","1"],["104494.2","0.15530407","0","1"],["104494.3","0.15563585","0","1"],["104495.9","0.28434292","0","1"],["104497.1","0.14719475","0","1"],["104497.5","0.25779055","0","2"],["104499.3","0.25197012","0","1"],["104499.4","0","0","0"],["104499.7","0.27377185","0","1"],["104502","0.13875214","0","1"],["104503.3","0.25944216","0","1"],["104510.2","0.07465265","0","2"],["104510.6","0","0","0"],["104510.7","0","0","0"],["104511","0.002","0","2"],["104512","0.001","0","1"],["104512.6","0.77866876","0","1"],["104513","0","0","0"],["104514","0","0","0"],["104514.8","0.36889007","0","2"],["104514.9","0","0","0"],["104521.4","0.27400353","0","2"],["104533","0.16","0","2"],["104534","0.37242971","0","4"],["104535","0.05","0","1"],["104535.8","0.87866876","0","2"],["104536","0.00001","0","1"],["104537.1","0","0","0"],["104539","0.00004416","0","1"],["104540","0.00332186","0","6"],["104572.2","5.69114754","0","1"],["104590.4","0.0000949","0","1"],["104595.5","0","0","0"],["104622.1","0","0","0"],["104623.3","0","0","0"],["104623.4","0","0","0"],["104623.6","0","0","0"],["104625","0","0","0"],["104625.4","0","0","0"],["104625.7","0","0","0"],["104625.8","0","0","0"],["104626","0","0","0"],["104626.1","0","0","0"]],"bids":[["104481","0.12736545","0","4"],["104480","0.09321","0","2"],["104478.1","0","0","0"],["104476","0.0932","0","1"],["104472.1","0.27071386","0","1"],["104471.5","0","0","0"],["104469.8","0.18010132","0","2"],["104468.3","0.09233693","0","1"],["104467.9","0.04193458","0","1"],["104467.8","0.18519628","0","2"],["104467.7","0.09458231","0","1"],["104466.7","0.16062303","0","1"],["104466.3","0.16092077","0","1"],["104464.8","0.1647941","0","1"],["104462.5","0.28421105","0","2"],["104462.1","0.19093122","0","3"],["104460.3","0.00478449","0","1"],["104459.8","0.2689653","0","1"],["104458.8","0.00191","0","1"],["104457.4","0.40716632","0","2"],["104456.7","0.23925064","0","2"],["104455.8","0.33108362","0","2"],["104453.4","0.1388","0","2"],["104450.7","0","0","0"],["104424.5","0.35841135","0","2"],["104278.3","0","0","0"],["104277.8","0","0","0"],["104277.7","0","0","0"],["104277.6","0","0","0"],["104277.4","0","0","0"],["104277.2","0","0","0"]],"ts":"1747171006401","checksum":-1467468712,"seqId":54226724134,"prevSeqId":54226723881}]}
{"arg":{"channel":"books","instId":"BTC-USDT"},"action":"update","data":[{"asks":[["104481.1","0.50013434","0","14"],["104482.4","0.41368348","0","3"],["104486.1","0","0","0"],["104488.7","0","0","0"],["104489.2","0.09883168","0","1"],["104489.3","0.02467504","0","1"],["104489.9","0.23055852","0","2"],["104490.3","0","0","0"],["104490.8","0","0","0"],["104490.9","0.09418852","0","1"],["104491.4","0.09502761","0","1"],["104493.8","0","0","0"],["104494.2","0","0","0"],["104494.3","0","0","0"],["104494.4","0.1597423","0","1"],["104494.7","0.16198917","0","1"],["104494.8","0.42856343","0","1"],["104494.9","0.16709953","0","1"],["104495.9","0","0","0"],["104497.1","0","0","0"],["104497.5","0.000015","0","1"],["104497.6","0.1607235","0","1"],["104498.1","0.25161144","0","1"],["104499.3","0","0","0"],["104499.6","0.6015777","0","2"],["104499.7","0","0","0"],["104499.9","0.25773455","0","1"],["104500.2","0.26382971","0","1"],["104500.4","0","0","0"],["104503.3","0","0","0"],["104503.9","0.23448719","0","2"],["104513.2","0.0001303","0","1"],["104519.8","0","0","0"],["104526.2","0.02164047","0","1"],["104534","0.44242971","0","6"],["104535","0.085","0","2"],["104542","0.00002848","0","1"],["104543","0","0","0"],["104568.8","5.69114754","0","1"],["104572.2","0","0","0"],["104622.1","0.0140803","0","1"]],"bids":[["104481","0.23928883","0","5"],["104475.4","0.02464703","0","1"],["104470.4","0.18031011","0","2"],["104469.8","0","0","0"],["104468.9","0.09983814","0","1"],["104468.3","0","0","0"],["104468.2","0.09078017","0","1"],["104467.9","0","0","0"],["104467.8","0.27324056","0","2"],["104467.7","0","0","0"],["104467.2","0.16469575","0","1"],["104466.9","0.14476336","0","1"],["104466.7","0","0","0"],["104466.3","0","0","0"],["104465.4","0.15923328","0","1"],["104464.8","0","0","0"],["104463.1","0.27091468","0","2"],["104462.6","0.68253435","0","3"],["104462.5","0.03","0","1"],["104462.1","0.04010414","0","2"],["104460.4","0.24830487","0","1"],["104459.8","0","0","0"],["104457.2","0.27259845","0","1"],["104456.7","0.00001","0","1"],["104456.4","0.23609363","0","1"],["104455.8","0.07298372","0","1"],["104417.7","0.00002963","0","1"],["104381.4","0.00010529","0","1"],["104328.4","0.0009569","0","1"],["104279.4","0","0","0"],["104279.1","0","0","0"],["104279","0","0","0"],["104278.6","0","0","0"],["104278.4","0","0","0"]],"ts":"1747171006501","checksum":-1327078253,"seqId":54226724223,"prevSeqId":54226724134}]}
{"arg":{"channel":"books","instId":"BTC-USDT"},"action":"update","data":[{"asks":[["104481.1","0.44019872","0","14"],["104481.9","0","0","0"],["104483.4","0","0","0"],["104487.6","0","0","0"],["104487.7","0.03832933","0","1"],["104487.9","0.00011435","0","1"],["104489.2","0","0","0"],["104489.4","0.12280542","0","2"],["104489.9","0.13894282","0","1"],["104490.1","0.10184365","0","2"],["104490.9","0","0","0"],["104491.1","0.0923244","0","1"],["104491.4","0","0","0"],["104491.6","0.09925489","0","1"],["104494.4","0","0","0"],["104494.6","0.18483663","0","2"],["104494.7","0","0","0"],["104494.8","0.44158659","0","2"],["104494.9","0.15506065","0","1"],["104495.1","0.15890178","0","2"],["104497.6","0","0","0"],["104497.8","0.15815952","0","1"],["104498.1","0","0","0"],["104498.3","0.26542533","0","2"],["104499.6","0.42844324","0","1"],["104499.9","0","0","0"],["104500.1","0.25412015","0","1"],["104500.2","0","0","0"],["104500.4","0.26122054","0","1"],["104502","0","0","0"],["104502.4","0.1387507","0","1"],["104503.9","0.00041858","0","1"],["104504.1","0.25570776","0","1"],["104527","0","0","0"],["104623.3","0.03","0","1"],["104623.4","0.00001","0","1"],["104623.6","0.00083722","0","2"],["104625","0.0000103","0","1"],["104625.4","0.00037568","0","2"],["104625.6","0.234","0","1"]],"bids":[["104481","0.44005321","0","6"],["104480.1","0.13533004","0","1"],["104470.6","0.22538688","0","3"],["104470.4","0","0","0"],["104469.1","0.09507974","0","1"],["104468.9","0","0","0"],["104468.4","0.10249242","0","1"],["104468.2","0","0","0"],["104467.8","0.3211142","0","2"],["104467.4","0.16954961","0","1"],["104467.2","0","0","0"],["104467.1","0.14400757","0","1"],["104466.9","0","0","0"],["104465.9","0.01080989","0","1"],["104465.6","0.16453055","0","2"],["104465.4","0","0","0"],["104463.3","0.22944521","0","1"],["104463.1","0.03","0","1"],["104462.8","0.16166793","0","1"],["104462.6","0.52535184","0","2"],["104460.6","0.256366","0","1"],["104460.4","0","0","0"],["104457.4","0.65092753","0","3"],["104457.2","0","0","0"],["104456.6","0.24481982","0","1"],["104456.4","0","0","0"],["104454.1","0.1387507","0","1"],["104453.4","0.00004786","0","1"],["104439.1","0.00478582","0","1"],["104423.2","0.63819348","0","2"],["104313.9","0","0","0"],["104304.2","0.0001844","0","1"],["104280","0","0","0"],["104279.6","0","0","0"],["104279.5","0","0","0"]],"ts":"1747171006601","checksum":1685765363,"seqId":54226724320,"prevSeqId":54226724223}]}
{"arg":{"channel":"books","instId":"BTC-USDT"},"action":"update","data":[{"asks":[["104482.4","0.40508178","0","2"],["104489.3","0","0","0"],["104490","0.21738986","0","5"],["104490.1","0.005","0","1"],["104491","0.08858823","0","1"],["104491.1","0","0","0"],["104494.5","0.15923188","0","1"],["104494.6","0.0311371","0","1"],["104495","0.15909718","0","1"],["104495.1","0.00004789","0","1"],["104500","0.24645731","0","10"],["104500.1","0","0","0"],["104511","0","0","0"],["104512","0","0","0"],["104513","0.002","0","2"],["104514","0.001","0","1"],["104533","0","0","0"],["104534","0.19242972","0","1"],["104535","0.23","0","4"],["104536","0.21500999","0","5"],["104537","0.07869923","0","2"],["104582.8","0.12","0","1"],["104625.6","0","0","0"],["104625.7","0.0001","0","1"]],"bids":[["104481","0.32055321","0","5"],["104477.2","0.02464658","0","1"],["104475.4","0","0","0"],["104470.6","0.02862911","0","1"],["104470.5","0.41516104","0","3"],["104467.1","0","0","0"],["104467","0.14440925","0","1"],["104465.6","0.000015","0","1"],["104465.5","0.15110151","0","2"],["104460.6","0","0","0"],["104460.5","0.26343441","0","1"]],"ts":"1747171006701","checksum":-1845266438,"seqId":54226724380,"prevSeqId":54226724320}]}
{"arg":{"channel":"books","instId":"BTC-USDT"},"action":"update","data":[{"asks":[["104499.6","0.60291012","0","2"],["104558.6","5.69114754","0","1"],["104568.8","0","0","0"],["104625.6","0.234","0","1"],["104625.7","0","0","0"]],"bids":[],"ts":"1747171006801","checksum":-1845266438,"seqId":54226724410,"prevSeqId":54226724380}]}
{"arg":{"channel":"books","instId":"BTC-USDT"},"action":"update","data":[{"asks":[["104489.3","0.09828783","0","1"],["104489.4","0.02832415","0","1"],["104489.9","0.23641614","0","2"],["104490","0.11816494","0","4"],["104490.9","0.08567313","0","1"],["104491","0","0","0"],["104491.4","0.09519583","0","1"],["104491.6","0","0","0"],["104494.4","0.15429541","0","1"],["104494.5","0","0","0"],["104494.8","0.55213754","0","3"],["104494.9","0.17001265","0","1"],["104495","0","0","0"],["104497.7","0.52960601","0","2"],["104497.8","0","0","0"],["104498.2","0.25124387","0","1"],["104498.3","0.00851559","0","1"],["104499.6","0.60455751","0","2"],["104499.9","0.24188213","0","1"],["104500","0.00330988","0","9"],["104500.3","0.27062162","0","2"],["104500.4","0","0","0"],["104502.4","0","0","0"],["104503.6","0.13874974","0","1"],["104503.9","0.25349432","0","2"],["104504.1","0","0","0"],["104509.4","0.00023574","0","1"],["104511","0.002","0","2"],["104512","0.001","0","1"],["104513","0","0","0"],["104514","0","0","0"],["104533","0.16","0","2"],["104534","0.44242971","0","6"],["104535","0.085","0","2"],["104536","0.00001","0","1"],["104537","0.02869923","0","1"]],"bids":[["104481","0.23928883","0","5"],["104470.5","0.234","0","1"],["104470.4","0.17576339","0","2"],["104469.1","0","0","0"],["104468.9","0.09423171","0","1"],["104468.4","0","0","0"],["104468.3","0.10091505","0","1"],["104467.8","0.26996841","0","2"],["104467.4","0","0","0"],["104467.3","0.15125199","0","1"],["104467","0","0","0"],["104466.9","0.14243291","0","1"],["104465.5","0.002","0","1"],["104465.4","0.16124388","0","1"],["104463.3","0","0","0"],["104463.2","0.23301122","0","2"],["104462.8","0","0","0"],["104462.7","0.1524072","0","1"],["104460.5","0","0","0"],["104460.4","0.26615758","0","1"],["104457.4","0.40716632","0","2"],["104457.3","0.27075162","0","1"],["104456.6","0","0","0"],["104456.4","0.24570968","0","1"],["104454.1","0.13874974","0","1"],["104280.8","0","0","0"],["104280.5","0","0","0"]],"ts":"1747171006901","checksum":273844153,"seqId":54226724497,"prevSeqId":54226724410}]}
{"arg":{"channel":"books","instId":"BTC-USDT"},"action":"update","data":[{"asks":[["104485.7","0.19242972","0","1"],["104625.6","0","0","0"]],"bids":[["104468.8","0.05286722","0","3"]],"ts":"1747171007001","checksum":-1157080133,"seqId":54226724501,"prevSeqId":54226724497}]}
{"arg":{"channel":"books","instId":"BTC-USDT"},"action":"update","data":[{"asks":[["104481.1","0.40419872","0","13"],["104488","0.36325","0","7"],["104489.9","0.13894282","0","1"],["104490","0.2203958","0","5"],["104490.9","0","0","0"],["104491","0.08662222","0","1"],["104491.4","0","0","0"],["104491.5","0.16814814","0","2"],["104494.4","0","0","0"],["104494.5","0.15016887","0","1"],["104494.9","0","0","0"],["104495","0.15236419","0","1"],["104497","0","0","0"],["104499.9","0","0","0"],["104500","0.26761808","0","10"],["104503.9","0.00041858","0","1"],["104504","0.31480084","0","3"],["104512.1","0.0001303","0","1"],["104513.2","0","0","0"],["104545.7","0.00056666","0","1"],["104553.4","0","0","0"],["104558.6","0","0","0"],["104565.4","5.69114754","0","1"],["104625.6","0.234","0","1"],["104625.7","0.0001","0","1"],["104625.8","0.00009579","0","1"]],"bids":[["104481","0.27528883","0","6"],["104470.5","0.41053385","0","3"],["104470.4","0","0","0"],["104469","0.09925244","0","1"],["104468.9","0","0","0"],["104467.8","0.17886537","0","1"],["104467","0.14884846","0","1"],["104466.9","0","0","0"],["104465.5","0.16037243","0","2"],["104465.4","0","0","0"],["104460.6","0.00955758","0","1"],["104460.5","0.26841036","0","1"],["104460.4","0","0","0"],["104460","0.00220843","0","3"],["104456.5","0.2462237","0","1"],["104456.4","0","0","0"],["104424","0.000015","0","1"],["104419.3","1.33850018","0","1"],["104416.4","0.00056666","0","1"],["104406.8","0","0","0"],["104338","0","0","0"],["104330.4","0.00058166","0","2"],["104280.8","0.00001015","0","1"],["104280.5","0.77880494","0","3"]],"ts":"1747171007101","checksum":656193003,"seqId":54226724555,"prevSeqId":54226724501}]}
{"arg":{"channel":"books","instId":"BTC-USDT"},"action":"update","data":[{"asks":[["104481.1","0.39718072","0","12"],["104482.2","0","0","0"],["104488.4","0.00001","0","1"],["104489.3","0","0","0"],["104489.4","0.12909889","0","2"],["104490","0.11816494","0","4"],["104490.1","0.10525754","0","2"],["104491","0","0","0"],["104491.1","0.08981144","0","1"],["104491.5","0.07298372","0","1"],["104491.6","0.08952824","0","1"],["104494.5","0","0","0"],["104494.6","0.1887785","0","2"],["104494.8","0.25473309","0","1"],["104494.9","0.15101081","0","1"],["104495","0","0","0"],["104495.1","0.1571416","0","2"],["104497.7","0.36908178","0","1"],["104497.8","0.159859","0","1"],["104498.2","0","0","0"],["104498.3","0.25799287","0","2"],["104499.6","0.42844324","0","1"],["104500","0.00330988","0","9"],["104500.1","0.26932658","0","1"],["104500.3","0.00001","0","1"],["104500.4","0.25990189","0","1"],["104504","0.07299898","0","2"],["104504.1","0.26332387","0","1"],["104565.4","0","0","0"],["104572.2","5.69114754","0","1"],["104588.8","0.00009173","0","1"],["104590.4","0","0","0"],["104625.7","0","0","0"],["104625.8","0","0","0"]],"bids":[["104481","0.44055321","0","7"],["104475.2","0.07298372","0","1"],["104470.6","0.2081051","0","3"],["104470.5","0.234","0","1"],["104469.1","0.09524683","0","1"],["104469","0","0","0"],["104468.4","0.09257819","0","1"],["104468.3","0","0","0"],["104467.8","0.08121827","0","1"],["104467.4","0.16095226","0","1"],["104467.3","0","0","0"],["104467.1","0.15653045","0","1"],["104467","0","0","0"],["104465.6","0.15146622","0","2"],["104465.5","0.002","0","1"],["104463.3","0.23176189","0","1"],["104463.2","0.00005","0","1"],["104462.8","0.14872378","0","1"],["104462.7","0","0","0"],["104460.6","0.25781512","0","2"],["104460.5","0","0","0"],["104457.4","0.64976693","0","3"],["104457.3","0","0","0"],["104456.6","0.24203226","0","1"],["104456.5","0","0","0"],["104355","0.00001","0","1"],["104280.5","0","0","0"]],"ts":"1747171007201","checksum":-379483264,"seqId":54226724629,"prevSeqId":54226724555}]}
{"arg":{"channel":"books","instId":"BTC-USDT"},"action":"update","data":[{"asks":[["104481.1","0.43318072","0","13"],["104493","0","0","0"],["104494.5","0.00478449","0","1"],["104494.8","0.43662369","0","2"],["104499.6","0.61265282","0","2"],["104512.1","0","0","0"],["104568.8","5.69114754","0","1"],["104572.2","0","0","0"],["104588.8","0","0","0"],["104625.7","0.0001","0","1"],["104625.8","0.00009579","0","1"]],"bids":[["104481","0.44860321","0","8"],["104467.8","0.31968518","0","2"],["104461","0.00478449","0","1"],["104460.3","0","0","0"]],"ts":"1747171007301","checksum":-78734862,"seqId":54226724652,"prevSeqId":54226724629}]}
{"arg":{"channel":"books","instId":"BTC-USDT"},"action":"update","data":[{"asks":[["104535.7","0.469538","0","1"],["104539.1","0","0","0"],["104570.4","0.01052914","0","1"],["104588.8","0.00009173","0","1"]],"bids":[["104473.8","0.0017149","0","1"],["104473","0.19242972","0","1"],["104472.2","0","0","0"],["104472.1","0.53757043","0","2"],["104470.7","0.77866876","0","1"],["104452.1","0.51976689","0","2"],["104450.6","0","0","0"],["104419.3","0","0","0"],["104419.2","0.05372229","0","1"]],"ts":"1747171007401","checksum":909059575,"seqId":54226724667,"prevSeqId":54226724652}]}
{"arg":{"channel":"books","instId":"BTC-USDT"},"action":"update","data":[{"asks":[["104481.1","0.44945369","0","14"],["104483.2","0.005","0","1"],["104486.4","0.01627297","0","1"],["104495.7","0.0058","0","2"],["104511.9","0.0001403","0","2"],["104529","1.37333789","0","2"],["104560.3","2.54143182","0","2"],["104625.7","0","0","0"],["104625.8","0","0","0"]],"bids":[["104462.1","0.02929425","0","1"],["104440.9","1.41272073","0","1"],["104431.8","0.005","0","1"],["104419.3","0.005","0","1"],["104409.6","2.60088605","0","1"],["104281.3","0","0","0"],["104281.2","0","0","0"],["104281","0","0","0"],["104280.8","0","0","0"]],"ts":"1747171007501","checksum":-759170810,"seqId":54226724684,"prevSeqId":54226724667}]}
{"arg":{"channel":"books","instId":"BTC-USDT"},"action":"update","data":[{"asks":[["104527","1","0","1"],["104562","5.76096754","0","2"],["104568.8","0","0","0"]],"bids":[],"ts":"1747171007601","checksum":-759170810,"seqId":54226724690,"prevSeqId":54226724684}]}
{"arg":{"channel":"books","instId":"BTC-USDT"},"action":"update","data":[{"asks":[["104489.7","0.02467496","0","1"],["104490","0.09349006","0","3"],["104625.6","0","0","0"]],"bids":[["104481","0.44055321","0","7"]],"ts":"1747171007701","checksum":-13661077,"seqId":54226724696,"prevSeqId":54226724690}]}
{"arg":{"channel":"books","instId":"BTC-USDT"},"action":"update","data":[{"asks":[["104511","0","0","0"],["104512","0","0","0"],["104513","0.002","0","2"],["104514","0.001","0","1"],["104533","0","0","0"],["104534","0.19242972","0","1"],["104535","0.23","0","4"],["104536","0.21500999","0","5"],["104537","0.07869923","0","2"],["104625.6","0.234","0","1"]],"bids":[],"ts":"1747171007801","checksum":-13661077,"seqId":54226724720,"prevSeqId":54226724696}]}
{"arg":{"channel":"books","instId":"BTC-USDT"},"action":"update","data":[{"asks":[["104530.4","0.6806587","0","1"],["104531","0","0","0"],["104561.9","0.65925389","0","2"]],"bids":[["104441.6","0.9444356","0","3"],["104410.1","1.4255918","0","2"]],"ts":"1747171008001","checksum":-13661077,"seqId":54226724839,"prevSeqId":54226724720}]}
{"arg":{"channel":"books","instId":"BTC-USDT"},"action":"update","data":[{"asks":[["104489.2","0.10119449","0","1"],["104489.4","0.02832415","0","1"],["104489.9","0.24086639","0","2"],["104490.1","0.005","0","1"],["104490.9","0.09043784","0","1"],["104491.1","0","0","0"],["104491.4","0.09735097","0","1"],["104491.6","0","0","0"],["104494.4","0.14272686","0","1"],["104494.6","0.0311371","0","1"],["104494.7","0.16706076","0","1"],["104494.8","0.39040968","0","2"],["104494.9","0.1622228","0","1"],["104495.1","0.00004789","0","1"],["104497.7","0.5165528","0","2"],["104497.8","0","0","0"],["104498.1","0.24870026","0","1"],["104498.3","0.00851559","0","1"],["104499.9","0.25162409","0","1"],["104500.1","0","0","0"],["104500.2","0.25622375","0","1"],["104500.4","0","0","0"],["104503.9","0.26798423","0","2"],["104504.1","0","0","0"],["104511","0.002","0","2"],["104512","0.001","0","1"],["104513","0","0","0"],["104514","0","0","0"],["104533","0.16","0","2"],["104534","0.44242971","0","6"],["104535","0.085","0","2"],["104536","0.00001","0","1"],["104537","0.02869923","0","1"],["104545.7","0","0","0"],["104546.1","0.19299638","0","2"],["104625.4","0","0","0"],["104625.6","0","0","0"]],"bids":[["104481","0.20912983","0","5"],["104470.6","0.02862911","0","1"],["104470.4","0.18804942","0","2"],["104469.1","0","0","0"],["104468.9","0.09569985","0","1"],["104468.4","0","0","0"],["104468.2","0.09667675","0","1"],["104467.8","0.2714899","0","2"],["104467.4","0","0","0"],["104467.2","0.15948026","0","1"],["104467.1","0","0","0"],["104466.9","0.15029784","0","1"],["104465.6","0.000015","0","1"],["104465.4","0.160614","0","1"],["104463.3","0","0","0"],["104463.1","0.28465442","0","2"],["104462.8","0","0","0"],["104462.7","0.17172212","0","2"],["104461.2","0.00955752","0","1"],["104461","0","0","0"],["104460.6","0","0","0"],["104460.4","0.27198311","0","1"],["104457.4","0.40716632","0","2"],["104457.2","0.25065193","0","1"],["104456.6","0","0","0"],["104456.4","0.26071207","0","1"],["104455.9","0.13874854","0","1"],["104454.1","0","0","0"],["104416.9","0.77923542","0","2"],["104416.4","0","0","0"],["104368.3","0","0","0"],["104368.1","0.01117109","0","2"],["104330.9","0.00056666","0","1"],["104330.4","0.000015","0","1"],["104281.4","0","0","0"]],"ts":"1747171008101","checksum":1265809023,"seqId":54226724958,"prevSeqId":54226724839}]}
{"arg":{"channel":"books","instId":"BTC-USDT"},"action":"update","data":[{"asks":[["104503.6","0","0","0"],["104503.8","0.13874831","0","1"],["104511","0","0","0"],["104512","0","0","0"],["104513","0.002","0","2"],["104514","0.001","0","1"],["104519.8","0.00013934","0","1"],["104533","0","0","0"],["104534","0.26242972","0","3"],["104535","0.195","0","3"],["104536","0.18000999","0","4"],["104537","0.07869923","0","2"]],"bids":[["104481","0.21514983","0","6"],["104456.5","0.13874831","0","1"],["104455.9","0","0","0"],["104382.1","0.00009665","0","1"],["104381.4","0","0","0"],["104329.9","0.00095687","0","1"],["104328.4","0","0","0"]],"ts":"1747171008201","checksum":822584353,"seqId":54226724998,"prevSeqId":54226724958}]}
{"arg":{"channel":"books","instId":"BTC-USDT"},"action":"update","data":[{"asks":[["104493","0.00478449","0","1"],["104494.5","0","0","0"],["104503.8","0.13874827","0","1"],["104511","0.002","0","2"],["104512","0.001","0","1"],["104513","0","0","0"],["104514","0","0","0"],["104533","0.16","0","2"],["104534","0.44242971","0","6"],["104535","0.085","0","2"],["104536","0.00001","0","1"],["104537","0.02869923","0","1"],["104625","0","0","0"]],"bids":[["104462.7","0.16693763","0","1"],["104460.5","0.00478449","0","1"],["104456.5","0.13874827","0","1"],["104281.6","0","0","0"]],"ts":"1747171008301","checksum":822584353,"seqId":54226725028,"prevSeqId":54226724998}]}
{"arg":{"channel":"books","instId":"BTC-USDT"},"action":"update","data":[{"asks":[["104503.6","0.13874862","0","1"],["104503.8","0","0","0"],["104520.4","0.19242972","0","1"],["104533.3","0.02688022","0","6"]],"bids":[["104472.5","0","0","0"],["104456.5","0","0","0"],["104455.9","0.13874862","0","1"],["104281.6","3.43394024","0","2"]],"ts":"1747171008401","checksum":-1707962592,"seqId":54226725035,"prevSeqId":54226725028}]}
{"arg":{"channel":"books","instId":"BTC-USDT"},"action":"update","data":[{"asks":[],"bids":[["104477.1","0.0383585","0","1"],["104281.6","0","0","0"]],"ts":"1747171008501","checksum":-1471385001,"seqId":54226725040,"prevSeqId":54226725035}]}
{"arg":{"channel":"books","instId":"BTC-USDT"},"action":"update","data":[{"asks":[["104489.2","0","0","0"],["104489.4","0.12920289","0","2"],["104489.9","0.13894282","0","1"],["104490.1","0.09939084","0","2"],["104490.9","0","0","0"],["104491.1","0.09278814","0","1"],["104491.4","0","0","0"],["104491.6","0.09966669","0","1"],["104494.4","0","0","0"],["104494.6","0.18670875","0","2"],["104494.7","0","0","0"],["104494.9","0.16338148","0","1"],["104495.1","0.16090617","0","2"],["104497.7","0.36908178","0","1"],["104497.8","0.15088379","0","1"],["104498.1","0","0","0"],["104498.3","0.25080857","0","2"],["104499.6","0.60664509","0","2"],["104499.9","0","0","0"],["104500.1","0.25034766","0","1"],["104500.2","0","0","0"],["104500.4","0.2650269","0","1"],["104503.9","0.00041858","0","1"],["104504.1","0.25715316","0","1"],["104562","0.06982","0","1"],["104565.4","5.83350634","0","1"],["104625","0.0000103","0","1"]],"bids":[["104481","0.37941421","0","8"],["104470.6","0.21561162","0","3"],["104470.4","0","0","0"],["104469.1","0.10030648","0","1"],["104468.9","0","0","0"],["104468.4","0.09500464","0","1"],["104468.2","0","0","0"],["104467.8","0.22453892","0","2"],["104467.4","0.15638076","0","1"],["104467.2","0","0","0"],["104467.1","0.16073407","0","1"],["104466.9","0","0","0"],["104465.6","0.15606119","0","2"],["104465.4","0","0","0"],["104463.3","0.2289995","0","1"],["104463.1","0.03","0","1"],["104462.8","0.15296246","0","1"],["104462.7","0","0","0"],["104460.7","0.00479449","0","2"],["104460.6","0.25622666","0","1"],["104460.5","0","0","0"],["104460.4","0","0","0"],["104457.4","0.66181892","0","3"],["104457.2","0","0","0"],["104456.6","0.24431608","0","1"],["104456.4","0","0","0"],["104442.3","0.286","0","3"],["104281.6","3.43394024","0","2"],["104281.4","0.00095894","0","1"],["104281.3","0.00001888","0","1"]],"ts":"1747171008601","checksum":-741711297,"seqId":54226725113,"prevSeqId":54226725040}]}
{"arg":{"channel":"books","instId":"BTC-USDT"},"action":"update","data":[{"asks":[["104488.5","0.02335854","0","1"],["104489.3","0.09313351","0","1"],["104489.4","0.02832415","0","1"],["104489.5","0.12247256","0","1"],["104489.6","0.0552646","0","1"],["104489.7","0","0","0"],["104489.9","0.09150849","0","1"],["104490.1","0.005","0","1"],["104490.9","0.0971843","0","1"],["104491.1","0","0","0"],["104491.5","0.17326594","0","2"],["104491.6","0","0","0"],["104494.4","0.15593883","0","1"],["104494.6","0.0311371","0","1"],["104494.8","0.42342268","0","2"],["104494.9","0.1679557","0","1"],["104495.1","0.00004789","0","1"],["104497.7","0.51508018","0","2"],["104497.8","0","0","0"],["104498.2","0.23620017","0","1"],["104498.3","0.00851559","0","1"],["104499.6","0.42844324","0","1"],["104499.9","0.26844663","0","1"],["104500.1","0","0","0"],["104500.3","0.24860466","0","2"],["104500.4","0","0","0"],["104500.8","0","0","0"],["104504","0.31736126","0","3"],["104504.1","0","0","0"],["104527","0","0","0"],["104562","5.90332634","0","2"],["104565.4","0","0","0"],["104625.4","0.00037568","0","2"],["104625.6","0.234","0","1"]],"bids":[["104481","0.25389421","0","6"],["104477.2","0","0","0"],["104476.3","0.03004756","0","1"],["104470.6","0","0","0"],["104470.4","0.19623943","0","2"],["104469.1","0","0","0"],["104469","0.09709854","0","1"],["104468.4","0","0","0"],["104468.3","0.13884918","0","2"],["104467.8","0.07501158","0","1"],["104467.4","0","0","0"],["104467.3","0.15787542","0","1"],["104467.1","0","0","0"],["104466.9","0.14322472","0","1"],["104465.6","0.000015","0","1"],["104465.4","0.16393413","0","1"],["104463.3","0","0","0"],["104463.2","0.22872957","0","2"],["104462.8","0","0","0"],["104462.7","0.14921262","0","1"],["104460.7","0.00001","0","1"],["104460.6","0","0","0"],["104460.4","0.26557134","0","1"],["104460.3","0.00478449","0","1"],["104457.4","0.40716632","0","2"],["104457.3","0.24994907","0","1"],["104456.6","0","0","0"],["104456.5","0.25729466","0","1"],["104363.4","0.43409821","0","1"],["104361.8","0","0","0"],["104281.4","0","0","0"],["104281.3","0","0","0"]],"ts":"1747171008701","checksum":-54383496,"seqId":54226725198,"prevSeqId":54226725113}]}
{"arg":{"channel":"books","instId":"BTC-USDT"},"action":"update","data":[{"asks":[["104483.3","0.00838704","0","1"],["104489.3","0","0","0"],["104489.4","0.12127499","0","2"],["104489.5","0.17772436","0","2"],["104489.6","0","0","0"],["104489.9","0","0","0"],["104490.1","0.10525837","0","2"],["104490.9","0","0","0"],["104491.1","0.09150907","0","1"],["104491.5","0.07298372","0","1"],["104491.6","0.09870009","0","1"],["104494.4","0","0","0"],["104494.6","0.1838","0","2"],["104494.8","0.44654607","0","2"],["104494.9","0.16558538","0","1"],["104495.1","0.14921386","0","2"],["104497.7","0.36908178","0","1"],["104497.8","0.15740354","0","1"],["104498.1","0.04294454","0","1"],["104498.2","0","0","0"],["104498.3","0.23893154","0","2"],["104499.9","0","0","0"],["104500.1","0.26692665","0","1"],["104500.3","0.00001","0","1"],["104500.4","0.25848619","0","1"],["104503.6","0","0","0"],["104504","0.07299898","0","2"],["104504.1","0.25847525","0","1"],["104504.6","0.13874809","0","1"],["104504.7","0.19143139","0","1"],["104504.9","0.039","0","1"],["104562","0.06982","0","1"],["104565.4","5.95088355","0","1"],["104625","0","0","0"],["104625.4","0","0","0"],["104625.6","0","0","0"]],"bids":[["104481","0.37339421","0","7"],["104470.6","0.18190059","0","2"],["104470.4","0","0","0"],["104469.1","0.10015332","0","1"],["104469","0","0","0"],["104468.4","0.09684007","0","1"],["104468.3","0.04086314","0","1"],["104467.8","0.3369088","0","2"],["104467.4","0.16939767","0","1"],["104467.3","0","0","0"],["104467.1","0.16000043","0","1"],["104466.9","0","0","0"],["104465.6","0.16318912","0","2"],["104465.4","0","0","0"],["104463.3","0.24645731","0","1"],["104463.2","0.00005","0","1"],["104462.8","0.16521603","0","1"],["104462.7","0","0","0"],["104461","0.00478449","0","1"],["104460.6","0.25630615","0","1"],["104460.4","0","0","0"],["104460.3","0","0","0"],["104457.4","0.65559134","0","3"],["104457.3","0","0","0"],["104456.6","0.23713091","0","1"],["104456.5","0","0","0"],["104455.9","0.13874809","0","1"]],"ts":"1747171008801","checksum":-903831733,"seqId":54226725279,"prevSeqId":54226725198}]}
{"arg":{"channel":"books","instId":"BTC-USDT"},"action":"update","data":[{"asks":[["104481.1","0.41345369","0","13"],["104482.4","0.036","0","1"],["104485.7","0","0","0"],["104493","0","0","0"],["104494.5","0.00478449","0","1"],["104504.6","0","0","0"],["104506.5","0.13874634","0","1"],["104525.2","0.64432336","0","2"],["104557.2","0.36521389","0","1"],["104570","0.01087646","0","2"],["104582.2","0","0","0"],["104625","0.0000103","0","1"]],"bids":[["104461.3","0.00478449","0","1"],["104461","0","0","0"],["104457.5","0.13874723","0","1"],["104455.9","0","0","0"],["104419.2","0.67678781","0","2"]],"ts":"1747171009001","checksum":2044329425,"seqId":54226725297,"prevSeqId":54226725279}]}
{"arg":{"channel":"books","instId":"BTC-USDT"},"action":"update","data":[{"asks":[["104483.3","0","0","0"],["104483.9","0.17188462","0","1"],["104504.9","0.17774681","0","2"],["104506.5","0","0","0"],["104511","0","0","0"],["104512","0.002","0","2"],["104513","0.001","0","1"],["104545.6","0.00056666","0","1"],["104546.1","0.19242972","0","1"],["104561.9","0.01053014","0","1"]],"bids":[["104461.8","0.00955747","0","1"],["104461.3","0","0","0"],["104461.2","0","0","0"],["104461","0.00478449","0","1"],["104418.4","0.00056666","0","1"],["104416.9","0.77866876","0","1"],["104333.9","0.00056666","0","1"],["104330.9","0","0","0"],["104281.6","0","0","0"]],"ts":"1747171009101","checksum":-1952782578,"seqId":54226725322,"prevSeqId":54226725297}]}
{"arg":{"channel":"books","instId":"BTC-USDT"},"action":"update","data":[{"asks":[["104493","0.00478449","0","1"],["104494.5","0","0","0"],["104504.6","0.13874749","0","1"],["104504.9","0.039","0","1"],["104519.9","0.65483","0","2"],["104625","0","0","0"]],"bids":[["104481","0.37788421","0","8"],["104457.5","0","0","0"],["104457","0.13874749","0","1"]],"ts":"1747171009201","checksum":-920527772,"seqId":54226725338,"prevSeqId":54226725322}]}
{"arg":{"channel":"books","instId":"BTC-USDT"},"action":"update","data":[{"asks":[["104504.6","0","0","0"],["104506.5","0.13874659","0","1"]],"bids":[["104457.5","0.13874659","0","1"],["104457","0","0","0"]],"ts":"1747171009301","checksum":-920527772,"seqId":54226725344,"prevSeqId":54226725338}]}
{"arg":{"channel":"books","instId":"BTC-USDT"},"action":"update","data":[{"asks":[["104493","0","0","0"],["104496.1","0.00478449","0","1"],["104504.8","0.1387471","0","1"],["104506.5","0","0","0"]],"bids":[["104464.3","0.00478449","0","1"],["104461","0","0","0"],["104437","0","0","0"],["104430","0.48353493","0","3"],["104394.6","0.1125891","0","1"],["104390","0.00028006","0","1"],["104383","0.47439916","0","1"]],"ts":"1747171009401","checksum":-920527772,"seqId":54226725363,"prevSeqId":54226725344}]}
{"arg":{"channel":"books","instId":"BTC-USDT"},"action":"update","data":[{"asks":[["104495.2","0.00478449","0","1"],["104496.1","0","0","0"],["104499.6","0.60149065","0","2"],["104504.6","0.13874735","0","1"],["104504.8","0","0","0"]],"bids":[["104464.3","0","0","0"],["104463.4","0.00478449","0","1"],["104457.5","0","0","0"],["104457","0.13874735","0","1"]],"ts":"1747171009501","checksum":-920527772,"seqId":54226725378,"prevSeqId":54226725363}]}
{"arg":{"channel":"books","instId":"BTC-USDT"},"action":"update","data":[{"asks":[["104562","6.02070355","0","2"],["104565.4","0","0","0"],["104625","0.0000103","0","1"]],"bids":[],"ts":"1747171009601","checksum":-920527772,"seqId":54226725381,"prevSeqId":54226725378}]}
{"arg":{"channel":"books","instId":"BTC-USDT"},"action":"update","data":[{"asks":[["104488.5","0","0","0"],["104489.2","0.02335838","0","1"]],"bids":[["104481","0.37339421","0","7"],["104477.2","0.03004732","0","1"],["104476.3","0","0","0"],["104475.4","0.03004782","0","1"],["104444.7","0","0","0"]],"ts":"1747171009701","checksum":916710682,"seqId":54226725392,"prevSeqId":54226725381}]}
{"arg":{"channel":"books","instId":"BTC-USDT"},"action":"update","data":[{"asks":[["104494.5","0.00478449","0","1"],["104495.2","0","0","0"],["104503.9","0.139167","0","2"],["104504.6","0","0","0"],["104625.4","0.00037568","0","2"]],"bids":[["104463.4","0","0","0"],["104462","0.05962397","0","2"],["104457","0","0","0"],["104455.9","0.13874842","0","1"],["104281.6","3.43394024","0","2"]],"ts":"1747171009801","checksum":916710682,"seqId":54226725400,"prevSeqId":54226725392}]}
{"arg":{"channel":"books","instId":"BTC-USDT"},"action":"update","data":[{"asks":[["104503.6","0.13874906","0","1"],["104503.9","0.00041858","0","1"],["104542.4","0.12728484","0","1"],["104545.6","0","0","0"],["104546.3","0.77923542","0","2"],["104625.4","0","0","0"]],"bids":[["104462.7","0.00478449","0","1"],["104462.4","0.00955741","0","1"],["104462","0.05483948","0","1"],["104461.8","0","0","0"],["104419.2","0.67735447","0","3"],["104418.4","0","0","0"],["104404.6","0.08677179","0","2"],["104334.7","0.00056666","0","1"],["104333.9","0","0","0"]],"ts":"1747171010101","checksum":916710682,"seqId":54226725421,"prevSeqId":54226725400}]}
{"arg":{"channel":"books","instId":"BTC-USDT"},"action":"update","data":[{"asks":[["104490.1","0.10025837","0","1"],["104502.6","0","0","0"],["104588.5","0.0000916","0","1"],["104588.8","0","0","0"],["104625.4","0.00037568","0","2"]],"bids":[["104481","0.37744097","0","10"],["104471.2","0","0","0"],["104458.7","0","0","0"],["104330.1","0.01149441","0","2"],["104329.9","0","0","0"],["104281.4","0.00095894","0","1"],["104281.3","0.00001888","0","1"],["104281.2","0.00001019","0","1"]],"ts":"1747171010201","checksum":2140001293,"seqId":54226725432,"prevSeqId":54226725421}]}
{"arg":{"channel":"books","instId":"BTC-USDT"},"action":"update","data":[{"asks":[["104503.6","0","0","0"],["104503.9","0.13916708","0","2"],["104525.2","0.29114323","0","1"],["104529","0.000015","0","1"],["104560.3","0.00011389","0","1"],["104625.6","0.234","0","1"]],"bids":[["104462.9","0.00478449","0","1"],["104462.7","0","0","0"],["104455.9","0.1387485","0","1"],["104441.6","0.32907282","0","2"],["104440.9","0","0","0"],["104410.1","0.54303355","0","1"],["104409.6","0","0","0"],["104281","0.00002601","0","1"],["104280.8","0.00001015","0","1"]],"ts":"1747171010301","checksum":2140001293,"seqId":54226725458,"prevSeqId":54226725432}]}
{"arg":{"channel":"books","instId":"BTC-USDT"},"action":"update","data":[{"asks":[["104487.3","0.00859566","0","1"],["104494.5","0","0","0"],["104496.1","0.00478449","0","1"],["104503.6","0.13874987","0","1"],["104503.9","0.00041858","0","1"],["104529","1.43044344","0","2"],["104560.3","2.59829521","0","2"],["104625.4","0","0","0"],["104625.6","0","0","0"]],"bids":[["104473.8","0","0","0"],["104473.7","0","0","0"],["104473.1","0.0017149","0","1"],["104471.4","0","0","0"],["104464.3","0.00478449","0","1"],["104462.9","0","0","0"],["104455.9","0","0","0"],["104454.1","0.13874987","0","1"],["104441.6","0.84577009","0","3"],["104441.1","1.4358282","0","1"],["104409.7","2.57651855","0","1"]],"ts":"1747171010401","checksum":1330214549,"seqId":54226725487,"prevSeqId":54226725458}]}
{"arg":{"channel":"books","instId":"BTC-USDT"},"action":"update","data":[{"asks":[["104483.2","0.01","0","2"],["104495.7","0.0108","0","3"]],"bids":[["104471.2","0.005","0","1"],["104470.2","0.071774","0","1"],["104469.7","0.096705","0","1"],["104458.7","0.005","0","1"],["104454.1","0.13875","0","1"],["104281.3","0","0","0"],["104281.2","0","0","0"],["104281","0","0","0"],["104280.8","0","0","0"]],"ts":"1747171010501","checksum":-1001439716,"seqId":54226725497,"prevSeqId":54226725487}]}
{"arg":{"channel":"books","instId":"BTC-USDT"},"action":"update","data":[{"asks":[["104494.5","0.00478449","0","1"],["104496.1","0","0","0"]],"bids":[["104481","0.37679421","0","8"],["104473.1","0","0","0"],["104473","0","0","0"],["104472.2","0.0017149","0","1"],["104464.3","0","0","0"],["104462.9","0.00478449","0","1"],["104455.9","0.13874925","0","1"],["104454.1","0","0","0"],["104281.3","0.00001888","0","1"]],"ts":"1747171010601","checksum":-224980463,"seqId":54226725513,"prevSeqId":54226725497}]}
{"arg":{"channel":"books","instId":"BTC-USDT"},"action":"update","data":[{"asks":[["104483.8","0.19242972","0","1"],["104485.4","0.02657087","0","1"],["104488.6","0.08944869","0","1"],["104489.3","0.10218451","0","1"],["104489.4","0.02832415","0","1"],["104489.5","0.12247256","0","1"],["104490.1","0","0","0"],["104490.3","0.08763805","0","1"],["104490.8","0.08993607","0","1"],["104491.1","0","0","0"],["104491.6","0","0","0"],["104491.9","0.00478449","0","1"],["104493.8","0.14379466","0","1"],["104494.1","0.16704914","0","1"],["104494.3","0.15335335","0","1"],["104494.5","0","0","0"],["104494.6","0.0311371","0","1"],["104494.8","0.25473309","0","1"],["104494.9","0","0","0"],["104495.1","0.00004789","0","1"],["104497.1","0.15412497","0","1"],["104497.5","0.24940936","0","2"],["104497.8","0","0","0"],["104498.1","0","0","0"],["104498.3","0.00851559","0","1"],["104499.3","0.24874458","0","1"],["104499.6","0.69620394","0","2"],["104500.1","0","0","0"],["104500.4","0","0","0"],["104503.3","0.26238718","0","1"],["104503.6","0.13874982","0","1"],["104504.1","0","0","0"],["104521.4","0.09571","0","1"],["104573.5","0.31160459","0","2"],["104623.4","0","0","0"],["104623.6","0","0","0"],["104625","0","0","0"]],"bids":[["104481","0.01127545","0","5"],["104477.2","0","0","0"],["104475.4","0","0","0"],["104475.2","0","0","0"],["104473.6","0","0","0"],["104473.4","0.03211214","0","1"],["104472.1","0.44684063","0","2"],["104470.6","0","0","0"],["104470.5","0","0","0"],["104470.2","0","0","0"],["104469.8","0.19075443","0","2"],["104469.7","0","0","0"],["104469.1","0","0","0"],["104468.4","0","0","0"],["104468.3","0.14053872","0","2"],["104467.8","0.07501158","0","1"],["104467.6","0.0921126","0","1"],["104467.4","0","0","0"],["104467.1","0","0","0"],["104466.6","0.19176437","0","2"],["104466.3","0.14344198","0","1"],["104465.6","0.000015","0","1"],["104464.8","0.14990729","0","1"],["104463.3","0","0","0"],["104462.9","0","0","0"],["104462.8","0","0","0"],["104462.5","0.27424942","0","2"],["104462.1","0.18977272","0","2"],["104460.6","0","0","0"],["104460.1","0.00478449","0","1"],["104457.4","0.40716632","0","2"],["104456.6","0","0","0"],["104455.9","0.13874943","0","1"],["104455.8","0.33815622","0","2"],["104453.3","0.40924193","0","2"],["104281.2","0.00001019","0","1"],["104281","0.00002601","0","1"],["104280.8","0.00001015","0","1"],["104280.5","0.77880494","0","3"],["104280","0.00451315","0","15"],["104279.6","0.00026802","0","1"],["104279.5","0.00001392","0","1"],["104279.4","0.00021285","0","4"],["104279.1","0.00038358","0","1"],["104279","0.00009722","0","1"],["104278.6","0.00010262","0","1"]],"ts":"1747171010701","checksum":-432519155,"seqId":54226725671,"prevSeqId":54226725513}]}
{"arg":{"channel":"books","instId":"BTC-USDT"},"action":"update","data":[{"asks":[["104481.1","0.55053302","0","15"],["104483.7","0.25999054","0","1"],["104483.9","0","0","0"],["104486.6","0.0913066","0","1"],["104487.2","0.10192139","0","1"],["104487.7","0","0","0"],["104488.2","0.09348527","0","1"],["104488.6","0","0","0"],["104488.8","0.09622936","0","1"],["104489.2","0","0","0"],["104489.3","0","0","0"],["104489.5","0.28093476","0","2"],["104490.3","0","0","0"],["104490.8","0","0","0"],["104491.1","0.00478449","0","1"],["104491.7","0.15484968","0","1"],["104491.9","0","0","0"],["104492.1","0.16753431","0","1"],["104492.2","0.15357826","0","1"],["104493.2","0.17829353","0","1"],["104493.8","0","0","0"],["104494.1","0","0","0"],["104494.3","0","0","0"],["104494.5","0.52053702","0","2"],["104494.8","0","0","0"],["104495","0.15117729","0","1"],["104495.5","0.24644803","0","2"],["104497.1","0","0","0"],["104497.2","0.30516535","0","2"],["104497.5","0.000015","0","1"],["104497.6","0.25867127","0","1"],["104499.3","0","0","0"],["104499.6","0.42844324","0","1"],["104501.3","0.23368554","0","3"],["104503.3","0","0","0"],["104503.6","0.13874978","0","1"],["104508.4","0.00287065","0","1"],["104509","0.032","0","3"],["104510","0.00129006","0","3"],["104510.2","0.071782","0","1"],["104512","0","0","0"],["104513","0","0","0"],["104530","0.16029006","0","4"],["104531","0.24999999","0","5"],["104532","0.08501","0","3"],["104533","0","0","0"],["104534","0.19242972","0","1"],["104535","0","0","0"],["104562","0.06982","0","1"],["104623.4","0.00001","0","1"],["104623.6","0.00083722","0","2"],["104625","0.0000103","0","1"]],"bids":[["104480.1","0","0","0"],["104480","0.00001","0","1"],["104478","0","0","0"],["104477.2","0.0626617","0","1"],["104472.1","0.20823931","0","2"],["104470.7","0","0","0"],["104469.8","0","0","0"],["104468.8","0.03695722","0","2"],["104468.5","0.10516509","0","2"],["104468.3","0.04086314","0","1"],["104467.8","0.27683397","0","2"],["104467.7","0.18970154","0","2"],["104467.6","0","0","0"],["104466.6","0.04","0","1"],["104466.3","0.09326402","0","1"],["104465.6","0.09477502","0","2"],["104464.8","0","0","0"],["104464.6","0.16556885","0","2"],["104464.2","0.23369541","0","2"],["104462.7","0.16495706","0","1"],["104462.5","0.03","0","1"],["104462.1","0.02929425","0","1"],["104460.5","0.25345495","0","1"],["104460.1","0","0","0"],["104460","0.1511345","0","4"],["104459","0.00478449","0","1"],["104457.7","0.27092796","0","1"],["104455.9","0","0","0"],["104455.8","0.07298372","0","1"],["104454.7","0.13874978","0","1"],["104454.6","0.26005886","0","2"],["104453.8","0.25778709","0","1"],["104417.7","0","0","0"],["104278.4","0.000015","0","1"]],"ts":"1747171010801","checksum":-1565838066,"seqId":54226725918,"prevSeqId":54226725671}]}
{"arg":{"channel":"books","instId":"BTC-USDT"},"action":"update","data":[{"asks":[["104483.5","0.44726446","0","1"],["104483.6","0.36908178","0","1"],["104483.7","0","0","0"],["104501.2","0.13875204","0","1"],["104503.6","0","0","0"],["104509","0.03","0","1"],["104510","0.00029006","0","2"],["104512","0.002","0","2"],["104513","0.001","0","1"],["104530","0.00029006","0","2"],["104531","0","0","0"],["104532","0.00001","0","1"],["104533","0.16","0","2"],["104534","0.44242971","0","6"],["104535","0.085","0","2"],["104558.6","5.90729577","0","1"],["104622.1","0","0","0"],["104623.3","0","0","0"],["104623.4","0","0","0"],["104623.6","0","0","0"],["104625","0","0","0"]],"bids":[["104472.2","0","0","0"],["104472.1","0.15941638","0","2"],["104468.9","0.0017149","0","1"],["104468.5","0.00846109","0","1"],["104454.7","0","0","0"],["104453.9","0.13875204","0","1"]],"ts":"1747171010901","checksum":2032106349,"seqId":54226725966,"prevSeqId":54226725918}]}
{"arg":{"channel":"books","instId":"BTC-USDT"},"action":"update","data":[{"asks":[["104499.4","0.13875441","0","1"],["104501.2","0","0","0"],["104509","0.032","0","3"],["104510","0.00129006","0","3"],["104512","0","0","0"],["104513","0","0","0"],["104531","0.22999999","0","4"],["104532","0.21500999","0","5"],["104533","0.05","0","1"],["104534","0.19242972","0","1"],["104535","0","0","0"],["104558.6","0","0","0"],["104562","5.97711577","0","2"],["104622.1","0.0140803","0","1"],["104623.3","0.03","0","1"],["104623.4","0.00001","0","1"]],"bids":[["104472.2","0.0017149","0","1"],["104469.1","0.071773","0","1"],["104468.9","0","0","0"],["104468.6","0.096714","0","2"],["104453.9","0","0","0"],["104450","0.13904447","0","3"],["104417.7","0.00002963","0","1"],["104278.4","0","0","0"]],"ts":"1747171011001","checksum":-1167585052,"seqId":54226726017,"prevSeqId":54226725966}]}
{"arg":{"channel":"books","instId":"BTC-USDT"},"action":"update","data":[{"asks":[["104495.9","0.071773","0","1"],["104510.2","0","0","0"],["104525.2","0.66145502","0","2"],["104530","0.16029006","0","4"],["104531","0.24999999","0","5"],["104532","0.08501","0","3"],["104533","0","0","0"],["104546.3","0.77866876","0","1"],["104546.9","0.00056666","0","1"],["104557.2","0","0","0"],["104623.6","0.00083722","0","2"]],"bids":[["104478","0.0932","0","1"],["104469.1","0","0","0"],["104468.6","0.00001","0","1"],["104465.9","0","0","0"],["104462.9","0.00955737","0","1"],["104462.4","0","0","0"],["104462","0.06564937","0","2"],["104419.8","0.00056666","0","1"],["104419.2","0.67678781","0","2"],["104410.1","1.41828155","0","2"],["104335.3","0.00056666","0","1"],["104334.7","0","0","0"]],"ts":"1747171011101","checksum":1420789478,"seqId":54226726046,"prevSeqId":54226726017}]}
{"arg":{"channel":"books","instId":"BTC-USDT"},"action":"update","data":[{"asks":[["104483.5","0.33238167","0","1"],["104486.6","0","0","0"],["104487.2","0","0","0"],["104487.6","0.09307088","0","1"],["104488.2","0","0","0"],["104488.3","0.10195938","0","3"],["104488.8","0","0","0"],["104489.2","0.09299765","0","1"],["104489.5","0.25668754","0","2"],["104489.8","0.09226386","0","1"],["104491.7","0","0","0"],["104492.1","0","0","0"],["104492.2","0","0","0"],["104492.7","0.14358639","0","1"],["104493.1","0.19237946","0","2"],["104493.3","0.15928796","0","1"],["104494.5","0.47247308","0","2"],["104495","0","0","0"],["104495.5","0.00093","0","1"],["104496","0.16561391","0","1"],["104496.5","0.24917792","0","1"],["104497.1","0.13875789","0","1"],["104497.2","0.05228091","0","1"],["104497.6","0","0","0"],["104498.3","0.27559853","0","2"],["104498.6","0.26468532","0","1"],["104499.4","0","0","0"],["104501.3","0.00009573","0","2"],["104502.3","0.25291959","0","1"],["104558.1","0.0892307","0","1"],["104623.6","0","0","0"]],"bids":[["104481","0.00786545","0","3"],["104478.1","0.09815275","0","1"],["104477.2","0","0","0"],["104475.1","0.0251035","0","1"],["104472.2","0","0","0"],["104472.1","0.12730384","0","1"],["104468.9","0.0017149","0","1"],["104468.8","0.13243369","0","3"],["104468.7","0.09294135","0","1"],["104467.8","0.26289433","0","2"],["104467.7","0","0","0"],["104467.3","0.09796417","0","1"],["104466.6","0.13367984","0","2"],["104466.3","0","0","0"],["104465.6","0.16774008","0","2"],["104465.2","0.1574329","0","1"],["104464.6","0.00001","0","1"],["104464.2","0.07298372","0","1"],["104463.8","0.1698862","0","1"],["104462.7","0","0","0"],["104461.5","0.23739159","0","1"],["104461","0.16502476","0","1"],["104460.5","0","0","0"],["104460","0.00220843","0","3"],["104458.8","0.2417031","0","2"],["104457.7","0","0","0"],["104457.4","0.42347378","0","2"],["104455.6","0.26314608","0","1"],["104454.8","0.23652392","0","1"],["104454.6","0.00382941","0","1"],["104453.8","0","0","0"],["104450","0.00029006","0","2"],["104448.8","0.13876789","0","2"],["104279.1","0","0","0"],["104279","0","0","0"],["104278.6","0","0","0"]],"ts":"1747171011201","checksum":1878118242,"seqId":54226726173,"prevSeqId":54226726046}]}
{"arg":{"channel":"books","instId":"BTC-USDT"},"action":"update","data":[{"asks":[["104484.1","0.07298372","0","1"],["104487","0.09132217","0","1"],["104487.6","0.09062672","0","1"],["104488.3","0.00373804","0","2"],["104488.6","0.09035731","0","1"],["104489.1","0.09460584","0","1"],["104489.2","0","0","0"],["104489.5","0.27857522","0","2"],["104489.8","0","0","0"],["104491.1","0","0","0"],["104492.1","0.14611899","0","1"],["104492.5","0.15937832","0","1"],["104492.6","0.16745734","0","3"],["104492.7","0","0","0"],["104493.1","0.04","0","1"],["104493.3","0","0","0"],["104494.5","0.58718194","0","2"],["104495.4","0.16312991","0","1"],["104495.9","0.30945233","0","2"],["104496","0","0","0"],["104496.5","0","0","0"],["104497.6","0.26915799","0","1"],["104498","0.24990264","0","1"],["104498.3","0.00851559","0","1"],["104498.6","0","0","0"],["104501.6","0.25475909","0","1"],["104502.3","0","0","0"],["104573.5","0.01052914","0","1"],["104623.4","0","0","0"]],"bids":[["104468.8","0.03695722","0","2"],["104468.7","0","0","0"],["104468.1","0.18279112","0","2"],["104467.8","0.30855238","0","2"],["104467.3","0.071773","0","1"],["104466.8","0.096704","0","1"],["104466.6","0.13041074","0","2"],["104466","0.19281339","0","2"],["104465.6","0.000015","0","1"],["104465.2","0","0","0"],["104465","0.16225971","0","1"],["104464.6","0.15886468","0","2"],["104463.8","0","0","0"],["104463.1","0.18926618","0","2"],["104461.5","0","0","0"],["104461","0","0","0"],["104460.9","0.24008708","0","2"],["104460.4","0.16432276","0","1"],["104460.3","0.00478449","0","1"],["104459","0","0","0"],["104458.8","0.00191","0","1"],["104458.1","0.23892501","0","1"],["104457.4","0.41775949","0","2"],["104455.6","0","0","0"],["104455","0.25039168","0","1"],["104454.8","0","0","0"],["104454.1","0.25732674","0","1"]],"ts":"1747171011301","checksum":1621894074,"seqId":54226726243,"prevSeqId":54226726173}]}
{"arg":{"channel":"books","instId":"BTC-USDT"},"action":"update","data":[{"asks":[["104487","0","0","0"],["104487.6","0.09805203","0","1"],["104488.3","0.10073582","0","3"],["104488.6","0","0","0"],["104489.1","0","0","0"],["104489.2","0.09570397","0","1"],["104489.5","0.30509745","0","2"],["104489.8","0.08971396","0","1"],["104492.1","0","0","0"],["104492.5","0","0","0"],["104492.6","0.00485751","0","2"],["104492.7","0.16353925","0","1"],["104493.1","0.19019259","0","2"],["104493.3","0.15305876","0","1"],["104494.5","0.50163483","0","2"],["104495.4","0","0","0"],["104495.9","0.071773","0","1"],["104496","0.15995207","0","1"],["104496.5","0.23017061","0","1"],["104497.6","0","0","0"],["104498","0","0","0"],["104498.3","0.25310572","0","2"],["104498.6","0.27332614","0","1"],["104501.6","0","0","0"],["104502.3","0.26181389","0","1"],["104623.4","0.00001","0","1"]],"bids":[["104468.8","0.13292797","0","3"],["104468.7","0.09616394","0","1"],["104468.1","0","0","0"],["104467.8","0.30542704","0","2"],["104467.3","0.16472252","0","2"],["104466.6","0.13798324","0","2"],["104466","0.0932","0","1"],["104465.6","0.15661278","0","2"],["104465.2","0.14711259","0","1"],["104465","0","0","0"],["104464.6","0.00001","0","1"],["104463.8","0.16534376","0","1"],["104463.1","0.03","0","1"],["104461.5","0.23677342","0","1"],["104461","0.16502741","0","1"],["104460.9","0.00711203","0","1"],["104460.4","0","0","0"],["104458.8","0.24046379","0","2"],["104458.1","0","0","0"],["104457.4","0.41873113","0","2"],["104455.6","0.26412333","0","1"],["104455","0","0","0"],["104454.8","0.24683387","0","1"],["104454.1","0","0","0"],["104279.4","0","0","0"]],"ts":"1747171011401","checksum":1453615275,"seqId":54226726301,"prevSeqId":54226726243}]}
{"arg":{"channel":"books","instId":"BTC-USDT"},"action":"update","data":[{"asks":[["104483.8","0","0","0"],["104487.6","0.09633413","0","1"],["104488.3","0.09640903","0","3"],["104489.2","0.09357299","0","1"],["104489.5","0.30416486","0","2"],["104489.8","0.09720462","0","1"],["104492.7","0.14405705","0","1"],["104493.1","0.19631634","0","2"],["104493.3","0.15581791","0","1"],["104494.5","0.58417402","0","2"],["104496","0.16238904","0","1"],["104496.5","0.23649231","0","1"],["104497.1","0.13875771","0","1"],["104498.3","0.2692099","0","2"],["104498.6","0.25026652","0","1"],["104502.3","0.25602099","0","1"],["104562","0.06982","0","1"],["104623.6","0.00083722","0","2"]],"bids":[["104468.8","0.13063891","0","3"],["104468.7","0.09278204","0","1"],["104467.8","0.31102133","0","2"],["104467.3","0.17162871","0","2"],["104466.6","0.13788911","0","2"],["104465.6","0.16932168","0","2"],["104465.2","0.14784971","0","1"],["104463.8","0.16373332","0","1"],["104461.5","0.249111","0","1"],["104461","0.14762578","0","1"],["104458.8","0.25561801","0","2"],["104457.4","0.42194909","0","2"],["104455.6","0.25482005","0","1"],["104454.8","0.2668637","0","1"],["104449.6","0.50948096","0","3"],["104448.8","0.00001","0","1"]],"ts":"1747171011501","checksum":-333378769,"seqId":54226726375,"prevSeqId":54226726301}]}
{"arg":{"channel":"books","instId":"BTC-USDT"},"action":"update","data":[{"asks":[["104481.1","0.56201802","0","16"]],"bids":[["104481","0.01086545","0","4"]],"ts":"1747171011601","checksum":-2087462000,"seqId":54226726378,"prevSeqId":54226726375}]}
{"arg":{"channel":"books","instId":"BTC-USDT"},"action":"update","data":[{"asks":[["104485.4","0","0","0"],["104489.2","0","0","0"],["104489.3","0.08707641","0","1"],["104489.6","0.0391928","0","1"],["104492.7","0","0","0"],["104492.8","0.16107992","0","1"],["104496","0","0","0"],["104496.1","0.16467379","0","1"],["104497.2","0","0","0"],["104562","5.97711577","0","2"],["104625","0.0000103","0","1"]],"bids":[["104468.8","0.22237664","0","4"],["104468.7","0","0","0"],["104465.3","0.15143353","0","1"],["104465.2","0","0","0"],["104461.1","0.14905486","0","1"],["104461","0","0","0"],["104279.4","0.00021285","0","4"]],"ts":"1747171011701","checksum":-1883207658,"seqId":54226726404,"prevSeqId":54226726378}]}
{"arg":{"channel":"books","instId":"BTC-USDT"},"action":"update","data":[{"asks":[["104481.1","0.51220369","0","14"],["104483.4","0.19242972","0","1"],["104497.2","0.05228091","0","1"],["104623.6","0","0","0"],["104625","0","0","0"]],"bids":[],"ts":"1747171011801","checksum":97892896,"seqId":54226726411,"prevSeqId":54226726404}]}
{"arg":{"channel":"books","instId":"BTC-USDT"},"action":"update","data":[{"asks":[["104488.3","0.13473836","0","4"],["104491.1","0.00478449","0","1"],["104492.6","0.00007302","0","1"],["104509","0.03","0","1"],["104510","0.00029006","0","2"],["104512","0.002","0","2"],["104513","0.001","0","1"],["104531","0.14999999","0","3"],["104532","0.03501","0","2"],["104534","0.29242972","0","3"],["104535","0.05","0","1"],["104558.6","5.91757847","0","1"],["104562","0.06982","0","1"],["104621.4","0","0","0"],["104622","0","0","0"],["104622.1","0","0","0"],["104623.3","0","0","0"],["104623.4","0","0","0"]],"bids":[["104460.3","0","0","0"],["104459.3","0.00478449","0","1"]],"ts":"1747171011901","checksum":1529332717,"seqId":54226726454,"prevSeqId":54226726411}]}
{"arg":{"channel":"books","instId":"BTC-USDT"},"action":"update","data":[{"asks":[["104509","0.032","0","3"],["104510","0.00129006","0","3"],["104512","0","0","0"],["104513","0","0","0"],["104531","0.24999999","0","5"],["104532","0.08501","0","3"],["104534","0.19242972","0","1"],["104535","0","0","0"],["104621.4","0.0579344","0","1"],["104622","0.01101846","0","2"],["104622.1","0.0140803","0","1"]],"bids":[],"ts":"1747171012001","checksum":1529332717,"seqId":54226726466,"prevSeqId":54226726454}]}
{"arg":{"channel":"books","instId":"BTC-USDT"},"action":"update","data":[{"asks":[["104485.1","0.02527995","0","1"],["104488.3","0.04206737","0","3"],["104489.3","0","0","0"],["104492.8","0","0","0"],["104493.3","0","0","0"],["104496","0.15785814","0","1"],["104496.1","0","0","0"],["104497.1","0","0","0"],["104497.2","0","0","0"],["104497.6","0.13875778","0","1"],["104498.3","0.00851559","0","1"],["104511.9","0.00001","0","1"],["104512.1","0.0001303","0","1"],["104544.4","0.00056666","0","1"],["104546.9","0","0","0"],["104558.6","0","0","0"],["104616.1","5.91757847","0","1"],["104623.3","0.03","0","1"],["104623.4","0.00001","0","1"]],"bids":[["104481","0.00786545","0","3"],["104475.1","0","0","0"],["104472.2","0.0017149","0","1"],["104472.1","0.17696455","0","2"],["104471.8","0.03144464","0","1"],["104468.9","0","0","0"],["104468.8","0.03695722","0","2"],["104465.3","0","0","0"],["104463.8","0","0","0"],["104463.3","0.00955733","0","1"],["104462.9","0","0","0"],["104461.1","0","0","0"],["104461","0.14971715","0","1"],["104458.8","0.00191","0","1"],["104449.6","0.37072325","0","2"],["104448.8","0.13876778","0","2"],["104423.5","0.00056666","0","1"],["104419.8","0","0","0"],["104343","0.00056666","0","1"],["104335.3","0","0","0"],["104279.1","0.00038358","0","1"],["104279","0.00009722","0","1"]],"ts":"1747171012101","checksum":127513385,"seqId":54226726518,"prevSeqId":54226726466}]}
{"arg":{"channel":"books","instId":"BTC-USDT"},"action":"update","data":[{"asks":[["104488.3","0.13763639","0","4"],["104489.3","0.09219741","0","1"],["104492.8","0.14557206","0","1"],["104493.3","0.15143452","0","1"],["104498.3","0.2528416","0","2"],["104616.1","0","0","0"],["104619.5","5.91757847","0","1"],["104622.1","0","0","0"],["104623.3","0","0","0"],["104623.4","0","0","0"]],"bids":[["104475.2","0.03044116","0","1"],["104472.2","0","0","0"],["104472.1","0.12730384","0","1"],["104471.8","0","0","0"],["104468.9","0.0017149","0","1"],["104468.8","0.22915946","0","4"],["104465.3","0.14956029","0","1"],["104463.8","0.16291401","0","1"],["104458.8","0.24771339","0","2"],["104279.1","0","0","0"],["104279","0","0","0"]],"ts":"1747171012201","checksum":744424547,"seqId":54226726558,"prevSeqId":54226726518}]}
{"arg":{"channel":"books","instId":"BTC-USDT"},"action":"update","data":[{"asks":[],"bids":[["104450","0.13904722","0","3"],["104448.8","0.00001","0","1"]],"ts":"1747171012301","checksum":744424547,"seqId":54226726560,"prevSeqId":54226726558}]}
{"arg":{"channel":"books","instId":"BTC-USDT"},"action":"update","data":[{"asks":[["104491.1","0","0","0"],["104491.4","0.00478449","0","1"]],"bids":[],"ts":"1747171012401","checksum":744424547,"seqId":54226726567,"prevSeqId":54226726560}]}
{"arg":{"channel":"books","instId":"BTC-USDT"},"action":"update","data":[{"asks":[["104474.4","0.83515042","0","17"],["104474.5","0.14933162","0","1"],["104476","0.0932","0","1"],["104476.4","0.02528206","0","1"],["104477.2","0.28609","0","4"],["104478","0.0932","0","1"],["104478.8","0.01846919","0","1"],["104479.8","0.00533323","0","2"],["104479.9","0.48786512","0","1"],["104480","0.15070942","0","4"],["104480.1","0.21632","0","6"],["104480.6","0.09931264","0","1"],["104481.1","0.052","0","2"],["104481.6","0.00478449","0","1"],["104483.2","0.18829353","0","3"],["104483.5","0","0","0"],["104484.2","0.2730764","0","2"],["104484.4","0.05716684","0","2"],["104485","0.00045","0","1"],["104485.1","0","0","0"],["104486","0.13877239","0","1"],["104486.1","0.04","0","1"],["104487","0.000015","0","1"],["104487.1","0.04","0","1"],["104487.3","0.24380495","0","2"],["104487.4","0","0","0"],["104487.6","0","0","0"],["104487.9","0","0","0"],["104488.3","0.04206737","0","3"],["104489","0.65316952","0","2"],["104489.2","0.8169506","0","2"],["104489.3","0","0","0"],["104489.5","0","0","0"],["104489.8","0","0","0"],["104490.2","0.002","0","1"],["104490.3","0.00093","0","1"],["104490.4","0","0","0"],["104491.2","0","0","0"],["104491.4","0","0","0"],["104492.8","0","0","0"],["104493.1","0.26313357","0","1"],["104493.3","0","0","0"],["104494.5","0.41305712","0","2"],["104494.6","0","0","0"],["104495.3","0","0","0"],["104496","0","0","0"],["104496.5","0","0","0"],["104497.6","0","0","0"],["104498.3","0.00851559","0","1"],["104498.5","0.83391","0","2"],["104498.6","0","0","0"],["104499.5","0","0","0"],["104500.5","0.55812","0","1"],["104500.7","0.78057876","0","2"],["104502.3","0","0","0"],["104507.5","0.08894306","0","3"],["104507.7","0.00287069","0","1"],["104507.8","0.00287069","0","1"],["104508","0.00288569","0","2"],["104508.4","0","0","0"],["104509","0.03","0","1"],["104510","0.00029006","0","2"],["104511","0.002","0","2"],["104511.1","0","0","0"],["104511.2","0","0","0"],["104512","0.001","0","1"],["104513.7","0.02091112","0","1"],["104514.8","0.03747305","0","1"],["104518.7","0","0","0"],["104519.9","0","0","0"],["104521.4","0","0","0"],["104524.6","0","0","0"],["104529","1.50044344","0","4"],["104530","0.03529006","0","3"],["104531","0","0","0"],["104531.4","0.03080713","0","2"],["104532","0.16001","0","3"],["104533","0.17999999","0","3"],["104533.3","0.0059691","0","5"],["104534","0.24242972","0","2"],["104535.7","0","0","0"],["104535.8","0.77866876","0","1"],["104545.8","0","0","0"],["104547.1","0","0","0"],["104547.2","0","0","0"],["104547.6","0","0","0"],["104548.6","0","0","0"],["104549.3","0","0","0"],["104555.3","0","0","0"],["104558.1","0","0","0"],["104558.6","5.91757847","0","1"],["104560.6","0","0","0"],["104563.9","0.09564","0","1"],["104567.8","0.11477","0","2"],["104575.5","0.24182082","0","3"],["104588.9","0","0","0"],["104591.1","0","0","0"],["104599.6","0","0","0"],["104600.4","0","0","0"],["104619.5","0","0","0"],["104622.1","0.0140803","0","1"],["104623.3","0.03","0","1"],["104623.4","0.00001","0","1"],["104623.6","0.00083722","0","2"],["104624.8","0.00056666","0","1"],["104625","0.0000103","0","1"],["104625.4","0.00037568","0","2"],["104625.7","0.0001","0","1"],["104625.8","0.00009579","0","1"],["104626","0.01099591","0","1"],["104626.1","0.01488","0","1"],["104626.8","0.00001371","0","1"]],"bids":[["104481","0","0","0"],["104480","0","0","0"],["104479.8","0","0","0"],["104478.1","0","0","0"],["104478","0","0","0"],["104477.1","0","0","0"],["104476","0","0","0"],["104475.2","0","0","0"],["104474.5","0","0","0"],["104473.5","0","0","0"],["104473.4","0","0","0"],["104472.1","0","0","0"],["104472","0","0","0"],["104471.9","0","0","0"],["104470","0.00029006","0","2"],["104469.2","0.01619463","0","1"],["104468.9","0","0","0"],["104468.8","0.00095722","0","1"],["104468.5","0","0","0"],["104468.4","0.00262786","0","1"],["104468.3","0","0","0"],["104467.8","0","0","0"],["104467.3","0","0","0"],["104466.8","0","0","0"],["104466.6","0","0","0"],["104465.6","0","0","0"],["104465.3","0","0","0"],["104464.2","0","0","0"],["104464","0","0","0"],["104463.8","0","0","0"],["104463.1","0","0","0"],["104462.7","0.0017149","0","1"],["104462.6","0.13198479","0","2"],["104462.5","0","0","0"],["104462.2","0","0","0"],["104462.1","0","0","0"],["104462","0.01080989","0","1"],["104461.9","0.036","0","1"],["104461.5","0","0","0"],["104461","0","0","0"],["104460.9","0","0","0"],["104460.3","0.19242972","0","1"],["104460.2","0","0","0"],["104459.9","0.036","0","1"],["104459.3","0","0","0"],["104459.2","0","0","0"],["104459.1","0","0","0"],["104458.9","0","0","0"],["104458.8","0","0","0"],["104458.3","0","0","0"],["104458.1","0.13766676","0","2"],["104457.4","0.288653","0","2"],["104456.1","0.234","0","1"],["104455.8","0","0","0"],["104455.7","0.05191","0","2"],["104455.6","0","0","0"],["104454.8","0","0","0"],["104454.6","0","0","0"],["104453.6","0","0","0"],["104453.3","0.04016015","0","1"],["104452.7","0.02930425","0","2"],["104452.3","0.25545203","0","1"],["104452.1","0.34147336","0","1"],["104451.5","0.03","0","1"],["104450","0.00029006","0","2"],["104449.5","0.26380978","0","1"],["104448.5","0.033","0","1"],["104448.2","0.00711203","0","1"],["104446.4","0.24651791","0","1"],["104445.6","0.24362335","0","1"],["104445","0.06152637","0","1"],["104441.6","0.46563836","0","3"],["104441.1","0","0","0"],["104439.9","0.17829353","0","1"],["104439.1","0","0","0"],["104438.3","0.13877239","0","1"],["104436.8","0.17830353","0","2"],["104428.7","0","0","0"],["104424","0.00480069","0","2"],["104410.1","0.54303355","0","1"],["104409.7","0","0","0"],["104380.8","0","0","0"],["104365.3","0","0","0"],["104362.2","0.01390099","0","1"],["104360.9","0","0","0"],["104357.5","0.00001","0","1"],["104342.6","0.12503322","0","1"],["104279.1","0.00038358","0","1"],["104279","0.00009722","0","1"],["104278.6","0.00010262","0","1"],["104278.4","0.000015","0","1"],["104278.3","0.00079787","0","1"],["104277.8","0.01492147","0","2"],["104277.7","0.00002552","0","1"],["104277.6","0.00017517","0","3"],["104277.4","0.00010004","0","3"],["104277.2","0.00001034","0","1"],["104277.1","0.00001917","0","1"],["104276.9","0.00015431","0","1"],["104276.6","0.00001015","0","1"],["104276.3","0.00001008","0","1"],["104276.1","0.00001736","0","1"],["104276","0.00005734","0","2"],["104275.9","0.00001015","0","1"],["104275.5","0.00028209","0","1"],["104275.4","0.00018093","0","1"],["104275.2","0.00001919","0","1"],["104275","0.00559802","0","3"],["104274.8","0.00005355","0","1"],["104274.3","0.00005483","0","3"],["104274.1","0.0001347","0","1"],["104274","0.00001007","0","1"],["104273.7","0.00019702","0","2"],["104273.3","0.07298372","0","1"],["104272.9","0.00003136","0","1"],["104272.7","0.00025768","0","6"],["104272.3","0.00001222","0","1"],["104272.2","0.00033769","0","1"],["104272","0.00086241","0","4"],["104271.9","0.00004632","0","2"],["104271.8","0.0000102","0","1"],["104271.5","0.00030759","0","1"],["104271.1","0.00001029","0","1"]],"ts":"1747171012501","checksum":204157261,"seqId":54226727190,"prevSeqId":54226726567}]}
{"arg":{"channel":"books","instId":"BTC-USDT"},"action":"update","data":[{"asks":[["104470.1","0.56768296","0","11"],["104471.3","0.036","0","1"],["104474.4","0.052","0","2"],["104474.5","0","0","0"],["104474.9","0.02528243","0","1"],["104475.8","0.00011435","0","1"],["104475.9","0.17142107","0","1"],["104476.4","0","0","0"],["104476.7","0.03301843","0","1"],["104478.4","0.09802294","0","1"],["104478.7","0.02832415","0","1"],["104479","0.05715975","0","1"],["104479.1","0.09736657","0","1"],["104479.8","0.00521888","0","1"],["104480.1","0.14774282","0","3"],["104480.5","0.01","0","1"],["104480.6","0.09308442","0","1"],["104481.6","0","0","0"],["104482.9","0.04","0","1"],["104483.4","0.23071367","0","2"],["104483.6","0.52678874","0","2"],["104483.9","0.16739778","0","1"],["104484","0.46308507","0","3"],["104484.1","0.23656563","0","2"],["104484.2","0","0","0"],["104484.3","0","0","0"],["104486","0","0","0"],["104486.1","0","0","0"],["104486.3","0.0047848","0","1"],["104486.8","0.16079857","0","1"],["104487","0.13878552","0","2"],["104487.3","0.26524671","0","2"],["104489","0.39763436","0","1"],["104489.1","0.24635165","0","1"],["104489.2","0.77866876","0","1"],["104489.4","0.26782436","0","1"],["104489.6","0","0","0"],["104492","0.1332","0","2"],["104493.1","0.24810273","0","1"],["104504.4","0.00287","0","1"],["104504.7","0","0","0"],["104505","0.0619306","0","3"],["104506","0.00106","0","2"],["104507.5","0.04607237","0","1"],["104507.7","0","0","0"],["104507.8","0","0","0"],["104508","0.000015","0","1"],["104510.9","0.05980159","0","2"],["104511","0","0","0"],["104512","0","0","0"],["104514.8","0","0","0"],["104519.8","0","0","0"],["104520.5","0.36908178","0","1"],["104522.2","0.01808631","0","1"],["104522.3","0.0004786","0","1"],["104527","0.16","0","2"],["104528","0.24999999","0","5"],["104529","1.51544344","0","4"],["104530","0.00029006","0","2"],["104530.4","0","0","0"],["104530.5","0","0","0"],["104530.9","0.0008017","0","1"],["104532","0.00001","0","1"],["104533","0","0","0"],["104533.3","0.05084811","0","5"],["104534","0.19242972","0","1"],["104542.5","0.85665","0","1"],["104542.6","0","0","0"],["104546.2","0.39687904","0","1"],["104581.2","0.01232","0","1"],["104625.8","0","0","0"],["104626","0","0","0"],["104626.1","0","0","0"],["104626.8","0","0","0"]],"bids":[["104474.3","0","0","0"],["104472.6","0","0","0"],["104471.2","0","0","0"],["104470","0.43667782","0","6"],["104468.6","0","0","0"],["104468.1","0.056538","0","1"],["104464.3","0.03044436","0","1"],["104463.3","0","0","0"],["104462.7","0","0","0"],["104462.6","0.25003563","0","3"],["104462.5","0.03144744","0","1"],["104461.6","0.071773","0","1"],["104460.3","0","0","0"],["104459.6","0.19359664","0","3"],["104459.3","0.0017149","0","1"],["104458.1","0.14401168","0","2"],["104457.4","0.41992203","0","3"],["104456.4","0.16365388","0","1"],["104456.1","0.38599883","0","2"],["104455.7","0.09191","0","3"],["104454.6","0.16426907","0","1"],["104453.1","0.0047848","0","1"],["104452.7","0.05930425","0","3"],["104452.3","0.25009335","0","1"],["104452.1","0.38056361","0","2"],["104451.8","0.14984668","0","1"],["104449.6","0.62797797","0","3"],["104449.5","0","0","0"],["104448.5","0.063","0","2"],["104446.5","0.39417767","0","2"],["104446.4","0.2399244","0","1"],["104445.6","0.24208924","0","1"],["104443.6","0.00382982","0","1"],["104442.5","0","0","0"],["104439.9","0.23236188","0","2"],["104438.8","0.13877052","0","1"],["104438.3","0","0","0"],["104427.9","1.37629274","0","1"],["104423.2","0.58887","0","1"],["104422","0.00047858","0","1"],["104416.8","0.04713914","0","1"],["104415.4","0.45468381","0","1"],["104409.1","0.00001","0","1"],["104396.6","2.4982663","0","1"],["104384.7","0.37195278","0","2"],["104368.1","0.01053113","0","1"],["104361","0","0","0"],["104357.1","0.00064023","0","1"],["104353.5","0","0","0"],["104350.3","0.00084061","0","1"],["104272.3","0","0","0"],["104272.2","0","0","0"],["104272","0","0","0"],["104271.9","0","0","0"],["104271.8","0","0","0"],["104271.5","0","0","0"],["104271.1","0","0","0"]],"ts":"1747171012601","checksum":402657803,"seqId":54226727845,"prevSeqId":54226727190}]}
{"arg":{"channel":"books","instId":"BTC-USDT"},"action":"update","data":[{"asks":[["104470.1","0.53177296","0","11"],["104471.3","0","0","0"],["104474.4","0.036","0","1"],["104474.9","0","0","0"],["104477.2","0.286","0","3"],["104477.9","0.00045","0","1"],["104478.5","0.03301785","0","1"],["104479","0","0","0"],["104480.5","0","0","0"],["104483.2","0.18922353","0","4"],["104485","0","0","0"],["104487","0.000015","0","1"],["104487.7","0.04967946","0","1"],["104488.4","0.01094","0","3"],["104489","0.55687405","0","2"],["104490.3","0","0","0"],["104491.4","0.13876589","0","1"],["104494.1","0.00478606","0","1"],["104495.5","0","0","0"],["104498.6","0.05049549","0","1"],["104502.7","0.00487087","0","2"],["104505.6","0","0","0"],["104506.6","0.0331303","0","2"],["104507.5","0","0","0"],["104512.1","0","0","0"],["104516","1","0","1"],["104524.8","0.1","0","1"],["104527","0.15999999","0","2"],["104530.9","0.00160502","0","2"],["104546.8","0","0","0"],["104558.6","5.8685643","0","1"],["104588.5","0","0","0"],["104625.6","0.234","0","1"],["104625.8","0.00009579","0","1"],["104626","0.01099591","0","1"],["104626.1","0.01488","0","1"]],"bids":[["104470","0.47286813","0","9"],["104465.9","0.03044388","0","1"],["104463.2","0","0","0"],["104462.7","0.0017149","0","1"],["104462.2","0.0005","0","1"],["104462","0.04916839","0","2"],["104460.1","0.19242972","0","1"],["104459.3","0","0","0"],["104458.1","0.10006319","0","1"],["104456.9","0.05288","0","3"],["104452.8","0.03","0","1"],["104452.3","0.25014335","0","2"],["104452.1","0.512185","0","3"],["104451.7","0.00097","0","1"],["104448.5","0.096","0","3"],["104442.5","0.13876705","0","1"],["104438.8","0","0","0"],["104431.5","0.82580208","0","2"],["104417.7","0","0","0"],["104400","1.22149854","0","6"],["104382.1","0","0","0"],["104330.1","0.01053755","0","1"],["104272.9","0","0","0"],["104272.7","0","0","0"]],"ts":"1747171012701","checksum":-888112920,"seqId":54226727979,"prevSeqId":54226727845}]}
{"arg":{"channel":"books","instId":"BTC-USDT"},"action":"update","data":[{"asks":[["104470.1","0.26329701","0","7"],["104475.8","0","0","0"],["104475.9","0.06688931","0","1"],["104476.7","0","0","0"],["104477.2","0.036","0","1"],["104477.9","0.00056435","0","2"],["104478.4","0","0","0"],["104479.1","0.09815383","0","1"],["104479.7","0.09397266","0","1"],["104479.8","0.03823633","0","2"],["104479.9","0.36387852","0","1"],["104480.1","0.052","0","2"],["104480.6","0","0","0"],["104480.7","0.09040176","0","1"],["104481.2","0.09107334","0","1"],["104483.6","0.36908178","0","1"],["104483.9","0","0","0"],["104484","0.43552366","0","3"],["104484.1","0.07298372","0","1"],["104484.2","0.15280061","0","1"],["104484.6","0.15546093","0","1"],["104484.7","0.16921791","0","1"],["104486.3","0","0","0"],["104486.8","0","0","0"],["104487.3","0.00859566","0","1"],["104487.5","0.149653","0","1"],["104488","0.59810437","0","8"],["104488.9","0.00478486","0","1"],["104489","0.60914803","0","2"],["104489.1","0","0","0"],["104489.4","0","0","0"],["104489.7","0.26482912","0","1"],["104490.1","0.26946656","0","1"],["104491.4","0","0","0"],["104493.1","0.13876272","0","1"],["104493.7","0.26439692","0","1"],["104501.2","0.0001303","0","1"],["104505","0.0599306","0","1"],["104506","0.00006","0","1"],["104506.6","0.033","0","1"],["104507","0.002","0","2"],["104508","0.001015","0","2"],["104508.9","0.00013939","0","1"],["104510.4","0.09572","0","1"],["104513.6","0.09572","0","1"],["104513.7","0","0","0"],["104521","0.55453","0","1"],["104527","0","0","0"],["104527.7","0.02091112","0","1"],["104528","0","0","0"],["104529","1.59044344","0","4"],["104530","0.25029005","0","7"],["104531","0.085","0","2"],["104536","0.1435","0","2"],["104542.9","0.067","0","1"],["104558.6","0","0","0"],["104562","5.9383843","0","2"],["104625.4","0","0","0"],["104625.6","0","0","0"],["104625.7","0","0","0"],["104625.8","0","0","0"],["104626","0","0","0"],["104626.1","0","0","0"]],"bids":[["104470","0.70686813","0","10"],["104468.1","0.07922948","0","2"],["104467.6","0.0304434","0","1"],["104466.2","0.0383585","0","1"],["104464.3","0","0","0"],["104462.6","0.51796094","0","2"],["104462","0","0","0"],["104460.2","0.97031201","0","3"],["104460.1","0.26541344","0","2"],["104459.6","0.00955767","0","1"],["104458.7","0.10247634","0","2"],["104458.6","0.01088273","0","1"],["104458.1","0.09946834","0","1"],["104457.4","0.49789411","0","1"],["104457.1","0.15490323","0","1"],["104457","0.00478486","0","1"],["104456.7","0.14998024","0","2"],["104456.4","0","0","0"],["104456.1","0.234","0","1"],["104455.2","0.16671852","0","2"],["104454.7","0.36908178","0","1"],["104454.6","0","0","0"],["104453.1","0","0","0"],["104453","0.26165297","0","2"],["104452.5","0.16627393","0","1"],["104452.3","0.00005","0","1"],["104451.8","0","0","0"],["104450.2","0.24762263","0","1"],["104449.6","0.37072325","0","2"],["104447.1","0.2544186","0","1"],["104446.5","0.28522695","0","1"],["104446.4","0","0","0"],["104446.2","0.24209677","0","1"],["104445.6","0","0","0"],["104445.1","0.13876272","0","1"],["104442.5","0","0","0"],["104406.2","0.00002963","0","1"],["104399.6","0.555174","0","1"],["104274.3","0","0","0"],["104274.1","0","0","0"],["104274","0","0","0"],["104273.7","0","0","0"],["104273.3","0","0","0"]],"ts":"1747171012801","checksum":-783229250,"seqId":54226728143,"prevSeqId":54226727979}]}
{"arg":{"channel":"books","instId":"BTC-USDT"},"action":"update","data":[{"asks":[["104470.1","0.25842881","0","7"],["104481.2","0","0","0"],["104481.3","0.09029036","0","1"],["104493.7","0","0","0"],["104493.8","0.25751379","0","1"],["104505","0.0619306","0","3"],["104506","0.00106","0","2"],["104507","0","0","0"],["104508","0.000015","0","1"],["104537.9","0.09566","0","1"],["104551.9","5.8685743","0","2"],["104562","0.06982","0","1"]],"bids":[["104470","0.47286813","0","9"],["104469.3","0.0304429","0","1"],["104465.9","0","0","0"],["104458.8","0.09913245","0","1"],["104458.7","0.005","0","1"],["104446.3","0.2445571","0","1"],["104446.2","0","0","0"],["104370.1","0.00011851","0","1"],["104319","0.00095696","0","1"],["104275.2","0","0","0"],["104275","0","0","0"],["104274.8","0","0","0"]],"ts":"1747171012901","checksum":-2044719019,"seqId":54226728184,"prevSeqId":54226728143}]}
{"arg":{"channel":"books","instId":"BTC-USDT"},"action":"update","data":[{"asks":[["104493.1","0","0","0"],["104493.6","0.00191","0","1"],["104495.8","0.13876064","0","1"],["104498.8","0.00191","0","1"],["104500.7","0.77866876","0","1"],["104505","0.0599306","0","1"],["104505.9","0","0","0"],["104506","0.00006","0","1"],["104507","0.002","0","2"],["104508","0.001015","0","2"],["104516","0","0","0"],["104527","0.16","0","2"],["104528","0.17999999","0","3"],["104529","1.48044344","0","3"],["104530","0.07029006","0","4"],["104531","0.035","0","1"],["104623.6","0","0","0"],["104624.8","0","0","0"],["104625","0","0","0"]],"bids":[["104447.2","0.13876064","0","1"],["104446.5","0.28713695","0","2"],["104445.1","0","0","0"],["104441.3","0.00191","0","1"],["104428.4","0.00478606","0","1"],["104304.2","0","0","0"],["104295.6","0.0001844","0","1"],["104295.3","0","0","0"],["104277","0.001844","0","1"],["104275.5","0","0","0"],["104275.4","0","0","0"]],"ts":"1747171013001","checksum":-2044719019,"seqId":54226728222,"prevSeqId":54226728184}]}
{"arg":{"channel":"books","instId":"BTC-USDT"},"action":"update","data":[{"asks":[["104479.7","0","0","0"],["104480","0.11235092","0","3"],["104484.4","0.09552534","0","3"],["104484.7","0","0","0"],["104489.7","0","0","0"],["104505","0.0619306","0","3"],["104506","0.00106","0","2"],["104507","0","0","0"],["104508","0.000015","0","1"],["104508.4","0.096704","0","1"],["104532.1","0","0","0"],["104533.5","0.00056666","0","1"],["104544.4","0","0","0"],["104551.9","0.00001","0","1"],["104557.2","0.46541328","0","1"],["104558.6","5.8685643","0","1"],["104608","0.00056666","0","1"],["104623.6","0.00083722","0","2"]],"bids":[["104470","0.47285813","0","8"],["104460.2","0.87213481","0","2"],["104455.2","0.000015","0","1"],["104450.2","0","0","0"],["104423.5","0","0","0"],["104421.3","0.00056666","0","1"],["104346.8","0.00056666","0","1"],["104343","0","0","0"],["104275.5","0.00028209","0","1"]],"ts":"1747171013101","checksum":-1374280323,"seqId":54226728259,"prevSeqId":54226728222}]}
{"arg":{"channel":"books","instId":"BTC-USDT"},"action":"update","data":[{"asks":[["104495.8","0","0","0"],["104497.6","0.13875797","0","1"],["104498.3","0","0","0"],["104525.2","0.29114323","0","1"],["104528","0.24999999","0","5"],["104528.7","0.09567","0","1"],["104529","0.085015","0","3"],["104530","0.00029006","0","2"],["104531","0","0","0"],["104534","0.30722972","0","2"],["104544.2","0.19131","0","1"],["104558.6","0","0","0"],["104560.3","0.00011389","0","1"],["104563.9","0","0","0"],["104567.8","0.00001","0","1"],["104575.5","0.05057082","0","2"],["104625","0.0000103","0","1"],["104625.4","0.00037568","0","2"]],"bids":[["104461.9","0.04469868","0","2"],["104448.8","0.13876797","0","2"],["104447.2","0","0","0"],["104431.5","0.36869051","0","1"],["104427.9","0","0","0"],["104400","0.54405393","0","5"],["104396.6","0","0","0"],["104275.4","0.00018093","0","1"],["104275.2","0.00001919","0","1"],["104275","0.00559802","0","3"]],"ts":"1747171013201","checksum":-1246427217,"seqId":54226728292,"prevSeqId":54226728259}]}
{"arg":{"channel":"books","instId":"BTC-USDT"},"action":"update","data":[{"asks":[["104487.2","0.00478486","0","1"],["104488.9","0","0","0"],["104490.7","0.00478606","0","1"],["104497.6","0.13875796","0","1"],["104502.2","0","0","0"],["104520.2","1.36879678","0","2"],["104551.6","2.44949229","0","1"],["104551.9","5.8685743","0","2"],["104625.4","0","0","0"]],"bids":[["104457","0","0","0"],["104454.8","0.00478486","0","1"],["104448.8","0.13876796","0","2"],["104434.2","0.072525","0","2"],["104428.4","0.00765706","0","2"],["104427.9","1.42048014","0","1"],["104396.6","2.52477347","0","1"],["104384.7","0.36908178","0","1"],["104275.2","0","0","0"],["104275","0","0","0"]],"ts":"1747171013301","checksum":-1246427217,"seqId":54226728317,"prevSeqId":54226728292}]}
{"arg":{"channel":"books","instId":"BTC-USDT"},"action":"update","data":[{"asks":[["104470.1","0.39451378","0","8"],["104478.4","0.09224404","0","1"],["104479.1","0","0","0"],["104480.1","0.14145872","0","3"],["104480.6","0.0972758","0","1"],["104480.7","0","0","0"],["104481.3","0","0","0"],["104483.6","0.51241717","0","2"],["104483.9","0.15172954","0","1"],["104484","0.31507561","0","2"],["104484.2","0","0","0"],["104484.6","0","0","0"],["104486.8","0.15510996","0","1"],["104487.3","0.25376568","0","2"],["104487.5","0","0","0"],["104488","0.36325","0","7"],["104489","0.39763436","0","1"],["104489.4","0.25443018","0","1"],["104490.1","0","0","0"],["104493.1","0.24303665","0","1"],["104493.8","0","0","0"],["104551.9","0.00001","0","1"],["104555.2","5.8685643","0","1"],["104625.4","0.00037568","0","2"]],"bids":[["104460.2","0.77866876","0","1"],["104459.6","0.1023392","0","2"],["104458.8","0","0","0"],["104458.1","0.10019509","0","1"],["104457.4","0.41177042","0","2"],["104457.1","0","0","0"],["104456.7","0.00001","0","1"],["104456.4","0.16205869","0","1"],["104456.1","0.39145469","0","2"],["104453","0.002","0","1"],["104452.5","0","0","0"],["104452.3","0.24178386","0","2"],["104451.8","0.15753943","0","1"],["104447.1","0","0","0"],["104446.5","0.40550775","0","3"],["104446.4","0.26251519","0","1"],["104446.3","0","0","0"],["104445.6","0.2508987","0","1"],["104275.2","0.00001919","0","1"]],"ts":"1747171013401","checksum":-1678132437,"seqId":54226728372,"prevSeqId":54226728317}]}
{"arg":{"channel":"books","instId":"BTC-USDT"},"action":"update","data":[{"asks":[["104480.4","0.00001","0","1"],["104570.5","0.04781","0","1"],["104625","0","0","0"],["104625.4","0","0","0"]],"bids":[["104345.2","0.00001","0","1"],["104275.2","0","0","0"]],"ts":"1747171013501","checksum":-602967346,"seqId":54226728382,"prevSeqId":54226728372}]}
{"arg":{"channel":"books","instId":"BTC-USDT"},"action":"update","data":[{"asks":[],"bids":[["104470","0.47392813","0","9"]],"ts":"1747171013601","checksum":-295930763,"seqId":54226728386,"prevSeqId":54226728382}]}
{"arg":{"channel":"books","instId":"BTC-USDT"},"action":"update","data":[{"asks":[["104494.4","0.13876087","0","1"],["104497.6","0","0","0"]],"bids":[["104470","0.36200475","0","8"],["104448.8","0.00001","0","1"],["104447.1","0.13876087","0","1"],["104275.4","0","0","0"]],"ts":"1747171013701","checksum":-153166319,"seqId":54226728398,"prevSeqId":54226728386}]}
{"arg":{"channel":"books","instId":"BTC-USDT"},"action":"update","data":[{"asks":[["104478.1","0.09564206","0","1"],["104478.4","0","0","0"],["104479.7","0.09195904","0","1"],["104480.1","0.052","0","2"],["104480.2","0.09925815","0","1"],["104480.6","0","0","0"],["104483.2","0.34547657","0","5"],["104483.6","0.52055539","0","2"],["104483.9","0","0","0"],["104486.3","0.00478486","0","1"],["104486.5","0.16088181","0","1"],["104486.8","0","0","0"],["104486.9","0.23007284","0","1"],["104487.2","0","0","0"],["104487.3","0.00859566","0","1"],["104489.1","0.26767696","0","1"],["104489.4","0","0","0"],["104492.7","0.24310375","0","1"],["104493.1","0","0","0"],["104623.6","0","0","0"]],"bids":[["104470","0.20650475","0","6"],["104469.3","0","0","0"],["104468.1","0.07716357","0","1"],["104466.1","0.03144635","0","1"],["104459.6","0.00955767","0","1"],["104459.2","0.09304424","0","1"],["104458.1","0","0","0"],["104457.7","0.09009692","0","1"],["104457.4","0.31874623","0","1"],["104457.1","0.10190082","0","1"],["104456.4","0","0","0"],["104456.1","0.38987939","0","2"],["104455.7","0.24348527","0","4"],["104454.8","0","0","0"],["104453.4","0.00483272","0","2"],["104452.3","0.00005","0","1"],["104451.9","0.24149751","0","1"],["104451.8","0","0","0"],["104451.5","0.18966872","0","2"],["104447.1","0","0","0"],["104446.5","0.44755539","0","3"],["104446.4","0","0","0"],["104446.1","0.25865824","0","1"],["104445.6","0","0","0"],["104445.2","0.25615243","0","1"],["104445.1","0.13876202","0","1"]],"ts":"1747171013801","checksum":-704451919,"seqId":54226728462,"prevSeqId":54226728398}]}
{"arg":{"channel":"books","instId":"BTC-USDT"},"action":"update","data":[{"asks":[["104470.1","0.43717816","0","9"],["104476.5","0.02528202","0","1"],["104478.1","0","0","0"],["104478.3","0.10018191","0","1"],["104479.7","0","0","0"],["104480","0.20797395","0","4"],["104480.2","0","0","0"],["104480.5","0.09025049","0","1"],["104483.2","0.18922353","0","4"],["104483.5","0.16049638","0","1"],["104483.6","0.36908178","0","1"],["104483.8","0.15909529","0","1"],["104484.4","0.0383685","0","2"],["104486.5","0","0","0"],["104486.7","0.16409728","0","1"],["104486.9","0","0","0"],["104487.2","0.23366498","0","1"],["104489.1","0","0","0"],["104489.3","0.26689256","0","1"],["104492.7","0","0","0"],["104493","0.25620201","0","1"],["104504","0.07499898","0","4"],["104505","0.0609306","0","2"],["104506","0.00006","0","1"],["104526","0.15999999","0","2"],["104527","0.24999999","0","5"],["104528","0.085","0","2"],["104529","0.000015","0","1"],["104622.1","0","0","0"],["104623.3","0","0","0"],["104623.4","0","0","0"]],"bids":[["104470","0.30476913","0","7"],["104467.6","0","0","0"],["104466.2","0","0","0"],["104465.2","0.03144664","0","1"],["104462.6","0.24282269","0","2"],["104462.5","0","0","0"],["104460.4","0.04394753","0","1"],["104460.2","0","0","0"],["104459.5","0.08593651","0","1"],["104459.2","0","0","0"],["104458","0.09206332","0","1"],["104457.7","0","0","0"],["104457.4","0.30053908","0","2"],["104457.3","0.08942896","0","1"],["104457.1","0","0","0"],["104456.3","0.16012888","0","1"],["104456.1","0.234","0","1"],["104456","0.14550916","0","1"],["104455.7","0.09191","0","3"],["104454.7","0","0","0"],["104452.2","0.23279989","0","1"],["104451.9","0","0","0"],["104451.7","0.1489928","0","2"],["104451.5","0.03","0","1"],["104446.5","0.44684874","0","3"],["104446.3","0.26893468","0","1"],["104446.1","0","0","0"],["104445.5","0.2435205","0","1"],["104445.2","0","0","0"],["104428.4","0.00478606","0","1"],["104402.8","0.03567119","0","2"],["104275.4","0.00018093","0","1"]],"ts":"1747171013901","checksum":-1111550786,"seqId":54226728587,"prevSeqId":54226728462}]}
{"arg":{"channel":"books","instId":"BTC-USDT"},"action":"update","data":[{"asks":[["104475.9","0.09616732","0","2"],["104476.5","0","0","0"],["104488.5","0.04967909","0","1"],["104502","0.002","0","2"],["104503","0.001","0","1"],["104504","0.07299898","0","2"],["104505","0.0599306","0","1"],["104516","1","0","1"],["104524","0.16001723","0","3"],["104525","0.24999999","0","5"],["104526","0.085","0","2"],["104527","0","0","0"],["104528","0","0","0"],["104621.4","0","0","0"],["104622","0","0","0"]],"bids":[["104468.2","0.0383585","0","1"],["104454.1","0.36908178","0","1"],["104275.5","0","0","0"],["104275.4","0","0","0"]],"ts":"1747171014001","checksum":-1315008584,"seqId":54226728619,"prevSeqId":54226728587}]}
{"arg":{"channel":"books","instId":"BTC-USDT"},"action":"update","data":[{"asks":[["104492.9","0.1387636","0","1"],["104494.4","0","0","0"],["104515.9","0.30186148","0","1"],["104533","0.00056666","0","1"],["104533.5","0","0","0"],["104551.5","0.8365473","0","1"],["104604","0.00056666","0","1"],["104608","0","0","0"],["104620.2","0","0","0"],["104621.3","0","0","0"]],"bids":[["104470","0.30369913","0","6"],["104435.3","0.00001","0","1"],["104431.5","0.84049411","0","2"],["104426.1","0.00056666","0","1"],["104421.3","0","0","0"],["104400","1.39600289","0","6"],["104355","0.00057666","0","2"],["104346.8","0","0","0"]],"ts":"1747171014101","checksum":-75467063,"seqId":54226728650,"prevSeqId":54226728619}]}
{"arg":{"channel":"books","instId":"BTC-USDT"},"action":"update","data":[{"asks":[],"bids":[["104445.6","0.13876296","0","1"],["104445.1","0","0","0"],["104357.1","0","0","0"],["104354.6","0.00064013","0","1"]],"ts":"1747171014201","checksum":-75467063,"seqId":54226728662,"prevSeqId":54226728650}]}
{"arg":{"channel":"books","instId":"BTC-USDT"},"action":"update","data":[{"asks":[["104475.9","0.06688931","0","1"],["104478.3","0","0","0"],["104478.4","0.09088027","0","1"],["104479.1","0.09784046","0","1"],["104480","0.11235092","0","3"],["104480.1","0.14360715","0","3"],["104480.5","0","0","0"],["104480.6","0.09257951","0","1"],["104483.5","0","0","0"],["104483.6","0.52235652","0","2"],["104483.8","0","0","0"],["104483.9","0.52433984","0","3"],["104484","0.0932","0","1"],["104484.1","0.23133322","0","2"],["104486.7","0","0","0"],["104486.8","0.1457162","0","1"],["104487.2","0","0","0"],["104487.3","0.25047997","0","2"],["104489","0.56649328","0","2"],["104489.1","0.26836682","0","1"],["104489.3","0","0","0"],["104489.4","0.26956955","0","1"],["104492.9","0","0","0"],["104493","0","0","0"],["104493.1","0.25064038","0","1"],["104495.8","0.13876055","0","1"],["104557.2","0","0","0"],["104620.2","0.0026904","0","1"]],"bids":[["104470","0.36962251","0","8"],["104467.9","0.02336476","0","1"],["104465.2","0","0","0"],["104462.6","0.30958276","0","3"],["104459.6","0.18922234","0","3"],["104459.5","0","0","0"],["104458.1","0.09125159","0","1"],["104458","0","0","0"],["104457.4","0.41232221","0","2"],["104457.3","0","0","0"],["104456.4","0.1540506","0","1"],["104456.3","0","0","0"],["104456.1","0.3855219","0","2"],["104456","0","0","0"],["104454.6","0.15807241","0","1"],["104454.2","0.00478486","0","1"],["104453.4","0.00004786","0","1"],["104452.3","0.2337979","0","2"],["104452.2","0","0","0"],["104451.8","0.16450829","0","1"],["104451.7","0.00097","0","1"],["104449.6","0.64281077","0","3"],["104447.1","0.13876055","0","1"],["104446.5","0.39726998","0","3"],["104446.4","0.2505806","0","1"],["104446.3","0","0","0"],["104445.6","0.23537406","0","1"],["104445.5","0","0","0"],["104275.5","0.00028209","0","1"]],"ts":"1747171014301","checksum":-1698581919,"seqId":54226728769,"prevSeqId":54226728662}]}
{"arg":{"channel":"books","instId":"BTC-USDT"},"action":"update","data":[{"asks":[["104475.9","0.09412283","0","2"],["104478.8","0","0","0"],["104479.8","0.00521888","0","1"],["104480.2","0.02299079","0","1"],["104482.6","0.04435084","0","1"],["104488.5","0","0","0"],["104494.3","0.13876202","0","1"],["104495.8","0","0","0"],["104515.9","0","0","0"],["104516","0","0","0"],["104525","0.17999999","0","3"],["104526","0.05","0","1"],["104528","0.07","0","2"],["104529","0.035015","0","2"],["104555.2","0","0","0"],["104558.6","5.79887346","0","1"],["104621.3","0.01099559","0","1"]],"bids":[["104470","0.33969913","0","7"],["104468.1","0.07296633","0","1"],["104454.2","0","0","0"],["104453.4","0.00483272","0","2"],["104447.1","0","0","0"],["104445.7","0.13876193","0","1"],["104428.8","0.00001","0","1"]],"ts":"1747171014401","checksum":-1760878962,"seqId":54226728848,"prevSeqId":54226728769}]}
{"arg":{"channel":"books","instId":"BTC-USDT"},"action":"update","data":[{"asks":[["104475.4","0.0180746","0","1"],["104476.4","0.00001","0","1"],["104482.6","0","0","0"],["104483.4","0.19242972","0","1"],["104488.7","0.03828293","0","1"],["104494.3","0","0","0"],["104495.8","0.13876057","0","1"],["104503.1","0.05215051","0","1"],["104620","0","0","0"],["104620.2","0","0","0"],["104621.3","0","0","0"]],"bids":[["104470","0.41142251","0","9"],["104462.6","0.53483838","0","2"],["104460.2","0.77866876","0","1"],["104454.2","0.00478486","0","1"],["104453.4","0.00004786","0","1"],["104447.1","0.13876071","0","1"],["104445.7","0","0","0"],["104275.9","0","0","0"],["104275.5","0","0","0"]],"ts":"1747171014501","checksum":582643199,"seqId":54226728870,"prevSeqId":54226728848}]}
{"arg":{"channel":"books","instId":"BTC-USDT"},"action":"update","data":[{"asks":[["104525","0.24999999","0","5"],["104526","0.085","0","2"],["104528","0","0","0"],["104529","0.000015","0","1"],["104620","0.00222603","0","4"]],"bids":[["104470","0.37100251","0","9"]],"ts":"1747171014601","checksum":-1004454271,"seqId":54226728878,"prevSeqId":54226728870}]}
{"arg":{"channel":"books","instId":"BTC-USDT"},"action":"update","data":[{"asks":[["104486.3","0","0","0"],["104488.9","0.00478486","0","1"],["104494.4","0.13876176","0","1"],["104495.8","0","0","0"],["104521.4","0.00004967","0","1"],["104534.1","0","0","0"],["104583","0.0016","0","1"],["104620","0","0","0"]],"bids":[["104457","0.00478486","0","1"],["104454.2","0","0","0"],["104447.1","0","0","0"],["104445.7","0.13876176","0","1"]],"ts":"1747171014801","checksum":-1004454271,"seqId":54226728900,"prevSeqId":54226728878}]}
{"arg":{"channel":"books","instId":"BTC-USDT"},"action":"update","data":[{"asks":[["104478.5","0","0","0"],["104481.5","0.0229905","0","1"]],"bids":[],"ts":"1747171014901","checksum":-971546978,"seqId":54226728906,"prevSeqId":54226728900}]}
{"arg":{"channel":"books","instId":"BTC-USDT"},"action":"update","data":[{"asks":[["104486.3","0.00478486","0","1"],["104488.9","0","0","0"]],"bids":[["104470","0.34037913","0","8"],["104457","0","0","0"],["104454.2","0.00478486","0","1"],["104430","0.00029006","0","2"],["104419","0.53523352","0","3"],["104383","0","0","0"],["104372","0.47441417","0","2"],["104275.9","0.00001015","0","1"]],"ts":"1747171015001","checksum":-2026705089,"seqId":54226728917,"prevSeqId":54226728906}]}
{"arg":{"channel":"books","instId":"BTC-USDT"},"action":"update","data":[{"asks":[["104477.7","0.02776846","0","1"],["104494.4","0.13876092","0","1"],["104498.6","0","0","0"],["104506.5","0.12133243","0","1"],["104533","0","0","0"],["104533.6","0.00056666","0","1"],["104542.4","1.19751196","0","2"],["104551.5","0","0","0"],["104604","0","0","0"],["104604.7","0.03074142","0","3"],["104620","0.00222603","0","4"]],"bids":[["104470","0.37143589","0","11"],["104447.1","0.13876092","0","1"],["104445.7","0","0","0"],["104426.8","0.00074142","0","2"],["104426.1","0","0","0"],["104355.7","0.00056666","0","1"],["104355","0.00001","0","1"]],"ts":"1747171015101","checksum":1412452344,"seqId":54226728953,"prevSeqId":54226728917}]}
{"arg":{"channel":"books","instId":"BTC-USDT"},"action":"update","data":[{"asks":[["104472.3","0.002","0","1"],["104477.7","0","0","0"],["104484.8","0.002","0","1"],["104490.1","0.05565236","0","1"],["104490.2","0","0","0"],["104502.7","0.00287087","0","1"],["104620","0","0","0"]],"bids":[["104470","0.34038913","0","9"],["104467.7","0.002","0","1"],["104465.5","0","0","0"],["104455.2","0.002015","0","2"],["104453","0","0","0"],["104275.5","0.00028209","0","1"]],"ts":"1747171015201","checksum":-1622712797,"seqId":54226728971,"prevSeqId":54226728953}]}
{"arg":{"channel":"books","instId":"BTC-USDT"},"action":"update","data":[{"asks":[["104494.4","0","0","0"],["104495.8","0.13876052","0","1"],["104548.5","5.79887346","0","1"],["104558.6","0","0","0"]],"bids":[["104469.6","0.02336436","0","1"],["104453.3","0","0","0"]],"ts":"1747171015301","checksum":1569758771,"seqId":54226728991,"prevSeqId":54226728971}]}
{"arg":{"channel":"books","instId":"BTC-USDT"},"action":"update","data":[{"asks":[["104484.2","0.01","0","1"],["104488.4","0.00094","0","2"],["104516","1","0","1"],["104548.5","0","0","0"],["104558.6","5.82248206","0","1"],["104618.5","0","0","0"],["104619.3","0","0","0"]],"bids":[],"ts":"1747171015401","checksum":1569758771,"seqId":54226729002,"prevSeqId":54226728991}]}
{"arg":{"channel":"books","instId":"BTC-USDT"},"action":"update","data":[{"asks":[["104551.9","5.82249206","0","2"],["104558.6","0","0","0"],["104618.5","0.00009552","0","1"]],"bids":[["104470","0.37171251","0","10"]],"ts":"1747171015501","checksum":223263069,"seqId":54226729008,"prevSeqId":54226729002}]}
{"arg":{"channel":"books","instId":"BTC-USDT"},"action":"update","data":[{"asks":[["104551.9","5.8285679","0","2"]],"bids":[],"ts":"1747171015601","checksum":223263069,"seqId":54226729013,"prevSeqId":54226729008}]}
{"arg":{"channel":"books","instId":"BTC-USDT"},"action":"update","data":[{"asks":[],"bids":[["104470","0.37751251","0","11"]],"ts":"1747171015701","checksum":708112616,"seqId":54226729022,"prevSeqId":54226729013}]}
{"arg":{"channel":"books","instId":"BTC-USDT"},"action":"update","data":[{"asks":[["104470.1","0.39451378","0","8"],["104474.4","0","0","0"],["104486.3","0","0","0"],["104487.6","0.00478486","0","1"],["104495.8","0","0","0"],["104497.6","0.13875801","0","1"],["104516","0","0","0"],["104619.3","0.04304781","0","1"],["104620","0.00222603","0","4"]],"bids":[["104470","0.39779748","0","20"],["104455.8","0.00478486","0","1"],["104454.2","0","0","0"],["104448.8","0.13876864","0","2"],["104447.1","0","0","0"],["104275.4","0.00018093","0","1"]],"ts":"1747171015801","checksum":1405873465,"seqId":54226729074,"prevSeqId":54226729022}]}
{"arg":{"channel":"books","instId":"BTC-USDT"},"action":"update","data":[{"asks":[["104486.7","0.00478486","0","1"],["104487.6","0","0","0"],["104551.9","0.00001","0","1"],["104555.2","5.8285579","0","1"],["104620","0","0","0"]],"bids":[["104467.3","0.07298372","0","1"],["104455.8","0","0","0"],["104454.7","0.00478486","0","1"],["104439.7","0.002871","0","1"],["104428.8","0","0","0"],["104402.8","0.03279989","0","1"],["104275.4","0","0","0"]],"ts":"1747171015901","checksum":-354593142,"seqId":54226729088,"prevSeqId":54226729074}]}
{"arg":{"channel":"books","instId":"BTC-USDT"},"action":"update","data":[{"asks":[["104495.8","0.13875894","0","1"],["104497.6","0","0","0"]],"bids":[["104470","0.3598841","0","11"],["104462.6","0.43813438","0","1"],["104461.6","0","0","0"],["104448.8","0.00001","0","1"],["104447.1","0.13875894","0","1"],["104439.7","0","0","0"],["104416.7","0.002871","0","1"],["104406.2","0","0","0"],["104275.4","0.00018093","0","1"]],"ts":"1747171016001","checksum":-1985417127,"seqId":54226729113,"prevSeqId":54226729088}]}
{"arg":{"channel":"books","instId":"BTC-USDT"},"action":"update","data":[{"asks":[["104486.7","0","0","0"],["104487.2","0.00478486","0","1"],["104495.8","0","0","0"],["104497.6","0.13875641","0","1"],["104508.3","0.00013952","0","1"],["104508.9","0","0","0"],["104515.3","0.01047491","0","1"],["104533.6","0","0","0"],["104537.4","0.00056666","0","1"],["104604.7","0.03017476","0","2"],["104608.5","0.00056666","0","1"],["104618.5","0","0","0"],["104619.3","0","0","0"]],"bids":[["104470","0.4054811","0","18"],["104460.2","0.87537276","0","2"],["104458.8","0.071773","0","1"],["104455.3","0.00478486","0","1"],["104454.7","0","0","0"],["104450","0.13904646","0","3"],["104447.1","0","0","0"],["104430.5","0.00056666","0","1"],["104426.8","0.00017476","0","1"],["104406.2","0.00002963","0","1"],["104359.5","0.12056666","0","2"],["104357.1","0.00064011","0","1"],["104355.7","0","0","0"],["104354.6","0","0","0"],["104275.4","0","0","0"]],"ts":"1747171016101","checksum":-1951264380,"seqId":54226729169,"prevSeqId":54226729113}]}
{"arg":{"channel":"books","instId":"BTC-USDT"},"action":"update","data":[{"asks":[["104497.6","0.1387574","0","1"]],"bids":[["104450","0.13904703","0","3"],["104406.3","0.00002963","0","1"],["104406.2","0","0","0"]],"ts":"1747171016201","checksum":-1951264380,"seqId":54226729195,"prevSeqId":54226729169}]}
{"arg":{"channel":"books","instId":"BTC-USDT"},"action":"update","data":[{"asks":[["104486.7","0.00478486","0","1"],["104487.2","0","0","0"],["104495.8","0.1387591","0","1"],["104497.6","0","0","0"]],"bids":[["104455.3","0","0","0"],["104454.7","0.00478486","0","1"],["104450","0.00029006","0","2"],["104447.1","0.1387591","0","1"],["104435.3","0","0","0"]],"ts":"1747171016301","checksum":-1951264380,"seqId":54226729208,"prevSeqId":54226729195}]}
{"arg":{"channel":"books","instId":"BTC-USDT"},"action":"update","data":[{"asks":[["104486.7","0","0","0"],["104487","0.00479986","0","2"],["104489","0.39763436","0","1"],["104489.2","0","0","0"],["104495.8","0","0","0"],["104497.6","0.13875782","0","1"],["104601.5","0.00449585","0","2"],["104604.9","0","0","0"],["104618.5","0.00009552","0","1"],["104619.3","0.04304781","0","1"],["104620","0.00222603","0","4"]],"bids":[["104470","0.3894811","0","17"],["104455.3","0.00478486","0","1"],["104454.7","0","0","0"],["104448.8","0.13876782","0","2"],["104447.1","0","0","0"],["104275.4","0.00018093","0","1"]],"ts":"1747171016401","checksum":-2140201505,"seqId":54226729224,"prevSeqId":54226729208}]}
{"arg":{"channel":"books","instId":"BTC-USDT"},"action":"update","data":[{"asks":[["104483.9","0.73835085","0","2"],["104486.7","0.00478486","0","1"],["104487","0.000015","0","1"],["104487.9","0.77866876","0","1"],["104496.1","0.13875825","0","1"],["104497.6","0","0","0"],["104502","0","0","0"],["104503","0","0","0"],["104505","0.0619306","0","3"],["104506","0.00106","0","2"],["104524","0.00001723","0","1"],["104525","0","0","0"],["104526","0","0","0"],["104527","0.16","0","2"],["104528","0.24999999","0","5"],["104529","0.085015","0","3"]],"bids":[["104455.3","0","0","0"],["104454.7","0.00478486","0","1"]],"ts":"1747171016501","checksum":-2140201505,"seqId":54226729262,"prevSeqId":54226729224}]}
{"arg":{"channel":"books","instId":"BTC-USDT"},"action":"update","data":[{"asks":[["104495.8","0.13875895","0","1"],["104496.1","0","0","0"],["104503","0.002","0","2"],["104504","0.07399898","0","3"],["104505","0.0599306","0","1"],["104506","0.00006","0","1"],["104525","0.15999999","0","2"],["104526","0.24999999","0","5"],["104527","0.085","0","2"],["104528","0","0","0"],["104529","0.000015","0","1"],["104619.3","0","0","0"],["104620","0","0","0"]],"bids":[["104448.8","0.00001","0","1"],["104447.1","0.13875895","0","1"],["104275.4","0","0","0"]],"ts":"1747171016701","checksum":-2140201505,"seqId":54226729291,"prevSeqId":54226729262}]}
{"arg":{"channel":"books","instId":"BTC-USDT"},"action":"update","data":[{"asks":[["104486.7","0","0","0"],["104487.9","0.78345362","0","2"],["104495.8","0.13875909","0","1"],["104502","0.002","0","2"],["104503","0.001","0","1"],["104504","0.07299898","0","2"],["104524","0.16001723","0","3"],["104525","0.24999999","0","5"],["104526","0.085","0","2"],["104527","0","0","0"],["104619.3","0.04304781","0","1"]],"bids":[["104456.5","0.00478486","0","1"],["104454.7","0","0","0"],["104447.1","0.13875909","0","1"]],"ts":"1747171016801","checksum":-2140201505,"seqId":54226729322,"prevSeqId":54226729291}]}
{"arg":{"channel":"books","instId":"BTC-USDT"},"action":"update","data":[{"asks":[["104502.4","0.00287087","0","1"],["104502.7","0","0","0"]],"bids":[],"ts":"1747171016901","checksum":-2140201505,"seqId":54226729326,"prevSeqId":54226729322}]}
{"arg":{"channel":"books","instId":"BTC-USDT"},"action":"update","data":[{"asks":[["104495.8","0","0","0"],["104497.6","0.13875817","0","1"]],"bids":[["104470","0.3894711","0","16"],["104448.8","0.13876847","0","2"],["104447.1","0","0","0"],["104275.4","0.00018093","0","1"]],"ts":"1747171017001","checksum":-190141242,"seqId":54226729336,"prevSeqId":54226729326}]}
{"arg":{"channel":"books","instId":"BTC-USDT"},"action":"update","data":[{"asks":[["104487.9","0.77866876","0","1"],["104488.6","0.00478486","0","1"],["104537.3","0.01491285","0","2"],["104537.4","0","0","0"],["104608.3","0.03056666","0","2"],["104608.5","0","0","0"],["104620","0.00222603","0","4"]],"bids":[["104457","0.00478486","0","1"],["104456.5","0","0","0"],["104430.5","0","0","0"],["104430.4","0.00056666","0","1"],["104359.5","0.12","0","1"],["104359.3","0.00056666","0","1"],["104275.4","0","0","0"]],"ts":"1747171017101","checksum":-190141242,"seqId":54226729352,"prevSeqId":54226729336}]}
{"arg":{"channel":"books","instId":"BTC-USDT"},"action":"update","data":[{"asks":[["104488.3","0.04685223","0","4"],["104488.6","0","0","0"],["104495.8","0.13875863","0","1"],["104497.6","0","0","0"],["104520.1","1.0626784","0","2"],["104520.3","0","0","0"],["104546.2","0","0","0"],["104620.2","0.0026904","0","1"],["104621.3","0.01099559","0","1"],["104621.4","0.0579344","0","1"]],"bids":[["104457","0","0","0"],["104456.5","0.00478486","0","1"],["104448.8","0.00001","0","1"],["104447.1","0.13875907","0","1"],["104275.5","0","0","0"]],"ts":"1747171017201","checksum":-190141242,"seqId":54226729367,"prevSeqId":54226729352}]}
{"arg":{"channel":"books","instId":"BTC-USDT"},"action":"update","data":[{"asks":[["104488.3","0.04206737","0","3"],["104488.9","0.00478486","0","1"],["104495.8","0","0","0"],["104497.6","0.13875818","0","1"],["104621.4","0","0","0"]],"bids":[["104457","0.00478486","0","1"],["104456.5","0","0","0"],["104448.8","0.13876818","0","2"],["104447.1","0","0","0"],["104417.8","0.00001","0","1"]],"ts":"1747171017301","checksum":-190141242,"seqId":54226729378,"prevSeqId":54226729367}]}
{"arg":{"channel":"books","instId":"BTC-USDT"},"action":"update","data":[{"asks":[["104495.8","0.13875887","0","1"],["104497.6","0","0","0"]],"bids":[["104448.8","0.00001","0","1"],["104447.1","0.13875887","0","1"],["104275.9","0","0","0"]],"ts":"1747171017401","checksum":-190141242,"seqId":54226729382,"prevSeqId":54226729378}]}
{"arg":{"channel":"books","instId":"BTC-USDT"},"action":"update","data":[{"asks":[["104477.9","0.00045","0","1"],["104479.8","0.00533323","0","2"],["104495.8","0","0","0"],["104497.6","0.13875784","0","1"]],"bids":[["104470","0.3894811","0","17"],["104448.8","0.13876784","0","2"],["104447.1","0","0","0"],["104275.9","0.00001015","0","1"]],"ts":"1747171017501","checksum":1532889242,"seqId":54226729391,"prevSeqId":54226729382}]}
{"arg":{"channel":"books","instId":"BTC-USDT"},"action":"update","data":[{"asks":[["104590.1","0.0013452","0","1"],["104602.3","0","0","0"],["104602.4","0.0026904","0","1"],["104620.2","0","0","0"]],"bids":[["104366","0","0","0"],["104355.6","0","0","0"],["104344.8","0.0013452","0","1"],["104334.4","0.78135916","0","2"],["104275.5","0.00028209","0","1"]],"ts":"1747171017601","checksum":1532889242,"seqId":54226729401,"prevSeqId":54226729391}]}
{"arg":{"channel":"books","instId":"BTC-USDT"},"action":"update","data":[{"asks":[["104495.8","0.13875996","0","1"],["104497.6","0","0","0"]],"bids":[["104448.8","0.00001","0","1"],["104447.1","0.13875996","0","1"],["104275.5","0","0","0"]],"ts":"1747171017701","checksum":1532889242,"seqId":54226729406,"prevSeqId":54226729401}]}
{"arg":{"channel":"books","instId":"BTC-USDT"},"action":"update","data":[{"asks":[["104487.6","0.00478486","0","1"],["104488.9","0","0","0"],["104495.8","0.13875927","0","1"],["104516","1","0","1"],["104621.3","0","0","0"]],"bids":[["104457","0","0","0"],["104456.2","0.00478486","0","1"],["104447.1","0.13875927","0","1"],["104406.3","0","0","0"],["104275.5","0.00028209","0","1"]],"ts":"1747171017801","checksum":1532889242,"seqId":54226729423,"prevSeqId":54226729406}]}
{"arg":{"channel":"books","instId":"BTC-USDT"},"action":"update","data":[{"asks":[["104477.9","0.00056435","0","2"],["104479.8","0.00521888","0","1"],["104495.8","0","0","0"],["104497.6","0.1387567","0","1"]],"bids":[["104450","0.13904676","0","3"],["104447.1","0","0","0"],["104406.2","0.00002963","0","1"]],"ts":"1747171017901","checksum":-2140201505,"seqId":54226729431,"prevSeqId":54226729423}]}
{"arg":{"channel":"books","instId":"BTC-USDT"},"action":"update","data":[{"asks":[["104495.8","0.13875893","0","1"],["104497.6","0","0","0"]],"bids":[["104450","0.00029006","0","2"],["104447.1","0.13875893","0","1"],["104275.5","0","0","0"]],"ts":"1747171018001","checksum":-2140201505,"seqId":54226729449,"prevSeqId":54226729431}]}
{"arg":{"channel":"books","instId":"BTC-USDT"},"action":"update","data":[{"asks":[["104483.2","0.18422353","0","3"],["104487.6","0","0","0"],["104487.8","0.00478486","0","1"],["104488","0.3632","0","3"],["104495.7","0.0058","0","2"],["104537.1","0.00056666","0","1"],["104537.3","0.01434619","0","1"],["104608.1","0.00056666","0","1"],["104608.3","0.03","0","1"],["104619.3","0","0","0"],["104620","0","0","0"]],"bids":[["104459.6","0.17966467","0","2"],["104459.5","0.00955768","0","1"],["104431.8","0","0","0"],["104430.4","0","0","0"],["104430.3","0.00056666","0","1"],["104419.3","0","0","0"],["104275.5","0.00028209","0","1"]],"ts":"1747171018101","checksum":1022430721,"seqId":54226729472,"prevSeqId":54226729449}]}
{"arg":{"channel":"books","instId":"BTC-USDT"},"action":"update","data":[{"asks":[["104470.1","0.44117816","0","9"],["104480.1","0.14201122","0","3"],["104483.6","0.51488096","0","2"],["104487.6","0.00478486","0","1"],["104487.8","0","0","0"],["104490.2","0.009275","0","1"],["104492.3","0.009285","0","2"],["104493.4","0.009275","0","1"],["104494.4","0.13876155","0","1"],["104495.8","0","0","0"],["104498.6","0.009275","0","1"],["104510.9","0.00956633","0","1"],["104513","0.04581943","0","1"],["104515.3","0.30916554","0","2"],["104542.4","0.12728484","0","1"],["104546.2","0.08687986","0","1"],["104555.2","0","0","0"],["104558.6","5.89729135","0","1"],["104617.6","0","0","0"],["104617.7","0","0","0"],["104617.8","0","0","0"],["104618","0","0","0"],["104618.5","0","0","0"]],"bids":[["104470","0.35971116","0","10"],["104469.6","0","0","0"],["104467.3","0","0","0"],["104459.6","0.17673497","0","2"],["104457.5","0.04551465","0","1"],["104456.2","0","0","0"],["104456.1","0.38338433","0","2"],["104455.8","0.00478486","0","1"],["104447.1","0","0","0"],["104446.5","0.53603153","0","4"],["104275.4","0.00018093","0","1"],["104275.2","0.00001919","0","1"]],"ts":"1747171018201","checksum":83777965,"seqId":54226729544,"prevSeqId":54226729472}]}
{"arg":{"channel":"books","instId":"BTC-USDT"},"action":"update","data":[{"asks":[["104472.6","0.00854664","0","1"],["104479.3","0.0000125","0","1"],["104481.4","0.0000125","0","1"],["104482.4","0.0360125","0","2"],["104487.6","0.0000125","0","1"],["104488.9","0.00478486","0","1"],["104490.2","0","0","0"],["104492.3","0.00001","0","1"],["104493.4","0","0","0"],["104494.4","0","0","0"],["104495.8","0.13876002","0","1"],["104498.6","0","0","0"],["104515.3","0.01047491","0","1"],["104516","0","0","0"],["104555.2","5.89926827","0","1"],["104558.6","0","0","0"]],"bids":[["104470","0.39084198","0","11"],["104457.5","0","0","0"],["104457","0.00478486","0","1"],["104455.8","0","0","0"],["104447.1","0.13876002","0","1"],["104446.5","0.39726998","0","3"]],"ts":"1747171018301","checksum":284453369,"seqId":54226729581,"prevSeqId":54226729544}]}
{"arg":{"channel":"books","instId":"BTC-USDT"},"action":"update","data":[{"asks":[],"bids":[["104447.1","0.13876009","0","1"],["104370.1","0","0","0"],["104319","0","0","0"],["104275","0.00559802","0","3"],["104274.8","0.00005355","0","1"]],"ts":"1747171018401","checksum":284453369,"seqId":54226729587,"prevSeqId":54226729581}]}
{"arg":{"channel":"books","instId":"BTC-USDT"},"action":"update","data":[{"asks":[["104472.2","0.005","0","1"],["104484.7","0.005","0","1"],["104495.7","0.14456023","0","3"],["104495.8","0","0","0"],["104616.6","0","0","0"]],"bids":[["104470","0.43084198","0","11"],["104431.8","0.005","0","1"],["104419.3","0.005","0","1"],["104275","0","0","0"],["104274.8","0","0","0"]],"ts":"1747171018501","checksum":1617905472,"seqId":54226729601,"prevSeqId":54226729587}]}
{"arg":{"channel":"books","instId":"BTC-USDT"},"action":"update","data":[{"asks":[["104469.3","0.7580224","0","20"],["104469.6","0.09875","0","1"],["104470","0.00001","0","1"],["104470.1","0.286","0","3"],["104473.9","0.01914239","0","1"],["104475.9","0.14400048","0","2"],["104477.9","0.00045","0","1"],["104478.4","0","0","0"],["104478.5","0.02929014","0","1"],["104479.1","0.03746135","0","1"],["104479.7","0.00478486","0","1"],["104479.8","0.00533323","0","2"],["104480","0.09349006","0","3"],["104480.1","0.052","0","2"],["104480.2","0.0383585","0","1"],["104480.6","0","0","0"],["104481.5","0","0","0"],["104482.1","0.03828478","0","1"],["104482.2","0.05370644","0","1"],["104483.6","0.36908178","0","1"],["104483.9","0.58512813","0","1"],["104484.1","0.07298372","0","1"],["104484.4","0.00001","0","1"],["104486.8","0","0","0"],["104487.3","0.00859566","0","1"],["104488.3","0.00373804","0","2"],["104488.7","0","0","0"],["104488.9","0.13876849","0","1"],["104489","0.20374905","0","1"],["104489.1","0","0","0"],["104489.4","0","0","0"],["104490.1","0","0","0"],["104492","0.04","0","1"],["104493.1","0","0","0"],["104495.7","0.0058","0","2"],["104498","0.036","0","1"],["104500.5","0.56032","0","2"],["104501.6","0.00287087","0","1"],["104502","0","0","0"],["104502.4","0","0","0"],["104503","0.002","0","2"],["104504","0.07399898","0","3"],["104517.9","0.0022","0","1"],["104520.7","0","0","0"],["104524","0.00001723","0","1"],["104525","0.15999999","0","2"],["104526","0.24999999","0","5"],["104527","0.085","0","2"],["104538.1","0","0","0"],["104615.1","0.78926418","0","2"],["104616.6","0.00007797","0","4"]],"bids":[["104470","0","0","0"],["104468.2","0","0","0"],["104468.1","0","0","0"],["104468","0","0","0"],["104467.9","0","0","0"],["104466.1","0","0","0"],["104464.9","0.03072894","0","1"],["104464","0.0932","0","1"],["104462.7","0","0","0"],["104462.6","0.04871279","0","1"],["104461.9","0.036","0","1"],["104460.2","0","0","0"],["104460.1","0","0","0"],["104459.6","0","0","0"],["104459.5","0","0","0"],["104458.8","0.01127264","0","2"],["104458.1","0","0","0"],["104457.4","0.30423465","0","2"],["104457","0","0","0"],["104456.4","0","0","0"],["104456.1","0","0","0"],["104455.4","0.04551555","0","1"],["104454.6","0","0","0"],["104454.1","0","0","0"],["104452.3","0.00005","0","1"],["104451.8","0","0","0"],["104449.6","0.37072325","0","2"],["104447.6","0.00478486","0","1"],["104447.3","0","0","0"],["104447.1","0","0","0"],["104446.4","0","0","0"],["104445.6","0","0","0"],["104443.6","0","0","0"],["104443.4","0.25623602","0","1"],["104440.4","0.13876849","0","1"],["104434.2","0.000015","0","1"],["104429.9","0","0","0"],["104427.5","0.0022","0","1"],["104415.5","0.1586995","0","2"],["104415.4","0","0","0"],["104410.2","0.0022","0","1"],["104410","0.46447282","0","2"],["104391.9","0.234","0","1"],["104370.1","0.00011955","0","1"],["104363.3","0","0","0"],["104349.6","0.00001","0","1"],["104319","0.00095694","0","1"],["104280","0.004027","0","14"],["104275","0.00559802","0","3"],["104274.8","0.00005355","0","1"],["104274.3","0.00005483","0","3"],["104274.1","0.0001347","0","1"],["104274","0.00001007","0","1"],["104273.7","0.00019702","0","2"],["104273.3","0.07298372","0","1"],["104272.9","0.00003136","0","1"],["104272.7","0.00025768","0","6"],["104272.3","0.00001222","0","1"],["104272.2","0.00033769","0","1"],["104272","0.00086241","0","4"],["104271.9","0.00004632","0","2"],["104271.8","0.0000102","0","1"]],"ts":"1747171018601","checksum":987233738,"seqId":54226729912,"prevSeqId":54226729601}]}
{"arg":{"channel":"books","instId":"BTC-USDT"},"action":"update","data":[{"asks":[["104469.3","1.35985572","0","22"],["104469.5","0.17734463","0","2"],["104469.6","0","0","0"],["104470","0.09321","0","2"],["104470.8","0.0383585","0","1"],["104473.6","0.01","0","1"],["104474.1","0.00711203","0","1"],["104475.8","0.0047849","0","1"],["104475.9","0.20739836","0","2"],["104476.7","0.03828675","0","1"],["104477","0.00011435","0","1"],["104478.5","0.03929014","0","2"],["104479.7","0","0","0"],["104479.8","0.00521888","0","1"],["104479.9","0.61526438","0","2"],["104480.2","0","0","0"],["104482.1","0","0","0"],["104482.2","0","0","0"],["104482.8","0.1387764","0","1"],["104483.9","0.43329483","0","1"],["104484.2","0","0","0"],["104488.9","0","0","0"],["104489","0.18466625","0","2"],["104492.3","0.03601","0","2"],["104493.9","0.039","0","1"],["104496","0.002","0","2"],["104496.4","0.063","0","2"],["104497","0.001","0","1"],["104499","0.00287089","0","1"],["104499.4","0.00287089","0","1"],["104500.1","0.02091112","0","1"],["104501.6","0","0","0"],["104503","0.02164047","0","1"],["104503.1","0","0","0"],["104504","0.07299898","0","2"],["104504.9","0","0","0"],["104506.7","0","0","0"],["104510.4","0","0","0"],["104513.6","0","0","0"],["104517","0.1","0","2"],["104518","0.21","0","3"],["104519","0.14999999","0","3"],["104520","0.03830992","0","5"],["104520.2","0.0002898","0","1"],["104524","0.10001723","0","2"],["104524.8","0","0","0"],["104525","0","0","0"],["104525.8","0","0","0"],["104526","0","0","0"],["104526.2","0","0","0"],["104527","0","0","0"],["104527.7","0","0","0"],["104551.6","0","0","0"],["104555.2","5.87403146","0","1"],["104571.6","0.01914439","0","1"],["104573.7","0","0","0"],["104574","0","0","0"],["104579.2","0.0579344","0","1"],["104589","0","0","0"],["104598.9","0","0","0"],["104617.6","0.00003056","0","2"],["104617.7","0.01099591","0","1"],["104617.8","0.01099559","0","1"],["104618","0.00001632","0","1"],["104618.5","0.00009552","0","1"]],"bids":[["104466","0","0","0"],["104464.9","0","0","0"],["104464","0","0","0"],["104462.6","0","0","0"],["104461.9","0","0","0"],["104460.4","0","0","0"],["104459.9","0","0","0"],["104458.8","0","0","0"],["104458.6","0","0","0"],["104457.4","0.17653644","0","2"],["104456.9","0.03697","0","2"],["104455.7","0.036","0","1"],["104454.1","0.0017149","0","1"],["104453","0.04","0","1"],["104452.9","0.01088273","0","1"],["104452.2","0.19242972","0","1"],["104452.1","0.32379591","0","3"],["104451.5","0","0","0"],["104449.6","0.17829353","0","1"],["104448.7","0","0","0"],["104448.2","0","0","0"],["104447.6","0","0","0"],["104447","0","0","0"],["104446.5","0.36755201","0","3"],["104443.9","0.03","0","1"],["104443.4","0","0","0"],["104442.4","0.37386668","0","2"],["104440.6","0.00711203","0","1"],["104440.4","0","0","0"],["104439.5","0.2404439","0","1"],["104435.7","0.13877592","0","1"],["104428.4","0","0","0"],["104427.9","0","0","0"],["104427.5","0","0","0"],["104425","0.00478609","0","1"],["104423.2","0","0","0"],["104416.8","0","0","0"],["104416.7","0","0","0"],["104415.5","0.14770359","0","1"],["104413.1","0","0","0"],["104410.9","0","0","0"],["104410.2","0","0","0"],["104409.5","0.0478546","0","1"],["104406.2","0","0","0"],["104404.8","0","0","0"],["104401.5","0.0022","0","1"],["104400.7","0.58787","0","1"],["104400.1","0.06805026","0","2"],["104396.6","0","0","0"],["104394","0","0","0"],["104389.1","0","0","0"],["104388.6","0","0","0"],["104387.8","0","0","0"],["104385.7","0.002871","0","1"],["104381","0","0","0"],["104375.1","0","0","0"],["104375","0","0","0"],["104369.2","0.45794032","0","1"],["104369.1","0","0","0"],["104368","0.0211894","0","2"],["104366.8","0.0022","0","1"],["104362.1","0","0","0"],["104357.9","0","0","0"],["104357.1","0","0","0"],["104354.6","0.00064022","0","1"],["104350.3","0","0","0"],["104348.4","0.00084058","0","1"],["104344.7","2.84531","0","1"],["104334.5","0.2408166","0","1"],["104330.4","0.229739","0","2"],["104280.1","0.0022","0","1"],["104271.5","0.00030759","0","1"],["104271.1","0.00001029","0","1"],["104270.8","0.00022348","0","1"],["104270.5","0.00012512","0","2"],["104270.3","0.00003386","0","2"],["104270","0.00038892","0","2"],["104269.9","0.0000785","0","2"],["104269.6","0.00001237","0","1"],["104269.2","0.00026966","0","5"],["104269","0.00005407","0","1"],["104268.9","0.00001021","0","1"],["104268.8","0.31181159","0","3"],["104268.4","0.00039895","0","2"],["104268.3","0.00018565","0","4"],["104268","0.00011013","0","2"],["104267.5","0.80866876","0","2"],["104267.2","0.00001019","0","1"],["104267","0.0000111","0","1"],["104266.9","0.00002057","0","2"],["104266.8","0.00001005","0","1"],["104266.6","0.03545728","0","13"],["104266.3","0.00001","0","1"]],"ts":"1747171018701","checksum":1459781510,"seqId":54226730472,"prevSeqId":54226729912}]}
{"arg":{"channel":"books","instId":"BTC-USDT"},"action":"update","data":[{"asks":[["104467.8","1.47255992","0","17"],["104468","0.19195","0","2"],["104468.4","0.92059145","0","3"],["104468.5","0.2531443","0","2"],["104468.8","0.08129285","0","3"],["104468.9","0.40654313","0","2"],["104469.3","0.53636458","0","4"],["104469.5","0","0","0"],["104470.1","0.28720404","0","4"],["104470.3","0.03828933","0","1"],["104471.2","0.00478513","0","1"],["104473.9","0","0","0"],["104474.1","0","0","0"],["104475.8","0","0","0"],["104475.9","0.0180746","0","1"],["104476.1","0.04","0","1"],["104476.5","0.28401596","0","1"],["104476.7","0","0","0"],["104476.8","0.77866876","0","1"],["104477","0","0","0"],["104478.4","0.13878174","0","1"],["104479.1","0","0","0"],["104479.4","0.04","0","1"],["104479.8","0","0","0"],["104479.9","0.50598715","0","2"],["104480.5","0.04","0","1"],["104482.8","0.071774","0","1"],["104482.9","0","0","0"],["104483.1","0.17829353","0","1"],["104484.3","0.17829353","0","1"],["104486.4","0","0","0"],["104487.1","0","0","0"],["104487.6","0.00712453","0","2"],["104487.7","0","0","0"],["104489","0.11746392","0","1"],["104489.6","0.036","0","1"],["104490","0.00029006","0","2"],["104491","0.002","0","2"],["104492","0.001","0","1"],["104493.2","0.20222436","0","2"],["104494.3","0.04610885","0","1"],["104495.2","0.0028709","0","1"],["104495.9","0","0","0"],["104496","0","0","0"],["104496.5","0.03","0","1"],["104497","0","0","0"],["104498.1","0.26864","0","1"],["104499","0.00956749","0","1"],["104499.4","0","0","0"],["104505","0","0","0"],["104506.5","0","0","0"],["104506.6","0","0","0"],["104507.4","0","0","0"],["104509.1","0","0","0"],["104509.8","0.36908178","0","1"],["104510.9","0","0","0"],["104512.4","0","0","0"],["104512.9","0","0","0"],["104513","0","0","0"],["104516","0.15999999","0","2"],["104516.7","0.06701","0","1"],["104517","0.24999999","0","5"],["104518","0.085","0","2"],["104519","0","0","0"],["104519.8","0.02871661","0","1"],["104519.9","1.41596664","0","1"],["104520","0.00330992","0","4"],["104520.1","0.00001","0","1"],["104521","0","0","0"],["104521.5","2.67549","0","1"],["104524","0.00001723","0","1"],["104525.1","0.0287025","0","1"],["104531.4","0.00209352","0","1"],["104537","0","0","0"],["104551.2","0.04788817","0","2"],["104551.3","2.52994479","0","1"],["104551.9","5.87404146","0","2"],["104555.2","0","0","0"],["104559.2","0.01052914","0","1"],["104563.1","0","0","0"],["104567.3","0.00095632","0","1"],["104572","0.42947359","0","17"],["104596.7","0","0","0"],["104613.8","0","0","0"],["104615.1","1.02326418","0","3"],["104619.3","0.04304781","0","1"],["104620","0.00222603","0","4"]],"bids":[["104469.2","0","0","0"],["104468.8","0","0","0"],["104468.4","0","0","0"],["104467.7","0.00209","0","2"],["104461.7","0","0","0"],["104457.4","0","0","0"],["104457.3","0.00955788","0","1"],["104457","0.0026285","0","1"],["104456.9","0.00097","0","1"],["104455.7","0","0","0"],["104455.4","0","0","0"],["104454.1","0","0","0"],["104454","0","0","0"],["104453","0","0","0"],["104452.8","0","0","0"],["104452.7","0.00001","0","1"],["104452.2","0.032851","0","2"],["104452.1","0.29539194","0","2"],["104451","0.77866876","0","1"],["104450.6","0.19242972","0","1"],["104450","0.04580799","0","3"],["104449.9","0.036","0","1"],["104449.6","0","0","0"],["104448.7","0.00957211","0","1"],["104448.6","0.04824757","0","2"],["104448.5","0","0","0"],["104446.8","0.02929425","0","1"],["104444.3","0.04552038","0","1"],["104443.9","0","0","0"],["104443.6","0.03767982","0","1"],["104442.4","0.36908178","0","1"],["104441.6","0.6055108","0","1"],["104441.3","0.0057399","0","2"],["104440.6","0","0","0"],["104440.3","0","0","0"],["104440","0.18050196","0","4"],["104439.9","0.17829353","0","1"],["104439.5","0","0","0"],["104438.8","0.00478513","0","1"],["104437.3","0.03","0","1"],["104435.9","0.00711203","0","1"],["104435.8","0.311295","0","1"],["104435.7","0.17829353","0","1"],["104435.6","0","0","0"],["104434.8","0.04843278","0","1"],["104432.6","0","0","0"],["104431.5","0.36869051","0","1"],["104429.3","0.04843534","0","1"],["104428.6","0.13878174","0","1"],["104427.7","1.423353","0","1"],["104427.2","0.02871661","0","1"],["104425","0","0","0"],["104424.5","0.20869903","0","1"],["104424","0.000015","0","1"],["104422.6","0.02871632","0","1"],["104419.2","0.62306552","0","1"],["104417.6","0","0","0"],["104417.4","0","0","0"],["104417.1","0","0","0"],["104415.1","0.07349","0","1"],["104409.5","0","0","0"],["104407.9","0.02105828","0","2"],["104406.1","0","0","0"],["104406","0","0","0"],["104400","0.54405393","0","5"],["104399.6","0","0","0"],["104396.5","0.04786055","0","1"],["104396.3","2.54455195","0","1"],["104392.9","0.64214","0","1"],["104385.7","0","0","0"],["104378.9","0.11114712","0","3"],["104376.8","0","0","0"],["104357","0.0152","0","2"],["104356.9","0","0","0"],["104356.8","0.0228","0","3"],["104354.7","0.0076","0","1"],["104341.5","0.002871","0","1"],["104328.3","0","0","0"],["104324.1","0.04634752","0","1"],["104319","0","0","0"],["104318","0.00095696","0","1"],["104310.4","0.00478617","0","1"],["104306.4","0","0","0"],["104289.5","0.00957234","0","2"],["104266.2","0.00032044","0","1"],["104266.1","0.00005665","0","1"],["104265.9","0.00162451","0","1"],["104265.6","0.00001295","0","1"],["104265.5","0.00653561","0","3"]],"ts":"1747171018801","checksum":142280835,"seqId":54226731318,"prevSeqId":54226730472}]}
{"arg":{"channel":"books","instId":"BTC-USDT"},"action":"update","data":[{"asks":[["104467.8","1.53834542","0","19"],["104468.3","0.51534761","0","1"],["104468.4","0.10407701","0","2"],["104468.9","0.36908178","0","1"],["104469","0.09475052","0","1"],["104469.2","0.02929274","0","1"],["104470","0.18609474","0","3"],["104470.5","0.09457452","0","1"],["104471.2","0","0","0"],["104473.5","0.15685099","0","2"],["104473.9","0.16858646","0","1"],["104474","0.15026674","0","1"],["104475.8","0.00011435","0","1"],["104476.8","0.9451776","0","2"],["104477.3","0.25345585","0","1"],["104478.4","0","0","0"],["104478.7","0","0","0"],["104479","0.26405026","0","1"],["104479.4","0.27986943","0","2"],["104480.7","0.0599306","0","1"],["104481.9","0.1387781","0","1"],["104483","0.2501099","0","1"],["104485.4","0.075","0","2"],["104489.6","0.099","0","3"],["104493.2","0.20509529","0","3"],["104493.4","0.00287093","0","1"],["104493.9","0","0","0"],["104495.2","0","0","0"],["104496.4","0.033","0","1"],["104497.9","0.09572","0","1"],["104501","0.09572","0","1"],["104502.5","0","0","0"],["104504.1","0.04846421","0","1"],["104509","0","0","0"],["104513","0.16","0","2"],["104514","0.07999999","0","1"],["104516","0","0","0"],["104517","0.17","0","4"],["104523.6","0.1","0","1"],["104559.3","0.04773047","0","2"],["104560.9","0.01369533","0","2"],["104581.9","0.0105964","0","1"],["104614.9","0","0","0"],["104615","0","0","0"],["104615.1","0","0","0"],["104615.3","0","0","0"],["104615.5","0","0","0"],["104616.6","0","0","0"],["104617.6","0","0","0"],["104617.7","0","0","0"],["104617.8","0","0","0"],["104618","0","0","0"],["104618.5","0","0","0"],["104619.3","0","0","0"],["104620","0","0","0"]],"bids":[["104452.9","0","0","0"],["104452.3","0.0017649","0","2"],["104452.2","0.0311361","0","1"],["104452.1","0.09991122","0","1"],["104451","0","0","0"],["104449.5","0.19270388","0","2"],["104448","0.09126438","0","1"],["104447.4","0.09392809","0","1"],["104446.8","0","0","0"],["104446.4","0.15097984","0","1"],["104446","0.15442081","0","1"],["104444.9","0.01088273","0","1"],["104444.5","0.20524178","0","3"],["104442.3","0.52278471","0","4"],["104441.8","0.16655263","0","1"],["104441.5","0.03","0","1"],["104441.3","0.01052503","0","3"],["104440.8","0.03001","0","2"],["104439.5","0.24147457","0","1"],["104438.8","0","0","0"],["104436.6","0.063","0","2"],["104435.5","0.24155822","0","1"],["104434.8","0","0","0"],["104432.6","0.13877898","0","1"],["104428.6","0","0","0"],["104422","0","0","0"],["104418.9","0","0","0"],["104415.4","0.00047861","0","1"],["104412","0","0","0"],["104395.6","0.01436566","0","1"],["104378.2","0","0","0"],["104373.9","0","0","0"],["104370.1","0","0","0"],["104367.8","0","0","0"],["104353","0.01034","0","1"],["104348.4","0","0","0"],["104345.6","0.00084079","0","1"],["104318","0","0","0"],["104281.4","0","0","0"]],"ts":"1747171018901","checksum":-969797090,"seqId":54226731656,"prevSeqId":54226731318}]}
{"arg":{"channel":"books","instId":"BTC-USDT"},"action":"update","data":[{"asks":[["104467.8","1.54983242","0","20"],["104468.4","0.00533334","0","2"],["104468.6","0.09649756","0","1"],["104469","0","0","0"],["104469.2","0.12599643","0","2"],["104470","0.09321","0","2"],["104470.2","0.09542483","0","1"],["104470.5","0.01409438","0","1"],["104470.7","0.09259929","0","2"],["104473.5","0","0","0"],["104473.7","0.16308164","0","1"],["104473.9","0.49251074","0","2"],["104474","0","0","0"],["104474.1","0.15196804","0","1"],["104474.2","0.1954569","0","2"],["104475.4","0","0","0"],["104475.8","0","0","0"],["104476.5","0","0","0"],["104476.8","0.77866876","0","1"],["104477","0.14932004","0","1"],["104477.3","0","0","0"],["104477.5","0.23587915","0","1"],["104479","0","0","0"],["104479.2","0.26360812","0","1"],["104479.4","0.04","0","1"],["104479.6","0.24521478","0","1"],["104483","0","0","0"],["104483.2","0.41951294","0","4"],["104489.6","0.129","0","4"],["104491","0","0","0"],["104492","0","0","0"],["104493.2","0.20222436","0","2"],["104493.4","0","0","0"],["104494","0.002","0","2"],["104495","0.001","0","1"],["104496.4","0","0","0"],["104498","0","0","0"],["104500.1","0.02104142","0","2"],["104501.2","0","0","0"],["104511.8","0.554579","0","1"],["104513","0","0","0"],["104514","0","0","0"],["104517","0.16","0","2"],["104518","0.24999999","0","5"],["104519","0.085","0","2"],["104522.5","0.1","0","1"],["104523.6","0","0","0"],["104528.6","0.0015518","0","1"],["104545.1","5.87403146","0","1"],["104551.9","0.00001","0","1"],["104553.6","0.831536","0","1"],["104566.6","0.05738","0","1"],["104569.1","0.07172","0","1"],["104575.2","0.00009489","0","1"],["104612.6","0","0","0"],["104612.9","0","0","0"],["104613","0","0","0"]],"bids":[["104467.7","0.00269","0","3"],["104457.3","0","0","0"],["104453.9","0.03113561","0","1"],["104452.1","0.47617322","0","2"],["104450.7","0.77866876","0","1"],["104449.7","0.22973701","0","3"],["104449.5","0","0","0"],["104448.9","0.096705","0","1"],["104448.2","0.09429284","0","1"],["104448","0","0","0"],["104447.6","0.10023063","0","1"],["104447.4","0","0","0"],["104446.6","0.15601725","0","1"],["104446.4","0","0","0"],["104446.2","0.1578339","0","1"],["104446","0","0","0"],["104444.7","0.16130554","0","1"],["104444.5","0.052","0","2"],["104442.5","0.24311191","0","1"],["104442.3","0.286","0","3"],["104442","0.15003933","0","1"],["104441.8","0","0","0"],["104441.3","0.0057399","0","2"],["104439.7","0.25097489","0","1"],["104439.5","0","0","0"],["104439.3","0.00478537","0","1"],["104439.2","0.02929425","0","1"],["104436.6","0.33733612","0","4"],["104435.7","0.41794355","0","2"],["104435.5","0","0","0"],["104410","0.00028006","0","1"],["104390.5","0.555223","0","1"],["104356.5","0.00173869","0","1"],["104348.7","0.833168","0","1"],["104346.1","0.01150018","0","1"],["104266.9","0","0","0"],["104266.8","0","0","0"],["104266.6","0","0","0"],["104266.3","0","0","0"],["104266.2","0","0","0"],["104266.1","0","0","0"],["104265.9","0","0","0"],["104265.6","0","0","0"],["104265.5","0","0","0"]],"ts":"1747171019001","checksum":-2088889501,"seqId":54226731984,"prevSeqId":54226731656}]}
{"arg":{"channel":"books","instId":"BTC-USDT"},"action":"update","data":[{"asks":[["104468.6","0","0","0"],["104469.2","0.02929274","0","1"],["104470.2","0","0","0"],["104470.7","0.00478537","0","1"],["104471.1","0.09363478","0","1"],["104473.7","0","0","0"],["104473.9","0.54605908","0","2"],["104474.1","0","0","0"],["104474.2","0.02929133","0","1"],["104477","0","0","0"],["104477.5","0","0","0"],["104479.2","0","0","0"],["104479.6","0","0","0"],["104483.2","0.18422353","0","3"],["104483.6","0.61209943","0","2"],["104492","0.002","0","2"],["104492.3","0.00001","0","1"],["104493","0.001","0","1"],["104494","0","0","0"],["104495","0","0","0"],["104496.5","0","0","0"],["104515","0.16004786","0","3"],["104516","0.17999999","0","3"],["104517","0.05","0","1"],["104518","0.07","0","2"],["104519","0.035","0","1"],["104531.8","0.00056666","0","1"],["104537.1","0","0","0"],["104598.5","0.04025285","0","3"],["104608.1","0","0","0"],["104612.6","0.229704","0","1"],["104612.9","0.00001168","0","1"],["104613","0.000015","0","1"],["104614.9","0.0000105","0","1"],["104615","0.01099627","0","1"],["104615.1","0.78926418","0","2"],["104615.3","0.29225276","0","4"],["104615.5","0.00001","0","1"]],"bids":[["104457.3","0.00955788","0","1"],["104455.7","0.01930307","0","1"],["104455.6","0.03113508","0","1"],["104453.4","0.03840636","0","2"],["104452.3","0.00005","0","1"],["104452.2","0.0017149","0","1"],["104449.8","0.071774","0","1"],["104449.7","0","0","0"],["104448.6","0.14358625","0","3"],["104448.2","0","0","0"],["104447.6","0","0","0"],["104446.6","0","0","0"],["104446.2","0","0","0"],["104444.7","0","0","0"],["104442.5","0","0","0"],["104442","0","0","0"],["104439.7","0","0","0"],["104436.7","0.31908596","0","1"],["104436.6","0.096","0","3"],["104436.1","0.25759342","0","1"],["104435.8","0","0","0"],["104435.7","0.17829353","0","1"],["104431.5","0.36925717","0","2"],["104430.3","0","0","0"],["104402.9","0.00002963","0","1"],["104368.3","0.00011063","0","1"],["104364.9","0.00056666","0","1"],["104359.3","0","0","0"],["104316.5","0.00095706","0","1"],["104266.9","0.00002057","0","2"],["104266.8","0.00001005","0","1"]],"ts":"1747171019101","checksum":762086456,"seqId":54226732138,"prevSeqId":54226731984}]}
{"arg":{"channel":"books","instId":"BTC-USDT"},"action":"update","data":[{"asks":[["104462.1","0.67207222","0","15"],["104462.3","0.00009","0","1"],["104464","0.0932","0","1"],["104464.8","0.11557476","0","1"],["104464.9","0.29193486","0","1"],["104467.7","0.00011435","0","1"],["104467.8","0.1292725","0","5"],["104468","0.0932","0","1"],["104468.4","0.00521899","0","1"],["104469","0.09141136","0","1"],["104470.1","0.28765404","0","5"],["104470.5","0","0","0"],["104470.7","0","0","0"],["104471.1","0","0","0"],["104471.2","0.08958088","0","1"],["104472.5","0.00001","0","1"],["104472.8","0.04","0","1"],["104473.5","0.00478537","0","1"],["104473.9","0.55039477","0","2"],["104474.5","0.16711131","0","1"],["104475.4","0.00093","0","1"],["104476.5","0.00001501","0","1"],["104477.9","0.24699024","0","1"],["104479.4","0","0","0"],["104480","0.33682049","0","4"],["104480.6","0.00093","0","1"],["104483.2","0.18329353","0","2"],["104483.6","0.36908178","0","1"],["104483.7","0.25091812","0","1"],["104485.8","0.00191","0","1"],["104488","0.27","0","2"],["104488.4","0.00001","0","1"],["104491","0.00391","0","3"],["104492","0.001","0","1"],["104493","0","0","0"],["104493.6","0","0","0"],["104498.8","0","0","0"],["104504.4","0.18116353","0","2"],["104509.8","0.95062943","0","2"],["104514","0.16","0","2"],["104515","0.18004785","0","4"],["104516","0.12","0","3"],["104517","0.035","0","1"],["104518","0","0","0"],["104518.9","0.0149678","0","1"],["104519","0","0","0"],["104530.1","0","0","0"],["104531.5","0","0","0"],["104538.3","5.87403146","0","1"],["104542.4","0.95984485","0","2"],["104545.1","0","0","0"],["104590.6","0.01099627","0","1"],["104612.2","0","0","0"],["104612.6","0","0","0"],["104612.9","0","0","0"],["104613","0","0","0"],["104614.9","0","0","0"],["104615","0","0","0"],["104615.1","0","0","0"],["104615.3","0","0","0"],["104615.5","0","0","0"]],"bids":[["104467.7","0","0","0"],["104464.6","0","0","0"],["104462.2","0","0","0"],["104462","0.0932","0","1"],["104460.7","0","0","0"],["104460","0.09540843","0","4"],["104458","0.0932","0","1"],["104457.3","0","0","0"],["104456.9","0","0","0"],["104451.7","0","0","0"],["104451.6","0.0095584","0","1"],["104448.7","0.09847384","0","2"],["104448.6","0.04824757","0","2"],["104448","0.09373758","0","1"],["104447","0.16475746","0","1"],["104446.5","0.36564201","0","2"],["104442.9","0.25317111","0","1"],["104441.4","0.00478537","0","1"],["104441.3","0","0","0"],["104439.3","0","0","0"],["104437","0.27321759","0","1"],["104436.2","0.24892966","0","1"],["104436.1","0","0","0"],["104432.5","0.03102","0","1"],["104416.7","0.00478616","0","1"],["104407","0.01052914","0","1"],["104406.3","0.00478616","0","1"],["104404.5","0.17829353","0","1"],["104266.9","0","0","0"],["104266.8","0","0","0"]],"ts":"1747171019201","checksum":2044528950,"seqId":54226732416,"prevSeqId":54226732138}]}
{"arg":{"channel":"books","instId":"BTC-USDT"},"action":"update","data":[{"asks":[["104469","0","0","0"],["104469.1","0.09675887","0","1"],["104469.7","0.09997318","0","1"],["104470.7","0.09473172","0","1"],["104471.2","0","0","0"],["104471.3","0.10031575","0","1"],["104473.9","0.54931578","0","2"],["104474.2","0.17839184","0","2"],["104474.5","0","0","0"],["104474.6","0.16724532","0","1"],["104474.7","0.16003426","0","1"],["104477.5","0.15489223","0","1"],["104477.9","0","0","0"],["104478","0.34693812","0","2"],["104479.7","0.26877819","0","1"],["104480","0.09349006","0","3"],["104480.1","0.29698062","0","3"],["104483.7","0","0","0"],["104483.8","0.26547206","0","1"],["104504","1.07299898","0","3"],["104515","0.25004785","0","6"],["104516","0.085","0","2"],["104516.8","0.1","0","1"],["104517","0","0","0"],["104518.6","0.0008017","0","1"],["104520.3","0.0015518","0","1"],["104522.3","0","0","0"],["104522.5","0","0","0"],["104528.6","0","0","0"],["104530.9","0.00080332","0","1"],["104611","0","0","0"],["104611.3","0","0","0"],["104612.1","0","0","0"]],"bids":[["104457.4","0.03113454","0","1"],["104453.9","0","0","0"],["104450.2","0.18899971","0","2"],["104448.8","0.0965681","0","2"],["104448.7","0.00957211","0","1"],["104448.1","0.09034478","0","1"],["104448","0","0","0"],["104447.1","0.15692787","0","1"],["104447","0","0","0"],["104446.7","0.16312297","0","1"],["104445.2","0.15462415","0","1"],["104443","0.25653116","0","1"],["104442.9","0","0","0"],["104442.5","0.14775136","0","1"],["104440.2","0.26872209","0","1"],["104437.1","0.24653755","0","1"],["104437","0","0","0"],["104436.3","0.2351174","0","1"],["104436.2","0","0","0"],["104430","0.00028006","0","1"],["104415.4","0","0","0"],["104410","0.04915943","0","2"],["104354.6","0","0","0"],["104348.8","0.00064045","0","1"],["104345.6","0","0","0"],["104342.5","0.16161783","0","2"],["104267.5","0","0","0"],["104267.2","0","0","0"],["104267","0","0","0"]],"ts":"1747171019301","checksum":739554800,"seqId":54226732553,"prevSeqId":54226732416}]}
{"arg":{"channel":"books","instId":"BTC-USDT"},"action":"update","data":[{"asks":[["104462.1","0.67216222","0","16"],["104462.3","0","0","0"],["104469.3","0.55444151","0","5"],["104469.7","0","0","0"],["104469.8","0.10136543","0","1"],["104473.6","0","0","0"],["104474.7","0","0","0"],["104474.8","0.16175528","0","1"],["104479.7","0","0","0"],["104479.8","0.24534927","0","1"],["104514.3","0.00047864","0","1"],["104575.2","0","0","0"],["104576.8","0.13059606","0","2"],["104611","0.01099627","0","1"],["104611.3","0.00005484","0","1"]],"bids":[["104462","0.09329","0","2"],["104454.2","0.0005","0","1"],["104450.3","0.09140727","0","1"],["104450.2","0.09465047","0","1"],["104448.9","0.097675","0","2"],["104445.3","0.15501171","0","1"],["104445.2","0","0","0"],["104443.7","0.00097","0","1"],["104440.3","0.26518973","0","1"],["104440.2","0","0","0"],["104438.5","0.00191","0","1"],["104433.3","0.00191","0","1"],["104409.7","0.00047864","0","1"],["104368.3","0","0","0"],["104363.5","0.09766654","0","2"],["104316.5","0","0","0"],["104311.1","0.00095706","0","1"],["104268.9","0","0","0"],["104268.8","0","0","0"],["104268.4","0","0","0"],["104268.3","0","0","0"],["104268","0","0","0"]],"ts":"1747171019401","checksum":710215320,"seqId":54226732589,"prevSeqId":54226732553}]}
{"arg":{"channel":"books","instId":"BTC-USDT"},"action":"update","data":[{"asks":[["104462.1","0.51205356","0","15"],["104482.6","0.00478642","0","1"],["104492.9","0.0001303","0","1"],["104494.1","0","0","0"],["104500.1","0.02091112","0","1"],["104584.8","0.00126067","0","1"],["104611.3","0","0","0"]],"bids":[["104462","0.09366","0","3"],["104449.8","0","0","0"],["104448.9","0.00097","0","1"],["104420.9","0.46851381","0","1"],["104402.9","0","0","0"],["104397.9","0.00002963","0","1"],["104295.6","0","0","0"],["104284.7","0.0001844","0","1"]],"ts":"1747171019501","checksum":-931965917,"seqId":54226732617,"prevSeqId":54226732589}]}
{"arg":{"channel":"books","instId":"BTC-USDT"},"action":"update","data":[{"asks":[["104472.1","0.00478537","0","1"],["104473.5","0","0","0"]],"bids":[["104455.2","0.00308017","0","3"],["104447","0.071774","0","1"],["104446.6","0.096706","0","1"],["104445","0","0","0"],["104441.4","0","0","0"],["104439.3","0.00478537","0","1"],["104429.4","0.06152637","0","1"],["104345.6","0.00001","0","1"],["104269.6","0","0","0"],["104269.2","0","0","0"],["104269","0","0","0"]],"ts":"1747171019601","checksum":2059599042,"seqId":54226732629,"prevSeqId":54226732617}]}
{"arg":{"channel":"books","instId":"BTC-USDT"},"action":"update","data":[{"asks":[["104478.4","0.13878182","0","1"],["104481.9","0","0","0"],["104569.4","0.02164793","0","4"]],"bids":[["104462","0.09364865","0","3"],["104455.2","0.00521051","0","5"],["104432.6","0","0","0"],["104429.5","0.13878182","0","1"],["104421.3","0.00006","0","1"],["104417.8","0","0","0"]],"ts":"1747171019701","checksum":1011345229,"seqId":54226732641,"prevSeqId":54226732629}]}
{"arg":{"channel":"books","instId":"BTC-USDT"},"action":"update","data":[{"asks":[["104460.1","0.48594997","0","15"],["104461.6","0.09875","0","1"],["104461.9","0.12442528","0","1"],["104462","0.0932","0","1"],["104462.1","0.052","0","2"],["104464.8","0","0","0"],["104464.9","0","0","0"],["104469.1","0","0","0"],["104469.8","0","0","0"],["104470.7","0","0","0"],["104471.3","0","0","0"],["104473.9","0.5265747","0","2"],["104474.2","0.02929133","0","1"],["104474.6","0","0","0"],["104474.8","0","0","0"],["104477.5","0","0","0"],["104478","0.0932","0","1"],["104478.4","0.13878186","0","1"],["104479.8","0","0","0"],["104480.1","0.052","0","2"],["104483.8","0","0","0"],["104484","0","0","0"],["104488","0.234","0","1"],["104490","0.00229006","0","4"],["104491","0.00291","0","2"],["104492","0","0","0"],["104499.6","0.88855097","0","2"],["104508.3","0.02922144","0","2"],["104513","0.16","0","2"],["104514","0.24999999","0","5"],["104515","0.08504786","0","3"],["104515.3","0.49806437","0","2"],["104516","0","0","0"],["104516.8","0","0","0"],["104520.5","1.13611482","0","2"],["104525.2","0","0","0"],["104538.3","0","0","0"],["104541.7","5.87403146","0","1"],["104542.4","0","0","0"],["104546.2","0","0","0"],["104611.3","0.00005484","0","1"],["104612.1","0.01059606","0","1"],["104612.2","0.01407867","0","1"],["104612.6","0.229704","0","1"],["104612.9","0.00001168","0","1"],["104613","0.000015","0","1"],["104614.9","0.0000105","0","1"],["104615","0.01099627","0","1"],["104615.1","0.78926418","0","2"],["104615.3","0.29225276","0","4"],["104615.5","0.00001","0","1"],["104616.6","0.00007797","0","4"],["104617.6","0.00003056","0","2"]],"bids":[["104462","0","0","0"],["104460","0.00220843","0","3"],["104459.9","0.00027067","0","1"],["104458.1","0.0774425","0","1"],["104456","0.0932","0","1"],["104455.7","0","0","0"],["104455.2","0.00627568","0","6"],["104453.4","0.00004786","0","1"],["104452.2","0","0","0"],["104452.1","0.09430748","0","2"],["104451.6","0","0","0"],["104450.7","0","0","0"],["104450.6","0","0","0"],["104450.3","0","0","0"],["104450.2","0","0","0"],["104449.6","0.00955858","0","1"],["104448.9","0.0026849","0","2"],["104448.8","0.00001","0","1"],["104448.1","0","0","0"],["104447.1","0","0","0"],["104446.7","0","0","0"],["104446.5","0.33625376","0","2"],["104445.3","0","0","0"],["104443","0","0","0"],["104442.5","0","0","0"],["104442.4","0","0","0"],["104440.3","0","0","0"],["104437.1","0","0","0"],["104436.7","0.35390692","0","2"],["104436.3","0","0","0"],["104433.6","0.00383018","0","1"],["104431.5","0.77808841","0","3"],["104430","0.00029006","0","2"],["104429.5","0.13878186","0","1"],["104404.6","0.30901606","0","1"],["104400","1.25406099","0","6"],["104394.6","0.49177436","0","2"],["104388.6","0.02072229","0","1"],["104357.1","0.01738302","0","1"],["104352.4","0.35139151","0","2"],["104348.3","1.08785533","0","2"],["104341.6","0","0","0"],["104331.6","0.099038","0","1"],["104269.6","0.00001237","0","1"],["104269.2","0.00026966","0","5"],["104269","0.00005407","0","1"],["104268.9","0.00001021","0","1"],["104268.8","0.31181159","0","3"],["104268.4","0.00039895","0","2"],["104268.3","0.00018565","0","4"],["104268","0.00011013","0","2"],["104267.5","0.80866876","0","2"],["104267.2","0.00001019","0","1"],["104267","0.0000111","0","1"]],"ts":"1747171019801","checksum":-721226805,"seqId":54226732932,"prevSeqId":54226732641}]}
{"arg":{"channel":"books","instId":"BTC-USDT"},"action":"update","data":[{"asks":[["104466.3","0.0901288","0","1"],["104466.9","0.10188936","0","1"],["104467.9","0.09171244","0","1"],["104468.5","0.34173078","0","3"],["104471.4","0.15566267","0","1"],["104471.8","0.15587508","0","1"],["104471.9","0.16829842","0","1"],["104473.9","0.31788101","0","1"],["104474.7","0.14571343","0","1"],["104475.2","0.26027277","0","1"],["104476.9","0.24859565","0","1"],["104477.3","0.26467907","0","1"],["104481","0.24195603","0","1"],["104494","0.00287","0","1"],["104514.8","0.1","0","1"],["104518.5","0.00156679","0","2"],["104520.3","0","0","0"],["104538.3","5.89458457","0","1"],["104539.2","0.413504","0","1"],["104541.7","0","0","0"],["104612.1","0","0","0"],["104612.2","0","0","0"],["104612.6","0","0","0"],["104612.9","0","0","0"],["104613","0","0","0"],["104614.9","0","0","0"],["104615","0","0","0"],["104615.1","0","0","0"],["104615.3","0","0","0"],["104615.5","0","0","0"],["104616.6","0","0","0"],["104617.6","0","0","0"]],"bids":[["104460","0.00273843","0","4"],["104452.1","0.04504982","0","1"],["104448.9","0.00097","0","1"],["104448.8","0.0017249","0","2"],["104447.4","0.18689419","0","2"],["104446.5","0.15958684","0","1"],["104446","0.09200362","0","1"],["104445.3","0.09212502","0","1"],["104444.3","0.20532436","0","2"],["104443.9","0.16231371","0","1"],["104442.4","0.15539287","0","1"],["104440.2","0.2404758","0","1"],["104439.7","0.15025566","0","1"],["104437.4","0.26295739","0","1"],["104436.7","0.22453721","0","1"],["104433.5","0.26387065","0","1"],["104348.8","0","0","0"],["104346.2","0.00064048","0","1"],["104342.5","0.160777","0","1"],["104340.5","0.00084085","0","1"],["104269.2","0","0","0"],["104269","0","0","0"],["104268.9","0","0","0"],["104268.8","0","0","0"],["104268.4","0","0","0"],["104268.3","0","0","0"],["104268","0","0","0"],["104267.5","0","0","0"],["104267.2","0","0","0"],["104267","0","0","0"]],"ts":"1747171019901","checksum":-287762625,"seqId":54226733065,"prevSeqId":54226732932}]}
{"arg":{"channel":"books","instId":"BTC-USDT"},"action":"update","data":[{"asks":[["104466.3","0","0","0"],["104466.9","0","0","0"],["104467.4","0.00011435","0","1"],["104467.5","0.09457177","0","1"],["104467.7","0","0","0"],["104467.9","0","0","0"],["104468.2","0.09293135","0","1"],["104468.5","0.2531443","0","2"],["104469.2","0.12715187","0","2"],["104469.7","0.09069653","0","1"],["104470","0.09349006","0","3"],["104471.4","0","0","0"],["104471.8","0","0","0"],["104471.9","0","0","0"],["104472.7","0.15465147","0","1"],["104473","0.16294402","0","1"],["104473.2","0.15487792","0","1"],["104473.9","0.44944286","0","2"],["104474.7","0","0","0"],["104475.2","0","0","0"],["104476","0.25297286","0","2"],["104476.4","0.22942354","0","2"],["104476.9","0","0","0"],["104477.3","0","0","0"],["104478.2","0.25385192","0","1"],["104478.5","0.30011454","0","3"],["104480","0.09540843","0","4"],["104481","0","0","0"],["104482.2","0.2615136","0","1"],["104538.3","0","0","0"],["104541.7","5.89458457","0","1"],["104612.1","0.01059606","0","1"],["104612.2","0.01407867","0","1"],["104612.6","0.229704","0","1"]],"bids":[["104460","0.0932","0","1"],["104459.9","0","0","0"],["104454.6","0.0383585","0","1"],["104452.2","0.0017149","0","1"],["104452.1","0.37453424","0","2"],["104449.3","0.77866876","0","1"],["104449.2","0.19242972","0","1"],["104448.8","0.00001","0","1"],["104448.7","0.20054167","0","3"],["104447.4","0","0","0"],["104447.2","0.09657411","0","1"],["104446.5","0.41718415","0","3"],["104446","0","0","0"],["104445.5","0.1618623","0","1"],["104445.3","0","0","0"],["104445.2","0.151282","0","1"],["104444.6","0.07298372","0","1"],["104444.3","0.04552038","0","1"],["104443.9","0","0","0"],["104443.7","0.15648932","0","2"],["104442.4","0","0","0"],["104441.4","0.24540307","0","1"],["104441","0.16141905","0","1"],["104440.2","0","0","0"],["104439.7","0","0","0"],["104438.7","0.45525586","0","2"],["104437.4","0","0","0"],["104436.7","0.35282315","0","2"],["104435.5","0.25330773","0","1"],["104434.7","0.26403907","0","1"],["104433.5","0","0","0"],["104363.5","0.09757082","0","1"],["104362.3","0.00009912","0","1"],["104311.1","0","0","0"],["104310.1","0.00095706","0","1"],["104270","0","0","0"],["104269.9","0","0","0"],["104269.6","0","0","0"]],"ts":"1747171020001","checksum":-963845036,"seqId":54226733240,"prevSeqId":54226733065}]}
{"arg":{"channel":"books","instId":"BTC-USDT"},"action":"update","data":[{"asks":[["104467.4","0","0","0"],["104467.5","0","0","0"],["104467.7","0.00011435","0","1"],["104468","0.18689701","0","2"],["104468.2","0","0","0"],["104468.7","0.09778088","0","1"],["104469.2","0.02929274","0","1"],["104469.7","0.08981968","0","1"],["104470.2","0.09690912","0","1"],["104472.7","0","0","0"],["104473","0","0","0"],["104473.2","0.15197008","0","1"],["104473.5","0.16753294","0","1"],["104473.7","0.16000385","0","1"],["104473.9","0.31788101","0","1"],["104476","0.0932","0","1"],["104476.4","0.00001","0","1"],["104476.5","0.16117162","0","2"],["104476.9","0.23488549","0","1"],["104478.2","0","0","0"],["104478.4","0","0","0"],["104478.5","0.03929014","0","2"],["104478.7","0.23821108","0","1"],["104479","0.27305985","0","1"],["104481.9","0.13877783","0","1"],["104482.2","0","0","0"],["104482.7","0.25741204","0","1"],["104490.9","0.0001303","0","1"],["104492.9","0","0","0"],["104498.4","0.00013962","0","1"],["104508.3","0.02908192","0","1"],["104524.2","0.00056666","0","1"],["104531.8","0","0","0"],["104589.8","0.00056666","0","1"],["104598.5","0.03968619","0","2"],["104611.3","0","0","0"],["104612.1","0","0","0"],["104612.2","0","0","0"],["104612.6","0","0","0"]],"bids":[["104460","0.2127","0","2"],["104449.2","0.37589756","0","3"],["104448.7","0.00957211","0","1"],["104447.7","0.09139112","0","1"],["104447.2","0","0","0"],["104447","0.16898257","0","2"],["104446.5","0.32595729","0","2"],["104446","0.15551829","0","1"],["104445.7","0.16262305","0","1"],["104445.5","0","0","0"],["104445.2","0","0","0"],["104444.2","0.1581405","0","1"],["104443.7","0.00097","0","1"],["104442.3","0.65508178","0","4"],["104441.9","0.26099314","0","1"],["104441.5","0.19410005","0","2"],["104441.4","0","0","0"],["104441","0","0","0"],["104439.2","0.26743781","0","2"],["104438.7","0.19242972","0","1"],["104436","0.24431334","0","1"],["104435.5","0","0","0"],["104435.2","0.26059581","0","1"],["104434.7","0","0","0"],["104432.6","0.1387794","0","1"],["104431.5","0.77752175","0","2"],["104429.5","0","0","0"],["104425.4","0.00056666","0","1"],["104397.9","0","0","0"],["104396.6","0.00002963","0","1"],["104364.9","0","0","0"],["104359.8","0.00056666","0","1"],["104270.3","0","0","0"]],"ts":"1747171020101","checksum":-1114563379,"seqId":54226733365,"prevSeqId":54226733240}]}
{"arg":{"channel":"books","instId":"BTC-USDT"},"action":"update","data":[{"asks":[["104460.1","0.46994997","0","14"],["104462.1","0.036","0","1"],["104468","0.0932","0","1"],["104468.4","0.09540027","0","2"],["104468.5","0.0191443","0","1"],["104468.7","0","0","0"],["104469","0.09030213","0","1"],["104469.7","0","0","0"],["104470","0.18004426","0","4"],["104470.2","0","0","0"],["104470.5","0.08865154","0","1"],["104473.2","0","0","0"],["104473.5","0.1577338","0","1"],["104473.7","0","0","0"],["104473.9","0.61872332","0","3"],["104474","0.1550759","0","1"],["104476.5","0.00001501","0","1"],["104476.8","0.9251925","0","2"],["104476.9","0","0","0"],["104477.2","0.27271867","0","2"],["104478.7","0","0","0"],["104479","0.24988925","0","1"],["104479.4","0.26417239","0","1"],["104482.7","0","0","0"],["104483","0.24112805","0","1"],["104567.5","0.00009396","0","1"],["104569.4","0.02155541","0","3"],["104611.3","0.00005484","0","1"],["104612.1","0.01059606","0","1"]],"bids":[["104460","0.32471338","0","4"],["104449.5","0.19847006","0","2"],["104449.2","0.19242972","0","1"],["104448","0.09965062","0","1"],["104447.7","0","0","0"],["104447.4","0.09285312","0","1"],["104447","0.071774","0","1"],["104446.5","0.48858047","0","1"],["104446.4","0.15217873","0","1"],["104446","0.14503226","0","1"],["104445.7","0","0","0"],["104444.5","0.20533074","0","3"],["104444.2","0","0","0"],["104442.2","0.43873193","0","2"],["104441.9","0","0","0"],["104441.8","0.16358478","0","1"],["104441.5","0.03","0","1"],["104439.6","0.00478537","0","1"],["104439.5","0.25531211","0","1"],["104439.3","0","0","0"],["104439.2","0.02929425","0","1"],["104436.4","0.25067562","0","1"],["104436","0","0","0"],["104435.5","0.25608018","0","1"],["104435.2","0","0","0"],["104362.3","0","0","0"],["104360.9","0.00010573","0","1"],["104335.4","0.00001","0","1"],["104310.1","0","0","0"],["104308.6","0.00095707","0","1"],["104271.1","0","0","0"],["104270.8","0","0","0"],["104270.5","0","0","0"]],"ts":"1747171020201","checksum":-1081014283,"seqId":54226733442,"prevSeqId":54226733365}]}
{"arg":{"channel":"books","instId":"BTC-USDT"},"action":"update","data":[{"asks":[["104468.8","0.052","0","2"],["104470.5","0","0","0"],["104470.6","0.09574239","0","1"],["104477.2","0.036","0","1"],["104477.3","0.2468958","0","1"],["104481.1","0.10379065","0","3"],["104483","0","0","0"],["104483.1","0.44221","0","2"]],"bids":[["104459.3","0.0281285","0","1"],["104448.1","0.0877996","0","1"],["104448","0","0","0"],["104444.3","0","0","0"],["104442.3","0.90061977","0","5"],["104442.2","0.17829353","0","1"],["104435.6","0.24277847","0","1"],["104435.5","0","0","0"],["104400","1.25407099","0","7"]],"ts":"1747171020301","checksum":-212000026,"seqId":54226733461,"prevSeqId":54226733442}]}
{"arg":{"channel":"books","instId":"BTC-USDT"},"action":"update","data":[{"asks":[["104468","0.19572445","0","2"],["104468.4","0.00521899","0","1"],["104468.7","0.09207042","0","1"],["104469","0","0","0"],["104469.7","0.09463643","0","1"],["104470","0.09349006","0","3"],["104470.2","0.09334305","0","1"],["104470.6","0","0","0"],["104470.9","0.02713911","0","1"],["104473.2","0.14848967","0","1"],["104473.5","0.15769657","0","1"],["104473.7","0.16134255","0","1"],["104473.9","0.31788101","0","1"],["104474","0","0","0"],["104476.5","0.15700332","0","2"],["104476.8","0.77866876","0","1"],["104476.9","0.24098748","0","1"],["104477.3","0","0","0"],["104478.5","0.01","0","1"],["104478.7","0.23956527","0","1"],["104479","0.24674413","0","1"],["104479.2","0.00478651","0","1"],["104479.4","0","0","0"],["104482.7","0.26256058","0","1"],["104483.1","0.17829353","0","1"],["104490.7","0","0","0"],["104610.9","0","0","0"],["104611","0","0","0"],["104611.3","0","0","0"],["104612.1","0","0","0"]],"bids":[["104460","0.2128","0","4"],["104459.3","0","0","0"],["104449.5","0","0","0"],["104449.2","0.37938867","0","3"],["104448.1","0","0","0"],["104447.7","0.09666704","0","1"],["104447.4","0","0","0"],["104447.2","0.05329894","0","1"],["104447","0.0956521","0","1"],["104446.6","0","0","0"],["104446.5","0.47807153","0","2"],["104446.4","0","0","0"],["104446","0.15618183","0","1"],["104445.7","0.15787829","0","1"],["104444.5","0.052","0","2"],["104444.2","0.15603542","0","1"],["104442.3","0.65508178","0","4"],["104441.9","0.239825","0","1"],["104441.8","0","0","0"],["104441.5","0.18366263","0","2"],["104439.6","0","0","0"],["104439.5","0","0","0"],["104439.3","0.00478537","0","1"],["104439.2","0.29025958","0","2"],["104436.4","0","0","0"],["104435.6","0","0","0"],["104435.2","0.26160011","0","1"],["104271.1","0.00001029","0","1"],["104270.8","0.00022348","0","1"],["104270.5","0.00012512","0","2"],["104270.3","0.00003386","0","2"]],"ts":"1747171020401","checksum":-1344066687,"seqId":54226733550,"prevSeqId":54226733461}]}
{"arg":{"channel":"books","instId":"BTC-USDT"},"action":"update","data":[{"asks":[["104460.1","0.46972075","0","13"],["104481","0.13877852","0","1"],["104481.9","0","0","0"]],"bids":[["104436","0.26884401","0","1"],["104270.3","0","0","0"]],"ts":"1747171020501","checksum":-1269205839,"seqId":54226733559,"prevSeqId":54226733550}]}
{"arg":{"channel":"books","instId":"BTC-USDT"},"action":"update","data":[{"asks":[["104468.5","0.0191543","0","2"]],"bids":[["104460","0.0933","0","3"],["104419","0.05198865","0","2"],["104409","0.48324487","0","1"],["104372","0.00001501","0","1"],["104362","0.59439916","0","2"],["104270.5","0","0","0"]],"ts":"1747171020601","checksum":468417322,"seqId":54226733569,"prevSeqId":54226733559}]}
{"arg":{"channel":"books","instId":"BTC-USDT"},"action":"update","data":[{"asks":[["104467.4","0.00011435","0","1"],["104467.5","0.09340376","0","1"],["104467.7","0","0","0"],["104468","0.0932","0","1"],["104468.2","0.09387184","0","1"],["104468.7","0","0","0"],["104469.2","0.11782514","0","2"],["104469.7","0.09345248","0","1"],["104470.2","0","0","0"],["104470.7","0.00478537","0","1"],["104472.1","0","0","0"],["104472.7","0.1455516","0","1"],["104473","0.16119452","0","1"],["104473.2","0.16820031","0","1"],["104473.5","0","0","0"],["104473.7","0","0","0"],["104473.9","0.47638088","0","2"],["104476","0.23990022","0","2"],["104476.4","0.23322267","0","2"],["104476.5","0.00001501","0","1"],["104476.9","0","0","0"],["104478.2","0.2510841","0","1"],["104478.5","0.28121303","0","2"],["104478.7","0","0","0"],["104479","0","0","0"],["104482.2","0.26708922","0","1"],["104482.7","0","0","0"],["104610.9","0.01099559","0","1"],["104611","0.01099627","0","1"]],"bids":[["104449.2","0.19242972","0","1"],["104448.7","0.1931794","0","3"],["104447.7","0","0","0"],["104447.5","0.071774","0","1"],["104447.2","0.14874238","0","2"],["104447","0","0","0"],["104446.9","0.096706","0","1"],["104446.5","0.39829098","0","2"],["104446","0","0","0"],["104445.7","0","0","0"],["104445.5","0.16650878","0","1"],["104445.2","0.15174737","0","1"],["104444.2","0","0","0"],["104443.7","0.1647015","0","2"],["104441.9","0","0","0"],["104441.5","0.03","0","1"],["104441.4","0.23512384","0","1"],["104441","0.16678059","0","1"],["104439.3","0","0","0"],["104439.2","0.02929425","0","1"],["104438.8","0.00478537","0","1"],["104438.7","0.43330508","0","2"],["104436","0","0","0"],["104435.5","0.26601245","0","1"],["104435.2","0","0","0"],["104434.7","0.26658171","0","1"],["104419.2","0.41908952","0","1"],["104383.3","0","0","0"],["104380.8","0.00867222","0","1"]],"ts":"1747171020701","checksum":509921391,"seqId":54226733638,"prevSeqId":54226733569}]}
{"arg":{"channel":"books","instId":"BTC-USDT"},"action":"update","data":[{"asks":[["104487.6","0.0000125","0","1"],["104496.2","0.19954175","0","2"]],"bids":[["104387","0","0","0"],["104382.6","0","0","0"],["104382.4","0.0095448","0","2"],["104270.5","0.00012512","0","2"],["104270.3","0.00003386","0","2"]],"ts":"1747171020801","checksum":509921391,"seqId":54226733644,"prevSeqId":54226733638}]}
{"arg":{"channel":"books","instId":"BTC-USDT"},"action":"update","data":[{"asks":[["104467.4","0","0","0"],["104467.5","0","0","0"],["104467.7","0.00011435","0","1"],["104468","0.18858813","0","2"],["104468.2","0","0","0"],["104468.7","0.10212183","0","1"],["104469.2","0.02929274","0","1"],["104469.7","0.09790684","0","1"],["104470.2","0.09694579","0","1"],["104470.7","0","0","0"],["104472.1","0.00478537","0","1"],["104472.7","0","0","0"],["104473","0","0","0"],["104473.2","0.15744697","0","1"],["104473.5","0.16219227","0","1"],["104473.7","0.16714347","0","1"],["104473.9","0.31788101","0","1"],["104474.7","0.01","0","1"],["104476","0.0932","0","1"],["104476.4","0.00001","0","1"],["104476.5","0.15349189","0","2"],["104476.9","0.23111618","0","1"],["104478.2","0","0","0"],["104478.5","0","0","0"],["104478.7","0.24990181","0","1"],["104479","0.27050634","0","1"],["104481","0","0","0"],["104481.9","0.13877797","0","1"],["104482.2","0","0","0"],["104482.7","0.23367994","0","1"],["104538.3","5.89458457","0","1"],["104541.7","0","0","0"],["104610.9","0","0","0"],["104611","0","0","0"]],"bids":[["104460","0.21333","0","5"],["104449.2","0.38913233","0","3"],["104448.7","0.00957211","0","1"],["104447.7","0.09270242","0","1"],["104447.2","0.05329894","0","1"],["104447","0.09762951","0","1"],["104446.5","0.30237497","0","1"],["104446","0.16162306","0","1"],["104445.7","0.14359029","0","1"],["104445.5","0","0","0"],["104445.2","0","0","0"],["104444.2","0.15853654","0","1"],["104443.7","0.00097","0","1"],["104441.9","0.23561484","0","1"],["104441.5","0.19627743","0","2"],["104441.4","0","0","0"],["104441","0","0","0"],["104439.3","0.00478537","0","1"],["104439.2","0.29857849","0","2"],["104438.8","0","0","0"],["104438.7","0.19242972","0","1"],["104436","0.24703836","0","1"],["104435.5","0","0","0"],["104435.2","0.24105456","0","1"],["104434.7","0","0","0"],["104383.6","0","0","0"],["104380.1","0.04025378","0","4"],["104270.3","0","0","0"]],"ts":"1747171020901","checksum":-181310842,"seqId":54226733714,"prevSeqId":54226733644}]}
{"arg":{"channel":"books","instId":"BTC-USDT"},"action":"update","data":[{"asks":[["104470.8","0.04314387","0","2"],["104472.1","0","0","0"],["104610.9","0.01099559","0","1"]],"bids":[],"ts":"1747171021001","checksum":924112508,"seqId":54226733716,"prevSeqId":54226733714}]}
{"arg":{"channel":"books","instId":"BTC-USDT"},"action":"update","data":[{"asks":[["104460.1","0.42111672","0","10"],["104461.6","0","0","0"],["104461.9","0","0","0"],["104462.1","0","0","0"],["104467.8","0.1132725","0","4"],["104468","0.0932","0","1"],["104468.3","0","0","0"],["104468.4","0.09979171","0","2"],["104468.7","0","0","0"],["104468.8","0.036","0","1"],["104468.9","0","0","0"],["104469.1","0.12698843","0","2"],["104469.2","0","0","0"],["104469.3","0.07007693","0","3"],["104469.7","0","0","0"],["104470.1","0.3809637","0","6"],["104470.2","0","0","0"],["104470.3","0","0","0"],["104470.6","0.0897371","0","1"],["104470.8","0","0","0"],["104472.1","0.00478537","0","1"],["104473.2","0","0","0"],["104473.5","0","0","0"],["104473.6","0.15004963","0","1"],["104473.7","0","0","0"],["104473.9","0.2565046","0","2"],["104474.1","0.15265761","0","1"],["104476.2","0.03828716","0","1"],["104476.5","0.00001501","0","1"],["104476.8","0.14683051","0","1"],["104476.9","0","0","0"],["104477.3","0.23235888","0","1"],["104478.7","0","0","0"],["104479","0","0","0"],["104479.1","0.24544918","0","1"],["104479.4","0.26753217","0","1"],["104481.9","0","0","0"],["104482.7","0.13877616","0","1"],["104483.1","0.42907599","0","2"],["104483.9","0.17447054","0","1"],["104487.9","0","0","0"],["104490","0.00029006","0","2"],["104490.2","0.77866876","0","1"],["104491","0.00191","0","1"],["104493","0.002","0","2"],["104494","0.00387","0","2"],["104500.1","0","0","0"],["104503","0","0","0"],["104513","0","0","0"],["104514","0","0","0"],["104515","0.00004786","0","1"],["104516","0.15999999","0","2"],["104517","0.24999999","0","5"],["104517.4","0.02091112","0","1"],["104518","0.085","0","2"],["104518.2","0.02164047","0","1"],["104523","0.00056666","0","1"],["104524.2","0","0","0"],["104525.2","0.28430447","0","1"],["104531","0.33117244","0","1"],["104535.7","0.43094734","0","1"],["104538.3","5.96648584","0","1"],["104588.7","0.00056666","0","1"],["104589.8","0","0","0"],["104611","0.01099627","0","1"],["104611.3","0.00005484","0","1"],["104612.1","0.01059606","0","1"],["104612.2","0.01407867","0","1"]],"bids":[["104460","0.45939438","0","7"],["104452.4","0.0017149","0","1"],["104452.3","0.04653043","0","2"],["104452.2","0","0","0"],["104450","0.00029006","0","2"],["104449.6","0.19587193","0","3"],["104449.2","0.19242972","0","1"],["104448.1","0.09966165","0","1"],["104447.7","0","0","0"],["104447.4","0.09667158","0","1"],["104447","0","0","0"],["104446.4","0.17088287","0","1"],["104446.1","0.14746473","0","1"],["104446","0","0","0"],["104445.7","0","0","0"],["104444.6","0.22227704","0","2"],["104444.2","0","0","0"],["104442.3","0.88914784","0","5"],["104441.9","0","0","0"],["104441.8","0.14578704","0","1"],["104441.5","0.03","0","1"],["104440.1","0.00478537","0","1"],["104439.6","0.25978848","0","1"],["104439.3","0","0","0"],["104439.2","0.02929425","0","1"],["104436.4","0.24196175","0","1"],["104436","0","0","0"],["104435.6","0.26664693","0","1"],["104435.2","0","0","0"],["104432.6","0.13877616","0","1"],["104425.4","0","0","0"],["104424.4","0.41407066","0","2"],["104359.8","0","0","0"],["104358.8","0.07355038","0","2"],["104270.3","0.00003386","0","2"],["104270","0.00038892","0","2"]],"ts":"1747171021101","checksum":1894777535,"seqId":54226734047,"prevSeqId":54226733716}]}
{"arg":{"channel":"books","instId":"BTC-USDT"},"action":"update","data":[{"asks":[["104460.1","0.5285311","0","12"],["104463.9","0.12023246","0","1"],["104467.4","0.00011435","0","1"],["104467.5","0.100988","0","1"],["104467.7","0","0","0"],["104468.2","0.0922096","0","1"],["104468.4","0.00521899","0","1"],["104468.9","0.36908178","0","1"],["104469","0.40903169","0","2"],["104469.1","0.02882623","0","1"],["104469.2","0.09712972","0","1"],["104469.7","0.09575554","0","1"],["104469.9","0.19242972","0","1"],["104470.1","0.28645","0","4"],["104470.5","0.00478537","0","1"],["104470.6","0","0","0"],["104470.9","0.10012283","0","2"],["104471.2","0.0383585","0","1"],["104472.1","0","0","0"],["104472.7","0.16208047","0","1"],["104473","0.15573156","0","1"],["104473.2","0.16051723","0","1"],["104473.6","0","0","0"],["104473.9","0.49618571","0","1"],["104474.1","0","0","0"],["104476","0.25831443","0","2"],["104476.4","0.22976703","0","2"],["104476.8","0","0","0"],["104477.3","0","0","0"],["104477.9","0.77866876","0","1"],["104478.2","0.2407174","0","1"],["104478.5","0.25911622","0","1"],["104479.1","0","0","0"],["104479.4","0","0","0"],["104481.9","0.13877717","0","1"],["104482.2","0.24391003","0","1"],["104482.7","0","0","0"],["104483.1","0.17829353","0","1"],["104489","0.34266508","0","2"],["104492","0.002","0","2"],["104493","0.001","0","1"],["104494","0.00287","0","1"],["104511.4","0.00004968","0","1"],["104513","0.16","0","2"],["104514","0.24999999","0","5"],["104515","0.08504786","0","3"],["104516","0","0","0"],["104517","0","0","0"],["104518","0","0","0"],["104521.4","0","0","0"],["104522.1","0.0004968","0","1"],["104531","0","0","0"],["104535.7","0","0","0"],["104538.3","0","0","0"],["104541.7","5.96648584","0","1"],["104544.9","0","0","0"],["104608.6","0","0","0"],["104610","0","0","0"],["104610.9","0","0","0"],["104611","0","0","0"],["104611.3","0","0","0"],["104612.1","0","0","0"],["104612.2","0","0","0"]],"bids":[["104460","0.09383","0","4"],["104452.4","0","0","0"],["104452.1","0.14735374","0","1"],["104449.6","0.00955858","0","1"],["104449.3","0","0","0"],["104449.2","0","0","0"],["104449","0.0017149","0","1"],["104448.7","0.19799712","0","3"],["104448.1","0","0","0"],["104447.5","0","0","0"],["104447.4","0","0","0"],["104447.2","0.14883765","0","2"],["104446.9","0","0","0"],["104446.5","0.40066543","0","2"],["104446.4","0","0","0"],["104446.1","0","0","0"],["104445.5","0.16898722","0","1"],["104445.2","0.15954771","0","1"],["104444.6","0.07298372","0","1"],["104443.7","0.15314099","0","2"],["104442.3","0.286","0","3"],["104441.8","0","0","0"],["104441.4","0.2568526","0","1"],["104441","0.15079365","0","1"],["104440.1","0","0","0"],["104439.6","0","0","0"],["104438.8","0.00478537","0","1"],["104438.7","0.43934137","0","2"],["104436.4","0","0","0"],["104435.6","0","0","0"],["104435.5","0.25220284","0","1"],["104434.7","0.26381036","0","1"],["104432.6","0.13877717","0","1"],["104402.9","0.002871","0","1"],["104341.5","0","0","0"],["104269.9","0.0000785","0","2"],["104269.6","0.00001237","0","1"],["104269.2","0.00026966","0","5"],["104269","0.00005407","0","1"],["104268.9","0.00001021","0","1"],["104268.8","0.31181159","0","3"]],"ts":"1747171021201","checksum":261230336,"seqId":54226734214,"prevSeqId":54226734047}]}
{"arg":{"channel":"books","instId":"BTC-USDT"},"action":"update","data":[{"asks":[["104475.9","0.1805469","0","2"],["104476","0.0932","0","1"],["104483.2","0.17829353","0","1"],["104490","0.00229006","0","4"],["104491","0.00291","0","2"],["104492","0","0","0"],["104493","0","0","0"],["104495.7","0.0008","0","1"],["104574.8","0.12","0","1"],["104583.8","0","0","0"],["104608.6","0.03","0","1"],["104610","0.29261492","0","3"]],"bids":[["104458.7","0","0","0"],["104452.1","0.42753029","0","2"],["104449.3","0.0017149","0","1"],["104449.2","0.19242972","0","1"],["104449","0","0","0"],["104448.8","0.77867876","0","2"],["104447.5","0.071774","0","1"],["104446.8","0.096706","0","1"],["104442.4","0.36908178","0","1"],["104441","0","0","0"],["104440.9","0.15736441","0","1"],["104269","0","0","0"],["104268.9","0","0","0"],["104268.8","0","0","0"]],"ts":"1747171021301","checksum":-360928412,"seqId":54226734244,"prevSeqId":54226734214}]}
{"arg":{"channel":"books","instId":"BTC-USDT"},"action":"update","data":[{"asks":[],"bids":[["104452.4","0.0017149","0","1"],["104449.3","0","0","0"]],"ts":"1747171021401","checksum":1644187082,"seqId":54226734248,"prevSeqId":54226734244}]}
{"arg":{"channel":"books","instId":"BTC-USDT"},"action":"update","data":[{"asks":[["104466.7","0.00011435","0","1"],["104466.8","0.09234066","0","1"],["104467.1","0.02882678","0","1"],["104467.4","0","0","0"],["104467.5","0.09445682","0","1"],["104468.2","0","0","0"],["104468.5","0.11680825","0","3"],["104468.8","0.44633115","0","2"],["104469","0.09171449","0","1"],["104469.2","0","0","0"],["104469.7","0","0","0"],["104470.5","0","0","0"],["104470.8","0.00478537","0","1"],["104470.9","0.07298372","0","1"],["104472","0.15628024","0","1"],["104472.3","0.16863617","0","2"],["104472.5","0.16823806","0","2"],["104472.7","0","0","0"],["104473","0","0","0"],["104473.2","0","0","0"],["104475.3","0.15359624","0","1"],["104475.7","0.2298312","0","1"],["104475.9","0.0180746","0","1"],["104476.4","0.00501","0","2"],["104477.5","0.26105261","0","1"],["104477.8","0.23835977","0","1"],["104478.2","0","0","0"],["104478.5","0","0","0"],["104479.8","0.13878121","0","1"],["104481.5","0.25437104","0","1"],["104481.9","0","0","0"],["104482.2","0","0","0"],["104488.9","0.005","0","1"],["104515.3","0.05650539","0","1"],["104519.9","0","0","0"],["104551.3","0","0","0"],["104610.9","0.01099559","0","1"],["104611","0.01099627","0","1"]],"bids":[["104460","0.00063","0","3"],["104457.8","0.005","0","1"],["104457.4","0","0","0"],["104453.9","0.02689455","0","1"],["104452.4","0","0","0"],["104452.3","0.00005","0","1"],["104452.2","0.0017149","0","1"],["104448.7","0.00957211","0","1"],["104448","0.19006928","0","2"],["104447.2","0.05329894","0","1"],["104446.5","0.54534079","0","3"],["104445.8","0.09054446","0","1"],["104445.5","0","0","0"],["104445.3","0.005","0","1"],["104445.2","0","0","0"],["104444.8","0.1631663","0","3"],["104444.5","0.20142867","0","3"],["104443.7","0.00097","0","1"],["104443.6","0.09098058","0","2"],["104443","0.15743085","0","1"],["104441.4","0","0","0"],["104440.9","0","0","0"],["104440.7","0.25464324","0","1"],["104440.3","0.1531881","0","1"],["104438.8","0","0","0"],["104438.7","0.19242972","0","1"],["104438.6","0.00478537","0","1"],["104438","0.24482661","0","1"],["104435.5","0","0","0"],["104434.8","0.271395","0","1"],["104434.7","0","0","0"],["104434","0.25525243","0","1"],["104432.6","0","0","0"],["104431.5","0.36869051","0","1"],["104429.5","0.1387813","0","1"],["104427.7","0","0","0"],["104402.9","0","0","0"],["104400","0.54406393","0","6"],["104396.3","0","0","0"],["104364.2","0.002871","0","1"],["104269.6","0","0","0"],["104269.2","0","0","0"]],"ts":"1747171021501","checksum":115240514,"seqId":54226734357,"prevSeqId":54226734248}]}
{"arg":{"channel":"books","instId":"BTC-USDT"},"action":"update","data":[{"asks":[["104509.8","1.45238795","0","3"],["104510.9","1.40431164","0","1"],["104538.3","5.99755387","0","1"],["104541.7","0","0","0"],["104542.3","2.54598539","0","1"],["104610.9","0","0","0"],["104611","0","0","0"]],"bids":[["104432.1","0.13878043","0","1"],["104429.5","0","0","0"],["104420.2","0.84641258","0","1"],["104420.1","1.36521311","0","1"],["104419.2","0","0","0"],["104388.9","0.77292773","0","1"],["104388.8","2.51688103","0","1"],["104388.6","0","0","0"],["104270","0","0","0"],["104269.9","0","0","0"]],"ts":"1747171021601","checksum":115240514,"seqId":54226734371,"prevSeqId":54226734357}]}
{"arg":{"channel":"books","instId":"BTC-USDT"},"action":"update","data":[{"asks":[["104463.9","0.13718562","0","2"],["104466.7","0","0","0"],["104466.8","0.00011435","0","1"],["104466.9","0.09748986","0","1"],["104467.1","0","0","0"],["104467.5","0","0","0"],["104467.6","0.09748206","0","1"],["104468.5","0.0191543","0","2"],["104468.6","0.09089212","0","1"],["104469","0","0","0"],["104469.1","0.12276493","0","2"],["104470","0.1206294","0","4"],["104472","0","0","0"],["104472.1","0.15483565","0","1"],["104472.3","0.002","0","1"],["104472.4","0.16026501","0","1"],["104472.5","0.00001","0","1"],["104472.6","0.17284058","0","2"],["104473.9","0.58215886","0","2"],["104475.3","0","0","0"],["104475.4","0.15320918","0","2"],["104475.7","0","0","0"],["104475.8","0.25986267","0","1"],["104477.5","0","0","0"],["104477.6","0.26940126","0","1"],["104477.8","0","0","0"],["104477.9","1.03781294","0","2"],["104481.5","0","0","0"],["104481.6","0.23902534","0","1"],["104538.3","0","0","0"],["104541.7","5.99755387","0","1"],["104610.9","0.01099559","0","1"],["104611","0.01099627","0","1"]],"bids":[["104457.3","0.02812905","0","1"],["104448.1","0.18234961","0","2"],["104448","0","0","0"],["104446.6","0.09224564","0","1"],["104446.5","0.43706296","0","2"],["104445.9","0.09674438","0","1"],["104445.8","0","0","0"],["104444.9","0.17766419","0","2"],["104444.8","0.000025","0","2"],["104444.6","0.22737818","0","2"],["104444.5","0.052","0","2"],["104443.6","0.03767982","0","1"],["104443.1","0.15202924","0","1"],["104443","0","0","0"],["104440.8","0.27257616","0","3"],["104440.7","0","0","0"],["104440.4","0.15758117","0","1"],["104440.3","0","0","0"],["104438.1","0.25063964","0","1"],["104438","0","0","0"],["104434.9","0.26049344","0","1"],["104434.8","0","0","0"],["104434.1","0.25679291","0","1"],["104434","0","0","0"],["104270.3","0","0","0"]],"ts":"1747171021701","checksum":1433868695,"seqId":54226734440,"prevSeqId":54226734371}]}
{"arg":{"channel":"books","instId":"BTC-USDT"},"action":"update","data":[{"asks":[],"bids":[["104460","0.0001","0","2"]],"ts":"1747171021901","checksum":-186557301,"seqId":54226734443,"prevSeqId":54226734440}]}
{"arg":{"channel":"books","instId":"BTC-USDT"},"action":"update","data":[{"asks":[["104469.3","0.052","0","2"]],"bids":[],"ts":"1747171022001","checksum":-794463184,"seqId":54226734446,"prevSeqId":54226734443}]}
