{"arg":{"channel":"books","instId":"BTC-USDT"},"action":"update","data":[{"asks":[["104462.3","0.02662651","0","1"],["104463.4","0.00011435","0","1"],["104463.5","0.48057994","0","1"],["104463.6","0","0","0"],["104464","0.18839997","0","2"],["104464.1","0","0","0"],["104469.5","0.17050091","0","1"],["104469.6","0","0","0"],["104469.7","0.19945569","0","2"],["104470.5","0.00478546","0","1"],["104475","0.25345404","0","1"],["104475.1","0","0","0"],["104478.8","0","0","0"],["104480","0.14098898","0","4"],["104541.6","0.234","0","1"],["104546.2","0","0","0"],["104608.4","0.00041816","0","1"]],"bids":[["104454.2","0.0506466","0","1"],["104451.1","0.03281613","0","1"],["104443.1","0","0","0"],["104443","0.09889453","0","1"],["104442.1","0.071782","0","1"],["104442","0.94848602","0","2"],["104441.9","0.54020581","0","2"],["104438","0.00478546","0","1"],["104437.6","0","0","0"],["104432.1","0","0","0"],["104432","0.30738892","0","3"]],"ts":"1747171038801","checksum":204690794,"seqId":54226745682,"prevSeqId":54226745644}]}
{"arg":{"channel":"books","instId":"BTC-USDT"},"action":"update","data":[{"asks":[["104462.3","0","0","0"],["104469.7","0.25661014","0","3"],["104507","1","0","1"]],"bids":[],"ts":"1747171038901","checksum":-433166127,"seqId":54226745685,"prevSeqId":54226745682}]}
{"arg":{"channel":"books","instId":"BTC-USDT"},"action":"update","data":[{"asks":[["104456.3","0","0","0"],["104457.2","0.01259609","0","1"],["104488.1","0.00287134","0","1"],["104488.2","0","0","0"],["104507","0","0","0"],["104610","0.29261492","0","3"]],"bids":[["104456","0.21168729","0","12"]],"ts":"1747171039001","checksum":-1974035312,"seqId":54226745691,"prevSeqId":54226745685}]}
{"arg":{"channel":"books","instId":"BTC-USDT"},"action":"update","data":[{"asks":[["104467.9","0.00478546","0","1"],["104470.5","0","0","0"],["104491.7","0.00056666","0","1"],["104494","0.00287","0","1"],["104533.4","0.00056666","0","1"],["104538.1","0","0","0"],["104610","0","0","0"]],"bids":[["104438","0","0","0"],["104436","0.00478546","0","1"],["104432.7","0.13877947","0","1"],["104431.6","0.008","0","1"],["104429","0.00056666","0","1"],["104427.8","0","0","0"],["104387.3","0.00056666","0","1"],["104383.7","0","0","0"],["104269.6","0","0","0"]],"ts":"1747171039101","checksum":-1974035312,"seqId":54226745705,"prevSeqId":54226745691}]}
{"arg":{"channel":"books","instId":"BTC-USDT"},"action":"update","data":[{"asks":[["104463.5","0.30514996","0","1"],["104464","0.0932","0","1"],["104464.1","0.10062115","0","1"],["104464.7","0","0","0"],["104464.8","0.13283375","0","3"],["104465.7","0","0","0"],["104465.8","0.09796761","0","1"],["104466.2","0","0","0"],["104466.3","0.11580226","0","2"],["104468.4","0.5423562","0","2"],["104469.2","0","0","0"],["104469.3","0.1562975","0","1"],["104469.5","0","0","0"],["104469.6","0.16853877","0","1"],["104469.7","0.09551295","0","2"],["104469.8","0.16612105","0","1"],["104472.5","0.00001","0","1"],["104472.6","0.16432877","0","1"],["104472.9","0.002","0","1"],["104473","0.24870986","0","1"],["104474.7","0","0","0"],["104474.8","0.24364982","0","1"],["104475","0","0","0"],["104475.1","0.24343625","0","1"],["104478.7","0","0","0"],["104478.8","0.25841304","0","1"],["104480","0.00220843","0","3"],["104482.1","0.13877744","0","1"],["104608.2","0","0","0"],["104608.3","0","0","0"],["104608.4","0","0","0"]],"bids":[["104456","0.24768729","0","13"],["104446.9","0.4485081","0","2"],["104445.3","0.19689442","0","2"],["104445.2","0","0","0"],["104443.8","0.08944232","0","1"],["104443.7","0","0","0"],["104443.1","0.10003808","0","1"],["104443","0","0","0"],["104442.1","0.2254692","0","2"],["104442","0.77866876","0","1"],["104441.9","0.53642455","0","2"],["104441.8","0.18965732","0","2"],["104441.7","0","0","0"],["104440.3","0.16769911","0","2"],["104440.2","0","0","0"],["104438","0.23836845","0","1"],["104437.9","0","0","0"],["104437.6","0.15114617","0","1"],["104437.5","0","0","0"],["104437.4","0","0","0"],["104436.8","0.51847729","0","5"],["104436.7","0.42695975","0","3"],["104435.3","0.2596226","0","1"],["104435.2","0","0","0"],["104432.7","0.13877895","0","1"],["104432.1","0.25685874","0","1"],["104432","0.052","0","2"],["104431.3","0.25730336","0","1"],["104431.2","0","0","0"],["104389","0.01053074","0","1"],["104388.3","0.02005704","0","2"],["104384.9","0.02106148","0","2"],["104383.2","0.01053074","0","1"],["104381","0.01053074","0","1"],["104380.2","0.01053074","0","1"],["104379.1","0.01053074","0","1"],["104377.3","0.01054074","0","2"],["104375","0.01053074","0","1"],["104373.5","0.01053074","0","1"],["104369.3","0.01053074","0","1"],["104357.5","0.00001","0","1"],["104357.2","0.00010146","0","1"],["104271.8","0","0","0"],["104271.5","0","0","0"],["104271.1","0","0","0"],["104270.8","0","0","0"],["104270.5","0","0","0"],["104270.3","0","0","0"],["104270","0","0","0"],["104269.9","0","0","0"]],"ts":"1747171039201","checksum":-787851720,"seqId":54226745789,"prevSeqId":54226745705}]}
{"arg":{"channel":"books","instId":"BTC-USDT"},"action":"update","data":[{"asks":[["104469.7","0.05715445","0","1"],["104481","0.13877883","0","1"],["104482.1","0","0","0"]],"bids":[["104456","0.27279523","0","14"],["104454.1","0","0","0"],["104432.7","0.13877883","0","1"],["104271.8","0.0000102","0","1"]],"ts":"1747171039301","checksum":1096185710,"seqId":54226745806,"prevSeqId":54226745789}]}
{"arg":{"channel":"books","instId":"BTC-USDT"},"action":"update","data":[{"asks":[["104464.1","0","0","0"],["104464.2","0.09470888","0","1"],["104464.8","0.03852198","0","2"],["104464.9","0.09345573","0","1"],["104465.8","0","0","0"],["104465.9","0.0870672","0","2"],["104466.3","0.02822972","0","1"],["104466.4","0.13198489","0","2"],["104466.9","0.02510794","0","1"],["104468.4","0.45365674","0","2"],["104469.3","0","0","0"],["104469.4","0.16087547","0","1"],["104469.6","0","0","0"],["104469.7","0.20840066","0","2"],["104469.8","0","0","0"],["104469.9","0.17023916","0","1"],["104473","0","0","0"],["104473.1","0.24195236","0","1"],["104474.8","0","0","0"],["104474.9","0.31408393","0","2"],["104475.1","0","0","0"],["104475.2","0.26810822","0","1"],["104478.8","0","0","0"],["104478.9","1.01677768","0","3"],["104608.2","0.01059542","0","1"],["104608.3","0.03","0","1"]],"bids":[["104446.9","0.45164661","0","2"],["104445.4","0.18584762","0","2"],["104445.3","0","0","0"],["104443.9","0.13501249","0","2"],["104443.8","0","0","0"],["104443.2","0.1004506","0","1"],["104443.1","0","0","0"],["104442.2","0.16921302","0","1"],["104442.1","0.071782","0","1"],["104441.9","0.69009057","0","3"],["104441.8","0.03928085","0","1"],["104440.4","0.15317418","0","1"],["104440.3","0.00005","0","1"],["104438.1","0.25046717","0","1"],["104438","0","0","0"],["104436.7","0.41947204","0","3"],["104435.4","0.23741937","0","1"],["104435.3","0","0","0"],["104432.2","0.25410428","0","1"],["104432.1","0","0","0"],["104431.4","0.24945207","0","1"],["104431.3","0","0","0"],["104271.8","0","0","0"]],"ts":"1747171039401","checksum":1731886354,"seqId":54226745859,"prevSeqId":54226745806}]}
{"arg":{"channel":"books","instId":"BTC-USDT"},"action":"update","data":[{"asks":[["104456.1","0.46477225","0","7"],["104467.9","0","0","0"],["104469.3","0.00478546","0","1"]],"bids":[["104437.4","0.00478546","0","1"],["104436","0","0","0"]],"ts":"1747171039501","checksum":-1769296968,"seqId":54226745865,"prevSeqId":54226745859}]}
{"arg":{"channel":"books","instId":"BTC-USDT"},"action":"update","data":[{"asks":[["104456.7","0.00956983","0","1"],["104457.2","0","0","0"],["104462.9","0.02662636","0","1"],["104463.5","0.23611584","0","2"],["104463.7","0","0","0"],["104464.2","0","0","0"],["104464.4","0.09156245","0","1"],["104464.9","0","0","0"],["104465.1","0.09991396","0","1"],["104465.9","0.19287972","0","2"],["104466.1","0.09142283","0","1"],["104466.4","0.04","0","1"],["104466.6","0.08767325","0","1"],["104466.7","0","0","0"],["104467.3","0","0","0"],["104468.4","0.24359637","0","2"],["104469.3","0","0","0"],["104469.4","0","0","0"],["104469.6","0.14821737","0","1"],["104469.7","0.05715445","0","1"],["104469.9","0.16133011","0","1"],["104470.1","0.16386371","0","1"],["104470.6","0.00478546","0","1"],["104471.7","0","0","0"],["104472.6","0","0","0"],["104472.8","0.15533251","0","2"],["104473.1","0","0","0"],["104473.3","0.25141474","0","1"],["104474.9","0.04462016","0","1"],["104475.1","0.26944148","0","1"],["104475.2","0","0","0"],["104475.4","0.27117536","0","1"],["104478.9","0.77340335","0","2"],["104479.1","0.24678297","0","1"],["104481","0","0","0"],["104482.1","0.13877752","0","1"],["104514.9","0.06821783","0","1"],["104546.2","0.04383993","0","1"],["104607.5","0","0","0"],["104608.2","0","0","0"],["104608.3","0","0","0"]],"bids":[["104456","0.45175961","0","16"],["104446.9","0.49282508","0","2"],["104445.6","0.18424193","0","3"],["104445.4","0","0","0"],["104444.1","0.09804642","0","1"],["104443.9","0.04","0","1"],["104443.4","0.09698912","0","1"],["104443.2","0","0","0"],["104442.4","0.15960446","0","1"],["104442.2","0","0","0"],["104442.1","0.22331428","0","2"],["104441.9","0.37211211","0","1"],["104440.6","0.16696694","0","1"],["104440.4","0","0","0"],["104438.7","0.00478546","0","1"],["104438.3","0.24828047","0","1"],["104438.1","0","0","0"],["104437.8","0.15002522","0","1"],["104437.6","0","0","0"],["104437.4","0","0","0"],["104436.7","0.50295813","0","3"],["104435.6","0.25104245","0","1"],["104435.4","0","0","0"],["104432.4","0.26754459","0","1"],["104432.2","0","0","0"],["104431.6","0.26400904","0","2"],["104431.4","0","0","0"],["104388.9","0","0","0"],["104388.6","0.02896645","0","1"],["104271.8","0.0000102","0","1"]],"ts":"1747171039801","checksum":-188249038,"seqId":54226745952,"prevSeqId":54226745865}]}
{"arg":{"channel":"books","instId":"BTC-USDT"},"action":"update","data":[{"asks":[["104456.7","0","0","0"],["104462.9","0","0","0"],["104465.9","0.22198485","0","3"],["104470.6","0","0","0"],["104471.1","0.04703351","0","3"],["104607.5","0.00001","0","1"],["104608.2","0.01059542","0","1"],["104608.3","0.03","0","1"]],"bids":[["104456","0.44850961","0","13"]],"ts":"1747171039901","checksum":1601400446,"seqId":54226746003,"prevSeqId":54226745952}]}
{"arg":{"channel":"books","instId":"BTC-USDT"},"action":"update","data":[{"asks":[],"bids":[["104454.2","0.08380157","0","2"],["104451.1","0","0","0"],["104403.7","0.00048867","0","2"],["104271.5","0.00030759","0","1"]],"ts":"1747171040001","checksum":2084380605,"seqId":54226746009,"prevSeqId":54226746003}]}
{"arg":{"channel":"books","instId":"BTC-USDT"},"action":"update","data":[{"asks":[["104470.9","0.00478546","0","1"],["104471.1","0.04224805","0","2"],["104481","0.13877778","0","1"],["104482.1","0","0","0"],["104490.8","0.00056666","0","1"],["104491.7","0","0","0"],["104532.2","0.00056666","0","1"],["104533.4","0","0","0"],["104608.3","0","0","0"]],"bids":[["104439.6","0.04","0","1"],["104436.8","0.50891753","0","4"],["104436.6","0.10555977","0","4"],["104429","0","0","0"],["104428.5","0.07355038","0","2"],["104392.2","0.00002963","0","1"],["104392","0","0","0"],["104387.3","0","0","0"],["104387.1","0.00056666","0","1"]],"ts":"1747171040101","checksum":2084380605,"seqId":54226746032,"prevSeqId":54226746009}]}
{"arg":{"channel":"books","instId":"BTC-USDT"},"action":"update","data":[{"asks":[["104458.2","0.005","0","1"],["104463.5","0.39248688","0","1"],["104465.8","0.36908178","0","1"],["104470.7","0.005","0","1"],["104608.2","0","0","0"]],"bids":[["104431.8","0","0","0"],["104419.3","0","0","0"],["104357.2","0","0","0"],["104356.9","0.00009899","0","1"],["104271.1","0.00001029","0","1"],["104270.8","0.00022348","0","1"]],"ts":"1747171040201","checksum":-1252494964,"seqId":54226746044,"prevSeqId":54226746032}]}
{"arg":{"channel":"books","instId":"BTC-USDT"},"action":"update","data":[{"asks":[["104457.8","0.00956983","0","1"],["104470.9","0","0","0"],["104471.1","0.04703351","0","3"]],"bids":[["104456","0.45084961","0","14"],["104439.7","0.00575546","0","2"],["104438.7","0","0","0"],["104270.5","0.00012512","0","2"]],"ts":"1747171040401","checksum":-1715195584,"seqId":54226746054,"prevSeqId":54226746044}]}
{"arg":{"channel":"books","instId":"BTC-USDT"},"action":"update","data":[{"asks":[["104480","0.14098765","0","4"],["104481","0","0","0"],["104608.2","0.01059542","0","1"]],"bids":[["104439.7","0.00097","0","1"],["104438.7","0.00478546","0","1"],["104270.5","0","0","0"]],"ts":"1747171040501","checksum":-1715195584,"seqId":54226746066,"prevSeqId":54226746054}]}
{"arg":{"channel":"books","instId":"BTC-USDT"},"action":"update","data":[{"asks":[["104458.2","0.01","0","2"],["104470.7","0.01","0","2"],["104595.9","0.03","0","1"],["104608.2","0","0","0"]],"bids":[["104431.8","0.005","0","1"],["104419.3","0.005","0","1"],["104271.1","0","0","0"],["104270.8","0","0","0"]],"ts":"1747171040601","checksum":-1899084,"seqId":54226746071,"prevSeqId":54226746066}]}
{"arg":{"channel":"books","instId":"BTC-USDT"},"action":"update","data":[{"asks":[["104466.5","0.00478546","0","1"],["104471.1","0.04224805","0","2"],["104478.9","0.91218394","0","3"],["104480","0.00220843","0","3"],["104607.5","0","0","0"]],"bids":[["104456","0.43484961","0","13"],["104438.7","0","0","0"],["104434.6","0.00478546","0","1"],["104432.7","0","0","0"],["104431.7","0.1387804","0","1"]],"ts":"1747171040701","checksum":-687842612,"seqId":54226746094,"prevSeqId":54226746071}]}
{"arg":{"channel":"books","instId":"BTC-USDT"},"action":"update","data":[{"asks":[["104456.1","0.79752225","0","9"],["104462.9","0.02342365","0","1"],["104463.6","0.10204739","0","1"],["104464.2","0.09786976","0","1"],["104464.4","0","0","0"],["104465.1","0","0","0"],["104465.2","0.09806237","0","1"],["104465.7","0.09846003","0","1"],["104465.9","0.19766518","0","3"],["104466.1","0","0","0"],["104466.5","0","0","0"],["104466.6","0","0","0"],["104468.4","0.24232193","0","2"],["104468.7","0.15640492","0","1"],["104469.1","0.16051997","0","1"],["104469.2","0.15577455","0","1"],["104469.6","0","0","0"],["104469.9","0","0","0"],["104470.1","0","0","0"],["104472","0.14813901","0","1"],["104472.5","0.2279373","0","2"],["104472.8","0.0084426","0","1"],["104473.3","0","0","0"],["104474.2","0.26124404","0","1"],["104474.6","0.25321223","0","1"],["104475.1","0","0","0"],["104475.4","0","0","0"],["104478.2","0.42592891","0","2"],["104478.8","0.13878132","0","1"],["104478.9","0.77340335","0","2"],["104479.1","0","0","0"]],"bids":[["104456","0.11318523","0","9"],["104447","0","0","0"],["104446.9","0.19045026","0","2"],["104445.6","0.00262892","0","1"],["104444.8","0.0017399","0","3"],["104444.7","0.18094206","0","2"],["104444.1","0","0","0"],["104443.4","0","0","0"],["104443.2","0.09357562","0","1"],["104442.6","0.09517648","0","1"],["104442.4","0","0","0"],["104442.1","0.071782","0","1"],["104442","0","0","0"],["104441.9","0.51763872","0","2"],["104441.6","0.15448976","0","1"],["104441.2","0.33081151","0","3"],["104440.6","0","0","0"],["104439.7","0.15598289","0","2"],["104438.3","0","0","0"],["104437.8","0","0","0"],["104437.5","0.22961183","0","1"],["104437","0.15445989","0","1"],["104436.7","0.30385076","0","2"],["104435.6","0","0","0"],["104434.7","0.25151888","0","1"],["104434.6","0","0","0"],["104432.8","0.00478546","0","1"],["104432.4","0","0","0"],["104431.7","0","0","0"],["104431.6","0.27667869","0","2"],["104430.7","0.2392822","0","1"],["104429.5","0.13878132","0","1"],["104271.1","0.00001029","0","1"],["104270.8","0.00022348","0","1"]],"ts":"1747171040801","checksum":-130032538,"seqId":54226746238,"prevSeqId":54226746094}]}
{"arg":{"channel":"books","instId":"BTC-USDT"},"action":"update","data":[{"asks":[["104456.1","0.45990405","0","7"],["104465.9","0.19287972","0","2"],["104467.9","0.00478546","0","1"],["104472.4","0.25974239","0","1"],["104472.5","0.00001","0","1"],["104477.9","0.13878225","0","1"],["104478.8","0","0","0"],["104605.4","0","0","0"],["104605.7","0","0","0"]],"bids":[["104456","0.11084523","0","8"],["104447","0.0017149","0","1"],["104446.9","0.41212222","0","1"],["104444.8","0.000025","0","2"],["104442","0.77866876","0","1"],["104437.5","0","0","0"],["104437.4","0.23402591","0","1"],["104434.8","0.00478546","0","1"],["104432.8","0","0","0"],["104429.5","0.13878225","0","1"],["104271.1","0","0","0"],["104270.8","0","0","0"]],"ts":"1747171040901","checksum":-1080538595,"seqId":54226746278,"prevSeqId":54226746238}]}
{"arg":{"channel":"books","instId":"BTC-USDT"},"action":"update","data":[{"asks":[["104477.9","0","0","0"],["104478.8","0.1387816","0","1"]],"bids":[["104430.8","0.1387816","0","1"],["104429.5","0","0","0"]],"ts":"1747171041001","checksum":-1080538595,"seqId":54226746286,"prevSeqId":54226746278}]}
{"arg":{"channel":"books","instId":"BTC-USDT"},"action":"update","data":[{"asks":[["104478.8","0","0","0"],["104480","0.14098891","0","4"],["104488.4","0.00057666","0","2"],["104490.8","0","0","0"],["104527.5","0.00056666","0","1"],["104532.2","0","0","0"],["104605.4","0.03","0","1"],["104605.7","0.0000221","0","1"]],"bids":[["104456","0.23354523","0","10"],["104436.7","0.43094273","0","3"],["104436.6","0.096","0","3"],["104436.5","0.00478546","0","1"],["104436.4","0.00955979","0","1"],["104434.8","0","0","0"],["104431.7","0.13878076","0","1"],["104430.8","0","0","0"],["104429.7","0.00056666","0","1"],["104428.5","0.07298372","0","1"],["104390.6","0.00056666","0","1"],["104387.1","0","0","0"],["104271.8","0","0","0"],["104271.5","0","0","0"]],"ts":"1747171041101","checksum":-673469438,"seqId":54226746307,"prevSeqId":54226746286}]}
{"arg":{"channel":"books","instId":"BTC-USDT"},"action":"update","data":[{"asks":[["104457.8","0","0","0"],["104463.6","0","0","0"],["104464.2","0","0","0"],["104464.4","0.10128824","0","1"],["104465.1","0.09371134","0","1"],["104465.2","0","0","0"],["104465.7","0","0","0"],["104466.1","0.0857651","0","1"],["104466.6","0.09327869","0","1"],["104468.4","0.24651302","0","2"],["104468.7","0","0","0"],["104469.1","0","0","0"],["104469.2","0","0","0"],["104469.6","0.15977569","0","1"],["104469.9","0.15066981","0","1"],["104470.1","0.15920651","0","1"],["104472","0","0","0"],["104472.4","0","0","0"],["104472.8","0.16881385","0","2"],["104473.1","0.05486615","0","1"],["104473.3","0.24242996","0","1"],["104474.2","0","0","0"],["104474.6","0","0","0"],["104474.9","0","0","0"],["104475.1","0.26211998","0","1"],["104475.4","0.24791113","0","1"],["104478.2","0.19242972","0","1"],["104479","0.58286227","0","4"],["104479.1","0.24841267","0","1"],["104480","0.00220843","0","3"],["104607.5","0.00001","0","1"]],"bids":[["104456","0.35010961","0","10"],["104454.2","0.0506466","0","1"],["104450.8","0.027728","0","1"],["104445.6","0.19285702","0","3"],["104444.7","0","0","0"],["104444.1","0.09824185","0","1"],["104443.4","0.0966852","0","1"],["104443.2","0","0","0"],["104442.6","0","0","0"],["104442.4","0.15940129","0","1"],["104442.1","0.23523466","0","2"],["104441.9","0.37211211","0","1"],["104441.6","0","0","0"],["104441.2","0.18029353","0","2"],["104440.6","0.15056673","0","1"],["104439.7","0.00097","0","1"],["104438.3","0.2285039","0","1"],["104437.8","0.15896048","0","1"],["104437.4","0","0","0"],["104437","0","0","0"],["104436.7","0.51106002","0","3"],["104436.5","0","0","0"],["104436","0.00478546","0","1"],["104435.6","0.26089477","0","1"],["104434.7","0","0","0"],["104432.4","0.27074625","0","1"],["104431.7","0.13878049","0","1"],["104431.6","0.26839963","0","2"],["104430.7","0","0","0"],["104356.9","0","0","0"],["104356.6","0.00009894","0","1"],["104271.9","0","0","0"]],"ts":"1747171041201","checksum":-1056609908,"seqId":54226746443,"prevSeqId":54226746307}]}
{"arg":{"channel":"books","instId":"BTC-USDT"},"action":"update","data":[{"asks":[["104463.3","0.00011435","0","1"],["104463.4","0.10068838","0","1"],["104464","0.19167866","0","2"],["104464.4","0","0","0"],["104465","0.09725902","0","1"],["104465.1","0","0","0"],["104465.6","0.08874808","0","1"],["104466.1","0","0","0"],["104466.6","0","0","0"],["104468.4","0.53728184","0","1"],["104468.5","0.15153498","0","2"],["104468.9","0.16812043","0","1"],["104469","0.16732253","0","1"],["104469.6","0","0","0"],["104469.9","0","0","0"],["104470.1","0","0","0"],["104471.7","0.77866876","0","1"],["104471.8","0.16384634","0","1"],["104472.3","0.23300326","0","1"],["104472.8","0.0084426","0","1"],["104473.3","0","0","0"],["104473.4","0.50542588","0","2"],["104474","0.25895896","0","1"],["104474.4","0.25998196","0","1"],["104475.1","0","0","0"],["104475.4","0","0","0"],["104478.1","0.2378842","0","1"],["104479","0.44408178","0","3"],["104479.1","0","0","0"],["104481","0.13877904","0","1"],["104520.5","0.82863494","0","2"],["104607.5","0","0","0"]],"bids":[["104456","0.11084523","0","8"],["104445.6","0.00262892","0","1"],["104444.5","0.228231","0","4"],["104444.1","0","0","0"],["104443.4","0","0","0"],["104443.1","0.10018859","0","1"],["104442.4","0.09152342","0","1"],["104442.1","0.071782","0","1"],["104441.9","0.59222367","0","2"],["104441.4","0.17876297","0","2"],["104441","0.14685971","0","1"],["104440.6","0","0","0"],["104439.5","0.16900034","0","1"],["104438.3","0","0","0"],["104437.8","0","0","0"],["104437.3","0.27244166","0","2"],["104436.8","0.66352486","0","5"],["104436.7","0.30385076","0","2"],["104436","0","0","0"],["104435.6","0","0","0"],["104434.6","0.00478546","0","1"],["104434.5","0.25564579","0","2"],["104432.7","0.13877904","0","1"],["104432.4","0","0","0"],["104431.7","0","0","0"],["104431.6","0.008","0","1"],["104431.4","0.2679233","0","1"],["104430.6","0.26529227","0","1"],["104271.9","0.00004632","0","2"],["104271.8","0.0000102","0","1"]],"ts":"1747171041301","checksum":-317455405,"seqId":54226746517,"prevSeqId":54226746443}]}
{"arg":{"channel":"books","instId":"BTC-USDT"},"action":"update","data":[{"asks":[["104457","0.01574645","0","3"],["104480","0.14098887","0","4"],["104481","0","0","0"],["104505.1","0","0","0"],["104505.2","0.0287183","0","1"],["104520.5","0.93318738","0","3"],["104536.5","0","0","0"],["104607.5","0.00001","0","1"],["104608.2","0.01059542","0","1"],["104608.3","0.03","0","1"]],"bids":[["104456","0.11249523","0","9"],["104432.7","0","0","0"],["104431.6","0.1467807","0","2"],["104424.5","0.20869903","0","1"],["104423.4","0.03598865","0","1"],["104394.6","0.50585689","0","1"],["104392.1","0","0","0"],["104271.5","0.00030759","0","1"],["104271.1","0.00001029","0","1"]],"ts":"1747171041401","checksum":-1210929971,"seqId":54226746549,"prevSeqId":54226746517}]}
{"arg":{"channel":"books","instId":"BTC-USDT"},"action":"update","data":[{"asks":[["104457","0.00617662","0","2"],["104463.3","0","0","0"],["104463.4","0.00011435","0","1"],["104464","0.0932","0","1"],["104464.1","0.09637088","0","1"],["104464.8","0.13873199","0","3"],["104465","0","0","0"],["104465.6","0","0","0"],["104465.7","0.08791336","0","1"],["104466.3","0.12011834","0","2"],["104467.9","0","0","0"],["104468.3","0.00478546","0","1"],["104468.4","0.52866838","0","2"],["104468.5","0.00001","0","1"],["104468.9","0","0","0"],["104469","0","0","0"],["104469.2","0.14586649","0","1"],["104469.6","0.1498748","0","1"],["104469.8","0.16072979","0","1"],["104471.8","0","0","0"],["104472.3","0","0","0"],["104472.5","0.15054681","0","2"],["104473","0.23837748","0","1"],["104473.4","0.43376561","0","2"],["104474","0","0","0"],["104474.4","0","0","0"],["104474.8","0.24638015","0","1"],["104475.1","0.27157738","0","1"],["104478.1","0","0","0"],["104478.8","0.25654446","0","1"],["104505.2","1.40616047","0","2"],["104536.5","2.42938453","0","1"]],"bids":[["104456","0.23199523","0","10"],["104445.3","0.09343648","0","1"],["104445.2","0.08944894","0","1"],["104444.5","0.052","0","2"],["104443.8","0.09851728","0","1"],["104443.1","0.09892642","0","1"],["104442.4","0","0","0"],["104442.1","0.22574132","0","2"],["104441.9","0.54479566","0","2"],["104441.7","0.1475658","0","1"],["104441.4","0.028575","0","1"],["104441","0","0","0"],["104440.3","0.14908884","0","2"],["104439.5","0","0","0"],["104438","0.24323576","0","1"],["104437.5","0.16516324","0","1"],["104437.3","0.03","0","1"],["104436.8","0.50891753","0","4"],["104436.7","0.42905316","0","4"],["104435.3","0.25303354","0","1"],["104434.6","0","0","0"],["104434.5","0.00191","0","1"],["104432.1","0.24969944","0","1"],["104431.4","0","0","0"],["104431.3","0.24538427","0","1"],["104430.6","0","0","0"],["104424.5","0.6706556","0","2"],["104424.1","1.37582704","0","1"],["104394.6","1.19059187","0","2"],["104392.8","2.50219894","0","2"],["104271.9","0","0","0"],["104271.8","0","0","0"],["104271.5","0","0","0"],["104271.1","0","0","0"]],"ts":"1747171041501","checksum":879300069,"seqId":54226746621,"prevSeqId":54226746549}]}
{"arg":{"channel":"books","instId":"BTC-USDT"},"action":"update","data":[{"asks":[["104462.9","0","0","0"],["104463.4","0","0","0"],["104463.5","0","0","0"],["104463.9","0.00011435","0","1"],["104464.1","0","0","0"],["104464.3","0.22710434","0","1"],["104464.4","0.10148362","0","1"],["104464.8","0.03852198","0","2"],["104465.1","0.09235932","0","1"],["104465.7","0","0","0"],["104465.8","0","0","0"],["104465.9","0.00045","0","1"],["104466.1","0.08772309","0","1"],["104466.2","0.0306001","0","1"],["104466.3","0.02822972","0","1"],["104466.6","0.09256624","0","1"],["104467.7","0.19242972","0","1"],["104468.3","0","0","0"],["104468.4","0.26460823","0","2"],["104469.2","0","0","0"],["104469.6","0.16132543","0","1"],["104469.8","0","0","0"],["104469.9","0.16157096","0","1"],["104470.1","0.16633456","0","1"],["104470.6","0.00478546","0","1"],["104471.7","0","0","0"],["104472.5","0.00001","0","1"],["104472.8","0.16094623","0","2"],["104473","0","0","0"],["104473.3","0.24618427","0","1"],["104473.4","0.4306689","0","2"],["104474.8","0","0","0"],["104475.1","0.2388862","0","1"],["104475.4","0.26874898","0","1"],["104478.8","0","0","0"],["104479.1","0.24855664","0","1"],["104480","0.00220843","0","3"],["104482.1","0.13877762","0","1"],["104485","0.26864","0","1"],["104498.1","0","0","0"],["104608.2","0","0","0"],["104608.3","0","0","0"]],"bids":[["104456","0.47295961","0","13"],["104454.3","0.02866394","0","1"],["104450.8","0","0","0"],["104445.6","0.19194512","0","3"],["104445.3","0","0","0"],["104445.2","0","0","0"],["104444.1","0.09390375","0","1"],["104443.8","0","0","0"],["104443.4","0.09161808","0","1"],["104443.1","0","0","0"],["104442.4","0.16011958","0","1"],["104442.1","0.23386612","0","2"],["104441.9","0.37211211","0","1"],["104441.7","0","0","0"],["104440.6","0.15828729","0","1"],["104440.3","0.00005","0","1"],["104438.3","0.25263531","0","1"],["104438","0","0","0"],["104437.8","0.16142838","0","1"],["104437.5","0","0","0"],["104437.4","0.00478546","0","1"],["104436.7","0.50553879","0","3"],["104435.6","0.27044033","0","1"],["104435.3","0","0","0"],["104432.7","0.13877901","0","1"],["104432.4","0.2503175","0","1"],["104432.1","0","0","0"],["104431.6","0.26088047","0","2"],["104431.3","0","0","0"],["104397.1","0","0","0"],["104387.3","0.22835","0","1"],["104369.2","0","0","0"],["104365.2","0","0","0"],["104345.5","1.41786074","0","2"],["104271.9","0.00004632","0","2"],["104271.8","0.0000102","0","1"]],"ts":"1747171041601","checksum":-1459340622,"seqId":54226746727,"prevSeqId":54226746621}]}
{"arg":{"channel":"books","instId":"BTC-USDT"},"action":"update","data":[{"asks":[["104492","0","0","0"],["104493","0.77866876","0","1"],["104494","0.00487","0","3"],["104495","0.001","0","1"],["104513","0","0","0"],["104514","0","0","0"],["104515","0.00004786","0","1"],["104516","0.16","0","2"],["104517","0.24999999","0","5"],["104518","0.085","0","2"],["104607.5","0","0","0"]],"bids":[],"ts":"1747171041701","checksum":-1459340622,"seqId":54226746752,"prevSeqId":54226746727}]}
{"arg":{"channel":"books","instId":"BTC-USDT"},"action":"update","data":[{"asks":[["104456.1","0.49590405","0","8"],["104463","0.05942364","0","2"],["104463.8","0.00011435","0","1"],["104463.9","0.36908178","0","1"],["104464.3","0.48086581","0","2"],["104466.2","0","0","0"],["104467.6","0.77866876","0","1"],["104546.2","0.25905166","0","2"],["104605.7","0","0","0"]],"bids":[["104456","0.46975961","0","12"]],"ts":"1747171041801","checksum":725754595,"seqId":54226746762,"prevSeqId":54226746752}]}
{"arg":{"channel":"books","instId":"BTC-USDT"},"action":"update","data":[{"asks":[["104456.1","0.50547388","0","9"],["104461","0.02342407","0","1"],["104469.7","0","0","0"],["104492","0.002","0","2"],["104493","0.77966876","0","2"],["104494","0.00287","0","1"],["104495","0","0","0"],["104513","0.16","0","2"],["104514","0.17999999","0","3"],["104515","0.05004786","0","2"],["104516","0","0","0"],["104517","0.07","0","2"],["104518","0.035","0","1"],["104605.4","0","0","0"]],"bids":[["104456","0.34860961","0","10"],["104454.3","0","0","0"],["104451","0.02772796","0","1"]],"ts":"1747171041901","checksum":-819873527,"seqId":54226746788,"prevSeqId":54226746762}]}
{"arg":{"channel":"books","instId":"BTC-USDT"},"action":"update","data":[{"asks":[["104461","0","0","0"],["104473.5","0.28886599","0","2"],["104605.4","0.03","0","1"]],"bids":[],"ts":"1747171042001","checksum":236004796,"seqId":54226746791,"prevSeqId":54226746788}]}
{"arg":{"channel":"books","instId":"BTC-USDT"},"action":"update","data":[{"asks":[["104456.1","0.49590405","0","8"],["104468.3","0.00478546","0","1"],["104470.6","0","0","0"],["104480","0.14098822","0","4"],["104482.1","0","0","0"],["104487.8","0.00056666","0","1"],["104488.4","0.00001","0","1"],["104526.8","0.00056666","0","1"],["104527.5","0","0","0"]],"bids":[["104437.4","0","0","0"],["104436.4","0","0","0"],["104436.3","0.00478546","0","1"],["104436.2","0.00955981","0","1"],["104432.7","0","0","0"],["104432.6","0.50786138","0","2"],["104429.7","0","0","0"],["104429.2","0.00056666","0","1"],["104392.2","0","0","0"],["104392","0.00002963","0","1"],["104390.6","0","0","0"],["104390.1","0.00056666","0","1"],["104271.5","0.00030759","0","1"]],"ts":"1747171042101","checksum":1510697426,"seqId":54226746836,"prevSeqId":54226746791}]}
{"arg":{"channel":"books","instId":"BTC-USDT"},"action":"update","data":[{"asks":[["104514","0.24999999","0","5"],["104515","0.08504786","0","3"],["104517","0","0","0"],["104518","0","0","0"],["104605.7","0.0000221","0","1"],["104607.5","0.00001","0","1"]],"bids":[["104454.1","0.02573407","0","1"],["104451","0","0","0"],["104436.9","0.00478546","0","1"],["104436.3","0","0","0"],["104432.6","0.36908178","0","1"],["104432.1","0.13877975","0","1"],["104357.2","0.00009856","0","1"],["104356.6","0","0","0"],["104271.5","0","0","0"]],"ts":"1747171042201","checksum":-187863126,"seqId":54226746850,"prevSeqId":54226746836}]}
{"arg":{"channel":"books","instId":"BTC-USDT"},"action":"update","data":[{"asks":[["104468.3","0","0","0"],["104469.5","0.00478546","0","1"]],"bids":[],"ts":"1747171042301","checksum":-187863126,"seqId":54226746860,"prevSeqId":54226746850}]}
{"arg":{"channel":"books","instId":"BTC-USDT"},"action":"update","data":[{"asks":[["104457","0.01574645","0","3"],["104469.5","0","0","0"],["104469.8","0.00478546","0","1"],["104480","0.00220843","0","3"],["104481","0.13877899","0","1"],["104607.5","0","0","0"]],"bids":[["104456","0.34964961","0","11"],["104438.4","0.00478546","0","1"],["104436.9","0","0","0"],["104432.7","0.13877913","0","1"],["104432.1","0","0","0"],["104403.7","0.00047867","0","1"]],"ts":"1747171042401","checksum":-1705837673,"seqId":54226746881,"prevSeqId":54226746860}]}
{"arg":{"channel":"books","instId":"BTC-USDT"},"action":"update","data":[{"asks":[["104469.8","0","0","0"],["104470.6","0.00478546","0","1"]],"bids":[["104438.7","0.00478546","0","1"],["104438.4","0","0","0"]],"ts":"1747171042601","checksum":-1705837673,"seqId":54226746885,"prevSeqId":54226746881}]}
{"arg":{"channel":"books","instId":"BTC-USDT"},"action":"update","data":[{"asks":[["104480","0.14098819","0","4"],["104481","0","0","0"],["104607.5","0.00001","0","1"]],"bids":[["104432.7","0","0","0"],["104432.1","0.13877976","0","1"]],"ts":"1747171042701","checksum":-1705837673,"seqId":54226746889,"prevSeqId":54226746885}]}
{"arg":{"channel":"books","instId":"BTC-USDT"},"action":"update","data":[{"asks":[["104464.3","0.57343826","0","3"],["104464.4","0","0","0"],["104465","0.09268747","0","1"],["104465.1","0","0","0"],["104466","0.18189918","0","2"],["104466.1","0","0","0"],["104466.5","0.08957275","0","1"],["104466.6","0","0","0"],["104468.4","0.31657488","0","2"],["104469.5","0.14268575","0","1"],["104469.6","0","0","0"],["104469.8","0.1665636","0","1"],["104469.9","0","0","0"],["104470","0.24362953","0","4"],["104470.1","0","0","0"],["104472.7","0.16081374","0","1"],["104472.8","0.0084426","0","1"],["104473.2","0.25190862","0","1"],["104473.3","0","0","0"],["104475","0.25731572","0","1"],["104475.1","0","0","0"],["104475.3","0.24875056","0","1"],["104475.4","0","0","0"],["104478.8","0.13878108","0","1"],["104479","0.68511614","0","4"],["104479.1","0","0","0"],["104480","0.00220843","0","3"],["104505.1","0.4221011","0","1"],["104536.1","0.0208134","0","1"]],"bids":[["104456","0.31364961","0","10"],["104445.6","0.00262892","0","1"],["104445.5","0.1896209","0","2"],["104444.1","0","0","0"],["104444","0.08775024","0","1"],["104443.4","0","0","0"],["104443.3","0.09589598","0","1"],["104442.4","0","0","0"],["104442.3","0.21401265","0","3"],["104442.1","0.071782","0","1"],["104442","0.93347632","0","2"],["104440.6","0","0","0"],["104440.5","0.15115823","0","1"],["104438.3","0","0","0"],["104438.2","0.23711765","0","1"],["104437.8","0","0","0"],["104437.7","0.14676512","0","1"],["104436.7","0.42448699","0","3"],["104435.6","0","0","0"],["104435.5","0.24679049","0","1"],["104432.4","0","0","0"],["104432.3","0.25667439","0","1"],["104432.1","0","0","0"],["104431.6","0.008","0","1"],["104431.5","0.61202341","0","2"],["104429.5","0.13878108","0","1"],["104388.6","0.09368064","0","2"]],"ts":"1747171042801","checksum":1907220395,"seqId":54226746950,"prevSeqId":54226746889}]}
{"arg":{"channel":"books","instId":"BTC-USDT"},"action":"update","data":[{"asks":[["104456.1","0.82865405","0","10"],["104457.9","0.10066361","0","3"],["104463.3","0.09317352","0","1"],["104464","0.18625293","0","2"],["104464.3","0.48086581","0","2"],["104465","0.0947896","0","1"],["104465.5","0.09304274","0","1"],["104466","0.0932","0","1"],["104466.5","0","0","0"],["104467.7","0.24004852","0","2"],["104468.4","0.3211127","0","2"],["104468.5","0.16160183","0","2"],["104468.8","0.15181459","0","1"],["104469","0.15269288","0","1"],["104469.5","0","0","0"],["104469.8","0","0","0"],["104469.9","0.00478546","0","1"],["104470","0.09349006","0","3"],["104470.6","0","0","0"],["104471.8","0.15997076","0","1"],["104472.2","0.2611672","0","1"],["104472.7","0","0","0"],["104473.2","0","0","0"],["104473.4","0.50034594","0","2"],["104473.5","0.234","0","1"],["104474","0.26139683","0","1"],["104474.3","0.24113321","0","1"],["104475","0","0","0"],["104475.3","0","0","0"],["104478","0.33056193","0","2"],["104478.7","0.13878097","0","1"],["104478.8","0","0","0"],["104479","0.44408178","0","3"],["104607.5","0","0","0"]],"bids":[["104456","0.11189523","0","10"],["104454.2","0","0","0"],["104454.1","0.03913905","0","1"],["104451.1","0.03090389","0","1"],["104447","0","0","0"],["104446.9","0.19306616","0","2"],["104445.5","0","0","0"],["104444.7","0.0017149","0","1"],["104444.5","0.2393741","0","4"],["104444","0","0","0"],["104443.3","0","0","0"],["104443","0.09218704","0","1"],["104442.3","0.14913778","0","3"],["104442","0.77866876","0","1"],["104441.9","0.59030836","0","2"],["104441.3","0.17168918","0","2"],["104441","0.15087894","0","1"],["104440.5","0","0","0"],["104439.5","0.15677198","0","1"],["104438.7","0","0","0"],["104438.2","0","0","0"],["104437.7","0","0","0"],["104437.2","0.22951685","0","1"],["104436.9","0.00478546","0","1"],["104436.8","0.65698777","0","5"],["104436.7","0.30385076","0","2"],["104435.5","0","0","0"],["104434.5","0.25423277","0","2"],["104432.3","0","0","0"],["104431.5","0.53547939","0","2"],["104431.3","0.24557334","0","1"],["104430.5","0.26691416","0","1"],["104429.5","0.13878097","0","1"],["104271.5","0.00030759","0","1"],["104271.1","0.00001029","0","1"]],"ts":"1747171042901","checksum":1176709218,"seqId":54226747171,"prevSeqId":54226746950}]}
{"arg":{"channel":"books","instId":"BTC-USDT"},"action":"update","data":[{"asks":[["104456.1","0.58978585","0","9"],["104457.9","0.00038538","0","2"],["104462.9","0.00011435","0","1"],["104463.8","0","0","0"],["104477.9","0.13878225","0","1"],["104478.7","0","0","0"]],"bids":[["104447","0.0017149","0","1"],["104446.9","0.41389666","0","1"],["104444.7","0","0","0"],["104429.5","0.13878227","0","1"],["104411.7","0","0","0"],["104404.7","0.0105959","0","1"],["104383.6","0.00952859","0","1"],["104375.6","0.00013108","0","1"],["104271.1","0","0","0"]],"ts":"1747171043001","checksum":-1582847277,"seqId":54226747198,"prevSeqId":54226747171}]}
{"arg":{"channel":"books","instId":"BTC-USDT"},"action":"update","data":[{"asks":[["104458.2","0.005","0","1"],["104464.9","0.09156005","0","1"],["104465","0","0","0"],["104468.4","0.38611245","0","2"],["104468.5","0.00001","0","1"],["104469.9","0","0","0"],["104470.6","0.00478546","0","1"],["104470.7","0.005","0","1"],["104471.7","0.15758433","0","1"],["104471.8","0","0","0"],["104485","0.26920666","0","2"],["104487.8","0","0","0"],["104504","1.07299898","0","3"],["104520.6","0.52650152","0","3"],["104526.8","0","0","0"],["104607.5","0.00001","0","1"],["104608.2","0.01059542","0","1"]],"bids":[["104453.8","0","0","0"],["104444.5","0.14154919","0","3"],["104444.4","0.10852103","0","2"],["104441.3","0.16668918","0","1"],["104441","0","0","0"],["104440.9","0.15345101","0","1"],["104438.7","0.00478546","0","1"],["104436.9","0","0","0"],["104436.8","0.50891753","0","4"],["104436.7","0.4640298","0","3"],["104436.2","0","0","0"],["104435.8","0.00955985","0","1"],["104431.6","0.00856666","0","2"],["104429.2","0","0","0"],["104396","0.00056666","0","1"],["104390.1","0","0","0"],["104271.1","0.00001029","0","1"],["104270.8","0.00022348","0","1"]],"ts":"1747171043101","checksum":-1825210216,"seqId":54226747237,"prevSeqId":54226747198}]}
{"arg":{"channel":"books","instId":"BTC-USDT"},"action":"update","data":[{"asks":[["104477.9","0","0","0"],["104478.8","0.1387816","0","1"]],"bids":[["104430.6","0.1387816","0","1"],["104429.5","0","0","0"]],"ts":"1747171043201","checksum":-1825210216,"seqId":54226747246,"prevSeqId":54226747237}]}
{"arg":{"channel":"books","instId":"BTC-USDT"},"action":"update","data":[{"asks":[["104478.8","0","0","0"],["104480","0.14098871","0","4"],["104608.3","0.03","0","1"]],"bids":[["104431.6","0.14734694","0","3"],["104430.6","0","0","0"],["104270.5","0.00012512","0","2"]],"ts":"1747171043301","checksum":-1825210216,"seqId":54226747250,"prevSeqId":54226747246}]}
{"arg":{"channel":"books","instId":"BTC-USDT"},"action":"update","data":[{"asks":[["104512.3","0.413489","0","1"],["104539.2","0","0","0"]],"bids":[],"ts":"1747171043401","checksum":-1825210216,"seqId":54226747252,"prevSeqId":54226747250}]}
{"arg":{"channel":"books","instId":"BTC-USDT"},"action":"update","data":[{"asks":[["104458.2","0.01","0","2"],["104464.9","0","0","0"],["104467.9","0.00478546","0","1"],["104468.4","0.22314392","0","1"],["104470.6","0","0","0"],["104470.7","0.01","0","2"],["104471.7","0","0","0"],["104478.1","0.13878177","0","1"],["104480","0.00220843","0","3"],["104504","0.07299898","0","2"],["104608.4","0.00041816","0","1"]],"bids":[["104453.8","0.005","0","1"],["104444.4","0.01062754","0","1"],["104441.3","0.17168918","0","2"],["104440.9","0","0","0"],["104438.7","0","0","0"],["104436.7","0.30385076","0","2"],["104436","0.00478546","0","1"],["104431.6","0.00856666","0","2"],["104430.6","0.13878177","0","1"],["104270.5","0","0","0"]],"ts":"1747171043501","checksum":1128916519,"seqId":54226747274,"prevSeqId":54226747252}]}
{"arg":{"channel":"books","instId":"BTC-USDT"},"action":"update","data":[{"asks":[["104462.9","0","0","0"],["104463.8","0.00011435","0","1"],["104465","0.0897781","0","1"],["104468.5","0.15725626","0","2"],["104471.8","0.15642776","0","1"],["104478.1","0","0","0"],["104480","0.14098892","0","4"],["104608.4","0","0","0"]],"bids":[["104444.5","0.23294754","0","4"],["104441","0.14741155","0","1"],["104436.8","0.65860064","0","5"],["104431.6","0.14734715","0","3"],["104430.6","0","0","0"]],"ts":"1747171043601","checksum":-571750077,"seqId":54226747289,"prevSeqId":54226747274}]}
{"arg":{"channel":"books","instId":"BTC-USDT"},"action":"update","data":[{"asks":[["104462.9","0.00011435","0","1"],["104463.8","0","0","0"],["104467.5","0.00478546","0","1"],["104467.9","0","0","0"],["104478.1","0.13878171","0","1"],["104480","0.00220843","0","3"],["104608.3","0","0","0"]],"bids":[["104436","0","0","0"],["104434.6","0.00478546","0","1"],["104431.6","0.00856666","0","2"],["104430.6","0.13878171","0","1"],["104270.8","0","0","0"]],"ts":"1747171043701","checksum":327240029,"seqId":54226747304,"prevSeqId":54226747289}]}
{"arg":{"channel":"books","instId":"BTC-USDT"},"action":"update","data":[{"asks":[["104456.1","0.82378585","0","10"],["104462.9","0","0","0"],["104463.8","0.00011435","0","1"]],"bids":[["104368.1","0.041285","0","2"]],"ts":"1747171043801","checksum":-1641637761,"seqId":54226747310,"prevSeqId":54226747304}]}
{"arg":{"channel":"books","instId":"BTC-USDT"},"action":"update","data":[{"asks":[["104462.9","0.00011435","0","1"],["104463.8","0","0","0"]],"bids":[],"ts":"1747171043901","checksum":1347164257,"seqId":54226747316,"prevSeqId":54226747310}]}
{"arg":{"channel":"books","instId":"BTC-USDT"},"action":"update","data":[{"asks":[["104456.1","0.58978585","0","9"],["104477.9","0.13878235","0","1"],["104478.1","0","0","0"]],"bids":[["104430.6","0","0","0"],["104429.5","0.13878235","0","1"]],"ts":"1747171044001","checksum":327240029,"seqId":54226747330,"prevSeqId":54226747316}]}
{"arg":{"channel":"books","instId":"BTC-USDT"},"action":"update","data":[{"asks":[["104456.1","0.82378585","0","10"],["104462.9","0","0","0"],["104463.8","0.00011435","0","1"],["104477.9","0","0","0"],["104480","0.1409888","0","4"],["104483.1","0.17886019","0","2"],["104485","0.26864","0","1"],["104516.4","0.00056666","0","1"],["104520.6","0.52593486","0","2"]],"bids":[["104435.8","0","0","0"],["104435.6","0.00478546","0","1"],["104435.5","0.00955987","0","1"],["104434.6","0","0","0"],["104433.1","0.00056666","0","1"],["104431.6","0.14678037","0","2"],["104429.5","0","0","0"],["104399.8","0.00056666","0","1"],["104396","0","0","0"]],"ts":"1747171044101","checksum":-1641637761,"seqId":54226747378,"prevSeqId":54226747330}]}
{"arg":{"channel":"books","instId":"BTC-USDT"},"action":"update","data":[{"asks":[["104456.1","0.58978585","0","9"],["104462.9","0.00011435","0","1"],["104463.8","0","0","0"],["104478.8","0.13878071","0","1"],["104480","0.00220843","0","3"],["104608.2","0","0","0"]],"bids":[],"ts":"1747171044201","checksum":327240029,"seqId":54226747387,"prevSeqId":54226747378}]}
{"arg":{"channel":"books","instId":"BTC-USDT"},"action":"update","data":[{"asks":[["104478.8","0","0","0"],["104480","0.1409889","0","4"],["104567.3","0","0","0"],["104608.2","0.01059542","0","1"],["104608.3","0.03","0","1"]],"bids":[["104436","0.00478546","0","1"],["104435.6","0","0","0"],["104356.5","0","0","0"],["104346.1","0","0","0"],["104270.8","0.00022348","0","1"],["104270.5","0.00012512","0","2"]],"ts":"1747171044301","checksum":327240029,"seqId":54226747400,"prevSeqId":54226747387}]}
{"arg":{"channel":"books","instId":"BTC-USDT"},"action":"update","data":[{"asks":[["104467.5","0","0","0"],["104468.3","0.00478546","0","1"]],"bids":[["104436.8","0.6633861","0","6"],["104436","0","0","0"],["104357.6","0.0000977","0","1"],["104357.2","0","0","0"],["104270.3","0.00003386","0","2"]],"ts":"1747171044401","checksum":327240029,"seqId":54226747409,"prevSeqId":54226747400}]}
{"arg":{"channel":"books","instId":"BTC-USDT"},"action":"update","data":[{"asks":[["104499.6","0.6465985","0","2"],["104504","1.07299898","0","3"]],"bids":[],"ts":"1747171044501","checksum":327240029,"seqId":54226747417,"prevSeqId":54226747409}]}
{"arg":{"channel":"books","instId":"BTC-USDT"},"action":"update","data":[{"asks":[["104505.1","0","0","0"],["104505.2","0.0287183","0","1"],["104531","0.01268367","0","1"],["104536.5","0","0","0"],["104608.4","0.00041816","0","1"]],"bids":[["104436.8","0.65860064","0","5"],["104436.7","0.30863622","0","3"],["104424.5","0.20869903","0","1"],["104424.1","0","0","0"],["104394.6","0.50585689","0","1"],["104392.8","0.000015","0","1"],["104270","0.00038892","0","2"]],"ts":"1747171044601","checksum":327240029,"seqId":54226747429,"prevSeqId":54226747417}]}
{"arg":{"channel":"books","instId":"BTC-USDT"},"action":"update","data":[{"asks":[["104456.1","0.49103585","0","8"],["104463.8","0.40058149","0","1"],["104464.3","0","0","0"],["104467.5","0.00478546","0","1"],["104467.6","0","0","0"],["104468.3","0","0","0"],["104505.2","1.41495563","0","2"],["104536.5","2.45782811","0","1"],["104562.3","0.00095636","0","1"],["104608.4","0","0","0"]],"bids":[["104436.7","0.30385076","0","2"],["104435.8","0.00478546","0","1"],["104424.5","0.68981499","0","2"],["104422.6","1.46840799","0","2"],["104391.2","2.57234076","0","1"],["104359.8","0.00173863","0","1"],["104349.5","0.01149981","0","1"],["104270.8","0","0","0"],["104270.5","0","0","0"],["104270.3","0","0","0"],["104270","0","0","0"]],"ts":"1747171044701","checksum":-1592630130,"seqId":54226747448,"prevSeqId":54226747429}]}
{"arg":{"channel":"books","instId":"BTC-USDT"},"action":"update","data":[{"asks":[["104468.4","0.5331113","0","2"],["104471.7","0.77866876","0","1"],["104478.8","0.13878119","0","1"],["104480","0.00220843","0","3"],["104608.2","0","0","0"],["104608.3","0","0","0"]],"bids":[["104431.6","0.008","0","1"],["104430.6","0.13878119","0","1"],["104394.6","1.21146891","0","2"],["104271.1","0","0","0"]],"ts":"1747171044801","checksum":-1592630130,"seqId":54226747455,"prevSeqId":54226747448}]}
{"arg":{"channel":"books","instId":"BTC-USDT"},"action":"update","data":[{"asks":[["104462.9","0","0","0"],["104463","0.036","0","1"],["104463.3","0","0","0"],["104463.7","0.00011435","0","1"],["104464","0.0932","0","1"],["104464.1","0.10074508","0","1"],["104464.8","0.12941705","0","3"],["104465","0","0","0"],["104465.5","0","0","0"],["104465.8","0.0981595","0","1"],["104466","0.120278","0","2"],["104466.3","0.11686772","0","2"],["104467.5","0","0","0"],["104468.4","0.53565395","0","2"],["104468.5","0.00001","0","1"],["104468.8","0","0","0"],["104469","0","0","0"],["104469.3","0.14278113","0","1"],["104469.6","0.16288829","0","1"],["104469.8","0.14920943","0","1"],["104470.6","0.00478546","0","1"],["104471.8","0","0","0"],["104472.2","0","0","0"],["104472.5","0.16727086","0","2"],["104473","0.26089902","0","1"],["104473.4","0.42902081","0","2"],["104474","0","0","0"],["104474.3","0","0","0"],["104474.8","0.26011191","0","1"],["104475.1","0.24202964","0","1"],["104478","0.0932","0","1"],["104478.8","0.26525166","0","1"],["104481","0.13877904","0","1"],["104536.1","0.28495138","0","2"]],"bids":[["104456","0.23459523","0","12"],["104454.3","0.03296589","0","1"],["104451.1","0","0","0"],["104445.3","0.18227025","0","2"],["104444.5","0.052","0","2"],["104443.8","0.09940732","0","1"],["104443.1","0.09779709","0","1"],["104443","0","0","0"],["104442.3","0.052","0","2"],["104442.1","0.23875908","0","2"],["104441.9","0.54945619","0","2"],["104441.8","0.18492442","0","2"],["104441.3","0.005","0","1"],["104441","0","0","0"],["104440.3","0.15684131","0","2"],["104439.5","0","0","0"],["104438.7","0.00478546","0","1"],["104438","0.25795564","0","1"],["104437.5","0.15536277","0","1"],["104437.2","0","0","0"],["104436.8","0.50891753","0","4"],["104436.7","0.42976126","0","3"],["104435.8","0","0","0"],["104435.3","0.26114918","0","1"],["104434.5","0.00191","0","1"],["104432.7","0.13877904","0","1"],["104432.1","0.25933059","0","1"],["104431.5","0.36869051","0","1"],["104431.3","0.24087668","0","1"],["104430.6","0","0","0"],["104430.5","0","0","0"],["104271.8","0","0","0"],["104271.5","0","0","0"]],"ts":"1747171044901","checksum":-1702674830,"seqId":54226747590,"prevSeqId":54226747455}]}
{"arg":{"channel":"books","instId":"BTC-USDT"},"action":"update","data":[{"asks":[["104456.1","0.45503585","0","7"],["104463.8","0.24854592","0","2"],["104463.9","0","0","0"],["104464.1","0","0","0"],["104464.4","0.09521849","0","1"],["104464.8","0.03852198","0","2"],["104465.1","0.0953202","0","1"],["104465.8","0","0","0"],["104466.1","0.08897763","0","1"],["104466.3","0.02822972","0","1"],["104466.6","0.09381354","0","1"],["104468.4","0.24964462","0","2"],["104469.3","0","0","0"],["104469.6","0.16150879","0","1"],["104469.8","0","0","0"],["104469.9","0.16152361","0","1"],["104470.1","0.16718957","0","1"],["104471.7","0","0","0"],["104472.5","0.00001","0","1"],["104472.8","0.16068484","0","2"],["104473","0","0","0"],["104473.3","0.23846363","0","1"],["104473.4","0.43598654","0","2"],["104474.8","0","0","0"],["104475.1","0.26512132","0","1"],["104475.4","0.26023933","0","1"],["104478.8","0","0","0"],["104479.1","0.26740442","0","1"],["104481","0","0","0"],["104482.1","0.13877772","0","1"],["104499.6","0.42844324","0","1"],["104504","0.07299898","0","2"]],"bids":[["104456","0.47425961","0","14"],["104445.6","0.18516378","0","3"],["104445.3","0","0","0"],["104444.1","0.09832054","0","1"],["104443.8","0","0","0"],["104443.4","0.10024011","0","1"],["104443.1","0","0","0"],["104442.4","0.16017312","0","1"],["104442.1","0.23353033","0","2"],["104441.9","0.37211211","0","1"],["104441.8","0.03928085","0","1"],["104440.6","0.15398754","0","1"],["104440.3","0.00005","0","1"],["104438.3","0.2507058","0","1"],["104438","0","0","0"],["104437.8","0.16174766","0","1"],["104437.5","0","0","0"],["104436.7","0.51044803","0","3"],["104435.6","0.25850532","0","1"],["104435.3","0","0","0"],["104432.4","0.26784818","0","1"],["104432.1","0","0","0"],["104431.6","0.27108216","0","2"],["104431.3","0","0","0"]],"ts":"1747171045001","checksum":1826939003,"seqId":54226747663,"prevSeqId":54226747590}]}
{"arg":{"channel":"books","instId":"BTC-USDT"},"action":"update","data":[{"asks":[["104481","0.13877839","0","1"],["104482.1","0","0","0"],["104482.9","0.00056666","0","1"],["104483.1","0.17829353","0","1"],["104516.2","0.00056666","0","1"],["104516.4","0","0","0"],["104607.5","0","0","0"]],"bids":[["104435.5","0","0","0"],["104435.3","0.00955989","0","1"],["104433.1","0","0","0"],["104432.9","0.00057666","0","2"],["104399.8","0","0","0"],["104399.6","0.00056666","0","1"],["104271.8","0.0000102","0","1"]],"ts":"1747171045101","checksum":1826939003,"seqId":54226747675,"prevSeqId":54226747663}]}
{"arg":{"channel":"books","instId":"BTC-USDT"},"action":"update","data":[{"asks":[["104456.1","0.45494329","0","7"],["104463.7","0.36919613","0","2"],["104480","0.14098827","0","4"],["104481","0","0","0"],["104607.5","0.00001","0","1"]],"bids":[["104450","0.08696562","0","4"],["104449.2","0.19242972","0","1"],["104432.7","0","0","0"],["104432.1","0.13877984","0","1"],["104429","0.00256346","0","1"],["104271.9","0","0","0"],["104271.8","0","0","0"]],"ts":"1747171045201","checksum":337324912,"seqId":54226747685,"prevSeqId":54226747675}]}
{"arg":{"channel":"books","instId":"BTC-USDT"},"action":"update","data":[{"asks":[["104463.5","0.00011435","0","1"],["104463.6","0.43654038","0","1"],["104463.7","0.36908178","0","1"],["104463.8","0","0","0"],["104480","0.00220843","0","3"],["104481","0.13877857","0","1"],["104605.7","0","0","0"],["104607.5","0","0","0"]],"bids":[["104432.7","0.13877857","0","1"],["104432.1","0","0","0"]],"ts":"1747171045301","checksum":-1340221423,"seqId":54226747696,"prevSeqId":54226747685}]}
{"arg":{"channel":"books","instId":"BTC-USDT"},"action":"update","data":[{"asks":[["104469.5","0.00478546","0","1"],["104470.6","0","0","0"],["104481","0.13877853","0","1"]],"bids":[["104438.7","0","0","0"],["104437.9","0.00478546","0","1"],["104432.7","0.13877853","0","1"]],"ts":"1747171045401","checksum":-1340221423,"seqId":54226747709,"prevSeqId":54226747696}]}
{"arg":{"channel":"books","instId":"BTC-USDT"},"action":"update","data":[{"asks":[],"bids":[["104450","0.03337194","0","3"],["104449.2","0","0","0"],["104429.7","0.00256346","0","1"],["104429","0","0","0"],["104271.9","0.00004632","0","2"]],"ts":"1747171045501","checksum":80448750,"seqId":54226747713,"prevSeqId":54226747709}]}
{"event":"subscribe","arg":{"channel":"books","instId":"BTC-USDT"},"connId":"4b3956e4"}
{"arg":{"channel":"books","instId":"BTC-USDT"},"action":"snapshot","data":[{"asks":[["104523.9","0.26517406","0","8"],["104524","0.13619536","0","4"],["104524.2","0.00001221","0","1"],["104524.5","0.00055923","0","2"],["104525","0.0025","0","1"],["104525.4","0.00262617","0","1"],["104525.5","0.0000125","0","1"],["104525.9","0.10079529","0","2"],["104526","0.0932","0","1"],["104526.1","0.002","0","1"],["104527.4","0.07298372","0","1"],["104528","0.09321033","0","2"],["104528.1","0.00001","0","1"],["104528.3","0.00002714","0","1"],["104528.5","0.00041113","0","1"],["104529.2","0.00011817","0","2"],["104529.4","0.00002902","0","1"],["104529.5","0.10125825","0","2"],["104530","0.00029006","0","2"],["104530.3","0.00014294","0","1"],["104530.4","0.36598204","0","3"],["104530.5","0.05973587","0","1"],["104530.8","0.0000125","0","1"],["104531.4","0.00209352","0","1"],["104531.6","0.00001","0","1"],["104531.8","0.00045","0","1"],["104532.2","0.18391004","0","3"],["104532.9","0.0000535","0","1"],["104533","0.23072273","0","2"],["104533.3","0.01261438","0","9"],["104533.5","0.0239091","0","1"],["104533.6","0.00001161","0","1"],["104534.6","0.005","0","1"],["104534.7","0.00094804","0","1"],["104534.8","0.0127554","0","1"],["104535","0.15251275","0","1"],["104535.4","0.16906813","0","1"],["104535.5","0.00007327","0","1"],["104535.6","0.55887439","0","5"],["104535.7","0.14616131","0","1"],["104536","0.00002583","0","2"],["104536.4","0.00002296","0","1"],["104537.1","0.00093","0","1"],["104537.2","0.04223807","0","1"],["104537.8","0.00004785","0","1"],["104538","0.00478255","0","1"],["104538.1","0.01","0","1"],["104538.4","0.07300588","0","3"],["104538.5","0.15029777","0","5"],["104538.6","0.002","0","1"],["104538.8","0.03586365","0","1"],["104539","0.00004416","0","1"],["104539.5","0.248616","0","3"],["104540","0.00342039","0","7"],["104540.3","0.04283333","0","1"],["104540.4","0.23814639","0","1"],["104540.5","0.26589924","0","1"],["104541.2","0.00009506","0","1"],["104541.4","0.0001","0","1"],["104541.8","0.00481593","0","2"],["104541.9","0.00003805","0","1"],["104542","0.00002848","0","1"],["104542.1","0.00003343","0","1"],["104542.2","0.00007978","0","2"],["104542.3","0.00093","0","1"],["104542.5","0.78527738","0","1"],["104543.3","0.00001193","0","1"],["104543.6","0.03149164","0","1"],["104544","0.00001","0","1"],["104544.7","0.23647471","0","1"],["104544.9","0.00118674","0","1"],["104545","0.53986795","0","3"],["104545.1","0.95705339","0","2"],["104545.2","0.17838463","0","1"],["104545.4","0.00136665","0","8"],["104545.5","0.071759","0","1"],["104545.6","0.04","0","1"],["104545.7","0.04","0","1"],["104545.8","0.13077002","0","4"],["104546","0.17838463","0","1"],["104546.2","0.25253914","0","2"],["104546.6","0.00002544","0","1"],["104546.8","0.17838463","0","1"],["104546.9","0.00016922","0","1"],["104547.5","0.00191","0","1"],["104547.7","0.00002452","0","1"],["104547.8","0.22525473","0","1"],["104547.9","0.00001","0","1"],["104548.2","0.00008292","0","2"],["104548.3","0.00001619","0","1"],["104548.8","0.00007023","0","1"],["104548.9","0.17838463","0","1"],["104550","0.152799","0","13"],["104550.9","0.00009629","0","2"],["104551.2","0.00006067","0","2"],["104551.7","0.00478377","0","1"],["104552.1","0.13868456","0","1"],["104552.2","0.2882755","0","2"],["104552.3","0.17838463","0","1"],["104552.4","0.00006285","0","2"],["104552.5","0.00001318","0","1"],["104552.6","0.00711203","0","1"],["104552.7","0.00191","0","1"],["104553.1","0.00001019","0","1"],["104553.7","0.00002373","0","1"],["104553.8","0.09415","0","1"],["104554","0.18038463","0","3"],["104554.1","0.32063642","0","2"],["104554.8","0.00003857","0","1"],["104555","0.001","0","1"],["104555.5","0.00956262","0","1"],["104555.7","0.05996122","0","1"],["104555.8","0.011506","0","1"],["104555.9","0.19243972","0","2"],["104556.6","0.00019085","0","3"],["104557","0.00287","0","1"],["104557.2","0.26248243","0","1"],["104557.3","0.77866876","0","1"],["104557.8","0.00004723","0","1"],["104558.1","0.04845664","0","1"],["104558.2","0.00001105","0","1"],["104558.9","0.00040805","0","13"],["104559.4","0.00002482","0","1"],["104559.8","0.00001","0","1"],["104559.9","0.00004783","0","1"],["104560","0.00367155","0","9"],["104560.3","0.00011389","0","1"],["104560.5","0.00001501","0","1"],["104560.9","0.00023767","0","1"],["104561.1","0.00001686","0","1"],["104561.3","0.00002103","0","2"],["104561.6","0.20714158","0","2"],["104561.9","0.34742422","0","1"],["104562.1","0.00013857","0","1"],["104562.2","0.00019967","0","1"],["104562.9","0.00002305","0","2"],["104563","0.00014327","0","1"],["104563.8","0.00001","0","1"],["104563.9","0.00013857","0","3"],["104564.4","0.00286948","0","1"],["104565.1","0.00003524","0","3"],["104566.5","0.00880376","0","1"],["104566.6","0.00481788","0","1"],["104566.8","0.19242972","0","1"],["104566.9","0.66427902","0","1"],["104567","0.94409588","0","3"],["104567.1","0.00071107","0","1"],["104567.3","0.00001018","0","1"],["104567.5","0.00287","0","1"],["104567.6","0.00011258","0","1"],["104567.8","0.00001","0","1"],["104568.5","0.00004784","0","1"],["104569.3","1.4338577","0","1"],["104569.4","0.00003068","0","1"],["104570","0.00029006","0","2"],["104570.1","0.77866876","0","1"],["104570.3","0.00023506","0","1"],["104571","0.00001501","0","1"],["104571.2","0.00002544","0","1"],["104571.4","0.02203952","0","5"],["104571.8","0.00001","0","1"],["104572","0.00245746","0","15"],["104572.3","0.00047837","0","1"],["104572.9","0.04848587","0","1"],["104573.2","0.00071894","0","2"],["104574.9","0.00009806","0","2"],["104575","0.00001293","0","1"],["104575.5","0.03439274","0","1"],["104575.6","0.07298372","0","1"],["104575.7","0.00007234","0","6"],["104575.8","0.02870427","0","1"],["104576","0.00177128","0","2"],["104576.2","0.00021481","0","1"],["104576.6","0.01089604","0","1"],["104577.4","0.00001027","0","1"],["104577.7","0.00009281","0","1"],["104577.8","0.0000281","0","1"],["104578","0.34435078","0","8"],["104578.3","0.00004236","0","1"],["104578.7","0.1","0","1"],["104578.9","0.0001279","0","10"],["104579","0.16499999","0","3"],["104579.5","0.0000479","0","1"],["104579.6","0.01089604","0","1"],["104579.7","0.00001","0","1"],["104579.8","0.36739703","0","1"],["104579.9","0.34742422","0","1"],["104580","0.00222718","0","4"],["104580.5","0.00002636","0","1"],["104580.6","0.0003014","0","1"],["104581","0.00006705","0","1"],["104581.5","0.00003002","0","2"],["104581.6","0.02868786","0","1"],["104581.7","0.00001662","0","1"],["104581.8","0.00006856","0","1"],["104582","0.0025","0","1"],["104582.1","0.09567","0","1"],["104582.3","0.77866876","0","1"],["104582.6","0.05277031","0","3"],["104582.7","0.01137583","0","5"],["104582.9","0.00001022","0","1"],["104583","0.0016","0","1"],["104583.3","0.00128613","0","4"],["104583.4","0.00005163","0","1"],["104583.5","0.0008017","0","1"],["104583.7","0.00001","0","1"],["104583.8","0.00002973","0","1"],["104584","0.005","0","2"],["104584.3","0.00003465","0","1"],["104585.2","0.09567","0","1"],["104585.3","0.00017103","0","3"],["104585.4","0.01089604","0","1"],["104585.5","0.01059591","0","1"],["104586.2","0.01059591","0","1"],["104586.3","0.00012015","0","1"],["104586.8","0.00002219","0","1"],["104587","0.00009531","0","4"],["104587.4","0.00002013","0","1"],["104587.7","0.00001","0","1"],["104588","0.00004952","0","1"],["104588.2","0.00014513","0","1"],["104588.3","0.0008026","0","1"],["104588.4","0.01059591","0","1"],["104588.5","0.02142296","0","2"],["104588.6","0.0005","0","1"],["104588.7","0.14374436","0","2"],["104589.3","0.00002047","0","2"],["104589.6","0.01052692","0","1"],["104589.9","0.00001232","0","1"],["104590","0.00028006","0","1"],["104590.4","0.00003738","0","3"],["104590.8","0.02179208","0","2"],["104590.9","0.01059591","0","1"],["104591","0.00002611","0","1"],["104591.3","0.00029731","0","3"],["104591.6","0.00001","0","1"],["104591.7","0.00021266","0","4"],["104591.9","0.01052692","0","1"],["104592","0.0730493","0","3"],["104592.7","0.01089604","0","1"],["104592.8","0.35802013","0","2"],["104592.9","0.64240416","0","3"],["104593","0.77866876","0","1"],["104593.2","0.00003453","0","1"],["104593.4","0.00008341","0","1"],["104593.6","0.01139124","0","2"],["104594.1","0.01052692","0","1"],["104595.3","0.01059591","0","1"],["104595.6","0.00001","0","1"],["104595.7","0.06697","0","1"],["104595.8","0.554133","0","1"],["104596","0.00010095","0","1"],["104596.9","0.00014244","0","2"],["104597","0.85665","0","1"],["104597.1","0.00003805","0","1"],["104597.2","0.02185122","0","3"],["104597.3","0.01059591","0","1"],["104597.4","0.01052692","0","1"],["104597.5","0.00003019","0","2"],["104598.6","0.0001","0","1"],["104599","0.00287","0","1"],["104599.1","1.00174186","0","2"],["104599.3","0.0956","0","1"],["104599.4","0.01089604","0","1"],["104599.5","0.01052692","0","1"],["104599.6","0.00002057","0","2"],["104599.8","0.01059591","0","1"],["104599.9","0.00246247","0","5"],["104600","0.03507358","0","78"],["104600.2","0.0008","0","1"],["104600.3","0.00006","0","1"],["104600.4","0.01065475","0","4"],["104600.8","0.00002848","0","1"],["104601.3","0.46208986","0","3"],["104601.5","0.00449585","0","2"],["104601.9","0.00001587","0","1"],["104602.2","2.57659596","0","2"],["104602.5","0.00001501","0","1"],["104602.8","0.1434","0","1"],["104603","0.01089604","0","1"],["104603.1","0.01063811","0","3"],["104603.2","0.01052551","0","1"],["104603.3","0.01434842","0","2"],["104603.5","0.27366519","0","1"],["104603.6","0.7892043","0","3"],["104603.7","0.01052692","0","1"],["104604","0.11472","0","1"],["104604.3","0.00001","0","1"],["104604.7","0.00019394","0","2"],["104605.4","0.01089604","0","1"],["104605.6","0.01052531","0","1"],["104605.7","0.02107453","0","3"],["104605.9","0.00001004","0","1"],["104606","4.32159191","0","1"],["104606.7","0.00001236","0","1"],["104607.2","0.00045297","0","1"],["104607.4","0.0956","0","1"],["104607.5","0.01090604","0","2"],["104607.6","0.01052551","0","1"],["104607.7","0.0478131","0","1"],["104608","0.00036","0","1"],["104608.1","0.01053778","0","2"],["104608.3","0.01054238","0","2"],["104608.4","0.00041816","0","1"],["104608.8","0.51808936","0","16"],["104609","0.00002405","0","1"],["104609.1","0.4","0","1"],["104609.3","0.01089604","0","1"],["104609.4","0.01058144","0","5"],["104609.7","0.09645082","0","3"],["104610","0.29297492","0","4"],["104610.5","0.00002072","0","2"],["104610.9","0.00001023","0","1"],["104611.1","0.00008224","0","1"],["104611.3","0.00005484","0","1"],["104611.5","0.00001","0","1"],["104611.8","0.01089604","0","1"],["104612.3","0.00015701","0","4"],["104612.4","0.01059591","0","1"],["104612.5","0.01061957","0","3"],["104612.6","0.01052531","0","1"],["104612.7","0.01052551","0","1"],["104612.9","0.00001168","0","1"],["104613","0.00002505","0","2"],["104613.9","0.01052531","0","1"],["104614","0.97264328","0","1"],["104614.3","0.00018922","0","1"],["104614.5","0.00025252","0","1"],["104614.7","0.19118","0","1"],["104614.9","0.0000105","0","1"],["104615","0.01052551","0","1"],["104615.1","0.77866876","0","1"],["104615.3","0.29245206","0","6"],["104615.4","0.01052531","0","1"],["104615.5","0.01053551","0","2"],["104615.9","0.00004084","0","4"],["104616.1","0.01052551","0","1"],["104616.2","0.00836","0","1"],["104616.6","0.00010128","0","5"],["104617.6","0.00003056","0","2"],["104617.7","0.01052391","0","1"],["104617.8","0.0105243","0","1"],["104617.9","0.01052531","0","1"],["104618","0.00237876","0","4"],["104618.2","0.00002481","0","1"],["104618.5","0.00009552","0","1"],["104619.1","0.00002759","0","1"],["104619.5","0.01059977","0","3"],["104619.6","0.0105243","0","1"],["104619.7","0.01089604","0","1"],["104619.8","0.01529962","0","1"],["104620","0.00222603","0","4"],["104620.8","0.00001187","0","1"],["104620.9","0.01052531","0","1"],["104621","0.03","0","1"],["104621.2","0.06827236","0","2"],["104621.7","0.00018519","0","1"],["104621.8","0.06697","0","1"],["104622","0.00002255","0","1"],["104622.1","0.01052391","0","1"],["104622.2","0.04634752","0","1"],["104622.9","0.0105243","0","1"],["104623","0.01089604","0","1"],["104623.4","0.00001","0","1"],["104623.5","0.00001501","0","1"],["104623.6","0.00083722","0","2"],["104623.9","0.04059591","0","2"],["104624.3","0.00164236","0","2"],["104624.4","0.00017437","0","1"],["104624.8","0.0105243","0","1"],["104624.9","0.01059591","0","1"],["104625","0.00511417","0","6"],["104625.3","0.03","0","1"],["104625.4","0.00037568","0","2"],["104625.6","0.00017762","0","2"],["104625.7","0.0001","0","1"],["104625.8","0.12009579","0","2"],["104626.6","0.0000413","0","2"],["104626.8","0.12001371","0","2"],["104626.9","0.02142034","0","2"],["104627","0.87099337","0","2"],["104627.2","0.77866876","0","1"],["104627.4","0.00001","0","1"],["104627.8","0.00001104","0","1"],["104628.1","0.07769495","0","2"],["104628.4","0.00011498","0","1"],["104628.6","0.0001","0","1"],["104628.7","0.00001176","0","1"],["104628.8","0.07298372","0","1"],["104628.9","0.00047056","0","9"],["104629.1","0.00009584","0","1"],["104629.4","0.00001168","0","1"],["104629.5","0.00010997","0","1"],["104629.6","0.0002773","0","2"],["104629.9","0.02301636","0","2"],["104630","0.00039338","0","2"],["104630.1","0.5","0","1"],["104630.2","0.0004067","0","2"],["104630.4","0.00001585","0","1"],["104630.7","0.00024099","0","2"]],"bids":[["104523.8","0.04912611","0","6"],["104522.2","0.04388813","0","1"],["104522.1","0.03308376","0","1"],["104521","0.01","0","1"],["104520","0.10321","0","3"],["104519.9","0.00185441","0","1"],["104519.8","0.0330845","0","1"],["104518.1","0.04283076","0","1"],["104518","0.0932","0","1"],["104517.8","0.03829301","0","1"],["104516.4","0.01077618","0","1"],["104516.1","0.0005","0","1"],["104514.2","0.00168632","0","1"],["104514.1","0.33885364","0","2"],["104514","0.00521803","0","1"],["104513.9","0.05158077","0","1"],["104512.1","0.19242972","0","1"],["104512","0.11151267","0","3"],["104511.7","0.09532154","0","1"],["104511","0.34742422","0","1"],["104510.9","0.09361072","0","1"],["104510.8","0.072736","0","2"],["104510.6","0.05223905","0","1"],["104510","0.09349006","0","3"],["104509.9","0.08","0","1"],["104509.8","0.09416","0","1"],["104509.7","0.0915129","0","1"],["104509.2","0.06982057","0","2"],["104509","0.6752354","0","2"],["104508.9","0.77866876","0","1"],["104508.5","0.53199262","0","2"],["104508.3","0.00001","0","1"],["104508.2","0.15982709","0","1"],["104508","0.0932","0","1"],["104507.5","0.16568002","0","1"],["104507.2","0.00001501","0","1"],["104506.6","0.02651631","0","1"],["104506","0.0932","0","1"],["104505.9","0.15862776","0","1"],["104505.7","0.00478255","0","1"],["104505.6","0.04233353","0","2"],["104504.5","0.24282659","0","1"],["104504.3","0.30793471","0","3"],["104504","0.0932","0","1"],["104503.6","0.13868448","0","1"],["104503.5","0.14662632","0","1"],["104501.2","0.19242972","0","1"],["104500.9","0.27108268","0","1"],["104500.4","0.34934422","0","3"],["104500","0.00220843","0","3"],["104499.2","0.06","0","2"],["104498","0.17838463","0","1"],["104497.2","0.62287824","0","2"],["104497.1","0.4888","0","1"],["104496.8","0.000015","0","1"],["104496.4","0.00001","0","1"],["104496.1","0.77866876","0","1"],["104495.9","0.0038279","0","1"],["104495.4","0.04663166","0","1"],["104495.2","0.00191","0","1"],["104495","0.12","0","4"],["104494","0.00001478","0","1"],["104493.9","0.00061695","0","1"],["104493.4","0.22730303","0","1"],["104492.4","0.00001","0","1"],["104491.9","0.02870308","0","1"],["104491.8","0.17838463","0","1"],["104490.6","0.19954175","0","2"],["104490","0.00029006","0","2"],["104489.9","0.34747422","0","2"],["104488.8","0.02869899","0","1"],["104488.5","0.09167082","0","2"],["104488.2","0.17838463","0","1"],["104487","0.02870465","0","1"],["104486.4","0.000015","0","1"],["104485.4","0.00478395","0","1"],["104484.5","0.00001","0","1"],["104483.9","0.02706","0","1"],["104483.2","0.17838463","0","1"],["104482.7","0.07198","0","1"],["104482.4","0.00009571","0","1"],["104481.9","0.46940375","0","1"],["104481.6","0.01925039","0","1"],["104481.5","0.96045237","0","2"],["104480.6","0.41343","0","1"],["104480.1","0.06993255","0","1"],["104480","0.00220843","0","3"],["104479.3","0.97109848","0","2"],["104479.2","0.34742422","0","1"],["104479","0.48324487","0","1"],["104478.5","1.92853","0","1"],["104478","0.01441614","0","3"],["104476.7","0.52514348","0","2"],["104476.6","0.17838463","0","1"],["104476.4","1.43410608","0","1"],["104476","0.000015","0","1"],["104473.9","0.00478395","0","1"],["104473.4","0.17838463","0","1"],["104472.7","0.04936913","0","1"],["104472.6","0.00001","0","1"],["104471.6","0.05996122","0","1"],["104471.2","0.005","0","1"],["104470","0.00028006","0","1"],["104468.6","0.00001","0","1"],["104468.4","0.19242972","0","1"],["104468.2","0.88551563","0","1"],["104468.1","0.77866876","0","1"],["104468","2.17305","0","1"],["104467.7","0.00047837","0","1"],["104466.8","0.23904101","0","1"],["104466.7","0.34742422","0","1"],["104465.6","0.00001501","0","1"],["104465.5","0.002","0","1"],["104464.6","0.00001","0","1"],["104463.4","0.554835","0","1"],["104462.8","0.04698071","0","2"],["104462.7","0.04783165","0","1"],["104462","0.008","0","1"],["104460.8","0.01834343","0","1"],["104460.7","0.00001","0","1"],["104460","0.00220843","0","3"],["104459.9","0.02870264","0","1"],["104459.6","0.04639227","0","1"],["104459.4","0.00287","0","1"],["104458.8","0.00844239","0","1"],["104458.7","0.005","0","1"],["104457.2","0.00951596","0","1"],["104456.8","0.69562274","0","2"],["104456.7","0.77867876","0","2"],["104456.6","0.19242972","0","1"],["104455.2","0.000015","0","1"],["104454.9","0.34742422","0","1"],["104453.2","0.03827293","0","1"],["104452.7","0.00001","0","1"],["104452.1","0.09703673","0","1"],["104451.2","0.25605","0","1"],["104450","0.01468847","0","4"],["104448.8","0.00001","0","1"],["104447.7","0.0105239","0","1"],["104447.6","0.00287","0","1"],["104447.4","0.01052391","0","1"],["104447.3","0.0105239","0","1"],["104447.2","1.12854189","0","2"],["104446.2","0.77866876","0","1"],["104446.1","0.19242972","0","1"],["104444.8","0.00002501","0","2"],["104443.7","0.02104782","0","2"],["104443.6","0.0210478","0","2"],["104443.5","2.86992088","0","2"],["104442.6","0.06315306","0","6"],["104442","0.01052391","0","1"],["104441.9","0.02104781","0","2"],["104441.8","0.01052551","0","1"],["104440.8","0.00001","0","1"],["104440.7","0.01806884","0","1"],["104440","0.00220843","0","3"],["104439","0.01052551","0","1"],["104438.9","0.01052551","0","1"],["104437.9","0.03696","0","1"],["104436.8","0.00001","0","1"],["104435.8","0.1205","0","1"],["104435.6","0.19242972","0","1"],["104434.6","0.48976215","0","1"],["104434.5","0.77866876","0","1"],["104434.4","0.00001501","0","1"],["104434.2","0.000015","0","1"],["104432.9","0.00001","0","1"],["104432.7","0.00063872","0","1"],["104432.6","0.34742422","0","1"],["104432","0.47439916","0","1"],["104431.9","0.00173775","0","1"],["104431.8","0.01059655","0","1"],["104431.7","0.01903548","0","2"],["104431.4","0.00858103","0","1"],["104430.9","0.00735521","0","1"],["104430.1","0.0008391","0","1"],["104430","0.00028006","0","1"],["104428.9","0.00001","0","1"],["104428.2","0.00009054","0","1"],["104426.8","0.00017476","0","1"],["104426.5","0.005","0","1"],["104425.8","0.00952213","0","1"],["104425.3","0.1913","0","1"],["104425","0.00009624","0","1"],["104424.9","0.00001","0","1"],["104424.7","0.0095217","0","1"],["104424.1","0.01913619","0","1"],["104424","0.00001501","0","1"],["104423.7","0.30482331","0","1"],["104423.6","0.77866876","0","1"],["104423.5","0.19242972","0","1"],["104422","0.01435132","0","1"],["104421.5","0.01149189","0","1"],["104421.4","0.019136","0","1"],["104421","0.00957754","0","2"],["104420.7","0.04514518","0","1"],["104420.6","0.05448285","0","5"],["104420.1","0.0228","0","3"],["104420","0.01740843","0","5"],["104419.9","0.0076","0","1"],["104419.8","0.02225655","0","2"],["104419.1","0.07184","0","1"],["104417.8","0.02193265","0","4"],["104417","0.00001","0","1"],["104415.8","0.01059615","0","1"],["104415.7","0.00956754","0","1"],["104415.6","0.02179314","0","2"],["104415.4","0.0005","0","1"],["104415.1","0.68289385","0","1"],["104415","1.38913","0","1"],["104414","0.005","0","1"],["104413.6","0.00001501","0","1"],["104413.1","0.03179001","0","3"],["104413","0.00001","0","1"],["104412.1","0.01059655","0","1"],["104412","0.02179314","0","2"],["104411.9","0.77866876","0","1"],["104411.6","0.02871268","0","1"],["104410.9","0.01059667","0","1"],["104410","0.0408092","0","3"],["104409.3","0.02179314","0","2"],["104409.2","0.01059667","0","1"],["104409.1","0.01053914","0","2"],["104407.9","0.25236929","0","1"],["104407.8","0.01052914","0","1"],["104407.4","0.832699","0","1"],["104406.6","0.01052914","0","1"],["104406.5","0.02179314","0","2"],["104405.7","0.00123","0","1"],["104405.1","0.00001","0","1"],["104404.6","0.02832122","0","1"],["104403.2","0.00001501","0","1"],["104402.9","0.02179314","0","2"],["104402.8","0.02105828","0","2"],["104402.7","0.03238981","0","3"],["104401.1","0.00001","0","1"],["104400.2","0.01052914","0","1"],["104400.1","0.01059667","0","1"],["104400","0.00326757","0","8"],["104399.9","0.000173","0","1"],["104399.4","0.00041858","0","1"],["104398.7","0.01052914","0","1"],["104398.6","0.01059667","0","1"],["104398.5","0.25637931","0","1"],["104398.4","0.8004619","0","3"],["104396.9","0.01052914","0","1"],["104396.8","0.01059667","0","1"],["104395.2","0.06872117","0","1"],["104394.5","0.13059667","0","2"],["104394.2","0.01166","0","1"],["104394.1","0.01059667","0","1"],["104394","0.13102914","0","2"],["104393.2","0.00001","0","1"],["104392.8","0.00001501","0","1"],["104391.2","0.0008","0","1"],["104390.7","0.010531","0","1"],["104390","0.00028006","0","1"],["104389.7","0.010531","0","1"],["104389.4","0.28110087","0","1"],["104389.2","0.010896","0","1"],["104389.1","0.010531","0","1"],["104388.9","0.01052914","0","1"],["104388.5","0.00001","0","1"],["104387.8","0.07298372","0","1"],["104386.6","0.010531","0","1"],["104386.5","0.77866876","0","1"],["104385.3","0.02179314","0","2"],["104385.2","0.01052914","0","1"],["104385.1","0.010531","0","1"],["104384.8","0.74681381","0","1"],["104383","0.010896","0","1"],["104382.9","0.06","0","2"],["104382.8","0.03","0","1"],["104382.4","0.00001501","0","1"],["104382","0.00001501","0","1"],["104381.9","0.03","0","1"],["104381.5","0.07187","0","1"],["104381.3","0.00001","0","1"],["104380.1","0.010531","0","1"],["104380","2.21925496","0","4"],["104379.7","0.01089639","0","1"],["104379.6","0.03279432","0","2"],["104379.5","0.010896","0","1"],["104377.8","0.03","0","1"],["104377","0.05793435","0","1"],["104374.4","0.37641954","0","2"],["104374.2","0.77866876","0","1"],["104373.4","0.00001","0","1"],["104373.3","0.00958001","0","1"],["104373.1","0.1913","0","1"],["104372.9","0.0001","0","1"],["104372.2","0.00095644","0","1"],["104372.1","0.26274137","0","1"],["104372","0.000015","0","1"],["104370","0.00028006","0","1"],["104368.6","0.00223544","0","1"],["104368.4","0.01406184","0","1"],["104367.5","0.00017476","0","1"],["104365.1","0.0001849","0","1"],["104364.8","0.036","0","1"],["104364.7","0.12","0","1"],["104363.9","0.29384529","0","1"],["104363.3","0.02106714","0","2"],["104361.6","0.000015","0","1"],["104361.5","0.00001","0","1"],["104360.8","0.12","0","1"],["104360.3","0.01059667","0","1"],["104360","0.0033107","0","4"],["104359.9","0.00007315","0","1"],["104359.4","0.77866876","0","1"],["104358.7","0.86393825","0","2"],["104356.4","0.26274137","0","1"],["104356.2","2.57666","0","1"],["104354.9","0.0579344","0","1"],["104354.8","0.04634752","0","1"],["104353.5","0.00957756","0","3"],["104353.1","0.27925127","0","1"],["104352.3","0.1205","0","1"],["104351.2","0.000015","0","1"],["104350","0.00032024","0","2"],["104349.4","0.0084","0","1"],["104348.9","0.77866876","0","1"],["104347","0.04307409","0","1"],["104346.7","0.94072443","0","2"],["104346.6","2.852859","0","2"],["104346.3","0.07187","0","1"],["104343.4","0.00029004","0","1"],["104342.8","0.160792","0","1"],["104342.3","0.01406327","0","1"],["104342.1","0.29549787","0","1"],["104341.6","0.00001","0","1"],["104340.8","0.000015","0","1"],["104340.7","0.26274137","0","1"],["104340","0.00219843","0","2"],["104339.6","0.0001","0","1"],["104339.1","0.11003721","0","1"],["104338.3","0.77866876","0","1"],["104336.4","0.229809","0","1"],["104335.8","0.0144756","0","1"],["104333.7","0.00001","0","1"],["104333.3","0.000173","0","1"],["104332.1","0.00792495","0","1"],["104330.4","0.000015","0","1"],["104330","0.00028006","0","1"],["104329.8","0.00001501","0","1"],["104328.2","0.03","0","1"],["104328.1","0.00095851","0","1"],["104327.6","0.24994844","0","1"],["104327.5","0.77866876","0","1"],["104325","0.26274137","0","1"],["104321.8","0.00001","0","1"],["104320.9","0.1913","0","1"],["104320","0.00222344","0","4"],["104319.8","0.14","0","1"],["104317.4","0.00006","0","1"],["104316.8","0.25734187","0","1"],["104316.5","0.77866876","0","1"],["104315.7","0.00004382","0","1"],["104314.2","0.00008603","0","1"],["104313.9","0.00001","0","1"],["104311.1","0.07191","0","1"],["104310.8","0.00094847","0","1"],["104310.1","0.00097516","0","1"],["104310","0.00028006","0","1"],["104309.6","0.000015","0","1"],["104308.7","0.00007308","0","1"],["104308.2","0.00017476","0","1"],["104305.7","3.43393","0","1"],["104305","0.30623775","0","1"],["104302","0.77867876","0","2"],["104301.1","0.00005572","0","1"],["104300.8","0.07298372","0","1"],["104300","0.00330012","0","8"],["104298.8","0.00915963","0","1"],["104295.1","0.000419","0","1"],["104294.1","0.00001","0","1"],["104294","0.00139613","0","1"],["104293.9","0.00819798","0","2"],["104293.3","0.07298372","0","1"],["104291.2","0.35355563","0","1"],["104291.1","0.77866876","0","1"],["104290.3","0.00005072","0","1"],["104290","0.00028006","0","1"],["104289.7","0.03","0","1"],["104289.4","0.00139512","0","1"],["104288.6","0.0001","0","1"],["104287.6","0.00001725","0","1"],["104286.9","0.0008168","0","2"],["104286.2","0.00031695","0","2"],["104286.1","0.07298372","0","1"],["104285.7","0.00020198","0","3"],["104285.6","0.09","0","3"],["104285.5","0.03","0","1"],["104284.8","8.14173047","0","1"],["104284.6","0.01416","0","1"],["104283.8","0.00001527","0","1"],["104283","0.00023593","0","1"],["104282.2","0.00001068","0","1"],["104281.6","0.5999","0","1"],["104281","0.00002601","0","1"]],"ts":"1747171666501","checksum":296330431,"seqId":54227197940,"prevSeqId":-1}]}
{"arg":{"channel":"books","instId":"BTC-USDT"},"action":"update","data":[{"asks":[["104530.3","0","0","0"],["104537.2","0","0","0"],["104538.3","0.02441916","0","1"],["104554","0.17838463","0","1"],["104555","0","0","0"],["104556","0.002","0","2"],["104557","0.00387","0","2"],["104578","0.01435078","0","2"],["104579","0.15999999","0","2"],["104580","0.25222717","0","9"],["104581","0.08506705","0","3"],["104630.8","0.00001016","0","1"]],"bids":[["104503.6","0","0","0"],["104501.3","0.13868547","0","1"]],"ts":"1747171666601","checksum":-1486037777,"seqId":54227197974,"prevSeqId":54227197940}]}
{"arg":{"channel":"books","instId":"BTC-USDT"},"action":"update","data":[{"asks":[["104537","0.00478255","0","1"],["104538","0","0","0"]],"bids":[["104505.7","0","0","0"],["104504.6","0.00478255","0","1"]],"ts":"1747171666701","checksum":-1486037777,"seqId":54227197984,"prevSeqId":54227197974}]}
{"arg":{"channel":"books","instId":"BTC-USDT"},"action":"update","data":[{"asks":[["104523.9","0.20574783","0","6"],["104525.9","0","0","0"],["104529.5","0.00009587","0","1"],["104529.6","0.09784898","0","1"],["104530.3","0.00014294","0","1"],["104530.4","0.31404567","0","3"],["104532.2","0.19569663","0","3"],["104533","0.19242972","0","1"],["104535","0","0","0"],["104535.1","0.15038173","0","1"],["104535.4","0.15200102","0","1"],["104535.6","0.54648877","0","4"],["104535.7","0.1523217","0","1"],["104537","0","0","0"],["104538.3","0.02920171","0","2"],["104538.5","0.15409233","0","5"],["104539","0.02446315","0","2"],["104539.5","0.26107204","0","3"],["104540.4","0.26500624","0","1"],["104540.5","0","0","0"],["104540.6","0.24548763","0","1"],["104544.7","0.25113227","0","1"],["104554","0.18038463","0","3"],["104555","0.001","0","1"],["104556","0","0","0"],["104557","0.00287","0","1"],["104578","0.34435078","0","8"],["104579","0.16499999","0","3"],["104580","0.00222718","0","4"],["104581","0.00006705","0","1"],["104606","0","0","0"],["104631.1","0.00001258","0","1"]],"bids":[["104511.7","0.09680991","0","1"],["104510.9","0.09848424","0","1"],["104509.7","0.08986462","0","1"],["104508.6","0.10208681","0","1"],["104508.5","0.43383","0","1"],["104508.2","0.15491663","0","1"],["104507.6","0.1611679","0","1"],["104507.5","0","0","0"],["104506.7","0.00478255","0","1"],["104505.9","0.16788907","0","1"],["104504.6","0","0","0"],["104504.5","0.2439388","0","1"],["104504.1","0.13868415","0","1"],["104503.5","0.16400087","0","1"],["104501.3","0","0","0"],["104500.9","0.23894534","0","1"],["104497.2","0.62320584","0","2"],["104281","0","0","0"]],"ts":"1747171666801","checksum":-163957767,"seqId":54227198127,"prevSeqId":54227197984}]}
{"arg":{"channel":"books","instId":"BTC-USDT"},"action":"update","data":[{"asks":[["104525.9","0.07875551","0","1"],["104529.5","0.10095294","0","2"],["104529.6","0","0","0"],["104535","0.15893823","0","1"],["104535.1","0","0","0"],["104535.6","0.58478178","0","5"],["104538.3","0.02441916","0","1"],["104538.9","0.00478255","0","1"],["104540.5","0.26152576","0","1"],["104540.6","0","0","0"],["104552.1","0","0","0"],["104553.7","0.13870623","0","2"],["104554.1","0.29193486","0","1"],["104609.4","4.33015912","0","6"]],"bids":[["104523.8","0.04592611","0","5"],["104508.6","0","0","0"],["104508.5","0.52462645","0","2"],["104507.6","0","0","0"],["104507.5","0.16673461","0","1"],["104504.6","0.1386825","0","1"],["104504.1","0","0","0"],["104281","0.00002601","0","1"]],"ts":"1747171666901","checksum":-1251959942,"seqId":54227198157,"prevSeqId":54227198127}]}
{"arg":{"channel":"books","instId":"BTC-USDT"},"action":"update","data":[{"asks":[["104529.4","0.09519051","0","2"],["104529.5","0.00009587","0","1"],["104530.3","0.09121107","0","2"],["104530.4","0.10074084","0","1"],["104532.1","0.1902657","0","2"],["104532.2","0.00001293","0","1"],["104534.9","0.16444406","0","1"],["104535","0","0","0"],["104535.3","0.15082693","0","1"],["104535.4","0","0","0"],["104535.6","0.43379556","0","5"],["104535.7","0","0","0"],["104538.4","0.21978163","0","4"],["104538.5","0.00110176","0","4"],["104539","0.00004416","0","1"],["104539.4","0.2305534","0","1"],["104539.5","0.00002661","0","2"],["104540.3","0.29132174","0","2"],["104540.4","0.24360544","0","1"],["104540.5","0","0","0"],["104544.6","0.25203778","0","1"],["104544.7","0","0","0"],["104552.1","0.13868518","0","1"],["104553.7","0.00002373","0","1"],["104606","4.31957768","0","1"],["104609.4","0.01058144","0","5"],["104630.8","0","0","0"],["104631.1","0","0","0"]],"bids":[["104523.8","0.03353611","0","4"],["104512.3","0.00001","0","1"],["104511.7","0","0","0"],["104511.6","0.08837711","0","1"],["104510.9","0","0","0"],["104510.8","0.166891","0","3"],["104509.7","0","0","0"],["104509.6","0.09929625","0","1"],["104509","0.46157006","0","1"],["104508.5","0.43383","0","1"],["104508.4","0.09865067","0","1"],["104508.2","0","0","0"],["104508.1","0.16067194","0","1"],["104507.5","0","0","0"],["104507.4","0.17091865","0","1"],["104505.9","0","0","0"],["104505.8","0.1508876","0","1"],["104504.6","0","0","0"],["104504.5","0","0","0"],["104503.5","0","0","0"],["104503.4","0.15573016","0","1"],["104501.3","0.13868518","0","1"],["104500.9","0","0","0"],["104500.8","0.27221945","0","1"],["104497.2","0.38024513","0","1"],["104497.1","0.72592327","0","2"],["104480.5","0.00001","0","1"],["104281","0","0","0"]],"ts":"1747171667001","checksum":1142449067,"seqId":54227198233,"prevSeqId":54227198157}]}
{"arg":{"channel":"books","instId":"BTC-USDT"},"action":"update","data":[{"asks":[["104525.9","0.12477996","0","2"],["104530.2","0.00014294","0","1"],["104530.3","0.09106813","0","1"],["104530.4","0.23210135","0","2"],["104535.6","0.67893639","0","6"],["104536.6","0.02405442","0","1"],["104554","0.17838463","0","1"],["104554.1","0.32063642","0","2"],["104555","0","0","0"],["104556","0.002","0","2"],["104557","0.00387","0","2"],["104578","0.01435078","0","2"],["104579","0.15999999","0","2"],["104580","0.25222717","0","9"],["104581","0.08506705","0","3"],["104606","0","0","0"],["104609.4","4.33015912","0","6"],["104630.7","0","0","0"]],"bids":[["104504.4","0.25159045","0","1"],["104503.5","0.13868471","0","1"],["104501.3","0","0","0"],["104281.6","0","0","0"]],"ts":"1747171667101","checksum":-895051593,"seqId":54227198272,"prevSeqId":54227198233}]}
{"arg":{"channel":"books","instId":"BTC-USDT"},"action":"update","data":[{"asks":[["104554","0.18038463","0","3"],["104555","0.001","0","1"],["104556","0","0","0"],["104557","0.00287","0","1"],["104578","0.34435078","0","8"],["104579","0.16499999","0","3"],["104580","0.00222718","0","4"],["104581","0.00006705","0","1"]],"bids":[["104480.4","0.00954493","0","1"],["104478","0.004871","0","2"],["104282.2","0","0","0"]],"ts":"1747171667201","checksum":-895051593,"seqId":54227198304,"prevSeqId":54227198272}]}
{"arg":{"channel":"books","instId":"BTC-USDT"},"action":"update","data":[{"asks":[["104524","0.12019536","0","3"],["104525.9","0.07875551","0","1"],["104529.4","0.00002902","0","1"],["104530.2","0","0","0"],["104530.3","0.00014294","0","1"],["104530.4","0.14077629","0","2"],["104530.8","0.09392345","0","2"],["104531.7","0.09130906","0","1"],["104532.1","0","0","0"],["104533","0","0","0"],["104533.5","0.20497327","0","3"],["104534.9","0","0","0"],["104535.3","0","0","0"],["104535.6","0.4300509","0","4"],["104536.3","0.16890876","0","1"],["104536.7","0.16210139","0","1"],["104537","0.14938634","0","1"],["104538.4","0.07300588","0","3"],["104538.9","0","0","0"],["104539.4","0","0","0"],["104539.7","0.16370731","0","1"],["104539.9","0.00478255","0","1"],["104540.3","0.04283333","0","1"],["104540.4","0","0","0"],["104540.7","0.24559831","0","1"],["104541.7","0.25293314","0","1"],["104541.8","0.26917341","0","3"],["104544.6","0","0","0"],["104546","0.43050683","0","2"],["104630.7","0.00024099","0","2"]],"bids":[["104523.8","0.15623611","0","6"],["104522.4","0.14811539","0","1"],["104522.3","0.34742422","0","1"],["104522.2","0","0","0"],["104513","0.09340694","0","1"],["104512.2","0.09349691","0","1"],["104511.6","0","0","0"],["104511","0.43537779","0","2"],["104510.8","0.072736","0","2"],["104509.8","0.19138406","0","2"],["104509.6","0","0","0"],["104509.5","0.14740448","0","1"],["104508.8","0.15662051","0","1"],["104508.4","0","0","0"],["104508.1","0","0","0"],["104507.5","0.00478255","0","1"],["104507.4","0","0","0"],["104507.2","0.16329278","0","2"],["104506.7","0","0","0"],["104506.6","0","0","0"],["104505.8","0","0","0"],["104505.7","0.23229871","0","1"],["104504.7","0.15903468","0","1"],["104504.4","0","0","0"],["104503.4","0","0","0"],["104502.2","0.23890436","0","1"],["104500.8","0","0","0"],["104498.5","0.23777898","0","1"],["104497.1","0.4888","0","1"],["104492","0.02651631","0","1"],["104442","0.03806774","0","2"],["104440.7","0","0","0"],["104282.2","0.00001068","0","1"]],"ts":"1747171667301","checksum":2075001183,"seqId":54227198386,"prevSeqId":54227198304}]}
{"arg":{"channel":"books","instId":"BTC-USDT"},"action":"update","data":[{"asks":[["104525.9","0","0","0"],["104527.4","0","0","0"],["104530.4","0.19087311","0","2"],["104530.8","0.09552304","0","2"],["104531.7","0.09948108","0","1"],["104533.5","0.20424658","0","3"],["104535.6","0.499745","0","4"],["104536.3","0.16051106","0","1"],["104536.7","0.16364472","0","1"],["104537","0.15467545","0","1"],["104539.7","0.15810411","0","1"],["104539.9","0","0","0"],["104540.2","0.00478255","0","1"],["104540.7","0.2442647","0","1"],["104541.7","0.26970814","0","1"],["104541.8","0.27557542","0","3"],["104542.5","0.57422652","0","2"],["104544.9","0.7798555","0","2"],["104545","0.19244373","0","2"],["104545.1","0.17838463","0","1"],["104546","0.43181349","0","2"],["104552.1","0","0","0"],["104553.7","0.13870601","0","2"],["104554","0.17838463","0","1"],["104555","0.002","0","2"],["104556","0.001","0","1"],["104578","0.01435078","0","2"],["104579","0.32999999","0","6"],["104580","0.16722717","0","7"],["104630.8","0.00001016","0","1"],["104631.1","0.00001258","0","1"]],"bids":[["104523.8","0.15685306","0","7"],["104513","0.09368293","0","1"],["104512.2","0.09147172","0","1"],["104511","0.44250706","0","2"],["104509.8","0.18950691","0","2"],["104509.5","0.1500058","0","1"],["104508.8","0.15154216","0","1"],["104508.6","0.00478255","0","1"],["104507.5","0","0","0"],["104507.2","0.15963519","0","2"],["104505.7","0.24890654","0","1"],["104504.8","0.13868342","0","1"],["104504.7","0.16142218","0","1"],["104504.3","0.2163256","0","2"],["104503.5","0","0","0"],["104502.2","0.24203069","0","1"],["104498.5","0.26447385","0","1"],["104493.9","0","0","0"],["104281.6","0.5999","0","1"]],"ts":"1747171667401","checksum":-478849955,"seqId":54227198481,"prevSeqId":54227198386}]}
{"arg":{"channel":"books","instId":"BTC-USDT"},"action":"update","data":[{"asks":[["104525.9","0.0568604","0","1"],["104530.4","0.19471631","0","2"],["104530.6","0.09453158","0","1"],["104530.8","0.0000125","0","1"],["104531.5","0.10220088","0","1"],["104531.7","0","0","0"],["104533.3","0.18999853","0","11"],["104533.5","0.0239091","0","1"],["104534","0.19242972","0","1"],["104535.6","0.50346889","0","4"],["104536.1","0.20278398","0","2"],["104536.3","0","0","0"],["104536.5","0.16110705","0","1"],["104536.7","0","0","0"],["104536.8","0.14878518","0","1"],["104537","0","0","0"],["104539.4","0.00478255","0","1"],["104539.5","0.15169156","0","3"],["104539.7","0","0","0"],["104540.2","0","0","0"],["104540.5","0.25723471","0","1"],["104540.7","0","0","0"],["104541.5","0.26844934","0","1"],["104541.6","0.27277389","0","1"],["104541.7","0","0","0"],["104541.8","0.00481593","0","2"],["104544.8","0.34742422","0","1"],["104545.8","0.38270937","0","5"],["104546","0.17838463","0","1"],["104554","0.18038463","0","3"],["104555","0.001","0","1"],["104556","0","0","0"],["104578","0.34435078","0","8"],["104579","0.16499999","0","3"],["104580","0.00222718","0","4"],["104630.7","0","0","0"],["104630.8","0","0","0"],["104631.1","0","0","0"]],"bids":[["104523.8","0.04613306","0","7"],["104513","0","0","0"],["104512.8","0.09181685","0","1"],["104512.2","0","0","0"],["104512","0.20656912","0","4"],["104511","0.34742422","0","1"],["104510.8","0.17120861","0","3"],["104509.8","0.09416","0","1"],["104509.6","0.10009705","0","1"],["104509.5","0","0","0"],["104509.3","0.15249921","0","1"],["104509","0.64175217","0","2"],["104508.8","0","0","0"],["104508.6","0.16459846","0","1"],["104507.2","0.00001501","0","1"],["104507","0.16470444","0","1"],["104506.1","0.00478255","0","1"],["104505.7","0","0","0"],["104505.5","0.26001799","0","1"],["104504.7","0","0","0"],["104504.5","0.15582962","0","1"],["104502.2","0","0","0"],["104502","0.25937263","0","1"],["104498.5","0","0","0"],["104498.3","0.24034807","0","1"],["104281.6","0","0","0"]],"ts":"1747171667501","checksum":-482907635,"seqId":54227198610,"prevSeqId":54227198481}]}
{"arg":{"channel":"books","instId":"BTC-USDT"},"action":"update","data":[{"asks":[["104552.1","0.13868317","0","1"],["104553.7","0.00002373","0","1"],["104630.4","0","0","0"]],"bids":[["104521.1","0.01077618","0","1"],["104516.4","0","0","0"],["104504.8","0","0","0"],["104504.6","0.13868317","0","1"],["104494","0","0","0"],["104493.5","0.00001478","0","1"]],"ts":"1747171667601","checksum":-740403797,"seqId":54227198620,"prevSeqId":54227198610}]}
{"arg":{"channel":"books","instId":"BTC-USDT"},"action":"update","data":[{"asks":[["104536.1","0.16449097","0","1"],["104539.4","0","0","0"],["104541.4","0.00488255","0","2"],["104552.1","0.13868364","0","1"],["104554","0.17838463","0","1"],["104555","0","0","0"],["104556","0.002","0","2"],["104557","0.00387","0","2"],["104572.9","0.33464172","0","1"],["104573","1","0","1"],["104575.5","0","0","0"],["104578","0.01435078","0","2"],["104579","0.15999999","0","2"],["104580","0.25222717","0","9"],["104581","0.08506705","0","3"],["104630.4","0.00001585","0","1"]],"bids":[["104510.5","0.02651631","0","1"],["104509","0.64653472","0","3"],["104506.1","0","0","0"],["104492","0","0","0"],["104459.6","0","0","0"],["104281.6","0.5999","0","1"],["104281","0.00002601","0","1"]],"ts":"1747171667701","checksum":234257582,"seqId":54227198668,"prevSeqId":54227198620}]}
{"arg":{"channel":"books","instId":"BTC-USDT"},"action":"update","data":[{"asks":[["104540.2","0.00478255","0","1"],["104541.4","0.0001","0","1"],["104554","0.18038463","0","3"],["104555","0.001","0","1"],["104556","0","0","0"],["104557","0.00287","0","1"],["104564.8","0.04828405","0","1"],["104572.9","0","0","0"],["104573","0","0","0"],["104578","0.34435078","0","8"],["104579","0.16499999","0","3"],["104580","0.00222718","0","4"],["104581","0.00006705","0","1"],["104609.4","4.34665477","0","6"]],"bids":[["104509","0.64175217","0","2"],["104508.1","0.00478255","0","1"],["104470.6","0.04765474","0","1"],["104281.6","0","0","0"],["104281","0","0","0"]],"ts":"1747171667801","checksum":234257582,"seqId":54227198702,"prevSeqId":54227198668}]}
{"arg":{"channel":"books","instId":"BTC-USDT"},"action":"update","data":[{"asks":[["104536","0.03831884","0","3"]],"bids":[["104523.8","0.04293306","0","6"],["104504.6","0","0","0"],["104504.3","0.30154243","0","3"],["104502.1","0.13868461","0","1"]],"ts":"1747171667901","checksum":-1681577101,"seqId":54227198711,"prevSeqId":54227198702}]}
{"arg":{"channel":"books","instId":"BTC-USDT"},"action":"update","data":[{"asks":[["104531.4","0.09484889","0","2"],["104531.5","0","0","0"],["104533.2","0.17581699","0","2"],["104533.3","0.01261438","0","9"],["104536.4","0.14943926","0","2"],["104536.5","0","0","0"],["104536.7","0.15149162","0","1"],["104536.8","0","0","0"],["104540.2","0","0","0"],["104541.3","0.00478255","0","1"],["104541.4","0.27118313","0","2"],["104541.5","0","0","0"],["104545.7","0.2806336","0","2"],["104545.8","0.13077002","0","4"],["104588.2","0","0","0"],["104618","0.00341876","0","5"],["104630.7","0.00024099","0","2"],["104630.8","0.00001016","0","1"],["104631.1","0.00001258","0","1"]],"bids":[["104523.8","0.03735306","0","6"],["104516.2","0.00001","0","1"],["104512.8","0","0","0"],["104512.7","0.09616707","0","1"],["104512","0.11151267","0","3"],["104511.9","0.09925546","0","1"],["104510.8","0.072736","0","2"],["104510.7","0.09670072","0","1"],["104509.3","0.00478255","0","1"],["104509.2","0.22385081","0","3"],["104508.1","0","0","0"],["104507","0","0","0"],["104506.9","0.15124982","0","1"],["104502.1","0","0","0"],["104502","0","0","0"],["104501.9","0.24987856","0","1"],["104501.3","0.13868465","0","1"],["104498.3","0","0","0"],["104498.2","0.26167072","0","1"],["104476.5","0.00001","0","1"],["104283.8","0","0","0"],["104283","0","0","0"],["104282.2","0","0","0"]],"ts":"1747171668001","checksum":-2045724599,"seqId":54227198762,"prevSeqId":54227198711}]}
{"arg":{"channel":"books","instId":"BTC-USDT"},"action":"update","data":[{"asks":[["104536.6","0","0","0"],["104539.7","0.02367851","0","1"],["104588.2","0.00014513","0","1"],["104631.1","0","0","0"]],"bids":[["104509.3","0","0","0"],["104509.1","0.00478255","0","1"],["104504.4","0.13868373","0","1"],["104501.3","0","0","0"],["104482.8","0.00954471","0","1"],["104480.4","0","0","0"],["104310.1","0","0","0"],["104308.8","0.00097503","0","1"]],"ts":"1747171668101","checksum":-2045724599,"seqId":54227198794,"prevSeqId":54227198762}]}
{"arg":{"channel":"books","instId":"BTC-USDT"},"action":"update","data":[{"asks":[["104538.7","0.00478255","0","1"],["104541.3","0","0","0"],["104554.1","0.29193486","0","1"],["104588.2","0","0","0"],["104631.1","0.00001258","0","1"]],"bids":[["104509.1","0","0","0"],["104507","0.00478255","0","1"],["104504.4","0","0","0"],["104502","0.13868439","0","1"],["104426.5","0","0","0"],["104414","0","0","0"],["104283.8","0.00001527","0","1"],["104283","0.00023593","0","1"]],"ts":"1747171668201","checksum":-2045724599,"seqId":54227198825,"prevSeqId":54227198794}]}
{"arg":{"channel":"books","instId":"BTC-USDT"},"action":"update","data":[{"asks":[["104526","0.0982","0","2"],["104530.6","0","0","0"],["104530.8","0.08951841","0","2"],["104531.4","0.00209352","0","1"],["104531.7","0.1006394","0","1"],["104533.2","0","0","0"],["104533.5","0.21023842","0","3"],["104535.6","0.50182053","0","4"],["104536.1","0","0","0"],["104536.3","0.15684371","0","1"],["104536.4","0.00002296","0","1"],["104536.7","0.1647906","0","1"],["104537","0.14717819","0","1"],["104538.5","0.00610176","0","5"],["104538.7","0","0","0"],["104539.5","0.00002661","0","2"],["104539.6","0.00478255","0","1"],["104539.7","0.17188608","0","2"],["104540.5","0","0","0"],["104540.7","0.22871782","0","1"],["104541.4","0.0001","0","1"],["104541.6","0","0","0"],["104541.7","0.26231323","0","1"],["104541.8","0.26669331","0","3"],["104545.7","0.04","0","1"],["104546","0.41285256","0","2"],["104552.1","0","0","0"],["104553.7","0.13870666","0","2"],["104588.2","0.00014513","0","1"]],"bids":[["104523.8","0.15685306","0","7"],["104513","0.09325872","0","1"],["104512.7","0","0","0"],["104512.2","0.1014754","0","1"],["104511.9","0","0","0"],["104511","0.44570021","0","2"],["104510.7","0","0","0"],["104509.8","0.18390184","0","2"],["104509.6","0","0","0"],["104509.5","0.16091254","0","1"],["104509.2","0.06982057","0","2"],["104509","0.64019007","0","2"],["104508.8","0.16861498","0","1"],["104508.6","0","0","0"],["104507.3","0.00478255","0","1"],["104507.2","0.16000904","0","2"],["104507","0","0","0"],["104506.9","0","0","0"],["104505.7","0.25835535","0","1"],["104505.5","0","0","0"],["104504.8","0.13868293","0","1"],["104504.7","0.15460063","0","1"],["104504.5","0","0","0"],["104502.2","0.26649483","0","1"],["104502","0","0","0"],["104501.9","0","0","0"],["104498.5","0.26777161","0","1"],["104498.2","0","0","0"],["104452.5","0.005","0","1"],["104440","0.00720843","0","4"],["104425.9","0.0001","0","1"]],"ts":"1747171668301","checksum":-324137753,"seqId":54227198924,"prevSeqId":54227198825}]}
{"arg":{"channel":"books","instId":"BTC-USDT"},"action":"update","data":[{"asks":[["104530.5","0","0","0"],["104538","0.05973587","0","1"],["104538.7","0.00478255","0","1"],["104539.6","0","0","0"],["104552.1","0.13868407","0","1"],["104553.7","0.00002373","0","1"],["104554","0.17838463","0","1"],["104555","0","0","0"],["104556","0.002","0","2"],["104557","0.00387","0","2"],["104578","0.01435078","0","2"],["104579","0.15999999","0","2"],["104580","0.25222717","0","9"],["104581","0.08506705","0","3"],["104588.2","0","0","0"]],"bids":[["104507.3","0","0","0"],["104506.1","0.00478255","0","1"],["104504.8","0.13868325","0","1"],["104482.4","0","0","0"],["104282.2","0.00001068","0","1"]],"ts":"1747171668401","checksum":-103545291,"seqId":54227198969,"prevSeqId":54227198924}]}
{"arg":{"channel":"books","instId":"BTC-USDT"},"action":"update","data":[{"asks":[["104535.6","0.50250574","0","4"],["104538.7","0","0","0"],["104539.6","0.00478255","0","1"],["104539.7","0.02367851","0","1"],["104539.8","0.15002148","0","1"],["104540.7","0","0","0"],["104540.8","0.23137222","0","1"],["104588.2","0.00014513","0","1"],["104630.8","0","0","0"],["104631.1","0","0","0"]],"bids":[["104523.8","0.16393306","0","8"],["104507.3","0.00478255","0","1"],["104506.1","0","0","0"],["104505.8","0.24346856","0","1"],["104505.7","0","0","0"],["104504.8","0.29188887","0","2"],["104504.7","0","0","0"],["104281.6","0.5999","0","1"]],"ts":"1747171668501","checksum":-780582049,"seqId":54227198995,"prevSeqId":54227198969}]}
{"arg":{"channel":"books","instId":"BTC-USDT"},"action":"update","data":[{"asks":[["104554.1","0.29514486","0","2"],["104578","0.20935078","0","5"],["104579","0.07999999","0","1"],["104580","0.17222718","0","8"],["104581","0.05006705","0","2"]],"bids":[],"ts":"1747171668601","checksum":-780582049,"seqId":54227199041,"prevSeqId":54227198995}]}
{"arg":{"channel":"books","instId":"BTC-USDT"},"action":"update","data":[{"asks":[["104536.2","0.02456655","0","1"],["104539.7","0","0","0"],["104578","0.01435078","0","2"],["104579","0.15999999","0","2"],["104580","0.25222717","0","9"],["104581","0.08506705","0","3"]],"bids":[["104504.8","0.15320562","0","1"],["104504.4","0.13868346","0","1"],["104373","0.00095644","0","1"],["104372.2","0","0","0"],["104281.6","0","0","0"]],"ts":"1747171668701","checksum":-780582049,"seqId":54227199110,"prevSeqId":54227199041}]}
{"arg":{"channel":"books","instId":"BTC-USDT"},"action":"update","data":[{"asks":[["104524","0.08419536","0","2"],["104530.3","0","0","0"],["104530.4","0.17728862","0","2"],["104530.7","0.00014294","0","1"],["104530.8","0.0000125","0","1"],["104530.9","0.09666752","0","1"],["104531.7","0","0","0"],["104531.8","0.10256804","0","2"],["104533.5","0.0239091","0","1"],["104533.6","0.17698623","0","3"],["104535.6","0.45218989","0","4"],["104536.3","0","0","0"],["104536.4","0.15782781","0","2"],["104536.7","0","0","0"],["104536.8","0.16199656","0","1"],["104537","0","0","0"],["104537.1","0.14428433","0","2"],["104539.6","0","0","0"],["104539.8","0","0","0"],["104539.9","0.16805255","0","2"],["104540.8","0","0","0"],["104540.9","0.24951333","0","1"],["104541.7","0","0","0"],["104541.8","0.24310613","0","3"],["104541.9","0.2717359","0","2"],["104546","0.17838463","0","1"],["104546.1","0.25112943","0","1"],["104552.1","0","0","0"],["104553.7","0.1387061","0","2"],["104569.3","0","0","0"],["104579","1.16","0","3"],["104580","0.15222717","0","7"],["104581","0.03506705","0","2"],["104582","0.1025","0","3"],["104583","0.0516","0","2"],["104599.1","0.13500338","0","1"],["104602.2","0.0565927","0","1"],["104609.4","4.45254228","0","6"],["104630.8","0.00001016","0","1"],["104631.1","0.00001258","0","1"],["104631.4","1.25507","0","1"],["104631.5","0.00023552","0","2"],["104631.6","0.00007871","0","4"]],"bids":[["104513.1","0.0875095","0","1"],["104513","0","0","0"],["104512.3","0.09190782","0","2"],["104512.2","0","0","0"],["104511.1","0.09685341","0","1"],["104511","0.34742422","0","1"],["104509.9","0.17134164","0","2"],["104509.8","0.09416","0","1"],["104509.6","0.15648399","0","1"],["104509.5","0","0","0"],["104509","0.46157006","0","1"],["104508.9","0.92900202","0","2"],["104508.8","0","0","0"],["104507.3","0.15250218","0","1"],["104507.2","0.00001501","0","1"],["104506.1","0.00478255","0","1"],["104505.9","0.24372971","0","1"],["104505.8","0","0","0"],["104504.9","0.2936388","0","2"],["104504.8","0","0","0"],["104504.4","0","0","0"],["104504.3","0.2163256","0","2"],["104502.3","0.2542128","0","1"],["104502.2","0","0","0"],["104498.6","0.25579778","0","1"],["104498.5","0","0","0"],["104476.7","0.10847046","0","1"],["104476.4","0","0","0"],["104447.2","0.46802562","0","1"],["104443.5","0.34742422","0","1"],["104281.6","0.5999","0","1"],["104281","0.00002601","0","1"]],"ts":"1747171668801","checksum":-1100159858,"seqId":54227199225,"prevSeqId":54227199110}]}
{"arg":{"channel":"books","instId":"BTC-USDT"},"action":"update","data":[{"asks":[["104530.3","0.00014294","0","1"],["104530.7","0","0","0"],["104536.2","0","0","0"],["104539.8","0.02367848","0","1"],["104572.6","1.46359214","0","1"],["104579","0.16","0","2"],["104580","0.25222717","0","9"],["104581","0.08506705","0","3"],["104582","0.0025","0","1"],["104583","0.0016","0","1"],["104605.6","2.585685","0","2"],["104631.6","0","0","0"]],"bids":[["104477.8","0.53975709","0","1"],["104477.7","1.43761209","0","1"],["104476.7","0","0","0"],["104447.2","1.14623283","0","2"],["104444.8","2.58149147","0","3"],["104281","0","0","0"]],"ts":"1747171668901","checksum":-1487139587,"seqId":54227199247,"prevSeqId":54227199225}]}
{"arg":{"channel":"books","instId":"BTC-USDT"},"action":"update","data":[{"asks":[["104539.8","0.18338189","0","2"],["104539.9","0.00478255","0","1"],["104540.8","0.2422304","0","1"],["104540.9","0","0","0"],["104609.4","0.01058144","0","5"],["104631.3","0.00009382","0","1"],["104631.5","0","0","0"]],"bids":[["104523.8","0.15685306","0","7"],["104521.1","0","0","0"],["104518.3","0.01027086","0","1"],["104505.9","0","0","0"],["104505.8","0.24282814","0","1"],["104504.9","0.13868237","0","1"],["104504.8","0.166555","0","1"],["104404","0.00001","0","1"],["104282.2","0","0","0"],["104281.6","0","0","0"]],"ts":"1747171669001","checksum":-1577160356,"seqId":54227199269,"prevSeqId":54227199247}]}
{"arg":{"channel":"books","instId":"BTC-USDT"},"action":"update","data":[{"asks":[["104553.7","0.13870648","0","2"],["104554","0.18038463","0","3"],["104555","0.001","0","1"],["104556","0","0","0"],["104557","0.00287","0","1"],["104578","0.34435078","0","8"],["104579","0.16499999","0","3"],["104580","0.00222718","0","4"],["104581","0.00006705","0","1"]],"bids":[["104504.9","0.13868282","0","1"],["104485.1","0.0095445","0","1"],["104482.8","0","0","0"]],"ts":"1747171669101","checksum":-1577160356,"seqId":54227199313,"prevSeqId":54227199269}]}
{"arg":{"channel":"books","instId":"BTC-USDT"},"action":"update","data":[{"asks":[["104552.2","0.42695845","0","3"],["104553.7","0.00002373","0","1"],["104588.2","0","0","0"],["104631.5","0.00023552","0","2"]],"bids":[],"ts":"1747171669201","checksum":-1577160356,"seqId":54227199327,"prevSeqId":54227199313}]}
{"arg":{"channel":"books","instId":"BTC-USDT"},"action":"update","data":[{"asks":[["104579.7","0.09568","0","2"],["104588.2","0.00014513","0","1"],["104631.5","0","0","0"]],"bids":[],"ts":"1747171669301","checksum":-1577160356,"seqId":54227199339,"prevSeqId":54227199327}]}
{"arg":{"channel":"books","instId":"BTC-USDT"},"action":"update","data":[{"asks":[["104572.5","0.47371936","0","1"],["104609.4","4.45254228","0","6"],["104631.4","0","0","0"]],"bids":[],"ts":"1747171669401","checksum":-1577160356,"seqId":54227199344,"prevSeqId":54227199339}]}
{"arg":{"channel":"books","instId":"BTC-USDT"},"action":"update","data":[{"asks":[["104539.8","0.02367848","0","1"],["104539.9","0.1644398","0","2"],["104540.8","0","0","0"],["104540.9","0.25100346","0","1"],["104552.2","0.2882755","0","2"],["104553.7","0.13870635","0","2"],["104588.2","0","0","0"],["104631.4","1.25507","0","1"]],"bids":[["104523.8","0.16212306","0","8"],["104505.9","0.23624103","0","1"],["104505.8","0","0","0"],["104505","0.13868262","0","1"],["104504.9","0.16191344","0","1"],["104504.8","0","0","0"],["104504.3","0.29999447","0","3"]],"ts":"1747171669501","checksum":-1711295156,"seqId":54227199374,"prevSeqId":54227199344}]}
{"arg":{"channel":"books","instId":"BTC-USDT"},"action":"update","data":[{"asks":[["104588.2","0.00014513","0","1"],["104631.3","0","0","0"]],"bids":[],"ts":"1747171669601","checksum":-1711295156,"seqId":54227199380,"prevSeqId":54227199374}]}
{"arg":{"channel":"books","instId":"BTC-USDT"},"action":"update","data":[{"asks":[["104530.4","0.1867259","0","2"],["104530.9","0","0","0"],["104531","0.09595223","0","1"],["104531.8","0.00045","0","1"],["104531.9","0.10184339","0","1"],["104533.6","0.00001161","0","1"],["104533.7","0.18534155","0","2"],["104535.6","0.45256477","0","4"],["104536.4","0.00002296","0","1"],["104536.5","0.1596547","0","1"],["104536.8","0","0","0"],["104536.9","0.16659703","0","1"],["104537.1","0.00093","0","1"],["104537.2","0.15833953","0","1"],["104539.8","0","0","0"],["104541.8","0.00481593","0","2"],["104541.9","0.26408845","0","2"],["104542","0.24775767","0","2"],["104545.5","0","0","0"],["104546.1","0","0","0"],["104546.2","0.50472834","0","3"],["104588.2","0","0","0"],["104609.4","4.53038112","0","6"]],"bids":[["104523.4","0.03829301","0","1"],["104518.1","0.028113","0","1"],["104517.8","0","0","0"],["104513.2","0.08620398","0","1"],["104513.1","0","0","0"],["104512.4","0.0932071","0","1"],["104512.3","0.00001","0","1"],["104511.2","0.09786661","0","1"],["104511.1","0","0","0"],["104510.5","0","0","0"],["104510","0.19356015","0","4"],["104509.9","0.08","0","1"],["104509.7","0.15583763","0","1"],["104509.6","0","0","0"],["104509","0.62931861","0","2"],["104508.9","0.77866876","0","1"],["104507.4","0.15527848","0","1"],["104507.3","0","0","0"],["104504.3","0.2163256","0","2"],["104502.4","0.27061311","0","1"],["104502.3","0","0","0"],["104498.7","0.25639249","0","1"],["104498.6","0","0","0"],["104496","0.02651631","0","1"],["104375.7","0.160731","0","1"],["104342.8","0","0","0"],["104283","0","0","0"]],"ts":"1747171669701","checksum":126242647,"seqId":54227199448,"prevSeqId":54227199380}]}
{"arg":{"channel":"books","instId":"BTC-USDT"},"action":"update","data":[{"asks":[["104536.7","0.02456645","0","1"],["104546.7","0.071755","0","1"],["104553.7","0.1387066","0","2"],["104578","0.17435078","0","4"],["104579","0.07999999","0","1"],["104580","0.17222718","0","8"],["104581","0.08506705","0","3"],["104588.2","0.00014513","0","1"],["104630.8","0","0","0"],["104631.1","0","0","0"],["104631.4","0","0","0"]],"bids":[["104373","0","0","0"],["104372.2","0.00095645","0","1"]],"ts":"1747171669801","checksum":126242647,"seqId":54227199496,"prevSeqId":54227199448}]}
{"arg":{"channel":"books","instId":"BTC-USDT"},"action":"update","data":[{"asks":[["104552.1","0.1386843","0","1"],["104553.7","0.00002373","0","1"],["104578","0.34435078","0","8"],["104579","0.16499999","0","3"],["104580","0.00222718","0","4"],["104581","0.00006705","0","1"],["104630.7","0","0","0"]],"bids":[["104505","0","0","0"],["104504.3","0.30491448","0","3"],["104504.1","0.1386843","0","1"]],"ts":"1747171669901","checksum":126242647,"seqId":54227199517,"prevSeqId":54227199496}]}
{"arg":{"channel":"books","instId":"BTC-USDT"},"action":"update","data":[{"asks":[["104546.5","0.00014513","0","1"],["104588.2","0","0","0"]],"bids":[["104523.8","0.15685306","0","7"],["104493.5","0","0","0"],["104452.2","0.00001479","0","1"]],"ts":"1747171670001","checksum":1923802638,"seqId":54227199542,"prevSeqId":54227199517}]}
{"arg":{"channel":"books","instId":"BTC-USDT"},"action":"update","data":[{"asks":[["104530.3","0","0","0"],["104539.8","0.00478255","0","1"],["104539.9","0.15965725","0","1"]],"bids":[["104507.5","0.00478255","0","1"],["104506.1","0","0","0"],["104504.4","0.13868318","0","1"],["104504.1","0","0","0"],["104487.3","0.0095443","0","1"],["104485.1","0","0","0"]],"ts":"1747171670101","checksum":1910204340,"seqId":54227199567,"prevSeqId":54227199542}]}
{"arg":{"channel":"books","instId":"BTC-USDT"},"action":"update","data":[{"asks":[["104552.1","0","0","0"],["104553.7","0.13870651","0","2"],["104630.7","0.00024099","0","2"]],"bids":[["104505","0.13868278","0","1"],["104504.4","0","0","0"],["104471.6","0.05997122","0","2"],["104410.1","0.03834587","0","1"],["104407.9","0","0","0"],["104407.4","0","0","0"],["104283","0.00023593","0","1"]],"ts":"1747171670201","checksum":1910204340,"seqId":54227199585,"prevSeqId":54227199567}]}
{"arg":{"channel":"books","instId":"BTC-USDT"},"action":"update","data":[{"asks":[["104553.7","0.13870641","0","2"]],"bids":[["104505","0.13868268","0","1"],["104423.6","1.61123876","0","2"],["104310.1","0.00097513","0","1"],["104308.8","0","0","0"]],"ts":"1747171670301","checksum":1910204340,"seqId":54227199603,"prevSeqId":54227199585}]}
{"arg":{"channel":"books","instId":"BTC-USDT"},"action":"update","data":[{"asks":[["104525.9","0","0","0"],["104552.1","0.13868315","0","1"],["104553.7","0.00002373","0","1"],["104599.1","0.24574088","0","2"]],"bids":[["104523.8","0.16068306","0","8"],["104505","0","0","0"],["104504.4","0.13868315","0","1"],["104423.7","0.51649139","0","2"]],"ts":"1747171670401","checksum":-1452502112,"seqId":54227199622,"prevSeqId":54227199603}]}
{"arg":{"channel":"books","instId":"BTC-USDT"},"action":"update","data":[{"asks":[["104539.8","0","0","0"],["104540.8","0.00478255","0","1"],["104552.1","0","0","0"],["104553.7","0.13870663","0","2"],["104630.8","0.00001016","0","1"]],"bids":[["104509.1","0.00478255","0","1"],["104507.5","0","0","0"],["104505","0.1386829","0","1"],["104504.4","0","0","0"],["104496","0","0","0"],["104354.9","0","0","0"],["104282.2","0.00001068","0","1"],["104281.6","0.5999","0","1"]],"ts":"1747171670501","checksum":-1452502112,"seqId":54227199639,"prevSeqId":54227199622}]}
{"arg":{"channel":"books","instId":"BTC-USDT"},"action":"update","data":[{"asks":[["104523.9","0.20569178","0","6"],["104525.9","0.05831752","0","1"],["104540.8","0","0","0"],["104541.7","0.00478255","0","1"],["104552.1","0.13868329","0","1"],["104553.7","0.00002373","0","1"],["104609.4","0.01058144","0","5"],["104612.7","4.53032519","0","2"],["104630.7","0","0","0"],["104630.8","0","0","0"]],"bids":[["104509.9","0.08478255","0","2"],["104509.1","0","0","0"],["104505","0","0","0"],["104504.4","0.13868329","0","1"],["104281","0.00002601","0","1"]],"ts":"1747171670601","checksum":-962463461,"seqId":54227199657,"prevSeqId":54227199639}]}
{"arg":{"channel":"books","instId":"BTC-USDT"},"action":"update","data":[{"asks":[["104552.1","0","0","0"],["104553.7","0.13870631","0","2"],["104630.7","0.00024099","0","2"]],"bids":[["104509.3","0.002871","0","1"],["104505","0.13868258","0","1"],["104504.4","0","0","0"],["104478","0.002","0","1"],["104421.5","0","0","0"]],"ts":"1747171670701","checksum":-962463461,"seqId":54227199666,"prevSeqId":54227199657}]}
{"arg":{"channel":"books","instId":"BTC-USDT"},"action":"update","data":[{"asks":[["104525.9","0","0","0"],["104534","0","0","0"],["104553.7","0.13870596","0","2"],["104630.8","0.00001016","0","1"],["104631.1","0.00001258","0","1"]],"bids":[["104509.9","0.08","0","1"],["104509.4","0.00478255","0","1"],["104505","0.13868223","0","1"],["104281","0","0","0"]],"ts":"1747171670801","checksum":-1274643747,"seqId":54227199735,"prevSeqId":54227199666}]}
{"arg":{"channel":"books","instId":"BTC-USDT"},"action":"update","data":[{"asks":[],"bids":[["104523.8","0.15685306","0","7"]],"ts":"1747171670901","checksum":-1425899946,"seqId":54227199738,"prevSeqId":54227199735}]}
{"arg":{"channel":"books","instId":"BTC-USDT"},"action":"update","data":[{"asks":[["104533.6","0.19244133","0","2"],["104552.1","0.13868404","0","1"],["104553.7","0.00002373","0","1"],["104631.1","0","0","0"]],"bids":[["104523.8","0.03735306","0","6"],["104505","0","0","0"],["104504.1","0.13868404","0","1"],["104421.1","0.01149193","0","1"],["104281.6","0","0","0"]],"ts":"1747171671001","checksum":1297425897,"seqId":54227199753,"prevSeqId":54227199738}]}
{"arg":{"channel":"books","instId":"BTC-USDT"},"action":"update","data":[{"asks":[["104530.4","0.1722198","0","2"],["104530.9","0.00014294","0","1"],["104531","0.0937863","0","1"],["104531.9","0.08923442","0","1"],["104533.7","0.18778817","0","2"],["104535.6","0.40887116","0","4"],["104536.5","0.16603284","0","1"],["104536.9","0.16793922","0","1"],["104537.2","0.15992388","0","1"],["104539.9","0.15367128","0","1"],["104540.9","0.26104669","0","1"],["104541.9","0.24233845","0","2"],["104542","0.24150028","0","2"],["104546.2","0.51042329","0","3"],["104630.8","0","0","0"]],"bids":[["104523.8","0.15685306","0","7"],["104513.2","0.09422395","0","1"],["104512.4","0.08977977","0","1"],["104511.2","0.08784874","0","1"],["104510","0.18790734","0","4"],["104509.7","0.14891525","0","1"],["104509.4","0","0","0"],["104509.3","0.00478255","0","1"],["104509","0.61252343","0","2"],["104507.4","0.15855177","0","1"],["104505.9","0.24677454","0","1"],["104504.9","0.16720755","0","1"],["104502.4","0.26804987","0","1"],["104498.7","0.23550065","0","1"],["104494.1","0.002871","0","1"],["104489.5","0.00954409","0","1"],["104487.3","0","0","0"],["104379.6","0.07520425","0","1"]],"ts":"1747171671101","checksum":-1511378804,"seqId":54227199825,"prevSeqId":54227199753}]}
{"arg":{"channel":"books","instId":"BTC-USDT"},"action":"update","data":[{"asks":[["104526","0.1032","0","3"],["104530.4","0.05413727","0","1"],["104530.9","0.08936407","0","1"],["104531","0","0","0"],["104531.3","0.00014294","0","1"],["104531.8","0.10122314","0","2"],["104531.9","0","0","0"],["104533.6","0.37073475","0","4"],["104533.7","0","0","0"],["104534.6","0","0","0"],["104535.6","0.2762424","0","3"],["104536.4","0.15462913","0","2"],["104536.5","0","0","0"],["104536.8","0.16262718","0","1"],["104536.9","0","0","0"],["104537.1","0.16115807","0","2"],["104537.2","0","0","0"],["104538.5","0.01110176","0","6"],["104541.8","0.24287525","0","3"],["104541.9","0.24171513","0","2"],["104542","0.00002848","0","1"],["104546.1","0.24166501","0","1"],["104546.2","0.25253914","0","2"],["104630.8","0.00001016","0","1"],["104631.1","0.00001258","0","1"],["104631.4","1.25507","0","1"],["104631.5","0.00023552","0","2"]],"bids":[["104523.4","0","0","0"],["104513.2","0","0","0"],["104513.1","0.09020928","0","1"],["104512.4","0","0","0"],["104512.3","0.09382785","0","2"],["104511.2","0","0","0"],["104511.1","0.09050789","0","1"],["104510","0.09349006","0","3"],["104509.9","0.17362798","0","2"],["104509.7","0","0","0"],["104509.6","0.15933033","0","1"],["104509","0.46157006","0","1"],["104508.9","0.93200974","0","2"],["104507.4","0","0","0"],["104507.3","0.15745176","0","1"],["104502.4","0","0","0"],["104502.3","0.23780845","0","1"],["104498.7","0","0","0"],["104498.6","0.25612887","0","1"],["104476.5","0.00501","0","2"],["104471.2","0","0","0"],["104464","0.005","0","1"],["104462.8","0.02691177","0","1"],["104458.7","0","0","0"],["104281.6","0.5999","0","1"],["104281","0.00002601","0","1"],["104280","0.0023428","0","7"]],"ts":"1747171671201","checksum":196260248,"seqId":54227199881,"prevSeqId":54227199825}]}
{"arg":{"channel":"books","instId":"BTC-USDT"},"action":"update","data":[{"asks":[["104530.3","0.00014294","0","1"],["104530.4","0.17804236","0","2"],["104530.9","0","0","0"],["104531.3","0","0","0"],["104531.8","0.00045","0","1"],["104533.6","0.2793606","0","3"],["104535.6","0.45341796","0","4"],["104536.4","0.00002296","0","1"],["104536.8","0","0","0"],["104541.8","0.00481593","0","2"],["104541.9","0.00003805","0","1"],["104546.1","0","0","0"],["104552.1","0","0","0"],["104553.7","0.13870655","0","2"],["104631.6","0.00007871","0","4"],["104631.8","0.00008114","0","1"],["104632","0.01059591","0","1"],["104632.1","0.01059591","0","1"]],"bids":[["104523.2","0.03829301","0","1"],["104512.3","0.00001","0","1"],["104511.1","0","0","0"],["104509.9","0.08","0","1"],["104508.9","0.77866876","0","1"],["104507.3","0","0","0"],["104505","0.13868282","0","1"],["104504.1","0","0","0"],["104502.3","0","0","0"],["104498.6","0","0","0"],["104278.6","0.00010262","0","1"],["104277.6","0.77868377","0","2"],["104276.6","0.00118321","0","1"]],"ts":"1747171671301","checksum":1893165535,"seqId":54227199912,"prevSeqId":54227199881}]}
{"arg":{"channel":"books","instId":"BTC-USDT"},"action":"update","data":[{"asks":[["104530.4","0.17223064","0","2"],["104530.7","0.09197034","0","1"],["104531.6","0.08920164","0","2"],["104533.4","0.18654371","0","2"],["104533.6","0.19244133","0","2"],["104535.6","0.52727889","0","4"],["104536.2","0.15456156","0","1"],["104536.6","0.15907768","0","1"],["104536.9","0.15641862","0","1"],["104537.1","0.00093","0","1"],["104539.7","0.15769576","0","1"],["104539.9","0","0","0"],["104540.6","0.25246328","0","1"],["104540.9","0","0","0"],["104541.6","0.2580539","0","1"],["104541.7","0.25403288","0","2"],["104545.9","0.23590637","0","1"],["104631.1","0","0","0"],["104631.4","0","0","0"],["104631.5","0","0","0"],["104631.6","0","0","0"],["104631.8","0","0","0"],["104632","0","0","0"],["104632.1","0","0","0"]],"bids":[["104523.8","0.03995306","0","7"],["104513.1","0","0","0"],["104512.9","0.09321205","0","1"],["104512.1","0.28212672","0","2"],["104510.9","0.09347145","0","1"],["104509.7","0.0914866","0","1"],["104509.6","0","0","0"],["104509.4","0.16078258","0","1"],["104508.7","0.15667315","0","1"],["104507.1","0.1607004","0","1"],["104505.9","0","0","0"],["104505.6","0.28964566","0","3"],["104504.9","0","0","0"],["104504.7","0.14763666","0","1"],["104504.3","0.2163256","0","2"],["104502.1","0.26329233","0","1"],["104498.4","0.25607465","0","1"],["104281","0","0","0"],["104280","0","0","0"],["104278.6","0","0","0"],["104277.6","0","0","0"],["104276.6","0","0","0"]],"ts":"1747171671401","checksum":-813867801,"seqId":54227200000,"prevSeqId":54227199912}]}
{"arg":{"channel":"books","instId":"BTC-USDT"},"action":"update","data":[{"asks":[["104552.1","0.13868437","0","1"],["104553.7","0.00002373","0","1"],["104630.8","0","0","0"]],"bids":[["104505","0","0","0"],["104504.3","0.30271827","0","3"],["104502.2","0.13868437","0","1"]],"ts":"1747171671501","checksum":-813867801,"seqId":54227200005,"prevSeqId":54227200000}]}
{"arg":{"channel":"books","instId":"BTC-USDT"},"action":"update","data":[{"asks":[["104530.3","0","0","0"],["104530.4","0.17352461","0","2"],["104530.7","0","0","0"],["104530.9","0.00014294","0","1"],["104531","0.09895483","0","1"],["104531.6","0.00001","0","1"],["104531.9","0.09154579","0","1"],["104533.4","0","0","0"],["104533.7","0.18137538","0","2"],["104535.6","0.45978405","0","4"],["104536.2","0","0","0"],["104536.5","0.17099413","0","1"],["104536.6","0","0","0"],["104536.9","0.16906669","0","1"],["104537.2","0.16159011","0","1"],["104539.7","0","0","0"],["104539.9","0.14576527","0","1"],["104540.6","0","0","0"],["104540.9","0.25934171","0","1"],["104541.6","0","0","0"],["104541.7","0.00478255","0","1"],["104541.9","0.25576841","0","2"],["104542","0.24633324","0","2"],["104545.9","0","0","0"],["104546.2","0.49941836","0","3"],["104572.5","0","0","0"],["104572.6","0","0","0"],["104605.6","0.01052531","0","1"],["104609.4","4.55750741","0","6"],["104612.7","0.01052551","0","1"],["104630.8","0.00001016","0","1"],["104631.1","0.00001258","0","1"],["104631.4","1.25507","0","1"]],"bids":[["104523.8","0.15945306","0","8"],["104513.2","0.08736869","0","1"],["104512.9","0","0","0"],["104512.4","0.09548652","0","1"],["104512.1","0.19242972","0","1"],["104511.2","0.09331294","0","1"],["104510.9","0","0","0"],["104510","0.18885557","0","4"],["104509.7","0.16168958","0","1"],["104509.4","0","0","0"],["104509","0.62445438","0","2"],["104508.7","0","0","0"],["104507.4","0.15792942","0","1"],["104507.1","0","0","0"],["104505.9","0.24426574","0","1"],["104505.6","0.04233353","0","2"],["104504.9","0.15807267","0","1"],["104504.7","0","0","0"],["104502.4","0.25847952","0","1"],["104502.1","0","0","0"],["104498.7","0.23873868","0","1"],["104498.4","0","0","0"],["104477.8","0.10997346","0","1"],["104477.7","0","0","0"],["104447.2","0.46802562","0","1"],["104444.8","0.00002501","0","2"],["104373","0.00095645","0","1"],["104372.2","0","0","0"],["104281","0.00002601","0","1"]],"ts":"1747171671601","checksum":-1499251129,"seqId":54227200074,"prevSeqId":54227200005}]}
{"arg":{"channel":"books","instId":"BTC-USDT"},"action":"update","data":[{"asks":[["104530.3","0.00014294","0","1"],["104530.9","0","0","0"],["104539.9","0.15054782","0","2"],["104541.7","0","0","0"],["104569.8","1.42069423","0","1"],["104602.8","2.7285434","0","2"],["104609.4","0.01058144","0","5"],["104612.7","4.55745148","0","2"]],"bids":[["104509.3","0","0","0"],["104508.1","0.00478255","0","1"],["104477.7","1.4261095","0","1"],["104457.1","0.0005744","0","1"],["104447.2","1.13989321","0","2"],["104444.8","2.56035943","0","3"],["104281.6","0","0","0"],["104281","0","0","0"]],"ts":"1747171671701","checksum":673125620,"seqId":54227200094,"prevSeqId":54227200074}]}
{"arg":{"channel":"books","instId":"BTC-USDT"},"action":"update","data":[{"asks":[["104530.4","0.22745167","0","2"],["104530.7","0.09355273","0","1"],["104531","0","0","0"],["104531.6","0.09745619","0","2"],["104531.9","0","0","0"],["104533.4","0.18222738","0","2"],["104533.7","0","0","0"],["104535.6","0.52788522","0","4"],["104536.2","0.16369819","0","1"],["104536.5","0","0","0"],["104536.6","0.15577053","0","1"],["104536.9","0.15268425","0","1"],["104537.2","0","0","0"],["104539.7","0.16519557","0","1"],["104539.8","0.00478255","0","1"],["104539.9","0","0","0"],["104540.6","0.24152693","0","1"],["104540.9","0","0","0"],["104541.6","0.26878836","0","1"],["104541.7","0.26494517","0","1"],["104541.9","0.00003805","0","1"],["104542","0.00002848","0","1"],["104545.9","0.25487579","0","1"],["104546.2","0.25253914","0","2"],["104630.8","0","0","0"],["104631.1","0","0","0"],["104631.4","0","0","0"]],"bids":[["104523.8","0.03995306","0","7"],["104513.2","0","0","0"],["104512.9","0.08812601","0","1"],["104512.4","0","0","0"],["104512.1","0.28158604","0","2"],["104511.2","0","0","0"],["104510.9","0.09501194","0","1"],["104510","0.09349006","0","3"],["104509.7","0.10024636","0","1"],["104509.4","0.16182419","0","1"],["104509","0.63692712","0","2"],["104508.7","0.15042396","0","1"],["104508.1","0","0","0"],["104507.5","0.00478255","0","1"],["104507.4","0","0","0"],["104507.1","0.16678079","0","1"],["104505.9","0","0","0"],["104505.6","0.28997615","0","3"],["104504.9","0","0","0"],["104504.7","0.28566182","0","2"],["104502.4","0","0","0"],["104502.2","0","0","0"],["104502.1","0.25690595","0","1"],["104498.7","0","0","0"],["104498.4","0.26686369","0","1"],["104281.6","0.5999","0","1"]],"ts":"1747171671801","checksum":-484453087,"seqId":54227200207,"prevSeqId":54227200094}]}
{"arg":{"channel":"books","instId":"BTC-USDT"},"action":"update","data":[{"asks":[["104539.6","0.16529796","0","1"],["104539.7","0","0","0"]],"bids":[["104523.8","0.03735306","0","6"],["104504.7","0.13868329","0","1"],["104504.6","0.15717395","0","1"],["104431.9","0","0","0"],["104421.1","0","0","0"],["104328.1","0","0","0"],["104284.8","0","0","0"],["104281","0.00002601","0","1"],["104280","0.0023428","0","7"],["104278.6","0.00010262","0","1"]],"ts":"1747171671901","checksum":1595691243,"seqId":54227200223,"prevSeqId":54227200207}]}
{"arg":{"channel":"books","instId":"BTC-USDT"},"action":"update","data":[{"asks":[],"bids":[["104432.1","0.00173788","0","1"],["104421.6","0.01149187","0","1"],["104335.4","0.00095844","0","1"],["104281","0","0","0"],["104280","0","0","0"],["104278.6","0","0","0"]],"ts":"1747171672001","checksum":1595691243,"seqId":54227200228,"prevSeqId":54227200223}]}
{"arg":{"channel":"books","instId":"BTC-USDT"},"action":"update","data":[{"asks":[["104530.4","0.22954908","0","2"],["104530.7","0","0","0"],["104531","0.09944665","0","1"],["104531.6","0.00001","0","1"],["104531.9","0.098153","0","1"],["104533.4","0","0","0"],["104533.6","0.2779484","0","3"],["104533.7","0.09725387","0","1"],["104535.6","0.45572145","0","4"],["104536.2","0","0","0"],["104536.5","0.1513318","0","1"],["104536.6","0","0","0"],["104536.9","0.16170969","0","1"],["104537.1","0.15952287","0","2"],["104539.6","0","0","0"],["104539.9","0.1574573","0","1"],["104540.6","0","0","0"],["104540.9","0.2560542","0","1"],["104541.6","0","0","0"],["104541.7","0","0","0"],["104541.9","0.27055504","0","2"],["104542","0.24514226","0","2"],["104545.9","0","0","0"],["104546.2","0.50258783","0","3"],["104609.4","4.63630723","0","6"],["104612.7","0.01052551","0","1"],["104630.8","0.00001016","0","1"],["104631.1","0.00001258","0","1"],["104631.4","1.25507","0","1"]],"bids":[["104523.8","0.15685306","0","7"],["104513.1","0.09653172","0","1"],["104512.9","0","0","0"],["104512.4","0.09524046","0","1"],["104512.1","0.19242972","0","1"],["104511.2","0.08987514","0","1"],["104510.9","0","0","0"],["104510","0.19453308","0","4"],["104509.7","0","0","0"],["104509.6","0.15676813","0","1"],["104509.4","0","0","0"],["104509","0.62208015","0","2"],["104508.7","0","0","0"],["104507.4","0.15747148","0","1"],["104507.1","0","0","0"],["104505.9","0.2325622","0","1"],["104505.6","0.04233353","0","2"],["104504.9","0.16547443","0","1"],["104504.7","0","0","0"],["104504.6","0","0","0"],["104504.1","0.13868409","0","1"],["104502.4","0.26540032","0","1"],["104502.1","0","0","0"],["104498.7","0.2520101","0","1"],["104498.4","0","0","0"],["104491.7","0.00954389","0","1"],["104489.5","0","0","0"],["104480","0.4854533","0","4"],["104479","0","0","0"],["104433","0.47439916","0","1"],["104432","0","0","0"],["104310.1","0","0","0"],["104308.8","0.00097502","0","1"],["104288.5","7.90409368","0","1"]],"ts":"1747171672101","checksum":926952877,"seqId":54227200314,"prevSeqId":54227200228}]}
{"arg":{"channel":"books","instId":"BTC-USDT"},"action":"update","data":[{"asks":[["104525.9","0.0598604","0","1"],["104531.8","0.09499253","0","2"],["104531.9","0","0","0"],["104533.6","0.36950893","0","4"],["104533.7","0","0","0"],["104536.8","0.16506059","0","1"],["104536.9","0","0","0"],["104541.8","0.26340066","0","3"],["104541.9","0.00003805","0","1"],["104546.1","0.24192253","0","1"],["104546.2","0.25253914","0","2"],["104617.7","0.01186911","0","2"],["104628.3","0.0026904","0","1"],["104631.4","0","0","0"]],"bids":[["104512.4","0","0","0"],["104512.3","0.09104514","0","2"],["104511.2","0","0","0"],["104511.1","0.09838873","0","1"],["104508.1","0.00478255","0","1"],["104507.5","0","0","0"],["104507.4","0","0","0"],["104507.3","0.15685334","0","1"],["104504.2","0.13868394","0","1"],["104504.1","0","0","0"],["104502.4","0","0","0"],["104502.3","0.25273647","0","1"],["104498.7","0","0","0"],["104498.6","0.2470498","0","1"],["104433.1","0.00063869","0","1"],["104432.7","0","0","0"],["104409.1","0.01188434","0","3"],["104398.6","0.01328707","0","2"],["104281","0.00002601","0","1"]],"ts":"1747171672201","checksum":1261889885,"seqId":54227200349,"prevSeqId":54227200314}]}
{"arg":{"channel":"books","instId":"BTC-USDT"},"action":"update","data":[{"asks":[["104530.4","0.22505258","0","2"],["104530.7","0.09037127","0","1"],["104531","0","0","0"],["104531.6","0.09364428","0","2"],["104531.8","0.00045","0","1"],["104533.4","0.18136673","0","2"],["104533.6","0.19244133","0","2"],["104535.6","0.52675364","0","4"],["104536.2","0.16512422","0","1"],["104536.5","0","0","0"],["104536.6","0.14929331","0","1"],["104536.8","0","0","0"],["104536.9","0.1602397","0","1"],["104537.1","0.00093","0","1"],["104539.5","0.00480916","0","3"],["104539.6","0.15703019","0","1"],["104539.8","0","0","0"],["104539.9","0","0","0"],["104540.6","0.23417818","0","1"],["104540.9","0","0","0"],["104541.6","0.26059301","0","1"],["104541.7","0.25279933","0","1"],["104541.8","0.00481593","0","2"],["104542","0.00002848","0","1"],["104545.9","0.26410668","0","1"],["104546.1","0","0","0"],["104630.7","0","0","0"],["104630.8","0","0","0"],["104631.1","0","0","0"]],"bids":[["104523.8","0.03735306","0","6"],["104513.1","0","0","0"],["104512.9","0.09009932","0","1"],["104512.3","0.00001","0","1"],["104512.1","0.29072178","0","2"],["104511.1","0","0","0"],["104510.9","0.08758686","0","1"],["104510","0.09349006","0","3"],["104509.7","0.10050351","0","1"],["104509.6","0","0","0"],["104509.4","0.14823935","0","1"],["104509","0.46157006","0","1"],["104508.7","0.15639825","0","1"],["104508.1","0","0","0"],["104507.3","0","0","0"],["104507.2","0.00479756","0","2"],["104507.1","0.14929681","0","1"],["104505.9","0","0","0"],["104505.6","0.28233221","0","3"],["104504.9","0","0","0"],["104504.6","0.15211688","0","1"],["104502.3","0","0","0"],["104502.1","0.23941911","0","1"],["104498.6","0","0","0"],["104498.4","0.23483344","0","1"]],"ts":"1747171672301","checksum":-1657657691,"seqId":54227200418,"prevSeqId":54227200349}]}
{"arg":{"channel":"books","instId":"BTC-USDT"},"action":"update","data":[{"asks":[["104539.5","0.00002661","0","2"],["104539.9","0.00478255","0","1"],["104575.5","0.03439274","0","1"],["104609.4","0.01058144","0","5"],["104609.5","4.62452267","0","1"],["104630.1","0","0","0"],["104630.2","0","0","0"],["104630.4","0","0","0"]],"bids":[["104523.8","0.03912306","0","7"],["104508.1","0.00478255","0","1"],["104507.2","0.00001501","0","1"],["104504.2","0","0","0"],["104504.1","0.13868421","0","1"],["104471.6","0.05996122","0","1"],["104281","0","0","0"]],"ts":"1747171672401","checksum":-1846630897,"seqId":54227200442,"prevSeqId":54227200418}]}
{"arg":{"channel":"books","instId":"BTC-USDT"},"action":"update","data":[{"asks":[],"bids":[["104504.1","0","0","0"],["104502.2","0.13868516","0","1"]],"ts":"1747171672501","checksum":-1846630897,"seqId":54227200444,"prevSeqId":54227200442}]}
{"arg":{"channel":"books","instId":"BTC-USDT"},"action":"update","data":[{"asks":[["104533.5","0","0","0"],["104538.4","0.07778843","0","4"],["104539.9","0","0","0"],["104540.3","0.07869808","0","2"],["104552.1","0.13868579","0","1"],["104630.1","0.5","0","1"],["104630.2","0.0004067","0","2"]],"bids":[["104508.1","0","0","0"],["104506.1","0.00478255","0","1"],["104502.2","0.13868579","0","1"]],"ts":"1747171672601","checksum":-1846630897,"seqId":54227200468,"prevSeqId":54227200444}]}
{"arg":{"channel":"books","instId":"BTC-USDT"},"action":"update","data":[{"asks":[["104538.4","0.07300588","0","3"],["104541.5","0.00478255","0","1"],["104554","0.17838463","0","1"],["104555","0.002","0","2"],["104556","0.001","0","1"],["104578","0.01435078","0","2"],["104579","0.32999999","0","6"],["104580","0.16722717","0","7"],["104630.1","0","0","0"],["104630.2","0","0","0"]],"bids":[["104523.8","0.15862306","0","8"],["104509.1","0.00478255","0","1"],["104506.1","0","0","0"],["104502.2","0.13868523","0","1"]],"ts":"1747171672701","checksum":-907219139,"seqId":54227200494,"prevSeqId":54227200468}]}
{"arg":{"channel":"books","instId":"BTC-USDT"},"action":"update","data":[{"asks":[["104530.4","0.22228554","0","2"],["104530.7","0","0","0"],["104531","0.09762328","0","1"],["104531.6","0.00001","0","1"],["104531.8","0.09536509","0","2"],["104533.2","0.02390983","0","1"],["104533.4","0","0","0"],["104533.6","0.37996087","0","4"],["104535.6","0.46848174","0","4"],["104536.2","0","0","0"],["104536.5","0.17036785","0","1"],["104536.6","0","0","0"],["104536.8","0.14979257","0","1"],["104536.9","0","0","0"],["104537.1","0.15701177","0","2"],["104539.6","0","0","0"],["104539.9","0.16430157","0","1"],["104540.3","0.04283333","0","1"],["104540.6","0","0","0"],["104540.9","0.25992882","0","1"],["104541.6","0","0","0"],["104541.7","0","0","0"],["104541.8","0.27367798","0","3"],["104542","0.25256996","0","2"],["104545.9","0","0","0"],["104546.1","0.24091569","0","1"],["104555","0","0","0"],["104556","0.002","0","2"],["104557","0.00387","0","2"],["104579","0.15999999","0","2"],["104580","0.25222717","0","9"],["104581","0.08506705","0","3"],["104630.1","0.5","0","1"],["104630.2","0.0004067","0","2"],["104630.4","0.00001585","0","1"],["104630.7","0.00024099","0","2"]],"bids":[["104513.1","0.0854988","0","1"],["104512.9","0","0","0"],["104512.3","0.09668699","0","2"],["104512.1","0.19242972","0","1"],["104511.1","0.09161011","0","1"],["104510.9","0","0","0"],["104510","0.18310771","0","4"],["104509.7","0","0","0"],["104509.6","0.14333248","0","1"],["104509.4","0","0","0"],["104509","0.62461722","0","2"],["104508.7","0","0","0"],["104507.3","0.15625828","0","1"],["104507.1","0","0","0"],["104505.9","0.23117656","0","1"],["104505.6","0.04233353","0","2"],["104504.9","0.15715912","0","1"],["104504.6","0","0","0"],["104502.3","0.2568613","0","1"],["104502.1","0","0","0"],["104498.6","0.25674663","0","1"],["104498.4","0","0","0"],["104281","0.00002601","0","1"]],"ts":"1747171672801","checksum":-1709835967,"seqId":54227200592,"prevSeqId":54227200494}]}
{"arg":{"channel":"books","instId":"BTC-USDT"},"action":"update","data":[{"asks":[["104530.4","0.21923177","0","2"],["104530.7","0.09148225","0","1"],["104531","0","0","0"],["104531.6","0.09034199","0","2"],["104531.8","0.00045","0","1"],["104533.2","0","0","0"],["104533.4","0.18806441","0","2"],["104533.6","0.19244133","0","2"],["104535.6","0.52779846","0","4"],["104536.2","0.15185525","0","1"],["104536.5","0","0","0"],["104536.6","0.16979481","0","1"],["104536.8","0","0","0"],["104536.9","0.14245438","0","1"],["104537.1","0.00093","0","1"],["104539.6","0.14808263","0","1"],["104539.9","0","0","0"],["104540.2","0.00478255","0","1"],["104540.6","0.25716126","0","1"],["104540.9","0","0","0"],["104541.5","0","0","0"],["104541.6","0.25660192","0","1"],["104541.7","0.2632298","0","1"],["104541.8","0.00481593","0","2"],["104542","0.00002848","0","1"],["104545.9","0.26102345","0","1"],["104546.1","0","0","0"],["104555","0.002","0","2"],["104556","0.001","0","1"],["104557","0.00287","0","1"],["104576","1.00177128","0","3"],["104579","0.32999999","0","6"],["104580","0.16722717","0","7"],["104581","0.00006705","0","1"],["104609.5","0","0","0"],["104612.7","4.63504818","0","2"],["104630.2","0","0","0"],["104630.4","0","0","0"],["104630.7","0","0","0"]],"bids":[["104523.8","0.03735306","0","6"],["104513.1","0","0","0"],["104512.9","0.09236793","0","1"],["104512.3","0.00001","0","1"],["104512.1","0.28508622","0","2"],["104511.1","0","0","0"],["104510.9","0.09697408","0","1"],["104510","0.09349006","0","3"],["104509.7","0.09625444","0","1"],["104509.6","0","0","0"],["104509.4","0.14915406","0","1"],["104509.1","0","0","0"],["104509","0.46157006","0","1"],["104508.7","0.16310911","0","1"],["104508.6","0.00478255","0","1"],["104507.3","0","0","0"],["104507.1","0.15324442","0","1"],["104505.9","0","0","0"],["104505.6","0.29562329","0","3"],["104504.9","0","0","0"],["104504.6","0.16457668","0","1"],["104502.3","0","0","0"],["104502.1","0.26259642","0","1"],["104498.6","0","0","0"],["104498.4","0.25112099","0","1"],["104281","0","0","0"]],"ts":"1747171672901","checksum":281594304,"seqId":54227200695,"prevSeqId":54227200592}]}
{"arg":{"channel":"books","instId":"BTC-USDT"},"action":"update","data":[{"asks":[["104540.2","0","0","0"],["104541.5","0.00478255","0","1"],["104576","0.00177128","0","2"]],"bids":[["104509.1","0.00478255","0","1"],["104508.6","0","0","0"]],"ts":"1747171673001","checksum":281594304,"seqId":54227200702,"prevSeqId":54227200695}]}
{"arg":{"channel":"books","instId":"BTC-USDT"},"action":"update","data":[{"asks":[],"bids":[["104509","0.6365519","0","2"],["104502.2","0.13868457","0","1"],["104493.8","0.0095437","0","1"],["104491.7","0","0","0"]],"ts":"1747171673101","checksum":281594304,"seqId":54227200712,"prevSeqId":54227200702}]}
{"arg":{"channel":"books","instId":"BTC-USDT"},"action":"update","data":[{"asks":[["104552.1","0","0","0"],["104553.7","0.1387066","0","2"],["104554","0.18038463","0","3"],["104555","0.001","0","1"],["104556","0","0","0"],["104578","0.34435078","0","8"],["104579","0.16499999","0","3"],["104580","0.00222718","0","4"],["104630.2","0.0004067","0","2"],["104630.4","0.00001585","0","1"]],"bids":[["104504.7","0.13868287","0","1"],["104502.2","0","0","0"],["104425.4","0.00009618","0","1"],["104425","0","0","0"]],"ts":"1747171673201","checksum":281594304,"seqId":54227200739,"prevSeqId":54227200712}]}
{"arg":{"channel":"books","instId":"BTC-USDT"},"action":"update","data":[{"asks":[["104540.2","0.03586475","0","1"],["104553.7","0.13870655","0","2"],["104630.4","0","0","0"]],"bids":[["104523.8","0.03844306","0","7"],["104477.8","0.52405963","0","2"]],"ts":"1747171673401","checksum":-722609291,"seqId":54227200746,"prevSeqId":54227200739}]}
{"arg":{"channel":"books","instId":"BTC-USDT"},"action":"update","data":[{"asks":[["104530.4","0.22090156","0","2"],["104530.7","0","0","0"],["104531","0.09659148","0","1"],["104531.6","0.00001","0","1"],["104531.8","0.09920061","0","2"],["104533.4","0","0","0"],["104533.6","0.37254388","0","4"],["104535.6","0.46797927","0","4"],["104536.2","0","0","0"],["104536.5","0.15552564","0","1"],["104536.6","0","0","0"],["104536.8","0.16217354","0","1"],["104536.9","0","0","0"],["104537.1","0.15722528","0","2"],["104539.6","0","0","0"],["104539.9","0.16487437","0","1"],["104540.6","0","0","0"],["104540.9","0.2322663","0","1"],["104541.6","0","0","0"],["104541.7","0","0","0"],["104541.8","0.274395","0","3"],["104542","0.25801602","0","2"],["104545.9","0","0","0"],["104546.1","0.24697544","0","1"],["104599.1","1.00744171","0","1"],["104630.4","0.00001585","0","1"],["104630.7","0.00024099","0","2"],["104630.8","0.00001016","0","1"],["104631.1","0.00001258","0","1"]],"bids":[["104523.8","0.15794306","0","8"],["104513.1","0.09565566","0","1"],["104512.9","0","0","0"],["104512.3","0.09337101","0","2"],["104512.1","0.19242972","0","1"],["104511.1","0.08806332","0","1"],["104510.9","0","0","0"],["104510","0.19480201","0","4"],["104509.7","0","0","0"],["104509.6","0.16260093","0","1"],["104509.4","0","0","0"],["104509","0.61805129","0","2"],["104508.7","0","0","0"],["104507.3","0.16062989","0","1"],["104507.1","0","0","0"],["104505.9","0.25395172","0","1"],["104505.6","0.04233353","0","2"],["104504.9","0.15330985","0","1"],["104504.6","0","0","0"],["104504.3","0.2163256","0","2"],["104502.3","0.25698988","0","1"],["104502.1","0","0","0"],["104498.6","0.26406667","0","1"],["104498.4","0","0","0"],["104281","0.00002601","0","1"]],"ts":"1747171673501","checksum":-359964646,"seqId":54227200802,"prevSeqId":54227200746}]}
{"arg":{"channel":"books","instId":"BTC-USDT"},"action":"update","data":[{"asks":[["104552.1","0.13868325","0","1"],["104553.7","0.00002373","0","1"],["104631.1","0","0","0"]],"bids":[["104504.7","0","0","0"],["104504.4","0.13868325","0","1"]],"ts":"1747171673701","checksum":-359964646,"seqId":54227200811,"prevSeqId":54227200802}]}
{"arg":{"channel":"books","instId":"BTC-USDT"},"action":"update","data":[{"asks":[["104540.2","0","0","0"],["104631","0.00009112","0","1"]],"bids":[],"ts":"1747171673801","checksum":-359964646,"seqId":54227200848,"prevSeqId":54227200811}]}
{"arg":{"channel":"books","instId":"BTC-USDT"},"action":"update","data":[{"asks":[["104531","0","0","0"],["104531.8","0.00045","0","1"],["104533.6","0.19244133","0","2"],["104536.5","0","0","0"],["104536.8","0","0","0"],["104537.1","0.00093","0","1"],["104538.5","0.01588431","0","7"],["104539.9","0","0","0"],["104540.9","0","0","0"],["104541.5","0","0","0"],["104541.8","0.00481593","0","2"],["104542","0.00002848","0","1"],["104546.1","0","0","0"],["104631","0","0","0"],["104631.1","0.00001258","0","1"],["104631.4","1.25507","0","1"],["104631.5","0.00023552","0","2"],["104631.6","0.00007871","0","4"],["104631.8","0.00008114","0","1"],["104632","0.01059591","0","1"],["104632.1","0.01059591","0","1"],["104632.2","0.0405239","0","2"]],"bids":[["104523.8","0.03735306","0","6"],["104513.1","0","0","0"],["104512.3","0.00001","0","1"],["104511.1","0","0","0"],["104510","0.09349006","0","3"],["104509.6","0","0","0"],["104509.1","0","0","0"],["104509","0.46157006","0","1"],["104507.3","0","0","0"],["104506.1","0.00478255","0","1"],["104505.9","0","0","0"],["104504.9","0","0","0"],["104504.4","0","0","0"],["104502.4","0.13868498","0","1"],["104502.3","0","0","0"],["104498.6","0","0","0"],["104425.4","0","0","0"],["104425","0.00010102","0","1"],["104280","0.0023428","0","7"],["104278.6","0.00010262","0","1"],["104277.6","0.77868377","0","2"],["104276.6","0.00118321","0","1"],["104275.7","2.84056","0","1"],["104275.1","0.07298372","0","1"],["104275","0.00004692","0","1"],["104274.3","0.00001","0","1"]],"ts":"1747171673901","checksum":371586917,"seqId":54227200884,"prevSeqId":54227200848}]}
{"arg":{"channel":"books","instId":"BTC-USDT"},"action":"update","data":[{"asks":[["104530.4","0.22304147","0","2"],["104530.7","0.09767445","0","1"],["104531.6","0.10209813","0","2"],["104533.4","0.18281507","0","2"],["104535.6","0.52851836","0","4"],["104536.2","0.15808629","0","1"],["104536.6","0.16496532","0","1"],["104536.9","0.1453989","0","1"],["104538.5","0.01110176","0","6"],["104539.5","0.00480916","0","3"],["104539.6","0.16384509","0","1"],["104540.6","0.23945241","0","1"],["104541.6","0.25175874","0","1"],["104541.7","0.26042362","0","1"],["104545.9","0.26116134","0","1"],["104630.7","0","0","0"],["104630.8","0","0","0"],["104631.1","0","0","0"],["104631.4","0","0","0"],["104631.5","0","0","0"],["104631.6","0","0","0"],["104631.8","0","0","0"],["104632","0","0","0"],["104632.1","0","0","0"],["104632.2","0","0","0"]],"bids":[["104512.9","0.09091658","0","1"],["104512.1","0.29133885","0","2"],["104510.9","0.09795583","0","1"],["104509.7","0.09633699","0","1"],["104509.4","0.14951839","0","1"],["104508.7","0.15013757","0","1"],["104507.2","0.00479756","0","2"],["104507.1","0.16831362","0","1"],["104506.1","0","0","0"],["104505.6","0.29031521","0","3"],["104504.6","0.15286693","0","1"],["104504.4","0.13868348","0","1"],["104504.3","0.30105502","0","3"],["104502.4","0","0","0"],["104502.1","0.25774755","0","1"],["104498.4","0.26111277","0","1"],["104280","0","0","0"],["104278.6","0","0","0"],["104277.6","0","0","0"],["104276.6","0","0","0"],["104275.7","0","0","0"],["104275.1","0","0","0"],["104275","0","0","0"],["104274.3","0","0","0"]],"ts":"1747171674001","checksum":-734609744,"seqId":54227200935,"prevSeqId":54227200884}]}
{"arg":{"channel":"books","instId":"BTC-USDT"},"action":"update","data":[{"asks":[["104552.1","0","0","0"],["104553.7","0.13870653","0","2"],["104630.7","0.00024099","0","2"]],"bids":[["104504.7","0.1386833","0","1"],["104504.4","0","0","0"],["104495.9","0.01337141","0","2"],["104493.8","0","0","0"],["104425.1","0.00009729","0","1"],["104425","0","0","0"],["104373","0","0","0"],["104372.2","0.00095645","0","1"],["104280","0.0023428","0","7"]],"ts":"1747171674101","checksum":-734609744,"seqId":54227200969,"prevSeqId":54227200935}]}
{"arg":{"channel":"books","instId":"BTC-USDT"},"action":"update","data":[{"asks":[["104552.1","0.13868331","0","1"],["104553.7","0.00002373","0","1"],["104630.7","0","0","0"]],"bids":[["104471.6","0.05997122","0","2"],["104425.1","0","0","0"],["104425","0.00009892","0","1"],["104293.9","0.00767063","0","1"]],"ts":"1747171674201","checksum":-734609744,"seqId":54227200979,"prevSeqId":54227200969}]}
{"arg":{"channel":"books","instId":"BTC-USDT"},"action":"update","data":[{"asks":[["104538.7","0.00478255","0","1"],["104539.5","0.00002661","0","2"],["104540","0.03928435","0","8"],["104630.4","0","0","0"]],"bids":[["104523.8","0.03812306","0","7"],["104507.2","0.00001501","0","1"],["104506.1","0.00478255","0","1"],["104504.7","0","0","0"],["104504.4","0.13868348","0","1"],["104280","0","0","0"]],"ts":"1747171674301","checksum":-541427698,"seqId":54227200988,"prevSeqId":54227200979}]}
{"arg":{"channel":"books","instId":"BTC-USDT"},"action":"update","data":[{"asks":[["104529.1","0.07298372","0","1"],["104535","0.03365187","0","1"],["104537.9","0.00478255","0","1"],["104538.3","0","0","0"],["104538.7","0","0","0"],["104569.8","0","0","0"],["104599.1","0","0","0"],["104602.8","0.1434","0","1"],["104609.5","4.65576805","0","1"],["104612.7","0.01052551","0","1"],["104618","0.00445876","0","6"]],"bids":[["104523.8","0.03492306","0","6"],["104506.1","0","0","0"],["104505.7","0.00478255","0","1"],["104504.7","0.13868339","0","1"],["104504.4","0","0","0"],["104481.9","0","0","0"],["104477.8","0.10997346","0","1"],["104477.7","0","0","0"],["104454.8","0.46873819","0","1"],["104447.2","0.46802562","0","1"],["104444.8","0.00002501","0","2"],["104310.1","0.00097512","0","1"],["104308.8","0","0","0"],["104280","0.0023428","0","7"]],"ts":"1747171674401","checksum":1371105749,"seqId":54227201038,"prevSeqId":54227200988}]}
{"arg":{"channel":"books","instId":"BTC-USDT"},"action":"update","data":[{"asks":[["104523.9","0.20559608","0","6"],["104537.9","0","0","0"],["104538.4","0.07778843","0","4"],["104567","0.53039088","0","2"],["104569.4","1.47044207","0","2"],["104586.1","0.413276","0","1"],["104602.3","2.58490894","0","1"],["104609.5","0","0","0"],["104612.7","4.64980708","0","2"]],"bids":[["104523.8","0.03812306","0","7"],["104506.1","0.00478255","0","1"],["104505.7","0","0","0"],["104504.7","0","0","0"],["104502.2","0.1386844","0","1"],["104477.8","0.53999565","0","2"],["104476.5","1.48423956","0","3"],["104447.2","1.18763534","0","2"],["104443.5","3.06689907","0","2"]],"ts":"1747171674501","checksum":996650500,"seqId":54227201079,"prevSeqId":54227201038}]}
{"arg":{"channel":"books","instId":"BTC-USDT"},"action":"update","data":[{"asks":[["104552.1","0","0","0"],["104553.7","0.13870657","0","2"],["104609.5","4.63928157","0","1"],["104612.7","0.01052551","0","1"]],"bids":[["104504.7","0.13868284","0","1"],["104502.2","0","0","0"]],"ts":"1747171674601","checksum":996650500,"seqId":54227201089,"prevSeqId":54227201079}]}
{"arg":{"channel":"books","instId":"BTC-USDT"},"action":"update","data":[{"asks":[["104535","0","0","0"],["104537.9","0.00478255","0","1"],["104538.4","0.09994128","0","4"],["104552.1","0.13868432","0","1"],["104553.7","0.00002373","0","1"],["104630.2","0","0","0"]],"bids":[["104506.1","0","0","0"],["104504.7","0.00478255","0","1"],["104502.2","0.13868474","0","1"]],"ts":"1747171674701","checksum":996650500,"seqId":54227201103,"prevSeqId":54227201089}]}
{"arg":{"channel":"books","instId":"BTC-USDT"},"action":"update","data":[{"asks":[["104554","0.17838463","0","1"],["104555","0","0","0"],["104556","0.002","0","2"],["104557","0.00387","0","2"],["104578","0.01435078","0","2"],["104579","0.15999999","0","2"],["104580","0.25222717","0","9"],["104581","0.08506705","0","3"]],"bids":[["104523.8","0.03735306","0","6"]],"ts":"1747171674801","checksum":-1928740138,"seqId":54227201129,"prevSeqId":54227201103}]}
{"arg":{"channel":"books","instId":"BTC-USDT"},"action":"update","data":[{"asks":[["104554","0.18038463","0","3"],["104555","0.001","0","1"],["104556","0","0","0"],["104557","0.00287","0","1"],["104578","0.11435078","0","4"],["104579","0.20999999","0","3"],["104580","0.15222717","0","7"],["104581","0.03506705","0","2"]],"bids":[],"ts":"1747171674901","checksum":-1928740138,"seqId":54227201141,"prevSeqId":54227201129}]}
{"arg":{"channel":"books","instId":"BTC-USDT"},"action":"update","data":[{"asks":[["104530.4","0.22018275","0","2"],["104530.7","0.09075848","0","1"],["104531.6","0.09006317","0","2"],["104533.4","0.19223696","0","2"],["104535.6","0.54519392","0","4"],["104536.2","0.16882842","0","1"],["104536.6","0.16846053","0","1"],["104536.7","0","0","0"],["104536.9","0.1505932","0","1"],["104539.5","0.02696173","0","3"],["104539.6","0.15299428","0","1"],["104540.6","0.24570791","0","1"],["104541.6","0.23805651","0","1"],["104541.7","0.27057085","0","1"],["104545.9","0.26145579","0","1"],["104578","0.34435078","0","8"],["104579","0.16499999","0","3"],["104580","0.00222718","0","4"],["104581","0.00006705","0","1"],["104630.2","0.0004067","0","2"]],"bids":[["104512.9","0.08770541","0","1"],["104512.1","0.29060814","0","2"],["104510.9","0.08792013","0","1"],["104509.7","0.10158627","0","1"],["104509.4","0.15349772","0","1"],["104508.7","0.15748381","0","1"],["104507.1","0.16578676","0","1"],["104505.6","0.27084641","0","3"],["104504.7","0.14346592","0","2"],["104504.6","0.16734811","0","1"],["104504.3","0.2163256","0","2"],["104502.2","0","0","0"],["104502.1","0.25311594","0","1"],["104498.4","0.25702671","0","1"],["104476","0.00010985","0","2"],["104278.6","0.00010262","0","1"]],"ts":"1747171675001","checksum":-1471467794,"seqId":54227201211,"prevSeqId":54227201141}]}
{"arg":{"channel":"books","instId":"BTC-USDT"},"action":"update","data":[{"asks":[["104531.6","0.00001","0","1"],["104533.4","0","0","0"],["104536.6","0","0","0"],["104536.9","0","0","0"],["104541.6","0","0","0"],["104545.9","0","0","0"],["104630.4","0.00001585","0","1"],["104630.7","0.00024099","0","2"],["104630.8","0.00001016","0","1"],["104631.1","0.00001258","0","1"],["104631.4","1.25507","0","1"]],"bids":[["104523.8","0.03415306","0","5"],["104523.2","0","0","0"],["104512.9","0","0","0"],["104512.1","0.19242972","0","1"],["104510.9","0","0","0"],["104509.4","0","0","0"],["104507.1","0","0","0"],["104502.1","0","0","0"],["104498.4","0","0","0"],["104477.8","0.10997346","0","1"],["104476.5","0.00501","0","2"],["104447.2","0.46802562","0","1"],["104443.5","0.34742422","0","1"],["104277.6","0.77868377","0","2"],["104276.6","0.00118321","0","1"],["104275.7","2.84056","0","1"],["104275.1","0.07298372","0","1"],["104275","0.00004692","0","1"],["104274.3","0.00001","0","1"],["104274.1","0.0001347","0","1"]],"ts":"1747171675101","checksum":-1401422561,"seqId":54227201233,"prevSeqId":54227201211}]}
{"arg":{"channel":"books","instId":"BTC-USDT"},"action":"update","data":[{"asks":[["104526.1","0","0","0"],["104529.1","0","0","0"],["104530.4","0.2144258","0","2"],["104531.5","0.09108143","0","1"],["104533.3","0.20211225","0","11"],["104536.4","0.00480551","0","2"],["104536.5","0.1661438","0","1"],["104536.8","0.1569459","0","1"],["104537.9","0","0","0"],["104538.6","0","0","0"],["104541.5","0.26696915","0","1"],["104545.8","0.39335986","0","5"],["104554","0.17838463","0","1"],["104555","0.002","0","2"],["104556","0.001","0","1"],["104578","0.01435078","0","2"],["104579","0.32999999","0","6"],["104580","0.16722717","0","7"],["104631.4","0","0","0"]],"bids":[["104523.8","0.03735306","0","6"],["104512.8","0.09474203","0","1"],["104512","0.20317457","0","4"],["104510.8","0.16620768","0","3"],["104509.3","0.14257855","0","1"],["104507","0.16148706","0","1"],["104504.7","0.00478255","0","1"],["104504.3","0.30005004","0","3"],["104502.1","0.1386854","0","1"],["104502","0.2543986","0","1"],["104498.3","0.2605416","0","1"],["104498","0.18792795","0","2"],["104495.9","0.0038279","0","1"],["104478","0","0","0"],["104465.5","0","0","0"],["104373","0.00095645","0","1"],["104372.2","0","0","0"],["104276.6","0","0","0"],["104275.8","0.00118321","0","1"],["104275.1","0","0","0"],["104275","0","0","0"],["104274.3","0","0","0"],["104274.1","0","0","0"]],"ts":"1747171675201","checksum":95205448,"seqId":54227201298,"prevSeqId":54227201233}]}
{"arg":{"channel":"books","instId":"BTC-USDT"},"action":"update","data":[{"asks":[["104536.4","0.00002296","0","1"],["104537","0.00478255","0","1"],["104631.1","0","0","0"]],"bids":[["104522.1","0.07137677","0","2"],["104504.4","0.13868373","0","1"],["104502.1","0","0","0"],["104477.8","1.58323538","0","2"],["104444.9","2.71102189","0","1"],["104275.7","0","0","0"]],"ts":"1747171675301","checksum":1291805234,"seqId":54227201340,"prevSeqId":54227201298}]}
{"arg":{"channel":"books","instId":"BTC-USDT"},"action":"update","data":[{"asks":[["104537","0","0","0"],["104539.4","0.00478255","0","1"],["104552.1","0.13868305","0","1"]],"bids":[["104507.1","0.00478255","0","1"],["104504.7","0.13868305","0","1"],["104504.4","0","0","0"],["104276.6","0.00118321","0","1"],["104275.8","0","0","0"]],"ts":"1747171675401","checksum":1291805234,"seqId":54227201367,"prevSeqId":54227201340}]}
{"arg":{"channel":"books","instId":"BTC-USDT"},"action":"update","data":[{"asks":[["104602.1","0.84509289","0","1"],["104630.8","0","0","0"]],"bids":[["104504.7","0","0","0"],["104504.1","0.13868395","0","1"]],"ts":"1747171675501","checksum":1291805234,"seqId":54227201372,"prevSeqId":54227201367}]}
{"arg":{"channel":"books","instId":"BTC-USDT"},"action":"update","data":[{"asks":[],"bids":[["104504.1","0","0","0"],["104502.1","0.13868431","0","1"]],"ts":"1747171675601","checksum":1291805234,"seqId":54227201387,"prevSeqId":54227201372}]}
{"arg":{"channel":"books","instId":"BTC-USDT"},"action":"update","data":[{"asks":[["104532.9","0.02396281","0","2"],["104536.9","0.03365126","0","1"],["104539.5","0.00002661","0","2"],["104630.7","0","0","0"]],"bids":[["104523.8","0.03734171","0","6"]],"ts":"1747171675801","checksum":-702151716,"seqId":54227201393,"prevSeqId":54227201387}]}
{"arg":{"channel":"books","instId":"BTC-USDT"},"action":"update","data":[{"asks":[["104532.9","0.0000535","0","1"],["104540","0.00342039","0","7"]],"bids":[],"ts":"1747171675901","checksum":-702151716,"seqId":54227201427,"prevSeqId":54227201393}]}
{"arg":{"channel":"books","instId":"BTC-USDT"},"action":"update","data":[{"asks":[["104526.1","0.002","0","1"],["104538.6","0.002","0","1"],["104630.2","0","0","0"],["104630.4","0","0","0"]],"bids":[["104494.1","0","0","0"],["104493.5","0.00095659","0","1"],["104491.9","0","0","0"],["104479.1","0.002871","0","1"],["104478","0.002","0","1"],["104465.5","0.002","0","1"],["104277.6","0","0","0"],["104276.6","0","0","0"]],"ts":"1747171676001","checksum":-1525222935,"seqId":54227201437,"prevSeqId":54227201427}]}
{"arg":{"channel":"books","instId":"BTC-USDT"},"action":"update","data":[{"asks":[["104537.9","0.00478255","0","1"],["104539.4","0","0","0"]],"bids":[["104507.1","0","0","0"],["104506.1","0.00478255","0","1"],["104502.1","0.13868425","0","1"],["104500","0.01175157","0","4"],["104498","0.17838463","0","1"],["104310.1","0","0","0"],["104308.8","0.00097504","0","1"]],"ts":"1747171676101","checksum":-1525222935,"seqId":54227201463,"prevSeqId":54227201437}]}
{"arg":{"channel":"books","instId":"BTC-USDT"},"action":"update","data":[{"asks":[],"bids":[["104506.1","0","0","0"],["104505.7","0.00478255","0","1"],["104504.1","0.13868419","0","1"],["104502.1","0","0","0"],["104373","0","0","0"],["104372.2","0.00095645","0","1"]],"ts":"1747171676201","checksum":-1525222935,"seqId":54227201471,"prevSeqId":54227201463}]}
{"arg":{"channel":"books","instId":"BTC-USDT"},"action":"update","data":[{"asks":[["104540.1","0.03586392","0","1"],["104630.1","0","0","0"]],"bids":[["104523.8","0.03736171","0","7"]],"ts":"1747171676301","checksum":1149176404,"seqId":54227201477,"prevSeqId":54227201471}]}
{"arg":{"channel":"books","instId":"BTC-USDT"},"action":"update","data":[{"asks":[["104552.1","0.1386841","0","1"]],"bids":[["104504.1","0","0","0"],["104502.1","0.13868473","0","1"]],"ts":"1747171676401","checksum":1149176404,"seqId":54227201493,"prevSeqId":54227201477}]}
{"arg":{"channel":"books","instId":"BTC-USDT"},"action":"update","data":[{"asks":[["104546.2","0.17305101","0","1"],["104547.8","0","0","0"],["104560.2","0.22525473","0","1"]],"bids":[],"ts":"1747171676501","checksum":1149176404,"seqId":54227201497,"prevSeqId":54227201493}]}
{"arg":{"channel":"books","instId":"BTC-USDT"},"action":"update","data":[{"asks":[["104537.9","0","0","0"],["104539.9","0.00478255","0","1"],["104578.9","0.55732149","0","11"],["104579.8","0","0","0"],["104630.1","0.5","0","1"]],"bids":[["104522.3","0","0","0"],["104522.1","0.03308376","0","1"],["104508.1","0.00478255","0","1"],["104505.7","0","0","0"],["104477.9","0.55198049","0","1"],["104477.8","1.47326192","0","1"],["104447.2","1.18509945","0","2"]],"ts":"1747171676601","checksum":1693595893,"seqId":54227201513,"prevSeqId":54227201497}]}
{"arg":{"channel":"books","instId":"BTC-USDT"},"action":"update","data":[{"asks":[["104529.8","0.09795975","0","1"],["104530.4","0.13549571","0","1"],["104530.7","0.09699184","0","1"],["104531.5","0","0","0"],["104532.5","0.18500034","0","2"],["104533.3","0.01261438","0","9"],["104535.3","0.16990252","0","1"],["104535.6","0.26439409","0","3"],["104535.7","0.16373286","0","1"],["104536","0.18288014","0","4"],["104536.2","0","0","0"],["104536.5","0","0","0"],["104536.8","0","0","0"],["104538.8","0.18847556","0","2"],["104539.6","0","0","0"],["104539.8","0.24183449","0","1"],["104540.6","0","0","0"],["104540.7","0.25414286","0","1"],["104540.8","0.23937689","0","1"],["104541.5","0","0","0"],["104541.7","0","0","0"],["104545","0.43209446","0","3"],["104545.8","0.13077002","0","4"],["104552.1","0.13868585","0","1"],["104630.2","0.0004067","0","2"]],"bids":[["104522.4","0.04388813","0","1"],["104521.7","0.03829301","0","1"],["104512.8","0","0","0"],["104512","0.20899595","0","4"],["104511.2","0.09846889","0","1"],["104510.8","0.072736","0","2"],["104510","0.18517281","0","4"],["104509.7","0","0","0"],["104509.3","0","0","0"],["104508.8","0.09916983","0","1"],["104508.7","0","0","0"],["104507.8","0.16712392","0","1"],["104507.4","0.002871","0","1"],["104507","0","0","0"],["104506.2","0.16690038","0","1"],["104505.6","0.04233353","0","2"],["104504.8","0.25148122","0","1"],["104504.6","0","0","0"],["104503.8","0.15447784","0","1"],["104502.1","0","0","0"],["104502","0","0","0"],["104501.3","0.13868622","0","1"],["104498.3","0","0","0"],["104497.5","0.25250254","0","1"],["104479.1","0","0","0"],["104472.2","0.02243916","0","1"],["104368.1","0.0579344","0","1"],["104280","0","0","0"],["104278.6","0","0","0"]],"ts":"1747171676701","checksum":-534524208,"seqId":54227201631,"prevSeqId":54227201513}]}
{"arg":{"channel":"books","instId":"BTC-USDT"},"action":"update","data":[{"asks":[["104530.4","0.23859288","0","2"],["104535.6","0.64011154","0","4"]],"bids":[["104523.8","0.03737171","0","8"],["104513.9","0","0","0"],["104508.5","0.58814515","0","2"],["104501.2","0.45144691","0","2"],["104500.3","0.05105744","0","1"]],"ts":"1747171676801","checksum":2102384318,"seqId":54227201638,"prevSeqId":54227201631}]}
{"arg":{"channel":"books","instId":"BTC-USDT"},"action":"update","data":[{"asks":[["104538.7","0.15499982","0","1"],["104538.8","0.03586365","0","1"],["104539.7","0.23683799","0","2"],["104539.8","0","0","0"],["104539.9","0","0","0"],["104609.5","0","0","0"],["104612.7","4.63089884","0","2"],["104630.4","0.00001585","0","1"]],"bids":[["104523.8","0.03417171","0","7"],["104518.3","0","0","0"],["104514.8","0.01033259","0","1"],["104508.1","0","0","0"],["104506.3","0.00478255","0","1"],["104504.8","0","0","0"],["104504.7","0.23684462","0","1"],["104503.8","0","0","0"],["104503.7","0.14981706","0","1"],["104490.7","0.02243916","0","1"],["104472.2","0","0","0"]],"ts":"1747171676901","checksum":-1020588148,"seqId":54227201695,"prevSeqId":54227201638}]}
{"arg":{"channel":"books","instId":"BTC-USDT"},"action":"update","data":[{"asks":[["104539.6","0.00478255","0","1"],["104539.7","0.23205544","0","1"],["104570","1.00029006","0","3"],["104630.4","0","0","0"]],"bids":[["104507.5","0.00478255","0","1"],["104506.3","0","0","0"]],"ts":"1747171677001","checksum":-1020588148,"seqId":54227201700,"prevSeqId":54227201695}]}
{"arg":{"channel":"books","instId":"BTC-USDT"},"action":"update","data":[{"asks":[["104522.5","0.21909483","0","7"],["104523.9","0.00001","0","1"],["104529.7","0.00014294","0","1"],["104529.8","0","0","0"],["104530.3","0","0","0"],["104530.7","0","0","0"],["104532.5","0","0","0"],["104535.3","0","0","0"],["104535.7","0","0","0"],["104536","0.03831884","0","3"],["104537","0.00478255","0","1"],["104538.7","0","0","0"],["104539.6","0","0","0"],["104539.7","0","0","0"],["104540.7","0","0","0"],["104540.8","0","0","0"],["104545","0.19244373","0","2"],["104555","0","0","0"],["104556","0","0","0"],["104557","0.00487","0","3"],["104558","0.001","0","1"],["104579","0","0","0"],["104580","0.16222717","0","6"],["104581","0.25006704","0","6"],["104582","0.0875","0","3"],["104630.4","0.00001585","0","1"],["104630.7","0.00024099","0","2"],["104630.8","0.00001016","0","1"],["104631.1","0.00001258","0","1"],["104631.4","1.25507","0","1"],["104631.5","0.00023552","0","2"],["104631.6","0.00007871","0","4"],["104631.8","0.00008114","0","1"],["104632","0.01059591","0","1"],["104632.1","0.01059591","0","1"]],"bids":[["104523.8","0","0","0"],["104522.4","0.19870605","0","4"],["104521.8","0.08714535","0","1"],["104519.6","0.05535984","0","1"],["104518.1","0","0","0"],["104512.2","0.19242972","0","1"],["104512.1","0","0","0"],["104512","0.11151267","0","3"],["104511.2","0","0","0"],["104510","0.09349006","0","3"],["104509.2","0.79340502","0","3"],["104509.1","0.77866876","0","1"],["104509","0","0","0"],["104508.9","0","0","0"],["104508.8","0","0","0"],["104508.5","0.43383","0","1"],["104507.8","0","0","0"],["104507.5","0","0","0"],["104506.2","0","0","0"],["104504.8","0.00478255","0","1"],["104504.7","0","0","0"],["104504.4","0.13868341","0","1"],["104504.2","0.04928988","0","1"],["104503.7","0","0","0"],["104501.5","0.009543","0","1"],["104501.3","0","0","0"],["104501.2","0.19242972","0","1"],["104500","0.00220843","0","3"],["104497.5","0","0","0"],["104495.9","0","0","0"],["104495.4","0","0","0"],["104280","0.0023428","0","7"],["104278.6","0.00010262","0","1"],["104277.6","0.77868377","0","2"],["104276.6","0.00118321","0","1"],["104275.7","2.84056","0","1"],["104275.1","0.07298372","0","1"],["104275","0.00004692","0","1"],["104274.3","0.00001","0","1"]],"ts":"1747171677101","checksum":303669233,"seqId":54227201836,"prevSeqId":54227201700}]}
{"arg":{"channel":"books","instId":"BTC-USDT"},"action":"update","data":[{"asks":[["104525.9","0.10294405","0","2"],["104527.7","0.07298372","0","1"],["104529.5","0.00023881","0","2"],["104529.6","0.09557028","0","1"],["104529.7","0","0","0"],["104530.4","0.28669865","0","2"],["104530.5","0.09695045","0","1"],["104532.3","0.18629099","0","2"],["104535.1","0.16400145","0","1"],["104535.5","0.16507766","0","2"],["104535.6","0.59114054","0","4"],["104535.8","0.14431711","0","1"],["104536.8","0.00478255","0","1"],["104537","0","0","0"],["104538.6","0.15647694","0","2"],["104539.6","0.23590476","0","1"],["104540.5","0.23948397","0","1"],["104540.6","0.25884086","0","1"],["104544.8","0.60753681","0","2"],["104546.9","0.00400533","0","2"],["104569.4","0.00003068","0","1"],["104577.3","0.1","0","1"],["104578.7","0","0","0"],["104602.1","0","0","0"],["104602.3","0","0","0"],["104609.5","4.6197767","0","1"],["104612.7","0.01052551","0","1"],["104622.8","0.00163145","0","1"],["104624.3","0.00001097","0","1"],["104630.8","0","0","0"],["104631.1","0","0","0"],["104631.4","0","0","0"],["104631.5","0","0","0"],["104631.6","0","0","0"],["104631.8","0","0","0"],["104632","0","0","0"],["104632.1","0","0","0"]],"bids":[["104522.4","0.07920605","0","3"],["104511.8","0.09287577","0","1"],["104511","0.44578273","0","2"],["104509.8","0.18761617","0","2"],["104509.2","0.73773707","0","4"],["104508.6","0.10109228","0","1"],["104508.3","0.15473954","0","2"],["104507.6","0.1642071","0","1"],["104506","0.25777769","0","2"],["104504.8","0","0","0"],["104504.6","0.25263673","0","1"],["104504.5","0.00478255","0","1"],["104503.6","0.15380527","0","1"],["104501","0.24525542","0","1"],["104497.3","0.25966159","0","1"],["104477.9","0","0","0"],["104477.8","0","0","0"],["104471.6","0.05996122","0","1"],["104447.2","0.46802562","0","1"],["104444.9","0","0","0"],["104433.1","0","0","0"],["104432.2","0.00063869","0","1"],["104430.1","0","0","0"],["104428.3","0.00083904","0","1"],["104276.6","0","0","0"],["104275.8","0.00118321","0","1"],["104275.7","0","0","0"],["104275.1","0","0","0"],["104275","0","0","0"],["104274.3","0","0","0"]],"ts":"1747171677201","checksum":722192612,"seqId":54227201981,"prevSeqId":54227201836}]}
{"arg":{"channel":"books","instId":"BTC-USDT"},"action":"update","data":[{"asks":[["104536.8","0","0","0"],["104537","0.00478255","0","1"],["104555","0.002","0","2"],["104556","0.001","0","1"],["104557","0.00287","0","1"],["104558","0","0","0"],["104568.1","1.42843858","0","1"],["104579","0.33","0","6"],["104580","0.16722717","0","7"],["104581","0.00006705","0","1"],["104582","0.0025","0","1"],["104599.4","2.54912494","0","2"],["104609.4","4.63035814","0","6"],["104609.5","0","0","0"],["104629.8","0.00009264","0","1"],["104630.2","0","0","0"],["104630.4","0","0","0"],["104630.7","0","0","0"]],"bids":[["104522.4","0.07929605","0","4"],["104504.7","0.00478255","0","1"],["104504.5","0","0","0"],["104504.4","0","0","0"],["104501.3","0.13868493","0","1"],["104477.8","1.434501","0","1"],["104446.4","2.58039411","0","1"],["104425","0","0","0"],["104423.8","0.00009789","0","1"],["104372.2","0","0","0"],["104370.1","0.00095645","0","1"],["104277.6","0","0","0"],["104275.8","0","0","0"]],"ts":"1747171677301","checksum":1865095377,"seqId":54227202045,"prevSeqId":54227201981}]}
{"arg":{"channel":"books","instId":"BTC-USDT"},"action":"update","data":[{"asks":[["104529.5","0.00009587","0","1"],["104529.6","0","0","0"],["104529.9","0.00014294","0","1"],["104530","0.09117748","0","3"],["104530.4","0.23800684","0","2"],["104530.5","0","0","0"],["104530.9","0.09857462","0","1"],["104532.3","0","0","0"],["104532.7","0.18882571","0","2"],["104535.1","0","0","0"],["104535.5","0.16261419","0","2"],["104535.6","0.49911773","0","4"],["104535.8","0","0","0"],["104535.9","0.16798632","0","1"],["104536.2","0.16010562","0","1"],["104537","0","0","0"],["104538.6","0.002","0","1"],["104538.9","0.15462811","0","1"],["104539.6","0","0","0"],["104539.8","0.00478255","0","1"],["104539.9","0.24356088","0","1"],["104540.5","0","0","0"],["104540.6","0","0","0"],["104540.9","0.25543975","0","1"],["104541","0.23999188","0","1"],["104544.8","0.34742422","0","1"],["104544.9","0.78000063","0","3"],["104545.2","0.43548581","0","2"],["104546.5","0","0","0"],["104552.1","0.13868338","0","1"],["104579","0.32999999","0","6"]],"bids":[["104522.4","0.19879605","0","5"],["104512.2","0.28337532","0","2"],["104511.8","0","0","0"],["104511.4","0.0961463","0","1"],["104511","0.34742422","0","1"],["104510.2","0.08918437","0","1"],["104509.8","0.09416","0","1"],["104509.2","0.54609885","0","3"],["104509","0.09838336","0","1"],["104508.7","0.15205687","0","1"],["104508.6","0","0","0"],["104508.3","0.00001","0","1"],["104508","0.26057453","0","2"],["104507.6","0","0","0"],["104507.5","0.00478255","0","1"],["104506.4","0.15836681","0","1"],["104506","0.0932","0","1"],["104504.9","0.24835487","0","1"],["104504.7","0","0","0"],["104504.6","0","0","0"],["104504.4","0.13868338","0","1"],["104503.9","0.15181057","0","1"],["104503.6","0","0","0"],["104501.4","0.25763637","0","1"],["104501.3","0","0","0"],["104501","0","0","0"],["104497.7","0.24885384","0","1"],["104497.3","0","0","0"],["104452.2","0","0","0"],["104450.1","0.00001479","0","1"],["104280","0","0","0"],["104278.6","0","0","0"]],"ts":"1747171677401","checksum":2126869229,"seqId":54227202175,"prevSeqId":54227202045}]}
{"arg":{"channel":"books","instId":"BTC-USDT"},"action":"update","data":[{"asks":[],"bids":[["104509.2","0.73392499","0","4"],["104507.5","0","0","0"],["104506.5","0.00478255","0","1"],["104504.4","0","0","0"],["104501.5","0.14822804","0","2"],["104450.1","0","0","0"],["104280","0.0023428","0","7"],["104278.6","0.00010262","0","1"]],"ts":"1747171677501","checksum":2126869229,"seqId":54227202246,"prevSeqId":54227202175}]}
{"arg":{"channel":"books","instId":"BTC-USDT"},"action":"update","data":[{"asks":[["104523.9","0","0","0"],["104552","0.13868501","0","1"],["104552.1","0","0","0"],["104566.9","1.04687406","0","2"],["104599.3","1.09100497","0","2"],["104609.4","0.01058144","0","5"],["104612.7","4.63030221","0","2"],["104630.2","0.0004067","0","2"]],"bids":[["104501.5","0.1482283","0","2"],["104477.9","0.54035222","0","1"],["104450.1","0.00001479","0","1"],["104447.2","1.14591112","0","2"],["104280","0","0","0"],["104278.6","0","0","0"]],"ts":"1747171677601","checksum":1669469986,"seqId":54227202333,"prevSeqId":54227202246}]}
{"arg":{"channel":"books","instId":"BTC-USDT"},"action":"update","data":[{"asks":[["104539.8","0","0","0"],["104540","0.00820294","0","8"],["104609.5","4.61958722","0","1"],["104612.7","0.01052551","0","1"]],"bids":[["104508.6","0.00478255","0","1"],["104506.5","0","0","0"],["104450.1","0","0","0"],["104280","0.0023428","0","7"]],"ts":"1747171677701","checksum":1669469986,"seqId":54227202388,"prevSeqId":54227202333}]}
{"arg":{"channel":"books","instId":"BTC-USDT"},"action":"update","data":[{"asks":[["104555","0","0","0"],["104556","0","0","0"],["104557","0.00487","0","3"],["104558","0.001","0","1"],["104579","0","0","0"],["104580","0.16222717","0","6"],["104581","0.25006704","0","6"],["104582","0.0875","0","3"],["104630.4","0.00001585","0","1"],["104630.7","0.00024099","0","2"]],"bids":[],"ts":"1747171677801","checksum":1669469986,"seqId":54227202415,"prevSeqId":54227202388}]}
{"arg":{"channel":"books","instId":"BTC-USDT"},"action":"update","data":[{"asks":[["104539.8","0.00478255","0","1"],["104540","0.00342039","0","7"],["104552","0","0","0"],["104552.1","0.13868404","0","1"],["104555","0.002","0","2"],["104556","0.001","0","1"],["104557","0.00287","0","1"],["104558","0","0","0"],["104570","0.00029006","0","2"],["104579","0.1","0","2"],["104580","0.21222718","0","7"],["104581","0.15006704","0","4"],["104582","0.0375","0","2"],["104609.5","0","0","0"],["104612.7","4.63011273","0","2"],["104630.4","0","0","0"],["104630.7","0","0","0"]],"bids":[["104508.6","0","0","0"],["104507.5","0.00478255","0","1"],["104501.5","0.14822834","0","2"],["104480","0.00220843","0","3"],["104478","0.48524487","0","2"],["104450.1","0.00001479","0","1"],["104433","0","0","0"],["104431","0.47439916","0","1"],["104280","0","0","0"]],"ts":"1747171677901","checksum":1669469986,"seqId":54227202504,"prevSeqId":54227202415}]}
{"arg":{"channel":"books","instId":"BTC-USDT"},"action":"update","data":[{"asks":[["104522.5","0.20573783","0","5"],["104529.9","0","0","0"],["104530","0.000433","0","3"],["104530.1","0.09282064","0","1"],["104530.4","0.23182231","0","2"],["104530.9","0","0","0"],["104532.7","0","0","0"],["104535.5","0.00007327","0","1"],["104535.6","0.64104355","0","5"],["104535.9","0","0","0"],["104536.2","0","0","0"],["104538.9","0","0","0"],["104539","0.15720518","0","2"],["104539.9","0","0","0"],["104540","0.23504295","0","8"],["104540.9","0","0","0"],["104541","0","0","0"],["104541.1","0.27041911","0","1"],["104544.9","0.7798555","0","2"],["104545.2","0.17838463","0","1"],["104555","0","0","0"],["104556","0","0","0"],["104557","0.00487","0","3"],["104558","0.001","0","1"],["104579","0","0","0"],["104580","0.16222717","0","6"],["104581","0.25006704","0","6"],["104582","0.0875","0","3"],["104609.5","4.61958722","0","1"],["104612.7","0.01052551","0","1"],["104630.4","0.00001585","0","1"],["104630.7","0.00024099","0","2"],["104630.8","0.00001016","0","1"],["104631.1","0.00001258","0","1"],["104631.4","1.25507","0","1"],["104631.5","0.00023552","0","2"],["104631.6","0.00007871","0","4"],["104631.8","0.00008114","0","1"]],"bids":[["104522.4","0.21027605","0","6"],["104512.2","0.19242972","0","1"],["104511.4","0","0","0"],["104510.2","0","0","0"],["104509.1","0.87184896","0","2"],["104509","0","0","0"],["104508.7","0","0","0"],["104508.1","0.1532264","0","1"],["104508","0.0932","0","1"],["104506.4","0","0","0"],["104505","0.25342726","0","1"],["104504.9","0","0","0"],["104504","0.24639436","0","2"],["104503.9","0","0","0"],["104501.4","0","0","0"],["104497.7","0","0","0"],["104450.1","0","0","0"],["104434.6","0","0","0"],["104280","0.0023428","0","7"],["104278.6","0.00010262","0","1"],["104277.6","0.77868377","0","2"],["104275.7","2.84056","0","1"],["104275.1","0.07298372","0","1"],["104275","0.00004692","0","1"],["104274.3","0.00001","0","1"],["104274.1","0.0001347","0","1"],["104272.9","0.00003136","0","1"]],"ts":"1747171678001","checksum":-284256431,"seqId":54227202576,"prevSeqId":54227202504}]}
{"arg":{"channel":"books","instId":"BTC-USDT"},"action":"update","data":[{"asks":[["104522.5","0.20568179","0","5"],["104530.4","0.22949695","0","2"],["104531","0.0969907","0","1"],["104532.8","0.18265843","0","2"],["104536","0.19368131","0","4"],["104536.3","0.14733936","0","1"],["104539.8","0","0","0"],["104540.8","0.00478255","0","1"],["104541","0.27266516","0","1"],["104544.9","0.78000063","0","3"],["104545.3","0.25676153","0","1"],["104560.8","0.00013814","0","1"],["104562.1","0","0","0"],["104631.1","0","0","0"],["104631.4","0","0","0"],["104631.5","0","0","0"],["104631.6","0","0","0"],["104631.8","0","0","0"]],"bids":[["104512.3","0.0858492","0","2"],["104511.5","0.09375325","0","1"],["104510.3","0.0887727","0","1"],["104508.8","0.14343139","0","1"],["104508.6","0.00478255","0","1"],["104507.5","0","0","0"],["104506.5","0.14863391","0","1"],["104502.3","0.00954293","0","1"],["104501.6","0.13868511","0","1"],["104501.5","0.26079905","0","1"],["104497.8","0.2571658","0","1"],["104450.1","0.00001479","0","1"],["104308.8","0","0","0"],["104308.3","0.00097527","0","1"],["104278.6","0","0","0"],["104277.6","0","0","0"],["104275.7","0","0","0"],["104275.1","0","0","0"],["104275","0","0","0"],["104274.3","0","0","0"],["104274.1","0","0","0"],["104272.9","0","0","0"]],"ts":"1747171678101","checksum":-748728089,"seqId":54227202632,"prevSeqId":54227202576}]}
{"arg":{"channel":"books","instId":"BTC-USDT"},"action":"update","data":[{"asks":[["104544.9","0.7798555","0","2"]],"bids":[["104522.4","0.19879605","0","5"],["104288.5","0","0","0"],["104278.6","0.00010262","0","1"]],"ts":"1747171678201","checksum":-2123647706,"seqId":54227202646,"prevSeqId":54227202632}]}
{"arg":{"channel":"books","instId":"BTC-USDT"},"action":"update","data":[{"asks":[["104544.9","0.78000063","0","3"]],"bids":[],"ts":"1747171678301","checksum":-2123647706,"seqId":54227202649,"prevSeqId":54227202646}]}
{"arg":{"channel":"books","instId":"BTC-USDT"},"action":"update","data":[{"asks":[["104609.4","4.63016866","0","6"],["104609.5","0","0","0"],["104631.1","0.00001258","0","1"]],"bids":[["104471.6","0.05997122","0","2"],["104289.2","7.83841001","0","1"],["104278.6","0","0","0"]],"ts":"1747171678401","checksum":-2123647706,"seqId":54227202709,"prevSeqId":54227202649}]}
{"arg":{"channel":"books","instId":"BTC-USDT"},"action":"update","data":[{"asks":[],"bids":[["104504.1","0.13868404","0","1"],["104501.6","0","0","0"]],"ts":"1747171678501","checksum":-2123647706,"seqId":54227202713,"prevSeqId":54227202709}]}
{"arg":{"channel":"books","instId":"BTC-USDT"},"action":"update","data":[{"asks":[["104582.6","0.17382288","0","2"]],"bids":[["104504.1","0","0","0"],["104501.6","0.1386843","0","1"],["104435.7","0.40517139","0","1"],["104280","0","0","0"]],"ts":"1747171678601","checksum":-2123647706,"seqId":54227202724,"prevSeqId":54227202713}]}
{"arg":{"channel":"books","instId":"BTC-USDT"},"action":"update","data":[{"asks":[["104522.5","0.20569179","0","6"],["104538.3","0.00478255","0","1"],["104540.8","0","0","0"],["104549.8","0.13868604","0","1"],["104552.1","0","0","0"]],"bids":[["104522.4","0.19863085","0","5"],["104508.6","0","0","0"],["104506.6","0.00478255","0","1"]],"ts":"1747171678701","checksum":483283298,"seqId":54227202782,"prevSeqId":54227202724}]}
{"arg":{"channel":"books","instId":"BTC-USDT"},"action":"update","data":[{"asks":[["104537.9","0.00478255","0","1"],["104538.3","0","0","0"],["104549.8","0","0","0"],["104549.9","0.138687","0","1"]],"bids":[["104506.6","0","0","0"],["104506.1","0.00478255","0","1"],["104490.7","0","0","0"],["104474","0.02243916","0","1"]],"ts":"1747171678801","checksum":483283298,"seqId":54227202794,"prevSeqId":54227202782}]}
{"arg":{"channel":"books","instId":"BTC-USDT"},"action":"update","data":[{"asks":[["104522.2","0.25474367","0","10"],["104522.5","0.00001","0","1"],["104529.1","0.09009206","0","1"],["104529.9","0.09296724","0","2"],["104530","0.00029006","0","2"],["104530.1","0","0","0"],["104530.4","0.08394145","0","1"],["104531","0","0","0"],["104531.7","0.19470073","0","2"],["104532.8","0","0","0"],["104534.6","0.15963103","0","2"],["104534.9","0.16653833","0","1"],["104535.2","0.15228124","0","1"],["104535.6","0.28063327","0","3"],["104536","0.03831884","0","3"],["104536.3","0","0","0"],["104537.9","0","0","0"],["104538","0.207308","0","2"],["104539","0.25917421","0","2"],["104539.9","0.28089549","0","2"],["104540","0.00342039","0","7"],["104540.1","0.2701421","0","1"],["104541","0","0","0"],["104541.1","0","0","0"],["104544.2","0.25074154","0","1"],["104545.3","0","0","0"],["104546.9","0.00016922","0","1"],["104548.8","0.13875875","0","2"],["104549.9","0","0","0"],["104574","1","0","1"],["104580","0.16222718","0","6"],["104631.1","0","0","0"]],"bids":[["104522.4","0","0","0"],["104521.8","0","0","0"],["104520","0.01001","0","2"],["104512.3","0.00001","0","1"],["104511.5","0","0","0"],["104511.2","0.08945656","0","1"],["104510.4","0.09711979","0","1"],["104510.3","0","0","0"],["104509.2","0.64032101","0","4"],["104509.1","0.77866876","0","1"],["104508.8","0","0","0"],["104508.1","0.09583196","0","1"],["104507.1","0.16670508","0","1"],["104506.5","0","0","0"],["104506.1","0","0","0"],["104505.4","0.15749605","0","1"],["104505","0","0","0"],["104504","0.32256372","0","2"],["104503","0.14991059","0","1"],["104501.8","0.00478255","0","1"],["104501.6","0","0","0"],["104501.5","0","0","0"],["104500.5","0.13868852","0","1"],["104500.4","0.58848184","0","4"],["104497.8","0","0","0"],["104496.7","0.26365121","0","1"],["104494.8","0.02243916","0","1"],["104494.2","0.00382796","0","1"],["104474","0","0","0"],["104280","0.0023428","0","7"],["104278.6","0.00010262","0","1"]],"ts":"1747171678901","checksum":-96174564,"seqId":54227203033,"prevSeqId":54227202794}]}
{"arg":{"channel":"books","instId":"BTC-USDT"},"action":"update","data":[{"asks":[["104511.6","0.69825172","0","19"],["104512","0.20825344","0","2"],["104512.1","0.11192724","0","4"],["104514","0.09841796","0","2"],["104514.1","0.06107972","0","2"],["104514.2","0.052","0","2"],["104514.4","0.10135144","0","1"],["104515.1","0.00048166","0","1"],["104515.3","0.09923157","0","2"],["104515.7","0.0047827","0","1"],["104515.9","0.1228932","0","1"],["104516","0.0932","0","1"],["104517.1","0.18420974","0","2"],["104517.9","0.07298372","0","1"],["104518.3","0.17838463","0","1"],["104519.9","0.17084542","0","1"],["104520","0.00001","0","1"],["104520.1","0.00001","0","1"],["104520.3","0.16742697","0","1"],["104520.6","0.58848296","0","2"],["104520.8","0.77866876","0","1"],["104520.9","0.34742422","0","1"],["104521","0.21646092","0","2"],["104521.9","0.13872323","0","1"],["104522","0.0932","0","1"],["104522.2","0.05209","0","3"],["104523.4","0.14906157","0","1"],["104524","0.08464536","0","3"],["104524.1","0.00001","0","1"],["104524.4","0.22892135","0","1"],["104524.5","0.00767126","0","3"],["104525.2","0.08688809","0","2"],["104525.4","0.45904095","0","2"],["104525.9","0","0","0"],["104527.3","0.00093","0","1"],["104529","0.000015","0","1"],["104529.1","0","0","0"],["104529.6","0.25952157","0","1"],["104529.9","0","0","0"],["104530.4","0.41941136","0","1"],["104531.2","0.05558744","0","1"],["104531.7","0","0","0"],["104531.8","0","0","0"],["104532","0.01","0","1"],["104532.5","0.00093","0","1"],["104532.7","0.02390933","0","1"],["104533.4","0.34742422","0","1"],["104533.5","0.77866876","0","1"],["104534.6","0","0","0"],["104534.9","0","0","0"],["104535.2","0","0","0"],["104535.4","0.039","0","1"],["104535.6","0.21664729","0","3"],["104536","0.00002583","0","2"],["104536.5","0.00383611","0","1"],["104536.9","0","0","0"],["104537.1","0","0","0"],["104537.7","0.00191","0","1"],["104538","0","0","0"],["104538.1","0","0","0"],["104538.4","0.07300588","0","3"],["104539","0.00004416","0","1"],["104539.6","0.039","0","1"],["104539.9","0","0","0"],["104540.1","0","0","0"],["104540.3","0","0","0"],["104542.3","0","0","0"],["104542.9","0.00191","0","1"],["104543.6","0","0","0"],["104544.2","0","0","0"],["104545","0.19444373","0","4"],["104545.7","0","0","0"],["104546","0.001","0","1"],["104546.2","0.12190923","0","1"],["104546.4","0.00287","0","1"],["104546.8","0","0","0"],["104547.5","0","0","0"],["104548.8","0.00007023","0","1"],["104549.4","0.45068485","0","1"],["104552.6","0","0","0"],["104552.7","0","0","0"],["104552.8","0.01618377","0","1"],["104554.1","0.29801452","0","3"],["104555.1","0.00286966","0","1"],["104556.4","0.00286966","0","1"],["104557","0.00287","0","1"],["104558","0","0","0"],["104558.1","0","0","0"],["104559","1","0","1"],["104559.4","0.00289446","0","2"],["104560.7","0.00286964","0","1"],["104563.3","0.0287047","0","1"],["104564.4","0","0","0"],["104568","0.16","0","2"],["104569","0.17999999","0","3"],["104570","0.05029006","0","3"],["104571","0.07001501","0","3"],["104572","0.03745746","0","16"],["104572.3","0","0","0"],["104572.9","0.00965572","0","1"],["104574","0","0","0"],["104575.8","0","0","0"],["104577","0.1","0","1"],["104577.3","0","0","0"],["104579.7","0.00001","0","1"],["104580","0.00222718","0","4"],["104581","0.00006705","0","1"],["104582","0.0025","0","1"],["104582.1","0","0","0"],["104582.3","1.33857876","0","2"],["104585.2","0","0","0"],["104591","0.58391611","0","2"],["104595.7","0","0","0"],["104595.8","0","0","0"],["104598.6","0.0580344","0","2"],["104599","0","0","0"],["104599.3","0.99540497","0","1"],["104601.3","0.0105377","0","2"],["104602.8","0","0","0"],["104604","0","0","0"],["104606","4.61958722","0","1"],["104607.4","0","0","0"],["104608.8","0.00043936","0","15"],["104609.4","0.01058144","0","5"],["104614.4","0.00163175","0","1"],["104614.7","0","0","0"],["104616.5","2.59643","0","1"],["104617.7","0.05014143","0","3"],["104621.2","0.03","0","1"],["104621.8","0","0","0"],["104622.8","0","0","0"],["104628.4","0","0","0"],["104628.6","0","0","0"],["104628.7","0","0","0"],["104628.8","0","0","0"],["104628.9","0","0","0"],["104629.1","0","0","0"],["104629.4","0","0","0"],["104629.5","0","0","0"],["104629.6","0","0","0"],["104629.8","0","0","0"],["104629.9","0","0","0"],["104630","0","0","0"],["104630.1","0","0","0"],["104630.2","0","0","0"],["104630.4","0","0","0"],["104630.7","0","0","0"],["104630.8","0","0","0"]],"bids":[["104522.1","0","0","0"],["104521.7","0","0","0"],["104521","0","0","0"],["104520","0","0","0"],["104519.9","0","0","0"],["104519.8","0","0","0"],["104519.6","0","0","0"],["104518","0","0","0"],["104516.2","0","0","0"],["104516.1","0","0","0"],["104514.8","0","0","0"],["104514.2","0","0","0"],["104514.1","0","0","0"],["104514","0","0","0"],["104512.3","0","0","0"],["104512.2","0","0","0"],["104512","0","0","0"],["104511.5","0.01008157","0","1"],["104511.2","0","0","0"],["104511","0","0","0"],["104510.8","0","0","0"],["104510.6","0","0","0"],["104510.4","0","0","0"],["104510","0.00029006","0","2"],["104509.9","0","0","0"],["104509.8","0","0","0"],["104509.2","0","0","0"],["104509.1","0","0","0"],["104508.5","0","0","0"],["104508.3","0","0","0"],["104508.1","0","0","0"],["104508","0","0","0"],["104507.4","0","0","0"],["104507.2","0","0","0"],["104507.1","0","0","0"],["104506.1","0.08","0","1"],["104505.6","0","0","0"],["104505.4","0","0","0"],["104504.3","0.00001","0","1"],["104504.2","0","0","0"],["104504","0.0932","0","1"],["104503","0","0","0"],["104502.7","0.03933738","0","1"],["104502.6","0.00262657","0","1"],["104502.5","0.03434931","0","1"],["104502.3","0","0","0"],["104501.8","0","0","0"],["104501.2","0","0","0"],["104500.8","0.00956763","0","1"],["104500.5","0","0","0"],["104500.4","0.00001","0","1"],["104500.3","0","0","0"],["104499.2","0","0","0"],["104498","0","0","0"],["104497.6","0.0269475","0","1"],["104497.5","0.04668584","0","1"],["104497.2","0","0","0"],["104497.1","0","0","0"],["104496.7","0","0","0"],["104496.6","0.09592224","0","1"],["104496.1","0","0","0"],["104495.8","0.09002659","0","1"],["104495.6","0.04311416","0","1"],["104495.2","0","0","0"],["104495","0","0","0"],["104494.8","0","0","0"],["104494.6","0.08794647","0","1"],["104494.2","0","0","0"],["104493.5","0.00179975","0","2"],["104493.4","0.41073241","0","3"],["104492.4","0.16715386","0","2"],["104490.6","0","0","0"],["104490","0.19271978","0","3"],["104488.8","0","0","0"],["104488.5","0.15465605","0","3"],["104488.4","0.22452696","0","2"],["104485.4","0","0","0"],["104483.2","0","0","0"],["104482.7","0","0","0"],["104482.6","0.03934494","0","1"],["104482.1","0.23386147","0","1"],["104482","0.58854185","0","1"],["104481.9","0.77866876","0","1"],["104481.8","0.17838463","0","1"],["104481.7","0.03","0","1"],["104481.5","0","0","0"],["104480.1","0","0","0"],["104479.3","0.19242972","0","1"],["104478.5","0","0","0"],["104478","0.002","0","1"],["104477.9","0","0","0"],["104477.8","0","0","0"],["104477.5","0.03","0","1"],["104476.9","0.10856673","0","1"],["104476.8","0.17838463","0","1"],["104474.7","0.02870288","0","1"],["104473.9","0","0","0"],["104473.4","0","0","0"],["104472.7","0","0","0"],["104471.4","0.49244","0","1"],["104470.6","0","0","0"],["104470","0.48352493","0","2"],["104467.7","0","0","0"],["104467.6","0.04811439","0","1"],["104467.4","0.06993255","0","1"],["104462.7","0","0","0"],["104460.3","0.17838463","0","1"],["104459.4","0","0","0"],["104459.1","0.07213","0","1"],["104454.8","0","0","0"],["104454.5","0.04275388","0","1"],["104450.1","0","0","0"],["104448.6","0.04783815","0","1"],["104447.2","0.46802562","0","1"],["104446.4","0.07298372","0","1"],["104440.3","2.34794","0","1"],["104432.2","0","0","0"],["104432.1","0","0","0"],["104431.8","0","0","0"],["104431","0","0","0"],["104430.7","0.21573237","0","1"],["104428.3","0","0","0"],["104423","0.47439916","0","1"],["104422.8","0.002871","0","1"],["104421.4","0","0","0"],["104420.1","0","0","0"],["104420","0.00220843","0","3"],["104419.8","0.01166","0","1"],["104415.8","0","0","0"],["104415","1.65187137","0","2"],["104412.1","0","0","0"],["104404","0.01914635","0","2"],["104401.1","0","0","0"],["104399.2","0.0152","0","2"],["104399.1","0.0228","0","3"],["104384.8","0.07119851","0","1"],["104380","0.01309496","0","3"],["104377","0","0","0"],["104374.4","0.37163576","0","1"],["104368.1","0","0","0"],["104363.2","0.00478405","0","1"],["104353.5","0.00001","0","1"],["104342.3","0.02363137","0","3"],["104335.6","0.05793435","0","1"],["104335.4","0","0","0"],["104325.6","0.0579344","0","1"],["104308.3","0","0","0"],["104277.6","0.77868377","0","2"],["104276.6","0.00118236","0","1"],["104275.7","2.84056","0","1"],["104275.1","0.07298372","0","1"],["104275","0.00004692","0","1"],["104274.3","0.00001","0","1"],["104274.1","0.0001347","0","1"],["104272.9","0.00003136","0","1"],["104272","0.00002721","0","1"],["104270","0.00038892","0","2"],["104269.3","0.007986","0","1"],["104268.8","0.023","0","1"],["104268.3","0.00002454","0","1"],["104267.2","0.00001019","0","1"],["104266.6","0.01094602","0","2"],["104266.5","0.77866876","0","1"],["104266.3","0.00001","0","1"],["104265.5","0.00653561","0","3"],["104265.2","0.00002222","0","1"],["104263.5","0.03","0","1"],["104262.5","0.00002","0","2"],["104261.4","0.00002208","0","1"],["104260.9","0.01148","0","1"],["104260.1","0.04796","0","1"],["104260","0.00221814","0","3"],["104259.5","0.07298372","0","1"],["104259.2","0.00009608","0","1"],["104258.7","2.20877","0","1"],["104258.5","0.00001498","0","1"],["104257.1","0.00001436","0","1"],["104256.5","0.01160029","0","1"],["104255.8","0.77866876","0","1"],["104255.5","0.00008121","0","1"],["104255.2","0.00002044","0","2"],["104255.1","0.00002471","0","1"],["104254.8","0.00168502","0","2"],["104254.5","0.00001","0","1"],["104253.3","0.0001","0","1"],["104250","0.02793832","0","30"],["104248.9","0.00017476","0","1"],["104246.5","0.00044255","0","2"],["104245.5","0.02300636","0","1"],["104245.3","0.00001858","0","1"],["104244.5","0.77866876","0","1"],["104244","0.00108617","0","1"],["104243.3","0.00001394","0","1"]],"ts":"1747171679001","checksum":1101434934,"seqId":54227204369,"prevSeqId":54227203033}]}
{"arg":{"channel":"books","instId":"BTC-USDT"},"action":"update","data":[{"asks":[["104506.2","0.58235354","0","17"],["104507.9","0.02796","0","1"],["104508","0.0932","0","1"],["104509.9","0.12852631","0","1"],["104510","0.00001","0","1"],["104510.1","0.05202583","0","3"],["104511.2","0.01141991","0","1"],["104511.6","0.052","0","2"],["104512","0.0932","0","1"],["104512.4","0.09525181","0","1"],["104513.3","0.10209243","0","1"],["104513.9","0.0009861","0","1"],["104514.4","0","0","0"],["104515.1","0.188893","0","2"],["104515.3","0","0","0"],["104515.7","0","0","0"],["104515.9","0.23931514","0","2"],["104517.1","0","0","0"],["104517.9","0.26742984","0","3"],["104518.3","0.34036184","0","2"],["104518.6","0.14764089","0","1"],["104519.9","0","0","0"],["104520","0.00029006","0","2"],["104520.3","0","0","0"],["104520.4","0.5489356","0","2"],["104520.5","0.77866876","0","1"],["104520.6","0","0","0"],["104520.8","0","0","0"],["104521","0.19242972","0","1"],["104521.4","0.16092121","0","1"],["104521.9","0","0","0"],["104522.2","0.052","0","2"],["104522.4","0.257903","0","1"],["104523.3","0.26825008","0","1"],["104523.4","0.26977956","0","1"],["104523.9","0.02855548","0","1"],["104524.4","0.00478296","0","1"],["104525.2","0.04","0","1"],["104525.4","0.29334859","0","2"],["104526","0.0982","0","2"],["104527.2","0.13871743","0","1"],["104527.3","0.17931463","0","2"],["104527.6","0.2585615","0","1"],["104528.3","0.05561615","0","2"],["104529.6","0","0","0"],["104531.2","0","0","0"],["104531.3","0.05996122","0","1"],["104531.5","0.071747","0","1"],["104535.4","0.078","0","2"],["104536.5","0","0","0"],["104538.5","0.00610176","0","5"],["104539.6","0.111","0","3"],["104542","0.00202848","0","3"],["104542.1","0.22528816","0","2"],["104543","0.001","0","1"],["104545","0.19244373","0","2"],["104545.8","0.05277002","0","2"],["104546","0","0","0"],["104546.7","0","0","0"],["104550.1","0.00286989","0","1"],["104550.4","0.00286989","0","1"],["104554.1","0.29514486","0","2"],["104555.1","0","0","0"],["104555.7","0","0","0"],["104556.4","0","0","0"],["104559.4","0.00002482","0","1"],["104560.2","0","0","0"],["104560.7","0","0","0"],["104560.8","0","0","0"],["104564.3","0.00047841","0","1"],["104565","0.16","0","2"],["104566","0.24999999","0","5"],["104566.4","0.1","0","1"],["104567","0.61539088","0","4"],["104568","0","0","0"],["104568.7","0.0008017","0","1"],["104569","0","0","0"],["104570","0.00029006","0","2"],["104571","0.00001501","0","1"],["104572","0.00245746","0","15"],["104572.9","0","0","0"],["104573.6","0.00080262","0","1"],["104575.5","0","0","0"],["104577","0","0","0"],["104577.2","0.02214","0","1"],["104583.5","0","0","0"],["104588.3","0","0","0"],["104588.7","0.69791536","0","3"],["104606","0","0","0"],["104607.1","0.00163175","0","1"],["104609.4","4.63312812","0","6"],["104614.4","0","0","0"],["104619.1","0.00098343","0","2"],["104627.8","0","0","0"],["104628.1","0","0","0"],["104628.3","0","0","0"]],"bids":[["104511.5","0","0","0"],["104510","0","0","0"],["104506.1","0.08009","0","2"],["104506","0","0","0"],["104504.1","0.08234999","0","1"],["104502.5","0","0","0"],["104502","0.0932","0","1"],["104500.6","0.03434994","0","1"],["104497.6","0.06052712","0","2"],["104497.5","0","0","0"],["104496.6","0","0","0"],["104495.8","0","0","0"],["104495.7","0.00954353","0","1"],["104495.2","0.071747","0","1"],["104494.6","0.09215013","0","1"],["104493.8","0.100807","0","1"],["104493.7","0.00084316","0","1"],["104493.6","0.59479406","0","3"],["104493.5","0.00095659","0","1"],["104493.4","0","0","0"],["104492.6","0.08761802","0","1"],["104492.4","0.00001","0","1"],["104491.8","0","0","0"],["104491.6","0.07298372","0","1"],["104491.4","0.09748891","0","1"],["104491.1","0.14460813","0","1"],["104490.4","0.16593614","0","1"],["104488.8","0.16836538","0","1"],["104488.5","0.30000723","0","3"],["104488.4","0.05730401","0","1"],["104487.6","0.094134","0","1"],["104487.4","0.24392951","0","1"],["104486.4","0.16245003","0","2"],["104483.9","0","0","0"],["104483.8","0.27150873","0","1"],["104482.1","0","0","0"],["104481.8","0","0","0"],["104481.7","0.06","0","2"],["104480.1","0.25588091","0","1"],["104478.6","0.13871743","0","1"],["104478.5","0.17838463","0","1"],["104477.5","0.09","0","3"],["104477.4","0.1925881","0","1"],["104477.3","0.17838463","0","1"],["104476.9","0","0","0"],["104476.6","0.25136835","0","2"],["104464.5","0.00711203","0","1"],["104459.2","0.00047841","0","1"],["104458.9","1.35841483","0","1"],["104456.8","0.46727274","0","1"],["104452.5","0","0","0"],["104450.1","0.00001479","0","1"],["104443","0.22835","0","1"],["104440","0.00220843","0","3"],["104427.6","2.50010053","0","1"],["104423.8","0","0","0"],["104423.7","0.51658772","0","3"],["104411.3","0.00173828","0","1"],["104319.8","0","0","0"],["104315.2","0.00095863","0","1"],["104276.6","0","0","0"],["104257.3","0.00118236","0","1"],["104255.5","0","0","0"],["104255.2","0","0","0"],["104255.1","0","0","0"],["104254.8","0","0","0"],["104254.5","0","0","0"],["104253.3","0","0","0"],["104250","0","0","0"],["104248.9","0","0","0"],["104246.5","0","0","0"],["104245.5","0","0","0"],["104245.3","0","0","0"],["104244.5","0","0","0"],["104244","0","0","0"],["104243.3","0","0","0"]],"ts":"1747171679101","checksum":1339414293,"seqId":54227205005,"prevSeqId":54227204369}]}
{"arg":{"channel":"books","instId":"BTC-USDT"},"action":"update","data":[{"asks":[["104506.2","0.38701529","0","14"],["104510.1","0.052","0","2"],["104512.4","0","0","0"],["104513.2","0.09098262","0","1"],["104513.3","0","0","0"],["104513.9","0","0","0"],["104514","0.09886796","0","3"],["104514.1","0.16326533","0","3"],["104515.1","0","0","0"],["104515.8","0.0009861","0","1"],["104515.9","0.43362914","0","4"],["104517.9","0.11477476","0","2"],["104518.3","0.17838463","0","1"],["104518.5","0.00001501","0","1"],["104518.6","0","0","0"],["104518.7","0.15328149","0","1"],["104519.1","0.16002739","0","1"],["104519.3","0.00093","0","1"],["104519.4","0.15774745","0","1"],["104520.4","0.59793114","0","2"],["104521.4","0","0","0"],["104522.2","0.2090051","0","3"],["104522.4","0","0","0"],["104523.2","0.24215751","0","1"],["104523.3","0","0","0"],["104523.4","0","0","0"],["104523.9","0.00478296","0","1"],["104524","0.08419536","0","2"],["104524.1","0.26211761","0","2"],["104524.2","0.2396151","0","2"],["104524.4","0","0","0"],["104524.5","0.00860126","0","4"],["104526.3","0.02855484","0","1"],["104526.9","0.02855467","0","1"],["104527.2","0","0","0"],["104527.3","0.17838463","0","1"],["104527.6","0","0","0"],["104528.3","0.00002714","0","1"],["104528.4","0.23485597","0","1"],["104530.3","0.13871421","0","1"],["104532.5","0","0","0"],["104534.9","0.05558551","0","1"],["104535.5","0.0002184","0","2"],["104537","0.05558437","0","1"],["104539.6","0.141","0","4"],["104544.7","0.00013822","0","1"],["104544.9","0.7798555","0","2"],["104550","0.011799","0","9"],["104561","0.1","0","1"],["104564","0.16","0","2"],["104565","0.07999999","0","1"],["104566","0.17","0","4"],["104566.4","0","0","0"],["104602.6","4.62254668","0","1"],["104609.4","0.01058144","0","5"],["104626.9","0","0","0"],["104627","0","0","0"],["104627.2","0","0","0"],["104627.4","0","0","0"]],"bids":[["104506.1","0.16933162","0","5"],["104506","0.0932","0","1"],["104505.9","0.03136074","0","1"],["104498.3","0.0005","0","1"],["104497.7","0.00084316","0","1"],["104497.6","0.26376042","0","1"],["104495.4","0.08754272","0","1"],["104495.1","0.03829301","0","1"],["104494.6","0.09509291","0","1"],["104494","0.77866876","0","1"],["104493.8","0","0","0"],["104493.7","0","0","0"],["104493.6","0.36329119","0","3"],["104493.4","0.09288092","0","1"],["104493","0.00097","0","1"],["104492.6","0","0","0"],["104492.2","0.10244039","0","1"],["104491.9","0.15170738","0","1"],["104491.4","0","0","0"],["104491.2","0.16535247","0","1"],["104491.1","0","0","0"],["104490.4","0","0","0"],["104490.1","0.00478296","0","1"],["104489.9","0.34742422","0","1"],["104489.6","0.15440256","0","1"],["104488.8","0","0","0"],["104488.5","0.22361596","0","3"],["104488.2","0.43296081","0","2"],["104487.8","0.00097","0","1"],["104487.4","0","0","0"],["104487.2","0.15441011","0","1"],["104486.4","0.000015","0","1"],["104484.6","0.2726656","0","1"],["104483.8","0","0","0"],["104482.6","0.04125494","0","2"],["104480.9","0.2516295","0","1"],["104480.7","0.13871421","0","1"],["104480.1","0","0","0"],["104478.6","0","0","0"],["104477.5","0.12","0","4"],["104477.4","0.1944981","0","2"],["104476.1","0.00005","0","1"],["104450.1","0","0","0"],["104423.8","0.01059598","0","1"],["104423.7","0.51649139","0","2"],["104420.1","0.01059598","0","1"],["104415.8","0.00063897","0","1"],["104412.1","0.00083933","0","1"],["104410.2","0.01059598","0","1"],["104395.3","0.01059598","0","1"],["104389","0.01059598","0","1"],["104370.1","0","0","0"],["104291.3","0.00097707","0","1"],["104265.2","0","0","0"],["104263.5","0","0","0"],["104262.5","0","0","0"],["104261.4","0","0","0"],["104260.9","0","0","0"],["104260.1","0","0","0"],["104260","0","0","0"],["104259.5","0","0","0"],["104259.2","0","0","0"],["104258.7","0","0","0"],["104258.5","0","0","0"],["104257.3","0","0","0"],["104257.1","0","0","0"],["104256.5","0","0","0"],["104255.8","0","0","0"]],"ts":"1747171679201","checksum":2039464748,"seqId":54227205331,"prevSeqId":54227205005}]}
