{"arg":{"channel":"books","instId":"BTC-USDT"},"action":"update","data":[{"asks":[["104460.1","0.37678228","0","9"],["104462","0","0","0"],["104463","0.01807693","0","1"],["104463.9","0","0","0"],["104466","0.0932","0","1"],["104466.8","0","0","0"],["104466.9","0","0","0"],["104467.6","0","0","0"],["104468.6","0","0","0"],["104468.8","0.036","0","1"],["104468.9","0","0","0"],["104469.1","0.02882623","0","1"],["104469.3","0.036","0","1"],["104469.5","0.10013375","0","1"],["104469.9","0.00011435","0","1"],["104470.1","0.03645","0","2"],["104470.2","0.09773251","0","1"],["104470.6","0.234","0","1"],["104470.8","0","0","0"],["104471.2","0.09159146","0","1"],["104471.7","0.09155249","0","1"],["104472.1","0","0","0"],["104472.4","0","0","0"],["104472.6","0.00854664","0","1"],["104473.9","0","0","0"],["104474.7","0.15813129","0","2"],["104475","0.17021197","0","1"],["104475.2","0.15290714","0","1"],["104475.3","0.00478537","0","1"],["104475.4","0.00093","0","1"],["104475.8","0","0","0"],["104476.5","0","0","0"],["104477.6","0","0","0"],["104477.9","0.16347347","0","1"],["104478.4","0.23509021","0","1"],["104479.8","0","0","0"],["104479.9","0","0","0"],["104480.2","0.2557012","0","1"],["104481.6","0","0","0"],["104482.3","0.13877643","0","1"],["104482.8","0","0","0"],["104483.4","0","0","0"],["104483.9","0","0","0"],["104484.2","0.41254707","0","2"],["104485","0.19242972","0","1"],["104488.9","0.36234807","0","2"],["104489","0","0","0"],["104490","0.00029006","0","2"],["104490.2","0","0","0"],["104491","0.00191","0","1"],["104493","0.002","0","2"],["104494","0.00387","0","2"],["104502.1","0.071784","0","2"],["104513","0","0","0"],["104514","0","0","0"],["104515","0.00004786","0","1"],["104515.3","0.15125158","0","2"],["104517","0.15999999","0","2"],["104518","0.07999999","0","1"],["104519","0.17","0","4"],["104520","0.08830992","0","6"],["104523","0","0","0"],["104523.8","0.00056666","0","1"],["104531","0.33117244","0","1"],["104535.7","0.5988106","0","1"],["104583.6","0.24516208","0","3"],["104588.7","0","0","0"],["104611.3","0.00005484","0","1"],["104612.1","0.01059606","0","1"],["104612.2","0.01407867","0","1"],["104612.6","0.229704","0","1"],["104612.9","0.00001168","0","1"]],"bids":[["104460","0.4941","0","9"],["104459.3","0.0383585","0","1"],["104458.3","0.08610922","0","1"],["104458.1","0","0","0"],["104454.6","0","0","0"],["104453.9","0","0","0"],["104452.3","0.0017649","0","2"],["104452.2","0","0","0"],["104450.7","0.19036867","0","2"],["104449.2","0.28257184","0","2"],["104448.5","0.09771611","0","1"],["104448.1","0","0","0"],["104447.5","0.22365442","0","2"],["104447.2","0.20336404","0","2"],["104446.6","0","0","0"],["104446.5","0.30237497","0","1"],["104445.9","0","0","0"],["104445.7","0.16693687","0","1"],["104444.9","0.01088273","0","1"],["104444.8","0.039411","0","3"],["104444.6","0.07298372","0","1"],["104443.7","0.00575537","0","2"],["104443.4","0.24963779","0","1"],["104443.1","0","0","0"],["104442.9","0.1667297","0","1"],["104440.8","0.03001","0","2"],["104440.4","0","0","0"],["104438.6","0","0","0"],["104438.1","0","0","0"],["104436.7","0.60072005","0","3"],["104434.9","0","0","0"],["104434.1","0","0","0"],["104434","0.00056666","0","1"],["104432.6","0.13877931","0","1"],["104432.1","0","0","0"],["104424.4","0.413504","0","1"],["104374.3","0.00056666","0","1"],["104358.8","0.07298372","0","1"],["104270.3","0.00003386","0","2"],["104270","0.00038892","0","2"],["104269.9","0.0000785","0","2"],["104269.6","0.00001237","0","1"]],"ts":"1747171022101","checksum":839448730,"seqId":54226734745,"prevSeqId":54226734446}]}
{"arg":{"channel":"books","instId":"BTC-USDT"},"action":"update","data":[{"asks":[["104460.1","0","0","0"],["104463","0.08917693","0","2"],["104464","0","0","0"],["104467.8","0.0657855","0","2"],["104468.5","0.00001","0","1"],["104468.8","0","0","0"],["104469.1","0","0","0"],["104469.3","0","0","0"],["104469.5","0","0","0"],["104469.9","0","0","0"],["104470","0.09349006","0","3"],["104470.2","0","0","0"],["104470.6","0","0","0"],["104470.9","0","0","0"],["104471.2","0","0","0"],["104471.7","0","0","0"],["104472.7","0.00011435","0","1"],["104472.9","0.09890218","0","1"],["104473.5","0.234","0","1"],["104473.6","0.09206869","0","1"],["104474.2","0.01914246","0","1"],["104474.6","0.09248604","0","1"],["104474.7","0","0","0"],["104475","0","0","0"],["104475.1","0.09192481","0","1"],["104475.2","0","0","0"],["104475.3","0","0","0"],["104476.2","0","0","0"],["104476.4","0.0357134","0","3"],["104477.9","0","0","0"],["104478.1","0.16330517","0","1"],["104478.4","0.16401525","0","1"],["104478.6","0.1592575","0","1"],["104479.4","0.28190564","0","2"],["104480.2","0","0","0"],["104480.7","0","0","0"],["104481.1","0.052","0","2"],["104481.3","0.16359005","0","1"],["104481.8","0.24685695","0","1"],["104482.2","0.03828493","0","1"],["104482.3","0","0","0"],["104482.6","0.06471702","0","2"],["104482.7","0.04316151","0","1"],["104483.1","0.1830789","0","2"],["104483.6","0.24601145","0","1"],["104484.1","0","0","0"],["104484.2","0","0","0"],["104485","0","0","0"],["104487","0","0","0"],["104487.6","0.24536336","0","2"],["104488.9","0.005","0","1"],["104491.4","0.13876602","0","1"],["104493","0","0","0"],["104494","0.00287","0","1"],["104496.2","0.00711203","0","1"],["104497.7","0","0","0"],["104499.4","0.19242972","0","1"],["104499.6","0.42844324","0","1"],["104500.7","0","0","0"],["104501.8","0.04417434","0","1"],["104504","0.07299898","0","2"],["104504.2","0.09573","0","1"],["104506","0.00206","0","3"],["104507","0.001","0","1"],["104509.8","0.90352473","0","3"],["104510.9","0","0","0"],["104512.6","0","0","0"],["104514.8","0.77866876","0","1"],["104515.3","0.05650539","0","1"],["104517","0","0","0"],["104517.4","0","0","0"],["104517.7","0.1","0","1"],["104518","0","0","0"],["104518.2","0","0","0"],["104518.5","0.000015","0","1"],["104519","0","0","0"],["104520","0.00330992","0","4"],["104521.4","0.00155176","0","1"],["104529","0.160015","0","3"],["104530","0.08029005","0","3"],["104541.6","1.45143609","0","2"],["104541.7","0","0","0"],["104542.3","0","0","0"],["104546.2","0.46010773","0","1"],["104555.2","5.99755387","0","1"],["104613","0.000015","0","1"],["104614.9","0.0000105","0","1"],["104615","0.01099627","0","1"],["104615.1","1.02326418","0","3"],["104615.3","0.29225276","0","4"],["104615.5","0.00001","0","1"],["104616.6","0.00007797","0","4"],["104617.6","0.00003056","0","2"],["104617.7","0.01099591","0","1"],["104617.8","0.01099559","0","1"],["104618","0.00001632","0","1"],["104618.5","0.00009552","0","1"],["104619.3","0.04304781","0","1"],["104620","0.00222603","0","4"],["104621.3","0.01099559","0","1"]],"bids":[["104462.9","1.18838285","0","18"],["104462.7","0.07298372","0","1"],["104462","0.0932","0","1"],["104460.2","0.09155982","0","1"],["104460","0.14522","0","5"],["104459.4","0.02342091","0","1"],["104458.3","0","0","0"],["104457.3","0","0","0"],["104456.2","0.0017149","0","1"],["104456.1","0.14574297","0","2"],["104455.6","0.1041188","0","2"],["104454.1","0.19469406","0","2"],["104452.8","0.0017149","0","1"],["104452.6","0.10036491","0","1"],["104452.5","0.00955832","0","1"],["104452.3","0.00005","0","1"],["104451.9","0.09518659","0","1"],["104451","0.00478537","0","1"],["104450.9","0.1518639","0","1"],["104450.7","0","0","0"],["104450.6","0.15144298","0","1"],["104449.6","0","0","0"],["104449.5","0.01096915","0","1"],["104449.2","0.19242972","0","1"],["104449.1","0.14933775","0","1"],["104448.5","0","0","0"],["104447.5","0","0","0"],["104447.2","0.05329894","0","1"],["104446.9","0.45767378","0","1"],["104446.8","0.25370293","0","1"],["104446.5","0","0","0"],["104446.3","0.16225375","0","1"],["104445.7","0","0","0"],["104444.9","0","0","0"],["104444.8","0.000025","0","2"],["104444.1","0.24774029","0","1"],["104443.7","0.00097","0","1"],["104443.4","0","0","0"],["104442.9","0","0","0"],["104442.5","0.13876602","0","1"],["104440.1","0.24024871","0","1"],["104436.7","0.35282315","0","2"],["104436.4","0.25396301","0","1"],["104433.6","0","0","0"],["104432.6","0","0","0"],["104424.5","0.21089903","0","2"],["104414.7","0.002871","0","1"],["104407.2","0.0022","0","1"],["104401.5","0","0","0"],["104394","0.1205","0","1"],["104366.8","0","0","0"],["104364.2","0","0","0"],["104363.8","0.0022","0","1"],["104348.8","0.00064048","0","1"],["104346.2","0","0","0"],["104343.3","0.00084085","0","1"],["104340.5","0","0","0"],["104280.1","0","0","0"],["104271.9","0","0","0"],["104271.8","0","0","0"],["104271.5","0","0","0"],["104271.1","0","0","0"],["104270.8","0","0","0"],["104270.5","0","0","0"],["104270.3","0","0","0"],["104270","0","0","0"],["104269.9","0","0","0"],["104269.6","0","0","0"]],"ts":"1747171022201","checksum":161470026,"seqId":54226735241,"prevSeqId":54226734745}]}
{"arg":{"channel":"books","instId":"BTC-USDT"},"action":"update","data":[{"asks":[["104466","0","0","0"],["104467.8","0.02832415","0","1"],["104472.7","0","0","0"],["104472.9","0","0","0"],["104473.4","0.00011435","0","1"],["104473.6","0.095491","0","1"],["104473.9","0.01","0","1"],["104474.2","0.11174205","0","2"],["104474.6","0","0","0"],["104475.1","0","0","0"],["104475.2","0.12892984","0","2"],["104475.8","0.08991612","0","1"],["104478.1","0","0","0"],["104478.4","0","0","0"],["104478.6","0","0","0"],["104478.7","0.14359883","0","1"],["104479.1","0.15669473","0","1"],["104479.2","0.17005837","0","2"],["104481.3","0","0","0"],["104481.8","0","0","0"],["104482","0.24742082","0","2"],["104482.5","0.2499281","0","1"],["104483","0.00478537","0","1"],["104483.1","0.17829353","0","1"],["104483.6","0","0","0"],["104484.2","0.24020012","0","1"],["104487.6","0.0000125","0","1"],["104488.3","0.26698439","0","3"],["104488.7","0.19242972","0","1"],["104489.5","0.16533879","0","1"],["104491.3","0.13876677","0","1"],["104491.4","0","0","0"],["104491.8","0.00287107","0","1"],["104498.4","0","0","0"],["104502","0.0001398","0","1"],["104506","0.00006","0","1"],["104507","0","0","0"],["104509.8","1.30655004","0","2"],["104511","0.002","0","2"],["104512","0.001","0","1"],["104513.1","1.4055583","0","1"],["104529","0.000015","0","1"],["104530","0.16029005","0","4"],["104531","0.41117243","0","2"],["104544.4","2.57509299","0","1"],["104546.2","0","0","0"],["104555.2","0","0","0"],["104562","6.06737387","0","2"],["104620","0","0","0"],["104621.3","0","0","0"]],"bids":[["104456.1","0.16768407","0","2"],["104454.7","0.18628982","0","2"],["104454.1","0","0","0"],["104453.3","0.08865271","0","1"],["104452.8","0","0","0"],["104452.6","0.09495804","0","1"],["104451.9","0","0","0"],["104451.6","0.16865757","0","1"],["104451.2","0.15108814","0","1"],["104451","0","0","0"],["104450.9","0","0","0"],["104450.6","0","0","0"],["104450","0.00507543","0","3"],["104449.7","0.16092264","0","1"],["104449.1","0","0","0"],["104447.5","0.24586487","0","1"],["104447.3","0.071774","0","1"],["104447","0.16292646","0","1"],["104446.9","0.34224019","0","1"],["104446.8","0","0","0"],["104446.3","0","0","0"],["104444.7","0.24055126","0","1"],["104444.3","0.096706","0","1"],["104444.1","0","0","0"],["104442.5","0","0","0"],["104442.4","0.50784855","0","2"],["104440.8","0.282964","0","3"],["104440.1","0","0","0"],["104346.2","0.01059531","0","1"],["104271.9","0.00004632","0","2"]],"ts":"1747171022301","checksum":1770318969,"seqId":54226735368,"prevSeqId":54226735241}]}
{"arg":{"channel":"books","instId":"BTC-USDT"},"action":"update","data":[{"asks":[["104463","0.08926693","0","3"],["104467.8","0","0","0"],["104470.1","0.00045","0","1"],["104472.6","0","0","0"],["104473.6","0","0","0"],["104473.9","0.10795541","0","2"],["104474.2","0.01914246","0","1"],["104474.6","0.10022043","0","1"],["104475.2","0.03746135","0","1"],["104475.4","0.02925415","0","2"],["104475.6","0.09612489","0","1"],["104475.8","0","0","0"],["104476.1","0.13487271","0","2"],["104476.4","0.00501","0","2"],["104478.4","0.03065974","0","1"],["104478.7","0","0","0"],["104479.1","0.14789549","0","1"],["104479.2","0.53483497","0","3"],["104479.4","0.43381448","0","3"],["104479.6","0.15554449","0","1"],["104482","0.0932","0","1"],["104482.2","0.07664343","0","2"],["104482.4","0.19004604","0","3"],["104482.5","0","0","0"],["104482.8","0.2576286","0","1"],["104483","0","0","0"],["104484.1","0.00478537","0","1"],["104484.2","0.34724008","0","2"],["104484.6","0.25933547","0","1"],["104484.8","0.04104265","0","2"],["104488.3","0.00373804","0","2"],["104488.6","0.24571428","0","1"],["104490.9","0","0","0"],["104491.3","0","0","0"],["104493.1","0.13876353","0","1"],["104493.9","0.0001303","0","1"],["104494.3","0","0","0"],["104496","0.002","0","2"],["104497","0.001","0","1"],["104498","0.36908178","0","1"],["104499.6","0.63933093","0","2"],["104503.6","0.77866876","0","1"],["104511","0","0","0"],["104512","0","0","0"],["104541.6","0.40644271","0","2"],["104562","0.06982","0","1"],["104565.4","5.99755387","0","1"],["104567.5","0","0","0"],["104570.3","0.00032734","0","2"],["104618.5","0","0","0"],["104619.3","0","0","0"]],"bids":[["104462.1","0.0234203","0","1"],["104460","0.14633114","0","5"],["104456.1","0.16966511","0","2"],["104455.1","0.18353917","0","2"],["104454.7","0","0","0"],["104453.6","0.09511833","0","1"],["104453.3","0","0","0"],["104452.9","0.09784653","0","1"],["104452.6","0","0","0"],["104451.9","0.16865274","0","1"],["104451.7","0.00478537","0","1"],["104451.6","0.15049917","0","1"],["104451.2","0","0","0"],["104450.1","0.16724949","0","1"],["104450","0.00029006","0","2"],["104449.7","0","0","0"],["104447.8","0.23738066","0","1"],["104447.5","0","0","0"],["104447.4","0.14586824","0","1"],["104447","0","0","0"],["104445.1","0.25656756","0","1"],["104444.7","0.13876353","0","1"],["104442.4","0.36908178","0","1"],["104441.1","0.26695109","0","1"],["104440.8","0.03001","0","2"],["104397.9","0.00002963","0","1"],["104396.6","0","0","0"],["104363.6","0.00010874","0","1"],["104360.9","0","0","0"],["104311.1","0.00095706","0","1"],["104308.6","0","0","0"],["104272.3","0","0","0"],["104272.2","0","0","0"],["104272","0","0","0"],["104271.9","0","0","0"]],"ts":"1747171022401","checksum":-1200350742,"seqId":54226735546,"prevSeqId":54226735368}]}
{"arg":{"channel":"books","instId":"BTC-USDT"},"action":"update","data":[{"asks":[["104463","0.21196693","0","5"],["104466","0.0932","0","1"],["104472","0.09466117","0","1"],["104472.6","0.00011435","0","1"],["104472.7","0.09781637","0","1"],["104472.8","0.0484426","0","2"],["104473.4","0.31055272","0","1"],["104473.7","0.09674223","0","1"],["104473.9","0","0","0"],["104474.2","0.11479909","0","2"],["104474.6","0","0","0"],["104475.6","0","0","0"],["104476.1","0.04","0","1"],["104476.4","0.03571341","0","3"],["104476.5","0.000015","0","1"],["104477.2","0.18855287","0","2"],["104477.5","0.15574118","0","1"],["104477.7","0.15357643","0","1"],["104478","0.1315585","0","2"],["104478.2","0.19242972","0","1"],["104478.4","0","0","0"],["104479","0.36908178","0","1"],["104479.1","0","0","0"],["104479.4","0.27190564","0","1"],["104479.6","0","0","0"],["104479.9","0.00478537","0","1"],["104480.5","0.20527762","0","2"],["104480.9","0.23043803","0","1"],["104482.2","0.03828493","0","1"],["104482.4","0.0360125","0","2"],["104482.7","0.31168789","0","2"],["104482.8","0","0","0"],["104484.1","0","0","0"],["104484.2","0.21029984","0","1"],["104484.6","0","0","0"],["104486.7","0.2605792","0","1"],["104487","0.000015","0","1"],["104488.6","0","0","0"],["104489.5","0.37109185","0","2"],["104491.4","0.13876507","0","1"],["104491.7","0.00287107","0","1"],["104491.8","0","0","0"],["104493","0.77866876","0","1"],["104493.1","0","0","0"],["104493.2","0.17829353","0","1"],["104495","0.002","0","2"],["104496","0.001","0","1"],["104497","0","0","0"],["104504.2","0","0","0"],["104522.9","0.02091112","0","1"],["104525.3","0.80030923","0","2"],["104541.6","0.234","0","1"],["104555.2","5.99755387","0","1"],["104560.9","0.00023767","0","1"],["104565.4","0","0","0"],["104616.6","0","0","0"],["104617.6","0","0","0"],["104617.7","0","0","0"],["104617.8","0","0","0"],["104618","0","0","0"]],"bids":[["104462.9","1.1655594","0","17"],["104459.3","0","0","0"],["104456.1","0.11397507","0","2"],["104455.1","0","0","0"],["104453.6","0","0","0"],["104453.2","0.19087057","0","3"],["104452.9","0","0","0"],["104452.1","0.31734555","0","2"],["104451.9","0","0","0"],["104451.7","0.088857","0","1"],["104451.6","0","0","0"],["104451","0.10065809","0","1"],["104450.2","0.02929425","0","1"],["104450.1","0","0","0"],["104450","0.16348039","0","3"],["104449.7","0.1509049","0","1"],["104448.8","0.00001","0","1"],["104448.2","0.15796441","0","1"],["104447.8","0","0","0"],["104447.4","0.00478537","0","1"],["104446.9","0.52526397","0","2"],["104445.9","0.25046711","0","1"],["104445.5","0.16127796","0","1"],["104445.1","0","0","0"],["104444.7","0","0","0"],["104443.2","0.24422978","0","1"],["104442.5","0.13876529","0","1"],["104441.1","0","0","0"],["104439.2","0.25400985","0","1"],["104272.3","0.00001222","0","1"],["104272.2","0.00033769","0","1"]],"ts":"1747171022501","checksum":1634076562,"seqId":54226735664,"prevSeqId":54226735546}]}
{"arg":{"channel":"books","instId":"BTC-USDT"},"action":"update","data":[{"asks":[["104463","0.20876693","0","4"],["104467.7","0.19242972","0","1"],["104472","0.09584476","0","1"],["104472.7","0.09659928","0","1"],["104473.4","0.4269494","0","2"],["104473.7","0.09679193","0","1"],["104474.2","0.1143732","0","2"],["104474.4","0.03070401","0","1"],["104477.2","0.17982286","0","2"],["104477.5","0.15522061","0","1"],["104477.7","0.15016066","0","1"],["104479.4","0","0","0"],["104480.5","0.19437816","0","2"],["104480.9","0.2393355","0","1"],["104482.5","0.77866876","0","1"],["104482.7","0.28999829","0","2"],["104483","0.25231351","0","1"],["104485.3","0.01","0","1"],["104486.7","0.26498544","0","1"],["104488.6","0.13876849","0","1"],["104491.4","0","0","0"],["104570.3","0.00023506","0","1"],["104572","0.44292909","0","18"],["104608.6","0","0","0"],["104615.1","0","0","0"],["104615.3","0","0","0"],["104615.5","0","0","0"]],"bids":[["104462.7","0","0","0"],["104462","0.1315585","0","2"],["104456.1","0.11722216","0","2"],["104455.2","0.00521051","0","5"],["104453.2","0.19997931","0","3"],["104452.1","0.14735374","0","1"],["104451.7","0.10007094","0","1"],["104451","0.09886752","0","1"],["104450","0.16913582","0","3"],["104449.7","0.15522597","0","1"],["104449.2","0","0","0"],["104448.2","0.1515672","0","1"],["104446.9","0.34224019","0","1"],["104445.9","0.25309158","0","1"],["104445.5","0.15579829","0","1"],["104443.2","0.26231964","0","1"],["104442.5","0","0","0"],["104442.4","0","0","0"],["104440.9","0.13876849","0","1"],["104440","0.41946241","0","5"],["104439.2","0.24542766","0","1"],["104436.7","0.22453721","0","1"],["104436.4","0","0","0"],["104272","0.00086241","0","4"],["104271.9","0.00004632","0","2"],["104271.8","0.0000102","0","1"],["104271.5","0.00030759","0","1"]],"ts":"1747171022601","checksum":-168156972,"seqId":54226735803,"prevSeqId":54226735664}]}
{"arg":{"channel":"books","instId":"BTC-USDT"},"action":"update","data":[{"asks":[["104463","0.21196693","0","5"],["104469.9","0.11179672","0","1"],["104471.9","0.00011435","0","1"],["104472.1","0.03070468","0","1"],["104472.6","0","0","0"],["104480.4","0.16413274","0","2"],["104480.5","0.04","0","1"],["104482.7","0.24683678","0","1"],["104484.2","0.31985583","0","2"],["104487.9","0.13877037","0","1"],["104488.6","0","0","0"],["104535.7","0","0","0"],["104551.9","6.00386612","0","2"],["104555.2","0","0","0"]],"bids":[["104462.9","1.0668094","0","16"],["104462.1","0","0","0"],["104455.2","0.00308017","0","3"],["104454.1","0.04122026","0","1"],["104452.1","0.26351743","0","2"],["104445.5","0","0","0"],["104445.4","0.15149183","0","1"],["104440.9","0","0","0"],["104439.3","0.13877037","0","1"]],"ts":"1747171022701","checksum":1271688922,"seqId":54226735861,"prevSeqId":54226735803}]}
{"arg":{"channel":"books","instId":"BTC-USDT"},"action":"update","data":[{"asks":[["104479.9","0","0","0"],["104481.9","0.00478537","0","1"],["104502.1","0.00001","0","1"],["104545.1","6.00385612","0","1"],["104551.9","0.00001","0","1"],["104570.8","0.00009172","0","1"],["104614.9","0","0","0"],["104615","0","0","0"]],"bids":[["104460","0.14745229","0","6"],["104455.2","0.002015","0","2"],["104449.8","0.00478537","0","1"],["104447.4","0","0","0"],["104446.9","0.48691285","0","2"],["104443.3","0.36908178","0","1"],["104271.5","0","0","0"]],"ts":"1747171022801","checksum":282283102,"seqId":54226735875,"prevSeqId":54226735861}]}
{"arg":{"channel":"books","instId":"BTC-USDT"},"action":"update","data":[{"asks":[["104469.9","0","0","0"],["104471.9","0","0","0"],["104472","0","0","0"],["104472.7","0","0","0"],["104473.3","0.00011435","0","1"],["104473.4","0.26926596","0","1"],["104473.7","0","0","0"],["104474.2","0.01914246","0","1"],["104477.2","0.036","0","1"],["104477.5","0","0","0"],["104477.7","0","0","0"],["104478.6","0.071777","0","1"],["104480.4","0.00001","0","1"],["104480.9","0","0","0"],["104482.7","0","0","0"],["104483","0","0","0"],["104486.7","0","0","0"],["104516","0.17","0","4"],["104517","0.085","0","2"],["104614.9","0.0000105","0","1"],["104615","0.01099627","0","1"],["104615.1","1.02326418","0","3"],["104615.3","0.29225276","0","4"],["104615.5","0.00001","0","1"],["104616.6","0.00007797","0","4"],["104617.6","0.00003056","0","2"]],"bids":[["104462.9","1.0672494","0","17"],["104462.1","0.14208463","0","1"],["104461.7","0.07298372","0","1"],["104460.2","0","0","0"],["104459.1","0.02715442","0","1"],["104456.1","0.05919437","0","1"],["104455.6","0.07298372","0","1"],["104453.2","0.01077569","0","1"],["104452.1","0.07956344","0","1"],["104451.7","0","0","0"],["104451","0","0","0"],["104450","0.00029006","0","2"],["104449.7","0","0","0"],["104448.2","0","0","0"],["104446.9","0.34224019","0","1"],["104445.9","0","0","0"],["104445.4","0","0","0"],["104443.2","0","0","0"],["104440","0.18050196","0","4"],["104439.2","0","0","0"],["104271.5","0.00030759","0","1"],["104271.1","0.00001029","0","1"],["104270.8","0.00022348","0","1"],["104270.5","0.00012512","0","2"],["104270.3","0.00003386","0","2"],["104270","0.00038892","0","2"]],"ts":"1747171022901","checksum":371613239,"seqId":54226735926,"prevSeqId":54226735875}]}
{"arg":{"channel":"books","instId":"BTC-USDT"},"action":"update","data":[{"asks":[["104463","0.21201479","0","6"],["104484.2","0.21029984","0","1"],["104487.9","0","0","0"],["104489.4","0.13876778","0","1"],["104516","0","0","0"],["104517","0.16","0","2"],["104518","0.24999999","0","5"],["104519","0.085","0","2"],["104530","0.00029006","0","2"],["104531","0.33117244","0","1"],["104617.6","0","0","0"]],"bids":[["104462.9","1.16604726","0","19"],["104456.2","0","0","0"],["104452.8","0.0017149","0","1"],["104449.2","0.19242972","0","1"],["104441.7","0.13876778","0","1"],["104439.3","0","0","0"],["104270","0","0","0"]],"ts":"1747171023001","checksum":-1030762145,"seqId":54226735976,"prevSeqId":54226735926}]}
{"arg":{"channel":"books","instId":"BTC-USDT"},"action":"update","data":[{"asks":[["104463","0.20881479","0","5"],["104495","0","0","0"],["104496","0","0","0"],["104497","0.002","0","2"],["104498","0.37008178","0","2"],["104523.2","0.00056666","0","1"],["104523.8","0","0","0"],["104581.9","0.01116306","0","2"],["104583.6","0.24459542","0","2"],["104617.6","0.00003056","0","2"]],"bids":[["104452.1","0.12734692","0","2"],["104447.3","0","0","0"],["104444.3","0","0","0"],["104434.8","0.00056666","0","1"],["104434","0","0","0"],["104376.1","0.00056666","0","1"],["104374.3","0","0","0"],["104270","0.00038892","0","2"],["104269.9","0.0000785","0","2"]],"ts":"1747171023101","checksum":1269414699,"seqId":54226736019,"prevSeqId":54226735976}]}
{"arg":{"channel":"books","instId":"BTC-USDT"},"action":"update","data":[{"asks":[["104463","0.21201479","0","6"],["104479.9","0.00478537","0","1"],["104481.6","0.01","0","1"],["104481.9","0","0","0"],["104489.4","0","0","0"],["104491.4","0.13876653","0","1"],["104495","0.002","0","2"],["104496","0.001","0","1"],["104497","0","0","0"],["104498","0.36908178","0","1"],["104515","0.16004786","0","3"],["104516","0.07999999","0","1"],["104517","0","0","0"],["104518","0.17","0","4"],["104616.6","0","0","0"],["104617.6","0","0","0"]],"bids":[["104449.8","0","0","0"],["104447.9","0.071777","0","1"],["104447.3","0.00478537","0","1"],["104444.6","0.16969372","0","2"],["104442.4","0.13876653","0","1"],["104441.7","0","0","0"],["104363.9","0.0000975","0","1"],["104363.6","0","0","0"],["104269.9","0","0","0"]],"ts":"1747171023201","checksum":-1761607698,"seqId":54226736049,"prevSeqId":54226736019}]}
{"arg":{"channel":"books","instId":"BTC-USDT"},"action":"update","data":[{"asks":[["104487.9","0.13876892","0","1"],["104491.4","0","0","0"]],"bids":[["104462.9","1.16969726","0","20"],["104449.5","0","0","0"],["104442.4","0","0","0"],["104440.1","0.13876892","0","1"],["104428.8","0.00001","0","1"]],"ts":"1747171023401","checksum":787763438,"seqId":54226736102,"prevSeqId":54226736049}]}
{"arg":{"channel":"books","instId":"BTC-USDT"},"action":"update","data":[{"asks":[["104477.9","0.00478537","0","1"],["104479.9","0","0","0"],["104516","0.17999999","0","3"],["104517","0.05","0","1"],["104518","0.07","0","2"],["104519","0.035","0","1"],["104615.5","0","0","0"]],"bids":[["104447.3","0","0","0"],["104445.4","0.00478537","0","1"],["104397.1","0.22835","0","1"],["104270","0","0","0"]],"ts":"1747171023501","checksum":787763438,"seqId":54226736113,"prevSeqId":54226736102}]}
{"arg":{"channel":"books","instId":"BTC-USDT"},"action":"update","data":[{"asks":[["104463","0.08931479","0","4"],["104466","0","0","0"],["104467.7","0","0","0"],["104472.1","0","0","0"],["104473.4","0.20050157","0","1"],["104474.4","0","0","0"],["104477.9","0","0","0"],["104478.3","0.03065977","0","1"],["104478.6","0","0","0"],["104480.5","0","0","0"],["104484.1","0.00478537","0","1"],["104485.3","0","0","0"],["104485.7","0.08316027","0","2"],["104487.9","0","0","0"],["104497.8","0.1387602","0","1"],["104497.9","0","0","0"],["104545.1","0","0","0"],["104551.9","6.00386612","0","2"],["104615.5","0.00001","0","1"],["104616.6","0.00007797","0","4"],["104617.6","0.00003056","0","2"],["104617.7","0.01099591","0","1"],["104617.8","0.01099559","0","1"],["104618","0.00001632","0","1"],["104618.5","0.00009552","0","1"]],"bids":[["104461.8","0.02342038","0","1"],["104459.1","0","0","0"],["104453.2","0.04845551","0","2"],["104450.3","0.00478537","0","1"],["104447.3","0.1387602","0","1"],["104445.4","0","0","0"],["104443.6","0","0","0"],["104440.1","0","0","0"],["104270","0.00038892","0","2"]],"ts":"1747171023601","checksum":507518352,"seqId":54226736178,"prevSeqId":54226736113}]}
{"arg":{"channel":"books","instId":"BTC-USDT"},"action":"update","data":[{"asks":[["104473.3","0","0","0"],["104473.4","0","0","0"],["104475.2","0","0","0"],["104475.8","0.00011435","0","1"],["104477.5","0.071777","0","1"],["104480.1","0.036","0","1"],["104481.1","0.036","0","1"],["104482.4","0.07347385","0","3"],["104494.4","0.13876194","0","1"],["104497.8","0","0","0"],["104516","0.07999999","0","1"],["104517","0","0","0"],["104518","0.17","0","4"],["104519","0.085","0","2"],["104551.9","0.00001","0","1"],["104555.2","6.00385612","0","1"],["104619.3","0.04304781","0","1"]],"bids":[["104447.3","0","0","0"],["104444.7","0.13876194","0","1"]],"ts":"1747171023701","checksum":-1073659149,"seqId":54226736227,"prevSeqId":54226736178}]}
{"arg":{"channel":"books","instId":"BTC-USDT"},"action":"update","data":[{"asks":[["104473.4","0.00011435","0","1"],["104474.3","0.03070403","0","1"],["104475.8","0","0","0"],["104484.8","0.002","0","1"],["104504.2","0.09573","0","1"],["104516","0.17999999","0","3"],["104517","0.05","0","1"],["104518","0.07","0","2"],["104519","0.035","0","1"],["104570.8","0","0","0"],["104618.5","0","0","0"],["104619.3","0","0","0"]],"bids":[["104462.9","1.16890691","0","20"],["104414.7","0","0","0"],["104269.9","0.0000785","0","2"]],"ts":"1747171023801","checksum":1102945517,"seqId":54226736245,"prevSeqId":54226736227}]}
{"arg":{"channel":"books","instId":"BTC-USDT"},"action":"update","data":[{"asks":[["104473.8","0.33325181","0","1"],["104473.9","0.0966286","0","1"],["104474.6","0.1004435","0","1"],["104475.6","0.09006589","0","1"],["104476.1","0.13517273","0","2"],["104479.1","0.14919158","0","1"],["104479.4","0.16538286","0","1"],["104479.6","0.16699208","0","1"],["104482.3","0.15177919","0","1"],["104482.8","0.24496976","0","1"],["104484.2","0.36772837","0","2"],["104484.6","0.25738299","0","1"],["104484.9","0.27224078","0","1"],["104488.6","0.25697068","0","1"],["104516","0.24999999","0","5"],["104517","0.085","0","2"],["104518","0","0","0"],["104519","0","0","0"],["104555.2","6.0598049","0","1"],["104614.9","0","0","0"],["104615","0","0","0"],["104615.1","0","0","0"],["104615.3","0","0","0"],["104615.5","0","0","0"],["104616.6","0","0","0"],["104617.6","0","0","0"],["104617.7","0","0","0"],["104617.8","0","0","0"],["104618","0","0","0"]],"bids":[["104456.2","0.0017149","0","1"],["104456.1","0.1513115","0","1"],["104455.1","0.19167468","0","2"],["104453.6","0.09123436","0","1"],["104452.9","0.09527028","0","1"],["104452.8","0","0","0"],["104452.1","0.33586569","0","2"],["104451.9","0.1497864","0","1"],["104451.6","0.15685183","0","1"],["104450.1","0.16857966","0","1"],["104447.8","0.25700626","0","1"],["104447.3","0.16506717","0","1"],["104445.1","0.25635634","0","1"],["104441.9","0.26171155","0","1"],["104441.1","0.24871523","0","1"],["104272.2","0","0","0"],["104272","0","0","0"],["104271.9","0","0","0"],["104271.8","0","0","0"],["104271.5","0","0","0"],["104271.1","0","0","0"],["104270.8","0","0","0"],["104270.5","0","0","0"],["104270.3","0","0","0"],["104270","0","0","0"],["104269.9","0","0","0"]],"ts":"1747171023901","checksum":1978187981,"seqId":54226736347,"prevSeqId":54226736245}]}
{"arg":{"channel":"books","instId":"BTC-USDT"},"action":"update","data":[{"asks":[["104468","0","0","0"],["104473.8","0","0","0"],["104473.9","0","0","0"],["104474.3","0","0","0"],["104474.6","0","0","0"],["104475.6","0","0","0"],["104476.1","0.04","0","1"],["104476.4","0.00501","0","2"],["104479.1","0","0","0"],["104479.2","0.00478651","0","1"],["104479.4","0","0","0"],["104479.6","0","0","0"],["104480.3","0.03065917","0","1"],["104482.3","0","0","0"],["104482.8","0","0","0"],["104484.6","0","0","0"],["104484.9","0","0","0"],["104488.6","0","0","0"],["104488.8","0.04315895","0","1"],["104548.5","6.0598049","0","1"],["104555.2","0","0","0"],["104570.3","0.00032749","0","2"],["104614.9","0.0000105","0","1"],["104615","0.01099627","0","1"],["104615.1","1.02326418","0","3"],["104615.3","0.29225276","0","4"],["104615.5","0.00001","0","1"],["104616.6","0.00007797","0","4"],["104617.6","0.00003056","0","2"],["104617.7","0.01099591","0","1"],["104617.8","0.01099559","0","1"],["104618","0.00001632","0","1"],["104618.5","0.00009552","0","1"],["104619.3","0.04304781","0","1"]],"bids":[["104455.1","0","0","0"],["104453.6","0","0","0"],["104452.9","0","0","0"],["104451.9","0","0","0"],["104451.6","0","0","0"],["104450.1","0","0","0"],["104447.9","0","0","0"],["104447.8","0","0","0"],["104447.3","0","0","0"],["104445.1","0","0","0"],["104444.6","0.07298372","0","1"],["104441.9","0","0","0"],["104441.1","0","0","0"],["104272.2","0.00033769","0","1"],["104272","0.00086241","0","4"],["104271.9","0.00004632","0","2"],["104271.8","0.0000102","0","1"],["104271.5","0.00030759","0","1"],["104271.1","0.00001029","0","1"],["104270.8","0.00022348","0","1"],["104270.5","0.00012512","0","2"],["104270.3","0.00003386","0","2"],["104270","0.00038892","0","2"],["104269.9","0.0000785","0","2"],["104269.6","0.00001237","0","1"]],"ts":"1747171024001","checksum":1847910497,"seqId":54226736397,"prevSeqId":54226736347}]}
{"arg":{"channel":"books","instId":"BTC-USDT"},"action":"update","data":[{"asks":[["104463","0.40301479","0","8"],["104466","0.0932","0","1"],["104468","0.0932","0","1"],["104471","0.00011435","0","1"],["104471.1","0.03746135","0","1"],["104471.3","0.09379547","0","1"],["104472","0.09725696","0","1"],["104473","0.09447349","0","1"],["104473.4","0","0","0"],["104473.5","0.33255759","0","2"],["104474.9","0.03070385","0","1"],["104476.5","0.15625276","0","2"],["104476.8","0.15139924","0","1"],["104477","0.16777155","0","1"],["104477.4","0.00478525","0","1"],["104478","0.0932","0","1"],["104479.7","0.15734656","0","1"],["104479.9","0.48418552","0","1"],["104480.2","0.25043825","0","1"],["104480.3","0","0","0"],["104481.6","0","0","0"],["104482","0.33939439","0","2"],["104482.3","0.24573671","0","1"],["104482.4","0.0360125","0","2"],["104484.1","0","0","0"],["104484.2","0.36373132","0","2"],["104486","0.25737037","0","1"],["104487.9","0.13876931","0","1"],["104488.8","0","0","0"],["104491.6","0.00287107","0","1"],["104491.7","0","0","0"],["104494.4","0","0","0"],["104495","0","0","0"],["104496","0","0","0"],["104498","0.37108178","0","3"],["104499","0.01056749","0","2"],["104501.7","0.00013979","0","1"],["104502","0","0","0"],["104504.2","0","0","0"],["104509.8","0.36908178","0","1"],["104513.1","0","0","0"],["104515","0.00004786","0","1"],["104516","0","0","0"],["104517","0","0","0"],["104518","0.15999999","0","2"],["104519","0.24999999","0","5"],["104520","0.08830992","0","6"],["104520.5","1.13668148","0","3"],["104523.2","0","0","0"],["104544.4","0","0","0"],["104577.3","0.00056666","0","1"],["104581.9","0.0105964","0","1"],["104617.6","0","0","0"],["104617.7","0","0","0"],["104617.8","0","0","0"],["104618","0","0","0"],["104618.5","0","0","0"],["104619.3","0","0","0"]],"bids":[["104462.9","0.72335043","0","12"],["104461.8","0","0","0"],["104461.7","0","0","0"],["104461","0.00085","0","1"],["104460.8","0.01126952","0","1"],["104458.3","0.02715464","0","1"],["104456.2","0","0","0"],["104456.1","0.09078468","0","2"],["104455.6","0","0","0"],["104453.2","0","0","0"],["104452.6","0.0017149","0","1"],["104452.5","0.18274661","0","2"],["104452.1","0.23701048","0","2"],["104451.9","0.00955837","0","1"],["104451","0.09579277","0","1"],["104450.3","0.10140207","0","1"],["104449.3","0.14987664","0","1"],["104449.2","0","0","0"],["104449","0.15516993","0","1"],["104447.5","0.16594498","0","1"],["104447","0.071777","0","1"],["104445.4","0.00478525","0","1"],["104445.2","0.24364344","0","1"],["104444.7","0.2477747","0","2"],["104443.8","0.03767982","0","1"],["104443.3","0","0","0"],["104442.6","0.36908178","0","1"],["104442.5","0.24853876","0","1"],["104440.1","0.13876931","0","1"],["104439.3","0.25238558","0","1"],["104438.5","0.26162812","0","2"],["104435.1","0.00056666","0","1"],["104434.8","0","0","0"],["104425.3","0.002871","0","1"],["104424.5","0.20869903","0","1"],["104420.9","0","0","0"],["104407.2","0","0","0"],["104398.5","0.0022","0","1"],["104378.3","0.00056666","0","1"],["104376.1","0","0","0"],["104277.1","0.00221917","0","2"],["104271.9","0","0","0"],["104271.8","0","0","0"],["104271.5","0","0","0"],["104271.1","0","0","0"],["104270.8","0","0","0"],["104270.5","0","0","0"],["104270.3","0","0","0"],["104270","0","0","0"],["104269.9","0","0","0"],["104269.6","0","0","0"]],"ts":"1747171024101","checksum":16811431,"seqId":54226736710,"prevSeqId":54226736397}]}
{"arg":{"channel":"books","instId":"BTC-USDT"},"action":"update","data":[{"asks":[["104470.8","0.3563783","0","1"],["104470.9","0.77878311","0","2"],["104471","0","0","0"],["104472.1","0.03070467","0","1"],["104473.4","0.45317293","0","1"],["104475.8","0.0383585","0","1"],["104476.7","0.00478498","0","1"],["104476.8","0.22438296","0","2"],["104477.4","0","0","0"],["104514","1","0","1"],["104545.1","6.0598049","0","1"],["104548.5","0","0","0"],["104615","0","0","0"],["104615.1","0","0","0"],["104615.3","0","0","0"],["104615.5","0","0","0"],["104616.6","0","0","0"]],"bids":[["104461.7","0.02789309","0","1"],["104458.3","0","0","0"],["104449.4","0.19242972","0","1"],["104446.9","0.48125278","0","2"],["104445.4","0","0","0"],["104444.8","0.00480998","0","3"],["104440.1","0","0","0"],["104439.4","0.13877006","0","1"]],"ts":"1747171024201","checksum":-1995747494,"seqId":54226736736,"prevSeqId":54226736710}]}
{"arg":{"channel":"books","instId":"BTC-USDT"},"action":"update","data":[{"asks":[["104463","0.77955793","0","14"],["104464","0.0932","0","1"],["104465.9","0.22437345","0","1"],["104467","0.01914423","0","1"],["104467.6","0.36908178","0","1"],["104467.7","0.26541344","0","2"],["104470.7","0.00011435","0","1"],["104470.9","0.77866876","0","1"],["104471.3","0","0","0"],["104472","0","0","0"],["104472.1","0.03548995","0","2"],["104473","0","0","0"],["104473.5","0.234","0","1"],["104474.2","0","0","0"],["104474.8","0.03828847","0","1"],["104475.8","0","0","0"],["104476.5","0.000015","0","1"],["104476.7","0","0","0"],["104476.8","0.07298372","0","1"],["104477","0","0","0"],["104479.7","0","0","0"],["104480.2","0","0","0"],["104482","0.0932","0","1"],["104482.2","0","0","0"],["104482.3","0","0","0"],["104485.3","0.13877234","0","1"],["104486","0","0","0"],["104487.9","0","0","0"],["104497","0.002","0","2"],["104497.9","0.09573","0","1"],["104498","0.37008178","0","2"],["104499","0.00956749","0","1"],["104501.8","0","0","0"],["104512.7","1.43984587","0","1"],["104514","0","0","0"],["104542.4","0.41501232","0","1"],["104544.1","2.55411683","0","1"],["104615","0.01099627","0","1"],["104615.1","0.78926418","0","2"]],"bids":[["104462.9","0.00365853","0","5"],["104462.1","0","0","0"],["104462","0.0932","0","1"],["104461.7","0","0","0"],["104461","0","0","0"],["104460","0.09545229","0","4"],["104459.4","0","0","0"],["104457.9","0.0383585","0","1"],["104454.1","0","0","0"],["104452.5","0","0","0"],["104451","0","0","0"],["104450.3","0","0","0"],["104449.4","0","0","0"],["104449.3","0","0","0"],["104449","0","0","0"],["104447.5","0","0","0"],["104445.2","0","0","0"],["104444.8","0.000025","0","2"],["104444.7","0.09671","0","1"],["104442.6","0","0","0"],["104442.5","0","0","0"],["104440.1","0.00478528","0","1"],["104439.4","0","0","0"],["104439.3","0","0","0"],["104438.5","0.00191","0","1"],["104437.4","0.13877234","0","1"],["104398.6","0.00002963","0","1"],["104397.9","0","0","0"],["104271.9","0.00004632","0","2"],["104271.8","0.0000102","0","1"],["104271.5","0.00030759","0","1"],["104271.1","0.00001029","0","1"],["104270.8","0.00022348","0","1"],["104270.5","0.00012512","0","2"],["104270.3","0.00003386","0","2"],["104270","0.00038892","0","2"],["104269.9","0.0000785","0","2"],["104269.6","0.00001237","0","1"],["104269.2","0.00026966","0","5"],["104269","0.00005407","0","1"],["104268.9","0.00001021","0","1"],["104268.8","0.19131159","0","2"]],"ts":"1747171024301","checksum":470822751,"seqId":54226736851,"prevSeqId":54226736736}]}
{"arg":{"channel":"books","instId":"BTC-USDT"},"action":"update","data":[{"asks":[["104467.5","0.02432782","0","1"],["104467.9","0.02677051","0","1"],["104469.7","0.089835","0","1"],["104470.3","0.09575187","0","1"],["104471.3","0.09535601","0","1"],["104471.4","0.0383585","0","1"],["104471.8","0.09466657","0","1"],["104472","0.00478546","0","1"],["104472.1","0.03070467","0","1"],["104473.4","0.44883459","0","2"],["104474.8","0.19580198","0","2"],["104474.9","0","0","0"],["104475.2","0.15937579","0","1"],["104475.3","0.15605862","0","1"],["104478.1","0.15944581","0","1"],["104478.5","0.2490953","0","1"],["104478.9","0.75088467","0","1"],["104479.9","0","0","0"],["104480.3","0.24325544","0","1"],["104480.6","0.13970866","0","2"],["104480.7","0.24949072","0","1"],["104484.2","0.21029984","0","1"],["104484.3","0.44137451","0","2"],["104485.3","0","0","0"],["104491","0.00478107","0","2"],["104491.6","0","0","0"],["104497","0","0","0"],["104498","0.37108178","0","3"],["104499","0.01056749","0","2"],["104515.4","0","0","0"],["104611.3","0","0","0"],["104612.1","0","0","0"],["104612.2","0","0","0"],["104612.6","0","0","0"],["104612.9","0","0","0"],["104613","0","0","0"],["104614.9","0","0","0"],["104615","0","0","0"],["104615.1","0","0","0"]],"bids":[["104460.8","0","0","0"],["104456.7","0.04407745","0","2"],["104456.1","0","0","0"],["104454.5","0.02322418","0","1"],["104452.6","0","0","0"],["104452.2","0.0017149","0","1"],["104452.1","0.24851787","0","2"],["104450.8","0.19063308","0","2"],["104450.2","0","0","0"],["104449.3","0.09741585","0","1"],["104448.7","0.10131681","0","2"],["104447.7","0.15047227","0","1"],["104447.3","0.16164234","0","1"],["104446.9","0.37650973","0","2"],["104445.8","0.16289485","0","1"],["104444.2","0.03927993","0","1"],["104443.5","0.25545971","0","1"],["104443.1","0.15170338","0","1"],["104440.8","0.29788323","0","3"],["104440.1","0.00478546","0","1"],["104437.7","0.25820517","0","1"],["104437.4","0","0","0"],["104436.8","0.42811461","0","3"],["104432.6","0.13877581","0","1"],["104425.3","0","0","0"],["104421.3","0","0","0"],["104394","0","0","0"],["104393.2","0.002881","0","2"],["104269.2","0","0","0"],["104269","0","0","0"],["104268.9","0","0","0"],["104268.8","0","0","0"]],"ts":"1747171024401","checksum":1009818074,"seqId":54226737003,"prevSeqId":54226736851}]}
{"arg":{"channel":"books","instId":"BTC-USDT"},"action":"update","data":[{"asks":[["104471.7","0.00478546","0","1"],["104472","0","0","0"],["104505.2","0.0287183","0","1"],["104611","0","0","0"]],"bids":[["104450.9","0.19242972","0","1"],["104449.2","0.01126952","0","1"],["104441.4","0.028575","0","1"],["104440.1","0","0","0"],["104438.8","0.00478546","0","1"],["104424.5","0.32564647","0","2"],["104423.2","0.45150407","0","1"],["104270.3","0","0","0"],["104270","0","0","0"],["104269.9","0","0","0"],["104269.6","0","0","0"]],"ts":"1747171024501","checksum":31476272,"seqId":54226737063,"prevSeqId":54226737003}]}
{"arg":{"channel":"books","instId":"BTC-USDT"},"action":"update","data":[{"asks":[["104497","0.002","0","2"],["104498","0.37008178","0","2"],["104499","0.00956749","0","1"],["104610.9","0","0","0"]],"bids":[["104450.9","0","0","0"],["104449.4","0.19242972","0","1"]],"ts":"1747171024601","checksum":1385456542,"seqId":54226737071,"prevSeqId":54226737063}]}
{"arg":{"channel":"books","instId":"BTC-USDT"},"action":"update","data":[{"asks":[["104467.5","0","0","0"],["104468.5","0.02678035","0","2"],["104478.4","0.13878151","0","1"],["104480.6","0.00093","0","1"],["104485.7","0.04","0","1"],["104493.3","0.04663617","0","1"],["104494","0.00487","0","3"],["104495","0.001","0","1"],["104497","0","0","0"],["104498","0.36908178","0","1"],["104515","0.16004786","0","3"],["104516","0.14999999","0","3"],["104517","0.035","0","1"],["104518","0","0","0"],["104519","0.1","0","2"],["104520","0.05330992","0","5"],["104608.4","0","0","0"],["104610","0","0","0"]],"bids":[["104453","0.02322452","0","1"],["104432.6","0","0","0"],["104429.5","0.13878151","0","1"],["104411.1","0.0287183","0","1"],["104270.8","0","0","0"],["104270.5","0","0","0"]],"ts":"1747171024701","checksum":1570684548,"seqId":54226737099,"prevSeqId":54226737071}]}
{"arg":{"channel":"books","instId":"BTC-USDT"},"action":"update","data":[{"asks":[["104460.1","1.10193562","0","13"],["104462.1","0.47665959","0","1"],["104463","0.30407693","0","4"],["104465.9","0","0","0"],["104467.4","0.00011435","0","1"],["104467.5","0.09464781","0","1"],["104468.1","0.10027652","0","1"],["104469.1","0.09161148","0","1"],["104469.6","0.09449991","0","1"],["104469.7","0","0","0"],["104469.8","0.00478546","0","1"],["104470.3","0","0","0"],["104470.7","0","0","0"],["104471.3","0","0","0"],["104471.7","0","0","0"],["104471.8","0","0","0"],["104472.6","0.14255332","0","1"],["104473","0.14981898","0","1"],["104473.1","0.16203353","0","1"],["104473.4","0.4879676","0","2"],["104474.8","0.03828847","0","1"],["104475.2","0","0","0"],["104475.3","0","0","0"],["104475.9","0.17031015","0","2"],["104476.4","0.25606874","0","3"],["104478.1","0.25278998","0","1"],["104478.5","0.26624968","0","1"],["104478.9","0.56142812","0","1"],["104480.3","0","0","0"],["104480.7","0","0","0"],["104482.1","0.258618","0","1"],["104484.3","0.17829353","0","1"],["104494","0.00287","0","1"],["104495","0","0","0"],["104496","0.002","0","2"],["104497","0.001","0","1"],["104515","0.00004786","0","1"],["104516","0","0","0"],["104517","0","0","0"],["104517.7","0","0","0"],["104518","0.15999999","0","2"],["104518.5","0.00156676","0","2"],["104519","0.24999999","0","5"],["104520","0.08830992","0","6"],["104521.4","0","0","0"],["104608.4","0.00041816","0","1"]],"bids":[["104462.9","0","0","0"],["104462","0","0","0"],["104458.1","0.07291802","0","1"],["104457.9","0","0","0"],["104456.7","0.00001","0","1"],["104452.2","0","0","0"],["104452.1","0.12181593","0","1"],["104451.9","0","0","0"],["104450.8","0","0","0"],["104449.6","0.00955858","0","1"],["104449.5","0.0017149","0","1"],["104449.3","0","0","0"],["104448.7","0.00957211","0","1"],["104448.6","0.23258735","0","4"],["104447.7","0","0","0"],["104447.3","0","0","0"],["104447.1","0.09505514","0","1"],["104446.9","0.37726352","0","2"],["104446.5","0.09519395","0","1"],["104445.8","0","0","0"],["104445.5","0.1579446","0","1"],["104445.1","0.15965637","0","1"],["104443.6","0.15977566","0","1"],["104443.5","0","0","0"],["104443.1","0","0","0"],["104441.4","0.2762694","0","2"],["104440.9","0.15432599","0","1"],["104440.8","0.03001","0","2"],["104438.8","0","0","0"],["104438.6","0.2414632","0","1"],["104437.7","0","0","0"],["104437.4","0.00478546","0","1"],["104436.8","0.17830353","0","2"],["104436.7","0.34585976","0","2"],["104435.5","0.24848449","0","1"],["104434.6","0.24508437","0","1"],["104433.6","0.00383018","0","1"],["104348.8","0","0","0"],["104346.3","0.0006405","0","1"],["104343.3","0","0","0"],["104340.5","0.00084087","0","1"]],"ts":"1747171024801","checksum":377688498,"seqId":54226737424,"prevSeqId":54226737099}]}
{"arg":{"channel":"books","instId":"BTC-USDT"},"action":"update","data":[{"asks":[["104490.7","0.00287115","0","1"],["104491","0.00191","0","1"],["104514.8","0.87866876","0","2"],["104517","0.16","0","2"],["104518","0.17999999","0","3"],["104519","0.12","0","3"],["104520","0.03830992","0","5"],["104608.3","0","0","0"],["104608.4","0","0","0"]],"bids":[],"ts":"1747171024901","checksum":377688498,"seqId":54226737435,"prevSeqId":54226737424}]}
{"arg":{"channel":"books","instId":"BTC-USDT"},"action":"update","data":[{"asks":[["104467.5","0.09338952","0","1"],["104468.1","0.09208639","0","1"],["104469.1","0.09019006","0","1"],["104469.6","0.09709815","0","1"],["104472.6","0.14949444","0","1"],["104473","0.17053462","0","1"],["104473.1","0.16439115","0","1"],["104473.4","0.49516402","0","2"],["104475.9","0.18488453","0","2"],["104476.4","0.26062762","0","3"],["104478.1","0.25764478","0","1"],["104478.5","0.24525324","0","1"],["104482.1","0.25657189","0","1"],["104490.6","0.00287115","0","1"],["104490.7","0","0","0"],["104490.9","0.0001303","0","1"],["104493.9","0","0","0"],["104518","0.24999999","0","5"],["104519","0.085","0","2"],["104520","0.00330992","0","4"],["104570.3","0.00023506","0","1"]],"bids":[["104460","0.09554229","0","5"],["104458.1","0.07291352","0","1"],["104455.2","0.002","0","1"],["104455","0.0383585","0","1"],["104452.1","0","0","0"],["104449.6","0.01127348","0","2"],["104449.5","0.13896028","0","2"],["104448.6","0.23512538","0","4"],["104447.1","0.08795656","0","1"],["104446.9","0.37637929","0","2"],["104446.5","0.09385111","0","1"],["104445.5","0.16999383","0","1"],["104445.1","0.14333266","0","1"],["104443.6","0.16244557","0","1"],["104441.4","0.28846397","0","2"],["104440.9","0.14888665","0","1"],["104438.6","0.23761181","0","1"],["104436.7","0.35610886","0","2"],["104435.5","0.262752","0","1"],["104434.6","0.2649805","0","1"],["104398.6","0","0","0"],["104396.6","0.00002963","0","1"],["104363.9","0","0","0"],["104360.9","0.00010487","0","1"],["104311.1","0","0","0"],["104308.6","0.00095707","0","1"]],"ts":"1747171025001","checksum":-1838094324,"seqId":54226737570,"prevSeqId":54226737435}]}
{"arg":{"channel":"books","instId":"BTC-USDT"},"action":"update","data":[{"asks":[["104460.1","1.11635388","0","14"],["104463","0.286","0","3"],["104465.4","0.01441826","0","1"],["104467.9","0","0","0"],["104469.6","0","0","0"],["104469.7","0.09601466","0","1"],["104475.9","0.16680993","0","1"],["104478.4","0","0","0"],["104478.8","0.13878124","0","1"],["104480.4","0.04359366","0","2"],["104482.1","0","0","0"],["104482.2","0.24343307","0","1"],["104516.2","0.00056666","0","1"],["104520.5","1.13611482","0","2"],["104573","0.0110958","0","2"],["104577.3","0","0","0"]],"bids":[["104460","0.09553229","0","4"],["104456.5","0.02789449","0","1"],["104453","0","0","0"],["104447.2","0.14126104","0","2"],["104447.1","0","0","0"],["104435.1","0","0","0"],["104434.7","0.26000558","0","1"],["104434.6","0","0","0"],["104430.9","0.00056666","0","1"],["104429.5","0.13878124","0","1"],["104378.3","0","0","0"],["104374.1","0.00056666","0","1"],["104270.8","0.00022348","0","1"]],"ts":"1747171025101","checksum":1918397905,"seqId":54226737603,"prevSeqId":54226737570}]}
{"arg":{"channel":"books","instId":"BTC-USDT"},"action":"update","data":[{"asks":[["104460.1","1.10193562","0","13"],["104468.7","0.02677031","0","1"],["104469.6","0.12888359","0","2"],["104469.7","0","0","0"],["104472.8","0.0084426","0","1"],["104480.4","0.00001","0","1"],["104482.1","0.25976405","0","1"],["104482.2","0","0","0"],["104608.2","0","0","0"]],"bids":[["104456.5","0","0","0"],["104452.9","0.02322453","0","1"],["104450","0.00200496","0","3"],["104449.6","0.00955858","0","1"],["104447.2","0.05329894","0","1"],["104447.1","0.09388739","0","1"],["104434.7","0","0","0"],["104434.6","0.26452764","0","1"],["104270.8","0","0","0"]],"ts":"1747171025201","checksum":-257952452,"seqId":54226737661,"prevSeqId":54226737603}]}
{"arg":{"channel":"books","instId":"BTC-USDT"},"action":"update","data":[{"asks":[["104502","1","0","1"],["104510","0.98613403","0","3"],["104531","0","0","0"],["104542.4","0","0","0"],["104608.2","0.01059542","0","1"]],"bids":[["104460","0.09708229","0","5"]],"ts":"1747171025301","checksum":-1681380078,"seqId":54226737666,"prevSeqId":54226737661}]}
{"arg":{"channel":"books","instId":"BTC-USDT"},"action":"update","data":[{"asks":[["104460.1","1.13549923","0","15"],["104462","0.00011435","0","1"],["104463.7","0.09469762","0","1"],["104464.3","0.09408894","0","1"],["104465.3","0.09403294","0","1"],["104465.9","0.09632801","0","1"],["104466.3","0.02822972","0","1"],["104467","0","0","0"],["104467.4","0","0","0"],["104467.5","0.00478546","0","1"],["104467.6","0.40744028","0","2"],["104468.1","0","0","0"],["104468.5","0.00001","0","1"],["104468.7","0","0","0"],["104468.8","0.15356843","0","1"],["104469.1","0.0382906","0","1"],["104469.2","0.1663975","0","1"],["104469.3","0.1594354","0","1"],["104469.6","0.04","0","1"],["104469.8","0","0","0"],["104471.4","0","0","0"],["104472.1","0.18737787","0","2"],["104472.6","0.22893924","0","1"],["104473","0","0","0"],["104473.1","0","0","0"],["104473.3","0.13878903","0","1"],["104473.4","0.47280155","0","2"],["104474.3","0.25904237","0","1"],["104474.7","0.24930026","0","1"],["104474.8","0","0","0"],["104475.4","0.00093","0","1"],["104475.9","0","0","0"],["104476.4","0.00501","0","2"],["104478.1","0","0","0"],["104478.4","0.25404425","0","1"],["104478.5","0","0","0"],["104478.8","0","0","0"],["104482.1","0","0","0"],["104485.3","0.17829353","0","1"],["104487.3","0","0","0"],["104490.1","0.00287115","0","1"],["104490.6","0","0","0"],["104494","0.00487","0","3"],["104495","0.001","0","1"],["104496","0","0","0"],["104497","0","0","0"],["104504.3","0.02091112","0","1"],["104504.9","0.02164047","0","1"],["104513.3","0.00007315","0","1"],["104515","0.16004785","0","3"],["104516","0.24999999","0","5"],["104517","0.085","0","2"],["104518","0","0","0"],["104519","0","0","0"],["104522.9","0","0","0"],["104525.3","0.77866876","0","1"],["104608.3","0.03","0","1"],["104608.4","0.00041816","0","1"]],"bids":[["104460","0.00388229","0","4"],["104458.1","0","0","0"],["104458","0","0","0"],["104456","0.09422698","0","2"],["104455","0","0","0"],["104454.5","0","0","0"],["104452.9","0","0","0"],["104450","0.02349286","0","3"],["104449.5","0","0","0"],["104449.4","0","0","0"],["104448.6","0.00824757","0","1"],["104447.2","0","0","0"],["104447.1","0","0","0"],["104447","0.0017149","0","1"],["104446.9","0.20152205","0","1"],["104446.5","0","0","0"],["104445.5","0","0","0"],["104445.1","0","0","0"],["104444.8","0.17880252","0","4"],["104444.7","0","0","0"],["104443.9","0.04","0","1"],["104443.6","0","0","0"],["104443.4","0.09760554","0","1"],["104442.7","0.0947295","0","1"],["104442.2","0","0","0"],["104441.7","0.15143269","0","1"],["104441.6","0.43505324","0","2"],["104441.4","0.028575","0","1"],["104441.3","0.15854298","0","1"],["104440.9","0","0","0"],["104439.9","0","0","0"],["104439.8","0.15639689","0","1"],["104438.7","0","0","0"],["104438.6","0","0","0"],["104438.2","0","0","0"],["104437.6","0.24720108","0","1"],["104437.4","0","0","0"],["104437.1","0.16655243","0","1"],["104436.7","0.3537179","0","2"],["104435.5","0","0","0"],["104434.8","0.26847396","0","1"],["104434.6","0","0","0"],["104433.7","0.00478546","0","1"],["104431.7","0.2470699","0","1"],["104431.6","0.008","0","1"],["104430.9","0.25166354","0","2"],["104429.5","0","0","0"],["104427.9","0.17829353","0","1"],["104427.2","0","0","0"],["104424.8","0.13878903","0","1"],["104424.5","0.20869903","0","1"],["104423.3","0.17829353","0","1"],["104423.2","0","0","0"],["104422.8","0.04741394","0","1"],["104415.7","0.02871914","0","1"],["104410.9","0.46746826","0","1"],["104410","0.00028006","0","1"],["104407.9","0","0","0"],["104407","0","0","0"],["104405.7","0.04575116","0","1"],["104402.8","0","0","0"],["104380.7","0.03829218","0","1"],["104270.8","0.00022348","0","1"],["104270.5","0.00012512","0","2"],["104270.3","0.00003386","0","2"],["104270","0.00038892","0","2"],["104269.9","0.0000785","0","2"],["104269.6","0.00001237","0","1"],["104269.2","0.00026966","0","5"],["104269","0.00005407","0","1"],["104268.9","0.00001021","0","1"],["104268.8","0.31181159","0","3"]],"ts":"1747171025601","checksum":1282992821,"seqId":54226737943,"prevSeqId":54226737666}]}
{"arg":{"channel":"books","instId":"BTC-USDT"},"action":"update","data":[{"asks":[["104463","0.27","0","2"],["104463.7","0","0","0"],["104464.3","0","0","0"],["104465.3","0","0","0"],["104465.9","0","0","0"],["104467.5","0","0","0"],["104468.8","0","0","0"],["104469","0.00478546","0","1"],["104469.2","0","0","0"],["104469.3","0","0","0"],["104470.6","0.40341227","0","1"],["104470.8","0","0","0"],["104472.1","0.03070467","0","1"],["104472.6","0","0","0"],["104473.3","0","0","0"],["104473.4","0.54187626","0","2"],["104474.3","0","0","0"],["104474.7","0","0","0"],["104477.9","0.13878265","0","1"],["104478.4","0","0","0"],["104479","0.44408178","0","3"],["104483.2","0.24429353","0","3"],["104485.4","0.036","0","1"],["104489.9","0.00287115","0","1"],["104490.1","0","0","0"],["104493","0.78066876","0","3"],["104494","0.00387","0","2"],["104495","0","0","0"],["104502","0","0","0"],["104514","0.16","0","2"],["104515","0.08004785","0","2"],["104516","0.17","0","4"],["104525.2","0","0","0"],["104545.1","0","0","0"],["104555.2","6.09428346","0","1"],["104610","0.29261492","0","3"],["104610.9","0.01099559","0","1"],["104611","0.01099627","0","1"],["104611.3","0.00005484","0","1"],["104612.1","0.01059606","0","1"],["104612.2","0.01407867","0","1"],["104612.6","0.229704","0","1"],["104612.9","0.00001168","0","1"],["104613","0.000015","0","1"],["104614.9","0.0000105","0","1"],["104615","0.01099627","0","1"],["104615.1","0.78926418","0","2"],["104615.3","0.29225276","0","4"]],"bids":[["104460","0.28768229","0","7"],["104458.1","0.07141074","0","1"],["104458","0.0932","0","1"],["104456","0.09628093","0","4"],["104452.9","0.0383585","0","1"],["104451.3","0.03555047","0","1"],["104451.2","0.02789591","0","1"],["104450","0.00029006","0","2"],["104449","0.0017149","0","1"],["104448.6","0","0","0"],["104447","0","0","0"],["104446.9","0.39713293","0","2"],["104444.8","0.000025","0","2"],["104444.6","0.14476372","0","2"],["104443.4","0","0","0"],["104443","0.096611","0","1"],["104442.7","0","0","0"],["104441.9","0.67193648","0","1"],["104441.8","0.77866876","0","1"],["104441.7","0.19242972","0","1"],["104441.6","0","0","0"],["104441.3","0","0","0"],["104439.8","0","0","0"],["104437.6","0","0","0"],["104437.1","0","0","0"],["104436.9","0.00478546","0","1"],["104436.7","0.35237186","0","2"],["104434.8","0","0","0"],["104433.7","0","0","0"],["104432.6","0.36908178","0","1"],["104431.7","0","0","0"],["104430.9","0.00056666","0","1"],["104429.5","0.13878265","0","1"],["104429.3","0","0","0"],["104424.8","0","0","0"],["104393.2","0.00001","0","1"],["104358.5","0.002871","0","1"],["104268.4","0.00039895","0","2"]],"ts":"1747171025701","checksum":1647797856,"seqId":54226738220,"prevSeqId":54226737943}]}
{"arg":{"channel":"books","instId":"BTC-USDT"},"action":"update","data":[{"asks":[["104460.1","1.00074923","0","13"],["104462","0","0","0"],["104462.1","0.30936482","0","1"],["104463","0.036","0","1"],["104467.5","0.00011435","0","1"],["104467.8","0.02677055","0","1"],["104468.4","0.09912171","0","2"],["104469","0","0","0"],["104469.1","0.13987831","0","2"],["104470.1","0.09838647","0","2"],["104470.6","0.34834584","0","2"],["104472","0.00478546","0","1"],["104473.4","0.47932671","0","2"],["104473.6","0.1475712","0","1"],["104473.9","0.1632562","0","1"],["104474.1","0.16226375","0","1"],["104476.8","0.22664064","0","2"],["104477.3","0.2306487","0","1"],["104477.9","0","0","0"],["104478.9","0.79565364","0","2"],["104479.1","0.26020718","0","1"],["104479.4","0.26457684","0","1"],["104479.7","0.13878048","0","1"],["104483.1","0.41339659","0","2"],["104483.2","0.30729353","0","5"],["104489.6","0.03","0","1"],["104551.9","6.09429346","0","2"],["104555.2","0","0","0"],["104612.9","0","0","0"],["104613","0","0","0"],["104614.9","0","0","0"],["104615","0","0","0"],["104615.1","0","0","0"],["104615.3","0","0","0"]],"bids":[["104460","0.42746105","0","10"],["104456","0.09730791","0","5"],["104455.4","0.02789479","0","1"],["104453.2","0.02789537","0","1"],["104451.4","0.0017149","0","1"],["104451.3","0.13220223","0","2"],["104449.6","0.19852614","0","3"],["104449","0","0","0"],["104448.1","0.09664274","0","1"],["104447.4","0.09393973","0","1"],["104446.9","0.40398269","0","2"],["104446.4","0.16311281","0","1"],["104446.1","0.16360342","0","1"],["104444.6","0.30862524","0","3"],["104442.3","0.53256609","0","4"],["104441.9","0.49004339","0","1"],["104441.8","0.94591214","0","2"],["104439.6","0.25587301","0","1"],["104438.6","0.00478546","0","1"],["104436.9","0","0","0"],["104436.7","0.35756193","0","2"],["104436.4","0.2549985","0","1"],["104435.6","0.25108857","0","1"],["104432.1","0.13878048","0","1"],["104429.5","0","0","0"],["104270.3","0","0","0"],["104270","0","0","0"],["104269.9","0","0","0"],["104269.6","0","0","0"],["104269.2","0","0","0"],["104269","0","0","0"],["104268.9","0","0","0"],["104268.8","0","0","0"],["104268.4","0","0","0"]],"ts":"1747171025801","checksum":1103641459,"seqId":54226738388,"prevSeqId":54226738220}]}
{"arg":{"channel":"books","instId":"BTC-USDT"},"action":"update","data":[{"asks":[["104462.8","0.02432891","0","1"],["104467.7","0.19242972","0","1"],["104467.8","0","0","0"],["104468.6","0.14607877","0","1"],["104470.6","0.08965963","0","1"],["104470.9","0","0","0"],["104479.7","0","0","0"],["104481.9","0.13877789","0","1"],["104485.4","0","0","0"],["104515","0.18004785","0","4"],["104516","0.12","0","3"],["104517","0.035","0","1"],["104612.9","0.00001168","0","1"]],"bids":[["104460","0.17383229","0","6"],["104458.1","0","0","0"],["104455.4","0","0","0"],["104451.4","0","0","0"],["104451.3","0","0","0"],["104450","0.00200496","0","3"],["104441.8","0.98519299","0","3"],["104432.7","0.13877789","0","1"],["104432.1","0","0","0"],["104414.7","0.00287107","0","1"],["104358.5","0","0","0"],["104270.3","0.00003386","0","2"],["104270","0.00038892","0","2"],["104269.9","0.0000785","0","2"],["104269.6","0.00001237","0","1"]],"ts":"1747171025901","checksum":448446456,"seqId":54226738433,"prevSeqId":54226738388}]}
{"arg":{"channel":"books","instId":"BTC-USDT"},"action":"update","data":[{"asks":[["104458.1","0.78936151","0","15"],["104459.5","0.04622307","0","2"],["104460","0.09321","0","2"],["104460.1","0.06956361","0","3"],["104462.1","0","0","0"],["104462.8","0","0","0"],["104464.5","0.00001","0","1"],["104464.8","0.01","0","1"],["104465","0.0243284","0","1"],["104465.5","0.09378166","0","1"],["104465.6","0.37026014","0","2"],["104465.9","0.00045","0","1"],["104466.2","0.09518979","0","1"],["104467.1","0.0926349","0","1"],["104467.5","0.00478546","0","1"],["104467.7","0.28485995","0","2"],["104468.4","0.00521899","0","1"],["104468.6","0.38111465","0","1"],["104469.1","0.0382906","0","1"],["104470.1","0","0","0"],["104470.6","0.16235515","0","1"],["104471","0.16577935","0","1"],["104471.2","0.16502533","0","2"],["104471.8","0.77866876","0","1"],["104472","0","0","0"],["104473.4","0.49089631","0","2"],["104473.6","0","0","0"],["104473.9","0.14999457","0","1"],["104474.1","0","0","0"],["104474.4","0.25003976","0","1"],["104475.4","0","0","0"],["104476.2","0.24141753","0","1"],["104476.4","0.00594","0","3"],["104476.5","0.24787849","0","2"],["104476.8","0.07298372","0","1"],["104477.3","0","0","0"],["104478.8","0.13878122","0","1"],["104478.9","0.56142812","0","1"],["104479.1","0","0","0"],["104479.4","0","0","0"],["104480.2","0.25113288","0","1"],["104480.6","0","0","0"],["104481.6","0.00191","0","1"],["104481.9","0","0","0"],["104482","0","0","0"],["104483.1","0.17829353","0","1"],["104485.8","0","0","0"],["104486.8","0.00191","0","1"],["104489.4","0.00287115","0","1"],["104489.5","0.373963","0","3"],["104489.6","0","0","0"],["104489.9","0","0","0"],["104491","0","0","0"],["104492","0.002","0","2"],["104493","0.77966876","0","2"],["104494","0.00287","0","1"],["104513","0.16","0","2"],["104514","0.07999999","0","1"],["104514.8","0.77866876","0","1"],["104515","0.17004786","0","5"],["104516","0.085","0","2"],["104517","0","0","0"],["104517.5","0.00155176","0","1"],["104518.5","0.000015","0","1"],["104520.5","0.36908178","0","1"],["104538.3","6.09428346","0","1"],["104542.4","0.37980418","0","1"],["104551.9","0.00001","0","1"],["104580.7","0.01052914","0","1"],["104610","0","0","0"],["104610.9","0","0","0"],["104611","0","0","0"],["104611.3","0","0","0"],["104612.1","0","0","0"],["104612.2","0","0","0"],["104612.6","0","0","0"],["104612.9","0","0","0"]],"bids":[["104460","0","0","0"],["104456.1","0.07764589","0","1"],["104454.2","0","0","0"],["104454","0.0932","0","1"],["104453.2","0","0","0"],["104452.3","0","0","0"],["104451.3","0.03922106","0","1"],["104450.2","0.0005","0","1"],["104450","0.00029006","0","2"],["104449.6","0","0","0"],["104449.2","0","0","0"],["104449","0.02322541","0","1"],["104448.9","0","0","0"],["104448.1","0","0","0"],["104447.7","0.0017149","0","1"],["104447.6","0.00955877","0","1"],["104447.5","0.04691","0","1"],["104447.4","0","0","0"],["104446.9","0.39272471","0","2"],["104446.7","0.09360071","0","1"],["104446.6","0.08673549","0","1"],["104446.4","0","0","0"],["104446.1","0","0","0"],["104445.2","0.09169082","0","1"],["104444.9","0.00097","0","1"],["104444.6","0.14476372","0","2"],["104444.5","0.14524327","0","3"],["104444.4","0.01062754","0","1"],["104443.7","0","0","0"],["104443.5","0.16466544","0","1"],["104443.1","0.15015714","0","1"],["104442.3","0.286","0","3"],["104441.8","0.81794961","0","2"],["104441.7","0.34766596","0","2"],["104440.3","0.00005","0","1"],["104439.7","0.00097","0","1"],["104439.6","0","0","0"],["104439.4","0.24690248","0","1"],["104438.9","0.14904104","0","1"],["104438.6","0","0","0"],["104438.5","0","0","0"],["104436.7","0.60540033","0","3"],["104436.4","0","0","0"],["104435.6","0","0","0"],["104434.6","0.00478546","0","1"],["104434.5","0.00191","0","1"],["104433.6","0","0","0"],["104433.5","0.2690036","0","1"],["104433.3","0","0","0"],["104432.7","0.24648899","0","1"],["104429.5","0.13878122","0","1"],["104429.3","0.00191","0","1"],["104414.7","0","0","0"],["104379.8","0.00287107","0","1"],["104346.3","0","0","0"],["104345.6","0.00065053","0","2"],["104340.5","0","0","0"],["104338.2","0.0008409","0","1"],["104270.3","0","0","0"],["104270","0","0","0"],["104269.9","0","0","0"],["104269.6","0","0","0"]],"ts":"1747171026001","checksum":982770137,"seqId":54226738880,"prevSeqId":54226738433}]}
{"arg":{"channel":"books","instId":"BTC-USDT"},"action":"update","data":[{"asks":[["104458.1","0.80490049","0","14"],["104465.3","0.00011435","0","1"],["104465.6","0.37014579","0","1"],["104477.1","0.13878317","0","1"],["104478.8","0","0","0"],["104489.1","0.0028712","0","1"],["104489.4","0","0","0"],["104489.5","0.37109185","0","2"],["104497.8","0.00013979","0","1"],["104501.7","0","0","0"],["104507.5","0.00056666","0","1"],["104510","0.98612403","0","2"],["104512.8","0.1","0","1"],["104514","0.24999999","0","5"],["104515","0.08504786","0","3"],["104515.3","0","0","0"],["104516","0","0","0"],["104516.2","0","0","0"],["104516.6","0.00155176","0","1"],["104517.5","0","0","0"],["104556.6","0.00056666","0","1"],["104573","0.01052914","0","1"],["104608.4","0","0","0"]],"bids":[["104433.6","0.00056666","0","1"],["104430.9","0","0","0"],["104429.5","0.13878262","0","1"],["104396.6","0","0","0"],["104384.5","0.07244666","0","2"],["104374.1","0","0","0"],["104345.6","0.00001","0","1"],["104344.9","0.00064054","0","1"],["104270.3","0.00003386","0","2"]],"ts":"1747171026101","checksum":-1909328221,"seqId":54226738989,"prevSeqId":54226738880}]}
{"arg":{"channel":"books","instId":"BTC-USDT"},"action":"update","data":[{"asks":[["104465.3","0","0","0"],["104465.4","0.01453261","0","2"],["104472.3","0","0","0"],["104475.9","0.13878535","0","1"],["104477.1","0","0","0"],["104484.8","0","0","0"],["104489.9","0.0001303","0","1"],["104490.9","0","0","0"],["104608.4","0.00041816","0","1"],["104610","0.29261492","0","3"],["104610.9","0.01099559","0","1"]],"bids":[["104458","0.09329","0","2"],["104455.2","0","0","0"],["104447.7","0","0","0"],["104447.6","0.01127367","0","2"],["104429.5","0","0","0"],["104428.2","0.13878535","0","1"],["104394.8","0.00002963","0","1"],["104360.9","0","0","0"],["104358.9","0.00010593","0","1"],["104308.6","0","0","0"],["104307.2","0.00095708","0","1"],["104270","0.00038892","0","2"]],"ts":"1747171026201","checksum":1248035690,"seqId":54226739019,"prevSeqId":54226738989}]}
{"arg":{"channel":"books","instId":"BTC-USDT"},"action":"update","data":[{"asks":[["104463.7","0.07298372","0","1"],["104467.1","0.00478546","0","1"],["104467.2","0.0887495","0","1"],["104467.5","0","0","0"],["104470.6","0","0","0"],["104470.7","0.15906463","0","1"],["104472.9","0.002","0","1"],["104475.9","0.13878665","0","1"],["104485.4","0.002","0","1"],["104489","0.0001303","0","1"],["104489.9","0","0","0"],["104492","0","0","0"],["104493","0.78066876","0","3"],["104494","0.00387","0","2"],["104504.1","0","0","0"],["104513","0","0","0"],["104514","0.15999999","0","2"],["104515","0.25004785","0","6"],["104516","0.085","0","2"],["104520.5","0.82863494","0","2"],["104610.9","0","0","0"]],"bids":[["104458","0.09426","0","3"],["104455.7","0.002","0","1"],["104451.2","0","0","0"],["104447.7","0.0017149","0","1"],["104447.6","0.00955877","0","1"],["104446.7","0.18821482","0","2"],["104446.6","0","0","0"],["104443.2","0.1477512","0","2"],["104443.1","0","0","0"],["104428.8","0","0","0"],["104428.2","0","0","0"],["104424.8","0.13878665","0","1"],["104415.5","0.28177343","0","2"],["104269.9","0.0000785","0","2"]],"ts":"1747171026301","checksum":746128662,"seqId":54226739075,"prevSeqId":54226739019}]}
{"arg":{"channel":"books","instId":"BTC-USDT"},"action":"update","data":[{"asks":[["104457.9","0.62546709","0","17"],["104458","0.22558171","0","3"],["104458.1","0.286","0","3"],["104459.5","0","0","0"],["104462.7","0.02432895","0","1"],["104463.6","0.00011435","0","1"],["104464","0.44783705","0","3"],["104464.6","0.08954504","0","1"],["104465.4","0.01441826","0","1"],["104465.5","0","0","0"],["104465.6","0.09623682","0","1"],["104465.9","0.00523546","0","2"],["104466.1","0.09937921","0","1"],["104466.2","0","0","0"],["104467.1","0","0","0"],["104467.2","0","0","0"],["104467.7","0.19242972","0","1"],["104469.1","0.1924108","0","2"],["104469.5","0.15877074","0","1"],["104469.6","0.20908957","0","2"],["104470.7","0","0","0"],["104471","0","0","0"],["104471.2","0.00093","0","1"],["104472.4","0.1567536","0","1"],["104472.8","0.23980126","0","2"],["104473.4","0.41966673","0","2"],["104473.9","0","0","0"],["104474.4","0","0","0"],["104474.5","0.1387868","0","1"],["104474.6","0.26544664","0","1"],["104475","0.24765013","0","1"],["104475.9","0","0","0"],["104476.2","0","0","0"],["104476.5","0.000015","0","1"],["104478.6","0.24166993","0","1"],["104480","0.00220843","0","3"],["104480.2","0","0","0"],["104489.1","0","0","0"],["104497.9","0.14230514","0","2"],["104512.8","0","0","0"],["104566.5","0.00010343","0","1"],["104581.4","0.22976","0","1"]],"bids":[["104458","0","0","0"],["104456.7","0","0","0"],["104456.1","0","0","0"],["104452.7","0","0","0"],["104447.7","0","0","0"],["104447.6","0","0","0"],["104447.5","0","0","0"],["104447.4","0.00955878","0","1"],["104447.2","0.02518828","0","1"],["104447","0.0017149","0","1"],["104446.9","0.28632221","0","2"],["104446.7","0","0","0"],["104445.2","0","0","0"],["104445.1","0.18206529","0","2"],["104444.5","0.052","0","2"],["104443.8","0","0","0"],["104443.6","0.09507365","0","1"],["104443.5","0","0","0"],["104443.2","0.002","0","1"],["104443","0.19159117","0","2"],["104442.3","0.052","0","2"],["104442","0.15710032","0","1"],["104441.9","0.7248115","0","2"],["104441.8","0.03928085","0","1"],["104441.7","0.19242972","0","1"],["104441.6","0.16203275","0","1"],["104440.1","0.16371873","0","1"],["104439.4","0","0","0"],["104438.9","0","0","0"],["104437.8","0.25374909","0","1"],["104437.4","0.15839246","0","1"],["104436.8","0.41230353","0","3"],["104436.7","0.34877078","0","2"],["104435.1","0.2595815","0","1"],["104434.6","0","0","0"],["104433.7","0.00478546","0","1"],["104433.5","0","0","0"],["104432.7","0","0","0"],["104432","0.29533365","0","3"],["104431.4","0.00383027","0","1"],["104431.1","0.24940866","0","1"],["104424.8","0.1387868","0","1"],["104409","0","0","0"],["104407","0.48324487","0","1"],["104394.8","0","0","0"],["104362","0.12","0","1"],["104360","0.47660759","0","4"],["104337.7","0.00001","0","1"],["104269.6","0.00001237","0","1"],["104269.2","0.00026966","0","5"]],"ts":"1747171026401","checksum":2031571321,"seqId":54226739352,"prevSeqId":54226739075}]}
{"arg":{"channel":"books","instId":"BTC-USDT"},"action":"update","data":[{"asks":[["104457.9","0.60262844","0","16"],["104460.1","0.0551453","0","2"],["104465.8","0.00478546","0","1"],["104465.9","0.00045","0","1"],["104474.5","0","0","0"],["104475.9","0.13878517","0","1"],["104488.5","0.00287121","0","1"],["104512.6","0.1","0","1"],["104518.6","0.00160511","0","2"],["104530.9","0","0","0"],["104538.3","0","0","0"],["104541.7","6.09428346","0","1"],["104608.4","0","0","0"],["104610","0","0","0"]],"bids":[["104446.9","0.48955934","0","1"],["104444.6","0.07298372","0","1"],["104443","0.09498017","0","1"],["104442.1","0.77866876","0","1"],["104436.7","0.3864506","0","3"],["104433.8","0.00478546","0","1"],["104433.7","0","0","0"],["104428.2","0.13878517","0","1"],["104424.8","0","0","0"],["104394.8","0.00002963","0","1"],["104269.6","0","0","0"],["104269.2","0","0","0"]],"ts":"1747171026501","checksum":-4708303,"seqId":54226739402,"prevSeqId":54226739352}]}
{"arg":{"channel":"books","instId":"BTC-USDT"},"action":"update","data":[{"asks":[["104457.9","0.85104675","0","18"],["104458.1","0.052","0","2"],["104475.9","0","0","0"],["104478.8","0.13878094","0","1"],["104531.6","6.09428346","0","1"],["104541.7","0","0","0"]],"bids":[["104457.8","0.00509","0","2"],["104447.3","0.234","0","1"],["104447.2","0","0","0"],["104446.9","0.44467835","0","2"],["104442.1","0","0","0"],["104442","0.93576908","0","2"],["104441.8","0.11106085","0","2"],["104440.3","0.096661","0","2"],["104431.6","0.14678094","0","2"],["104428.2","0","0","0"],["104394.8","0","0","0"],["104269.6","0.00001237","0","1"],["104269.2","0.00026966","0","5"],["104269","0.00005407","0","1"]],"ts":"1747171026601","checksum":-287927214,"seqId":54226739433,"prevSeqId":54226739402}]}
{"arg":{"channel":"books","instId":"BTC-USDT"},"action":"update","data":[{"asks":[["104457.9","0.8282081","0","17"],["104458","0.14850659","0","2"],["104458.1","0.036","0","1"],["104460.1","0.06371992","0","3"],["104462.7","0","0","0"],["104463.6","0","0","0"],["104463.7","0","0","0"],["104463.9","0.00011435","0","1"],["104464","0.35378186","0","2"],["104464.1","0.09904628","0","1"],["104464.6","0","0","0"],["104464.7","0.10097719","0","1"],["104465.6","0","0","0"],["104465.7","0.08760722","0","1"],["104465.8","0","0","0"],["104466.1","0","0","0"],["104466.2","0.09337807","0","1"],["104466.4","0.03049553","0","1"],["104467.5","0.00478546","0","1"],["104469.1","0.0382906","0","1"],["104469.2","0.14938049","0","1"],["104469.5","0","0","0"],["104469.6","0.19399779","0","2"],["104469.7","0.16796653","0","1"],["104472.4","0","0","0"],["104472.5","0.1459451","0","2"],["104472.8","0.0084426","0","1"],["104473","0.25173685","0","1"],["104473.4","0.41870209","0","2"],["104474.6","0","0","0"],["104474.7","0.2490556","0","1"],["104475","0","0","0"],["104475.1","0.26083005","0","1"],["104478.6","0","0","0"],["104478.7","0.24290609","0","1"],["104478.8","0","0","0"],["104480","0.14098797","0","4"],["104492","0.002","0","2"],["104493","0.77966876","0","2"],["104494","0.00287","0","1"],["104513","0.16","0","2"],["104514","0.24999999","0","5"],["104515","0.08504786","0","3"],["104516","0","0","0"],["104531.6","0","0","0"],["104545.1","6.09428346","0","1"],["104571.8","0.12","0","1"],["104608.2","0","0","0"],["104608.3","0","0","0"]],"bids":[["104453.6","0.02428791","0","1"],["104451.3","0.02426138","0","1"],["104447.7","0.00837957","0","1"],["104447.3","0","0","0"],["104446.9","0.43630239","0","2"],["104445.2","0.17758839","0","2"],["104445.1","0","0","0"],["104444.2","0","0","0"],["104443.7","0.10010382","0","1"],["104443.6","0","0","0"],["104443.1","0.09426467","0","1"],["104443","0","0","0"],["104442.1","0.1686226","0","1"],["104442","0.77866876","0","1"],["104441.9","0.49004339","0","1"],["104441.7","0.34092573","0","2"],["104441.6","0","0","0"],["104440.2","0.14960199","0","1"],["104440.1","0","0","0"],["104438","0.24266725","0","1"],["104437.8","0","0","0"],["104437.5","0.1496864","0","1"],["104437.4","0","0","0"],["104435.3","0.00478546","0","1"],["104435.2","0.25458212","0","1"],["104435.1","0","0","0"],["104433.8","0","0","0"],["104432.7","0.13877954","0","1"],["104432.1","0.24573539","0","1"],["104432","0.052","0","2"],["104431.6","0.008","0","1"],["104431.2","0.26090319","0","1"],["104431.1","0","0","0"],["104394.6","0.49180399","0","3"],["104269.2","0","0","0"],["104269","0","0","0"]],"ts":"1747171026701","checksum":-1705773109,"seqId":54226739576,"prevSeqId":54226739433}]}
{"arg":{"channel":"books","instId":"BTC-USDT"},"action":"update","data":[{"asks":[["104489","0","0","0"],["104566.5","0","0","0"],["104582.8","0","0","0"],["104608.2","0.01059542","0","1"],["104608.3","0.03","0","1"],["104608.4","0.00041816","0","1"]],"bids":[],"ts":"1747171026801","checksum":-1705773109,"seqId":54226739581,"prevSeqId":54226739576}]}
{"arg":{"channel":"books","instId":"BTC-USDT"},"action":"update","data":[{"asks":[["104457.9","0.82844893","0","18"],["104478.8","0.13878115","0","1"],["104480","0.00220843","0","3"],["104608.4","0","0","0"]],"bids":[["104432.7","0","0","0"],["104431.3","0.13878115","0","1"]],"ts":"1747171026901","checksum":1911745418,"seqId":54226739586,"prevSeqId":54226739581}]}
{"arg":{"channel":"books","instId":"BTC-USDT"},"action":"update","data":[{"asks":[["104488.8","0.0001303","0","1"],["104535","6.10399322","0","1"],["104545.1","0","0","0"],["104608.3","0","0","0"]],"bids":[["104277","0","0","0"],["104269.2","0.00026966","0","5"]],"ts":"1747171027001","checksum":1911745418,"seqId":54226739641,"prevSeqId":54226739586}]}
{"arg":{"channel":"books","instId":"BTC-USDT"},"action":"update","data":[{"asks":[["104457.9","0.57175483","0","17"],["104464.1","0","0","0"],["104464.7","0","0","0"],["104465.7","0","0","0"],["104466.2","0","0","0"],["104469.2","0","0","0"],["104469.6","0.04","0","1"],["104469.7","0","0","0"],["104472.5","0.00001","0","1"],["104473","0","0","0"],["104473.4","0.44508928","0","2"],["104474.7","0","0","0"],["104475.1","0","0","0"],["104478.7","0","0","0"],["104478.8","0","0","0"],["104480","0.14098883","0","4"],["104492","0","0","0"],["104493","0.78066876","0","3"],["104494","0.00387","0","2"],["104502.9","0.00056666","0","1"],["104507.5","0","0","0"],["104513","0","0","0"],["104514","0.15999999","0","2"],["104515","0.25004785","0","6"],["104516","0.085","0","2"],["104550.8","0.00056666","0","1"],["104556.6","0","0","0"],["104566.5","0.00010673","0","1"],["104608.3","0.03","0","1"],["104608.4","0.00041816","0","1"],["104610","0.29261492","0","3"],["104610.9","0.01099559","0","1"],["104611","0.01099627","0","1"],["104611.3","0.00005484","0","1"],["104612.1","0.01059606","0","1"],["104612.2","0.01407867","0","1"],["104612.9","0.00001168","0","1"],["104613","0.000015","0","1"],["104614.9","0.0000105","0","1"]],"bids":[["104457.8","0.12459","0","3"],["104456.1","0.07656065","0","1"],["104451.3","0.09342811","0","2"],["104447.4","0.01127368","0","2"],["104447.3","0.234","0","1"],["104447","0","0","0"],["104446.9","0.47848061","0","2"],["104445.2","0","0","0"],["104443.7","0","0","0"],["104443.1","0","0","0"],["104442.1","0","0","0"],["104441.7","0.19242972","0","1"],["104440.2","0","0","0"],["104438","0","0","0"],["104437.5","0","0","0"],["104435.2","0","0","0"],["104433.6","0","0","0"],["104432.1","0.1387804","0","1"],["104431.3","0","0","0"],["104431.2","0","0","0"],["104430.8","0.00056666","0","1"],["104384.5","0.07188","0","1"],["104382.9","0.00056666","0","1"],["104269","0.00005407","0","1"],["104268.9","0.00001021","0","1"],["104268.8","0.31181159","0","3"],["104268.4","0.00039895","0","2"],["104268.3","0.00018565","0","4"],["104268","0.00011013","0","2"],["104267.5","0.80866876","0","2"],["104267.2","0.00001019","0","1"]],"ts":"1747171027101","checksum":554826786,"seqId":54226739766,"prevSeqId":54226739641}]}
{"arg":{"channel":"books","instId":"BTC-USDT"},"action":"update","data":[{"asks":[["104457.9","0.47300483","0","16"],["104458","0.0932","0","1"],["104459.9","0.04707898","0","1"],["104463.9","0","0","0"],["104464","0.29269172","0","3"],["104465.8","0.10165661","0","2"],["104466.5","0.09546692","0","1"],["104467.5","0.10281172","0","2"],["104467.6","0.0383585","0","1"],["104467.7","0","0","0"],["104468","0.18379725","0","2"],["104468.6","0.21202165","0","2"],["104471","0.15655536","0","1"],["104471.3","0.15474668","0","1"],["104471.5","0.15885561","0","1"],["104471.8","0","0","0"],["104473.4","0.49633367","0","2"],["104474.3","0.15800418","0","1"],["104474.7","0.24796253","0","1"],["104476.5","0.24570073","0","2"],["104476.8","0.31654617","0","2"],["104480.5","0.26232952","0","1"],["104611.3","0","0","0"],["104612.1","0","0","0"],["104612.2","0","0","0"],["104612.9","0","0","0"],["104613","0","0","0"],["104614.9","0","0","0"]],"bids":[["104457.8","0.19470338","0","4"],["104447.5","0.0017149","0","1"],["104447.4","0.00955878","0","1"],["104447","0.19842864","0","2"],["104446.9","0.48252648","0","2"],["104445.5","0.08893792","0","1"],["104444.8","0.10121199","0","3"],["104443.8","0.15596427","0","1"],["104443.7","0.36908178","0","1"],["104443.5","0.15538607","0","1"],["104442","0.93959546","0","2"],["104439.7","0.24167958","0","2"],["104439.3","0.14585355","0","1"],["104437","0.25999264","0","1"],["104433.8","0.25849325","0","1"],["104433","0.24426409","0","1"],["104307.2","0","0","0"],["104306","0.00095709","0","1"],["104269.6","0","0","0"],["104269.2","0","0","0"],["104269","0","0","0"],["104268.9","0","0","0"],["104268.8","0","0","0"],["104268.4","0","0","0"],["104268.3","0","0","0"],["104268","0","0","0"],["104267.5","0","0","0"],["104267.2","0","0","0"]],"ts":"1747171027201","checksum":487010902,"seqId":54226739948,"prevSeqId":54226739766}]}
{"arg":{"channel":"books","instId":"BTC-USDT"},"action":"update","data":[{"asks":[["104457.9","0.80575483","0","18"],["104463.9","0.00011435","0","1"],["104464.2","0.09066549","0","1"],["104464.8","0.10457971","0","2"],["104465.8","0.09457447","0","1"],["104466.4","0.12286056","0","2"],["104466.5","0","0","0"],["104467.5","0.00478546","0","1"],["104467.6","0.23078822","0","2"],["104468","0.0932","0","1"],["104468.6","0.32561071","0","1"],["104469.3","0.16307987","0","1"],["104469.7","0.16667879","0","1"],["104469.8","0.16429478","0","1"],["104471","0","0","0"],["104471.3","0","0","0"],["104471.5","0","0","0"],["104472.6","0.15654522","0","1"],["104473.1","0.25758654","0","1"],["104473.4","0.29567888","0","1"],["104474.3","0","0","0"],["104474.7","0","0","0"],["104474.8","0.26958059","0","1"],["104475.2","0.25409078","0","1"],["104476.5","0.000015","0","1"],["104476.8","0.07298372","0","1"],["104478.9","0.81126983","0","2"],["104480.5","0","0","0"],["104490","0.00229006","0","4"],["104491","0.001","0","1"],["104493","0.77866876","0","1"],["104494","0.00287","0","1"],["104511","0.16","0","2"],["104512","0.24999999","0","5"],["104513","0.085","0","2"],["104514","0","0","0"],["104515","0.00004786","0","1"],["104516","0","0","0"],["104608.4","0","0","0"],["104610","0","0","0"],["104610.9","0","0","0"],["104611","0","0","0"]],"bids":[["104457.8","0.00089","0","2"],["104456.1","0","0","0"],["104447.5","0","0","0"],["104447.4","0.01127368","0","2"],["104447","0","0","0"],["104445.5","0","0","0"],["104445.3","0.18977086","0","3"],["104444.8","0.000025","0","2"],["104443.9","0.12983003","0","2"],["104443.8","0","0","0"],["104443.7","0","0","0"],["104443.5","0","0","0"],["104443.2","0.09548768","0","2"],["104442.2","0.1651392","0","1"],["104442","0.77866876","0","1"],["104441.8","0.2633608","0","3"],["104440.3","0.26254927","0","3"],["104439.7","0.00097","0","1"],["104439.3","0","0","0"],["104438.1","0.25360629","0","1"],["104437.6","0.15411895","0","1"],["104437","0","0","0"],["104435.3","0.25375846","0","2"],["104433.8","0","0","0"],["104433","0","0","0"],["104432.2","0.25109815","0","1"],["104431.4","0.24282056","0","2"],["104269.6","0.00001237","0","1"],["104269.2","0.00026966","0","5"],["104269","0.00005407","0","1"],["104268.9","0.00001021","0","1"],["104268.8","0.31181159","0","3"],["104268.4","0.00039895","0","2"],["104268.3","0.00018565","0","4"]],"ts":"1747171027301","checksum":835157759,"seqId":54226740073,"prevSeqId":54226739948}]}
{"arg":{"channel":"books","instId":"BTC-USDT"},"action":"update","data":[{"asks":[["104457.9","0.47300483","0","16"],["104464","0.44927635","0","2"],["104464.2","0","0","0"],["104464.8","0.01","0","1"],["104465.2","0.09690451","0","1"],["104465.8","0","0","0"],["104465.9","0.0956444","0","2"],["104466.4","0.03049553","0","1"],["104466.9","0.08596438","0","1"],["104467.4","0.09545442","0","1"],["104467.5","0.37386724","0","2"],["104468.6","0.2110473","0","2"],["104469.3","0","0","0"],["104469.7","0","0","0"],["104469.8","0","0","0"],["104470.4","0.1588794","0","1"],["104470.7","0.15207273","0","1"],["104470.9","0.16825074","0","1"],["104472.6","0","0","0"],["104473.1","0","0","0"],["104473.4","0.5034979","0","2"],["104473.7","0.15943567","0","1"],["104474.1","0.2602215","0","1"],["104474.8","0","0","0"],["104475.2","0","0","0"],["104475.9","0.25488904","0","1"],["104476.2","0.25677443","0","1"],["104478.9","0.56142812","0","1"],["104479.9","0.26422135","0","1"],["104520.5","1.24915447","0","3"],["104608.2","0","0","0"],["104608.3","0","0","0"]],"bids":[["104457.8","0.12039","0","3"],["104446.9","0.48122176","0","2"],["104446.4","0.18680258","0","2"],["104445.3","0.005","0","1"],["104444.9","0.10041674","0","2"],["104444.2","0.09159866","0","1"],["104443.9","0.04","0","1"],["104443.2","0.1670254","0","2"],["104442.9","0.14743733","0","1"],["104442.2","0","0","0"],["104441.8","0.11106085","0","2"],["104441.4","0.1925707","0","2"],["104440.3","0.096661","0","2"],["104439.1","0.23695115","0","1"],["104438.7","0.14830287","0","1"],["104438.1","0","0","0"],["104437.6","0","0","0"],["104436.4","0.24332963","0","1"],["104435.3","0.00478546","0","1"],["104433.2","0.26468938","0","1"],["104432.4","0.23854747","0","1"],["104432.2","0","0","0"],["104431.4","0.00383027","0","1"],["104268.9","0","0","0"],["104268.8","0","0","0"],["104268.4","0","0","0"],["104268.3","0","0","0"]],"ts":"1747171027401","checksum":-197780456,"seqId":54226740198,"prevSeqId":54226740073}]}
{"arg":{"channel":"books","instId":"BTC-USDT"},"action":"update","data":[{"asks":[["104457.9","0.80575483","0","18"],["104464","0.66406474","0","3"],["104464.2","0.09341741","0","1"],["104464.8","0.10776468","0","2"],["104465.2","0","0","0"],["104465.8","0.09333982","0","1"],["104465.9","0.00045","0","1"],["104466","0.16618372","0","2"],["104466.4","0.1195651","0","2"],["104466.9","0","0","0"],["104467.3","0.77866876","0","1"],["104467.4","0","0","0"],["104468.6","0.33264731","0","2"],["104469.3","0.16299664","0","1"],["104469.7","0.15256814","0","1"],["104469.8","0.16943564","0","1"],["104470.4","0","0","0"],["104470.7","0","0","0"],["104470.9","0","0","0"],["104472.6","0.1598076","0","1"],["104473.1","0.23972822","0","1"],["104473.4","0.29567888","0","1"],["104473.7","0","0","0"],["104474.1","0","0","0"],["104474.8","0.24507207","0","1"],["104475.2","0.25242142","0","1"],["104475.9","0","0","0"],["104476.2","0","0","0"],["104478.9","0.8088882","0","2"],["104479.9","0","0","0"],["104481.1","0.59842","0","2"],["104499.6","0.42844324","0","1"],["104500.5","0.0022","0","1"],["104608.2","0.01059542","0","1"]],"bids":[["104457.8","0.00089","0","2"],["104447.3","0","0","0"],["104446.9","0.43947136","0","2"],["104446.4","0","0","0"],["104445.3","0.19816991","0","3"],["104444.9","0.00097","0","1"],["104444.2","0","0","0"],["104443.9","0.13236916","0","2"],["104443.2","0.10339116","0","2"],["104442.9","0","0","0"],["104442.2","0.16421248","0","1"],["104441.9","0.33672438","0","1"],["104441.8","0.19053033","0","2"],["104441.4","0.028575","0","1"],["104440.3","0.15450295","0","2"],["104439.1","0","0","0"],["104438.7","0","0","0"],["104438.1","0.24501896","0","1"],["104437.6","0.15497028","0","1"],["104436.4","0","0","0"],["104435.3","0.26985656","0","2"],["104433.2","0","0","0"],["104432.4","0","0","0"],["104432.2","0.26302528","0","1"],["104431.4","0.24216963","0","2"],["104384.8","0.3955667","0","1"],["104383.8","0","0","0"],["104342.8","0.91520049","0","1"],["104342.7","2.63306","0","1"],["104342.6","0","0","0"],["104268.9","0.00001021","0","1"],["104268.8","0.31181159","0","3"],["104268.4","0.00039895","0","2"],["104268.3","0.00018565","0","4"],["104268","0.00011013","0","2"]],"ts":"1747171027501","checksum":-800883203,"seqId":54226740270,"prevSeqId":54226740198}]}
{"arg":{"channel":"books","instId":"BTC-USDT"},"action":"update","data":[{"asks":[["104463.8","0.00011435","0","1"],["104463.9","0.09266355","0","1"],["104464.2","0","0","0"],["104464.6","0.09351957","0","1"],["104464.8","0.01","0","1"],["104465.6","0.09213415","0","1"],["104465.8","0","0","0"],["104466.1","0.09555824","0","1"],["104466.4","0.03049553","0","1"],["104468.6","0.33708363","0","2"],["104469.1","0.19353059","0","2"],["104469.3","0","0","0"],["104469.4","0.16794445","0","1"],["104469.6","0.208633","0","2"],["104469.7","0","0","0"],["104469.8","0","0","0"],["104472.4","0.16229216","0","1"],["104472.6","0","0","0"],["104472.8","0.25365699","0","2"],["104473.1","0","0","0"],["104474.6","0.26780758","0","1"],["104474.8","0","0","0"],["104474.9","0.24061679","0","1"],["104475.2","0","0","0"],["104478.6","0.26336779","0","1"],["104478.8","0.13878123","0","1"],["104478.9","0.56142812","0","1"],["104480","0.00220843","0","3"],["104608.2","0","0","0"]],"bids":[["104453.6","0","0","0"],["104451.4","0.02428841","0","1"],["104451.3","0.02426138","0","1"],["104447.4","0.00955878","0","1"],["104447","0.0017149","0","1"],["104446.9","0.38753721","0","2"],["104445.3","0.005","0","1"],["104445.1","0.18786063","0","2"],["104443.9","0.04","0","1"],["104443.6","0.09372659","0","1"],["104443.2","0.002","0","1"],["104442.9","0.09644166","0","1"],["104442.2","0","0","0"],["104441.9","0.67963855","0","3"],["104441.8","0.11106085","0","2"],["104441.6","0.14392722","0","1"],["104440.3","0.00005","0","1"],["104440.2","0.096611","0","1"],["104440.1","0.1666562","0","1"],["104439.6","0.0497493","0","1"],["104438.1","0","0","0"],["104437.8","0.24584421","0","1"],["104437.6","0","0","0"],["104437.4","0.15605736","0","1"],["104435.3","0.00478546","0","1"],["104435.1","0.247167","0","1"],["104432.2","0","0","0"],["104432.1","0","0","0"],["104431.9","0.25831616","0","1"],["104431.4","0.00383027","0","1"],["104431.1","0.2358735","0","1"],["104429.5","0.13878123","0","1"],["104269.9","0","0","0"],["104269.6","0","0","0"],["104269.2","0","0","0"],["104269","0","0","0"],["104268.9","0","0","0"],["104268.8","0","0","0"],["104268.4","0","0","0"],["104268.3","0","0","0"],["104268","0","0","0"]],"ts":"1747171027601","checksum":1305543318,"seqId":54226740396,"prevSeqId":54226740270}]}
{"arg":{"channel":"books","instId":"BTC-USDT"},"action":"update","data":[{"asks":[["104456.1","0.77623183","0","14"],["104456.6","0.09875","0","1"],["104457.1","0.036","0","1"],["104457.9","0.24880369","0","4"],["104462.8","0.00011435","0","1"],["104463","0.06521232","0","2"],["104463.2","0.09501717","0","1"],["104463.8","0.10079863","0","1"],["104463.9","0","0","0"],["104464.6","0","0","0"],["104464.8","0.10491549","0","2"],["104465.4","0.11247378","0","2"],["104465.6","0","0","0"],["104466.1","0","0","0"],["104468.3","0.15685198","0","1"],["104468.4","0","0","0"],["104468.6","0.07689878","0","1"],["104468.7","0.16421756","0","1"],["104468.8","0.16965495","0","1"],["104469.1","0.0382906","0","1"],["104469.4","0","0","0"],["104469.6","0.04","0","1"],["104471.6","0.15204157","0","1"],["104472.1","0.29138315","0","2"],["104472.4","0","0","0"],["104472.8","0.0084426","0","1"],["104473.8","0.25326263","0","1"],["104474.2","0.26986459","0","1"],["104474.6","0","0","0"],["104474.9","0","0","0"],["104477.9","0.24879906","0","1"],["104478.3","0","0","0"],["104478.6","0","0","0"],["104488.3","0.00660927","0","3"],["104488.5","0","0","0"],["104505","1","0","1"],["104514.3","0","0","0"],["104535","6.09744036","0","1"]],"bids":[["104457.8","0","0","0"],["104457","0","0","0"],["104456","0.08676076","0","5"],["104454.1","0.03948191","0","1"],["104447.4","0","0","0"],["104445.6","0.00955895","0","1"],["104445.1","0","0","0"],["104444.3","0.17566649","0","2"],["104443.6","0","0","0"],["104442.9","0.09675792","0","1"],["104442.2","0.09558334","0","1"],["104441.9","0.51538325","0","2"],["104441.6","0","0","0"],["104441.2","0.32779921","0","2"],["104440.8","0.1926876","0","3"],["104440.1","0","0","0"],["104439.3","0.16241067","0","1"],["104437.8","0","0","0"],["104437.4","0","0","0"],["104436.7","0.26365266","0","2"],["104436.6","0.25516021","0","4"],["104435.1","0","0","0"],["104434.3","0.2562767","0","1"],["104431.9","0","0","0"],["104431.5","0.54088653","0","2"],["104431.4","0","0","0"],["104431.2","0.24394084","0","1"],["104431.1","0","0","0"],["104430.4","0.25905201","0","1"],["104429.6","0.00383033","0","1"],["104409.7","0","0","0"],["104269.9","0.0000785","0","2"],["104269.6","0.00001237","0","1"],["104269.2","0.00026966","0","5"],["104269","0.00005407","0","1"],["104268.9","0.00001021","0","1"]],"ts":"1747171027701","checksum":-1400178442,"seqId":54226740626,"prevSeqId":54226740396}]}
{"arg":{"channel":"books","instId":"BTC-USDT"},"action":"update","data":[{"asks":[["104456.6","0","0","0"],["104457","0.0052193","0","1"],["104457.5","0.00095732","0","1"],["104462.8","0","0","0"],["104463","0.036","0","1"],["104463.2","0","0","0"],["104463.8","0","0","0"],["104463.9","0.00011435","0","1"],["104464.3","0.09105139","0","1"],["104464.8","0.01","0","1"],["104464.9","0.09453754","0","1"],["104465.4","0.01441826","0","1"],["104465.9","0.09755618","0","2"],["104466.4","0.09299353","0","1"],["104466.7","0.03049542","0","1"],["104467.2","0.00478546","0","1"],["104467.5","0.36908178","0","1"],["104468.3","0","0","0"],["104468.6","0.33108095","0","2"],["104468.7","0","0","0"],["104468.8","0","0","0"],["104469.4","0.15074503","0","1"],["104469.8","0.16480458","0","1"],["104469.9","0.16288605","0","1"],["104471.6","0","0","0"],["104472.1","0.03070467","0","1"],["104472.7","0.15236475","0","1"],["104473.2","0.24851464","0","1"],["104473.8","0","0","0"],["104474.2","0","0","0"],["104474.9","0.26775717","0","1"],["104475.3","0.24014561","0","1"],["104475.9","0.05351487","0","1"],["104477.9","0","0","0"],["104478.9","0.79813568","0","2"],["104490","0.00029006","0","2"],["104491","0","0","0"],["104492","0.002","0","2"],["104493","0.77966876","0","2"],["104495","0.00013979","0","1"],["104497.8","0","0","0"],["104508.3","0.02956059","0","2"],["104511","0","0","0"],["104511.3","0.1","0","1"],["104512","0","0","0"],["104512.6","0","0","0"],["104513","0.16","0","2"],["104514","0.24999999","0","5"],["104514.7","0.00155176","0","1"],["104515","0.08504786","0","3"],["104516.6","0","0","0"],["104605.4","0","0","0"],["104605.7","0","0","0"],["104607.5","0","0","0"]],"bids":[["104456","0.29154357","0","7"],["104453.7","0.02428787","0","1"],["104445.6","0.01218787","0","2"],["104445.4","0.18794972","0","2"],["104444.3","0","0","0"],["104443.9","0.12995369","0","2"],["104443.3","0.09435655","0","1"],["104442.9","0","0","0"],["104442.3","0.22245316","0","3"],["104442.2","0","0","0"],["104441.9","0.65982694","0","3"],["104441.2","0.17829353","0","1"],["104440.8","0.03001","0","2"],["104440.4","0.16275895","0","1"],["104439.6","0","0","0"],["104439.3","0","0","0"],["104438.2","0.25161235","0","1"],["104437.7","0.16634671","0","1"],["104436.7","0.39542965","0","3"],["104436.6","0.096","0","3"],["104435.4","0.26479664","0","1"],["104435.3","0","0","0"],["104434.6","0.00478546","0","1"],["104434.3","0","0","0"],["104432.3","0.26861532","0","1"],["104431.4","0.24852142","0","1"],["104431.2","0","0","0"],["104430.4","0","0","0"],["104403.7","0.00047867","0","1"],["104344.9","0","0","0"],["104343.3","0.00064059","0","1"],["104338.2","0","0","0"],["104336.5","0.00084095","0","1"],["104269","0","0","0"],["104268.9","0","0","0"]],"ts":"1747171027801","checksum":1696134070,"seqId":54226740841,"prevSeqId":54226740626}]}
{"arg":{"channel":"books","instId":"BTC-USDT"},"action":"update","data":[{"asks":[["104487.9","0.0001303","0","1"],["104488.8","0","0","0"],["104490","0.00229006","0","4"],["104491","0.001","0","1"],["104492","0","0","0"],["104493","0.77866876","0","1"],["104505","0","0","0"],["104510.8","0.1","0","1"],["104511","0.16","0","2"],["104511.3","0","0","0"],["104512","0.17999999","0","3"],["104513","0.05","0","1"],["104514","0.07","0","2"],["104515","0.03504786","0","2"],["104564.4","0.00009705","0","1"],["104566.5","0","0","0"],["104605.3","0","0","0"]],"bids":[["104456","0.29163357","0","8"],["104394.6","0.49177436","0","2"],["104393","0.00002963","0","1"],["104358.9","0","0","0"],["104357.6","0.00009943","0","1"],["104306","0","0","0"],["104303.6","0.0009571","0","1"],["104269.2","0","0","0"]],"ts":"1747171027901","checksum":-483928261,"seqId":54226740919,"prevSeqId":54226740841}]}
{"arg":{"channel":"books","instId":"BTC-USDT"},"action":"update","data":[{"asks":[["104464","0.75848332","0","4"],["104464.3","0","0","0"],["104464.7","0.09848861","0","1"],["104464.9","0","0","0"],["104465.7","0.0980293","0","1"],["104465.9","0.00045","0","1"],["104466.2","0.09162017","0","1"],["104466.4","0","0","0"],["104468.6","0.32405914","0","2"],["104469.2","0.14391881","0","1"],["104469.4","0","0","0"],["104469.5","0.16390901","0","1"],["104469.7","0.1631969","0","1"],["104469.8","0","0","0"],["104469.9","0","0","0"],["104472.4","0.15215571","0","1"],["104472.7","0","0","0"],["104472.9","0.23472858","0","2"],["104473.2","0","0","0"],["104474.7","0.25278018","0","1"],["104474.9","0","0","0"],["104475","0.24159707","0","1"],["104475.3","0","0","0"],["104478.7","0.24089875","0","1"],["104478.9","0.56142812","0","1"],["104511","0","0","0"],["104512","0.17","0","4"],["104513","0.245","0","4"],["104514","0.07999999","0","1"],["104515","0.00004786","0","1"],["104605.3","0.01059549","0","1"]],"bids":[["104456","0.20635076","0","7"],["104445.4","0","0","0"],["104445.2","0.19075851","0","2"],["104443.9","0.04","0","1"],["104443.7","0.09988525","0","1"],["104443.3","0","0","0"],["104443","0.09780434","0","1"],["104442.3","0.052","0","2"],["104442","0.93009192","0","2"],["104441.9","0.51538325","0","2"],["104441.7","0.35152663","0","2"],["104440.4","0","0","0"],["104440.2","0.26415977","0","2"],["104438.2","0","0","0"],["104437.9","0.25658944","0","1"],["104437.7","0","0","0"],["104437.4","0.15289372","0","1"],["104436.7","0.39260602","0","3"],["104435.4","0","0","0"],["104435.2","0.25489298","0","1"],["104432.3","0","0","0"],["104432","0.3211069","0","3"],["104431.4","0","0","0"],["104431.2","0.23366237","0","1"],["104393","0","0","0"],["104392","0.00002963","0","1"],["104269.2","0.00026966","0","5"]],"ts":"1747171028001","checksum":-1574452379,"seqId":54226741030,"prevSeqId":54226740919}]}
{"arg":{"channel":"books","instId":"BTC-USDT"},"action":"update","data":[{"asks":[["104467.2","0","0","0"],["104467.4","0.00478546","0","1"],["104478.8","0","0","0"],["104481","0.13877926","0","1"],["104494.4","0.00013991","0","1"],["104495","0","0","0"],["104500.8","0.00056666","0","1"],["104502.9","0","0","0"],["104511","0.16","0","2"],["104512","0.24999999","0","5"],["104513","0.085","0","2"],["104514","0","0","0"],["104548.7","0.00056666","0","1"],["104550.8","0","0","0"]],"bids":[["104451.3","0.03118036","0","2"],["104449","0","0","0"],["104447.5","0.05602676","0","1"],["104435.8","0.00478546","0","1"],["104434.6","0","0","0"],["104432.7","0.1387795","0","1"],["104430.8","0","0","0"],["104429.5","0","0","0"],["104428.8","0.00056666","0","1"],["104382.9","0","0","0"],["104380.9","0.01204505","0","2"],["104343.3","0","0","0"],["104342.9","0.0006406","0","1"],["104269","0.00005407","0","1"]],"ts":"1747171028101","checksum":-805726233,"seqId":54226741097,"prevSeqId":54226741030}]}
{"arg":{"channel":"books","instId":"BTC-USDT"},"action":"update","data":[{"asks":[["104473.4","0.43275947","0","2"],["104475.5","0.17829353","0","1"],["104480","0.14098798","0","4"],["104481","0","0","0"],["104503.7","0.17829353","0","1"]],"bids":[["104432.7","0","0","0"],["104432.1","0.13877982","0","1"],["104357.6","0","0","0"],["104357.2","0.00010066","0","1"]],"ts":"1747171028201","checksum":-805726233,"seqId":54226741115,"prevSeqId":54226741097}]}
{"arg":{"channel":"books","instId":"BTC-USDT"},"action":"update","data":[{"asks":[["104478.6","0.13878152","0","1"],["104480","0.00220843","0","3"],["104605.3","0","0","0"]],"bids":[["104447.7","0","0","0"],["104432.1","0","0","0"],["104431.3","0.13878137","0","1"],["104268.9","0.00001021","0","1"]],"ts":"1747171028301","checksum":482485202,"seqId":54226741127,"prevSeqId":54226741115}]}
{"arg":{"channel":"books","instId":"BTC-USDT"},"action":"update","data":[{"asks":[["104478.6","0","0","0"],["104478.9","0.70020894","0","2"],["104516.6","0.03620833","0","1"],["104542.4","0","0","0"],["104605.3","0.01059549","0","1"]],"bids":[["104431.6","0.14678082","0","2"],["104431.3","0","0","0"],["104268.8","0.31181159","0","3"]],"ts":"1747171028401","checksum":482485202,"seqId":54226741137,"prevSeqId":54226741127}]}
{"arg":{"channel":"books","instId":"BTC-USDT"},"action":"update","data":[{"asks":[["104467.2","0.00478546","0","1"],["104467.4","0","0","0"],["104478.9","0.56142812","0","1"],["104480","0.14098899","0","4"]],"bids":[],"ts":"1747171028501","checksum":-1047722430,"seqId":54226741149,"prevSeqId":54226741137}]}
{"arg":{"channel":"books","instId":"BTC-USDT"},"action":"update","data":[{"asks":[["104483.4","0.096614","0","1"],["104508.3","0.00047867","0","1"],["104508.4","0","0","0"]],"bids":[["104456","0.21023076","0","8"],["104441.8","0.03928085","0","1"],["104440.2","0.16754877","0","1"]],"ts":"1747171028701","checksum":861848097,"seqId":54226741164,"prevSeqId":54226741149}]}
{"arg":{"channel":"books","instId":"BTC-USDT"},"action":"update","data":[{"asks":[],"bids":[["104442.1","0.071782","0","1"],["104436.8","0.50891753","0","4"],["104268.8","0","0","0"]],"ts":"1747171028801","checksum":861848097,"seqId":54226741168,"prevSeqId":54226741164}]}
{"arg":{"channel":"books","instId":"BTC-USDT"},"action":"update","data":[{"asks":[["104467.2","0","0","0"],["104471","0.00478546","0","1"],["104490","0.00029006","0","2"],["104491","0","0","0"],["104492","0.002","0","2"],["104493","0.77966876","0","2"],["104505","1","0","1"],["104511","0","0","0"],["104512","0","0","0"],["104513","0.16","0","2"],["104514","0.24999999","0","5"],["104515","0.08504786","0","3"],["104535","0","0","0"],["104541.7","6.12760074","0","1"]],"bids":[["104438","0.00478546","0","1"],["104435.8","0","0","0"]],"ts":"1747171028901","checksum":-300816463,"seqId":54226741204,"prevSeqId":54226741168}]}
{"arg":{"channel":"books","instId":"BTC-USDT"},"action":"update","data":[{"asks":[["104457.9","0.01480369","0","3"],["104464","0.66406474","0","3"],["104464.7","0","0","0"],["104465.7","0","0","0"],["104466.2","0","0","0"],["104469.2","0","0","0"],["104469.5","0","0","0"],["104469.7","0","0","0"],["104472.4","0","0","0"],["104472.9","0.002","0","1"],["104474.7","0","0","0"],["104475","0","0","0"],["104478.7","0","0","0"],["104505","0","0","0"],["104535","6.12760074","0","1"],["104541.7","0","0","0"],["104605.4","0.03","0","1"],["104605.7","0.0000221","0","1"],["104607.5","0.00001","0","1"],["104608.2","0.01059542","0","1"],["104608.3","0.03","0","1"],["104608.4","0.00041816","0","1"],["104610","0.29261492","0","3"],["104610.9","0.01099559","0","1"],["104611","0.01099627","0","1"],["104611.3","0.00005484","0","1"],["104612.1","0.01059606","0","1"]],"bids":[["104456","0.42029514","0","9"],["104445.2","0","0","0"],["104443.7","0","0","0"],["104443","0","0","0"],["104442","0.77866876","0","1"],["104441.7","0.19242972","0","1"],["104440.2","0","0","0"],["104437.9","0","0","0"],["104437.4","0","0","0"],["104435.2","0","0","0"],["104432","0.052","0","2"],["104431.2","0","0","0"],["104268.8","0.31181159","0","3"],["104268.4","0.00039895","0","2"],["104268.3","0.00018565","0","4"],["104268","0.00011013","0","2"],["104267.5","0.80866876","0","2"],["104267.2","0.00001019","0","1"],["104267","0.0000111","0","1"],["104266.9","0.00002057","0","2"]],"ts":"1747171029001","checksum":1983214381,"seqId":54226741235,"prevSeqId":54226741204}]}
{"arg":{"channel":"books","instId":"BTC-USDT"},"action":"update","data":[{"asks":[["104456.1","0.74023183","0","13"],["104459.9","0","0","0"],["104464","0.0932","0","1"],["104464.4","0.09806762","0","1"],["104465.1","0.09050387","0","1"],["104465.3","0.32321281","0","1"],["104466.1","0.09469929","0","1"],["104466.6","0.08818811","0","1"],["104467.3","0","0","0"],["104467.6","0.19242972","0","1"],["104468.6","0.2610832","0","2"],["104469.6","0.18656","0","2"],["104469.9","0.16651119","0","1"],["104470.1","0.16353663","0","1"],["104472.8","0.17303853","0","2"],["104473.3","0.2459384","0","1"],["104473.4","0.42830568","0","2"],["104475.1","0.23802766","0","1"],["104475.4","0.24150363","0","1"],["104478.9","0.77340335","0","2"],["104479.1","0.86507849","0","2"],["104480","0.00220843","0","3"],["104481","0.13877868","0","1"],["104494.5","0.26557422","0","1"],["104498.5","0.234","0","1"],["104500.8","0","0","0"],["104504.1","0.00056666","0","1"],["104546.2","0.08110019","0","1"],["104548.7","0","0","0"],["104552","0.01156293","0","2"],["104605.7","0","0","0"],["104607.5","0","0","0"],["104608.2","0","0","0"],["104608.3","0","0","0"],["104608.4","0","0","0"],["104610","0","0","0"],["104610.9","0","0","0"],["104611","0","0","0"],["104611.3","0","0","0"],["104612.1","0","0","0"]],"bids":[["104456","0.47229514","0","11"],["104445.6","0.18523417","0","3"],["104445.3","0.01455898","0","2"],["104444.1","0.09317185","0","1"],["104443.4","0.09834374","0","1"],["104442.4","0.16790908","0","1"],["104442.1","0.23389516","0","2"],["104441.9","0.49849951","0","2"],["104440.6","0.16724627","0","1"],["104438.4","0.00478546","0","1"],["104438.3","0.2555488","0","1"],["104438","0","0","0"],["104437.8","0.15535774","0","1"],["104436.7","0.46220176","0","3"],["104435.6","0.24950044","0","1"],["104432.7","0.13877868","0","1"],["104432.4","0.26102728","0","1"],["104432.1","0.00056666","0","1"],["104431.6","0.25824342","0","2"],["104431.5","0.36869051","0","1"],["104428.8","0","0","0"],["104384.2","0.77923542","0","2"],["104380.9","0.01147839","0","1"],["104268.9","0","0","0"],["104268.8","0","0","0"],["104268.4","0","0","0"],["104268.3","0","0","0"],["104268","0","0","0"],["104267.5","0","0","0"],["104267.2","0","0","0"],["104267","0","0","0"],["104266.9","0","0","0"]],"ts":"1747171029101","checksum":-324906684,"seqId":54226741342,"prevSeqId":54226741235}]}
{"arg":{"channel":"books","instId":"BTC-USDT"},"action":"update","data":[{"asks":[["104456.1","0.47284045","0","8"],["104457.1","0","0","0"],["104458.1","0","0","0"],["104465","0","0","0"],["104465.3","0","0","0"],["104466","0.0932","0","1"],["104467.5","0","0","0"],["104467.6","0","0","0"],["104468.3","0.03161562","0","1"],["104472.2","0","0","0"],["104481","0","0","0"],["104482.3","0.13877788","0","1"],["104484.7","0","0","0"],["104492","0","0","0"],["104493","0.77866876","0","1"],["104495","0.002","0","2"],["104496","0.001","0","1"],["104504.9","0","0","0"],["104513","0","0","0"],["104514","0","0","0"],["104515","0.00004786","0","1"],["104516","0.15999999","0","2"],["104517","0.24999999","0","5"],["104518","0.085","0","2"],["104535","0","0","0"],["104541.7","6.12760074","0","1"],["104605.7","0.0000221","0","1"],["104607.5","0.00001","0","1"],["104608.2","0.01059542","0","1"],["104608.3","0.03","0","1"],["104608.4","0.00041816","0","1"],["104610","0.29261492","0","3"]],"bids":[["104456","0.47230514","0","12"],["104455.8","0.03353126","0","1"],["104451.4","0","0","0"],["104447.6","0.00866406","0","1"],["104446.9","0.60299878","0","1"],["104445.7","0.36908178","0","1"],["104431.8","0","0","0"],["104419.3","0","0","0"],["104418.8","0.0028711","0","1"],["104379.8","0","0","0"]],"ts":"1747171029201","checksum":1576276614,"seqId":54226741433,"prevSeqId":54226741342}]}
{"arg":{"channel":"books","instId":"BTC-USDT"},"action":"update","data":[{"asks":[["104465","0.21774432","0","1"],["104467.7","0.19242972","0","1"],["104469.8","0.00478546","0","1"],["104471","0","0","0"],["104492","0.002","0","2"],["104493","0.77966876","0","2"],["104495","0","0","0"],["104496","0","0","0"],["104518.8","0.02164047","0","1"],["104608.4","0","0","0"],["104610","0","0","0"]],"bids":[["104445.7","0","0","0"],["104438.4","0","0","0"],["104437.9","0.00478546","0","1"],["104268.9","0.00001021","0","1"]],"ts":"1747171029301","checksum":1866994920,"seqId":54226741447,"prevSeqId":54226741433}]}
{"arg":{"channel":"books","instId":"BTC-USDT"},"action":"update","data":[{"asks":[["104460.1","0.0551453","0","2"],["104469","0.00478546","0","1"],["104469.5","0.0383585","0","1"],["104469.8","0","0","0"],["104513","0.16","0","2"],["104514","0.17999999","0","3"],["104515","0.05004786","0","2"],["104516","0","0","0"],["104516.6","0","0","0"],["104517","0.07","0","2"],["104518","0.035","0","1"],["104608.3","0","0","0"]],"bids":[["104437.9","0","0","0"],["104436.9","0.00478546","0","1"]],"ts":"1747171029401","checksum":943354638,"seqId":54226741468,"prevSeqId":54226741447}]}
{"arg":{"channel":"books","instId":"BTC-USDT"},"action":"update","data":[{"asks":[["104463.9","0","0","0"],["104464.3","0.09670819","0","1"],["104464.4","0","0","0"],["104464.9","0.10210479","0","2"],["104465","0.30125081","0","2"],["104465.1","0","0","0"],["104465.9","0.0955489","0","2"],["104466.1","0","0","0"],["104466.4","0.0925763","0","1"],["104466.6","0","0","0"],["104467.6","0.36908178","0","1"],["104468.2","0.00478546","0","1"],["104468.6","0.07689878","0","1"],["104469","0","0","0"],["104469.4","0.14415102","0","1"],["104469.6","0.04","0","1"],["104469.8","0.1623174","0","1"],["104469.9","0.16791378","0","1"],["104470.1","0","0","0"],["104472.7","0.15821902","0","1"],["104472.8","0.0084426","0","1"],["104473.3","0","0","0"],["104474.9","0.25058178","0","1"],["104475.1","0","0","0"],["104475.3","0.24236899","0","1"],["104475.4","0","0","0"],["104478.9","1.03780882","0","3"],["104479.1","0.60218","0","1"],["104481","0.13877922","0","1"],["104482.3","0","0","0"]],"bids":[["104456","0.26544076","0","12"],["104446.9","0.32947348","0","1"],["104445.6","0.00262892","0","1"],["104445.4","0.19470632","0","2"],["104444.1","0","0","0"],["104443.9","0.12832109","0","2"],["104443.4","0","0","0"],["104443.3","0.09178224","0","1"],["104442.4","0","0","0"],["104442.3","0.21764277","0","3"],["104442.1","0.071782","0","1"],["104441.9","0.49819342","0","2"],["104440.6","0","0","0"],["104440.4","0.16894823","0","1"],["104438.3","0","0","0"],["104437.8","0","0","0"],["104437.7","0.15832803","0","1"],["104436.9","0","0","0"],["104436.7","0.26365266","0","2"],["104436","0.00478546","0","1"],["104435.6","0","0","0"],["104435.4","0.25441446","0","1"],["104432.4","0","0","0"],["104432.3","0.26859067","0","1"],["104431.6","0.008","0","1"],["104431.4","0.25889284","0","1"],["104268.8","0.31181159","0","3"]],"ts":"1747171029501","checksum":1915233311,"seqId":54226741534,"prevSeqId":54226741468}]}
{"arg":{"channel":"books","instId":"BTC-USDT"},"action":"update","data":[{"asks":[["104458.2","0.005","0","1"],["104463.9","0.00011435","0","1"],["104464.3","0","0","0"],["104464.4","0.08982296","0","1"],["104464.9","0","0","0"],["104465.1","0.10037869","0","1"],["104465.9","0.00045","0","1"],["104466.1","0.08813423","0","1"],["104466.4","0","0","0"],["104466.6","0.09935913","0","1"],["104468.2","0","0","0"],["104468.6","0.26908281","0","2"],["104469","0.00478546","0","1"],["104469.4","0","0","0"],["104469.5","0","0","0"],["104469.6","0.19622333","0","2"],["104469.8","0","0","0"],["104469.9","0.15343509","0","1"],["104470.1","0.15726143","0","1"],["104470.7","0.005","0","1"],["104472.7","0","0","0"],["104472.8","0.17103336","0","2"],["104473.3","0.24701229","0","1"],["104474.9","0","0","0"],["104475.1","0.26223016","0","1"],["104475.3","0","0","0"],["104475.4","0.27253298","0","1"],["104478.9","0.77340335","0","2"],["104479.1","0.86054075","0","2"],["104607.5","0","0","0"],["104608.2","0","0","0"]],"bids":[["104456","0.43022852","0","14"],["104455.8","0","0","0"],["104452.4","0.03143834","0","1"],["104446.9","0.49708435","0","2"],["104445.6","0.19875084","0","3"],["104445.4","0","0","0"],["104444.1","0.09822777","0","1"],["104443.9","0.04","0","1"],["104443.4","0.09772626","0","1"],["104443.3","0","0","0"],["104442.4","0.16119241","0","1"],["104442.3","0.052","0","2"],["104442.1","0.21449717","0","2"],["104441.9","0.48842742","0","2"],["104440.6","0.15091042","0","1"],["104440.4","0","0","0"],["104438.3","0.24180093","0","1"],["104437.8","0.15186784","0","1"],["104437.7","0","0","0"],["104436.9","0.00478546","0","1"],["104436.7","0.5012046","0","3"],["104436","0","0","0"],["104435.6","0.23923772","0","1"],["104435.4","0","0","0"],["104432.4","0.26402519","0","1"],["104432.3","0","0","0"],["104431.8","0.005","0","1"],["104431.6","0.25617235","0","2"],["104431.4","0","0","0"],["104419.3","0.005","0","1"],["104269","0","0","0"],["104268.9","0","0","0"],["104268.8","0","0","0"]],"ts":"1747171029601","checksum":-1902956830,"seqId":54226741615,"prevSeqId":54226741534}]}
{"arg":{"channel":"books","instId":"BTC-USDT"},"action":"update","data":[{"asks":[["104457.5","0","0","0"],["104469","0","0","0"],["104469.8","0.00478546","0","1"],["104470.5","0.0383585","0","1"],["104514","0.24999999","0","5"],["104515","0.08504786","0","3"],["104517","0","0","0"],["104518","0","0","0"],["104607.5","0.00001","0","1"],["104608.2","0.01059542","0","1"]],"bids":[["104437.9","0.00478546","0","1"],["104436.9","0","0","0"]],"ts":"1747171029701","checksum":-247710142,"seqId":54226741627,"prevSeqId":54226741615}]}
{"arg":{"channel":"books","instId":"BTC-USDT"},"action":"update","data":[{"asks":[["104481","0","0","0"],["104482.3","0.13877789","0","1"]],"bids":[],"ts":"1747171029801","checksum":-247710142,"seqId":54226741632,"prevSeqId":54226741627}]}
{"arg":{"channel":"books","instId":"BTC-USDT"},"action":"update","data":[{"asks":[["104471.1","0.04224805","0","2"],["104482.6","0.0599306","0","1"]],"bids":[],"ts":"1747171029901","checksum":-247710142,"seqId":54226741634,"prevSeqId":54226741632}]}
{"arg":{"channel":"books","instId":"BTC-USDT"},"action":"update","data":[{"asks":[["104469","0.00478546","0","1"],["104469.8","0","0","0"],["104512.7","0","0","0"],["104544.1","0","0","0"],["104608.3","0.03","0","1"],["104608.4","0.00041816","0","1"]],"bids":[["104437.9","0","0","0"],["104436.9","0.00478546","0","1"],["104420.1","0","0","0"],["104388.8","0","0","0"],["104269","0.00005407","0","1"],["104268.9","0.00001021","0","1"]],"ts":"1747171030001","checksum":-247710142,"seqId":54226741645,"prevSeqId":54226741634}]}
{"arg":{"channel":"books","instId":"BTC-USDT"},"action":"update","data":[{"asks":[["104482.3","0.13877713","0","1"],["104502.6","0.00056666","0","1"],["104504.1","0","0","0"],["104505.2","1.43737096","0","2"],["104510","0.00028006","0","1"],["104538.3","6.12760074","0","1"],["104541.7","0","0","0"],["104550.4","0.00056666","0","1"],["104552","0.01099627","0","1"],["104608.4","0","0","0"]],"bids":[["104445.3","0.005","0","1"],["104444.1","0.10778686","0","2"],["104432.1","0","0","0"],["104430.6","0.00056666","0","1"],["104422.6","1.45466513","0","2"],["104420.2","0.43770998","0","1"],["104388.9","0.01786342","0","1"],["104384.2","0.77866876","0","1"],["104382.7","0.00056666","0","1"],["104268.9","0","0","0"]],"ts":"1747171030101","checksum":-853029087,"seqId":54226741711,"prevSeqId":54226741645}]}
{"arg":{"channel":"books","instId":"BTC-USDT"},"action":"update","data":[{"asks":[["104536.5","2.52973322","0","1"],["104538.3","0","0","0"],["104541.7","6.09942657","0","1"],["104608.3","0","0","0"]],"bids":[["104456","0.42895526","0","14"],["104391.3","2.61697461","0","1"],["104269","0","0","0"]],"ts":"1747171030201","checksum":211608887,"seqId":54226741717,"prevSeqId":54226741711}]}
{"arg":{"channel":"books","instId":"BTC-USDT"},"action":"update","data":[{"asks":[["104462","0.0932","0","1"],["104465","0.34481309","0","1"],["104466.4","0.04","0","1"],["104468.5","0.00479546","0","2"],["104469","0","0","0"],["104469.6","0.15622333","0","1"],["104481","0.13877791","0","1"],["104482.3","0","0","0"],["104490","0.00229006","0","4"],["104491","0.001","0","1"],["104492","0","0","0"],["104493","0.77866876","0","1"],["104511","0.16","0","2"],["104512","0.24999999","0","5"],["104513","0.085","0","2"],["104514","0","0","0"],["104515","0.00004786","0","1"],["104607.5","0","0","0"],["104608.2","0","0","0"]],"bids":[],"ts":"1747171030301","checksum":2048463550,"seqId":54226741759,"prevSeqId":54226741717}]}
{"arg":{"channel":"books","instId":"BTC-USDT"},"action":"update","data":[{"asks":[["104468.5","0.00001","0","1"],["104469","0.00478546","0","1"],["104470.5","0","0","0"],["104490","0.00029006","0","2"],["104491","0","0","0"],["104492","0.002","0","2"],["104493","0.77966876","0","2"],["104505.1","0.43146425","0","1"],["104511","0","0","0"],["104512","0","0","0"],["104513","0.16","0","2"],["104514","0.24999999","0","5"],["104515","0.08504786","0","3"],["104535.9","0.55551571","0","1"],["104605.7","0","0","0"]],"bids":[],"ts":"1747171030401","checksum":2048463550,"seqId":54226741793,"prevSeqId":54226741759}]}
{"arg":{"channel":"books","instId":"BTC-USDT"},"action":"update","data":[{"asks":[["104470.4","0.0383585","0","1"],["104605.4","0","0","0"]],"bids":[],"ts":"1747171030501","checksum":2048463550,"seqId":54226741796,"prevSeqId":54226741793}]}
{"arg":{"channel":"books","instId":"BTC-USDT"},"action":"update","data":[{"asks":[["104468.5","0.00479546","0","2"],["104469","0","0","0"],["104605.4","0.03","0","1"]],"bids":[["104436.9","0","0","0"],["104436.8","0.51370299","0","5"],["104269","0.00005407","0","1"]],"ts":"1747171030601","checksum":2048463550,"seqId":54226741802,"prevSeqId":54226741796}]}
{"arg":{"channel":"books","instId":"BTC-USDT"},"action":"update","data":[{"asks":[["104464.8","0.03852198","0","2"],["104468.3","0","0","0"],["104605.7","0.0000221","0","1"]],"bids":[],"ts":"1747171030701","checksum":274675898,"seqId":54226741807,"prevSeqId":54226741802}]}
{"arg":{"channel":"books","instId":"BTC-USDT"},"action":"update","data":[{"asks":[],"bids":[["104456","0.42575526","0","13"]],"ts":"1747171030801","checksum":-2140084611,"seqId":54226741812,"prevSeqId":54226741807}]}
{"arg":{"channel":"books","instId":"BTC-USDT"},"action":"update","data":[{"asks":[["104460.1","0.06375059","0","3"],["104465","0.53531208","0","2"],["104467.5","0.77866876","0","1"],["104605.7","0","0","0"]],"bids":[["104456","0.32723188","0","12"],["104436.8","0.50891753","0","4"],["104436","0.00478546","0","1"],["104418.8","0","0","0"],["104399","0.002871","0","1"],["104269","0","0","0"]],"ts":"1747171030901","checksum":-215694579,"seqId":54226741822,"prevSeqId":54226741812}]}
{"arg":{"channel":"books","instId":"BTC-USDT"},"action":"update","data":[{"asks":[["104465","0.63074254","0","3"],["104465.1","0","0","0"],["104466","0.19043494","0","2"],["104466.1","0","0","0"],["104466.5","0.09512482","0","1"],["104466.6","0","0","0"],["104468.6","0.24535259","0","2"],["104469.5","0.14987516","0","1"],["104469.6","0","0","0"],["104470","0.25388893","0","4"],["104470.1","0","0","0"],["104475","0.26556604","0","1"],["104475.1","0","0","0"],["104479","0.68749223","0","4"],["104479.1","0.60218","0","1"],["104480","0.14098808","0","4"],["104481","0","0","0"],["104505","1","0","1"],["104605.7","0.0000221","0","1"],["104607.5","0.00001","0","1"],["104608.2","0.01059542","0","1"]],"bids":[["104445.6","0.00262892","0","1"],["104445.5","0.18631448","0","2"],["104444.1","0.00955909","0","1"],["104444","0.08848831","0","1"],["104442.1","0.071782","0","1"],["104442","0.93736335","0","2"],["104440.6","0","0","0"],["104440.5","0.14873568","0","1"],["104436.7","0.35624722","0","2"],["104435.6","0","0","0"],["104435.5","0.2618303","0","1"],["104432.7","0","0","0"],["104432.6","0.50786143","0","2"],["104431.6","0.008","0","1"],["104431.5","0.62520882","0","2"],["104269.2","0","0","0"]],"ts":"1747171031001","checksum":1889696069,"seqId":54226741866,"prevSeqId":54226741822}]}
{"arg":{"channel":"books","instId":"BTC-USDT"},"action":"update","data":[{"asks":[["104465","0.53531208","0","2"],["104465.1","0.09549326","0","1"],["104466","0.0932","0","1"],["104466.1","0.09202695","0","1"],["104466.5","0","0","0"],["104466.6","0.09634091","0","1"],["104468.6","0.24392374","0","2"],["104469.5","0","0","0"],["104469.6","0.14997168","0","1"],["104470","0.09349006","0","3"],["104470.1","0.15553953","0","1"],["104475","0","0","0"],["104475.1","0.25586081","0","1"],["104479","0.44408178","0","3"],["104479.1","0.85119193","0","2"],["104480","0.14098778","0","4"],["104501.1","0.00056666","0","1"],["104502.6","0","0","0"],["104548.9","0.00056666","0","1"],["104550.4","0","0","0"],["104605.7","0","0","0"],["104607.5","0","0","0"],["104608.2","0","0","0"]],"bids":[["104456","0.36965526","0","13"],["104445.6","0.18585828","0","3"],["104445.5","0","0","0"],["104444.1","0.09849254","0","1"],["104444","0","0","0"],["104442.8","0.00955921","0","1"],["104442.1","0.21723387","0","2"],["104442","0.77866876","0","1"],["104440.6","0.1678585","0","1"],["104440.5","0","0","0"],["104436.8","0.51370299","0","5"],["104436.7","0.50192455","0","3"],["104436","0","0","0"],["104435.6","0.27015621","0","1"],["104435.5","0","0","0"],["104432.7","0.13877921","0","1"],["104432.6","0.36908178","0","1"],["104431.6","0.26680045","0","2"],["104431.5","0.36869051","0","1"],["104430.6","0","0","0"],["104429.1","0.00056666","0","1"],["104382.7","0","0","0"],["104381.2","0.00056666","0","1"],["104269.2","0.00026966","0","5"]],"ts":"1747171031101","checksum":1132483858,"seqId":54226741916,"prevSeqId":54226741866}]}
{"arg":{"channel":"books","instId":"BTC-USDT"},"action":"update","data":[{"asks":[["104464.1","0.09457524","0","1"],["104464.4","0","0","0"],["104464.8","0.13978933","0","3"],["104465.1","0","0","0"],["104465.8","0.0946567","0","1"],["104466.1","0","0","0"],["104466.3","0.1203221","0","2"],["104466.6","0","0","0"],["104467.9","0.00478546","0","1"],["104468.5","0.00001","0","1"],["104468.6","0.31800444","0","2"],["104469.3","0.14365938","0","1"],["104469.6","0.15102962","0","1"],["104469.8","0.1656384","0","1"],["104469.9","0","0","0"],["104470.1","0","0","0"],["104472.6","0.16422565","0","1"],["104472.8","0.0084426","0","1"],["104473","0.24391966","0","1"],["104473.3","0","0","0"],["104474.8","0.27049522","0","1"],["104475.1","0.27156715","0","1"],["104475.4","0","0","0"],["104478.8","0.25740915","0","1"],["104479.1","0.60218","0","1"],["104480","0.14098776","0","4"],["104605.4","0","0","0"]],"bids":[["104456","0.2484475","0","12"],["104445.6","0.00262892","0","1"],["104445.3","0.18049237","0","3"],["104444.1","0","0","0"],["104443.8","0.09859376","0","1"],["104443.4","0","0","0"],["104443.1","0.08973425","0","1"],["104442.4","0","0","0"],["104442.1","0.22441945","0","2"],["104441.8","0.18985697","0","2"],["104440.6","0","0","0"],["104440.3","0.1566416","0","2"],["104438.3","0","0","0"],["104438","0.23652412","0","1"],["104437.8","0","0","0"],["104437.6","0.15306754","0","1"],["104436.8","0.50891753","0","4"],["104436.7","0.35624722","0","2"],["104436","0.00478546","0","1"],["104435.6","0","0","0"],["104435.3","0.2434292","0","1"],["104432.7","0","0","0"],["104432.4","0","0","0"],["104432.1","0.38839613","0","2"],["104431.6","0.008","0","1"],["104431.3","0.26100578","0","1"],["104392","0","0","0"],["104269","0.00005407","0","1"],["104268.9","0.00001021","0","1"]],"ts":"1747171031201","checksum":481776491,"seqId":54226742000,"prevSeqId":54226741916}]}
{"arg":{"channel":"books","instId":"BTC-USDT"},"action":"update","data":[{"asks":[["104488.2","0.00287126","0","1"],["104488.3","0.00373804","0","2"],["104505","0","0","0"]],"bids":[["104392","0.00002963","0","1"],["104268.9","0","0","0"]],"ts":"1747171031301","checksum":481776491,"seqId":54226742009,"prevSeqId":54226742000}]}
{"arg":{"channel":"books","instId":"BTC-USDT"},"action":"update","data":[{"asks":[],"bids":[["104392","0","0","0"],["104268.9","0.00001021","0","1"]],"ts":"1747171031401","checksum":481776491,"seqId":54226742012,"prevSeqId":54226742009}]}
{"arg":{"channel":"books","instId":"BTC-USDT"},"action":"update","data":[{"asks":[["104509.8","1.0506188","0","2"],["104535.9","0","0","0"],["104605.4","0.03","0","1"]],"bids":[["104424.5","0.68569213","0","2"],["104394.6","1.22947748","0","1"],["104392","0.00002963","0","1"],["104268.9","0","0","0"]],"ts":"1747171031501","checksum":481776491,"seqId":54226742021,"prevSeqId":54226742012}]}
{"arg":{"channel":"books","instId":"BTC-USDT"},"action":"update","data":[{"asks":[["104467.9","0","0","0"],["104468.5","0.00479546","0","2"],["104605.7","0.0000221","0","1"]],"bids":[["104432.1","0.24961639","0","1"],["104431.6","0.14678044","0","2"]],"ts":"1747171031601","checksum":481776491,"seqId":54226742029,"prevSeqId":54226742021}]}
{"arg":{"channel":"books","instId":"BTC-USDT"},"action":"update","data":[{"asks":[["104464","0.18626525","0","2"],["104464.1","0","0","0"],["104464.7","0.09293808","0","1"],["104464.8","0.03852198","0","2"],["104465.7","0.09397549","0","1"],["104465.8","0","0","0"],["104466.2","0.09379092","0","1"],["104466.3","0.02822972","0","1"],["104467.4","0.00478546","0","1"],["104468.5","0.00001","0","1"],["104468.6","0.32738515","0","2"],["104469.2","0.14824961","0","1"],["104469.3","0","0","0"],["104469.5","0.16157288","0","1"],["104469.6","0","0","0"],["104469.7","0.15191521","0","1"],["104469.8","0","0","0"],["104472.4","0.15248865","0","1"],["104472.6","0","0","0"],["104472.9","0.2520173","0","2"],["104473","0","0","0"],["104474.7","0.24580242","0","1"],["104474.8","0","0","0"],["104475","0.26977498","0","1"],["104475.1","0","0","0"],["104478.6","0.13878126","0","1"],["104478.7","0.2521848","0","1"],["104478.8","0","0","0"],["104479.1","0","0","0"],["104480","0.00220843","0","3"],["104481.1","0.036","0","1"],["104505.1","1.03364425","0","2"],["104506.4","0.56242","0","1"],["104605.4","0","0","0"],["104605.7","0","0","0"]],"bids":[["104456","0.2092475","0","10"],["104446.9","0.32947348","0","1"],["104445.3","0.005","0","1"],["104445.2","0.18907006","0","2"],["104443.8","0","0","0"],["104443.7","0.09152038","0","1"],["104443.1","0","0","0"],["104443","0.09366232","0","1"],["104442.1","0.071782","0","1"],["104442","0.93678098","0","2"],["104441.9","0.47006458","0","2"],["104441.8","0.03928085","0","1"],["104441.7","0.35437764","0","2"],["104440.3","0.00005","0","1"],["104440.2","0.16172388","0","1"],["104438","0","0","0"],["104437.9","0.22832975","0","1"],["104437.6","0","0","0"],["104437.4","0.16448337","0","1"],["104436.7","0.39401757","0","3"],["104436","0","0","0"],["104435.4","0.00478546","0","1"],["104435.3","0","0","0"],["104435.2","0.25880203","0","1"],["104432.1","0","0","0"],["104432","0.32190302","0","3"],["104431.6","0.008","0","1"],["104431.3","0","0","0"],["104431.2","0.25988193","0","1"],["104429.5","0.13878149","0","1"],["104269.2","0","0","0"],["104269","0","0","0"]],"ts":"1747171031701","checksum":-1159057987,"seqId":54226742127,"prevSeqId":54226742029}]}
{"arg":{"channel":"books","instId":"BTC-USDT"},"action":"update","data":[{"asks":[["104462.3","0.02852266","0","1"],["104467.4","0","0","0"],["104467.9","0.00478546","0","1"],["104475.9","0","0","0"]],"bids":[["104453.7","0","0","0"],["104450.6","0.0259714","0","1"],["104436","0.00478546","0","1"],["104435.4","0","0","0"],["104431.3","0.13878115","0","1"],["104429.5","0","0","0"]],"ts":"1747171031801","checksum":750242221,"seqId":54226742139,"prevSeqId":54226742127}]}
{"arg":{"channel":"books","instId":"BTC-USDT"},"action":"update","data":[{"asks":[["104462.3","0","0","0"],["104475.8","0.04873479","0","1"],["104478.6","0","0","0"],["104480","0.140989","0","4"],["104605.4","0.03","0","1"]],"bids":[["104431.6","0.14678057","0","2"],["104431.3","0","0","0"],["104407","0","0","0"],["104406","0.48324487","0","1"],["104360","0.00220843","0","3"],["104359","0.47439916","0","1"],["104357.2","0","0","0"],["104303.6","0","0","0"],["104269.2","0.00026966","0","5"],["104269","0.00005407","0","1"]],"ts":"1747171031901","checksum":-393007399,"seqId":54226742153,"prevSeqId":54226742139}]}
{"arg":{"channel":"books","instId":"BTC-USDT"},"action":"update","data":[{"asks":[["104465","0.34481309","0","1"],["104467.5","0","0","0"],["104467.9","0","0","0"],["104468.5","0.00479546","0","2"],["104470.1","0.0383585","0","1"],["104470.4","0","0","0"],["104472.4","0","0","0"],["104482.7","0.60218","0","1"],["104484","0.56242","0","1"],["104505.1","0.43146425","0","1"],["104506.4","0","0","0"],["104605.7","0.0000221","0","1"],["104607.5","0.00001","0","1"]],"bids":[["104456","0.2124475","0","11"],["104437.4","0","0","0"],["104268.9","0.00001021","0","1"]],"ts":"1747171032001","checksum":-555824442,"seqId":54226742166,"prevSeqId":54226742153}]}
{"arg":{"channel":"books","instId":"BTC-USDT"},"action":"update","data":[{"asks":[["104464","0.0932","0","1"],["104464.3","0.09454552","0","1"],["104464.7","0","0","0"],["104465","0.59521689","0","3"],["104465.7","0","0","0"],["104466","0.18587598","0","2"],["104466.2","0","0","0"],["104466.5","0.09083348","0","1"],["104467.5","0.77866876","0","1"],["104468.4","0.00478546","0","1"],["104468.5","0.00001","0","1"],["104468.6","0.33458688","0","2"],["104469.2","0","0","0"],["104469.5","0.15744508","0","1"],["104469.7","0","0","0"],["104469.8","0.16710094","0","1"],["104470","0.24765146","0","4"],["104472.8","0.17379099","0","2"],["104472.9","0.002","0","1"],["104473.2","0.24419362","0","1"],["104473.4","0.42951518","0","2"],["104474.7","0","0","0"],["104475","0.23755901","0","1"],["104475.3","0.25078403","0","1"],["104478.7","0","0","0"],["104479","0.68504134","0","4"],["104480","0.14098884","0","4"],["104500.1","0.00056666","0","1"],["104501.1","0","0","0"],["104541.6","0.27137867","0","2"],["104548","0.00056666","0","1"],["104548.9","0","0","0"]],"bids":[["104456","0.32089088","0","10"],["104446.9","0.48836944","0","2"],["104445.5","0.18470534","0","2"],["104445.2","0","0","0"],["104444","0.09531145","0","1"],["104443.7","0","0","0"],["104443.3","0.09605823","0","1"],["104443","0","0","0"],["104442.8","0","0","0"],["104442.3","0.20559608","0","3"],["104442","0.92549046","0","2"],["104441.7","0.19242972","0","1"],["104441.6","0.00955932","0","1"],["104440.5","0.15330415","0","1"],["104440.2","0","0","0"],["104438.2","0.24824946","0","1"],["104437.9","0","0","0"],["104437.8","0.15757404","0","1"],["104435.5","0.2586857","0","1"],["104435.2","0","0","0"],["104432.3","0.26000225","0","1"],["104432","0.052","0","2"],["104431.5","0.63545114","0","2"],["104431.2","0","0","0"],["104429.1","0","0","0"],["104428.1","0.19299638","0","2"],["104381.2","0","0","0"],["104380.3","0.00056666","0","1"],["104357.6","0.00009662","0","1"],["104303.6","0.00095709","0","1"],["104269","0","0","0"],["104268.9","0","0","0"]],"ts":"1747171032101","checksum":1661320381,"seqId":54226742267,"prevSeqId":54226742166}]}
{"arg":{"channel":"books","instId":"BTC-USDT"},"action":"update","data":[{"asks":[["104464","0.18995244","0","2"],["104464.3","0","0","0"],["104464.7","0.09569775","0","1"],["104465","0.50528038","0","2"],["104465.7","0.09159032","0","1"],["104466","0.0932","0","1"],["104466.2","0.0945972","0","1"],["104466.5","0","0","0"],["104467.9","0.00478546","0","1"],["104468.4","0","0","0"],["104468.6","0.32787779","0","2"],["104469.2","0.15783382","0","1"],["104469.5","0.15963386","0","1"],["104469.7","0.15291524","0","1"],["104469.8","0","0","0"],["104470","0.09349006","0","3"],["104472.8","0.0084426","0","1"],["104472.9","0.23756267","0","2"],["104473.2","0","0","0"],["104473.4","0.43798512","0","2"],["104474.7","0.2717295","0","1"],["104475","0.24984666","0","1"],["104475.3","0","0","0"],["104476.4","0.00094","0","2"],["104478.7","0.24327269","0","1"],["104479","0.44408178","0","3"],["104479.9","0.13877979","0","1"],["104480","0.00220843","0","3"],["104488.9","0","0","0"],["104605.7","0","0","0"],["104607.5","0","0","0"]],"bids":[["104456","0.2121675","0","10"],["104446.9","0.32947348","0","1"],["104445.5","0","0","0"],["104445.3","0","0","0"],["104445.2","0.18975977","0","2"],["104444","0","0","0"],["104443.7","0.09479778","0","1"],["104443.3","0","0","0"],["104443","0.09833147","0","1"],["104442.3","0.052","0","2"],["104442","0.93069629","0","2"],["104441.7","0.34615802","0","2"],["104440.5","0","0","0"],["104440.2","0.1655728","0","1"],["104438.2","0","0","0"],["104437.9","0.2336473","0","1"],["104437.8","0","0","0"],["104435.5","0","0","0"],["104435.2","0.25584126","0","1"],["104432.3","0","0","0"],["104432.1","0.13877979","0","1"],["104432","0.32552561","0","3"],["104431.6","0.008","0","1"],["104431.5","0.36869051","0","1"],["104431.2","0.2483294","0","1"],["104269","0.00005407","0","1"]],"ts":"1747171032201","checksum":-836417047,"seqId":54226742409,"prevSeqId":54226742267}]}
{"arg":{"channel":"books","instId":"BTC-USDT"},"action":"update","data":[{"asks":[["104472.4","0.14754748","0","1"],["104478.6","0.13878133","0","1"],["104479.9","0","0","0"],["104605.4","0","0","0"]],"bids":[["104456","0.2089675","0","9"],["104437.4","0.15039447","0","1"],["104432.1","0","0","0"],["104429.5","0.13878161","0","1"],["104269","0","0","0"]],"ts":"1747171032301","checksum":-430015739,"seqId":54226742424,"prevSeqId":54226742409}]}
{"arg":{"channel":"books","instId":"BTC-USDT"},"action":"update","data":[{"asks":[["104464","0.19035352","0","2"],["104464.7","0.09414582","0","1"],["104465.7","0.09395105","0","1"],["104466.2","0.09937289","0","1"],["104467.9","0","0","0"],["104468.4","0.00478546","0","1"],["104468.6","0.33107929","0","2"],["104469.2","0.14856082","0","1"],["104469.5","0.16579432","0","1"],["104469.7","0.15180189","0","1"],["104472.4","0","0","0"],["104472.5","0.16131537","0","2"],["104472.9","0.25109507","0","2"],["104473.4","0.43003617","0","2"],["104474.7","0.24853297","0","1"],["104475","0.2465467","0","1"],["104478.7","0.25129274","0","1"],["104605.4","0.03","0","1"]],"bids":[["104456","0.2121675","0","10"],["104447","0","0","0"],["104446.9","0.24346661","0","2"],["104445.3","0.0017149","0","1"],["104445.2","0.19142408","0","2"],["104443.7","0.09283935","0","1"],["104443","0.09394556","0","1"],["104442","0.16474145","0","1"],["104441.7","0.34141777","0","2"],["104440.2","0.16949234","0","1"],["104437.9","0.23909916","0","1"],["104437.5","0.16243888","0","1"],["104437.4","0","0","0"],["104436.7","0.39133821","0","3"],["104435.2","0.27253387","0","1"],["104432","0.29923997","0","3"],["104431.2","0.23606225","0","1"]],"ts":"1747171032401","checksum":1270367674,"seqId":54226742554,"prevSeqId":54226742424}]}
{"arg":{"channel":"books","instId":"BTC-USDT"},"action":"update","data":[{"asks":[["104458.2","0.01","0","2"],["104467.9","0.00478546","0","1"],["104468.4","0","0","0"],["104470.7","0.01","0","2"],["104472.5","0.00001","0","1"],["104483.9","0.41884016","0","1"],["104484.2","0","0","0"],["104514.9","0.06821783","0","1"],["104546.2","0","0","0"]],"bids":[["104456","0.2089675","0","9"],["104453.8","0.005","0","1"],["104447","0.0017149","0","1"],["104446.9","0.45755759","0","1"],["104445.3","0","0","0"],["104442","0.94341021","0","2"],["104441.3","0.005","0","1"],["104437.5","0","0","0"],["104269.2","0","0","0"]],"ts":"1747171032501","checksum":1963628425,"seqId":54226742581,"prevSeqId":54226742554}]}
{"arg":{"channel":"books","instId":"BTC-USDT"},"action":"update","data":[{"asks":[["104467.9","0","0","0"],["104468.5","0.00479546","0","2"],["104478.6","0","0","0"],["104480","0.14098908","0","4"],["104590.1","0","0","0"],["104602.4","0","0","0"],["104605.7","0.0000221","0","1"],["104607.5","0.00001","0","1"],["104608.2","0.01059542","0","1"],["104608.3","0.03","0","1"]],"bids":[["104456","0.2124675","0","11"],["104431.6","0.14678065","0","2"],["104429.5","0","0","0"],["104344.8","0","0","0"],["104334.4","0.77866876","0","1"],["104269.2","0.00026966","0","5"],["104269","0.00005407","0","1"]],"ts":"1747171032601","checksum":1348743671,"seqId":54226742602,"prevSeqId":54226742581}]}
{"arg":{"channel":"books","instId":"BTC-USDT"},"action":"update","data":[{"asks":[["104456.1","0.70684045","0","9"],["104457.9","0.00038538","0","2"],["104472.4","0.15511857","0","1"],["104480","0.00220843","0","3"],["104481","0.13877912","0","1"],["104550.9","0.0013452","0","1"],["104561.3","0.01321954","0","2"],["104607.5","0","0","0"],["104608.2","0","0","0"],["104608.3","0","0","0"]],"bids":[["104456","0.2092675","0","10"],["104437.4","0.16351697","0","1"],["104432.7","0.13877912","0","1"],["104431.6","0.008","0","1"],["104328.4","0.0013452","0","1"],["104318","0.0026904","0","1"],["104269.9","0","0","0"],["104269.6","0","0","0"],["104269.2","0","0","0"],["104269","0","0","0"]],"ts":"1747171032701","checksum":1606262451,"seqId":54226742625,"prevSeqId":54226742602}]}
{"arg":{"channel":"books","instId":"BTC-USDT"},"action":"update","data":[{"asks":[["104463.3","0.09261741","0","1"],["104464","0.18371008","0","2"],["104464.7","0","0","0"],["104465","0.59144422","0","3"],["104465.5","0.08983104","0","1"],["104465.7","0","0","0"],["104466.2","0","0","0"],["104468.4","0.00478546","0","1"],["104468.5","0.15487239","0","2"],["104468.6","0.27953465","0","2"],["104468.8","0.15492425","0","1"],["104469","0.15999598","0","1"],["104469.2","0","0","0"],["104469.5","0","0","0"],["104469.7","0","0","0"],["104471.8","0.15031822","0","1"],["104472.2","0.23450356","0","1"],["104472.4","0","0","0"],["104472.9","0.002","0","1"],["104473.4","0.51930951","0","2"],["104474","0.26363549","0","1"],["104474.3","0.26663633","0","1"],["104474.7","0","0","0"],["104475","0","0","0"],["104478","0.35558564","0","2"],["104478.7","0","0","0"],["104536.5","0","0","0"],["104607.5","0.00001","0","1"],["104608.2","0.01059542","0","1"]],"bids":[["104456","0.0897675","0","9"],["104446.9","0.32510578","0","1"],["104445.2","0","0","0"],["104444.5","0.24452118","0","4"],["104443.7","0","0","0"],["104443","0.08934857","0","1"],["104442.3","0.14412654","0","3"],["104442","0.77866876","0","1"],["104441.7","0.19242972","0","1"],["104441.3","0.15465597","0","2"],["104441","0.1551453","0","1"],["104440.2","0","0","0"],["104439.5","0.15674271","0","1"],["104437.9","0","0","0"],["104437.4","0","0","0"],["104437.2","0.24747106","0","1"],["104436.8","0.65867867","0","5"],["104435.2","0","0","0"],["104434.5","0.26032062","0","2"],["104432","0.052","0","2"],["104431.3","0.27067763","0","1"],["104431.2","0","0","0"],["104430.5","0.24204394","0","1"],["104422.6","0.02871632","0","1"],["104391.3","0","0","0"],["104269.9","0.0000785","0","2"],["104269.6","0.00001237","0","1"],["104269.2","0.00026966","0","5"]],"ts":"1747171032801","checksum":1167157303,"seqId":54226742695,"prevSeqId":54226742625}]}
{"arg":{"channel":"books","instId":"BTC-USDT"},"action":"update","data":[{"asks":[["104480","0.14098891","0","4"],["104481","0","0","0"],["104505.1","0","0","0"],["104505.2","1.41022873","0","2"],["104536.5","2.49941148","0","1"],["104608.3","0.03","0","1"]],"bids":[["104432.7","0","0","0"],["104431.6","0.14678048","0","2"],["104424.5","0.20869903","0","1"],["104423.3","1.61404275","0","2"],["104394.6","0.50585689","0","1"],["104391.9","2.74760033","0","2"],["104269","0.00005407","0","1"]],"ts":"1747171032901","checksum":1167157303,"seqId":54226742709,"prevSeqId":54226742695}]}
{"arg":{"channel":"books","instId":"BTC-USDT"},"action":"update","data":[{"asks":[["104457","0.00617662","0","2"],["104478.8","0.13878142","0","1"],["104480","0.00220843","0","3"],["104608.3","0","0","0"]],"bids":[["104431.6","0.008","0","1"],["104430.6","0.13878142","0","1"],["104424.5","0.68863225","0","2"],["104269","0","0","0"]],"ts":"1747171033001","checksum":1542635264,"seqId":54226742717,"prevSeqId":54226742709}]}
{"arg":{"channel":"books","instId":"BTC-USDT"},"action":"update","data":[{"asks":[["104464.9","0.08914644","0","1"],["104465","0.50528038","0","2"],["104467.6","0.37386724","0","2"],["104468.4","0.14465023","0","1"],["104468.5","0.00001","0","1"],["104471.7","0.16709898","0","1"],["104471.8","0","0","0"],["104497.6","0.00056666","0","1"],["104500.1","0","0","0"],["104545.5","0.01156293","0","2"],["104548","0","0","0"]],"bids":[["104456","0.0855775","0","6"],["104444.5","0.14740826","0","3"],["104444.4","0.10838241","0","2"],["104441.6","0","0","0"],["104441","0","0","0"],["104440.9","0.15513359","0","2"],["104436.8","0.50891753","0","4"],["104436.7","0.54473443","0","4"],["104428.1","0.19242972","0","1"],["104425.6","0.00056666","0","1"],["104380.3","0","0","0"],["104377.7","0.00056666","0","1"]],"ts":"1747171033101","checksum":1259104387,"seqId":54226742744,"prevSeqId":54226742717}]}
{"arg":{"channel":"books","instId":"BTC-USDT"},"action":"update","data":[{"asks":[["104456.1","0.48725009","0","9"],["104463.3","0","0","0"],["104464","0.0932","0","1"],["104464.9","0","0","0"],["104465","0.25845147","0","1"],["104465.5","0","0","0"],["104467.5","0","0","0"],["104467.6","0.36908178","0","1"],["104468.4","0","0","0"],["104468.6","0.25935698","0","2"],["104468.8","0","0","0"],["104469","0.00478546","0","1"],["104471.7","0","0","0"],["104472.2","0","0","0"],["104472.8","0.16910132","0","2"],["104473.4","0.43866251","0","2"],["104474","0","0","0"],["104474.3","0","0","0"],["104478","0.0932","0","1"],["104478.8","0","0","0"],["104480","0.14098895","0","4"],["104509","1","0","1"],["104608.3","0.03","0","1"],["104608.4","0.00041816","0","1"],["104610","0.29261492","0","3"],["104610.9","0.01099559","0","1"],["104611","0.01099627","0","1"],["104611.3","0.00005484","0","1"],["104612.1","0.01059606","0","1"],["104612.2","0.01407867","0","1"],["104612.9","0.00001168","0","1"],["104613","0.000015","0","1"]],"bids":[["104456","0.31964188","0","10"],["104446.9","0.49448978","0","2"],["104444.5","0.052","0","2"],["104444.4","0.01062754","0","1"],["104443","0","0","0"],["104442.3","0.052","0","2"],["104441.3","0.005","0","1"],["104440.9","0.00955938","0","1"],["104439.5","0","0","0"],["104437.8","0.14800989","0","1"],["104437.2","0","0","0"],["104436.9","0.00478546","0","1"],["104436.7","0.49158638","0","3"],["104436","0","0","0"],["104434.5","0.00191","0","1"],["104431.6","0.14678052","0","2"],["104431.3","0","0","0"],["104430.6","0","0","0"],["104430.5","0","0","0"],["104269","0.00005407","0","1"],["104268.9","0.00001021","0","1"],["104268.8","0.31181159","0","3"],["104268.4","0.00039895","0","2"],["104268.3","0.00018565","0","4"]],"ts":"1747171033301","checksum":2057907503,"seqId":54226742914,"prevSeqId":54226742744}]}
{"arg":{"channel":"books","instId":"BTC-USDT"},"action":"update","data":[{"asks":[["104464.3","0.0999985","0","1"],["104465","0.34851583","0","2"],["104466","0.18598327","0","2"],["104466.5","0.09374648","0","1"],["104468.6","0.31630576","0","1"],["104469.5","0.15755026","0","1"],["104469.8","0.16303529","0","1"],["104470","0.24807392","0","4"],["104473.2","0.23649601","0","1"],["104473.4","0.43384023","0","2"],["104475","0.25773292","0","1"],["104475.3","0.25002694","0","1"],["104479","0.70374884","0","4"],["104480","0.14098881","0","4"],["104509","0","0","0"],["104611","0","0","0"],["104611.3","0","0","0"],["104612.1","0","0","0"],["104612.2","0","0","0"],["104612.9","0","0","0"],["104613","0","0","0"]],"bids":[["104446.9","0.48729418","0","2"],["104445.5","0.19135035","0","2"],["104444","0.08741428","0","1"],["104443.3","0.08989814","0","1"],["104442.3","0.2090149","0","3"],["104442","0.92907982","0","2"],["104440.5","0.14901228","0","1"],["104438.2","0.23219934","0","1"],["104436.7","0.43872499","0","3"],["104435.5","0.27032262","0","1"],["104432.3","0.2734121","0","1"],["104431.6","0.14678038","0","2"],["104431.5","0.63413716","0","2"],["104357.6","0","0","0"],["104357.2","0.00010086","0","1"],["104269.6","0","0","0"],["104269.2","0","0","0"],["104269","0","0","0"],["104268.9","0","0","0"],["104268.8","0","0","0"],["104268.4","0","0","0"],["104268.3","0","0","0"]],"ts":"1747171033401","checksum":-515330584,"seqId":54226742966,"prevSeqId":54226742914}]}
{"arg":{"channel":"books","instId":"BTC-USDT"},"action":"update","data":[{"asks":[["104464.3","0","0","0"],["104464.4","0.09391222","0","1"],["104465","0.25845147","0","1"],["104465.1","0.09034982","0","1"],["104466","0.0932","0","1"],["104466.1","0.08587415","0","1"],["104466.5","0","0","0"],["104466.6","0.09638185","0","1"],["104468.6","0.25547071","0","2"],["104469.5","0","0","0"],["104469.6","0.15758844","0","1"],["104469.8","0","0","0"],["104469.9","0.15584146","0","1"],["104470","0.09349006","0","3"],["104470.1","0.20031882","0","2"],["104473.2","0","0","0"],["104473.3","0.24530196","0","1"],["104473.4","0.42658295","0","2"],["104475","0","0","0"],["104475.1","0.24331485","0","1"],["104475.3","0","0","0"],["104475.4","0.24025409","0","1"],["104479","0.44408178","0","3"],["104479.1","0.2392412","0","1"],["104490","0.00229006","0","4"],["104491","0.001","0","1"],["104492","0","0","0"],["104493","0.77866876","0","1"],["104505.1","0.42332158","0","1"],["104511","0.16","0","2"],["104512","0.17999999","0","3"],["104513","0.05","0","1"],["104514","0.07","0","2"],["104515","0.03504786","0","2"],["104607.5","0","0","0"],["104608.2","0","0","0"],["104608.3","0","0","0"],["104608.4","0","0","0"],["104610","0","0","0"],["104610.9","0","0","0"]],"bids":[["104456","0.37166526","0","11"],["104446.9","0.48853217","0","2"],["104445.6","0.18801974","0","3"],["104445.5","0","0","0"],["104444.1","0.09902429","0","1"],["104444","0","0","0"],["104443.4","0.0947444","0","1"],["104443.3","0","0","0"],["104442.4","0.14936924","0","1"],["104442.3","0.052","0","2"],["104442.1","0.22346862","0","2"],["104442","0.77866876","0","1"],["104440.6","0.15632995","0","1"],["104440.5","0","0","0"],["104438.3","0.25196152","0","1"],["104438.2","0","0","0"],["104436.7","0.50548471","0","3"],["104435.6","0.25347485","0","1"],["104435.5","0","0","0"],["104432.4","0.250898","0","1"],["104432.3","0","0","0"],["104431.6","0.40867477","0","3"],["104431.5","0.36869051","0","1"]],"ts":"1747171033501","checksum":-1284401517,"seqId":54226743043,"prevSeqId":54226742966}]}
{"arg":{"channel":"books","instId":"BTC-USDT"},"action":"update","data":[{"asks":[["104463.9","0","0","0"],["104464.4","0.09652063","0","1"],["104464.7","0.00011435","0","1"],["104465","0.3533872","0","2"],["104465.1","0","0","0"],["104466","0.1869648","0","2"],["104466.1","0","0","0"],["104466.5","0.09235094","0","1"],["104466.6","0","0","0"],["104468.5","0.00479546","0","2"],["104468.6","0.33058212","0","2"],["104469","0","0","0"],["104469.5","0.15937273","0","1"],["104469.6","0","0","0"],["104469.9","0.16583835","0","1"],["104470","0.26130276","0","4"],["104470.1","0.0383585","0","1"],["104473.2","0.25273456","0","1"],["104473.3","0","0","0"],["104473.4","0.42864544","0","2"],["104475","0.25179122","0","1"],["104475.1","0","0","0"],["104475.4","0.27297232","0","1"],["104479","0.70704718","0","4"],["104479.1","0","0","0"],["104607.5","0.00001","0","1"],["104608.2","0.01059542","0","1"],["104608.3","0.03","0","1"],["104608.4","0.00041816","0","1"]],"bids":[["104456","0.32269188","0","11"],["104446.9","0.48908318","0","2"],["104445.6","0.00262892","0","1"],["104445.5","0.18516347","0","2"],["104444.1","0","0","0"],["104444","0.0937334","0","1"],["104443.4","0.09336398","0","1"],["104442.4","0.15012578","0","1"],["104442.1","0.071782","0","1"],["104442","0.92593195","0","2"],["104440.6","0","0","0"],["104440.5","0.17007572","0","1"],["104438.3","0","0","0"],["104438.2","0.26112879","0","1"],["104436.9","0","0","0"],["104436.7","0.4294174","0","3"],["104436","0.00478546","0","1"],["104435.6","0","0","0"],["104435.5","0.2596839","0","1"],["104432.4","0.26248082","0","1"],["104431.6","0.14678038","0","2"],["104431.5","0.60799044","0","2"],["104269.9","0","0","0"]],"ts":"1747171033601","checksum":-650933680,"seqId":54226743156,"prevSeqId":54226743043}]}
{"arg":{"channel":"books","instId":"BTC-USDT"},"action":"update","data":[{"asks":[["104456.1","0.47284045","0","8"],["104463.9","0.00011435","0","1"],["104464.7","0","0","0"],["104465","0.61051612","0","3"],["104467.5","0.77866876","0","1"],["104512","0.24999999","0","5"],["104513","0.085","0","2"],["104514","0","0","0"],["104514.9","0","0","0"],["104515","0.00004786","0","1"],["104564.4","0","0","0"],["104566.5","0.00010645","0","1"],["104610","0.29261492","0","3"]],"bids":[["104357.2","0","0","0"],["104355.1","0.00010066","0","1"],["104303.6","0","0","0"],["104302.2","0.00095709","0","1"]],"ts":"1747171033701","checksum":-1158807115,"seqId":54226743177,"prevSeqId":54226743156}]}
{"arg":{"channel":"books","instId":"BTC-USDT"},"action":"update","data":[{"asks":[["104456.2","0.01440964","0","1"],["104465","0.25845147","0","1"],["104465.1","0.09526515","0","1"],["104466","0.0932","0","1"],["104466.1","0.08635453","0","1"],["104466.5","0","0","0"],["104466.6","0.09784998","0","1"],["104467.5","0","0","0"],["104468.6","0.24881709","0","2"],["104469.5","0","0","0"],["104469.6","0.14265788","0","1"],["104470","0.09349006","0","3"],["104470.1","0.18785921","0","2"],["104473.2","0","0","0"],["104473.3","0.2309279","0","1"],["104475","0","0","0"],["104475.1","0.24031206","0","1"],["104479","0.44408178","0","3"],["104479.1","0.23636272","0","1"],["104490","0.00029006","0","2"],["104491","0","0","0"],["104492","0.002","0","2"],["104493","0.77966876","0","2"],["104497.9","0.04657514","0","1"],["104501","0","0","0"],["104511","0","0","0"],["104512","0","0","0"],["104513","0.16","0","2"],["104514","0.24999999","0","5"],["104515","0.08504786","0","3"],["104516.7","0","0","0"],["104528.7","0","0","0"],["104534","0.19242972","0","1"],["104536","0.00001","0","1"],["104537.9","0","0","0"],["104542.9","0","0","0"],["104544.2","0","0","0"],["104566.6","0","0","0"],["104569.1","0","0","0"],["104570.5","0","0","0"],["104610.9","0.01099559","0","1"],["104611","0.01099627","0","1"],["104611.3","0.00005484","0","1"],["104612.1","0.01059606","0","1"],["104612.2","0.01407867","0","1"],["104612.9","0.00001168","0","1"],["104613","0.000015","0","1"]],"bids":[["104456","0.37231526","0","12"],["104445.6","0.19923457","0","3"],["104445.5","0","0","0"],["104444.1","0.0928108","0","1"],["104444","0","0","0"],["104442.1","0.22739427","0","2"],["104442","0.77866876","0","1"],["104440.6","0.14938996","0","1"],["104440.5","0","0","0"],["104438.3","0.25723916","0","1"],["104438.2","0","0","0"],["104435.6","0.24897503","0","1"],["104435.5","0","0","0"],["104431.6","0.41039113","0","3"],["104431.5","0.36869051","0","1"],["104426.2","0.02872024","0","1"],["104415.7","0","0","0"],["104269.9","0.0000785","0","2"]],"ts":"1747171033801","checksum":-1332130459,"seqId":54226743263,"prevSeqId":54226743177}]}
{"arg":{"channel":"books","instId":"BTC-USDT"},"action":"update","data":[{"asks":[["104468.5","0.00001","0","1"],["104470.6","0.00478546","0","1"],["104480","0.00220843","0","3"],["104482.3","0.13877767","0","1"],["104612.9","0","0","0"],["104613","0","0","0"]],"bids":[["104456","0.38831526","0","13"],["104438.4","0.00478546","0","1"],["104436","0","0","0"],["104432.7","0.13877767","0","1"],["104431.6","0.27161075","0","2"],["104269.9","0","0","0"]],"ts":"1747171033901","checksum":-1172221238,"seqId":54226743276,"prevSeqId":54226743263}]}
{"arg":{"channel":"books","instId":"BTC-USDT"},"action":"update","data":[{"asks":[["104456.2","0","0","0"],["104465","0.54358656","0","2"],["104467.5","0.77866876","0","1"],["104470.1","0.14950071","0","1"],["104497.9","0.14230514","0","2"],["104501","0.09573","0","1"],["104516.7","0.06701","0","1"],["104542.9","0.06701","0","1"],["104611.3","0","0","0"],["104612.1","0","0","0"],["104612.2","0","0","0"]],"bids":[["104388.6","0.0958","0","1"],["104270","0","0","0"]],"ts":"1747171034001","checksum":-1449521663,"seqId":54226743287,"prevSeqId":54226743276}]}
{"arg":{"channel":"books","instId":"BTC-USDT"},"action":"update","data":[{"asks":[["104465","0.25845147","0","1"],["104467.5","0","0","0"],["104469.4","0.00478546","0","1"],["104470.6","0","0","0"],["104482.3","0.1387777","0","1"],["104496.7","0.00056666","0","1"],["104497.6","0","0","0"],["104526.2","0.09567","0","1"],["104527.3","0.1435","0","1"],["104544.6","0.00056666","0","1"],["104545.5","0.01099627","0","1"],["104610.9","0","0","0"],["104611","0","0","0"]],"bids":[["104456","0.39099526","0","16"],["104440.9","0","0","0"],["104440.2","0.00955944","0","1"],["104438.4","0","0","0"],["104437.4","0.00478546","0","1"],["104425.6","0","0","0"],["104424.7","0.03655531","0","2"],["104377.7","0","0","0"],["104376.8","0.00056666","0","1"],["104270","0.00038892","0","2"]],"ts":"1747171034101","checksum":-2016309786,"seqId":54226743332,"prevSeqId":54226743287}]}
{"arg":{"channel":"books","instId":"BTC-USDT"},"action":"update","data":[{"asks":[["104464.3","0.27208362","0","1"],["104465","0","0","0"],["104467","0.19242972","0","1"],["104467.6","0","0","0"],["104467.7","0","0","0"],["104469.4","0","0","0"],["104472","0.00478546","0","1"],["104565.2","0.00009265","0","1"],["104566.5","0","0","0"],["104610.9","0.01099559","0","1"]],"bids":[["104456","0.39299526","0","16"],["104454.1","0.06354023","0","2"],["104450.6","0","0","0"],["104444.7","0.36908178","0","1"],["104439.8","0.00478546","0","1"],["104437.4","0","0","0"]],"ts":"1747171034201","checksum":1256837971,"seqId":54226743362,"prevSeqId":54226743332}]}
{"arg":{"channel":"books","instId":"BTC-USDT"},"action":"update","data":[{"asks":[["104456.1","0.46964045","0","7"],["104457.2","0.01259608","0","1"],["104460.1","0.0551453","0","2"],["104467","0","0","0"],["104482.2","0.77866876","0","1"],["104482.5","0","0","0"],["104492","0","0","0"],["104493","0.77866876","0","1"],["104496","0.002","0","2"],["104497","0.001","0","1"],["104513","0","0","0"],["104514","0","0","0"],["104515","0.00004786","0","1"],["104517","0.15999999","0","2"],["104518","0.07999999","0","1"],["104519","0.17","0","4"],["104520","0.08830992","0","6"],["104610","0","0","0"],["104610.9","0","0","0"]],"bids":[["104456","0.62699526","0","17"]],"ts":"1747171034301","checksum":62666412,"seqId":54226743450,"prevSeqId":54226743362}]}
{"arg":{"channel":"books","instId":"BTC-USDT"},"action":"update","data":[{"asks":[["104460.1","0.036","0","1"],["104466.8","0.01914419","0","1"],["104467.3","0.19242972","0","1"],["104469.1","0","0","0"],["104470.6","0.00478546","0","1"],["104472","0","0","0"],["104475.6","0.03828839","0","1"],["104482.3","0","0","0"],["104483","0.13877535","0","1"],["104495","0.002","0","2"],["104496","0.001","0","1"],["104497","0","0","0"],["104521.1","0.09567","0","1"],["104524.8","0.11481","0","1"],["104532.5","0.69133","0","2"],["104607.5","0","0","0"],["104608.2","0","0","0"],["104608.3","0","0","0"],["104608.4","0","0","0"]],"bids":[["104456","0.39299526","0","16"],["104452.4","0.08665235","0","2"],["104452.3","0.07298372","0","1"],["104451.3","0","0","0"],["104439.8","0","0","0"],["104438.4","0.00478546","0","1"],["104432.8","0.13877558","0","1"],["104432.7","0","0","0"],["104388.6","0","0","0"],["104269.9","0.0000785","0","2"]],"ts":"1747171034401","checksum":-7887261,"seqId":54226743484,"prevSeqId":54226743450}]}
{"arg":{"channel":"books","instId":"BTC-USDT"},"action":"update","data":[{"asks":[["104470.3","0.0383585","0","1"],["104481","0.13877816","0","1"],["104483","0","0","0"],["104492","0.002","0","2"],["104493","0.77966876","0","2"],["104495","0","0","0"],["104496","0","0","0"],["104513","0.16","0","2"],["104514","0.07999999","0","1"],["104517","0","0","0"],["104518","0","0","0"]],"bids":[["104456","0.39309526","0","17"],["104444.7","0","0","0"],["104432.8","0","0","0"],["104432.7","0.13877816","0","1"],["104269.6","0.00001237","0","1"]],"ts":"1747171034501","checksum":-920740328,"seqId":54226743507,"prevSeqId":54226743484}]}
{"arg":{"channel":"books","instId":"BTC-USDT"},"action":"update","data":[{"asks":[["104481","0","0","0"],["104482.1","0.13877698","0","1"],["104518.7","0.09709044","0","1"],["104605.7","0","0","0"]],"bids":[["104456","0.39310526","0","18"],["104394.6","1.19670488","0","2"]],"ts":"1747171034601","checksum":-428702431,"seqId":54226743516,"prevSeqId":54226743507}]}
{"arg":{"channel":"books","instId":"BTC-USDT"},"action":"update","data":[{"asks":[["104470.3","0","0","0"],["104514","0.17999999","0","3"],["104515","0.05004786","0","2"],["104518.7","0","0","0"],["104519","0.07","0","2"],["104520","0.03830992","0","5"],["104605.7","0.0000221","0","1"],["104607.5","0.00001","0","1"]],"bids":[["104456","0.39370526","0","24"]],"ts":"1747171034701","checksum":1388601708,"seqId":54226743530,"prevSeqId":54226743516}]}
{"arg":{"channel":"books","instId":"BTC-USDT"},"action":"update","data":[{"asks":[["104457.2","0","0","0"],["104457.6","0.01259609","0","1"]],"bids":[["104456","0.34408188","0","23"]],"ts":"1747171034801","checksum":-922012537,"seqId":54226743575,"prevSeqId":54226743530}]}
{"arg":{"channel":"books","instId":"BTC-USDT"},"action":"update","data":[{"asks":[["104463.9","0.36919613","0","2"],["104468.5","0.77867876","0","2"],["104471.4","0.0383585","0","1"],["104607.5","0","0","0"]],"bids":[["104456","0.2578175","0","14"],["104454.1","0.02405832","0","1"],["104452.9","0","0","0"],["104452.4","0.03143834","0","1"],["104442.1","0.41982399","0","3"],["104442","0","0","0"],["104441.7","0","0","0"],["104423.3","0.17829353","0","1"],["104391.9","0.234","0","1"],["104269.2","0.00026966","0","5"],["104269","0.00005407","0","1"],["104268.9","0.00001021","0","1"]],"ts":"1747171034901","checksum":-1371544118,"seqId":54226743605,"prevSeqId":54226743575}]}
{"arg":{"channel":"books","instId":"BTC-USDT"},"action":"update","data":[{"asks":[["104463.7","0.00011435","0","1"],["104463.8","0.30371432","0","1"],["104463.9","0.36908178","0","1"],["104464.3","0","0","0"],["104464.4","0.10203526","0","1"],["104465.1","0.10035894","0","1"],["104466.1","0.09401188","0","1"],["104466.6","0.09650114","0","1"],["104467.6","0.0383585","0","1"],["104467.9","0.00478546","0","1"],["104468.4","0.43584318","0","2"],["104468.6","0","0","0"],["104469.6","0.14528761","0","1"],["104469.9","0.15713006","0","1"],["104470.1","0.15837959","0","1"],["104470.6","0","0","0"],["104471.4","0","0","0"],["104472.8","0.15955962","0","2"],["104473.3","0.2431563","0","1"],["104475.1","0.24397377","0","1"],["104475.4","0.26428466","0","1"],["104478.8","0.13878152","0","1"],["104479.1","0.24560553","0","1"],["104482.1","0","0","0"],["104490","0.00229006","0","4"],["104491","0.001","0","1"],["104492","0","0","0"],["104493","0.77866876","0","1"],["104511","0.16","0","2"],["104512","0.07999999","0","1"],["104513","0","0","0"],["104514","0.1","0","2"],["104605.4","0","0","0"],["104605.7","0","0","0"]],"bids":[["104456","0.3914175","0","16"],["104452.3","0","0","0"],["104450","0.03337194","0","3"],["104446.9","0.28855624","0","2"],["104445.6","0.18749943","0","3"],["104444.1","0.09881898","0","1"],["104443.4","0.09871416","0","1"],["104442.4","0.15596054","0","1"],["104442.1","0.22838192","0","2"],["104441.9","0.50304735","0","2"],["104440.6","0.16111592","0","1"],["104438.6","0.19242972","0","1"],["104438.4","0","0","0"],["104438.3","0.26001267","0","1"],["104437.8","0.16240971","0","1"],["104436.7","0.46144622","0","3"],["104436","0.00478546","0","1"],["104435.6","0.24843911","0","1"],["104432.7","0","0","0"],["104432.4","0.24747258","0","1"],["104431.6","0.26555551","0","2"],["104429.5","0.13878152","0","1"],["104424.5","0.20869903","0","1"],["104394.6","0.50585689","0","1"]],"ts":"1747171035001","checksum":1062703118,"seqId":54226743728,"prevSeqId":54226743605}]}
{"arg":{"channel":"books","instId":"BTC-USDT"},"action":"update","data":[{"asks":[["104467.9","0","0","0"],["104468.3","0.00478546","0","1"],["104478.8","0","0","0"],["104480","0.14098881","0","4"],["104496.7","0","0","0"],["104497.4","0.00056666","0","1"],["104512","0.17999999","0","3"],["104513","0.05","0","1"],["104514","0","0","0"],["104515","0.00004786","0","1"],["104544.6","0","0","0"],["104545.3","0.00056666","0","1"],["104605.4","0.03","0","1"]],"bids":[["104456","0.2474175","0","12"],["104454.1","0.06296418","0","2"],["104441.9","0.71585761","0","1"],["104440.2","0","0","0"],["104439.5","0.00955951","0","1"],["104438.7","0.77866876","0","1"],["104431.7","0.13878047","0","1"],["104429.5","0","0","0"],["104425.4","0.00056666","0","1"],["104424.7","0.03598865","0","1"],["104424.5","0.6733341","0","2"],["104423.4","1.42074403","0","2"],["104392","2.49031202","0","2"],["104377.5","0.00056666","0","1"],["104376.8","0","0","0"],["104269","0","0","0"],["104268.9","0","0","0"]],"ts":"1747171035101","checksum":-438213887,"seqId":54226743783,"prevSeqId":54226743728}]}
{"arg":{"channel":"books","instId":"BTC-USDT"},"action":"update","data":[{"asks":[["104464.1","0.09034179","0","1"],["104464.4","0","0","0"],["104464.8","0.12894843","0","3"],["104465.1","0","0","0"],["104465.8","0.09556312","0","1"],["104466.1","0","0","0"],["104466.3","0.12163981","0","2"],["104466.6","0","0","0"],["104468.4","0.44602053","0","2"],["104469.3","0.14847698","0","1"],["104469.6","0.1673922","0","1"],["104469.8","0.16985986","0","1"],["104469.9","0","0","0"],["104470.1","0","0","0"],["104472.6","0.16010975","0","1"],["104472.8","0.0084426","0","1"],["104473","0.22973373","0","1"],["104473.3","0","0","0"],["104474.8","0.26764999","0","1"],["104475.1","0.24444828","0","1"],["104475.4","0","0","0"],["104478.8","0.26558199","0","1"],["104479.1","0","0","0"],["104490","0.00029006","0","2"],["104491","0","0","0"],["104492","0.002","0","2"],["104493","0.77966876","0","2"],["104511","0","0","0"],["104512","0","0","0"],["104513","0.16","0","2"],["104514","0.17999999","0","3"],["104515","0.05004786","0","2"],["104565.2","0","0","0"],["104605.7","0.0000221","0","1"],["104607.5","0.00001","0","1"],["104608.2","0.01059542","0","1"]],"bids":[["104454","0.1315585","0","2"],["104446.9","0.24438963","0","2"],["104445.6","0.00262892","0","1"],["104445.3","0.19672695","0","2"],["104444.1","0","0","0"],["104443.8","0.09530989","0","1"],["104443.4","0","0","0"],["104443.1","0.09279518","0","1"],["104442.4","0","0","0"],["104442.1","0.23469205","0","2"],["104441.8","0.1956793","0","2"],["104440.6","0","0","0"],["104440.3","0.168745","0","2"],["104438.3","0","0","0"],["104438","0.23743355","0","1"],["104437.8","0","0","0"],["104437.6","0.16737104","0","1"],["104436.7","0.43956666","0","3"],["104435.6","0","0","0"],["104435.3","0.2724406","0","1"],["104432.4","0","0","0"],["104432.2","0.13877972","0","1"],["104432.1","0.26931427","0","1"],["104431.7","0","0","0"],["104431.6","0.008","0","1"],["104431.3","0.26546383","0","1"],["104356.6","0.00009857","0","1"],["104355.1","0","0","0"],["104303.6","0.00095708","0","1"],["104302.2","0","0","0"]],"ts":"1747171035201","checksum":-1260804862,"seqId":54226743880,"prevSeqId":54226743783}]}
{"arg":{"channel":"books","instId":"BTC-USDT"},"action":"update","data":[{"asks":[["104457.6","0","0","0"],["104480","0.14098798","0","4"],["104490","0.00229006","0","4"],["104491","0.001","0","1"],["104492","0","0","0"],["104493","0.77866876","0","1"],["104511","0.16","0","2"],["104512","0.07999999","0","1"],["104513","0","0","0"],["104514","0.1","0","2"]],"bids":[["104432.7","0.13877955","0","1"],["104432.2","0","0","0"]],"ts":"1747171035301","checksum":-1978058879,"seqId":54226743901,"prevSeqId":54226743880}]}
{"arg":{"channel":"books","instId":"BTC-USDT"},"action":"update","data":[{"asks":[["104490","0.00029006","0","2"],["104491","0","0","0"],["104492","0.002","0","2"],["104493","0.77966876","0","2"],["104509","1","0","1"],["104511","0","0","0"],["104512","0","0","0"],["104513","0.16","0","2"],["104514","0.17999999","0","3"]],"bids":[],"ts":"1747171035401","checksum":-1978058879,"seqId":54226743930,"prevSeqId":54226743901}]}
{"arg":{"channel":"books","instId":"BTC-USDT"},"action":"update","data":[{"asks":[["104464.1","0","0","0"],["104464.4","0.09116309","0","1"],["104464.8","0.03852198","0","2"],["104465.1","0.09053926","0","1"],["104465.8","0","0","0"],["104466.1","0.08850339","0","1"],["104466.3","0.02822972","0","1"],["104466.6","0.08809609","0","1"],["104468.3","0","0","0"],["104468.4","0.44950765","0","2"],["104469.3","0","0","0"],["104469.6","0.16256126","0","1"],["104469.8","0","0","0"],["104469.9","0.16767069","0","1"],["104470.1","0.16742293","0","1"],["104470.6","0.00478546","0","1"],["104472.6","0","0","0"],["104472.8","0.16346479","0","2"],["104473","0","0","0"],["104473.3","0.25079825","0","1"],["104474.8","0","0","0"],["104475.1","0.26610176","0","1"],["104475.4","0.26575087","0","1"],["104478.8","0","0","0"],["104479.1","0.26672389","0","1"],["104480","0.00220843","0","3"],["104482.1","0.13877671","0","1"],["104607.5","0","0","0"],["104608.2","0","0","0"]],"bids":[["104456","0.43558188","0","13"],["104447","0","0","0"],["104446.9","0.28705546","0","2"],["104445.7","0.0017149","0","1"],["104445.6","0.18587982","0","3"],["104445.3","0","0","0"],["104444.1","0.09123372","0","1"],["104443.8","0","0","0"],["104443.4","0.09576478","0","1"],["104443.1","0","0","0"],["104442.4","0.16173731","0","1"],["104442.1","0.2297568","0","2"],["104441.8","0.03928085","0","1"],["104440.6","0.14912925","0","1"],["104440.3","0.00005","0","1"],["104438.3","0.25076622","0","1"],["104438","0","0","0"],["104437.8","0.15344167","0","1"],["104437.6","0","0","0"],["104437.4","0.00478546","0","1"],["104436.7","0.49975587","0","3"],["104436","0","0","0"],["104435.6","0.24097837","0","1"],["104435.3","0","0","0"],["104432.4","0.23914808","0","1"],["104432.1","0","0","0"],["104431.6","0.27504549","0","2"],["104431.3","0","0","0"]],"ts":"1747171035501","checksum":2138501249,"seqId":54226743998,"prevSeqId":54226743930}]}
{"arg":{"channel":"books","instId":"BTC-USDT"},"action":"update","data":[{"asks":[["104467.6","0","0","0"],["104505.1","0","0","0"],["104505.2","0.0287183","0","1"],["104509","0","0","0"],["104516.6","0.07420047","0","1"],["104536.5","0","0","0"],["104607.5","0.00001","0","1"],["104608.2","0.01059542","0","1"],["104608.3","0.03","0","1"]],"bids":[["104456","0.45157188","0","13"],["104454","0.0932","0","1"],["104452.4","0.08665235","0","2"],["104452.3","0.07298372","0","1"],["104450","0.00029006","0","2"],["104447","0.0017149","0","1"],["104445.7","0","0","0"],["104424.5","0.20869903","0","1"],["104423.4","0.03598865","0","1"],["104392","0.00002963","0","1"],["104269.2","0","0","0"]],"ts":"1747171035601","checksum":1488876516,"seqId":54226744021,"prevSeqId":54226743998}]}
{"arg":{"channel":"books","instId":"BTC-USDT"},"action":"update","data":[{"asks":[["104460.1","0.04465076","0","2"],["104468.4","0.30145879","0","1"],["104468.5","0.00001","0","1"],["104505.1","1.42424503","0","1"],["104536.5","2.58840288","0","1"],["104541.7","6.09424704","0","1"],["104546.2","0.04204765","0","1"],["104607.5","0","0","0"],["104608.2","0","0","0"],["104608.3","0","0","0"]],"bids":[["104423.2","1.43581879","0","1"],["104391.9","2.87072394","0","2"],["104269.6","0","0","0"]],"ts":"1747171035701","checksum":1496562973,"seqId":54226744035,"prevSeqId":54226744021}]}
{"arg":{"channel":"books","instId":"BTC-USDT"},"action":"update","data":[{"asks":[["104469.7","0.0383585","0","1"],["104605.7","0","0","0"]],"bids":[["104455.2","0.0383585","0","1"],["104269.9","0","0","0"]],"ts":"1747171035801","checksum":-1815824345,"seqId":54226744074,"prevSeqId":54226744035}]}
{"arg":{"channel":"books","instId":"BTC-USDT"},"action":"update","data":[{"asks":[],"bids":[["104456","0.45158188","0","14"]],"ts":"1747171036001","checksum":-1996084336,"seqId":54226744075,"prevSeqId":54226744074}]}
{"arg":{"channel":"books","instId":"BTC-USDT"},"action":"update","data":[{"asks":[["104456.1","0.48223654","0","8"],["104467.2","0.00478546","0","1"],["104470.6","0","0","0"],["104480","0.14098842","0","4"],["104482.1","0","0","0"],["104497.4","0","0","0"],["104497.7","0.00056666","0","1"],["104514","0.24999999","0","5"],["104515","0.08504786","0","3"],["104516.6","0","0","0"],["104519","0","0","0"],["104520","0.00330992","0","4"],["104545.3","0","0","0"],["104545.5","0.01156293","0","2"],["104605.7","0.0000221","0","1"],["104607.5","0.00001","0","1"],["104608.2","0.01059542","0","1"],["104608.3","0.03","0","1"]],"bids":[["104439.5","0","0","0"],["104438.8","0.00955957","0","1"],["104437.4","0","0","0"],["104435.8","0.00478546","0","1"],["104432.7","0","0","0"],["104432.1","0.13877999","0","1"],["104425.7","0.00056666","0","1"],["104425.4","0","0","0"],["104377.8","0.01013777","0","2"],["104377.5","0","0","0"],["104269.9","0.0000785","0","2"]],"ts":"1747171036101","checksum":-952659201,"seqId":54226744138,"prevSeqId":54226744075}]}
{"arg":{"channel":"books","instId":"BTC-USDT"},"action":"update","data":[{"asks":[["104467.2","0","0","0"],["104468.3","0.00478546","0","1"]],"bids":[["104436","0.00478546","0","1"],["104435.8","0","0","0"],["104357.1","0.01748015","0","2"],["104356.6","0","0","0"],["104269.6","0.00001237","0","1"]],"ts":"1747171036201","checksum":-952659201,"seqId":54226744196,"prevSeqId":54226744138}]}
{"arg":{"channel":"books","instId":"BTC-USDT"},"action":"update","data":[{"asks":[["104456.1","0.46964045","0","7"],["104456.2","0.01259609","0","1"],["104468.3","0","0","0"],["104469.5","0.00478546","0","1"],["104479","0.58286231","0","4"],["104480","0.00220843","0","3"],["104608.3","0","0","0"]],"bids":[["104436.9","0.00478546","0","1"],["104436","0","0","0"],["104432.1","0","0","0"],["104431.7","0.13878053","0","1"]],"ts":"1747171036301","checksum":881672924,"seqId":54226744219,"prevSeqId":54226744196}]}
{"arg":{"channel":"books","instId":"BTC-USDT"},"action":"update","data":[{"asks":[["104468.4","0.45957956","0","2"],["104469.4","0.00478546","0","1"],["104469.5","0.77866876","0","1"],["104479","0.44408178","0","3"],["104480","0.1409889","0","4"],["104608.2","0","0","0"]],"bids":[["104455.2","0","0","0"],["104431.7","0.13878047","0","1"],["104269.2","0.00026966","0","5"]],"ts":"1747171036401","checksum":-1824871950,"seqId":54226744283,"prevSeqId":54226744219}]}
{"arg":{"channel":"books","instId":"BTC-USDT"},"action":"update","data":[{"asks":[],"bids":[["104455.2","0.0383585","0","1"],["104269.2","0","0","0"]],"ts":"1747171036501","checksum":881672924,"seqId":54226744284,"prevSeqId":54226744283}]}
{"arg":{"channel":"books","instId":"BTC-USDT"},"action":"update","data":[{"asks":[["104467.9","0.00478546","0","1"],["104469.4","0","0","0"],["104478.8","0.13878084","0","1"],["104480","0.00220843","0","3"],["104504","1.07299898","0","3"],["104505","0.43614196","0","1"],["104605.7","0","0","0"],["104607.5","0","0","0"]],"bids":[["104456","0.39638188","0","11"],["104436.9","0","0","0"],["104436","0.00478546","0","1"],["104431.7","0.13878077","0","1"],["104424.5","0.68865312","0","2"],["104394.6","1.23364196","0","2"]],"ts":"1747171036601","checksum":-1651419077,"seqId":54226744312,"prevSeqId":54226744284}]}
{"arg":{"channel":"books","instId":"BTC-USDT"},"action":"update","data":[{"asks":[["104462.6","0.02743941","0","1"],["104463.5","0.00011435","0","1"],["104463.6","0.0942271","0","1"],["104463.7","0","0","0"],["104464.2","0.08910701","0","1"],["104464.4","0","0","0"],["104465.1","0","0","0"],["104465.2","0.09130724","0","1"],["104465.7","0.09098381","0","1"],["104466.1","0","0","0"],["104466.6","0","0","0"],["104468.4","0.52169516","0","2"],["104468.7","0.14383196","0","1"],["104469.1","0.15661122","0","1"],["104469.2","0.16277754","0","1"],["104469.6","0","0","0"],["104469.9","0","0","0"],["104470.1","0","0","0"],["104472","0.16300208","0","1"],["104472.4","0.25054881","0","1"],["104472.8","0.0084426","0","1"],["104473.3","0","0","0"],["104474.2","0.25686504","0","1"],["104474.6","0.25438596","0","1"],["104475.1","0","0","0"],["104475.4","0","0","0"],["104475.8","0","0","0"],["104478.2","0.42717282","0","2"],["104478.8","0.13878105","0","1"],["104479.1","0","0","0"],["104490","0.00229006","0","4"],["104491","0.001","0","1"],["104492","0","0","0"],["104493","0.77866876","0","1"],["104511","0.16","0","2"],["104512","0.17999999","0","3"],["104513","0.05","0","1"],["104514","0.07","0","2"],["104515","0.03504786","0","2"],["104605.3","0","0","0"],["104605.4","0","0","0"]],"bids":[["104456","0.0887175","0","9"],["104454.1","0.03890586","0","1"],["104450.1","0.02302519","0","1"],["104447","0","0","0"],["104446.9","0.19244414","0","2"],["104445.6","0.00262892","0","1"],["104445","0.0017149","0","1"],["104444.7","0.19075791","0","2"],["104444.1","0","0","0"],["104443.4","0","0","0"],["104443.2","0.08993308","0","2"],["104442.6","0.09418453","0","1"],["104442.4","0","0","0"],["104442.1","0.071782","0","1"],["104441.6","0.16065015","0","1"],["104441.2","0.32681418","0","2"],["104440.6","0","0","0"],["104439.7","0.16081838","0","2"],["104438.3","0","0","0"],["104437.8","0","0","0"],["104437.4","0.24812507","0","1"],["104437","0.1523271","0","1"],["104436.7","0.38679174","0","3"],["104436","0","0","0"],["104435.8","0.00478546","0","1"],["104435.6","0","0","0"],["104434.7","0.24509772","0","1"],["104432.4","0","0","0"],["104431.7","0","0","0"],["104431.6","0.25120426","0","2"],["104430.7","0.24791052","0","1"],["104429.5","0.13878105","0","1"],["104394.1","0","0","0"],["104269.2","0.00026966","0","5"]],"ts":"1747171036701","checksum":-1606084320,"seqId":54226744445,"prevSeqId":54226744312}]}
{"arg":{"channel":"books","instId":"BTC-USDT"},"action":"update","data":[{"asks":[["104478.8","0","0","0"],["104480","0.140989","0","4"],["104490","0.00029006","0","2"],["104491","0","0","0"],["104492","0.002","0","2"],["104493","0.77966876","0","2"],["104504","0.07299898","0","2"],["104511","0","0","0"],["104512","0","0","0"],["104513","0.16","0","2"],["104514","0.24999999","0","5"],["104515","0.08504786","0","3"],["104605.3","0.01059549","0","1"],["104605.4","0.03","0","1"],["104605.7","0.0000221","0","1"]],"bids":[["104431.7","0.13878057","0","1"],["104429.5","0","0","0"],["104388.3","0.0095263","0","1"],["104387.2","0","0","0"],["104385.9","0","0","0"],["104378.2","0.00745107","0","1"],["104375.5","0.00014277","0","1"],["104269.2","0","0","0"]],"ts":"1747171036801","checksum":-1606084320,"seqId":54226744484,"prevSeqId":54226744445}]}
{"arg":{"channel":"books","instId":"BTC-USDT"},"action":"update","data":[{"asks":[["104467.2","0.00478546","0","1"],["104467.9","0","0","0"]],"bids":[["104435.8","0","0","0"],["104434.8","0.00478546","0","1"]],"ts":"1747171036901","checksum":-1606084320,"seqId":54226744490,"prevSeqId":54226744484}]}
{"arg":{"channel":"books","instId":"BTC-USDT"},"action":"update","data":[{"asks":[["104472.4","0","0","0"],["104472.5","0.24500093","0","2"],["104607.5","0.00001","0","1"]],"bids":[["104456","0.08886729","0","9"],["104452.4","0.05521401","0","1"],["104437.5","0.24613873","0","1"],["104437.4","0","0","0"]],"ts":"1747171037001","checksum":-274631479,"seqId":54226744501,"prevSeqId":54226744490}]}
{"arg":{"channel":"books","instId":"BTC-USDT"},"action":"update","data":[{"asks":[["104463.6","0","0","0"],["104467.2","0","0","0"],["104469","0.00478546","0","1"],["104469.1","0","0","0"],["104472.4","0.23182668","0","1"],["104472.5","0.00001","0","1"],["104472.9","0","0","0"],["104474.6","0","0","0"],["104485.4","0","0","0"],["104496","0.00056666","0","1"],["104497.7","0","0","0"],["104541.4","0.36975844","0","4"],["104545.5","0.01099627","0","1"],["104608.2","0.01059542","0","1"],["104608.3","0.03","0","1"],["104608.4","0.00041816","0","1"],["104610","0.29261492","0","3"]],"bids":[["104456","0.09206729","0","10"],["104455.7","0","0","0"],["104447","0.0017149","0","1"],["104443.2","0.08793308","0","1"],["104442.6","0","0","0"],["104441.6","0","0","0"],["104438.8","0","0","0"],["104438.1","0.00955964","0","1"],["104437.5","0","0","0"],["104437.4","0.24885573","0","2"],["104434.8","0","0","0"],["104431.6","0.008","0","1"],["104427.7","0.00056666","0","1"],["104425.7","0","0","0"],["104382.3","0.00056666","0","1"],["104377.8","0.00957111","0","1"],["104269.2","0.00026966","0","5"],["104269","0.00005407","0","1"]],"ts":"1747171037101","checksum":-1879935015,"seqId":54226744536,"prevSeqId":54226744501}]}
{"arg":{"channel":"books","instId":"BTC-USDT"},"action":"update","data":[{"asks":[["104463.6","0.09171137","0","1"],["104469.1","0.16666515","0","1"],["104472.4","0.2482","0","1"],["104474.6","0.27118014","0","1"],["104608.3","0","0","0"],["104608.4","0","0","0"],["104610","0","0","0"]],"bids":[["104456","0.08886729","0","9"],["104452.5","0.03021565","0","1"],["104447","0","0","0"],["104442.6","0.09982142","0","1"],["104441.6","0.15891478","0","1"],["104437.4","0.23895232","0","2"],["104431.6","0.27070731","0","2"],["104269.2","0","0","0"],["104269","0","0","0"]],"ts":"1747171037201","checksum":-1067065988,"seqId":54226744566,"prevSeqId":54226744536}]}
{"arg":{"channel":"books","instId":"BTC-USDT"},"action":"update","data":[{"asks":[["104462.6","0","0","0"],["104469","0","0","0"],["104469.9","0.00478546","0","1"],["104472.1","0","0","0"],["104472.9","0.002","0","1"],["104485.4","0.002","0","1"]],"bids":[["104456","0.09206729","0","10"],["104453.7","0.002","0","1"],["104447","0.0017149","0","1"],["104445","0","0","0"],["104441.2","0.32881418","0","3"],["104438.2","0.00478546","0","1"],["104437.4","0.23416686","0","1"],["104269.9","0","0","0"],["104269.6","0","0","0"]],"ts":"1747171037301","checksum":1616608745,"seqId":54226744581,"prevSeqId":54226744566}]}
{"arg":{"channel":"books","instId":"BTC-USDT"},"action":"update","data":[{"asks":[["104462.8","0.02743935","0","1"],["104472.4","0","0","0"],["104472.5","0.23132805","0","2"],["104474.9","0.04462016","0","1"],["104608.2","0","0","0"]],"bids":[["104437.5","0.24995219","0","1"],["104437.4","0","0","0"]],"ts":"1747171037401","checksum":1311791773,"seqId":54226744587,"prevSeqId":54226744581}]}
{"arg":{"channel":"books","instId":"BTC-USDT"},"action":"update","data":[{"asks":[["104463.4","0.0940606","0","1"],["104463.5","0","0","0"],["104463.6","0","0","0"],["104463.7","0.00011435","0","1"],["104464","0.18840087","0","2"],["104464.2","0","0","0"],["104465","0.09193825","0","1"],["104465.2","0","0","0"],["104465.6","0.09339836","0","1"],["104465.7","0","0","0"],["104468.4","0.30145879","0","1"],["104468.5","0.15468515","0","2"],["104468.7","0","0","0"],["104468.9","0.1556401","0","1"],["104469","0.15290673","0","1"],["104469.1","0","0","0"],["104469.2","0","0","0"],["104471.8","0.15874723","0","1"],["104472","0","0","0"],["104472.3","0.25573687","0","1"],["104472.5","0.00001","0","1"],["104474","0.26734635","0","1"],["104474.2","0","0","0"],["104474.4","0.257826","0","1"],["104474.6","0","0","0"],["104478.1","0.2477666","0","1"],["104478.2","0.19242972","0","1"],["104538.5","6.08265491","0","2"],["104541.7","0","0","0"],["104608.2","0.01059542","0","1"]],"bids":[["104456","0.08887729","0","10"],["104455.2","0","0","0"],["104447","0","0","0"],["104446.9","0.09150515","0","1"],["104445","0.0017149","0","1"],["104444.7","0","0","0"],["104444.5","0.23116189","0","4"],["104443.2","0","0","0"],["104443.1","0.09836793","0","1"],["104442.6","0","0","0"],["104442.4","0.09416502","0","1"],["104441.6","0","0","0"],["104441.4","0.18701627","0","2"],["104441.2","0.18029353","0","2"],["104441","0.15486769","0","1"],["104439.7","0.00097","0","1"],["104439.5","0.16568674","0","1"],["104437.5","0","0","0"],["104437.3","0.26718333","0","2"],["104437","0","0","0"],["104436.8","0.66931877","0","5"],["104434.7","0","0","0"],["104434.5","0.24298133","0","2"],["104431.6","0.008","0","1"],["104431.4","0.25695541","0","1"],["104430.7","0","0","0"],["104430.6","0.24803255","0","1"],["104269.9","0.0000785","0","2"],["104269.6","0.00001237","0","1"],["104269.2","0.00026966","0","5"]],"ts":"1747171037501","checksum":-1489693236,"seqId":54226744650,"prevSeqId":54226744587}]}
{"arg":{"channel":"books","instId":"BTC-USDT"},"action":"update","data":[{"asks":[["104456.1","0.80239045","0","9"],["104457.9","0.10889541","0","3"],["104462.9","0.00011435","0","1"],["104463.2","0.09817891","0","1"],["104463.4","0","0","0"],["104463.7","0","0","0"],["104463.9","0.46303254","0","2"],["104464","0.0932","0","1"],["104464.9","0.09297571","0","1"],["104465","0","0","0"],["104465.4","0.10877914","0","2"],["104465.6","0","0","0"],["104468.4","0.63433871","0","3"],["104468.5","0.00001","0","1"],["104468.7","0.16683895","0","1"],["104468.8","0.00478546","0","1"],["104468.9","0.15766603","0","1"],["104469","0","0","0"],["104469.9","0","0","0"],["104471.6","0.1592772","0","1"],["104471.8","0","0","0"],["104472.1","0.23482621","0","1"],["104472.3","0","0","0"],["104473.9","0.24072668","0","1"],["104474","0","0","0"],["104474.2","0.23891955","0","1"],["104474.4","0","0","0"],["104477.9","0.39868773","0","2"],["104478.1","0","0","0"],["104480","0.00220843","0","3"],["104538.5","0.00003395","0","1"],["104541.7","6.08262096","0","1"]],"bids":[["104452.4","0.04022645","0","1"],["104452.3","0","0","0"],["104446.9","0.19531965","0","2"],["104445","0","0","0"],["104444.9","0.0026849","0","2"],["104444.5","0.052","0","2"],["104444.4","0.20152564","0","3"],["104443.1","0","0","0"],["104442.9","0.09508287","0","1"],["104442.4","0","0","0"],["104442.2","0.09847958","0","1"],["104441.9","0.53899798","0","2"],["104441.4","0.028575","0","1"],["104441.2","0.33074378","0","3"],["104441","0","0","0"],["104440.9","0.14250449","0","1"],["104439.5","0","0","0"],["104439.4","0.16437942","0","1"],["104438.7","0","0","0"],["104438.2","0","0","0"],["104437.3","0.03","0","1"],["104437.1","0.2539988","0","1"],["104436.9","0.00478546","0","1"],["104436.8","0.50891753","0","4"],["104436.7","0.36201679","0","3"],["104436.6","0.25970541","0","4"],["104434.5","0.00191","0","1"],["104434.4","0.26313083","0","2"],["104431.7","0","0","0"],["104431.5","0.53424997","0","2"],["104431.4","0","0","0"],["104431.2","0.24460778","0","1"],["104430.6","0","0","0"],["104430.4","0.2411702","0","1"],["104429.5","0.13878241","0","1"],["104399","0","0","0"],["104357.4","0.002871","0","1"],["104269","0.00005407","0","1"],["104268.9","0.00001021","0","1"]],"ts":"1747171037601","checksum":-1232475558,"seqId":54226744788,"prevSeqId":54226744650}]}
{"arg":{"channel":"books","instId":"BTC-USDT"},"action":"update","data":[{"asks":[["104456.1","0.56839045","0","8"],["104457.9","0.00038538","0","2"],["104462.8","0","0","0"],["104462.9","0","0","0"],["104463.2","0","0","0"],["104463.4","0.00011435","0","1"],["104463.5","0.09900005","0","1"],["104463.9","0.36908178","0","1"],["104464.1","0.09867166","0","1"],["104464.9","0","0","0"],["104465.1","0.09397407","0","1"],["104465.4","0.01441826","0","1"],["104465.6","0.09556701","0","1"],["104468.4","0.52036129","0","2"],["104468.6","0.16238528","0","1"],["104468.7","0","0","0"],["104468.8","0","0","0"],["104468.9","0","0","0"],["104469","0.15295833","0","1"],["104469.1","0.16667035","0","1"],["104469.7","0.07905013","0","2"],["104469.9","0.00478546","0","1"],["104471.6","0","0","0"],["104471.9","0.15062631","0","1"],["104472.1","0","0","0"],["104472.4","0.24856177","0","1"],["104473.9","0","0","0"],["104474.1","0.23836851","0","1"],["104474.2","0","0","0"],["104474.5","0.2507638","0","1"],["104477.9","0.13878241","0","1"],["104478.1","0.25314755","0","1"],["104538.5","6.08265491","0","2"],["104541.7","0","0","0"],["104607.5","0","0","0"],["104608.2","0","0","0"]],"bids":[["104456","0.09207729","0","11"],["104454","0.1315585","0","2"],["104447","0.0017149","0","1"],["104446.9","0.41594346","0","1"],["104444.9","0.00097","0","1"],["104444.6","0.25792697","0","3"],["104444.4","0.01062754","0","1"],["104443.1","0.09288931","0","1"],["104442.9","0","0","0"],["104442.5","0.09298304","0","1"],["104442.3","0.83066876","0","3"],["104442.2","0","0","0"],["104441.9","0.54299007","0","2"],["104441.5","0.19741026","0","2"],["104441.2","0.18029353","0","2"],["104441.1","0.14296333","0","1"],["104440.9","0","0","0"],["104439.6","0.15460332","0","1"],["104439.4","0","0","0"],["104438.2","0.00478546","0","1"],["104437.4","0.24846291","0","1"],["104437.1","0","0","0"],["104436.9","0.15416342","0","1"],["104436.7","0.26365266","0","2"],["104436.6","0.096","0","3"],["104434.6","0.25633353","0","1"],["104434.4","0.00001501","0","1"],["104431.5","0.77902003","0","3"],["104431.2","0","0","0"],["104430.6","0.24718929","0","1"],["104430.4","0","0","0"],["104269","0","0","0"],["104268.9","0","0","0"]],"ts":"1747171037701","checksum":-1951324005,"seqId":54226744886,"prevSeqId":54226744788}]}
{"arg":{"channel":"books","instId":"BTC-USDT"},"action":"update","data":[{"asks":[["104456.1","0.80239045","0","9"],["104457.9","0.10066361","0","3"],["104463.5","0","0","0"],["104464.1","0","0","0"],["104465.1","0","0","0"],["104465.6","0","0","0"],["104468.6","0","0","0"],["104468.9","0.00478546","0","1"],["104469","0","0","0"],["104469.1","0","0","0"],["104469.9","0","0","0"],["104471.9","0","0","0"],["104472.4","0","0","0"],["104474.1","0","0","0"],["104474.5","0","0","0"],["104477.9","0","0","0"],["104478.1","0","0","0"],["104480","0.14098893","0","4"],["104507","1","0","1"],["104538.5","0.00003395","0","1"],["104541.7","6.10059534","0","1"],["104607.5","0.00001","0","1"],["104608.2","0.01059542","0","1"],["104608.3","0.03","0","1"],["104608.4","0.00041816","0","1"],["104610","0.29261492","0","3"],["104610.9","0.01099559","0","1"],["104611","0.01099627","0","1"],["104611.3","0.00005484","0","1"],["104612.1","0.01059606","0","1"],["104612.2","0.01407867","0","1"],["104612.9","0.00001168","0","1"]],"bids":[["104456","0.08887729","0","10"],["104454.1","0","0","0"],["104454","0.0932","0","1"],["104452.4","0","0","0"],["104450","0.03337194","0","3"],["104446.9","0.20214983","0","1"],["104444.6","0.07298372","0","1"],["104443.1","0","0","0"],["104442.5","0","0","0"],["104442.3","0.052","0","2"],["104441.5","0.03","0","1"],["104441.1","0","0","0"],["104439.6","0","0","0"],["104438.2","0","0","0"],["104437.4","0","0","0"],["104437","0.00478546","0","1"],["104436.9","0","0","0"],["104436.7","0.35250463","0","3"],["104434.6","0","0","0"],["104431.6","0.1467805","0","2"],["104431.5","0.53424997","0","2"],["104430.6","0","0","0"],["104429.5","0","0","0"],["104269","0.00005407","0","1"],["104268.9","0.00001021","0","1"],["104268.8","0.31181159","0","3"],["104268.4","0.00039895","0","2"],["104268.3","0.00018565","0","4"],["104268","0.00011013","0","2"],["104267.5","0.80866876","0","2"],["104267.2","0.00001019","0","1"],["104267","0.0000111","0","1"],["104266.9","0.00002057","0","2"],["104266.8","0.00001005","0","1"]],"ts":"1747171037801","checksum":1023306626,"seqId":54226744934,"prevSeqId":54226744886}]}
{"arg":{"channel":"books","instId":"BTC-USDT"},"action":"update","data":[{"asks":[["104456.1","0.56839045","0","8"],["104457.9","0.00038538","0","2"],["104463.1","0.08987529","0","1"],["104463.4","0","0","0"],["104463.7","0.09695692","0","2"],["104464.7","0.09702193","0","1"],["104465.3","0.09960396","0","1"],["104468.2","0.15299091","0","1"],["104468.4","0.43877241","0","2"],["104468.6","0.15775224","0","1"],["104468.7","0.15666743","0","1"],["104471.5","0.16162689","0","1"],["104472","0.24916835","0","1"],["104473.7","0.25238973","0","1"],["104474.1","0.24596726","0","1"],["104477.8","0.23823666","0","1"],["104478.8","0.13878104","0","1"],["104480","0.00220843","0","3"],["104507","0","0","0"],["104538.5","6.10062929","0","2"],["104541.7","0","0","0"],["104608.2","0","0","0"],["104608.3","0","0","0"],["104608.4","0","0","0"],["104610","0","0","0"],["104610.9","0","0","0"],["104611","0","0","0"],["104611.3","0","0","0"],["104612.1","0","0","0"],["104612.2","0","0","0"],["104612.9","0","0","0"]],"bids":[["104454.1","0.0383585","0","1"],["104447","0","0","0"],["104446.9","0.1671193","0","2"],["104444.7","0.0017149","0","1"],["104444.2","0.19652358","0","2"],["104442.8","0.09374342","0","1"],["104442.1","0.17190957","0","2"],["104441.9","0.37211211","0","1"],["104441.1","0.16883614","0","1"],["104440.7","0.16307624","0","1"],["104439.2","0.15086909","0","1"],["104437","0.25600279","0","2"],["104436.5","0.15556533","0","1"],["104434.2","0.24494474","0","2"],["104431.6","0.008","0","1"],["104431.5","0.52797603","0","2"],["104431.1","0.24815739","0","1"],["104430.3","0.23591881","0","1"],["104429.5","0.13878104","0","1"],["104268.9","0","0","0"],["104268.8","0","0","0"],["104268.4","0","0","0"],["104268.3","0","0","0"],["104268","0","0","0"],["104267.5","0","0","0"],["104267.2","0","0","0"],["104267","0","0","0"],["104266.9","0","0","0"],["104266.8","0","0","0"]],"ts":"1747171037901","checksum":-880889018,"seqId":54226745037,"prevSeqId":54226744934}]}
{"arg":{"channel":"books","instId":"BTC-USDT"},"action":"update","data":[{"asks":[["104463.1","0","0","0"],["104463.3","0.00011435","0","1"],["104463.4","0.09446272","0","1"],["104463.7","0","0","0"],["104464.1","0.09130085","0","1"],["104464.7","0","0","0"],["104465.1","0.090648","0","1"],["104465.3","0","0","0"],["104465.6","0.0943829","0","1"],["104468.2","0","0","0"],["104468.4","0.53103079","0","2"],["104468.6","0.15913158","0","1"],["104468.7","0","0","0"],["104468.9","0.16255512","0","2"],["104469.1","0.15481466","0","1"],["104471.5","0","0","0"],["104471.8","0.16066726","0","1"],["104472","0","0","0"],["104472.3","0.24369224","0","1"],["104473.7","0","0","0"],["104474.1","0.26958263","0","1"],["104474.4","0.24465372","0","1"],["104477.8","0","0","0"],["104478.1","0.23667135","0","1"]],"bids":[["104456","0.09207729","0","11"],["104454.2","0.0506466","0","1"],["104447","0.0017149","0","1"],["104446.9","0.30413034","0","1"],["104444.7","0","0","0"],["104444.6","0.25018688","0","3"],["104444.2","0","0","0"],["104443.1","0.08807742","0","1"],["104442.8","0","0","0"],["104442.4","0.0926166","0","1"],["104442.1","0.071782","0","1"],["104442","0.77866876","0","1"],["104441.9","0.59351912","0","2"],["104441.4","0.19783964","0","2"],["104441.1","0.1555442","0","1"],["104440.7","0","0","0"],["104439.6","0.16076705","0","1"],["104439.2","0","0","0"],["104437.3","0.28670182","0","2"],["104437","0.00478546","0","1"],["104436.8","0.65970992","0","5"],["104436.7","0.26365266","0","2"],["104436.5","0","0","0"],["104434.6","0.26857412","0","1"],["104434.2","0.000015","0","1"],["104431.4","0.26878455","0","1"],["104431.1","0","0","0"],["104430.6","0.24365985","0","1"],["104430.3","0","0","0"],["104269","0","0","0"]],"ts":"1747171038001","checksum":-999169365,"seqId":54226745127,"prevSeqId":54226745037}]}
{"arg":{"channel":"books","instId":"BTC-USDT"},"action":"update","data":[{"asks":[["104456.1","0.46964045","0","7"],["104456.2","0","0","0"],["104456.3","0.01259609","0","1"],["104463.3","0","0","0"],["104463.4","0","0","0"],["104463.7","0.00011435","0","1"],["104463.8","0.28531043","0","2"],["104463.9","0","0","0"],["104464","0.19573707","0","2"],["104464.1","0","0","0"],["104464.7","0.09975377","0","1"],["104465.1","0","0","0"],["104465.6","0","0","0"],["104465.7","0.09789899","0","1"],["104466.2","0.08795805","0","1"],["104468.4","0.31422269","0","2"],["104468.6","0","0","0"],["104468.9","0","0","0"],["104469.1","0","0","0"],["104469.2","0.1523249","0","1"],["104469.5","0.15944378","0","1"],["104469.7","0.2052768","0","2"],["104470.6","0.00478546","0","1"],["104471.8","0","0","0"],["104472.3","0","0","0"],["104472.5","0.1615961","0","2"],["104472.9","0.23418719","0","2"],["104474.1","0","0","0"],["104474.4","0","0","0"],["104474.7","0.26189842","0","1"],["104475","0.26220684","0","1"],["104478.1","0","0","0"],["104478.7","0.24214438","0","1"],["104478.8","0","0","0"],["104480","0.14098889","0","4"],["104494","0.00343666","0","2"],["104496","0","0","0"],["104505","0","0","0"],["104505.1","0","0","0"],["104536.5","0","0","0"],["104538.1","0.00056666","0","1"],["104538.5","0.00003395","0","1"],["104541.4","0.36919178","0","3"],["104541.7","6.10059534","0","1"],["104546.2","0.11624812","0","2"],["104608.2","0.01059542","0","1"],["104608.3","0.03","0","1"],["104608.4","0.00041816","0","1"],["104610","0.29261492","0","3"],["104610.9","0.01099559","0","1"],["104611","0.01099627","0","1"],["104611.3","0.00005484","0","1"],["104612.1","0.01059606","0","1"]],"bids":[["104456","0.21157729","0","12"],["104446.9","0.44577282","0","2"],["104445.2","0.19013227","0","2"],["104444.6","0.07298372","0","1"],["104443.7","0.0876663","0","1"],["104443.1","0","0","0"],["104443","0.0960947","0","1"],["104442.4","0","0","0"],["104442","0.93571991","0","2"],["104441.9","0.539909","0","2"],["104441.7","0.1559449","0","1"],["104441.4","0.028575","0","1"],["104441.1","0","0","0"],["104440.2","0.15113931","0","1"],["104439.6","0","0","0"],["104438.1","0","0","0"],["104438","0.00478546","0","1"],["104437.9","0.26124108","0","1"],["104437.5","0.14604435","0","1"],["104437.4","0.0095597","0","1"],["104437.3","0.03","0","1"],["104437","0","0","0"],["104436.8","0.50891753","0","4"],["104436.7","0.35617693","0","3"],["104435.2","0.24676352","0","1"],["104434.6","0","0","0"],["104432.1","0.13877968","0","1"],["104432","0.31191537","0","3"],["104431.5","0.36869051","0","1"],["104431.4","0","0","0"],["104431.2","0.25484091","0","1"],["104430.6","0","0","0"],["104429.5","0","0","0"],["104427.8","0.00056666","0","1"],["104427.7","0","0","0"],["104383.7","0.00056666","0","1"],["104382.3","0","0","0"],["104269.6","0","0","0"],["104269.2","0","0","0"]],"ts":"1747171038101","checksum":-1286468922,"seqId":54226745312,"prevSeqId":54226745127}]}
{"arg":{"channel":"books","instId":"BTC-USDT"},"action":"update","data":[{"asks":[["104469.7","0.2436353","0","3"],["104480","0.00220843","0","3"],["104481","0.13877912","0","1"],["104505.2","1.43871225","0","2"],["104536.5","2.47602035","0","1"],["104611.3","0","0","0"],["104612.1","0","0","0"]],"bids":[["104432.7","0.13877912","0","1"],["104432.1","0","0","0"],["104410.5","0.002871","0","1"],["104357.5","0.00010634","0","2"],["104357.4","0","0","0"],["104357.1","0.01738302","0","1"]],"ts":"1747171038201","checksum":-1286468922,"seqId":54226745331,"prevSeqId":54226745312}]}
{"arg":{"channel":"books","instId":"BTC-USDT"},"action":"update","data":[{"asks":[["104463.8","0.2837459","0","2"],["104464","0.0932","0","1"],["104464.1","0.09558133","0","1"],["104464.7","0.09928505","0","1"],["104465.7","0.08950897","0","1"],["104466.2","0","0","0"],["104466.3","0.12678717","0","2"],["104468.4","0.31648361","0","2"],["104469.2","0.15347015","0","1"],["104469.5","0","0","0"],["104469.6","0.15045868","0","1"],["104469.7","0.19051799","0","2"],["104470.6","0","0","0"],["104471","0.00478546","0","1"],["104472.5","0.16512498","0","2"],["104472.9","0.002","0","1"],["104473","0.25879336","0","1"],["104474.7","0.25452652","0","1"],["104475","0","0","0"],["104475.1","0.24389843","0","1"],["104478.7","0","0","0"],["104478.8","0.26776385","0","1"],["104611","0","0","0"]],"bids":[["104456","0.22757729","0","13"],["104446.9","0.45160645","0","2"],["104445.2","0.19632967","0","2"],["104443.8","0.09397037","0","1"],["104443.7","0","0","0"],["104443.1","0.09459883","0","1"],["104443","0","0","0"],["104442.1","0.23727301","0","2"],["104442","0.77866876","0","1"],["104441.9","0.54578307","0","2"],["104441.7","0.15449425","0","1"],["104440.2","0.16467299","0","1"],["104438.7","0.00478546","0","1"],["104438","0.25941735","0","1"],["104437.9","0","0","0"],["104437.5","0.15536528","0","1"],["104436.7","0.42618119","0","3"],["104435.2","0.25131462","0","1"],["104432.1","0.26735804","0","1"],["104432","0.052","0","2"],["104431.3","0.26572704","0","1"],["104431.2","0","0","0"],["104269.9","0","0","0"]],"ts":"1747171038301","checksum":187936926,"seqId":54226745463,"prevSeqId":54226745331}]}
{"arg":{"channel":"books","instId":"BTC-USDT"},"action":"update","data":[{"asks":[["104469.6","0.15524414","0","2"],["104469.7","0.22887649","0","3"],["104471","0","0","0"],["104505.2","0.0287183","0","1"],["104536.5","0","0","0"],["104611","0.01099627","0","1"],["104611.3","0.00005484","0","1"]],"bids":[["104438.7","0","0","0"],["104438.1","0.00478546","0","1"],["104424.5","0.20869903","0","1"],["104423.2","0","0","0"],["104394.6","0.50585689","0","1"],["104391.9","0.234","0","1"],["104269.9","0.0000785","0","2"]],"ts":"1747171038401","checksum":187936926,"seqId":54226745478,"prevSeqId":54226745463}]}
{"arg":{"channel":"books","instId":"BTC-USDT"},"action":"update","data":[{"asks":[["104463.3","0.00011435","0","1"],["104463.4","0.09077675","0","1"],["104463.7","0.36908178","0","1"],["104464","0.18566987","0","2"],["104464.1","0","0","0"],["104464.7","0","0","0"],["104465","0.08887061","0","1"],["104465.6","0.0906609","0","1"],["104465.7","0","0","0"],["104466.3","0.02822972","0","1"],["104468.4","0.53612104","0","1"],["104468.5","0.14832469","0","2"],["104468.9","0.16820132","0","1"],["104469","0.15830187","0","1"],["104469.2","0","0","0"],["104469.5","0.00478546","0","1"],["104469.6","0","0","0"],["104469.7","0.07905013","0","2"],["104471.7","0.77866876","0","1"],["104471.8","0.16462827","0","1"],["104472.3","0.25983105","0","1"],["104472.5","0.00001","0","1"],["104473","0","0","0"],["104474","0.24120011","0","1"],["104474.4","0.25419593","0","1"],["104474.7","0","0","0"],["104475.1","0","0","0"],["104478.1","0.24214335","0","1"],["104478.8","0","0","0"],["104480","0.14098841","0","4"],["104481","0","0","0"],["104505.2","1.4599158","0","2"],["104536.5","2.59920135","0","1"],["104564.4","0.00010649","0","1"],["104608.4","0","0","0"],["104610","0","0","0"],["104610.9","0","0","0"],["104611","0","0","0"],["104611.3","0","0","0"]],"bids":[["104456","0.08886729","0","9"],["104445.2","0","0","0"],["104444.5","0.23976892","0","4"],["104443.8","0","0","0"],["104443.1","0.09577836","0","1"],["104442.4","0.09229087","0","1"],["104442.1","0.071782","0","1"],["104441.7","0","0","0"],["104441.4","0.18866868","0","2"],["104441","0.15778625","0","1"],["104440.2","0","0","0"],["104439.5","0.16647507","0","1"],["104438.1","0","0","0"],["104438","0","0","0"],["104437.6","0.00478546","0","1"],["104437.5","0","0","0"],["104437.3","0.25960133","0","2"],["104436.8","0.67521071","0","5"],["104436.7","0.30385076","0","2"],["104435.2","0","0","0"],["104434.5","0.2679605","0","2"],["104432.7","0","0","0"],["104432.1","0.13877998","0","1"],["104431.4","0.25589362","0","1"],["104431.3","0","0","0"],["104430.6","0.24668614","0","1"],["104423.4","1.46996133","0","2"],["104394.6","1.23187659","0","2"],["104392.1","2.64036634","0","1"],["104269.6","0.00001237","0","1"],["104269.2","0.00026966","0","5"],["104269","0.00005407","0","1"]],"ts":"1747171038501","checksum":-1519659403,"seqId":54226745560,"prevSeqId":54226745478}]}
{"arg":{"channel":"books","instId":"BTC-USDT"},"action":"update","data":[{"asks":[["104478.8","0.13878098","0","1"],["104480","0.00220843","0","3"],["104505.1","0.4382277","0","1"],["104608.2","0","0","0"],["104608.3","0","0","0"]],"bids":[["104432.1","0","0","0"],["104431.5","0.50747149","0","2"],["104424.5","0.68809929","0","2"],["104410.5","0","0","0"],["104387.2","0.002871","0","1"],["104342.5","0","0","0"],["104301.6","0.1608","0","1"],["104268.9","0.00001021","0","1"]],"ts":"1747171038601","checksum":-1519659403,"seqId":54226745570,"prevSeqId":54226745560}]}
{"arg":{"channel":"books","instId":"BTC-USDT"},"action":"update","data":[{"asks":[["104463.3","0","0","0"],["104463.4","0","0","0"],["104463.6","0.30382867","0","2"],["104463.8","0","0","0"],["104464","0.0932","0","1"],["104464.1","0.10004973","0","1"],["104464.7","0.101792","0","1"],["104465","0","0","0"],["104465.6","0","0","0"],["104465.7","0.09543334","0","1"],["104466.2","0.08861239","0","1"],["104468.4","0.52241643","0","2"],["104468.5","0.00001","0","1"],["104468.9","0","0","0"],["104469","0","0","0"],["104469.2","0.14865356","0","1"],["104469.6","0.15996209","0","1"],["104469.7","0.24014732","0","3"],["104471.8","0","0","0"],["104472.3","0","0","0"],["104472.5","0.15087571","0","2"],["104472.9","0.23062887","0","2"],["104474","0","0","0"],["104474.4","0","0","0"],["104474.7","0.25510832","0","1"],["104475.1","0.2721338","0","1"],["104478.1","0","0","0"],["104478.7","0.26767103","0","1"],["104478.8","0.13878084","0","1"],["104608.2","0.01059542","0","1"],["104608.3","0.03","0","1"]],"bids":[["104456","0.21156729","0","11"],["104454.2","0.08380159","0","2"],["104450.1","0","0","0"],["104446.9","0.44966436","0","2"],["104445.2","0.18441268","0","2"],["104444.5","0.052","0","2"],["104443.7","0.10019528","0","1"],["104443.1","0.09172541","0","1"],["104442.4","0","0","0"],["104442.1","0.23936487","0","2"],["104441.9","0.37211211","0","1"],["104441.7","0.15406507","0","1"],["104441.4","0.028575","0","1"],["104441","0","0","0"],["104440.2","0.16845952","0","1"],["104439.5","0","0","0"],["104437.9","0.23609451","0","1"],["104437.5","0.15673991","0","1"],["104437.3","0.03","0","1"],["104436.8","0.50891753","0","4"],["104436.7","0.42242948","0","3"],["104435.2","0.25873047","0","1"],["104434.5","0.00191","0","1"],["104432.1","0.24743476","0","1"],["104431.6","0.14678084","0","2"],["104431.5","0.36869051","0","1"],["104431.4","0","0","0"],["104431.2","0.23843449","0","1"],["104430.6","0","0","0"],["104269.2","0","0","0"],["104269","0","0","0"],["104268.9","0","0","0"]],"ts":"1747171038701","checksum":-743316044,"seqId":54226745644,"prevSeqId":54226745570}]}
