{"arg":{"channel":"books","instId":"BTC-USDT"},"action":"update","data":[{"asks":[["104316.1","0.96087076","0","14"],["104319.9","0.00479235","0","1"]],"bids":[],"ts":"1747170734701","checksum":2107313083,"seqId":54226510765,"prevSeqId":54226510756}]}
{"arg":{"channel":"books","instId":"BTC-USDT"},"action":"update","data":[{"asks":[["104319.9","0","0","0"],["104320.1","0.00479235","0","1"],["104323.9","0.44778379","0","4"],["104324.5","0.09601122","0","1"],["104325.5","0.09750086","0","1"],["104326.1","0.09450415","0","1"],["104329","0.1536979","0","1"],["104329.4","0.15065803","0","1"],["104329.5","0.62011742","0","3"],["104332.3","0.16340095","0","1"],["104332.8","0.23676879","0","1"],["104333","0.33249655","0","1"],["104334.5","0.31076792","0","2"],["104334.9","0.25504525","0","1"],["104338.6","0.26530709","0","1"]],"bids":[["104305","0.19053694","0","3"],["104303.6","0.08805766","0","1"],["104302.9","0.08977781","0","2"],["104301.9","0.16912437","0","2"],["104301.5","0.44420239","0","3"],["104300","0.20881416","0","42"],["104298","0.00001","0","1"],["104297.9","0.00505465","0","2"],["104297.8","0.25426594","0","1"],["104297.3","0.16438639","0","2"],["104295.7","0.31672306","0","3"],["104295","0.25280019","0","1"],["104291.9","0.27573763","0","3"],["104291.1","1.02888861","0","2"]],"ts":"1747170734801","checksum":409947647,"seqId":54226510830,"prevSeqId":54226510765}]}
{"arg":{"channel":"books","instId":"BTC-USDT"},"action":"update","data":[{"asks":[["104389.5","0","0","0"],["104396.3","6.24864793","0","2"],["104531.4","0.00209352","0","1"]],"bids":[],"ts":"1747170734901","checksum":409947647,"seqId":54226510836,"prevSeqId":54226510830}]}
{"arg":{"channel":"books","instId":"BTC-USDT"},"action":"update","data":[{"asks":[["104316.1","0.54782438","0","10"],["104316.8","0","0","0"],["104317.9","0","0","0"],["104318","0","0","0"],["104319.4","0","0","0"],["104319.8","0","0","0"],["104319.9","0.048969","0","1"],["104320.1","0","0","0"],["104320.2","0","0","0"],["104321.4","0","0","0"],["104323.1","0.00479222","0","1"],["104323.2","0.03000467","0","1"],["104323.8","0","0","0"],["104323.9","0.00227925","0","2"],["104324","0.0816","0","1"],["104324.2","0","0","0"],["104324.3","0.28602451","0","1"],["104324.4","0.12841129","0","2"],["104324.5","0","0","0"],["104325.1","0.16797379","0","2"],["104325.5","0","0","0"],["104326.1","0.08924674","0","1"],["104326.6","0.33077697","0","2"],["104328","0.01916928","0","1"],["104329","0","0","0"],["104329.4","0","0","0"],["104329.5","0.34128442","0","3"],["104329.6","0.1621513","0","2"],["104329.9","0.17088883","0","1"],["104330.1","0.16771577","0","1"],["104330.3","0","0","0"],["104331.4","0.00479206","0","1"],["104331.5","0.039371","0","1"],["104331.7","0","0","0"],["104332.3","0","0","0"],["104332.6","0.36908178","0","1"],["104332.7","0","0","0"],["104332.8","0.16428481","0","1"],["104333","0.43875194","0","2"],["104333.3","0.2521301","0","1"],["104334.3","0","0","0"],["104334.5","0.04","0","1"],["104334.9","0","0","0"],["104335.1","0.24005904","0","1"],["104335.4","0.24841517","0","1"],["104336.4","0.1389711","0","1"],["104337","0.03834936","0","1"],["104337.4","0.03833857","0","1"],["104338","0","0","0"],["104338.6","0","0","0"],["104339.1","0.43425773","0","2"],["104359.4","0.28828972","0","2"],["104366.4","0","0","0"],["104373.2","0","0","0"],["104375.8","0","0","0"],["104376.6","0.02265242","0","1"],["104377.2","0.00001","0","1"],["104383.2","0","0","0"],["104386.1","0.38179272","0","2"],["104389.6","0","0","0"],["104389.8","0","0","0"],["104396.3","0.16968822","0","1"],["104397.7","0.11495","0","1"],["104404.6","0.09578","0","1"],["104406.4","6.10282475","0","1"],["104408.3","0","0","0"],["104409.1","0.0022","0","1"],["104415.1","0","0","0"],["104415.7","0.01054345","0","1"],["104418.9","0","0","0"],["104419.5","0.023698","0","1"],["104495.7","0.003","0","2"],["104532","0.00001","0","1"],["104533.3","0.000173","0","1"],["104533.9","0.03","0","1"],["104534.7","0.00094804","0","1"],["104535.6","0.00002193","0","1"],["104535.8","0.77866876","0","1"],["104536.1","0.0152","0","1"],["104536.2","0.076","0","5"],["104536.3","0.076","0","5"],["104536.4","0.00002296","0","1"],["104538.4","0.07298372","0","1"]],"bids":[["104316","0.97745835","0","15"],["104314.1","0.06576893","0","1"],["104313.3","0.03234284","0","1"],["104309.5","0","0","0"],["104305.6","0.20274473","0","3"],["104305","0.00001","0","1"],["104304.1","0.09016641","0","2"],["104303.6","0","0","0"],["104303.4","0.09667859","0","1"],["104302.9","0.00001032","0","1"],["104302.4","0.15843847","0","1"],["104302.1","0.16323346","0","1"],["104301.9","0.0741919","0","2"],["104301.5","0.29145892","0","2"],["104300.6","0.16462503","0","1"],["104300","0.04150745","0","41"],["104299.4","0.00479206","0","1"],["104298.3","0.24491036","0","1"],["104297.9","0.00026259","0","1"],["104297.8","0.1626087","0","1"],["104297.3","0.00014981","0","1"],["104295.7","0.39393689","0","3"],["104295.6","0.24981875","0","1"],["104295","0","0","0"],["104292.4","0.24248322","0","1"],["104291.9","0.03308723","0","2"],["104291.6","0.26153482","0","3"],["104291.1","0.77866876","0","1"],["104286.9","0.13986509","0","5"],["104285.7","0.01187812","0","39"],["104233.9","0","0","0"],["104233.7","0","0","0"],["104233.3","0","0","0"],["104233","0","0","0"],["104232.9","0","0","0"],["104232.7","0","0","0"],["104232.5","0","0","0"]],"ts":"1747170735001","checksum":-1917934388,"seqId":54226511037,"prevSeqId":54226510836}]}
{"arg":{"channel":"books","instId":"BTC-USDT"},"action":"update","data":[{"asks":[["104319.9","0.07475713","0","2"],["104320","0.153503","0","3"],["104321.4","0.03448117","0","1"],["104325.9","0.19242972","0","1"],["104329.5","0.54261563","0","2"],["104331.4","0","0","0"],["104332.5","0.00479206","0","1"],["104332.7","0.77866876","0","1"],["104335.2","0.097949","0","1"],["104335.3","0.13897147","0","1"],["104336.4","0","0","0"],["104386.8","0","0","0"],["104387.5","0.00056666","0","1"],["104396.3","0","0","0"],["104406.4","0","0","0"],["104409.8","6.11338475","0","2"],["104440.1","0","0","0"],["104440.7","0.00056666","0","1"],["104536.4","0","0","0"],["104538.4","0","0","0"]],"bids":[["104313.3","0","0","0"],["104309.7","0.03001227","0","1"],["104307.4","0.00061219","0","2"],["104306.8","0","0","0"],["104300.1","0.04871262","0","4"],["104299.4","0","0","0"],["104286.9","0.13986546","0","5"],["104284.6","0.002877","0","1"],["104254.2","0.00072629","0","3"],["104253.5","0.5124704","0","1"],["104248.9","0.00017476","0","1"],["104233.9","2.62046286","0","1"]],"ts":"1747170735101","checksum":-2134000337,"seqId":54226511072,"prevSeqId":54226511037}]}
{"arg":{"channel":"books","instId":"BTC-USDT"},"action":"update","data":[{"asks":[["104316.1","0.69712076","0","11"],["104318.2","0.015","0","3"],["104323.1","0","0","0"],["104323.8","0.0047922","0","1"],["104330.7","0.015","0","3"],["104332.5","0","0","0"],["104334.3","0.00479206","0","1"],["104389.6","0.0671","0","1"],["104415.7","0.07764345","0","2"],["104536.3","0","0","0"]],"bids":[["104313.8","0.01519173","0","4"],["104301.6","0.00479206","0","1"],["104301.3","0.015","0","3"],["104300.1","0.04392056","0","3"],["104284.6","0","0","0"],["104267.9","0.1809421","0","2"],["104242.4","0.09594603","0","2"]],"ts":"1747170735201","checksum":-57555694,"seqId":54226511096,"prevSeqId":54226511072}]}
{"arg":{"channel":"books","instId":"BTC-USDT"},"action":"update","data":[{"asks":[["104377.2","0.14372","0","2"],["104383.2","0.0958","0","1"],["104536.2","0","0","0"]],"bids":[],"ts":"1747170735301","checksum":-57555694,"seqId":54226511098,"prevSeqId":54226511096}]}
{"arg":{"channel":"books","instId":"BTC-USDT"},"action":"update","data":[{"asks":[["104323.8","0","0","0"],["104324.2","0.00479221","0","1"],["104396.3","6.10282475","0","1"],["104409.8","0.01056","0","1"],["104536.1","0","0","0"]],"bids":[],"ts":"1747170735401","checksum":672977983,"seqId":54226511103,"prevSeqId":54226511098}]}
{"arg":{"channel":"books","instId":"BTC-USDT"},"action":"update","data":[{"asks":[["104335.1","0.35506904","0","2"],["104366.4","0.11498","0","1"],["104373.3","0.09582","0","2"],["104397.7","0","0","0"],["104404.6","0","0","0"],["104408.1","0.05747","0","1"],["104415","0.65097178","0","3"],["104418.9","0.07183","0","1"],["104535.8","0","0","0"]],"bids":[["104304.9","0.02428","0","1"],["104302.8","0.02428","0","1"],["104273.6","0.02428","0","1"],["104242.4","0.00001603","0","1"],["104234.3","0","0","0"],["104234","0","0","0"],["104233.9","0","0","0"]],"ts":"1747170735501","checksum":672977983,"seqId":54226511116,"prevSeqId":54226511103}]}
{"arg":{"channel":"books","instId":"BTC-USDT"},"action":"update","data":[{"asks":[["104389.8","0.19159","0","1"],["104535.6","0","0","0"]],"bids":[],"ts":"1747170735601","checksum":672977983,"seqId":54226511117,"prevSeqId":54226511116}]}
{"arg":{"channel":"books","instId":"BTC-USDT"},"action":"update","data":[{"asks":[["104319.6","0.03448177","0","1"],["104323.2","0","0","0"]],"bids":[["104310.8","0.03105296","0","1"],["104270","0.84229854","0","4"],["104234.4","0","0","0"]],"ts":"1747170735701","checksum":1859802146,"seqId":54226511121,"prevSeqId":54226511117}]}
{"arg":{"channel":"books","instId":"BTC-USDT"},"action":"update","data":[{"asks":[["104318.1","0.03448227","0","1"],["104334.8","0","0","0"],["104368","0.16","0","2"],["104369","0.24999999","0","5"],["104370","0.08528006","0","3"]],"bids":[["104311.3","0","0","0"],["104310.8","0","0","0"],["104304.7","0.05124388","0","1"],["104234.4","0.77963354","0","2"]],"ts":"1747170735801","checksum":937107261,"seqId":54226511131,"prevSeqId":54226511121}]}
{"arg":{"channel":"books","instId":"BTC-USDT"},"action":"update","data":[{"asks":[["104318.1","0","0","0"],["104329.8","0.040113","0","1"],["104332.1","0.03834034","0","1"],["104337.4","0","0","0"],["104377.5","0","0","0"],["104436.8","0","0","0"],["104535.6","0.00002193","0","1"],["104535.8","0.77866876","0","1"]],"bids":[["104309.3","0.03001238","0","1"],["104306.6","0.00003361","0","2"],["104234.4","0","0","0"]],"ts":"1747170735901","checksum":-1695438125,"seqId":54226511140,"prevSeqId":54226511131}]}
{"arg":{"channel":"books","instId":"BTC-USDT"},"action":"update","data":[{"asks":[["104323.8","0.0047922","0","1"],["104324.2","0","0","0"],["104332.9","0.00484206","0","2"],["104334.3","0","0","0"],["104335","0.13897257","0","1"],["104335.3","0","0","0"],["104343.1","0.37195698","0","2"],["104343.2","0","0","0"],["104387.5","0","0","0"],["104388","0.00056666","0","1"],["104440.7","0","0","0"],["104441.3","0.00056666","0","1"],["104536.1","0.0152","0","1"],["104536.2","0.076","0","5"]],"bids":[["104308","0.13378951","0","4"],["104307.4","0.00004553","0","1"],["104301.6","0","0","0"],["104301.4","0.00876613","0","4"],["104254.7","0.00056666","0","1"],["104254.2","0.00015963","0","2"]],"ts":"1747170736101","checksum":-628627413,"seqId":54226511173,"prevSeqId":54226511140}]}
{"arg":{"channel":"books","instId":"BTC-USDT"},"action":"update","data":[{"asks":[["104332.9","0.00005","0","1"],["104333","0.443544","0","3"],["104346","0.002","0","2"],["104372.1","0","0","0"],["104398.2","0.04948461","0","2"],["104536.3","0.076","0","5"]],"bids":[["104301.6","0.00479206","0","1"],["104301.4","0.00397407","0","3"],["104300.2","0","0","0"],["104274.1","0.0001347","0","1"],["104248","0","0","0"],["104234.4","0.77963354","0","2"]],"ts":"1747170736201","checksum":-628627413,"seqId":54226511192,"prevSeqId":54226511173}]}
{"arg":{"channel":"books","instId":"BTC-USDT"},"action":"update","data":[{"asks":[["104319.6","0","0","0"],["104322.9","0.02719325","0","1"],["104323.8","0","0","0"],["104325","0.00479206","0","1"],["104332.4","0.01","0","1"],["104333","0.43875194","0","2"],["104335","0.00479206","0","1"],["104337.8","0.1389691","0","1"],["104536.2","0","0","0"],["104536.3","0","0","0"]],"bids":[["104311.6","0.02615339","0","1"],["104309.3","0","0","0"],["104303.1","0.00485564","0","2"],["104301.6","0","0","0"],["104289.8","0.1389691","0","1"],["104286.9","0.00089399","0","4"]],"ts":"1747170736301","checksum":-976398974,"seqId":54226511221,"prevSeqId":54226511192}]}
{"arg":{"channel":"books","instId":"BTC-USDT"},"action":"update","data":[{"asks":[["104316.1","0.59712076","0","9"],["104319.8","0.02418041","0","1"],["104322.9","0","0","0"],["104325","0.00479208","0","1"],["104334.3","0.00479206","0","1"],["104335","0","0","0"],["104337.3","0","0","0"],["104337.8","0.13896906","0","1"],["104536.2","0.076","0","5"]],"bids":[["104303.1","0.00006358","0","1"],["104302.5","0.00479206","0","1"],["104289.8","0.13896906","0","1"],["104234.4","0","0","0"]],"ts":"1747170736401","checksum":-1401242027,"seqId":54226511250,"prevSeqId":54226511221}]}
{"arg":{"channel":"books","instId":"BTC-USDT"},"action":"update","data":[{"asks":[["104319.8","0","0","0"],["104322.7","0.02719329","0","1"],["104324.9","0.00479208","0","1"],["104325","0","0","0"],["104334.3","0","0","0"],["104335","0.00479206","0","1"]],"bids":[["104310.8","0.03056781","0","1"],["104303.1","0.00485564","0","2"],["104302.5","0","0","0"]],"ts":"1747170736501","checksum":1172304661,"seqId":54226511263,"prevSeqId":54226511250}]}
{"arg":{"channel":"books","instId":"BTC-USDT"},"action":"update","data":[{"asks":[["104316.1","0.47762076","0","8"],["104336.9","0.13896947","0","1"],["104337.8","0","0","0"]],"bids":[["104289.8","0","0","0"],["104289","0.13896947","0","1"]],"ts":"1747170736601","checksum":-660289183,"seqId":54226511285,"prevSeqId":54226511263}]}
{"arg":{"channel":"books","instId":"BTC-USDT"},"action":"update","data":[{"asks":[["104324.3","0.29081658","0","2"],["104324.9","0","0","0"],["104536.3","0.076","0","5"]],"bids":[["104310.8","0","0","0"],["104234.4","0.77963354","0","2"]],"ts":"1747170736701","checksum":-877998416,"seqId":54226511288,"prevSeqId":54226511285}]}
{"arg":{"channel":"books","instId":"BTC-USDT"},"action":"update","data":[{"asks":[["104319.8","0.02418042","0","1"],["104322.7","0","0","0"],["104353.7","0.56120425","0","1"],["104356.6","0","0","0"],["104387.9","0","0","0"],["104392.9","6.20578481","0","1"],["104396.3","0","0","0"],["104536.4","0.00002296","0","1"],["104538.4","0.07298372","0","1"]],"bids":[["104270","0.47121075","0","3"],["104265.2","0.46641679","0","3"]],"ts":"1747170736801","checksum":1542285846,"seqId":54226511301,"prevSeqId":54226511288}]}
{"arg":{"channel":"books","instId":"BTC-USDT"},"action":"update","data":[{"asks":[["104316.1","0.48082076","0","9"],["104353.7","0.90490373","0","2"],["104356.7","1.37950005","0","1"],["104388","2.50406258","0","2"],["104392.9","0","0","0"],["104396.3","6.21364958","0","1"],["104538.4","0","0","0"]],"bids":[["104270","0.83983275","0","4"],["104267.7","1.42203875","0","1"],["104236.4","2.49481626","0","2"],["104234.4","0","0","0"]],"ts":"1747170736901","checksum":-1260285470,"seqId":54226511310,"prevSeqId":54226511301}]}
{"arg":{"channel":"books","instId":"BTC-USDT"},"action":"update","data":[{"asks":[["104324.3","0.28602451","0","1"],["104325","0.00479208","0","1"],["104336.4","0.1389707","0","1"],["104336.9","0","0","0"],["104388","2.50349592","0","1"],["104388.6","0.00056666","0","1"],["104441.3","0","0","0"],["104441.8","0.00056666","0","1"],["104536.3","0","0","0"],["104536.4","0","0","0"]],"bids":[["104308.5","0.00056666","0","1"],["104308","0.13322285","0","3"],["104289","0","0","0"],["104288.6","0.13908128","0","3"],["104255.3","0.00056666","0","1"],["104254.7","0","0","0"]],"ts":"1747170737101","checksum":1341563914,"seqId":54226511336,"prevSeqId":54226511310}]}
{"arg":{"channel":"books","instId":"BTC-USDT"},"action":"update","data":[{"asks":[],"bids":[["104288.9","0.13829726","0","3"],["104268.7","0","0","0"],["104234.4","0.77963354","0","2"]],"ts":"1747170737201","checksum":1341563914,"seqId":54226511338,"prevSeqId":54226511336}]}
{"arg":{"channel":"books","instId":"BTC-USDT"},"action":"update","data":[{"asks":[["104324.3","0.29081659","0","2"],["104325","0","0","0"],["104336.4","0","0","0"],["104336.9","0.13896982","0","1"],["104440.6","0","0","0"],["104451","0","0","0"],["104536.3","0.076","0","5"],["104536.4","0.00002296","0","1"],["104538.4","0.07298372","0","1"]],"bids":[["104310.8","0.02986601","0","1"],["104289","0.13896982","0","1"],["104288.6","0.00011027","0","2"],["104234.5","0","0","0"],["104234.4","0","0","0"]],"ts":"1747170737401","checksum":-88243837,"seqId":54226511349,"prevSeqId":54226511338}]}
{"arg":{"channel":"books","instId":"BTC-USDT"},"action":"update","data":[{"asks":[["104336.9","0","0","0"],["104337.8","0.13896902","0","1"],["104440.6","0.0013452","0","1"],["104451","0.0026904","0","1"],["104536.4","0","0","0"],["104538.4","0","0","0"]],"bids":[["104289.8","0.13896902","0","1"],["104289","0","0","0"]],"ts":"1747170737501","checksum":-88243837,"seqId":54226511359,"prevSeqId":54226511349}]}
{"arg":{"channel":"books","instId":"BTC-USDT"},"action":"update","data":[{"asks":[["104316.1","0.45102438","0","9"],["104324.3","0.28602451","0","1"],["104324.4","0.03108988","0","1"],["104325","0.00479208","0","1"],["104329.9","0","0","0"],["104332.8","0","0","0"],["104333.3","0","0","0"],["104335.4","0","0","0"],["104336.4","0.13897019","0","1"],["104337","0","0","0"],["104337.8","0","0","0"],["104536.4","0.00002296","0","1"],["104538.4","0.07298372","0","1"],["104540","0.00330186","0","4"],["104541.2","0.00009506","0","1"]],"bids":[["104316","0.97845835","0","16"],["104303.4","0","0","0"],["104302.4","0","0","0"],["104298.3","0","0","0"],["104297.8","0","0","0"],["104292.4","0","0","0"],["104289.8","0","0","0"],["104289","0.13897019","0","1"],["104234.5","0.00003076","0","2"],["104234.4","0.77963354","0","2"],["104234.3","0.00028121","0","5"],["104234","0.00002831","0","2"],["104233.7","0.00003837","0","1"]],"ts":"1747170737601","checksum":-136045676,"seqId":54226511381,"prevSeqId":54226511359}]}
{"arg":{"channel":"books","instId":"BTC-USDT"},"action":"update","data":[{"asks":[["104316.1","0.44782438","0","8"],["104319.9","0","0","0"],["104324.4","0.12654368","0","2"],["104325","0","0","0"],["104325.3","0.00479208","0","1"],["104329.5","0.36863015","0","2"],["104329.9","0.15504503","0","1"],["104332.5","0.77866876","0","1"],["104332.7","0","0","0"],["104332.8","0.1479889","0","1"],["104333.3","0.24521456","0","1"],["104333.9","0.03834936","0","1"],["104335","0","0","0"],["104335.4","0.26450943","0","1"],["104336.3","0.00479206","0","1"],["104536.4","0","0","0"],["104538.4","0","0","0"],["104540","0","0","0"],["104541.2","0","0","0"]],"bids":[["104310.8","0","0","0"],["104303.5","0.00514967","0","5"],["104303.4","0.09184582","0","1"],["104303.1","0.00006358","0","1"],["104302.4","0.15119974","0","1"],["104301.5","0.28837895","0","2"],["104298.3","0.25237286","0","1"],["104297.8","0.14946583","0","1"],["104292.4","0.25376384","0","1"],["104234.4","0","0","0"],["104234.3","0","0","0"],["104234","0","0","0"],["104233.7","0","0","0"]],"ts":"1747170737701","checksum":-131817162,"seqId":54226511412,"prevSeqId":54226511381}]}
{"arg":{"channel":"books","instId":"BTC-USDT"},"action":"update","data":[{"asks":[["104316.1","0.45102438","0","9"],["104324.2","0.00479208","0","1"],["104324.4","0.12829972","0","2"],["104325.3","0","0","0"],["104329.5","0.55615389","0","3"],["104329.9","0.1689439","0","1"],["104332.8","0.15562853","0","1"],["104333.3","0.25866627","0","1"],["104335.4","0.27296933","0","1"]],"bids":[["104303.4","0.10262903","0","1"],["104302.4","0.16284807","0","1"],["104301.5","0.1597262","0","1"],["104298.3","0.24400619","0","1"],["104297.8","0.15751403","0","1"],["104292.4","0.24030157","0","1"]],"ts":"1747170737801","checksum":1556231393,"seqId":54226511442,"prevSeqId":54226511412}]}
{"arg":{"channel":"books","instId":"BTC-USDT"},"action":"update","data":[{"asks":[],"bids":[["104301.5","0.28828341","0","2"],["104273.8","0","0","0"],["104234.4","0.77963354","0","2"]],"ts":"1747170737901","checksum":1556231393,"seqId":54226511447,"prevSeqId":54226511442}]}
{"arg":{"channel":"books","instId":"BTC-USDT"},"action":"update","data":[{"asks":[["104332.3","0.00479206","0","1"],["104335","0.13897206","0","1"],["104336.3","0","0","0"],["104336.4","0","0","0"],["104388.6","0","0","0"],["104389.2","0.00056666","0","1"],["104441.8","0","0","0"],["104442.4","0.00056666","0","1"]],"bids":[["104309.1","0.00056666","0","1"],["104308.5","0","0","0"],["104303.5","0.00035761","0","4"],["104300.7","0.00479206","0","1"],["104289","0","0","0"],["104286.9","0.13986605","0","5"],["104255.9","0.00068576","0","2"],["104255.3","0","0","0"],["104234.3","0.00028121","0","5"]],"ts":"1747170738101","checksum":1924029023,"seqId":54226511483,"prevSeqId":54226511447}]}
{"arg":{"channel":"books","instId":"BTC-USDT"},"action":"update","data":[{"asks":[["104332","0.00479206","0","1"],["104332.3","0","0","0"],["104335","0","0","0"],["104336.4","0.13897079","0","1"]],"bids":[["104300.7","0","0","0"],["104300.2","0.00479206","0","1"],["104286.9","0.13986504","0","5"],["104273.8","0.00002967","0","1"],["104234.3","0","0","0"]],"ts":"1747170738201","checksum":1924029023,"seqId":54226511498,"prevSeqId":54226511483}]}
{"arg":{"channel":"books","instId":"BTC-USDT"},"action":"update","data":[{"asks":[["104324.2","0","0","0"],["104325","0.00479208","0","1"],["104344","0.002","0","2"],["104345","0.001","0","1"],["104346","0","0","0"],["104347","0","0","0"],["104367","0.33","0","6"],["104368","0.16499999","0","3"],["104369","0","0","0"],["104370","0.00028006","0","1"]],"bids":[["104316","0.97745835","0","15"],["104310.8","0.03020165","0","1"],["104287","0.13897105","0","1"],["104286.9","0.00089399","0","4"],["104234.5","0","0","0"],["104234.4","0","0","0"]],"ts":"1747170738301","checksum":1138784578,"seqId":54226511547,"prevSeqId":54226511498}]}
{"arg":{"channel":"books","instId":"BTC-USDT"},"action":"update","data":[{"asks":[["104319.9","0.08087825","0","1"],["104332","0","0","0"],["104332.3","0.00479206","0","1"],["104417.9","0","0","0"]],"bids":[["104303.9","0.01151892","0","1"],["104300.7","0.00479206","0","1"],["104300.2","0","0","0"],["104300.1","0.03239275","0","2"],["104234.6","0","0","0"]],"ts":"1747170738401","checksum":-331529653,"seqId":54226511559,"prevSeqId":54226511547}]}
{"arg":{"channel":"books","instId":"BTC-USDT"},"action":"update","data":[{"asks":[["104316.1","0.45002438","0","9"],["104319.9","0","0","0"],["104324.4","0.12979603","0","2"],["104325","0","0","0"],["104325.6","0.00479208","0","1"],["104326.6","0.3251217","0","2"],["104329.5","0.36863015","0","2"],["104329.9","0.15132748","0","1"],["104332.3","0","0","0"],["104332.5","0","0","0"],["104332.8","0.16666934","0","1"],["104333.3","0.25176086","0","1"],["104333.9","0","0","0"],["104335.4","0.2677294","0","1"],["104336.3","0.00479206","0","1"],["104336.4","0","0","0"],["104337.8","0.13896867","0","1"],["104339.1","0.43904312","0","2"],["104344","0","0","0"],["104345","0","0","0"],["104346","0.002","0","2"],["104347","0.001","0","1"],["104353.7","0.56120425","0","1"],["104356.7","0","0","0"],["104367","0","0","0"],["104368","0.15999999","0","2"],["104369","0.24999999","0","5"],["104370","0.08528006","0","3"],["104386.1","0.43605955","0","3"],["104388","0","0","0"],["104536.4","0.00002296","0","1"],["104538.4","0.07298372","0","1"],["104538.5","0.234","0","1"],["104540","0.00330186","0","4"],["104541.2","0.00009506","0","1"]],"bids":[["104304.1","0.10141033","0","3"],["104303.4","0.09055658","0","1"],["104302.4","0.15752365","0","1"],["104301.5","0.2797823","0","2"],["104300.7","0","0","0"],["104298.3","0.22961782","0","1"],["104297.8","0.1550932","0","1"],["104295.7","0.39141761","0","3"],["104292.4","0.25977916","0","1"],["104291.6","0.23584127","0","3"],["104289.8","0.13896867","0","1"],["104287","0","0","0"],["104234.6","0.00199229","0","3"]],"ts":"1747170738501","checksum":-1151303269,"seqId":54226511644,"prevSeqId":54226511559}]}
{"arg":{"channel":"books","instId":"BTC-USDT"},"action":"update","data":[{"asks":[["104319.9","0.08087825","0","1"],["104324.2","0.00479208","0","1"],["104325.6","0","0","0"],["104329.5","0.56064276","0","3"],["104332.7","0.77866876","0","1"],["104333.8","0.03834936","0","1"],["104335","0.00479206","0","1"],["104336.3","0","0","0"],["104423.9","0.00095763","0","1"],["104538.4","0","0","0"],["104538.5","0","0","0"],["104540","0","0","0"],["104541.2","0","0","0"]],"bids":[["104304.1","0.09661827","0","2"],["104303.5","0.00514967","0","5"]],"ts":"1747170738601","checksum":-738686462,"seqId":54226511660,"prevSeqId":54226511644}]}
{"arg":{"channel":"books","instId":"BTC-USDT"},"action":"update","data":[{"asks":[["104353.7","0.92359758","0","2"],["104356.7","1.44181289","0","1"],["104367.8","0.77866876","0","1"],["104388","2.64838752","0","1"],["104536.3","0","0","0"],["104536.4","0","0","0"]],"bids":[["104310.8","0","0","0"],["104303.5","0.00035761","0","4"],["104303.1","0.00485564","0","2"],["104267.9","0.1780651","0","1"],["104243.1","0.002877","0","1"]],"ts":"1747170738701","checksum":2101704069,"seqId":54226511678,"prevSeqId":54226511660}]}
{"arg":{"channel":"books","instId":"BTC-USDT"},"action":"update","data":[{"asks":[["104367.8","0.77879906","0","2"]],"bids":[],"ts":"1747170738801","checksum":2101704069,"seqId":54226511726,"prevSeqId":54226511678}]}
{"arg":{"channel":"books","instId":"BTC-USDT"},"action":"update","data":[{"asks":[["104316.1","0.44682438","0","8"],["104328.6","0.01","0","1"],["104332.4","0","0","0"],["104367.8","0.77866876","0","1"]],"bids":[["104316","0.97799835","0","16"]],"ts":"1747170738901","checksum":-1973693399,"seqId":54226511733,"prevSeqId":54226511726}]}
{"arg":{"channel":"books","instId":"BTC-USDT"},"action":"update","data":[{"asks":[["104367.8","0.77879906","0","2"]],"bids":[],"ts":"1747170739001","checksum":-1973693399,"seqId":54226511736,"prevSeqId":54226511733}]}
{"arg":{"channel":"books","instId":"BTC-USDT"},"action":"update","data":[{"asks":[["104318.3","0","0","0"],["104330.8","0","0","0"],["104336.4","0.13897041","0","1"],["104337.8","0","0","0"],["104389.2","0","0","0"],["104389.7","0.00056666","0","1"],["104442.4","0","0","0"],["104443","0.00056666","0","1"],["104536.3","0.076","0","5"],["104536.4","0.00002296","0","1"]],"bids":[["104313.7","0","0","0"],["104309.7","0.03057893","0","2"],["104309.1","0","0","0"],["104301.2","0.00032901","0","4"],["104289.8","0","0","0"],["104289","0.13897041","0","1"],["104256.4","0.00057784","0","2"],["104255.9","0.0001191","0","1"],["104234.5","0.00003076","0","2"],["104234.4","0.77963354","0","2"]],"ts":"1747170739101","checksum":-543099426,"seqId":54226511755,"prevSeqId":54226511736}]}
{"arg":{"channel":"books","instId":"BTC-USDT"},"action":"update","data":[{"asks":[["104316.1","0.32732438","0","7"],["104319.8","0","0","0"],["104322.7","0.02672409","0","1"],["104324.2","0","0","0"],["104324.4","0.03108988","0","1"],["104324.5","0.10229164","0","1"],["104325","0.00479201","0","1"],["104325.1","0.07298372","0","1"],["104325.2","0.093959","0","1"],["104326.6","0.234","0","1"],["104326.7","0.09167005","0","1"],["104329.9","0","0","0"],["104330","0.24216701","0","4"],["104330.1","0","0","0"],["104330.2","0.16295863","0","1"],["104332.8","0","0","0"],["104332.9","0.15192472","0","2"],["104333","0.4177625","0","2"],["104333.3","0","0","0"],["104333.4","0.23375996","0","1"],["104333.8","0","0","0"],["104335","0","0","0"],["104335.1","0.11501","0","1"],["104335.2","0.37032435","0","2"],["104335.4","0","0","0"],["104335.5","0.25997814","0","1"],["104336.4","0.00479206","0","1"],["104337.8","0.13896872","0","1"],["104339.1","0.1780651","0","1"],["104339.2","0.24812698","0","1"],["104419.7","0.0210868","0","2"],["104496.9","0","0","0"]],"bids":[["104316","0.97798116","0","16"],["104313.2","0.02953548","0","1"],["104305.7","0.09647598","0","1"],["104305.6","0.10074691","0","2"],["104304.2","0.08900827","0","1"],["104304.1","0.00484006","0","2"],["104303.5","0.08990745","0","5"],["104303.4","0","0","0"],["104303.1","0.00006358","0","1"],["104302.5","0.16909448","0","1"],["104302.4","0","0","0"],["104301.5","0.26750532","0","2"],["104300.7","0.15147607","0","1"],["104300.6","0","0","0"],["104299.3","0","0","0"],["104298.4","0.24822885","0","6"],["104298.3","0","0","0"],["104297.9","0.15616958","0","2"],["104297.8","0","0","0"],["104295.7","0.56740552","0","4"],["104295.6","0","0","0"],["104292.5","0.2422995","0","3"],["104292.4","0","0","0"],["104291.7","0.24494449","0","3"],["104291.6","0.00100678","0","2"],["104289.8","0.13896872","0","1"],["104289","0","0","0"],["104234.3","0.00028121","0","5"],["104234","0.00002831","0","2"],["104233.7","0.00003837","0","1"]],"ts":"1747170739201","checksum":-138290175,"seqId":54226511843,"prevSeqId":54226511755}]}
{"arg":{"channel":"books","instId":"BTC-USDT"},"action":"update","data":[{"asks":[["104319.9","0.10872386","0","2"],["104322.7","0","0","0"],["104325","0.00479199","0","1"],["104332.9","0.15671678","0","3"],["104333.7","0.03834936","0","1"],["104336.4","0","0","0"],["104337.8","0.13896864","0","1"],["104425.5","0.01347206","0","1"],["104502.9","0.00123213","0","1"],["104536.4","0","0","0"]],"bids":[["104316","0.97298536","0","16"],["104313.2","0","0","0"],["104304.1","0.000048","0","1"],["104301.5","0.27229738","0","3"],["104301.2","0.05214032","0","5"],["104289.8","0.13896864","0","1"],["104233.3","0.00482005","0","1"]],"ts":"1747170739301","checksum":-968381020,"seqId":54226511869,"prevSeqId":54226511843}]}
{"arg":{"channel":"books","instId":"BTC-USDT"},"action":"update","data":[{"asks":[["104337.8","0.13896862","0","1"]],"bids":[["104289.8","0.13896862","0","1"]],"ts":"1747170739401","checksum":-968381020,"seqId":54226511877,"prevSeqId":54226511869}]}
{"arg":{"channel":"books","instId":"BTC-USDT"},"action":"update","data":[{"asks":[["104316.1","0.45002438","0","9"],["104324.3","0.2908165","0","2"],["104324.4","0.12957368","0","2"],["104324.5","0","0","0"],["104325","0","0","0"],["104325.1","0.17121034","0","2"],["104325.2","0","0","0"],["104326.6","0.3284584","0","2"],["104326.7","0","0","0"],["104329.9","0.15876197","0","1"],["104330","0.08190006","0","3"],["104330.1","0.15407569","0","1"],["104330.2","0","0","0"],["104332.5","0.00479206","0","1"],["104332.8","0.14682178","0","1"],["104332.9","0.00005","0","1"],["104333","0.24750964","0","1"],["104333.3","0.23133517","0","1"],["104333.4","0","0","0"],["104335.1","0.35504395","0","2"],["104335.2","0.097949","0","1"],["104335.4","0.26617721","0","1"],["104335.5","0","0","0"],["104339.1","0.42791557","0","2"],["104339.2","0","0","0"],["104536.4","0.00002296","0","1"],["104538.4","0.07298372","0","1"]],"bids":[["104305.7","0","0","0"],["104305.6","0.1913106","0","3"],["104304.2","0","0","0"],["104304.1","0.09402459","0","2"],["104303.5","0.00035761","0","4"],["104303.4","0.09034982","0","1"],["104302.5","0","0","0"],["104302.4","0.16668247","0","1"],["104301.5","0.1597262","0","1"],["104300.7","0","0","0"],["104300.6","0.15090134","0","1"],["104300.2","0.00479206","0","1"],["104298.4","0.00542256","0","5"],["104298.3","0.24989894","0","1"],["104297.9","0.00026259","0","1"],["104297.8","0.15016499","0","1"],["104295.7","0.19380067","0","2"],["104295.6","0.25136254","0","1"],["104292.5","0.00002543","0","2"],["104292.4","0.26091741","0","1"],["104291.7","0.00009425","0","2"],["104291.6","0.26784911","0","3"],["104234.3","0","0","0"],["104234","0","0","0"],["104233.7","0","0","0"],["104233.3","0","0","0"]],"ts":"1747170739501","checksum":-1320508732,"seqId":54226511929,"prevSeqId":54226511877}]}
{"arg":{"channel":"books","instId":"BTC-USDT"},"action":"update","data":[{"asks":[["104333","0.48946732","0","2"],["104353.7","0.56120425","0","1"],["104356.7","0","0","0"],["104388","0","0","0"],["104392.9","6.21740286","0","1"],["104396.3","0","0","0"],["104538.5","0.234","0","1"],["104540","0.00330186","0","4"]],"bids":[["104301.5","0.2847191","0","2"],["104295.7","0.40182457","0","3"],["104270","0.47121075","0","3"],["104267.7","0","0","0"],["104236.4","0.00012145","0","1"],["104234.3","0.00028121","0","5"]],"ts":"1747170739601","checksum":-1320508732,"seqId":54226511946,"prevSeqId":54226511929}]}
{"arg":{"channel":"books","instId":"BTC-USDT"},"action":"update","data":[{"asks":[["104319.9","0.34872386","0","3"],["104323.8","0.004792","0","1"],["104324.3","0.28602451","0","1"],["104336.4","0.13897133","0","1"],["104337.8","0","0","0"],["104353.7","0.90173735","0","2"],["104356.7","1.36894546","0","1"],["104388","2.52670226","0","1"],["104392.9","0","0","0"],["104396.3","6.21740286","0","1"],["104425.5","0","0","0"],["104502.9","0","0","0"],["104538.5","0","0","0"]],"bids":[["104289.8","0","0","0"],["104286.9","0.13986541","0","5"],["104270","0.81222234","0","4"],["104266.1","1.43118269","0","2"],["104234.8","2.50064546","0","2"],["104234","0.00002831","0","2"]],"ts":"1747170739701","checksum":2052604308,"seqId":54226511974,"prevSeqId":54226511946}]}
{"arg":{"channel":"books","instId":"BTC-USDT"},"action":"update","data":[{"asks":[["104319.8","0.16123193","0","1"],["104319.9","0.26784561","0","2"],["104331.4","0.00479206","0","1"],["104332.5","0","0","0"],["104386.1","0.38179272","0","2"],["104419.5","0","0","0"],["104423.9","0","0","0"],["104538.5","0.234","0","1"]],"bids":[["104316","0.97244536","0","15"],["104311.6","0","0","0"],["104308.2","0.02658583","0","2"],["104300.2","0","0","0"],["104298.5","0.00479206","0","1"],["104233.7","0.00003837","0","1"]],"ts":"1747170739801","checksum":-1944303893,"seqId":54226511991,"prevSeqId":54226511974}]}
{"arg":{"channel":"books","instId":"BTC-USDT"},"action":"update","data":[{"asks":[["104318.3","0.002","0","1"],["104330.8","0.002","0","1"],["104423","0.02401584","0","2"],["104423.2","0.00095764","0","1"],["104500.3","0.00123216","0","1"],["104536.4","0","0","0"],["104538.4","0","0","0"],["104538.5","0","0","0"],["104540","0","0","0"]],"bids":[["104316","0.97722536","0","16"],["104313.7","0.002","0","1"],["104301.2","0.05414032","0","6"],["104233.7","0","0","0"]],"ts":"1747170739901","checksum":1178625127,"seqId":54226512006,"prevSeqId":54226511991}]}
{"arg":{"channel":"books","instId":"BTC-USDT"},"action":"update","data":[{"asks":[["104331.4","0","0","0"],["104333.2","0.00479206","0","1"],["104344","0.002","0","2"],["104345","0.001","0","1"],["104346","0","0","0"],["104347","0","0","0"],["104367","0.33","0","6"],["104368","0.16499999","0","3"],["104369","0","0","0"],["104370","0.00028006","0","1"]],"bids":[["104312.9","0","0","0"],["104301.6","0.00479206","0","1"],["104298.5","0","0","0"],["104233.7","0.00003837","0","1"]],"ts":"1747170740001","checksum":-175805159,"seqId":54226512033,"prevSeqId":54226512006}]}
{"arg":{"channel":"books","instId":"BTC-USDT"},"action":"update","data":[{"asks":[["104333.2","0","0","0"],["104333.6","0.00480206","0","2"],["104336.4","0.13897094","0","1"],["104344","0","0","0"],["104345","0","0","0"],["104346","0.002","0","2"],["104347","0.001","0","1"],["104367","0","0","0"],["104368","0.15999999","0","2"],["104369","0.24999999","0","5"],["104370","0.08528006","0","3"],["104389.7","0","0","0"],["104390.2","0.77923542","0","2"],["104423","0.02410835","0","3"],["104443","0","0","0"],["104443.5","0.00056666","0","1"],["104536.4","0.00002296","0","1"],["104538.4","0.07298372","0","1"]],"bids":[["104310.2","0.00056666","0","1"],["104309.7","0.03001227","0","1"],["104302","0.00479206","0","1"],["104301.6","0","0","0"],["104288.6","0.13908121","0","3"],["104286.9","0.00089399","0","4"],["104256.9","0.00077686","0","5"],["104256.4","0.00001118","0","1"],["104233.7","0","0","0"]],"ts":"1747170740101","checksum":1694842169,"seqId":54226512081,"prevSeqId":54226512033}]}
{"arg":{"channel":"books","instId":"BTC-USDT"},"action":"update","data":[{"asks":[["104319.8","0.08923193","0","1"],["104319.9","0.02784561","0","1"],["104333.6","0.00001","0","1"],["104334.3","0.00479206","0","1"],["104538.4","0","0","0"]],"bids":[["104316","1.01557472","0","17"],["104302.2","0.00482478","0","2"],["104302","0","0","0"],["104233.7","0.00003837","0","1"]],"ts":"1747170740201","checksum":1051495039,"seqId":54226512105,"prevSeqId":54226512081}]}
{"arg":{"channel":"books","instId":"BTC-USDT"},"action":"update","data":[{"asks":[],"bids":[["104316","1.01567472","0","18"],["104288.6","0.00011027","0","2"],["104286.9","0.13986524","0","5"]],"ts":"1747170740301","checksum":-788135984,"seqId":54226512108,"prevSeqId":54226512105}]}
{"arg":{"channel":"books","instId":"BTC-USDT"},"action":"update","data":[{"asks":[["104334.3","0","0","0"],["104335","0.00479206","0","1"],["104336.4","0.13897126","0","1"]],"bids":[["104303.1","0.00485564","0","2"],["104302.2","0.00003272","0","1"],["104286.9","0.13986525","0","5"]],"ts":"1747170740401","checksum":-788135984,"seqId":54226512128,"prevSeqId":54226512108}]}
{"arg":{"channel":"books","instId":"BTC-USDT"},"action":"update","data":[{"asks":[["104334.9","0.00479206","0","1"],["104335","0","0","0"],["104336.4","0.13897099","0","1"]],"bids":[["104288.6","0.13908126","0","3"],["104286.9","0.00089399","0","4"]],"ts":"1747170740501","checksum":-788135984,"seqId":54226512147,"prevSeqId":54226512128}]}
{"arg":{"channel":"books","instId":"BTC-USDT"},"action":"update","data":[{"asks":[["104334.3","0.00479206","0","1"],["104334.9","0","0","0"],["104336.4","0.13897119","0","1"]],"bids":[["104303.1","0.00006358","0","1"],["104302.9","0.00480238","0","2"],["104288.6","0.00011027","0","2"],["104286.9","0.13986537","0","5"],["104273.8","0","0","0"],["104233.3","0.00482005","0","1"]],"ts":"1747170740601","checksum":-788135984,"seqId":54226512159,"prevSeqId":54226512147}]}
{"arg":{"channel":"books","instId":"BTC-USDT"},"action":"update","data":[{"asks":[],"bids":[["104273.8","0.00002967","0","1"],["104233.3","0","0","0"]],"ts":"1747170740701","checksum":-788135984,"seqId":54226512161,"prevSeqId":54226512159}]}
{"arg":{"channel":"books","instId":"BTC-USDT"},"action":"update","data":[{"asks":[["104392.9","6.21770478","0","1"],["104396.3","0","0","0"]],"bids":[["104302.9","0.00001032","0","1"],["104302.5","0.00479206","0","1"],["104233.7","0","0","0"]],"ts":"1747170740801","checksum":-788135984,"seqId":54226512170,"prevSeqId":54226512161}]}
{"arg":{"channel":"books","instId":"BTC-USDT"},"action":"update","data":[{"asks":[],"bids":[["104289","0.13897045","0","1"],["104286.9","0.00089399","0","4"],["104234","0","0","0"]],"ts":"1747170741001","checksum":-788135984,"seqId":54226512172,"prevSeqId":54226512170}]}
{"arg":{"channel":"books","instId":"BTC-USDT"},"action":"update","data":[{"asks":[["104390.2","0.77866876","0","1"],["104390.8","0.00056666","0","1"],["104443.5","0","0","0"],["104444","0.00056666","0","1"],["104536.4","0","0","0"]],"bids":[["104310.7","0.00056666","0","1"],["104310.2","0","0","0"],["104257.5","0.00056666","0","1"],["104256.9","0.0002102","0","4"],["104234.3","0","0","0"]],"ts":"1747170741101","checksum":20029153,"seqId":54226512182,"prevSeqId":54226512172}]}
{"arg":{"channel":"books","instId":"BTC-USDT"},"action":"update","data":[{"asks":[],"bids":[["104289","0","0","0"],["104288.6","0.13908132","0","3"],["104234.3","0.00028121","0","5"]],"ts":"1747170741201","checksum":20029153,"seqId":54226512189,"prevSeqId":54226512182}]}
{"arg":{"channel":"books","instId":"BTC-USDT"},"action":"update","data":[{"asks":[["104330.1","0.17924952","0","2"],["104333.7","0","0","0"],["104536.4","0.00002296","0","1"]],"bids":[["104316","1.00249919","0","18"],["104289","0.13896995","0","1"],["104288.6","0.00011027","0","2"],["104234.3","0","0","0"]],"ts":"1747170741301","checksum":876666048,"seqId":54226512205,"prevSeqId":54226512189}]}
{"arg":{"channel":"books","instId":"BTC-USDT"},"action":"update","data":[{"asks":[["104349.6","0.00958168","0","1"],["104375.7","0.02874504","0","1"],["104401.8","0.0479084","0","1"],["104536.2","0","0","0"],["104536.3","0","0","0"],["104536.4","0","0","0"]],"bids":[["104307.4","0.00963109","0","2"],["104289","0.13897017","0","1"],["104281.3","0.02877556","0","2"],["104273.8","0","0","0"],["104255.2","0.04794824","0","3"],["104234.3","0.00028121","0","5"]],"ts":"1747170741401","checksum":1066049502,"seqId":54226512229,"prevSeqId":54226512205}]}
{"arg":{"channel":"books","instId":"BTC-USDT"},"action":"update","data":[{"asks":[["104334.3","0","0","0"],["104335","0.00479206","0","1"]],"bids":[["104303.1","0.00485564","0","2"],["104302.5","0","0","0"],["104273.8","0.00002967","0","1"]],"ts":"1747170741501","checksum":1066049502,"seqId":54226512236,"prevSeqId":54226512229}]}
{"arg":{"channel":"books","instId":"BTC-USDT"},"action":"update","data":[{"asks":[],"bids":[["104289","0","0","0"],["104286.9","0.13986505","0","5"],["104234","0.00002831","0","2"]],"ts":"1747170741701","checksum":1066049502,"seqId":54226512242,"prevSeqId":54226512236}]}
{"arg":{"channel":"books","instId":"BTC-USDT"},"action":"update","data":[{"asks":[["104450.4","0","0","0"],["104468.9","0.16102","0","1"]],"bids":[],"ts":"1747170742001","checksum":1066049502,"seqId":54226512248,"prevSeqId":54226512242}]}
{"arg":{"channel":"books","instId":"BTC-USDT"},"action":"update","data":[{"asks":[["104316.1","0.44682438","0","8"],["104319.8","0","0","0"],["104319.9","0","0","0"],["104322.6","0.02806011","0","1"],["104336.4","0","0","0"],["104337","0.13896945","0","1"],["104390.8","0","0","0"],["104391.3","0.00056666","0","1"],["104392.9","0","0","0"],["104406.4","6.20961784","0","1"],["104444","0","0","0"],["104444.6","0.00056666","0","1"],["104536.2","0.076","0","5"]],"bids":[["104316","1.00349919","0","19"],["104312.4","0.02576764","0","1"],["104311.3","0.00056666","0","1"],["104310.7","0","0","0"],["104304.7","0","0","0"],["104289","0.13897045","0","1"],["104286.9","0.00089399","0","4"],["104258","0.00056666","0","1"],["104257.5","0","0","0"],["104234","0","0","0"]],"ts":"1747170742101","checksum":-502684249,"seqId":54226512317,"prevSeqId":54226512248}]}
{"arg":{"channel":"books","instId":"BTC-USDT"},"action":"update","data":[{"asks":[["104323.8","0","0","0"],["104324.2","0.00479198","0","1"],["104336.4","0.13897001","0","1"],["104337","0","0","0"],["104367.8","0.77866876","0","1"],["104423","0.02401584","0","2"],["104423.1","0.01063498","0","2"]],"bids":[["104289","0.13897001","0","1"]],"ts":"1747170742201","checksum":-1983802403,"seqId":54226512345,"prevSeqId":54226512317}]}
{"arg":{"channel":"books","instId":"BTC-USDT"},"action":"update","data":[{"asks":[["104367.8","0.77879906","0","2"]],"bids":[["104316","1.00339919","0","18"],["104289","0","0","0"],["104288.6","0.13908126","0","3"],["104281","0.00074601","0","3"],["104234","0.00002831","0","2"]],"ts":"1747170742301","checksum":676597823,"seqId":54226512364,"prevSeqId":54226512345}]}
{"arg":{"channel":"books","instId":"BTC-USDT"},"action":"update","data":[{"asks":[["104333.2","0.00479206","0","1"],["104335","0","0","0"],["104336.4","0.13897048","0","1"],["104353.7","0.56120425","0","1"],["104356.7","0","0","0"],["104388","0","0","0"],["104392.9","6.20961784","0","1"],["104406.4","0","0","0"],["104423.1","0.01054312","0","1"],["104536.3","0.076","0","5"],["104536.4","0.00002296","0","1"]],"bids":[["104303.1","0.00006358","0","1"],["104301.6","0.00479206","0","1"],["104289","0.13897048","0","1"],["104288.6","0.00011027","0","2"],["104270","0.47121075","0","3"],["104266.1","0.00005665","0","1"],["104234.8","0.00061782","0","1"],["104234.3","0","0","0"],["104234","0","0","0"]],"ts":"1747170742401","checksum":676597823,"seqId":54226512394,"prevSeqId":54226512364}]}
{"arg":{"channel":"books","instId":"BTC-USDT"},"action":"update","data":[{"asks":[["104316.1","0.45002438","0","9"],["104319.8","0.02336485","0","1"],["104319.9","0.08087825","0","1"],["104322.6","0","0","0"],["104323.8","0.00479207","0","1"],["104324.2","0.01","0","1"],["104328.6","0","0","0"],["104332","0.00479206","0","1"],["104333.2","0","0","0"],["104334.4","0.13990259","0","2"],["104336.4","0","0","0"],["104353.7","0.90343644","0","2"],["104356.5","1.37460909","0","1"],["104387.9","2.50971548","0","1"],["104392.9","0","0","0"],["104396.3","6.20961784","0","1"],["104536.3","0","0","0"],["104536.4","0","0","0"]],"bids":[["104316","0.97822536","0","17"],["104314.1","0","0","0"],["104312.4","0","0","0"],["104306.1","0.2718564","0","1"],["104304","0.00027736","0","4"],["104302.3","0.00050557","0","2"],["104301.6","0","0","0"],["104300.2","0.00479206","0","1"],["104300.1","0.07885879","0","3"],["104289","0","0","0"],["104285.7","0.15085214","0","40"],["104280.4","0","0","0"],["104274.6","0.59297412","0","3"],["104270.7","1.38343611","0","1"],["104264.3","0.00001003","0","1"],["104262.2","0.04642577","0","2"],["104239.4","2.44318881","0","1"],["104234.3","0.00028121","0","5"],["104234","0.00002831","0","2"]],"ts":"1747170742501","checksum":2141643948,"seqId":54226512441,"prevSeqId":54226512394}]}
{"arg":{"channel":"books","instId":"BTC-USDT"},"action":"update","data":[{"asks":[["104332","0","0","0"],["104332.6","0.37387384","0","2"],["104344","0.002","0","2"],["104345","0.001","0","1"],["104346","0","0","0"],["104347","0","0","0"],["104367","0.33","0","6"],["104368","0.16499999","0","3"],["104369","0","0","0"],["104370","0.00028006","0","1"],["104423.1","0.01063463","0","2"],["104536.3","0.076","0","5"]],"bids":[["104300.7","0.00479206","0","1"],["104300.2","0","0","0"]],"ts":"1747170742601","checksum":2141643948,"seqId":54226512472,"prevSeqId":54226512441}]}
{"arg":{"channel":"books","instId":"BTC-USDT"},"action":"update","data":[{"asks":[["104319.3","0.00182925","0","1"],["104319.4","0.27636329","0","1"],["104319.5","0.36908178","0","1"],["104319.7","0.24","0","1"],["104319.9","0","0","0"],["104322.2","0.01917018","0","1"],["104323.8","0.00479216","0","1"],["104323.9","0.00045","0","1"],["104328","0","0","0"],["104332.6","0.36908178","0","1"],["104332.7","0.78346082","0","2"],["104344","0","0","0"],["104345","0","0","0"],["104346","0.002","0","2"],["104347","0.001","0","1"],["104367","0","0","0"],["104368","0.15999999","0","2"],["104369","0.24999999","0","5"],["104370","0.08528006","0","3"],["104386.1","0.234","0","1"],["104396.3","6.20137817","0","1"],["104536.1","0","0","0"],["104536.2","0","0","0"],["104536.3","0","0","0"]],"bids":[["104316","1.00339919","0","18"],["104314.1","0.05576412","0","1"],["104301.3","0.01979206","0","4"],["104300.7","0","0","0"]],"ts":"1747170742701","checksum":-1386630623,"seqId":54226512533,"prevSeqId":54226512472}]}
{"arg":{"channel":"books","instId":"BTC-USDT"},"action":"update","data":[{"asks":[],"bids":[["104316","1.00356919","0","19"],["104303.6","0.19242972","0","1"],["104302.5","0.77866876","0","1"],["104234.3","0","0","0"],["104234","0","0","0"]],"ts":"1747170742801","checksum":778117789,"seqId":54226512536,"prevSeqId":54226512533}]}
{"arg":{"channel":"books","instId":"BTC-USDT"},"action":"update","data":[{"asks":[],"bids":[["104306.1","0.53462593","0","2"]],"ts":"1747170742901","checksum":-1483356844,"seqId":54226512537,"prevSeqId":54226512536}]}
{"arg":{"channel":"books","instId":"BTC-USDT"},"action":"update","data":[{"asks":[["104332.7","0.77866876","0","1"],["104334.3","0.00479206","0","1"],["104516.6","0.00037885","0","1"],["104525.9","0","0","0"],["104535.8","0","0","0"]],"bids":[["104302.9","0.00480238","0","2"],["104301.3","0.015","0","3"]],"ts":"1747170743001","checksum":-1483356844,"seqId":54226512543,"prevSeqId":54226512537}]}
{"arg":{"channel":"books","instId":"BTC-USDT"},"action":"update","data":[{"asks":[["104316.1","0.44682438","0","8"],["104318.2","0.01","0","2"],["104319.3","0","0","0"],["104319.4","0","0","0"],["104319.7","0","0","0"],["104323.9","0.00227925","0","2"],["104330.7","0.01","0","2"],["104334.3","0","0","0"],["104334.4","0.00093","0","1"],["104336.3","0.13897135","0","1"],["104336.4","0.00479206","0","1"],["104444.5","0.00056666","0","1"],["104444.6","0","0","0"],["104535.8","0.77866876","0","1"],["104536.1","0.0152","0","1"]],"bids":[["104313.8","0.01019173","0","3"],["104311.3","0","0","0"],["104311.2","0.00056666","0","1"],["104310.7","0.02656985","0","1"],["104304","0.00506942","0","5"],["104302.9","0.00001032","0","1"],["104301.3","0.01","0","2"],["104286.9","0.13986674","0","5"],["104285.7","0.01187812","0","39"],["104234.4","0","0","0"]],"ts":"1747170743101","checksum":-599979996,"seqId":54226512582,"prevSeqId":54226512543}]}
{"arg":{"channel":"books","instId":"BTC-USDT"},"action":"update","data":[{"asks":[["104316.1","0.45002438","0","9"],["104318.2","0.015","0","3"],["104330.7","0.015","0","3"],["104335.1","0.49401567","0","3"],["104336.3","0","0","0"],["104374.3","0.04032221","0","2"],["104441.2","0.0579344","0","1"]],"bids":[["104316","1.00256919","0","18"],["104313.8","0.01519173","0","4"],["104301.3","0.015","0","3"]],"ts":"1747170743201","checksum":-1378984389,"seqId":54226512593,"prevSeqId":54226512582}]}
{"arg":{"channel":"books","instId":"BTC-USDT"},"action":"update","data":[{"asks":[["104332.5","0.00479206","0","1"],["104336.4","0","0","0"],["104392.9","6.20137817","0","1"],["104396.3","0","0","0"],["104423","0.01054345","0","1"],["104423.2","0","0","0"],["104500.3","0","0","0"],["104536.2","0.076","0","5"],["104536.3","0.076","0","5"]],"bids":[["104310.7","0","0","0"],["104304","0.00027736","0","4"],["104300.7","0.00479206","0","1"]],"ts":"1747170743301","checksum":-1747405651,"seqId":54226512606,"prevSeqId":54226512593}]}
{"arg":{"channel":"books","instId":"BTC-USDT"},"action":"update","data":[{"asks":[["104316.1","0.44582438","0","8"],["104332.5","0","0","0"],["104334.3","0.00479206","0","1"],["104335.1","0.35504395","0","2"],["104337","0.1389698","0","1"],["104392.9","0","0","0"],["104396.3","6.20137817","0","1"],["104422.4","0.1014372","0","9"],["104422.6","0.00095764","0","1"],["104499.8","0.00123217","0","1"],["104536.1","0","0","0"],["104536.2","0","0","0"],["104536.3","0","0","0"]],"bids":[["104302.4","0.17147453","0","2"],["104300.7","0","0","0"],["104289","0.13897046","0","1"],["104286.9","0.00089399","0","4"]],"ts":"1747170743401","checksum":-108621189,"seqId":54226512629,"prevSeqId":54226512606}]}
{"arg":{"channel":"books","instId":"BTC-USDT"},"action":"update","data":[{"asks":[["104423.1","0.01054312","0","1"]],"bids":[],"ts":"1747170743501","checksum":-108621189,"seqId":54226512632,"prevSeqId":54226512629}]}
{"arg":{"channel":"books","instId":"BTC-USDT"},"action":"update","data":[{"asks":[["104319.4","0.24","0","1"],["104332.5","0.00479206","0","1"],["104334.3","0","0","0"],["104535.8","0","0","0"]],"bids":[["104302.4","0.16668247","0","1"],["104300.7","0.00479206","0","1"],["104234.5","0","0","0"]],"ts":"1747170743601","checksum":295338839,"seqId":54226512637,"prevSeqId":54226512632}]}
{"arg":{"channel":"books","instId":"BTC-USDT"},"action":"update","data":[{"asks":[["104319.3","0.00182925","0","1"],["104323.8","0","0","0"],["104323.9","0.00524199","0","2"],["104336.4","0.13897106","0","1"],["104337","0","0","0"],["104423","0.0106349","0","2"]],"bids":[["104316","1.00239919","0","17"],["104289","0","0","0"],["104286.9","0.13986516","0","5"],["104234.5","0.00003076","0","2"]],"ts":"1747170743701","checksum":1924023578,"seqId":54226512658,"prevSeqId":54226512637}]}
{"arg":{"channel":"books","instId":"BTC-USDT"},"action":"update","data":[{"asks":[["104316.1","0.44902438","0","9"],["104334.4","0.13990267","0","2"],["104336.4","0","0","0"],["104535.8","0.77866876","0","1"]],"bids":[],"ts":"1747170743801","checksum":1386478487,"seqId":54226512661,"prevSeqId":54226512658}]}
{"arg":{"channel":"books","instId":"BTC-USDT"},"action":"update","data":[{"asks":[["104332.5","0","0","0"],["104334.3","0.00479206","0","1"]],"bids":[["104302.6","0.00484264","0","6"],["104300.7","0","0","0"],["104234.4","0.77963354","0","2"]],"ts":"1747170743901","checksum":1386478487,"seqId":54226512667,"prevSeqId":54226512661}]}
{"arg":{"channel":"books","instId":"BTC-USDT"},"action":"update","data":[{"asks":[["104368","0","0","0"],["104369","0.25999999","0","4"],["104370","0.20028005","0","5"],["104371","0.035","0","1"]],"bids":[],"ts":"1747170744001","checksum":1386478487,"seqId":54226512692,"prevSeqId":54226512667}]}
{"arg":{"channel":"books","instId":"BTC-USDT"},"action":"update","data":[{"asks":[["104323.8","0.00479199","0","1"],["104323.9","0.00045","0","1"],["104334.3","0","0","0"],["104334.4","0.00572206","0","2"],["104335.3","0.13897163","0","1"],["104368","0.16","0","2"],["104369","0.24999999","0","5"],["104370","0.08528006","0","3"],["104371","0","0","0"],["104391.3","0","0","0"],["104391.5","0.00056666","0","1"],["104444.5","0","0","0"],["104444.7","0.00057666","0","2"]],"bids":[["104311.4","0.00056666","0","1"],["104311.2","0","0","0"],["104302.9","0.00480238","0","2"],["104302.6","0.00005058","0","5"],["104258.1","0.19299638","0","2"],["104258","0","0","0"],["104234.3","0.00028121","0","5"]],"ts":"1747170744101","checksum":762251973,"seqId":54226512728,"prevSeqId":54226512692}]}
{"arg":{"channel":"books","instId":"BTC-USDT"},"action":"update","data":[{"asks":[["104334.3","0.00479206","0","1"],["104334.4","0.00093","0","1"],["104335","0.1389719","0","1"],["104335.3","0","0","0"],["104422.4","0.0879652","0","8"],["104422.6","0","0","0"],["104423","0.01054345","0","1"],["104499.8","0","0","0"],["104536.1","0.0152","0","1"]],"bids":[["104316","1.00254919","0","18"],["104302.9","0.00001032","0","1"],["104302.6","0.00484264","0","6"],["104286.9","0.13986589","0","5"]],"ts":"1747170744201","checksum":1988080766,"seqId":54226512770,"prevSeqId":54226512728}]}
{"arg":{"channel":"books","instId":"BTC-USDT"},"action":"update","data":[{"asks":[["104425.4","0.01347162","0","1"],["104425.6","0.00095761","0","1"],["104502.7","0.00123214","0","1"],["104535.6","0","0","0"],["104535.8","0","0","0"],["104536.1","0","0","0"]],"bids":[["104302.6","0.00005058","0","5"],["104302","0.00479206","0","1"],["104234.3","0","0","0"]],"ts":"1747170744301","checksum":1988080766,"seqId":54226512778,"prevSeqId":54226512770}]}
{"arg":{"channel":"books","instId":"BTC-USDT"},"action":"update","data":[{"asks":[["104335","0","0","0"],["104336.4","0.13897125","0","1"]],"bids":[["104302.6","0.00484264","0","6"],["104302","0","0","0"],["104286.9","0.13986601","0","5"],["104234.3","0.00028121","0","5"]],"ts":"1747170744401","checksum":1988080766,"seqId":54226512795,"prevSeqId":54226512778}]}
{"arg":{"channel":"books","instId":"BTC-USDT"},"action":"update","data":[{"asks":[["104319.2","0.00182925","0","1"],["104319.3","0.27636329","0","1"],["104336.4","0.13897136","0","1"],["104534.7","0","0","0"]],"bids":[["104302.6","0.00005058","0","5"],["104302.4","0.17147453","0","2"]],"ts":"1747170744501","checksum":1359065927,"seqId":54226512812,"prevSeqId":54226512795}]}
{"arg":{"channel":"books","instId":"BTC-USDT"},"action":"update","data":[{"asks":[["104316.1","0.68902438","0","10"],["104319.1","0.00182925","0","1"],["104319.2","0.24","0","1"],["104533.9","0","0","0"]],"bids":[["104286.9","0.13986535","0","5"]],"ts":"1747170744601","checksum":755693615,"seqId":54226512820,"prevSeqId":54226512812}]}
{"arg":{"channel":"books","instId":"BTC-USDT"},"action":"update","data":[{"asks":[["104332","0.00479206","0","1"],["104334.3","0","0","0"],["104334.4","0.13990289","0","2"],["104336.4","0","0","0"],["104533.9","0.03","0","1"]],"bids":[["104302.4","0.16668247","0","1"],["104300.2","0.00479206","0","1"],["104234.3","0","0","0"]],"ts":"1747170744701","checksum":755693615,"seqId":54226512826,"prevSeqId":54226512820}]}
{"arg":{"channel":"books","instId":"BTC-USDT"},"action":"update","data":[{"asks":[["104316.1","0.44902438","0","9"],["104334.4","0.00093","0","1"],["104335.3","0.13897162","0","1"],["104533.9","0","0","0"]],"bids":[],"ts":"1747170744801","checksum":-171529119,"seqId":54226512830,"prevSeqId":54226512826}]}
{"arg":{"channel":"books","instId":"BTC-USDT"},"action":"update","data":[{"asks":[["104316.1","0.44582438","0","8"],["104319.1","0","0","0"],["104319.2","0","0","0"],["104319.3","0","0","0"],["104319.4","0","0","0"],["104319.5","0","0","0"],["104323.9","0.00227925","0","2"],["104332","0","0","0"],["104332.5","0.00479206","0","1"],["104335.3","0","0","0"],["104336.4","0.1389711","0","1"],["104533.9","0.03","0","1"],["104534.7","0.00094804","0","1"],["104535.6","0.00002193","0","1"],["104535.8","0.77866876","0","1"],["104536.1","0.0152","0","1"]],"bids":[["104311.3","0.02816415","0","1"],["104310.6","0.0265172","0","1"],["104300.7","0.00479206","0","1"],["104300.2","0","0","0"],["104300.1","0.03239275","0","2"],["104234.5","0","0","0"],["104234.4","0","0","0"]],"ts":"1747170744901","checksum":-1903166476,"seqId":54226512850,"prevSeqId":54226512830}]}
{"arg":{"channel":"books","instId":"BTC-USDT"},"action":"update","data":[{"asks":[["104316.1","0.44902438","0","9"],["104319.9","0.08662931","0","1"],["104332","0.00479206","0","1"],["104332.5","0","0","0"],["104536.1","0","0","0"]],"bids":[["104300.7","0","0","0"],["104300.2","0.00479206","0","1"]],"ts":"1747170745001","checksum":958996830,"seqId":54226512857,"prevSeqId":54226512850}]}
{"arg":{"channel":"books","instId":"BTC-USDT"},"action":"update","data":[{"asks":[["104335.3","0.13897143","0","1"],["104336.4","0","0","0"],["104391.5","0","0","0"],["104391.6","0.00056666","0","1"],["104444.7","0.00001","0","1"],["104444.9","0.00056666","0","1"],["104535.8","0","0","0"]],"bids":[["104311.5","0.00056666","0","1"],["104311.4","0","0","0"],["104311.3","0","0","0"],["104310.6","0","0","0"],["104299.6","0.03908723","0","1"],["104286.9","0.13986542","0","5"],["104258.3","0.00056666","0","1"],["104258.1","0.19242972","0","1"]],"ts":"1747170745101","checksum":-294733821,"seqId":54226512878,"prevSeqId":54226512857}]}
{"arg":{"channel":"books","instId":"BTC-USDT"},"action":"update","data":[{"asks":[["104332","0","0","0"],["104334.3","0.00479206","0","1"],["104335","0.13897185","0","1"],["104335.3","0","0","0"],["104353.7","0.56120425","0","1"],["104356.5","0","0","0"],["104387.9","0","0","0"],["104392.9","6.19114518","0","1"],["104396.3","0","0","0"],["104535.8","0.77866876","0","1"],["104536.1","0.0152","0","1"]],"bids":[["104316","1.0025356","0","18"],["104302.6","0.00484264","0","6"],["104300.2","0","0","0"],["104286.9","0.13986584","0","5"],["104274.6","0.22464067","0","2"],["104270.7","0","0","0"],["104239.4","0","0","0"],["104234.5","0.00003076","0","2"],["104234.4","0.77963354","0","2"],["104234.3","0.00028121","0","5"]],"ts":"1747170745201","checksum":1499552073,"seqId":54226512914,"prevSeqId":54226512878}]}
{"arg":{"channel":"books","instId":"BTC-USDT"},"action":"update","data":[{"asks":[["104353.7","0.90001687","0","2"],["104356.6","1.36321053","0","1"],["104387.9","2.52633668","0","1"],["104392.9","0","0","0"],["104396.3","6.18375281","0","1"],["104535.8","0","0","0"],["104536.1","0","0","0"]],"bids":[["104270","0.80581393","0","4"],["104268.7","1.40976468","0","1"],["104237.5","2.58855393","0","1"],["104234.4","0","0","0"],["104234.3","0","0","0"]],"ts":"1747170745301","checksum":1499552073,"seqId":54226512923,"prevSeqId":54226512914}]}
{"arg":{"channel":"books","instId":"BTC-USDT"},"action":"update","data":[{"asks":[["104423.5","0.00009579","0","1"],["104535.6","0","0","0"]],"bids":[],"ts":"1747170745401","checksum":1499552073,"seqId":54226512928,"prevSeqId":54226512923}]}
{"arg":{"channel":"books","instId":"BTC-USDT"},"action":"update","data":[{"asks":[["104334.4","0.13990393","0","2"],["104335","0","0","0"],["104535.6","0.00002193","0","1"]],"bids":[["104286.9","0.00089399","0","4"],["104285.7","0.15085205","0","40"]],"ts":"1747170745501","checksum":1499552073,"seqId":54226512934,"prevSeqId":54226512928}]}
{"arg":{"channel":"books","instId":"BTC-USDT"},"action":"update","data":[{"asks":[["104392.9","6.18375281","0","1"],["104396.3","0","0","0"]],"bids":[["104316","1.00241514","0","18"]],"ts":"1747170745601","checksum":1539848671,"seqId":54226512940,"prevSeqId":54226512934}]}
{"arg":{"channel":"books","instId":"BTC-USDT"},"action":"update","data":[{"asks":[["104323.8","0","0","0"],["104325","0.00479206","0","1"],["104334.4","0.00093","0","1"],["104336.4","0.13897132","0","1"],["104345.9","0.0001303","0","1"],["104367.8","0.77866876","0","1"],["104392.9","0","0","0"],["104396.3","6.18375281","0","1"],["104534.7","0","0","0"],["104535.6","0","0","0"]],"bids":[["104316","1.00226514","0","17"],["104311.7","0.02816405","0","1"],["104299.6","0","0","0"],["104286.9","0.13986544","0","5"],["104285.7","0.01187812","0","39"],["104273.8","0","0","0"],["104250.9","0.00002967","0","1"]],"ts":"1747170745701","checksum":-966344788,"seqId":54226512969,"prevSeqId":54226512940}]}
{"arg":{"channel":"books","instId":"BTC-USDT"},"action":"update","data":[{"asks":[["104317.4","0.07298372","0","1"],["104325","0.00479205","0","1"],["104533.9","0","0","0"]],"bids":[["104316","1.00216892","0","17"]],"ts":"1747170745801","checksum":-1422821091,"seqId":54226512978,"prevSeqId":54226512969}]}
{"arg":{"channel":"books","instId":"BTC-USDT"},"action":"update","data":[{"asks":[["104392.9","6.18405497","0","1"],["104396.3","0","0","0"]],"bids":[],"ts":"1747170745901","checksum":-1422821091,"seqId":54226512983,"prevSeqId":54226512978}]}
{"arg":{"channel":"books","instId":"BTC-USDT"},"action":"update","data":[{"asks":[["104318.2","0.005","0","1"],["104330.7","0.005","0","1"],["104332.9","0.00484206","0","2"],["104334.3","0","0","0"],["104336.3","0.13897014","0","1"],["104336.4","0","0","0"],["104391.6","0","0","0"],["104391.7","0.00056666","0","1"],["104392.9","0","0","0"],["104396.3","6.18405497","0","1"],["104533.9","0.03","0","1"]],"bids":[["104313.8","0.00519173","0","2"],["104311.7","0.02873071","0","2"],["104311.5","0","0","0"],["104302.6","0.00005058","0","5"],["104301.4","0.00876613","0","4"],["104301.3","0.005","0","1"],["104289","0.13897014","0","1"],["104286.9","0.00089399","0","4"],["104258.5","0.00058164","0","2"],["104258.3","0","0","0"],["104234.4","0.77963354","0","2"]],"ts":"1747170746101","checksum":-2023423200,"seqId":54226513027,"prevSeqId":54226512983}]}
{"arg":{"channel":"books","instId":"BTC-USDT"},"action":"update","data":[{"asks":[["104318.2","0.01","0","2"],["104330.7","0.01","0","2"]],"bids":[["104316","1.02315892","0","18"],["104313.8","0.01019173","0","3"],["104310.6","0.02633029","0","1"],["104301.3","0.01","0","2"],["104234.4","0","0","0"]],"ts":"1747170746201","checksum":-783222075,"seqId":54226513035,"prevSeqId":54226513027}]}
{"arg":{"channel":"books","instId":"BTC-USDT"},"action":"update","data":[{"asks":[["104316.1","0.44582438","0","8"],["104317.4","0","0","0"],["104332.9","0.00005","0","1"],["104335","0.00479206","0","1"],["104336.3","0","0","0"],["104337","0.13896928","0","1"],["104368","0.15999998","0","2"]],"bids":[["104303.1","0.00485564","0","2"],["104301.4","0.00397407","0","3"],["104289.1","0.13896954","0","1"],["104289","0","0","0"]],"ts":"1747170746301","checksum":1822773758,"seqId":54226513101,"prevSeqId":54226513035}]}
{"arg":{"channel":"books","instId":"BTC-USDT"},"action":"update","data":[{"asks":[["104335","0","0","0"],["104335.1","0.35983601","0","3"],["104337","0.13896965","0","1"],["104368","0.15999999","0","2"],["104534.7","0.00094804","0","1"]],"bids":[["104310.6","0","0","0"],["104303.7","0.00479206","0","1"],["104303.1","0.00006358","0","1"],["104289.1","0","0","0"],["104289","0.13896965","0","1"]],"ts":"1747170746401","checksum":-273504596,"seqId":54226513163,"prevSeqId":54226513101}]}
{"arg":{"channel":"books","instId":"BTC-USDT"},"action":"update","data":[{"asks":[["104316.1","0.32632438","0","7"],["104324.4","0.03108988","0","1"],["104324.5","0.09991535","0","1"],["104325.1","0.07298372","0","1"],["104325.2","0.09754966","0","1"],["104326.1","0","0","0"],["104326.2","0.0973878","0","1"],["104326.6","0.234","0","1"],["104326.7","0.08810444","0","1"],["104329.5","0.51506042","0","3"],["104329.6","0.00479312","0","1"],["104329.7","0.15275787","0","2"],["104329.9","0","0","0"],["104330","0.24108706","0","4"],["104330.1","0.02517383","0","1"],["104330.2","0.16902094","0","1"],["104332.8","0","0","0"],["104332.9","0.15020633","0","2"],["104333","0.40037242","0","2"],["104333.3","0","0","0"],["104333.4","0.23227374","0","1"],["104335.1","0.11980206","0","2"],["104335.2","0.36781558","0","2"],["104335.4","0","0","0"],["104335.5","0.24184585","0","1"],["104337","0.13896989","0","1"],["104339.1","0.1780651","0","1"],["104339.2","0.23480004","0","1"],["104533.3","0","0","0"],["104533.9","0","0","0"],["104534.7","0","0","0"]],"bids":[["104306.1","0.53385432","0","2"],["104305.7","0.17858724","0","2"],["104305.6","0.00917734","0","1"],["104304.2","0.09324157","0","1"],["104304.1","0.000048","0","1"],["104303.5","0.1013528","0","5"],["104303.4","0","0","0"],["104302.5","0.94772617","0","2"],["104302.4","0","0","0"],["104302.2","0.14716283","0","2"],["104302.1","0","0","0"],["104301.5","0.29176596","0","2"],["104300.7","0.16641614","0","1"],["104300.6","0","0","0"],["104298.4","0.26632034","0","6"],["104298.3","0","0","0"],["104297.9","0.15519553","0","2"],["104297.8","0","0","0"],["104295.7","0.57841443","0","4"],["104295.6","0","0","0"],["104292.5","0.25769281","0","3"],["104292.4","0","0","0"],["104291.7","0.24867419","0","3"],["104291.6","0.00100678","0","2"],["104289","0.13896989","0","1"],["104234.4","0.77963354","0","2"],["104234.3","0.00028121","0","5"],["104234","0.00002831","0","2"],["104233.7","0.00003837","0","1"],["104233.3","0.00482005","0","1"]],"ts":"1747170746501","checksum":408604705,"seqId":54226513293,"prevSeqId":54226513163}]}
{"arg":{"channel":"books","instId":"BTC-USDT"},"action":"update","data":[{"asks":[["104319.7","0.24","0","1"],["104335","0.00479206","0","1"],["104335.1","0.11501","0","1"],["104344","0.002","0","2"],["104345","0.001","0","1"],["104346","0","0","0"],["104347","0","0","0"],["104367","0.33","0","6"],["104368","0.16499999","0","3"],["104369","0","0","0"],["104370","0.00028006","0","1"],["104531.4","0","0","0"],["104532","0","0","0"]],"bids":[["104303.7","0","0","0"],["104303.1","0.00485564","0","2"],["104233","0.00086083","0","2"]],"ts":"1747170746601","checksum":-2011574466,"seqId":54226513322,"prevSeqId":54226513293}]}
{"arg":{"channel":"books","instId":"BTC-USDT"},"action":"update","data":[{"asks":[["104335.5","0.28084585","0","2"],["104339.7","0.036","0","1"],["104530","0","0","0"]],"bids":[],"ts":"1747170746901","checksum":-2011574466,"seqId":54226513371,"prevSeqId":54226513322}]}
{"arg":{"channel":"books","instId":"BTC-USDT"},"action":"update","data":[{"asks":[["104319.7","0","0","0"],["104325.2","0","0","0"],["104330.2","0","0","0"],["104335.2","0.097949","0","1"],["104340.7","0","0","0"],["104344","0","0","0"],["104344.9","0","0","0"],["104345","0","0","0"],["104346","0.002","0","2"],["104347","0.001","0","1"],["104367","0.16","0","2"],["104368","0.07999999","0","1"],["104369","0.17","0","4"],["104370","0.08528006","0","3"],["104530","0.00028006","0","1"],["104531.4","0.00209352","0","1"],["104532","0.00001","0","1"],["104533.3","0.000173","0","1"]],"bids":[["104305.7","0.08758208","0","1"],["104300.7","0","0","0"],["104295.7","0.31996208","0","3"],["104232.9","0.00005458","0","1"]],"ts":"1747170747001","checksum":-546093409,"seqId":54226513406,"prevSeqId":54226513371}]}
{"arg":{"channel":"books","instId":"BTC-USDT"},"action":"update","data":[{"asks":[["104367","0","0","0"],["104368","0.15999999","0","2"],["104369","0.24999999","0","5"],["104388.8","0.00056666","0","1"],["104391.7","0","0","0"],["104392.9","6.18405497","0","1"],["104396.3","0","0","0"],["104440.1","0.00056666","0","1"],["104444.9","0","0","0"],["104533.9","0.03","0","1"]],"bids":[["104316","1.00216892","0","17"],["104260.4","0.0005783","0","2"],["104258.5","0.00001498","0","1"]],"ts":"1747170747101","checksum":36797778,"seqId":54226513455,"prevSeqId":54226513406}]}
{"arg":{"channel":"books","instId":"BTC-USDT"},"action":"update","data":[{"asks":[["104320.8","0.01","0","1"],["104324.2","0","0","0"]],"bids":[],"ts":"1747170747201","checksum":-1452159376,"seqId":54226513458,"prevSeqId":54226513455}]}
{"arg":{"channel":"books","instId":"BTC-USDT"},"action":"update","data":[{"asks":[["104344","0.002","0","2"],["104345","0.001","0","1"],["104346","0","0","0"],["104347","0","0","0"],["104367","0.33","0","6"],["104368","0.16499999","0","3"],["104369","0","0","0"],["104370","0.00028006","0","1"]],"bids":[],"ts":"1747170747401","checksum":-1452159376,"seqId":54226513482,"prevSeqId":54226513458}]}
{"arg":{"channel":"books","instId":"BTC-USDT"},"action":"update","data":[{"asks":[["104332.5","0.00479206","0","1"],["104335","0","0","0"],["104344","0","0","0"],["104345","0","0","0"],["104346","0.002","0","2"],["104347","0.001","0","1"],["104367","0","0","0"],["104368","0.15999999","0","2"],["104369","0.24999999","0","5"],["104370","0.08528006","0","3"]],"bids":[["104303.1","0.00006358","0","1"],["104300.2","0.00479206","0","1"],["104232.9","0","0","0"]],"ts":"1747170747501","checksum":-1452159376,"seqId":54226513509,"prevSeqId":54226513482}]}
{"arg":{"channel":"books","instId":"BTC-USDT"},"action":"update","data":[{"asks":[["104316.1","0.44582438","0","8"],["104319.8","0.26336485","0","2"],["104324.4","0.12958798","0","2"],["104324.5","0","0","0"],["104325","0.00479201","0","1"],["104326.1","0.09370065","0","1"],["104326.2","0","0","0"],["104326.6","0.32482086","0","2"],["104326.7","0","0","0"],["104329.6","0.15733188","0","2"],["104329.7","0.00001","0","1"],["104329.9","0.16843906","0","1"],["104330","0.08190006","0","3"],["104332.8","0.15891217","0","1"],["104332.9","0.00005","0","1"],["104333","0.41746764","0","2"],["104333.3","0.25117299","0","1"],["104333.4","0","0","0"],["104335.4","0.2457225","0","1"],["104335.5","0.039","0","1"],["104339.1","0.41480626","0","2"],["104339.2","0","0","0"],["104392.9","0","0","0"],["104396.3","6.17966579","0","1"]],"bids":[["104316","1.02447892","0","18"],["104306.1","0.5025787","0","2"],["104305.7","0","0","0"],["104305.6","0.10370701","0","2"],["104304.2","0","0","0"],["104304.1","0.09924713","0","2"],["104303.5","0.00035761","0","4"],["104303.4","0.09827111","0","1"],["104302.5","0.77866876","0","1"],["104302.4","0.15114663","0","1"],["104302.2","0.00003272","0","1"],["104302.1","0.14640497","0","1"],["104301.5","0.23839455","0","2"],["104298.4","0.00542256","0","5"],["104298.3","0.24307166","0","1"],["104297.9","0.00026259","0","1"],["104297.8","0.15647842","0","1"],["104295.7","0.31726599","0","3"],["104292.5","0.00002543","0","2"],["104292.4","0.24335288","0","1"],["104291.7","0.00009425","0","2"],["104291.6","0.25491424","0","3"],["104234","0","0","0"],["104233.7","0","0","0"],["104233.3","0","0","0"],["104233","0","0","0"]],"ts":"1747170747601","checksum":1670088322,"seqId":54226513566,"prevSeqId":54226513509}]}
{"arg":{"channel":"books","instId":"BTC-USDT"},"action":"update","data":[{"asks":[["104316.1","0.44902438","0","9"],["104324.2","0.00479204","0","1"],["104325","0","0","0"],["104336.4","0.13897034","0","1"],["104337","0","0","0"]],"bids":[["104311.7","0.00056666","0","1"],["104299.7","0.04115917","0","1"],["104289","0","0","0"],["104286.9","0.1398651","0","5"]],"ts":"1747170747701","checksum":890454552,"seqId":54226513593,"prevSeqId":54226513566}]}
{"arg":{"channel":"books","instId":"BTC-USDT"},"action":"update","data":[{"asks":[["104318.2","0.04339525","0","3"],["104326.4","0","0","0"],["104332","0.00479206","0","1"],["104332.5","0","0","0"],["104344","0.002","0","2"],["104345","0.001","0","1"],["104346","0","0","0"],["104347","0","0","0"],["104367","0.33","0","6"],["104368","0.16499999","0","3"],["104369","0","0","0"],["104370","0.00028006","0","1"],["104534.7","0.00094804","0","1"]],"bids":[["104300.2","0","0","0"],["104300.1","0.03718481","0","3"],["104250.9","0","0","0"],["104234","0.00002831","0","2"],["104233.7","0.00003837","0","1"]],"ts":"1747170747801","checksum":1792145744,"seqId":54226513630,"prevSeqId":54226513593}]}
{"arg":{"channel":"books","instId":"BTC-USDT"},"action":"update","data":[{"asks":[["104344","0","0","0"],["104345","0","0","0"],["104346","0.002","0","2"],["104347","0.001","0","1"],["104367","0","0","0"],["104368","0.15999999","0","2"],["104369","0.24999999","0","5"],["104370","0.08528006","0","3"]],"bids":[["104250.9","0.00002967","0","1"],["104233.7","0","0","0"]],"ts":"1747170747901","checksum":1792145744,"seqId":54226513656,"prevSeqId":54226513630}]}
{"arg":{"channel":"books","instId":"BTC-USDT"},"action":"update","data":[{"asks":[["104353.7","0.56120425","0","1"],["104356.6","0","0","0"],["104387.9","0","0","0"],["104392.9","6.17966579","0","1"],["104396.3","0","0","0"],["104535.6","0.00002193","0","1"],["104535.8","0.77866876","0","1"]],"bids":[["104270","0.47121075","0","3"],["104268.7","0","0","0"],["104250.9","0","0","0"],["104237.5","0","0","0"],["104233.7","0.00003837","0","1"],["104233.3","0.00482005","0","1"],["104233","0.00086083","0","2"]],"ts":"1747170748001","checksum":1792145744,"seqId":54226513668,"prevSeqId":54226513656}]}
{"arg":{"channel":"books","instId":"BTC-USDT"},"action":"update","data":[{"asks":[["104325.1","0.16649296","0","2"],["104330.1","0.17347119","0","2"],["104335.1","0.38090993","0","2"],["104345.9","0","0","0"],["104346.3","0.0001303","0","1"],["104353.7","0.91325659","0","2"],["104356.5","1.40734293","0","1"],["104387.8","2.54029811","0","1"],["104388.8","0","0","0"],["104388.9","0.00056666","0","1"],["104440.1","0","0","0"],["104440.2","0.00056666","0","1"],["104535.6","0","0","0"],["104535.8","0","0","0"]],"bids":[["104311.8","0.00056666","0","1"],["104311.7","0","0","0"],["104305.6","0.19956548","0","3"],["104300.6","0.15184018","0","1"],["104300.2","0.00479206","0","1"],["104300.1","0.03239275","0","2"],["104295.6","0.24201778","0","1"],["104288.6","0.13908126","0","3"],["104286.9","0.00089399","0","4"],["104270","0.80463726","0","4"],["104268.7","1.40584244","0","1"],["104260.5","0.00056666","0","1"],["104260.4","0.00001164","0","1"],["104250.9","0.00002967","0","1"],["104237.5","2.52478887","0","1"],["104234.5","0","0","0"],["104234.4","0","0","0"],["104234.3","0","0","0"],["104234","0","0","0"],["104233.7","0","0","0"],["104233.3","0","0","0"],["104233","0","0","0"]],"ts":"1747170748101","checksum":-743968241,"seqId":54226513697,"prevSeqId":54226513668}]}
{"arg":{"channel":"books","instId":"BTC-USDT"},"action":"update","data":[{"asks":[["104324.2","0.00479207","0","1"],["104335","0.036","0","1"],["104336.3","0.13897103","0","1"],["104336.4","0","0","0"],["104339.2","0.093","0","3"],["104344.4","0.063","0","2"],["104392.9","0","0","0"],["104396.3","6.16591364","0","1"],["104533.9","0","0","0"],["104534.7","0","0","0"]],"bids":[["104288.6","0.1390813","0","3"]],"ts":"1747170748201","checksum":-255381777,"seqId":54226513719,"prevSeqId":54226513697}]}
{"arg":{"channel":"books","instId":"BTC-USDT"},"action":"update","data":[{"asks":[["104319.5","0.00182925","0","1"],["104319.6","0.36908178","0","1"],["104319.7","0.16863876","0","1"],["104319.9","0","0","0"],["104323.9","0.00524207","0","2"],["104324.2","0","0","0"],["104335.3","0.13897138","0","1"],["104336.3","0","0","0"],["104340.2","0","0","0"],["104344.4","0","0","0"],["104533.9","0.03","0","1"]],"bids":[["104316","0.99930509","0","17"],["104300.2","0","0","0"],["104300.1","0.03718481","0","3"],["104288.6","0.00011027","0","2"],["104286.9","0.13986522","0","5"],["104253","0.03","0","1"]],"ts":"1747170748301","checksum":-175795099,"seqId":54226513789,"prevSeqId":54226513719}]}
{"arg":{"channel":"books","instId":"BTC-USDT"},"action":"update","data":[{"asks":[["104323.9","0.00045","0","1"],["104324.2","0.00479215","0","1"],["104533.9","0","0","0"]],"bids":[["104316","1.02447892","0","18"]],"ts":"1747170748401","checksum":1130919132,"seqId":54226513836,"prevSeqId":54226513789}]}
{"arg":{"channel":"books","instId":"BTC-USDT"},"action":"update","data":[{"asks":[["104323.8","0.00479209","0","1"],["104324.2","0","0","0"],["104331.4","0.00479206","0","1"],["104332","0","0","0"],["104334.9","0.13897201","0","1"],["104335.3","0","0","0"]],"bids":[["104300.1","0.03239275","0","2"],["104300","0.04629951","0","42"]],"ts":"1747170748501","checksum":1990549483,"seqId":54226513848,"prevSeqId":54226513836}]}
{"arg":{"channel":"books","instId":"BTC-USDT"},"action":"update","data":[{"asks":[["104319.4","0.00182925","0","1"],["104319.5","0.24","0","1"],["104319.7","0.09663876","0","1"],["104319.8","0.02336485","0","1"],["104323.8","0","0","0"],["104324.2","0.00479209","0","1"],["104331.4","0","0","0"],["104332","0.00479206","0","1"],["104334.9","0","0","0"],["104336.4","0.13897112","0","1"],["104533.3","0","0","0"]],"bids":[["104316","1.00216892","0","17"],["104300.2","0.00479206","0","1"],["104300","0.04150745","0","41"],["104286.9","0.13986507","0","5"],["104234.6","0","0","0"]],"ts":"1747170748601","checksum":1182502859,"seqId":54226513869,"prevSeqId":54226513848}]}
{"arg":{"channel":"books","instId":"BTC-USDT"},"action":"update","data":[{"asks":[["104318.3","0.07498372","0","2"],["104332","0","0","0"],["104334.3","0.00479206","0","1"]],"bids":[["104302.6","0.00484264","0","6"],["104300.2","0","0","0"],["104289","0.13896994","0","1"],["104286.9","0.00089399","0","4"]],"ts":"1747170748801","checksum":-1901180649,"seqId":54226513881,"prevSeqId":54226513869}]}
{"arg":{"channel":"books","instId":"BTC-USDT"},"action":"update","data":[{"asks":[["104335.3","0.13897158","0","1"],["104336.4","0","0","0"]],"bids":[["104289","0","0","0"],["104286.9","0.13986557","0","5"],["104234.6","0.00199229","0","3"]],"ts":"1747170748901","checksum":-1901180649,"seqId":54226513885,"prevSeqId":54226513881}]}
{"arg":{"channel":"books","instId":"BTC-USDT"},"action":"update","data":[{"asks":[["104332.5","0.00479206","0","1"],["104334.3","0","0","0"],["104345.9","0.0001303","0","1"],["104346.3","0","0","0"],["104387.3","0.00056666","0","1"],["104388.9","0","0","0"],["104437.4","0.00056666","0","1"],["104440.2","0","0","0"]],"bids":[["104316","1.02447892","0","18"],["104311.9","0.00056666","0","1"],["104311.8","0","0","0"],["104302.6","0.00005058","0","5"],["104300.7","0.00479206","0","1"],["104261.8","0.00056666","0","1"],["104260.5","0","0","0"],["104234.6","0","0","0"]],"ts":"1747170749101","checksum":1847213617,"seqId":54226513904,"prevSeqId":54226513885}]}
{"arg":{"channel":"books","instId":"BTC-USDT"},"action":"update","data":[{"asks":[["104335.3","0","0","0"],["104336.4","0.13897121","0","1"],["104425.4","0","0","0"],["104425.6","0","0","0"],["104502.7","0","0","0"],["104533.3","0.000173","0","1"],["104533.9","0.03","0","1"],["104534.7","0.00094804","0","1"]],"bids":[],"ts":"1747170749201","checksum":1847213617,"seqId":54226513912,"prevSeqId":54226513904}]}
{"arg":{"channel":"books","instId":"BTC-USDT"},"action":"update","data":[{"asks":[["104336.4","0.13897123","0","1"]],"bids":[],"ts":"1747170749301","checksum":1847213617,"seqId":54226513924,"prevSeqId":54226513912}]}
{"arg":{"channel":"books","instId":"BTC-USDT"},"action":"update","data":[{"asks":[["104392.9","6.17349876","0","1"],["104396.3","0","0","0"]],"bids":[["104287","0.13897116","0","1"],["104286.9","0.00089399","0","4"],["104234.8","0","0","0"]],"ts":"1747170749401","checksum":1847213617,"seqId":54226513930,"prevSeqId":54226513924}]}
{"arg":{"channel":"books","instId":"BTC-USDT"},"action":"update","data":[{"asks":[["104332","0.00479206","0","1"],["104332.5","0","0","0"]],"bids":[["104300.7","0","0","0"],["104300.2","0.00479206","0","1"]],"ts":"1747170749501","checksum":1847213617,"seqId":54226513934,"prevSeqId":54226513930}]}
{"arg":{"channel":"books","instId":"BTC-USDT"},"action":"update","data":[{"asks":[["104316.1","0.60402438","0","10"],["104318","0.0816","0","1"],["104319.3","0.00182925","0","1"],["104319.4","0.27936329","0","1"],["104319.7","0","0","0"],["104323.8","0.00479209","0","1"],["104324.2","0","0","0"],["104329.7","0.00480206","0","2"],["104332","0","0","0"],["104334.4","0.13990274","0","2"],["104336.4","0","0","0"],["104392.9","0","0","0"],["104396.3","6.17349876","0","1"],["104535.6","0.00002193","0","1"]],"bids":[["104316","0.86960509","0","19"],["104314.1","0","0","0"],["104310.1","0","0","0"],["104306.1","0.2718564","0","1"],["104302.5","0","0","0"],["104301.9","0.00120818","0","1"],["104300.2","0","0","0"],["104297.9","0.00505465","0","2"],["104287","0","0","0"],["104286.9","0.13986673","0","5"],["104270","0.47121075","0","3"],["104268.7","0","0","0"],["104237.5","0","0","0"],["104234.8","0.00061782","0","1"],["104234.6","0.00199229","0","3"],["104234.5","0.00003076","0","2"],["104234.4","0.77963354","0","2"],["104234.3","0.00028121","0","5"],["104234","0.00002831","0","2"],["104233.7","0.00003837","0","1"]],"ts":"1747170749601","checksum":-218268035,"seqId":54226513973,"prevSeqId":54226513934}]}
{"arg":{"channel":"books","instId":"BTC-USDT"},"action":"update","data":[{"asks":[["104321.9","0.00479217","0","1"],["104323.8","0","0","0"],["104329.7","0.00001","0","1"],["104332.7","0.78346082","0","2"],["104344","0.002","0","2"],["104345","0.001","0","1"],["104346","0","0","0"],["104347","0","0","0"],["104367","0.16","0","2"],["104368","0.07999999","0","1"],["104369","0.17","0","4"],["104392.9","6.17349876","0","1"],["104396.3","0","0","0"],["104421.3","0.01347261","0","1"],["104421.5","0.01525765","0","2"],["104498.7","0.00123218","0","1"],["104533.9","0","0","0"],["104534.7","0","0","0"],["104535.6","0","0","0"]],"bids":[["104314.1","0.05426412","0","1"],["104310.1","0.08476448","0","1"],["104303.6","0","0","0"],["104301.3","0.01479206","0","3"],["104297.9","0.00026259","0","1"],["104286.9","0.00089399","0","4"],["104285.7","0.15085203","0","40"],["104233.7","0","0","0"]],"ts":"1747170749701","checksum":-964194393,"seqId":54226514061,"prevSeqId":54226513973}]}
{"arg":{"channel":"books","instId":"BTC-USDT"},"action":"update","data":[{"asks":[["104321.9","0","0","0"],["104323.8","0.00479216","0","1"],["104344","0","0","0"],["104345","0","0","0"],["104346","0.002","0","2"],["104347","0.001","0","1"],["104367","0","0","0"],["104368","0.15999999","0","2"],["104369","0.24999999","0","5"],["104533.9","0.03","0","1"]],"bids":[["104303.6","0.19242972","0","1"],["104285.8","0.22389464","0","2"],["104283.5","0.00001212","0","1"],["104268.6","1.40269507","0","1"],["104237.3","2.53541875","0","2"],["104234.3","0","0","0"],["104234","0","0","0"]],"ts":"1747170749801","checksum":-1963288184,"seqId":54226514105,"prevSeqId":54226514061}]}
{"arg":{"channel":"books","instId":"BTC-USDT"},"action":"update","data":[{"asks":[["104332.7","0.77866876","0","1"],["104334.3","0.00479206","0","1"],["104334.4","0.00093","0","1"],["104336.4","0.13897024","0","1"],["104533.3","0","0","0"],["104533.9","0","0","0"]],"bids":[["104316","0.89477892","0","20"],["104306.1","0.50944113","0","2"],["104302","0.00479206","0","1"],["104301.6","0.77866876","0","1"],["104301.3","0.01","0","2"],["104289","0.13897024","0","1"],["104285.7","0.01187812","0","39"],["104234.6","0","0","0"],["104234.5","0","0","0"],["104234.4","0","0","0"]],"ts":"1747170749901","checksum":-304788311,"seqId":54226514126,"prevSeqId":54226514105}]}
{"arg":{"channel":"books","instId":"BTC-USDT"},"action":"update","data":[{"asks":[["104336.4","0.13897123","0","1"],["104392.9","0","0","0"],["104396.3","6.17849734","0","1"]],"bids":[["104289","0","0","0"],["104286.9","0.13986545","0","5"],["104234.6","0.00199229","0","3"]],"ts":"1747170750001","checksum":-304788311,"seqId":54226514139,"prevSeqId":54226514126}]}
{"arg":{"channel":"books","instId":"BTC-USDT"},"action":"update","data":[{"asks":[["104336.4","0","0","0"],["104337","0.13896946","0","1"]],"bids":[["104316","0.87246892","0","19"],["104312","0.08216666","0","2"],["104311.9","0","0","0"],["104302.2","0.00482478","0","2"],["104302","0","0","0"],["104289","0.13896946","0","1"],["104286.9","0.00089399","0","4"],["104261.9","0.00056666","0","1"],["104261.8","0","0","0"],["104250.9","0","0","0"],["104234.5","0.00003076","0","2"],["104234.4","0.77963354","0","2"]],"ts":"1747170750101","checksum":1087697507,"seqId":54226514160,"prevSeqId":54226514139}]}
{"arg":{"channel":"books","instId":"BTC-USDT"},"action":"update","data":[{"asks":[["104323.8","0.00479211","0","1"],["104335.4","0.3846938","0","2"],["104337","0","0","0"],["104533.3","0.000173","0","1"]],"bids":[["104302.2","0.00003272","0","1"],["104302","0.00479206","0","1"],["104289","0","0","0"],["104286.9","0.13986508","0","5"]],"ts":"1747170750201","checksum":1754267466,"seqId":54226514180,"prevSeqId":54226514160}]}
{"arg":{"channel":"books","instId":"BTC-USDT"},"action":"update","data":[{"asks":[["104318.3","0.07298372","0","1"],["104330.8","0","0","0"],["104335.4","0.2457225","0","1"],["104336.4","0.13897105","0","1"]],"bids":[["104313.7","0","0","0"],["104301.2","0.05214032","0","5"],["104286.9","0.13986504","0","5"],["104250.9","0.00002967","0","1"]],"ts":"1747170750301","checksum":-942527709,"seqId":54226514197,"prevSeqId":54226514180}]}
{"arg":{"channel":"books","instId":"BTC-USDT"},"action":"update","data":[{"asks":[["104323.8","0.0047921","0","1"],["104392.9","6.17849734","0","1"],["104396.3","0","0","0"]],"bids":[["104250.9","0","0","0"],["104234.3","0.00028121","0","5"]],"ts":"1747170750401","checksum":418364580,"seqId":54226514206,"prevSeqId":54226514197}]}
{"arg":{"channel":"books","instId":"BTC-USDT"},"action":"update","data":[{"asks":[["104316.1","0.60385348","0","10"],["104334.4","0.13990265","0","2"],["104336.4","0","0","0"],["104533.9","0.03","0","1"]],"bids":[["104250.9","0.00002967","0","1"],["104234.3","0","0","0"]],"ts":"1747170750501","checksum":1320076346,"seqId":54226514212,"prevSeqId":54226514206}]}
{"arg":{"channel":"books","instId":"BTC-USDT"},"action":"update","data":[{"asks":[["104316.1","0.84385348","0","11"],["104344","0.002","0","2"],["104345","0.001","0","1"],["104346","0","0","0"],["104347","0","0","0"],["104367","0.33","0","6"],["104368","0.16499999","0","3"],["104369","0","0","0"],["104370","0.00028006","0","1"]],"bids":[["104316","0.89477892","0","20"],["104302","0","0","0"],["104301.7","0.00479206","0","1"]],"ts":"1747170750601","checksum":1373227340,"seqId":54226514256,"prevSeqId":54226514212}]}
{"arg":{"channel":"books","instId":"BTC-USDT"},"action":"update","data":[{"asks":[["104316.1","0.60385348","0","10"],["104332","0.00479206","0","1"],["104334.3","0","0","0"],["104334.4","0.00093","0","1"],["104336.4","0.13897121","0","1"],["104353.7","0.56120425","0","1"],["104356.5","0","0","0"],["104387.8","0","0","0"],["104534.7","0.00094804","0","1"]],"bids":[["104301.7","0","0","0"],["104300.2","0.00479206","0","1"],["104268.6","0","0","0"],["104237.3","0.00001","0","1"],["104234.3","0.00028121","0","5"]],"ts":"1747170750701","checksum":891495992,"seqId":54226514277,"prevSeqId":54226514256}]}
{"arg":{"channel":"books","instId":"BTC-USDT"},"action":"update","data":[{"asks":[["104345.9","0","0","0"],["104346.3","0.0001303","0","1"],["104353.7","0.89878216","0","2"],["104356.5","1.35909483","0","1"],["104387.8","2.37683716","0","1"],["104533.9","0","0","0"],["104534.7","0","0","0"]],"bids":[["104268.6","1.40685129","0","1"],["104237.3","2.47807821","0","2"],["104234.3","0","0","0"]],"ts":"1747170750801","checksum":891495992,"seqId":54226514285,"prevSeqId":54226514277}]}
{"arg":{"channel":"books","instId":"BTC-USDT"},"action":"update","data":[{"asks":[["104316.1","0.60065348","0","9"]],"bids":[],"ts":"1747170750901","checksum":498734439,"seqId":54226514286,"prevSeqId":54226514285}]}
{"arg":{"channel":"books","instId":"BTC-USDT"},"action":"update","data":[{"asks":[["104318.3","0.07498372","0","2"],["104330.8","0.002","0","1"],["104533.3","0","0","0"]],"bids":[["104313.7","0.002","0","1"],["104301.2","0.05414032","0","6"],["104234.4","0","0","0"]],"ts":"1747170751001","checksum":-1855842999,"seqId":54226514291,"prevSeqId":54226514286}]}
{"arg":{"channel":"books","instId":"BTC-USDT"},"action":"update","data":[{"asks":[["104344","0","0","0"],["104345","0","0","0"],["104346","0.002","0","2"],["104347","0.001","0","1"],["104367","0.23","0","4"],["104368","0.11499999","0","2"],["104369","0.1","0","2"],["104370","0.05028006","0","2"],["104387.3","0","0","0"],["104387.5","0.00056666","0","1"],["104437.4","0","0","0"],["104437.6","0.00056666","0","1"],["104532","0","0","0"]],"bids":[["104312.1","0.00056666","0","1"],["104312","0.0816","0","1"],["104287.2","0.13897106","0","1"],["104286.9","0.00089399","0","4"],["104270","0.80493991","0","4"],["104262","0.48381153","0","2"],["104261.9","0","0","0"],["104234.5","0","0","0"]],"ts":"1747170751101","checksum":-2007409743,"seqId":54226514357,"prevSeqId":54226514291}]}
{"arg":{"channel":"books","instId":"BTC-USDT"},"action":"update","data":[{"asks":[["104344","0.002","0","2"],["104345","0.001","0","1"],["104346","0","0","0"],["104347","0","0","0"],["104367","0.33","0","6"],["104368","0.16499999","0","3"],["104369","0","0","0"],["104370","0.00028006","0","1"],["104532","0.00001","0","1"]],"bids":[],"ts":"1747170751201","checksum":-2007409743,"seqId":54226514369,"prevSeqId":54226514357}]}
{"arg":{"channel":"books","instId":"BTC-USDT"},"action":"update","data":[{"asks":[["104332","0","0","0"],["104334.3","0.00479206","0","1"],["104335.3","0.13897147","0","1"],["104336.4","0","0","0"]],"bids":[["104316","0.87246892","0","19"],["104302.5","0.00479206","0","1"],["104300.2","0","0","0"],["104287.2","0","0","0"],["104286.9","0.13986546","0","5"],["104234.5","0.00003076","0","2"]],"ts":"1747170751501","checksum":-1803869679,"seqId":54226514388,"prevSeqId":54226514369}]}
{"arg":{"channel":"books","instId":"BTC-USDT"},"action":"update","data":[{"asks":[["104318.3","0.002","0","1"],["104335.3","0","0","0"],["104336.4","0.13897117","0","1"],["104346.3","0","0","0"],["104533.3","0.000173","0","1"]],"bids":[["104261.8","0.414048","0","1"],["104254.6","0.00349257","0","7"],["104234.5","0","0","0"]],"ts":"1747170751601","checksum":1741170920,"seqId":54226514396,"prevSeqId":54226514388}]}
{"arg":{"channel":"books","instId":"BTC-USDT"},"action":"update","data":[{"asks":[["104346.3","0.0001303","0","1"],["104533.3","0","0","0"]],"bids":[["104302.5","0","0","0"],["104302","0.00479206","0","1"]],"ts":"1747170751701","checksum":1741170920,"seqId":54226514404,"prevSeqId":54226514396}]}
{"arg":{"channel":"books","instId":"BTC-USDT"},"action":"update","data":[{"asks":[["104346.3","0","0","0"],["104533.3","0.000173","0","1"]],"bids":[],"ts":"1747170751801","checksum":1741170920,"seqId":54226514408,"prevSeqId":54226514404}]}
{"arg":{"channel":"books","instId":"BTC-USDT"},"action":"update","data":[{"asks":[["104346.3","0.0001303","0","1"],["104533.3","0","0","0"]],"bids":[["104263.8","0.00048931","0","2"]],"ts":"1747170751901","checksum":1741170920,"seqId":54226514412,"prevSeqId":54226514408}]}
{"arg":{"channel":"books","instId":"BTC-USDT"},"action":"update","data":[{"asks":[["104317.4","0.01","0","1"],["104320.8","0","0","0"],["104344","0","0","0"],["104345","0","0","0"],["104346","0.002","0","2"],["104347","0.001","0","1"],["104367","0","0","0"],["104368","0.15999999","0","2"],["104369","0.24999999","0","5"],["104370","0.08528006","0","3"]],"bids":[["104316","0.89477892","0","20"]],"ts":"1747170752001","checksum":-1677989675,"seqId":54226514438,"prevSeqId":54226514412}]}
{"arg":{"channel":"books","instId":"BTC-USDT"},"action":"update","data":[{"asks":[["104335.4","0.38469384","0","2"],["104336.4","0","0","0"],["104377.6","0.00056666","0","1"],["104387.5","0","0","0"],["104421.4","0.00056666","0","1"],["104437.6","0","0","0"],["104533.3","0.000173","0","1"]],"bids":[["104312.1","0","0","0"],["104311.7","0.00056666","0","1"],["104302.5","0.00479206","0","1"],["104302","0","0","0"],["104267.9","0.17863176","0","2"],["104262","0.48324487","0","1"]],"ts":"1747170752101","checksum":448166226,"seqId":54226514457,"prevSeqId":54226514438}]}
{"arg":{"channel":"books","instId":"BTC-USDT"},"action":"update","data":[{"asks":[["104335.4","0.2457225","0","1"],["104336.4","0.1389706","0","1"],["104345.9","0.0001303","0","1"],["104346.3","0","0","0"],["104533.3","0","0","0"]],"bids":[["104316","0.87527892","0","19"],["104302.5","0","0","0"],["104302.4","0.15593869","0","2"],["104288.6","0.13908087","0","3"],["104286.9","0.00089399","0","4"],["104234.5","0.00003076","0","2"]],"ts":"1747170752201","checksum":-719516882,"seqId":54226514487,"prevSeqId":54226514457}]}
{"arg":{"channel":"books","instId":"BTC-USDT"},"action":"update","data":[{"asks":[["104334.9","0.13897197","0","1"],["104336.4","0","0","0"]],"bids":[["104310.6","0.0262908","0","1"],["104288.6","0.00011027","0","2"],["104286.9","0.13986596","0","5"],["104234.5","0","0","0"]],"ts":"1747170752301","checksum":-1723587733,"seqId":54226514492,"prevSeqId":54226514487}]}
{"arg":{"channel":"books","instId":"BTC-USDT"},"action":"update","data":[{"asks":[["104318.3","0.07498372","0","2"],["104332","0.00479206","0","1"],["104334.3","0","0","0"],["104334.9","0","0","0"],["104336.4","0.13897023","0","1"]],"bids":[["104302.4","0.15114663","0","1"],["104300.2","0.00479206","0","1"],["104289","0.13897023","0","1"],["104286.9","0.00089399","0","4"],["104234.8","0","0","0"],["104234.6","0","0","0"]],"ts":"1747170752401","checksum":-1375808784,"seqId":54226514551,"prevSeqId":54226514492}]}
{"arg":{"channel":"books","instId":"BTC-USDT"},"action":"update","data":[{"asks":[["104316.1","0.84065348","0","10"],["104335.3","0.13897157","0","1"],["104336.4","0","0","0"],["104440.6","0","0","0"],["104451","0","0","0"],["104533.3","0.000173","0","1"],["104533.9","0.03","0","1"]],"bids":[["104316","0.86976892","0","19"],["104289","0","0","0"],["104287","0.13897157","0","1"]],"ts":"1747170752501","checksum":1962311239,"seqId":54226514565,"prevSeqId":54226514551}]}
{"arg":{"channel":"books","instId":"BTC-USDT"},"action":"update","data":[{"asks":[["104392.9","6.19966924","0","1"]],"bids":[],"ts":"1747170752601","checksum":1962311239,"seqId":54226514567,"prevSeqId":54226514565}]}
{"arg":{"channel":"books","instId":"BTC-USDT"},"action":"update","data":[{"asks":[],"bids":[["104250.9","0","0","0"],["104234.8","0.00061782","0","1"]],"ts":"1747170752701","checksum":1962311239,"seqId":54226514569,"prevSeqId":54226514567}]}
{"arg":{"channel":"books","instId":"BTC-USDT"},"action":"update","data":[{"asks":[["104331.3","0.00479206","0","1"],["104332","0","0","0"]],"bids":[["104316","0.84716892","0","16"],["104300.2","0","0","0"],["104298.5","0.00479206","0","1"],["104250.9","0.00002967","0","1"],["104234.8","0","0","0"]],"ts":"1747170752801","checksum":-975240031,"seqId":54226514582,"prevSeqId":54226514569}]}
{"arg":{"channel":"books","instId":"BTC-USDT"},"action":"update","data":[{"asks":[["104316.1","0.60065348","0","9"],["104331.3","0","0","0"],["104332.5","0.00479206","0","1"],["104334.9","0.13897203","0","1"],["104335.3","0","0","0"],["104440.6","0.0013452","0","1"],["104451","0.0026904","0","1"],["104490","0.00028006","0","1"],["104533.3","0","0","0"],["104533.9","0","0","0"]],"bids":[["104300.7","0.00479206","0","1"],["104298.5","0","0","0"],["104287","0","0","0"],["104286.9","0.13986602","0","5"],["104250.9","0","0","0"],["104234.8","0.00061782","0","1"],["104234.6","0.00199229","0","3"]],"ts":"1747170752901","checksum":-1656576371,"seqId":54226514605,"prevSeqId":54226514582}]}
{"arg":{"channel":"books","instId":"BTC-USDT"},"action":"update","data":[{"asks":[["104332.5","0","0","0"],["104333","0.4222597","0","3"],["104334.9","0","0","0"],["104336.4","0.13897116","0","1"],["104392.9","0","0","0"],["104396.3","6.19966924","0","1"],["104506.1","0.00037885","0","1"],["104516.6","0","0","0"],["104533.3","0.000173","0","1"]],"bids":[["104316","0.86675892","0","17"],["104301.6","0.78346082","0","2"],["104300.7","0","0","0"],["104250.9","0.00002967","0","1"]],"ts":"1747170753001","checksum":214967154,"seqId":54226514620,"prevSeqId":54226514605}]}
{"arg":{"channel":"books","instId":"BTC-USDT"},"action":"update","data":[{"asks":[["104372.8","0.00056666","0","1"],["104377.6","0","0","0"],["104392.9","6.2081742","0","1"],["104396.3","0","0","0"],["104413.6","0.00056666","0","1"],["104421.4","0","0","0"]],"bids":[["104311.7","0","0","0"],["104311.5","0.00056666","0","1"],["104270.7","0.00056666","0","1"],["104267.9","0.1780651","0","1"],["104234.6","0","0","0"]],"ts":"1747170753101","checksum":-813598408,"seqId":54226514630,"prevSeqId":54226514620}]}
{"arg":{"channel":"books","instId":"BTC-USDT"},"action":"update","data":[{"asks":[["104334.9","0.13897199","0","1"],["104336.4","0","0","0"]],"bids":[["104316","0.87775892","0","18"]],"ts":"1747170753201","checksum":-1460142268,"seqId":54226514636,"prevSeqId":54226514630}]}
{"arg":{"channel":"books","instId":"BTC-USDT"},"action":"update","data":[{"asks":[["104333","0.41746764","0","2"],["104334.3","0.00479206","0","1"],["104533.3","0","0","0"]],"bids":[["104302","0.00479206","0","1"],["104301.6","0.77866876","0","1"],["104234.8","0","0","0"]],"ts":"1747170753401","checksum":-1460142268,"seqId":54226514640,"prevSeqId":54226514636}]}
{"arg":{"channel":"books","instId":"BTC-USDT"},"action":"update","data":[{"asks":[["104316.1","0.84065348","0","10"],["104333.2","0.00479206","0","1"],["104334.3","0","0","0"]],"bids":[["104302","0","0","0"],["104301.7","0.00479206","0","1"]],"ts":"1747170753501","checksum":-261464728,"seqId":54226514645,"prevSeqId":54226514640}]}
{"arg":{"channel":"books","instId":"BTC-USDT"},"action":"update","data":[{"asks":[["104316.1","0.60065348","0","9"],["104333.2","0","0","0"],["104334.3","0.00479206","0","1"],["104334.9","0","0","0"],["104336.4","0.13897106","0","1"]],"bids":[],"ts":"1747170753601","checksum":-1460142268,"seqId":54226514650,"prevSeqId":54226514645}]}
{"arg":{"channel":"books","instId":"BTC-USDT"},"action":"update","data":[{"asks":[["104333.2","0.00479206","0","1"],["104334.3","0","0","0"],["104334.9","0.13897215","0","1"],["104336.4","0","0","0"],["104353.7","0.56120425","0","1"],["104356.5","0","0","0"],["104387.8","0","0","0"],["104533.3","0.000173","0","1"],["104533.9","0.03","0","1"]],"bids":[["104270","0.47121075","0","3"],["104268.6","0","0","0"],["104237.3","0.00001","0","1"],["104234.8","0.00061782","0","1"]],"ts":"1747170753701","checksum":-1460142268,"seqId":54226514666,"prevSeqId":54226514650}]}
{"arg":{"channel":"books","instId":"BTC-USDT"},"action":"update","data":[{"asks":[["104333.2","0","0","0"],["104334.3","0.00479206","0","1"],["104353.7","0.90733847","0","2"],["104356.5","1.38761584","0","1"],["104387.8","2.47959853","0","1"],["104533.3","0","0","0"],["104533.9","0","0","0"]],"bids":[["104270","0.81052404","0","4"],["104267","1.68821751","0","3"],["104263.8","0.00047931","0","1"],["104235.7","2.51472339","0","2"]],"ts":"1747170753801","checksum":-1460142268,"seqId":54226514680,"prevSeqId":54226514666}]}
{"arg":{"channel":"books","instId":"BTC-USDT"},"action":"update","data":[{"asks":[["104318.2","0.01","0","2"],["104324.7","0.04424155","0","1"],["104532","0","0","0"]],"bids":[["104316","0.86866892","0","18"]],"ts":"1747170754001","checksum":-937105344,"seqId":54226514692,"prevSeqId":54226514680}]}
{"arg":{"channel":"books","instId":"BTC-USDT"},"action":"update","data":[{"asks":[["104318.2","0.005","0","1"],["104330.7","0.005","0","1"],["104334.9","0","0","0"],["104335.4","0.38469377","0","2"],["104372.8","0","0","0"],["104372.9","0.00056666","0","1"],["104413.6","0","0","0"],["104413.7","0.00056666","0","1"],["104532","0.00001","0","1"]],"bids":[["104313.8","0.00519173","0","2"],["104311.6","0.00056666","0","1"],["104311.5","0","0","0"],["104302.4","0.15593869","0","2"],["104301.7","0","0","0"],["104301.3","0.005","0","1"],["104270.8","0.00079014","0","2"],["104270.7","0","0","0"],["104250.9","0","0","0"],["104234.6","0.00199229","0","3"],["104234.5","0.00003076","0","2"],["104234.4","0.77963354","0","2"]],"ts":"1747170754101","checksum":-1410837533,"seqId":54226514719,"prevSeqId":54226514692}]}
{"arg":{"channel":"books","instId":"BTC-USDT"},"action":"update","data":[{"asks":[["104335.4","0.2457225","0","1"],["104336.4","0.13897122","0","1"],["104532","0","0","0"]],"bids":[["104286.9","0.1398657","0","5"],["104250.9","0.00002967","0","1"],["104234.4","0","0","0"]],"ts":"1747170754201","checksum":-1410837533,"seqId":54226514738,"prevSeqId":54226514719}]}
{"arg":{"channel":"books","instId":"BTC-USDT"},"action":"update","data":[{"asks":[["104318.2","0.01","0","2"],["104330.7","0.01","0","2"]],"bids":[["104313.8","0.01019173","0","3"],["104301.3","0.01","0","2"]],"ts":"1747170754301","checksum":160979566,"seqId":54226514787,"prevSeqId":54226514738}]}
{"arg":{"channel":"books","instId":"BTC-USDT"},"action":"update","data":[{"asks":[["104319.8","0","0","0"],["104321.9","0.03286585","0","1"],["104329.8","0","0","0"],["104331.6","0.05549548","0","1"],["104336.4","0.13897097","0","1"],["104392.9","0","0","0"],["104532","0.00001","0","1"]],"bids":[["104311.8","0.0237036","0","1"],["104308.2","0.0005","0","1"],["104306.2","0.05545585","0","1"],["104299.7","0","0","0"],["104287.1","0.13897106","0","1"],["104286.9","0.00089399","0","4"],["104234.6","0","0","0"],["104234.5","0","0","0"]],"ts":"1747170754401","checksum":206150507,"seqId":54226514809,"prevSeqId":54226514787}]}
{"arg":{"channel":"books","instId":"BTC-USDT"},"action":"update","data":[{"asks":[["104396.3","6.21515243","0","1"],["104532","0","0","0"]],"bids":[["104316","0.89085892","0","19"]],"ts":"1747170754501","checksum":1260419620,"seqId":54226514811,"prevSeqId":54226514809}]}
{"arg":{"channel":"books","instId":"BTC-USDT"},"action":"update","data":[{"asks":[["104392.9","6.21515243","0","1"],["104396.3","0","0","0"]],"bids":[["104289","0.13897051","0","1"],["104287.1","0","0","0"]],"ts":"1747170754601","checksum":1260419620,"seqId":54226514816,"prevSeqId":54226514811}]}
{"arg":{"channel":"books","instId":"BTC-USDT"},"action":"update","data":[{"asks":[["104323.8","0","0","0"],["104323.9","0.00524205","0","2"],["104331.4","0.00479206","0","1"],["104334.3","0","0","0"],["104336.4","0.13897014","0","1"],["104353.7","0.56120425","0","1"],["104356.5","0","0","0"],["104387.8","0","0","0"],["104532","0.00001","0","1"],["104533.3","0.000173","0","1"],["104533.9","0.03","0","1"]],"bids":[["104302.4","0.15114663","0","1"],["104299.9","0.01016539","0","5"],["104289","0.13897014","0","1"]],"ts":"1747170754701","checksum":-1300809409,"seqId":54226514841,"prevSeqId":54226514816}]}
{"arg":{"channel":"books","instId":"BTC-USDT"},"action":"update","data":[{"asks":[["104323.9","0.00045","0","1"],["104324.2","0.00479205","0","1"],["104533.9","0","0","0"]],"bids":[],"ts":"1747170754801","checksum":87698178,"seqId":54226514843,"prevSeqId":54226514841}]}
{"arg":{"channel":"books","instId":"BTC-USDT"},"action":"update","data":[{"asks":[["104319.7","0.02364475","0","1"],["104321.9","0","0","0"],["104356.5","1.38986675","0","1"],["104387.8","2.52295092","0","1"],["104532","0","0","0"],["104533.3","0","0","0"]],"bids":[],"ts":"1747170754901","checksum":1837906465,"seqId":54226514847,"prevSeqId":54226514843}]}
{"arg":{"channel":"books","instId":"BTC-USDT"},"action":"update","data":[{"asks":[["104316.1","0.48115348","0","8"],["104324.2","0","0","0"],["104324.6","0.00479209","0","1"],["104331.4","0","0","0"],["104331.5","0.04416306","0","2"],["104336.4","0","0","0"],["104337.8","0.13896908","0","1"],["104532","0.00001","0","1"]],"bids":[["104300.1","0.03718481","0","3"],["104299.9","0.00537333","0","4"],["104289.8","0.13896908","0","1"],["104289","0","0","0"]],"ts":"1747170755001","checksum":-1048090546,"seqId":54226514864,"prevSeqId":54226514847}]}
{"arg":{"channel":"books","instId":"BTC-USDT"},"action":"update","data":[{"asks":[["104331.4","0.00479206","0","1"],["104331.5","0.039371","0","1"],["104337","0.13896945","0","1"],["104337.8","0","0","0"],["104372.9","0","0","0"],["104373.1","0.00056666","0","1"],["104413.7","0","0","0"],["104413.9","0.00056666","0","1"],["104532","0","0","0"]],"bids":[["104311.7","0.00056666","0","1"],["104311.6","0","0","0"],["104300.1","0.03239275","0","2"],["104299.9","0.01016539","0","5"],["104289.8","0","0","0"],["104289","0.13896945","0","1"],["104271","0.00056666","0","1"],["104270.8","0.00022348","0","1"],["104234.8","0","0","0"]],"ts":"1747170755101","checksum":-1549391827,"seqId":54226514884,"prevSeqId":54226514864}]}
{"arg":{"channel":"books","instId":"BTC-USDT"},"action":"update","data":[{"asks":[["104316.1","0.48435348","0","9"],["104324.2","0.0047921","0","1"],["104324.6","0","0","0"],["104331.4","0","0","0"],["104332.6","0.37387384","0","2"],["104353.7","0.90801374","0","2"],["104392.9","0","0","0"],["104396.3","6.21515243","0","1"],["104532","0.00001","0","1"]],"bids":[["104300.7","0.00479206","0","1"],["104299.9","0.00537333","0","4"],["104234.9","0","0","0"]],"ts":"1747170755301","checksum":-745721934,"seqId":54226514903,"prevSeqId":54226514884}]}
{"arg":{"channel":"books","instId":"BTC-USDT"},"action":"update","data":[{"asks":[["104323.9","0.0052421","0","2"],["104324.2","0","0","0"],["104332.6","0.36908178","0","1"],["104333","0.4222597","0","3"],["104533.3","0.000173","0","1"]],"bids":[["104301.6","0.78346082","0","2"],["104300.7","0","0","0"],["104234.9","0.00024984","0","5"]],"ts":"1747170755401","checksum":-1886739866,"seqId":54226514911,"prevSeqId":54226514903}]}
{"arg":{"channel":"books","instId":"BTC-USDT"},"action":"update","data":[{"asks":[["104317.9","0.24","0","1"],["104533.3","0","0","0"]],"bids":[],"ts":"1747170755501","checksum":-783856471,"seqId":54226514913,"prevSeqId":54226514911}]}
{"arg":{"channel":"books","instId":"BTC-USDT"},"action":"update","data":[{"asks":[],"bids":[["104250.9","0","0","0"],["104234.8","0.00061782","0","1"]],"ts":"1747170755801","checksum":-783856471,"seqId":54226514916,"prevSeqId":54226514913}]}
{"arg":{"channel":"books","instId":"BTC-USDT"},"action":"update","data":[{"asks":[["104318.3","0.002","0","1"]],"bids":[],"ts":"1747170756001","checksum":-1951296164,"seqId":54226514923,"prevSeqId":54226514916}]}
{"arg":{"channel":"books","instId":"BTC-USDT"},"action":"update","data":[{"asks":[["104323.8","0.0047921","0","1"],["104323.9","0.00045","0","1"],["104332.9","0.00484206","0","2"],["104333","0.41746764","0","2"],["104336.4","0.13897017","0","1"],["104337","0","0","0"],["104532","0","0","0"]],"bids":[["104311.8","0.02427026","0","2"],["104311.7","0","0","0"],["104301.6","0.77866876","0","1"],["104301.4","0.00876613","0","4"],["104251","0.00002967","0","1"]],"ts":"1747170756101","checksum":-892922264,"seqId":54226514939,"prevSeqId":54226514923}]}
{"arg":{"channel":"books","instId":"BTC-USDT"},"action":"update","data":[{"asks":[["104470","0.00076621","0","2"]],"bids":[],"ts":"1747170756201","checksum":-892922264,"seqId":54226514940,"prevSeqId":54226514939}]}
{"arg":{"channel":"books","instId":"BTC-USDT"},"action":"update","data":[{"asks":[["104349.6","0","0","0"],["104375.7","0","0","0"],["104401.8","0","0","0"],["104532","0.00001","0","1"],["104533.3","0.000173","0","1"],["104533.9","0.03","0","1"]],"bids":[["104307.4","0.00004553","0","1"],["104301.5","0.24318661","0","3"],["104301.4","0.00397407","0","3"],["104289","0.13897008","0","1"],["104281.3","0.00001888","0","1"],["104255.2","0.00002044","0","2"]],"ts":"1747170756301","checksum":771758741,"seqId":54226514968,"prevSeqId":54226514940}]}
{"arg":{"channel":"books","instId":"BTC-USDT"},"action":"update","data":[{"asks":[["104316.1","0.48115348","0","8"],["104335.2","0","0","0"],["104340.5","0.097642","0","1"]],"bids":[],"ts":"1747170756401","checksum":483973848,"seqId":54226514971,"prevSeqId":54226514968}]}
{"arg":{"channel":"books","instId":"BTC-USDT"},"action":"update","data":[{"asks":[["104317.9","0","0","0"],["104323.8","0","0","0"],["104323.9","0.00524206","0","2"],["104332","0.00479206","0","1"],["104332.9","0.00005","0","1"],["104336.4","0","0","0"],["104337","0.13896984","0","1"],["104534.7","0.00094804","0","1"]],"bids":[["104316","0.89084757","0","19"],["104302.3","0.07348929","0","3"],["104301.5","0.23839455","0","2"],["104300.2","0.00479206","0","1"],["104234.8","0","0","0"]],"ts":"1747170756501","checksum":-661501499,"seqId":54226514990,"prevSeqId":54226514971}]}
{"arg":{"channel":"books","instId":"BTC-USDT"},"action":"update","data":[{"asks":[["104323.9","0.00045","0","1"],["104324.3","0.29081657","0","2"]],"bids":[],"ts":"1747170756601","checksum":1762738124,"seqId":54226514994,"prevSeqId":54226514990}]}
{"arg":{"channel":"books","instId":"BTC-USDT"},"action":"update","data":[{"asks":[["104324.3","0.28602451","0","1"],["104324.6","0.00479206","0","1"],["104534.7","0","0","0"]],"bids":[],"ts":"1747170756701","checksum":-272947562,"seqId":54226514998,"prevSeqId":54226514994}]}
{"arg":{"channel":"books","instId":"BTC-USDT"},"action":"update","data":[{"asks":[["104319.3","0","0","0"],["104319.4","0","0","0"],["104319.5","0","0","0"],["104323.9","0.00227925","0","2"],["104324.6","0","0","0"],["104325","0.00479206","0","1"],["104337","0","0","0"],["104337.8","0.13896888","0","1"],["104534.7","0.00094804","0","1"],["104535.6","0.00002193","0","1"],["104535.8","0.77866876","0","1"]],"bids":[["104289.8","0.13896939","0","1"],["104289","0","0","0"]],"ts":"1747170756801","checksum":-2034429392,"seqId":54226515011,"prevSeqId":54226514998}]}
{"arg":{"channel":"books","instId":"BTC-USDT"},"action":"update","data":[{"asks":[["104318","0","0","0"],["104337","0.13896951","0","1"],["104337.8","0","0","0"],["104536.1","0.0152","0","1"]],"bids":[["104289.8","0","0","0"],["104289","0.13896951","0","1"]],"ts":"1747170756901","checksum":1515105067,"seqId":54226515016,"prevSeqId":54226515011}]}
{"arg":{"channel":"books","instId":"BTC-USDT"},"action":"update","data":[{"asks":[["104316.1","0.32615348","0","7"],["104319.7","0","0","0"],["104324.4","0.03108988","0","1"],["104324.5","0.09658504","0","1"],["104325","0","0","0"],["104326.3","0.00479206","0","1"],["104326.4","0.05477464","0","1"],["104326.6","0","0","0"],["104326.7","0.09113287","0","1"],["104329.9","0","0","0"],["104330","0.24845895","0","4"],["104332","0","0","0"],["104332.8","0","0","0"],["104332.9","0.16518717","0","2"],["104333.3","0","0","0"],["104333.4","0.25456109","0","1"],["104334.3","0.00479206","0","1"],["104335.4","0","0","0"],["104335.5","0.29743688","0","2"],["104337","0","0","0"],["104339","0.13896722","0","1"],["104339.1","0.1780651","0","1"],["104339.2","0.34245263","0","4"],["104347.9","0.00056666","0","1"],["104361.7","0.27419548","0","1"],["104363","0","0","0"],["104372.7","0.00104595","0","2"],["104373.1","0","0","0"],["104390.1","0.03680273","0","1"],["104396.3","0","0","0"],["104403.1","6.24630187","0","1"],["104413.9","0","0","0"],["104536.2","0.076","0","5"],["104536.3","0.076","0","5"],["104536.4","0.00002296","0","1"]],"bids":[["104311.8","0.0237036","0","1"],["104310.5","0.00056666","0","1"],["104304.2","0.09348443","0","1"],["104304.1","0.000048","0","1"],["104303.5","0.09307863","0","5"],["104303.4","0","0","0"],["104302.5","0.17012697","0","1"],["104302.4","0","0","0"],["104301.7","0.00479206","0","1"],["104300.2","0","0","0"],["104298.4","0.2645123","0","6"],["104298.3","0","0","0"],["104297.9","0.15254025","0","2"],["104297.8","0","0","0"],["104292.5","0.26254313","0","3"],["104292.4","0","0","0"],["104291.7","0.24468534","0","3"],["104291.6","0.00100678","0","2"],["104291.3","0.13896722","0","1"],["104289","0","0","0"],["104285.7","0.01244478","0","40"],["104280.4","0.36908178","0","1"],["104271","0","0","0"],["104251","0","0","0"],["104250.9","0.00002967","0","1"],["104234.8","0.00061782","0","1"],["104234.6","0.00199229","0","3"]],"ts":"1747170757101","checksum":265314902,"seqId":54226515165,"prevSeqId":54226515016}]}
{"arg":{"channel":"books","instId":"BTC-USDT"},"action":"update","data":[{"asks":[["104326","0.11889154","0","3"],["104326.3","0","0","0"],["104326.6","0.234","0","1"],["104332.6","0.37387384","0","2"],["104334.3","0","0","0"],["104338","0.13896788","0","1"],["104339","0","0","0"],["104538.4","0.07298372","0","1"]],"bids":[["104304.8","0.03988045","0","1"],["104301.7","0","0","0"],["104300.7","0.00479206","0","1"],["104296.8","0","0","0"],["104291.3","0","0","0"],["104290.5","0.13900599","0","2"],["104281.1","0.002877","0","1"],["104243.1","0","0","0"],["104234.5","0.00003076","0","2"]],"ts":"1747170757201","checksum":-450449829,"seqId":54226515214,"prevSeqId":54226515165}]}
{"arg":{"channel":"books","instId":"BTC-USDT"},"action":"update","data":[{"asks":[["104325.6","0.00479199","0","1"],["104326","0.11409956","0","2"],["104326.6","0","0","0"],["104337.8","0.13896852","0","1"],["104338","0","0","0"]],"bids":[["104290.5","0.00003811","0","1"],["104289.8","0.13896852","0","1"],["104234.5","0","0","0"]],"ts":"1747170757301","checksum":11841904,"seqId":54226515235,"prevSeqId":54226515214}]}
{"arg":{"channel":"books","instId":"BTC-USDT"},"action":"update","data":[{"asks":[["104324.5","0","0","0"],["104326.6","0.234","0","1"],["104330","0.08190006","0","3"],["104335.5","0.039","0","1"],["104336.4","0.13897006","0","1"],["104337.8","0","0","0"]],"bids":[["104303.5","0.00035761","0","4"],["104302.5","0","0","0"],["104292.5","0.00002543","0","2"],["104289.8","0","0","0"],["104289","0.13897006","0","1"],["104234.5","0.00003076","0","2"]],"ts":"1747170757401","checksum":-1488305595,"seqId":54226515252,"prevSeqId":54226515235}]}
{"arg":{"channel":"books","instId":"BTC-USDT"},"action":"update","data":[{"asks":[["104321.9","0.03005752","0","1"],["104324.7","0","0","0"],["104326.6","0","0","0"],["104336.4","0","0","0"],["104337.8","0.13896876","0","1"],["104396.3","6.24630187","0","1"],["104403.1","0","0","0"],["104538.5","0.234","0","1"]],"bids":[["104289.8","0.13896876","0","1"],["104289","0","0","0"]],"ts":"1747170757501","checksum":2032656962,"seqId":54226515265,"prevSeqId":54226515252}]}
{"arg":{"channel":"books","instId":"BTC-USDT"},"action":"update","data":[{"asks":[],"bids":[["104316","1.12484757","0","20"],["104281.1","0","0","0"],["104259.6","0.002877","0","1"]],"ts":"1747170757601","checksum":-602034079,"seqId":54226515269,"prevSeqId":54226515265}]}
{"arg":{"channel":"books","instId":"BTC-USDT"},"action":"update","data":[{"asks":[],"bids":[["104316","0.89184757","0","20"]],"ts":"1747170757701","checksum":-935930142,"seqId":54226515275,"prevSeqId":54226515269}]}
{"arg":{"channel":"books","instId":"BTC-USDT"},"action":"update","data":[{"asks":[],"bids":[["104245.1","0.00953963","0","1"],["104238.7","0.00894927","0","1"],["104237.2","0.00802982","0","7"],["104234.6","0","0","0"],["104234.5","0","0","0"]],"ts":"1747170757801","checksum":-935930142,"seqId":54226515279,"prevSeqId":54226515275}]}
{"arg":{"channel":"books","instId":"BTC-USDT"},"action":"update","data":[{"asks":[["104326.6","0.234","0","1"],["104538.5","0","0","0"]],"bids":[],"ts":"1747170758001","checksum":-1412323938,"seqId":54226515284,"prevSeqId":54226515279}]}
{"arg":{"channel":"books","instId":"BTC-USDT"},"action":"update","data":[{"asks":[["104325.3","0.00479193","0","1"],["104325.6","0","0","0"],["104332.5","0.00479206","0","1"],["104332.6","0.36908178","0","1"],["104346.6","0.00056666","0","1"],["104347.9","0","0","0"],["104364","1.58412494","0","3"],["104370.6","0.00056666","0","1"],["104372.7","0.00047929","0","1"],["104536.4","0","0","0"],["104538.4","0","0","0"]],"bids":[["104286.6","0.00058719","0","3"],["104285.7","0.01187812","0","39"]],"ts":"1747170758101","checksum":-1314539214,"seqId":54226515303,"prevSeqId":54226515284}]}
{"arg":{"channel":"books","instId":"BTC-USDT"},"action":"update","data":[{"asks":[["104316.1","0.32935348","0","8"],["104325","0.00479193","0","1"],["104325.3","0","0","0"],["104326.6","0.33243987","0","2"],["104326.7","0","0","0"],["104330.7","0.01479206","0","3"],["104332.5","0","0","0"],["104336.4","0.13896996","0","1"],["104337.8","0","0","0"],["104339.1","0.42723734","0","2"],["104339.2","0.093","0","3"],["104536.4","0.00002296","0","1"],["104538.4","0.07298372","0","1"]],"bids":[["104304.2","0","0","0"],["104304.1","0.09279877","0","2"],["104300.7","0","0","0"],["104298.5","0.00479206","0","1"],["104291.7","0.00009425","0","2"],["104291.6","0.24234515","0","3"],["104289.8","0","0","0"],["104288.6","0.1390808","0","3"],["104234.6","0.00199229","0","3"],["104234.5","0.00003076","0","2"]],"ts":"1747170758201","checksum":391794099,"seqId":54226515335,"prevSeqId":54226515303}]}
{"arg":{"channel":"books","instId":"BTC-USDT"},"action":"update","data":[{"asks":[["104325","0","0","0"],["104325.3","0.00479193","0","1"],["104330.6","0.00479206","0","1"],["104330.7","0.01","0","2"],["104538.4","0","0","0"]],"bids":[["104298.6","0.00479206","0","1"],["104298.5","0","0","0"]],"ts":"1747170758301","checksum":-912499144,"seqId":54226515347,"prevSeqId":54226515335}]}
{"arg":{"channel":"books","instId":"BTC-USDT"},"action":"update","data":[{"asks":[["104316.1","0.32615348","0","7"],["104319.6","0","0","0"],["104321.4","0","0","0"],["104324.1","0.02649816","0","1"],["104324.3","0.19056036","0","1"],["104324.5","0.09776587","0","1"],["104325.3","0","0","0"],["104325.9","0","0","0"],["104326.4","0.0595667","0","2"],["104326.6","0","0","0"],["104326.7","0.09698304","0","1"],["104329.5","0.36863015","0","2"],["104330","0.25111536","0","4"],["104330.6","0","0","0"],["104332.7","0","0","0"],["104335.5","0.28724011","0","2"],["104336.4","0","0","0"],["104337.8","0.00479206","0","1"],["104339","0.13896739","0","1"],["104339.1","0.1780651","0","1"],["104339.2","0.34419295","0","4"],["104361.7","0.53992105","0","2"],["104538.4","0.07298372","0","1"],["104538.5","0.234","0","1"],["104540","0.00330186","0","4"]],"bids":[["104316","1.12584757","0","21"],["104314.3","0.03097347","0","1"],["104306.3","0.00479206","0","1"],["104304.2","0.09279151","0","1"],["104304.1","0.000048","0","1"],["104303.5","0.0937335","0","5"],["104302.5","0.16992615","0","1"],["104301.2","0.00232901","0","5"],["104298.6","0","0","0"],["104292.5","0.24984639","0","3"],["104291.7","0.26499526","0","3"],["104291.6","0.00100678","0","2"],["104291.3","0.13896739","0","1"],["104288.6","0.00011027","0","2"],["104234.9","0","0","0"],["104234.8","0","0","0"],["104234.6","0","0","0"],["104234.5","0","0","0"]],"ts":"1747170758401","checksum":-519756660,"seqId":54226515447,"prevSeqId":54226515347}]}
{"arg":{"channel":"books","instId":"BTC-USDT"},"action":"update","data":[{"asks":[["104324.2","0.19242972","0","1"],["104329.5","0.51640384","0","3"],["104332.8","0.77866876","0","1"],["104337","0.00479206","0","1"],["104337.8","0","0","0"],["104538.5","0","0","0"],["104540","0","0","0"]],"bids":[["104316","1.36584757","0","22"],["104314.3","0","0","0"],["104306.3","0","0","0"],["104305","0.00480206","0","2"],["104302.2","0.05243258","0","2"],["104234.9","0.00024984","0","5"],["104234.8","0.00061782","0","1"]],"ts":"1747170758501","checksum":-1109644304,"seqId":54226515458,"prevSeqId":54226515447}]}
{"arg":{"channel":"books","instId":"BTC-USDT"},"action":"update","data":[{"asks":[["104326.3","0.00479191","0","1"],["104326.4","0.05477464","0","1"],["104335.4","0.00479206","0","1"],["104337","0","0","0"],["104339","0.13896698","0","1"],["104538.4","0","0","0"]],"bids":[["104306.9","0.04782795","0","1"],["104306.2","0","0","0"],["104305","0.00001","0","1"],["104303.7","0.00479206","0","1"],["104291.3","0.13896698","0","1"],["104234.8","0","0","0"]],"ts":"1747170758601","checksum":-2063859235,"seqId":54226515481,"prevSeqId":54226515458}]}
{"arg":{"channel":"books","instId":"BTC-USDT"},"action":"update","data":[{"asks":[["104338","0.13896787","0","1"],["104339","0","0","0"]],"bids":[["104291.3","0","0","0"],["104290.5","0.13900598","0","2"],["104234.8","0.00061782","0","1"]],"ts":"1747170758701","checksum":-2063859235,"seqId":54226515488,"prevSeqId":54226515481}]}
{"event":"subscribe","arg":{"channel":"books","instId":"BTC-USDT"},"connId":"9dca1958"}
{"arg":{"channel":"books","instId":"BTC-USDT"},"action":"snapshot","data":[{"asks":[["104488","0.2691672","0","9"],["104488.3","0.00373804","0","2"],["104490","0.09349006","0","3"],["104491.2","0.00262746","0","1"],["104492","0.0932","0","1"],["104492.6","0.00007302","0","1"],["104495.1","0.00004789","0","1"],["104495.7","0.0028","0","2"],["104495.8","0.00045","0","1"],["104496.3","0.00001","0","1"],["104496.4","0.00011435","0","1"],["104496.5","0.09221998","0","1"],["104496.9","0.04","0","1"],["104497","0.005","0","1"],["104497.2","0.10029009","0","1"],["104497.5","0.31531026","0","1"],["104497.6","0.19242972","0","1"],["104497.7","0.36908178","0","1"],["104498.2","0.12147783","0","2"],["104498.3","0.00851559","0","1"],["104498.5","0.234","0","1"],["104498.7","0.09948061","0","1"],["104499","0.01913838","0","1"],["104499.2","0.03832933","0","1"],["104499.8","0.02832415","0","1"],["104500","0.00330988","0","9"],["104500.3","0.00001","0","1"],["104500.8","0.02854184","0","1"],["104501.1","0.00093","0","1"],["104501.3","0.00009573","0","2"],["104501.4","0.48646829","0","1"],["104501.5","0.77866876","0","1"],["104501.7","0.1635359","0","1"],["104501.9","0.00001946","0","1"],["104502","0.15138247","0","1"],["104502.1","0.00001","0","1"],["104502.2","0.16612307","0","2"],["104502.8","0.00001679","0","1"],["104503.6","0.00478362","0","1"],["104503.7","0.35658706","0","2"],["104503.9","0.00041858","0","1"],["104504","0.00001526","0","1"],["104504.9","0.37272","0","2"],["104505","0.20722773","0","2"],["104505.4","0.23389752","0","1"],["104505.6","0.04314406","0","2"],["104506","0.00006","0","1"],["104506.3","0.00093","0","1"],["104506.4","0.05286856","0","1"],["104506.8","0.03827676","0","1"],["104507.2","0.24011282","0","1"],["104507.4","0.17829353","0","1"],["104507.5","0.31165982","0","2"],["104507.8","0.04","0","1"],["104508","0.000015","0","1"],["104508.1","0.00004378","0","1"],["104508.2","0.00001","0","1"],["104509.4","0.00023574","0","1"],["104509.8","1.05560083","0","2"],["104509.9","0.19242972","0","1"],["104510","0.00029006","0","2"],["104510.1","0.234","0","1"],["104510.2","0.071782","0","1"],["104510.7","0.075","0","2"],["104510.9","0.00956633","0","1"],["104511.2","0.42853823","0","2"],["104511.5","0.00191","0","1"],["104511.9","0.0028806","0","2"],["104512","0.05212769","0","1"],["104512.2","0.0001","0","1"],["104512.4","0.17829353","0","1"],["104512.6","0.77866876","0","1"],["104512.9","0.26864","0","1"],["104513.3","0.17836668","0","2"],["104513.9","0.00004793","0","1"],["104514.8","0.43489007","0","4"],["104514.9","0.063","0","2"],["104515","0.00004786","0","1"],["104515.4","0.02871143","0","1"],["104516.1","0.00001","0","1"],["104516.7","0.00191","0","1"],["104517.6","0.00287","0","1"],["104518.5","0.00712703","0","2"],["104518.7","0.59819","0","1"],["104519.9","0.55912","0","1"],["104520","0.00530992","0","6"],["104520.1","0.00001","0","1"],["104520.2","0.13901621","0","2"],["104520.3","0.40596644","0","1"],["104520.4","0.19242972","0","1"],["104520.5","0.36908178","0","1"],["104520.6","0.52593486","0","2"],["104521","0.001","0","1"],["104521.4","0.17829353","0","1"],["104521.7","0.00001067","0","1"],["104521.8","0.00001","0","1"],["104522.7","0.00005567","0","1"],["104524","0.00001723","0","1"],["104524.5","0.00054673","0","1"],["104525.2","0.29114323","0","1"],["104525.3","0.77866876","0","1"],["104525.6","0.04385719","0","1"],["104526.7","0.00013936","0","1"],["104526.8","0.0022","0","1"],["104527.7","0.0957","0","1"],["104528.1","0.00001","0","1"],["104529","0.000015","0","1"],["104529.2","0.00001501","0","1"],["104529.4","0.00002902","0","1"],["104529.5","0.07298372","0","1"],["104530","0.00029006","0","2"],["104530.1","0.01496725","0","1"],["104530.3","0.04599851","0","1"],["104530.8","0.0957","0","1"],["104531","0.36304409","0","1"],["104531.1","0.24275682","0","2"],["104531.4","0.00209352","0","1"],["104531.5","0.17829353","0","1"],["104532","0.00001","0","1"],["104532.1","0.09681","0","1"],["104532.5","0.5","0","1"],["104533.3","0.00549055","0","4"],["104534","0.19242972","0","1"],["104534.1","0.00004969","0","1"],["104534.7","0.00094804","0","1"],["104535.4","1.36083823","0","1"],["104535.6","0.00002193","0","1"],["104535.7","0.469538","0","1"],["104535.8","0.77866876","0","1"],["104536","0.00001","0","1"],["104536.4","0.00002296","0","1"],["104537","0.02869923","0","1"],["104537.3","0.01434619","0","1"],["104538.4","0.07299586","0","2"],["104538.5","0.00003395","0","1"],["104539","0.47497897","0","2"],["104539.2","0.416374","0","2"],["104539.5","0.00001501","0","1"],["104540","0.55775086","0","7"],["104540.3","0.00047852","0","1"],["104541","0.16","0","2"],["104541.2","0.00009506","0","1"],["104541.4","0.36919178","0","3"],["104541.5","0.0001303","0","1"],["104541.6","0.234","0","1"],["104541.9","0.00003805","0","1"],["104542","0.25002847","0","6"],["104542.4","0.98746105","0","1"],["104542.5","0.87473631","0","2"],["104542.6","0.0008017","0","1"],["104542.7","0.1","0","1"],["104543","0.085","0","2"],["104543.6","2.42368","0","1"],["104544","0.49439815","0","1"],["104544.9","0.0004969","0","1"],["104545.4","0.00021056","0","2"],["104545.5","0.01099627","0","1"],["104545.8","0.02871162","0","1"],["104546.1","0.19242972","0","1"],["104546.2","0.44137699","0","1"],["104546.3","0.77866876","0","1"],["104546.6","0.00002544","0","1"],["104546.8","0.00080324","0","1"],["104547.1","0.09565","0","1"],["104547.3","0.01099627","0","1"],["104547.6","0.06699","0","1"],["104547.7","0.00002452","0","1"],["104547.9","0.02092112","0","2"],["104549.2","0.29193486","0","1"],["104549.3","0.11478","0","1"],["104549.9","0.4","0","1"],["104550","0.01162949","0","6"],["104550.7","0.02164047","0","1"],["104551.2","0.00005067","0","1"],["104551.9","0.00001","0","1"],["104552","0.19450287","0","2"],["104552.1","0.234","0","1"],["104552.4","0.00004887","0","1"],["104552.6","0.14347","0","1"],["104553.1","0.09565","0","1"],["104553.7","0.00002373","0","1"],["104554","0.01099627","0","1"],["104554.1","0.29193486","0","1"],["104555.3","0.04295641","0","1"],["104555.5","0.01052914","0","1"],["104555.9","0.00001","0","1"],["104556","0.00056666","0","1"],["104556.8","0.01099627","0","1"],["104556.9","0.01052914","0","1"],["104557.1","0.5615115","0","2"],["104557.2","0.23710567","0","1"],["104557.3","0.79972804","0","3"],["104558.2","0.01054019","0","2"],["104558.4","0.03","0","1"],["104558.9","0.00040805","0","13"],["104559","0.01053014","0","1"],["104559.2","2.66827914","0","2"],["104559.3","0.01052914","0","1"],["104559.4","0.00002482","0","1"],["104559.8","0.00001","0","1"],["104559.9","0.01099627","0","1"],["104560","0.00222145","0","4"],["104560.3","0.00011389","0","1"],["104560.5","0.00001501","0","1"],["104560.6","0.19128","0","1"],["104560.9","0.00023767","0","1"],["104561.1","0.00002686","0","2"],["104561.3","0.01052914","0","1"],["104561.7","0.01099627","0","1"],["104561.9","0.01053014","0","1"],["104562","0.06982","0","1"],["104562.6","0.234","0","1"],["104562.9","0.01054214","0","2"],["104563.1","0.04783204","0","1"],["104564.5","0.01099627","0","1"],["104564.6","0.01052914","0","1"],["104565","0.01052914","0","1"],["104565.1","0.03","0","1"],["104565.3","0.0791","0","1"],["104566.8","2.42732091","0","2"],["104566.9","0.0105964","0","1"],["104567","0.02105828","0","2"],["104567.1","0.00071107","0","1"],["104567.6","0.00011258","0","1"],["104567.8","0.00001","0","1"],["104568","0.01099559","0","1"],["104568.1","0.01099627","0","1"],["104568.2","0.01052914","0","1"],["104569.4","0.02155541","0","3"],["104569.5","0.0105964","0","1"],["104569.6","0.01052914","0","1"],["104570","0.01087646","0","2"],["104570.1","0.77866876","0","1"],["104570.3","0.00023506","0","1"],["104570.4","0.01052914","0","1"],["104570.6","0.00652172","0","1"],["104570.9","0.00001","0","1"],["104571","0.000015","0","1"],["104571.2","0.00002544","0","1"],["104571.3","0.01052914","0","1"],["104571.4","0.00068048","0","3"],["104571.9","0.01052914","0","1"],["104572","0.37153924","0","16"],["104572.8","0.01059606","0","1"],["104572.9","0.0105964","0","1"],["104573","0.01052914","0","1"],["104573.1","0.234","0","1"],["104573.5","0.01052914","0","1"],["104573.6","0.10660768","0","2"],["104573.7","0.06699","0","1"],["104574","0.831373","0","1"],["104574.9","0.00006102","0","1"],["104575.3","0.02119098","0","2"],["104575.4","0.01052914","0","1"],["104575.5","5.80580569","0","3"],["104575.6","0.07298372","0","1"],["104575.7","0.00001","0","1"],["104575.8","0.0022","0","1"],["104576.8","0.01059606","0","1"],["104576.9","0.01052914","0","1"],["104577","0.01052914","0","1"],["104577.8","0.0000281","0","1"],["104578.2","0.01059549","0","1"],["104578.3","0.0105715","0","2"],["104579.5","0.0000479","0","1"],["104579.7","0.00001","0","1"],["104579.9","0.01059606","0","1"],["104580","0.0131947","0","3"],["104580.6","0.0003014","0","1"],["104580.7","0.01053914","0","2"],["104580.8","0.04888372","0","2"],["104581","0.00006705","0","1"],["104581.5","0.00003002","0","2"],["104581.8","0.01059606","0","1"],["104581.9","0.0105964","0","1"],["104582","0.0025","0","1"],["104582.3","0.77866876","0","1"],["104583.3","0.00117232","0","2"],["104583.6","0.24459542","0","2"],["104584","0.005","0","2"],["104584.3","0.01063007","0","2"],["104584.4","0.01194126","0","2"],["104584.5","0.01052823","0","1"],["104584.8","0.12126067","0","2"],["104585.9","0.04634752","0","1"],["104587","0.00009531","0","4"],["104587.4","0.00002013","0","1"],["104587.7","0.00001","0","1"],["104587.9","0.01059542","0","1"],["104588","0.01099559","0","1"],["104588.1","0.01059549","0","1"],["104588.2","0.01052823","0","1"],["104588.6","0.0005","0","1"],["104588.9","0.08827235","0","2"],["104589","0.01489996","0","1"],["104589.9","0.00001232","0","1"],["104590","0.00028006","0","1"],["104590.5","0.01052823","0","1"],["104590.6","0.01100627","0","2"],["104590.7","0.01345386","0","1"],["104591.1","0.05737","0","1"],["104591.2","0.0009561","0","1"],["104592","0.07304929","0","3"],["104593","0.77866876","0","1"],["104593.2","0.00003453","0","1"],["104593.4","0.00008341","0","1"],["104593.9","0.01059606","0","1"],["104594","0.0105964","0","1"],["104594.1","0.234","0","1"],["104594.8","0.0026904","0","1"],["104595.5","0.00009127","0","1"],["104595.6","0.00001","0","1"],["104596","0.00010095","0","1"],["104596.4","0.01059542","0","1"],["104596.5","1.26606559","0","2"],["104596.9","0.00014244","0","2"],["104597.1","0.00003805","0","1"],["104597.2","0.00005914","0","1"],["104598","0.97264328","0","1"],["104598.4","0.01059549","0","1"],["104598.5","0.03968619","0","2"],["104598.6","0.0001","0","1"],["104598.7","0.0032497","0","1"],["104599.6","0.00001","0","1"],["104599.9","0.00235551","0","3"],["104600","0.01686056","0","53"],["104600.2","0.0008","0","1"],["104600.3","0.00006","0","1"],["104600.4","0.00001","0","1"],["104600.9","0.04415483","0","1"],["104601","0.0698","0","1"],["104601.1","0.0105964","0","1"],["104601.5","2.89435585","0","3"],["104602.5","0.000015","0","1"],["104603","0.01099559","0","1"],["104603.1","0.00001531","0","1"],["104603.3","0.00375251","0","1"],["104603.6","0.77866876","0","1"],["104604.3","0.00001","0","1"],["104604.5","0.01099627","0","1"],["104604.6","0.234","0","1"],["104604.7","0.03017476","0","2"],["104604.9","0.03","0","1"],["104605.2","0.01059606","0","1"],["104605.3","0.01059549","0","1"],["104605.4","0.03","0","1"],["104605.7","0.0000221","0","1"],["104607.5","0.00001","0","1"],["104608.2","0.01059542","0","1"],["104608.3","0.03","0","1"],["104608.4","0.00041816","0","1"],["104608.5","0.010429","0","1"],["104608.6","0.03","0","1"],["104610","0.29261492","0","3"],["104610.2","0.00001","0","1"],["104610.9","0.01099559","0","1"],["104611","0.01099627","0","1"],["104611.3","0.00005484","0","1"],["104612.1","0.01059606","0","1"],["104612.2","0.01407867","0","1"],["104612.6","0.229704","0","1"],["104612.9","0.00001168","0","1"],["104613","0.000015","0","1"],["104613.8","0.05793435","0","1"],["104614.9","0.0000105","0","1"],["104615","0.01099627","0","1"],["104615.1","1.02326418","0","3"],["104615.3","0.29225276","0","4"],["104615.5","0.00001","0","1"],["104616.6","0.00007797","0","4"],["104617.6","0.00003056","0","2"],["104617.7","0.01099591","0","1"],["104617.8","0.01099559","0","1"],["104617.9","0.160824","0","1"],["104618","0.00001632","0","1"],["104618.5","0.00009552","0","1"],["104619.3","0.04304781","0","1"],["104620","0.00222603","0","4"],["104621.3","0.01099559","0","1"],["104621.4","0.0579344","0","1"],["104622","0.01101846","0","2"],["104622.1","0.0140803","0","1"],["104623.3","0.03","0","1"],["104623.4","0.00001","0","1"],["104623.6","0.00083722","0","2"],["104625","0.0000103","0","1"],["104625.4","0.00037568","0","2"],["104625.6","0.234","0","1"],["104625.7","0.0001","0","1"],["104625.8","0.00009579","0","1"],["104626","0.01099591","0","1"],["104626.1","0.01488","0","1"],["104626.8","0.00001371","0","1"],["104627.2","0.77866876","0","1"],["104627.8","0.00001104","0","1"],["104628.6","0.0001","0","1"],["104628.7","0.00001176","0","1"],["104628.8","0.07298372","0","1"],["104629.5","0.00010997","0","1"],["104629.6","0.000096","0","1"]],"bids":[["104487.9","0.43495288","0","16"],["104487.2","0.03054712","0","1"],["104486.1","0.06481925","0","1"],["104486","0.0932","0","1"],["104484.5","0.02794928","0","1"],["104484","0.0932","0","1"],["104483.3","0.27191968","0","1"],["104483.1","0.052","0","2"],["104482.6","0.012","0","1"],["104482.5","0.03127482","0","1"],["104482.3","0.05263489","0","3"],["104482","0.0932","0","1"],["104481.3","0.0242","0","1"],["104481","0.0076569","0","1"],["104480.9","0.05191","0","2"],["104480.5","0.00001","0","1"],["104480.1","0.0022149","0","2"],["104480","0.09321","0","2"],["104479.8","0.00521895","0","1"],["104479.7","0.234","0","1"],["104479","0.07298372","0","1"],["104478.3","0.36412281","0","1"],["104478","0.0932","0","1"],["104477.7","0.19392027","0","2"],["104476.5","0.00001","0","1"],["104476.4","0.04013884","0","2"],["104476.2","0.08844299","0","1"],["104476","0.000015","0","1"],["104475.5","0.09601321","0","1"],["104474.8","0.00097","0","1"],["104474.5","0.1683731","0","1"],["104474.3","0.0087017","0","1"],["104474.2","0.14460986","0","1"],["104473.8","0.096716","0","1"],["104473.5","0.05191","0","2"],["104472.8","0.33115613","0","2"],["104472.7","0.15175613","0","1"],["104472.6","0.00001","0","1"],["104472.5","0.02929425","0","1"],["104472.1","0.45755124","0","1"],["104472","0.0932","0","1"],["104471.9","0.05191","0","2"],["104471.2","0.00478362","0","1"],["104471","0.07298372","0","1"],["104470.5","0.00106586","0","1"],["104470.4","0.22896551","0","1"],["104470.1","0.77866876","0","1"],["104470","0.25184157","0","4"],["104469.6","0.00097","0","1"],["104469.5","0.17829353","0","1"],["104468.8","0.28591","0","3"],["104468.6","0.00001","0","1"],["104468.5","0.00846109","0","1"],["104468","0.13229025","0","2"],["104467.7","0.24856768","0","1"],["104467.6","0.3240023","0","2"],["104466.8","0.17829353","0","1"],["104466.6","0.04","0","1"],["104466","0.0932","0","1"],["104465.6","0.071803","0","2"],["104464.6","0.00001","0","1"],["104464.5","0.26206635","0","1"],["104464.4","0.00191","0","1"],["104464.2","0.07298372","0","1"],["104463.7","0.26086011","0","1"],["104463.6","0.17829353","0","1"],["104463.3","0.0537761","0","1"],["104463.2","0.00005","0","1"],["104463.1","0.03","0","1"],["104462.6","0.37310335","0","1"],["104462.5","0.03","0","1"],["104462.2","0.19242972","0","1"],["104461.9","0.05191","0","2"],["104461.7","0.00957092","0","1"],["104460.7","0.00001","0","1"],["104460","0.00220843","0","3"],["104459.9","0.05191","0","2"],["104459.2","0.78057876","0","2"],["104459.1","0.063","0","2"],["104458.9","0.033","0","1"],["104458.3","0.03","0","1"],["104457.4","0.12680025","0","1"],["104456.9","0.05191","0","2"],["104456.7","0.00001","0","1"],["104455.8","0.07298372","0","1"],["104455.7","0.28591","0","3"],["104455.2","0.000015","0","1"],["104454.4","0.002","0","1"],["104453.4","0.00004786","0","1"],["104453.3","0.36908178","0","1"],["104452.7","0.00001","0","1"],["104452.1","0.34147336","0","1"],["104450","0.00029006","0","2"],["104449.9","0.05191","0","2"],["104449.6","0.19242972","0","1"],["104449.5","0.06152637","0","1"],["104449.1","0.00478518","0","1"],["104448.8","0.00001","0","1"],["104448.7","0.77866876","0","1"],["104448.6","0.00824757","0","1"],["104447.7","0.00955876","0","1"],["104447.4","0.58887","0","1"],["104447.1","0.00002962","0","1"],["104447","0.07298372","0","1"],["104446.7","1.38464907","0","1"],["104444.9","0.00287075","0","1"],["104444.8","0.000025","0","2"],["104444.7","0.04332177","0","1"],["104444.5","0.052","0","2"],["104442.4","0.36908178","0","1"],["104442.3","0.30871424","0","4"],["104442.2","0.17829353","0","1"],["104441.9","0.002","0","1"],["104441.6","0.64407852","0","2"],["104441.5","0.63816","0","1"],["104441.2","0.17829353","0","1"],["104440.8","0.00001","0","1"],["104440.3","0.07335","0","1"],["104440","0.00220843","0","3"],["104439.9","0.18307882","0","2"],["104438.7","0.19242972","0","1"],["104438.2","0.77866876","0","1"],["104436.8","0.00001","0","1"],["104436.2","0.04656475","0","1"],["104436","0.48324487","0","1"],["104435.7","0.00047852","0","1"],["104435.6","0.02871276","0","1"],["104434.4","0.00001501","0","1"],["104434.2","0.000015","0","1"],["104432.9","0.00001","0","1"],["104432.6","0.20063058","0","1"],["104432.5","0.20931353","0","2"],["104432","0.052","0","2"],["104431.6","0.37708178","0","2"],["104431.5","0.36869051","0","1"],["104430","0.00029006","0","2"],["104428.9","0.00001","0","1"],["104428.7","0.00001","0","1"],["104428.5","0.07298372","0","1"],["104428.1","0.19242972","0","1"],["104428","0.0022","0","1"],["104427.6","0.77866876","0","1"],["104426.8","0.00017476","0","1"],["104424.9","0.00001","0","1"],["104424.7","0.03598865","0","1"],["104424.4","0.413504","0","1"],["104424","0.000015","0","1"],["104423.7","0.234","0","1"],["104423.4","0.03598865","0","1"],["104421.6","0.00871811","0","1"],["104421.1","0.00056666","0","1"],["104421","0.00001","0","1"],["104420","0.00220843","0","3"],["104419.7","0.05198865","0","2"],["104419.3","0.005","0","1"],["104419.2","0.43961667","0","1"],["104419.1","0.36908178","0","1"],["104419","0.05198865","0","2"],["104418.9","0.01436245","0","1"],["104418.7","0.555073","0","1"],["104417.6","0.02105828","0","2"],["104417.5","0.19242972","0","1"],["104417.1","0.01052914","0","1"],["104417","0.00001","0","1"],["104416.9","0.77866876","0","1"],["104415.5","0.01099591","0","1"],["104415.4","0.45468381","0","1"],["104415.3","2.43274954","0","1"],["104415.1","0.01052914","0","1"],["104415","0.05198865","0","2"],["104413.6","0.000015","0","1"],["104413.1","0.01099591","0","1"],["104413","0.0106059","0","2"],["104412.9","0.28598865","0","3"],["104412.8","0.07298372","0","1"],["104412","0.02871296","0","1"],["104411.7","0.00952945","0","1"],["104410.9","0.01099591","0","1"],["104410.8","0.0022","0","1"],["104410.1","0.54303355","0","1"],["104410","0.00028006","0","1"],["104409.5","0.05885051","0","2"],["104409.1","0.00001","0","1"],["104408.9","0.0000814","0","1"],["104408.7","0.0105959","0","1"],["104408.6","0.36908178","0","1"],["104408.2","0.0005","0","1"],["104407.9","0.03158742","0","3"],["104407.8","0.0105959","0","1"],["104407.7","0.05198865","0","2"],["104407","0.29649914","0","2"],["104406.9","0.19242972","0","1"],["104406.8","0.005","0","1"],["104406.1","0.01052823","0","1"],["104406","0.01052914","0","1"],["104405.9","0.77866876","0","1"],["104405.1","0.00001","0","1"],["104404.8","0.01099591","0","1"],["104404.7","0.01071402","0","2"],["104404.6","0.02065347","0","1"],["104403.2","0.00001501","0","1"],["104402.8","0.03279989","0","1"],["104401.1","0.00001","0","1"],["104400.9","0.03102","0","1"],["104400.1","0.0105959","0","1"],["104400","0.54405393","0","5"],["104399.9","0.05216165","0","3"],["104399.7","0.32612","0","1"],["104397.8","0.0211918","0","2"],["104397.2","0.00001","0","1"],["104396.4","0.19242972","0","1"],["104395.4","0.36908178","0","1"],["104395.3","0.83065741","0","3"],["104394.7","0.0105959","0","1"],["104394.6","0.1125891","0","1"],["104394.5","0.24496497","0","3"],["104394.1","0.00952697","0","1"],["104394","0.1205","0","1"],["104393.2","0.00001","0","1"],["104392.8","0.000015","0","1"],["104390","0.00028006","0","1"],["104389.2","0.00001","0","1"],["104389.1","0.01109203","0","2"],["104389","0.47439916","0","1"],["104388.6","0.93361682","0","2"],["104388.5","0.05198865","0","2"],["104387.8","2.83775","0","1"],["104387.2","0.00011811","0","1"],["104387","0.00952955","0","1"],["104386.1","0.0191411","0","1"],["104385.9","0.00742798","0","1"],["104385.3","0.00001","0","1"],["104384.8","1.13535078","0","2"],["104384.7","0.36908178","0","1"],["104384.5","0.07188","0","1"],["104384.2","0.77866876","0","1"],["104383.8","2.61845","0","1"],["104383.6","0.00953135","0","1"],["104383.3","0.00867111","0","1"],["104383.1","0.007986","0","1"],["104382.6","0.00953079","0","1"],["104382.4","0.000015","0","1"],["104382","0.000015","0","1"],["104381.3","0.00001","0","1"],["104381","0.01099591","0","1"],["104380.9","0.01147839","0","1"],["104380.1","0.0211894","0","2"],["104380","0.00230423","0","4"],["104379","0.01053064","0","1"],["104378.9","0.14914712","0","8"],["104378.8","0.26274137","0","1"],["104378.2","0.00173837","0","1"],["104377.8","0.00957111","0","1"],["104377.3","0.00001","0","1"],["104377.2","0.0105947","0","1"],["104377","0.01053064","0","1"],["104376.8","0.0076","0","1"],["104375","0.01099591","0","1"],["104374.9","0.0105947","0","1"],["104374","0.00063965","0","1"],["104373.9","0.01034","0","1"],["104373.4","0.01054064","0","2"],["104373.3","0.01053113","0","1"],["104373.1","0.1913","0","1"],["104372.9","0.0001","0","1"],["104372.6","0.00957111","0","1"],["104372.5","0.0105947","0","1"],["104372.4","0.38498809","0","3"],["104372.2","0.36908178","0","1"],["104372.1","0.77866876","0","1"],["104372","0.00001501","0","1"],["104370","0.00028006","0","1"],["104369.4","0.00001","0","1"],["104369.2","0.74341828","0","1"],["104369.1","0.833005","0","1"],["104368.3","0.00084002","0","1"],["104368.2","0.0105959","0","1"],["104368.1","0.01053113","0","1"],["104368","0.03218531","0","3"],["104367.8","0.0114978","0","1"],["104367.5","0.00017476","0","1"],["104366.1","0.01053403","0","1"],["104365.9","0.05793435","0","1"],["104365.4","0.00001","0","1"],["104365.3","0.01099591","0","1"],["104365.2","1.38913","0","1"],["104365.1","0.0105947","0","1"],["104365","0.06","0","2"],["104363.5","0.09757082","0","1"],["104362.1","0.01099591","0","1"],["104362","0.12","0","1"],["104361.9","0.0105959","0","1"],["104361.8","0.28938925","0","1"],["104361.6","0.000015","0","1"],["104361.5","0.00001","0","1"],["104360.9","0.01099591","0","1"],["104360.8","0.09","0","3"],["104360.6","0.77866876","0","1"],["104360","0.00220843","0","3"],["104359.5","0.12","0","1"],["104358.8","0.07298372","0","1"],["104357.9","0.01319591","0","2"],["104356.9","0.04634752","0","1"],["104354.5","0.0105947","0","1"],["104353.5","0.00001","0","1"],["104352.4","0.11570969","0","1"],["104352.3","0.1205","0","1"],["104351.7","0.07298372","0","1"],["104351.2","0.120015","0","2"],["104350.2","0.07188","0","1"],["104350","0.00032024","0","2"],["104348.3","0.23360363","0","1"],["104348.2","0.77866876","0","1"],["104345.5","0.02873074","0","1"],["104343.4","0.00001","0","1"],["104343.2","0.0579344","0","1"],["104342.4","0.0105947","0","1"],["104341.6","0.00001","0","1"],["104340.8","0.00001501","0","1"],["104340.7","0.85782283","0","1"],["104340.6","2.56317","0","1"],["104340.4","0.01059492","0","1"],["104340.3","0.23163255","0","1"],["104340","0.00219843","0","2"],["104339.6","0.0001","0","1"],["104338.1","0.00085478","0","1"],["104337.9","0.0013452","0","1"],["104336.5","0.00095678","0","1"],["104336.4","0.01053561","0","1"],["104335.2","0.0105947","0","1"],["104335.1","0.01053561","0","1"],["104335","0.07298372","0","1"],["104334.4","0.77866876","0","1"],["104333.3","0.01076792","0","2"],["104333","0.01059492","0","1"],["104332.9","2.82157","0","1"],["104331.9","0.25083422","0","3"],["104331.8","0.01053755","0","1"],["104331.3","0.00056666","0","1"],["104330.4","0.000015","0","1"],["104330.1","0.01053755","0","1"],["104330","0.00028006","0","1"],["104329.8","0.01056256","0","3"],["104328.3","0.00478556","0","1"],["104327.8","0.02107316","0","2"],["104327.5","0.0026904","0","1"],["104326.5","0.01053755","0","1"],["104326.4","0.07298372","0","1"],["104324.2","0.01053755","0","1"],["104323.5","0.23676189","0","1"],["104323.2","0.77866876","0","1"],["104322.4","0.01053755","0","1"],["104321.8","0.01053755","0","1"],["104321.2","0.01059517","0","1"],["104321","0.0316161","0","3"],["104320.9","0.1913","0","1"],["104320","0.00222343","0","4"],["104318.9","0.01053755","0","1"],["104318.8","0.07298372","0","1"],["104317.9","0.00001","0","1"],["104317","0.06","0","2"],["104316.4","0.07191","0","1"],["104315","0.29253729","0","1"],["104314.9","0.03","0","1"],["104314.2","0.00008603","0","1"],["104313.9","0.0001844","0","1"],["104312.8","0.09","0","3"],["104312.7","0.77866876","0","1"],["104311","0.01059526","0","1"],["104310.8","0.00094847","0","1"],["104310.5","0.1205","0","1"],["104310.3","2.57666","0","1"],["104310.2","0.01128","0","1"],["104310","0.00028006","0","1"],["104309.6","0.000015","0","1"],["104308.5","0.04308984","0","1"],["104308.2","0.00017476","0","1"],["104307.1","0.07298372","0","1"],["104306.8","0.27407485","0","1"],["104306.4","0.00957112","0","2"],["104305.9","0.00001","0","1"],["104304.8","0.16083","0","1"],["104303.4","0.14","0","1"],["104302.1","0.77866876","0","1"],["104302","0.00001","0","1"],["104301","0.00036","0","1"],["104300.6","0.01448862","0","1"],["104300.3","0.04800131","0","1"],["104300","0.00368303","0","7"],["104299.2","0.00001501","0","1"],["104298","0.00286","0","2"],["104297.3","0.13591292","0","1"],["104297","0.00286","0","2"],["104295.3","0.001844","0","1"],["104295.1","0.000419","0","1"],["104294.1","0.00001","0","1"],["104291.4","0.77866876","0","1"],["104290.3","0.00005072","0","1"],["104290","0.00028006","0","1"],["104289.4","0.00139512","0","1"]],"ts":"1747170999301","checksum":-1403528294,"seqId":54226718828,"prevSeqId":-1}]}
{"arg":{"channel":"books","instId":"BTC-USDT"},"action":"update","data":[{"asks":[["104490.1","0.005","0","1"],["104502.6","0.005","0","1"],["104520.2","0.0002898","0","1"],["104521.3","0.13872488","0","1"],["104628.8","0","0","0"],["104629.5","0","0","0"],["104629.6","0","0","0"]],"bids":[["104472.9","0.13872537","0","1"],["104472.8","0.19242972","0","1"],["104471.2","0.00978362","0","2"],["104458.7","0.005","0","1"],["104290","0","0","0"],["104289.4","0","0","0"]],"ts":"1747170999501","checksum":-191133864,"seqId":54226718839,"prevSeqId":54226718828}]}
{"arg":{"channel":"books","instId":"BTC-USDT"},"action":"update","data":[{"asks":[["104617.9","0","0","0"],["104628.8","0.07298372","0","1"]],"bids":[["104487.9","0.46392131","0","17"],["104363.3","0.22969","0","1"],["104331.9","0.02107122","0","2"],["104290.3","0","0","0"]],"ts":"1747170999601","checksum":-1863562107,"seqId":54226718845,"prevSeqId":54226718839}]}
{"arg":{"channel":"books","instId":"BTC-USDT"},"action":"update","data":[{"asks":[["104501.4","0.25436766","0","1"],["104501.5","0","0","0"],["104503.6","0","0","0"],["104504.8","0.00478362","0","1"],["104505.6","0.00478556","0","1"],["104520","0.00330992","0","4"],["104521","0","0","0"],["104521.3","0.13872477","0","1"],["104522","0.002","0","2"],["104523","0.001","0","1"],["104541","0","0","0"],["104542","0.00002848","0","1"],["104543","0.16","0","2"],["104544","0.67439814","0","4"],["104545","0.12","0","3"],["104546","0.035","0","1"],["104628.8","0","0","0"]],"bids":[["104472.2","0.00478362","0","1"],["104471.2","0.005","0","1"],["104470.5","0","0","0"],["104468.1","0.00106586","0","1"],["104291.4","0","0","0"]],"ts":"1747170999701","checksum":-1863562107,"seqId":54226718933,"prevSeqId":54226718845}]}
{"arg":{"channel":"books","instId":"BTC-USDT"},"action":"update","data":[{"asks":[["104503.6","0.00478362","0","1"],["104504.8","0","0","0"],["104522","0","0","0"],["104523","0.002","0","2"],["104524","0.00101723","0","2"],["104531","0.7285421","0","2"],["104543","0","0","0"],["104544","0.65439814","0","3"],["104545","0.24999999","0","5"],["104546","0.085","0","2"],["104557.2","0","0","0"],["104628.8","0.07298372","0","1"],["104629.5","0.00010997","0","1"],["104629.6","0.000096","0","1"]],"bids":[["104472.2","0","0","0"],["104471.3","0.00478362","0","1"],["104446.8","0.70168684","0","1"],["104415.4","1.33287226","0","2"],["104294.1","0","0","0"]],"ts":"1747170999801","checksum":-1863562107,"seqId":54226718970,"prevSeqId":54226718933}]}
{"arg":{"channel":"books","instId":"BTC-USDT"},"action":"update","data":[{"asks":[["104501.4","0.45617233","0","2"],["104501.6","0.77866876","0","1"],["104522","0.002","0","2"],["104523","0.001","0","1"],["104524","0.00001723","0","1"],["104543","0.16","0","2"],["104544","0.67439814","0","4"],["104545","0.12","0","3"],["104546","0.035","0","1"],["104552","0.01099627","0","1"],["104628.8","0","0","0"],["104629.5","0","0","0"],["104629.6","0","0","0"]],"bids":[],"ts":"1747170999901","checksum":-1863562107,"seqId":54226718985,"prevSeqId":54226718970}]}
{"arg":{"channel":"books","instId":"BTC-USDT"},"action":"update","data":[{"asks":[["104504.3","0.0383585","0","1"],["104628.7","0","0","0"]],"bids":[],"ts":"1747171000001","checksum":-1863562107,"seqId":54226719059,"prevSeqId":54226718985}]}
{"arg":{"channel":"books","instId":"BTC-USDT"},"action":"update","data":[{"asks":[["104520","0.00530992","0","6"],["104521","0.001","0","1"],["104522","0","0","0"],["104523","0","0","0"],["104542","0.10002848","0","3"],["104543","0.21","0","3"],["104544","0.57439814","0","2"],["104545","0.07","0","2"],["104556","0","0","0"],["104556.6","0.00056666","0","1"],["104628.7","0.00001176","0","1"]],"bids":[["104473.6","0.13872494","0","1"],["104472.9","0","0","0"],["104449.2","0.00955862","0","1"],["104447.7","0","0","0"],["104423","0.00056666","0","1"],["104421.1","0","0","0"],["104334.2","0.00056666","0","1"],["104331.3","0","0","0"]],"ts":"1747171000101","checksum":-1863562107,"seqId":54226719088,"prevSeqId":54226719059}]}
{"arg":{"channel":"books","instId":"BTC-USDT"},"action":"update","data":[{"asks":[["104520.4","0.33115538","0","2"],["104521.3","0","0","0"],["104538","1","0","1"],["104541","0.16","0","2"],["104542","0.25002847","0","6"],["104543","0.085","0","2"],["104544","0.49439815","0","1"],["104545","0","0","0"],["104546","0","0","0"],["104628.8","0.07298372","0","1"]],"bids":[["104473.6","0","0","0"],["104472.9","0.13872542","0","1"],["104389.2","0.00010644","0","2"],["104389.1","0.01099591","0","1"]],"ts":"1747171000201","checksum":-1863562107,"seqId":54226719115,"prevSeqId":54226719088}]}
{"arg":{"channel":"books","instId":"BTC-USDT"},"action":"update","data":[{"asks":[["104520","0.00330992","0","4"],["104520.4","0.19242972","0","1"],["104521","0","0","0"],["104522","0.002","0","2"],["104523","0.001","0","1"],["104525.1","0.13872398","0","1"],["104541","0","0","0"],["104542","0.00002848","0","1"],["104543","0.16","0","2"],["104544","0.74439814","0","6"],["104545","0.085","0","2"],["104628.7","0","0","0"],["104628.8","0","0","0"]],"bids":[["104474.6","0.13872398","0","1"],["104472.9","0","0","0"]],"ts":"1747171000301","checksum":-1863562107,"seqId":54226719150,"prevSeqId":54226719115}]}
{"arg":{"channel":"books","instId":"BTC-USDT"},"action":"update","data":[{"asks":[["104500.7","0.00478362","0","1"],["104503.6","0","0","0"],["104520.5","0.50780738","0","2"],["104525.1","0","0","0"],["104628.7","0.00001176","0","1"]],"bids":[["104487.9","0.46390996","0","17"],["104474.6","0","0","0"],["104472.9","0.1387256","0","1"],["104471.3","0","0","0"],["104468.9","0.00478362","0","1"]],"ts":"1747171000401","checksum":-2075028628,"seqId":54226719227,"prevSeqId":54226719150}]}
{"arg":{"channel":"books","instId":"BTC-USDT"},"action":"update","data":[{"asks":[["104488","0.24872074","0","8"],["104496.4","0","0","0"],["104496.5","0.00011435","0","1"],["104496.6","0.0938365","0","1"],["104498.7","0","0","0"],["104498.8","0.08977219","0","1"],["104500.7","0","0","0"],["104502","0","0","0"],["104502.1","0.1649662","0","2"],["104503.6","0.00478362","0","1"],["104504.9","0.3546903","0","2"],["104505.4","0","0","0"],["104505.5","0.23401161","0","1"],["104507.5","0.04","0","1"],["104507.6","0.24980525","0","1"],["104511.2","0.17829353","0","1"],["104511.3","0.24447808","0","1"],["104520","0.00530992","0","6"],["104520.5","0.36908178","0","1"],["104521","0.001","0","1"],["104521.3","0.13872447","0","1"],["104522","0","0","0"],["104523","0","0","0"],["104541","0.16","0","2"],["104542","0.25002847","0","6"],["104543","0.085","0","2"],["104544","0.49439815","0","1"],["104545","0","0","0"],["104628.7","0","0","0"]],"bids":[["104483.4","0.0017149","0","1"],["104480.1","0.0005","0","1"],["104478.3","0.25720767","0","1"],["104476.3","0.09793444","0","1"],["104476.2","0","0","0"],["104475.6","0.10184449","0","1"],["104475.5","0","0","0"],["104474.6","0.15642602","0","1"],["104474.5","0","0","0"],["104473.9","0.13872443","0","1"],["104472.9","0","0","0"],["104471.3","0.00478362","0","1"],["104470.5","0.23340748","0","1"],["104470.4","0","0","0"],["104468.9","0","0","0"],["104464.6","0.26586221","0","2"],["104464.5","0","0","0"],["104463.8","0.25054076","0","1"],["104463.7","0","0","0"],["104444.9","0","0","0"],["104421.3","0.002871","0","1"]],"ts":"1747171000501","checksum":-1353716071,"seqId":54226719311,"prevSeqId":54226719227}]}
{"arg":{"channel":"books","instId":"BTC-USDT"},"action":"update","data":[{"asks":[["104520","0.00330992","0","4"],["104521","0","0","0"],["104522","0.002","0","2"],["104523","0.001","0","1"],["104541","0","0","0"],["104542","0.00002848","0","1"],["104543","0.16","0","2"],["104544","0.67439814","0","4"],["104545","0.12","0","3"],["104546","0.035","0","1"],["104627.8","0","0","0"],["104628.6","0","0","0"]],"bids":[["104428.7","0","0","0"],["104294.1","0.00001","0","1"]],"ts":"1747171000701","checksum":-1353716071,"seqId":54226719373,"prevSeqId":54226719311}]}
{"arg":{"channel":"books","instId":"BTC-USDT"},"action":"update","data":[{"asks":[["104522","0","0","0"],["104523","0.002","0","2"],["104524","0.00101723","0","2"],["104535.7","0.94462004","0","2"],["104543","0","0","0"],["104544","0.65439815","0","3"],["104545","0.24999999","0","5"],["104546","0.085","0","2"],["104546.2","0","0","0"],["104627.8","0.00001104","0","1"],["104628.6","0.0001","0","1"],["104628.7","0.00001176","0","1"]],"bids":[["104473.9","0","0","0"],["104472.9","0.13872539","0","1"],["104457.4","0.21874048","0","2"],["104424.5","0.20869903","0","1"],["104294.1","0","0","0"]],"ts":"1747171000801","checksum":-1353716071,"seqId":54226719428,"prevSeqId":54226719373}]}
{"arg":{"channel":"books","instId":"BTC-USDT"},"action":"update","data":[{"asks":[["104488","0.36822074","0","9"],["104496.2","0.00011435","0","1"],["104496.3","0.09834595","0","2"],["104496.5","0","0","0"],["104496.6","0","0","0"],["104497","0.09855757","0","2"],["104497.2","0","0","0"],["104498","0.09580323","0","1"],["104498.2","0.03141905","0","1"],["104498.5","0.33377307","0","2"],["104498.8","0","0","0"],["104501.5","0.16105349","0","1"],["104501.7","0","0","0"],["104501.8","0.16767684","0","1"],["104502","0.16684446","0","1"],["104502.1","0.00001","0","1"],["104502.2","0.00478491","0","1"],["104504.7","0.14728848","0","1"],["104504.9","0.34076286","0","2"],["104505","0.0599306","0","1"],["104505.2","0.25311388","0","1"],["104505.5","0","0","0"],["104507","0.26430241","0","1"],["104507.2","0","0","0"],["104507.3","0.24642267","0","1"],["104507.6","0","0","0"],["104511","0.26228988","0","1"],["104511.3","0","0","0"],["104520","0.00530992","0","6"],["104521","0.001","0","1"],["104523","0","0","0"],["104524","0.00001723","0","1"],["104541","0.16","0","2"],["104542","0.08002847","0","2"],["104544","0.49439815","0","1"],["104545","0.17","0","4"],["104628.6","0","0","0"],["104628.7","0","0","0"]],"bids":[["104487.9","0.49914132","0","18"],["104483.4","0","0","0"],["104480.1","0.0022149","0","2"],["104478.3","0.28171757","0","2"],["104477.7","0","0","0"],["104477.5","0.18963124","0","2"],["104476.3","0","0","0"],["104476","0.09436471","0","2"],["104475.6","0","0","0"],["104475.3","0.09971756","0","1"],["104474.6","0","0","0"],["104474.3","0.16573716","0","2"],["104474.2","0","0","0"],["104474","0.14312074","0","1"],["104472.7","0","0","0"],["104472.5","0.18586732","0","2"],["104472.1","0.68316939","0","2"],["104470.5","0","0","0"],["104470.2","0.22842506","0","1"],["104470.1","1.14775054","0","2"],["104470","0.09349006","0","3"],["104469.7","0.16680925","0","1"],["104467.7","0","0","0"],["104467.6","0.42551164","0","2"],["104467.5","0.26629987","0","1"],["104464.6","0.00001","0","1"],["104464.3","0.26719086","0","1"],["104463.8","0","0","0"],["104463.5","0.24797455","0","1"],["104436.2","0","0","0"],["104294.1","0.00001","0","1"],["104291.4","0.77866876","0","1"],["104290.3","0.00005072","0","1"]],"ts":"1747171000901","checksum":1435889829,"seqId":54226719510,"prevSeqId":54226719428}]}
{"arg":{"channel":"books","instId":"BTC-USDT"},"action":"update","data":[{"asks":[["104501.7","0.00478362","0","1"],["104503.6","0","0","0"],["104542","0.25002847","0","6"],["104543","0.085","0","2"],["104545","0","0","0"],["104546","0","0","0"],["104628.6","0.0001","0","1"]],"bids":[["104471.3","0","0","0"],["104470.1","1.15253416","0","3"],["104468.7","0.01472078","0","1"],["104468.1","0","0","0"],["104434","0.0476405","0","1"]],"ts":"1747171001001","checksum":1435889829,"seqId":54226719530,"prevSeqId":54226719510}]}
{"arg":{"channel":"books","instId":"BTC-USDT"},"action":"update","data":[{"asks":[["104501.7","0","0","0"],["104502.1","0.00479362","0","2"],["104521.3","0","0","0"],["104525","0.1387236","0","1"],["104556.3","0.00056666","0","1"],["104556.6","0","0","0"],["104628.7","0.00001176","0","1"]],"bids":[["104474.5","0.1387236","0","1"],["104472.9","0","0","0"],["104470.3","0.00478362","0","1"],["104470.1","1.14775054","0","2"],["104468.9","0.01472078","0","1"],["104468.7","0","0","0"],["104459.9","0.054781","0","3"],["104451.5","0.00955841","0","1"],["104449.2","0","0","0"],["104423","0","0","0"],["104422.5","0.00056666","0","1"],["104421.3","0","0","0"],["104334.2","0","0","0"],["104333.6","0.00056666","0","1"]],"ts":"1747171001101","checksum":1435889829,"seqId":54226719602,"prevSeqId":54226719530}]}
{"arg":{"channel":"books","instId":"BTC-USDT"},"action":"update","data":[{"asks":[["104518","0.002","0","2"],["104519","0.001","0","1"],["104520","0.00330992","0","4"],["104521","0","0","0"],["104521.3","0.13872484","0","1"],["104525","0","0","0"],["104538","0","0","0"],["104539","0.63497897","0","4"],["104540","0.80775085","0","12"],["104541","0.085","0","2"],["104542","0.00002848","0","1"],["104543","0","0","0"],["104628.8","0.07298372","0","1"]],"bids":[["104474.5","0","0","0"],["104473.9","0.13872484","0","1"],["104459.9","0.05191","0","2"],["104440.9","0.002871","0","1"],["104290.3","0","0","0"]],"ts":"1747171001201","checksum":1435889829,"seqId":54226719633,"prevSeqId":54226719602}]}
{"arg":{"channel":"books","instId":"BTC-USDT"},"action":"update","data":[{"asks":[["104488","0.37142074","0","10"],["104496.2","0","0","0"],["104496.3","0.09974654","0","2"],["104496.8","0.00011435","0","1"],["104497","0.09415679","0","2"],["104498","0.0865453","0","1"],["104498.5","0.33010153","0","2"],["104501.4","0.25436766","0","1"],["104501.5","0.16315017","0","1"],["104501.6","0","0","0"],["104501.8","0.16504611","0","1"],["104502","0.15734573","0","1"],["104502.1","0.00001","0","1"],["104502.5","0.00478362","0","1"],["104504.3","0","0","0"],["104504.7","0.16102847","0","1"],["104504.9","0.34413408","0","2"],["104505.2","0.25742937","0","1"],["104507","0.26170845","0","1"],["104507.3","0.25593853","0","1"],["104511","0.26512934","0","1"],["104629.5","0.00010997","0","1"]],"bids":[["104487.9","0.88982618","0","20"],["104478.3","0.28139453","0","2"],["104477.5","0.17768632","0","2"],["104476","0.08760626","0","2"],["104475.3","0.09394414","0","1"],["104474.3","0.17789529","0","2"],["104474","0.15436261","0","1"],["104473.9","0","0","0"],["104472.9","0.13872532","0","1"],["104472.5","0.18672078","0","2"],["104470.2","0.24626685","0","1"],["104469.7","0.16140405","0","1"],["104467.6","0.33924042","0","2"],["104467.5","0.25675792","0","1"],["104464.3","0.2714523","0","1"],["104463.5","0.23713661","0","1"]],"ts":"1747171001301","checksum":-1870077284,"seqId":54226719702,"prevSeqId":54226719633}]}
{"arg":{"channel":"books","instId":"BTC-USDT"},"action":"update","data":[{"asks":[["104496.2","0.00011435","0","1"],["104496.8","0","0","0"],["104497.5","0.3226682","0","1"],["104501","0.00478362","0","1"],["104501.3","0.49084967","0","3"],["104501.4","0.77866876","0","1"],["104502.5","0","0","0"],["104506","0.0384185","0","2"],["104521.3","0","0","0"],["104525.1","0.13872383","0","1"],["104590.7","0","0","0"],["104591.2","0","0","0"],["104591.5","0.01345383","0","1"],["104629.6","0.000096","0","1"]],"bids":[["104487.9","0.58687375","0","12"],["104474.4","0.13872383","0","1"],["104472.9","0","0","0"],["104470.3","0","0","0"],["104470.1","0.77866876","0","1"],["104469","0.00478362","0","1"],["104446.8","0","0","0"],["104446.7","0","0","0"],["104415.4","0.45468381","0","1"],["104415.3","0","0","0"],["104290.3","0.00005072","0","1"],["104290","0.00028006","0","1"],["104289.4","0.00139512","0","1"]],"ts":"1747171001401","checksum":-1797578705,"seqId":54226719739,"prevSeqId":54226719702}]}
{"arg":{"channel":"books","instId":"BTC-USDT"},"action":"update","data":[{"asks":[["104496.3","0.10213354","0","2"],["104497","0.09890662","0","2"],["104498","0.09295117","0","1"],["104498.5","0.33020805","0","2"],["104501.3","0.34375198","0","3"],["104501.5","0.16087155","0","1"],["104501.8","0.15094892","0","1"],["104502","0.16884656","0","1"],["104504.7","0.16029505","0","1"],["104504.9","0.35052739","0","2"],["104505.2","0.23312091","0","1"],["104507","0.25110967","0","1"],["104507.3","0.27379833","0","1"],["104511","0.2617493","0","1"],["104518","0","0","0"],["104519","0","0","0"],["104520","0.00530992","0","6"],["104521","0.001","0","1"],["104521.3","0.13872449","0","1"],["104525.1","0","0","0"],["104535.7","0.469538","0","1"],["104539","0.47497897","0","2"],["104540","0.55775086","0","7"],["104541","0.16","0","2"],["104542","0.25002847","0","6"],["104543","0.085","0","2"]],"bids":[["104487.9","0.62523225","0","13"],["104478.3","0.32728445","0","2"],["104477.5","0.19222938","0","2"],["104476","0.09542451","0","2"],["104475.3","0.09413489","0","1"],["104474.4","0","0","0"],["104474.3","0.1619374","0","2"],["104474","0.16201147","0","1"],["104472.9","0.13872536","0","1"],["104472.5","0.19046125","0","2"],["104470.2","0.23446968","0","1"],["104469.7","0.16713113","0","1"],["104467.6","0.41794382","0","2"],["104467.5","0.2615648","0","1"],["104464.3","0.23887038","0","1"],["104463.5","0.25580404","0","1"],["104449.5","1.46814282","0","2"],["104418.2","2.48053221","0","1"],["104289.4","0","0","0"]],"ts":"1747171001501","checksum":1117594692,"seqId":54226719843,"prevSeqId":54226719739}]}
{"arg":{"channel":"books","instId":"BTC-USDT"},"action":"update","data":[{"asks":[["104496.2","0","0","0"],["104496.3","0.09507836","0","2"],["104496.8","0.00011435","0","1"],["104497","0.09650868","0","2"],["104498","0.09244625","0","1"],["104498.5","0.3261273","0","2"],["104501","0","0","0"],["104501.5","0.16137824","0","1"],["104501.8","0.1687154","0","1"],["104502","0.16463489","0","1"],["104502.5","0.00478363","0","1"],["104504.7","0.16272719","0","1"],["104504.9","0.34669327","0","2"],["104505.2","0.25154178","0","1"],["104507","0.24676587","0","1"],["104507.3","0.24694085","0","1"],["104511","0.2421209","0","1"],["104518.6","0.13873051","0","1"],["104521.3","0","0","0"],["104570","0.264023","0","3"],["104598.9","0.00095603","0","1"],["104629.6","0","0","0"]],"bids":[["104478.3","0.28865132","0","2"],["104477.5","0.18878107","0","2"],["104476","0.09610185","0","2"],["104475.3","0.10211756","0","1"],["104474.3","0.17437349","0","2"],["104474","0.15430996","0","1"],["104472.9","0","0","0"],["104472.5","0.18284159","0","2"],["104470.2","0.24354474","0","2"],["104469.7","0.15906615","0","1"],["104469.6","0.13970051","0","2"],["104469","0","0","0"],["104467.8","0.41479453","0","2"],["104467.6","0","0","0"],["104467.5","0.24984324","0","1"],["104464.3","0.26679603","0","1"],["104463.5","0.23572926","0","1"],["104289.4","0.00139512","0","1"],["104288.8","0.000015","0","1"]],"ts":"1747171001601","checksum":1905697099,"seqId":54226719977,"prevSeqId":54226719843}]}
{"arg":{"channel":"books","instId":"BTC-USDT"},"action":"update","data":[{"asks":[["104501.4","0","0","0"],["104502.5","0","0","0"],["104503.6","0.00478363","0","1"],["104518.6","0","0","0"],["104519.8","0.13872804","0","1"],["104629.6","0.000096","0","1"]],"bids":[["104471.1","0.14351167","0","2"],["104470.2","0.23876111","0","1"],["104469.6","0.00097","0","1"],["104288.8","0","0","0"]],"ts":"1747171001701","checksum":1905697099,"seqId":54226719989,"prevSeqId":54226719977}]}
{"arg":{"channel":"books","instId":"BTC-USDT"},"action":"update","data":[{"asks":[["104496.3","0.00001","0","1"],["104496.6","0.10207289","0","1"],["104496.8","0","0","0"],["104497","0.005","0","1"],["104497.2","0.09455523","0","1"],["104497.4","0.00011435","0","1"],["104498","0","0","0"],["104498.2","0.12663222","0","2"],["104498.5","0.234","0","1"],["104498.8","0.09078719","0","1"],["104501.3","0.24127924","0","4"],["104501.5","0","0","0"],["104501.7","0.15885184","0","1"],["104501.8","0","0","0"],["104502","0","0","0"],["104502.1","0.16058292","0","2"],["104502.2","0.16412394","0","2"],["104504.7","0","0","0"],["104504.9","0.39988576","0","2"],["104505","0.21946719","0","2"],["104505.2","0","0","0"],["104505.5","0.24184319","0","1"],["104507","0","0","0"],["104507.2","0.26792905","0","1"],["104507.3","0","0","0"],["104507.6","0.25324797","0","1"],["104511","0","0","0"],["104511.3","0.23934275","0","1"],["104519.8","0","0","0"],["104521.3","0.13872447","0","1"],["104546.2","0.01064277","0","1"],["104572.2","5.67093892","0","1"],["104575.5","0.05057082","0","2"],["104629.6","0","0","0"]],"bids":[["104478.3","0.32865529","0","2"],["104477.7","0.19597793","0","2"],["104477.5","0","0","0"],["104476.3","0.09905084","0","1"],["104476","0.000015","0","1"],["104475.6","0.09827448","0","1"],["104475.3","0","0","0"],["104474.6","0.15436991","0","1"],["104474.3","0.0087017","0","1"],["104474.2","0.15391617","0","1"],["104474","0","0","0"],["104473.9","0.13872447","0","1"],["104472.7","0.16038","0","1"],["104472.5","0.02929425","0","1"],["104471.1","0.00478363","0","1"],["104470.5","0.23874991","0","1"],["104470.2","0","0","0"],["104470","0.24531293","0","4"],["104469.7","0","0","0"],["104467.8","0.42244852","0","2"],["104467.7","0.24986985","0","1"],["104467.5","0","0","0"],["104464.6","0.26879012","0","2"],["104464.3","0","0","0"],["104463.8","0.25923187","0","1"],["104463.5","0","0","0"],["104452.1","0.88818959","0","2"],["104419.2","1.28716811","0","2"],["104290","0","0","0"],["104289.4","0","0","0"]],"ts":"1747171001801","checksum":1420841495,"seqId":54226720079,"prevSeqId":54226719989}]}
{"arg":{"channel":"books","instId":"BTC-USDT"},"action":"update","data":[{"asks":[["104496.3","0.08935538","0","2"],["104496.6","0","0","0"],["104496.8","0.00011435","0","1"],["104497","0.10638229","0","2"],["104497.2","0","0","0"],["104497.4","0","0","0"],["104498","0.09402756","0","1"],["104498.2","0.03141905","0","1"],["104498.5","0.32566819","0","2"],["104498.8","0","0","0"],["104501.3","0.24211697","0","4"],["104501.5","0.16139135","0","1"],["104501.7","0","0","0"],["104501.8","0.15696217","0","1"],["104502","0.16320272","0","1"],["104502.1","0.00001","0","1"],["104502.2","0.00478491","0","1"],["104504.7","0.1602955","0","1"],["104504.9","0.34474022","0","2"],["104505","0.0599306","0","1"],["104505.2","0.23908276","0","1"],["104505.5","0","0","0"],["104507","0.24258827","0","1"],["104507.2","0","0","0"],["104507.3","0.25706731","0","1"],["104507.6","0","0","0"],["104511","0.25938337","0","1"],["104511.3","0","0","0"],["104518.6","0.13872895","0","1"],["104521.3","0","0","0"],["104629.5","0","0","0"]],"bids":[["104487.9","0.62526225","0","14"],["104478.3","0.27952739","0","2"],["104477.7","0","0","0"],["104477.5","0.18488876","0","2"],["104476.3","0","0","0"],["104476","0.09611697","0","2"],["104475.6","0","0","0"],["104475.3","0.09393518","0","1"],["104474.6","0","0","0"],["104474.3","0.16004031","0","2"],["104474.2","0","0","0"],["104474","0.15028959","0","1"],["104473.9","0","0","0"],["104472.7","0","0","0"],["104472.5","0.19818453","0","2"],["104470.5","0","0","0"],["104470.3","0.13872895","0","1"],["104470.2","0.23105651","0","1"],["104470","0.09349006","0","3"],["104469.7","0.16236207","0","1"],["104467.8","0.42420727","0","2"],["104467.7","0","0","0"],["104467.5","0.27180673","0","1"],["104464.6","0.00001","0","1"],["104464.3","0.24686198","0","1"],["104463.8","0","0","0"],["104463.5","0.26507564","0","1"],["104290","0.00028006","0","1"]],"ts":"1747171001901","checksum":437067517,"seqId":54226720154,"prevSeqId":54226720079}]}
{"arg":{"channel":"books","instId":"BTC-USDT"},"action":"update","data":[{"asks":[["104503.6","0.00478413","0","1"],["104550.5","0.00056666","0","1"],["104556.3","0","0","0"],["104584.4","0.01059606","0","1"],["104594.8","0","0","0"],["104629.5","0.00010997","0","1"]],"bids":[["104472","0.09798413","0","2"],["104471.1","0","0","0"],["104470.3","0","0","0"],["104469.8","0.36908178","0","1"],["104468.1","0.13873169","0","1"],["104453.8","0.0095582","0","1"],["104451.5","0","0","0"],["104422.5","0","0","0"],["104421.2","0.00056666","0","1"],["104337.9","0","0","0"],["104335.2","0.01116136","0","2"],["104333.6","0","0","0"],["104327.5","0","0","0"],["104289.4","0.00139512","0","1"],["104288.8","0.000015","0","1"],["104288.6","0.0001","0","1"]],"ts":"1747171002101","checksum":437067517,"seqId":54226720198,"prevSeqId":54226720154}]}
{"arg":{"channel":"books","instId":"BTC-USDT"},"action":"update","data":[{"asks":[["104501","0.00478413","0","1"],["104503.6","0","0","0"],["104515.3","0.13873254","0","1"],["104518.6","0","0","0"],["104537","1.02869923","0","2"]],"bids":[["104487.9","0.6252509","0","14"],["104483.4","0.0017149","0","1"],["104480.1","0.0005","0","1"],["104476.4","0.03302681","0","1"],["104472","0.0932","0","1"],["104469","0.00478413","0","1"],["104468.1","0.13873242","0","1"],["104460.9","0.00711203","0","1"],["104389.3","0.00009948","0","1"],["104389.2","0.00001","0","1"],["104290","0","0","0"],["104289.4","0","0","0"],["104288.8","0","0","0"],["104288.6","0","0","0"]],"ts":"1747171002201","checksum":691981332,"seqId":54226720232,"prevSeqId":54226720198}]}
{"arg":{"channel":"books","instId":"BTC-USDT"},"action":"update","data":[{"asks":[["104524.6","0.0957","0","1"],["104530.8","0","0","0"]],"bids":[],"ts":"1747171002301","checksum":691981332,"seqId":54226720239,"prevSeqId":54226720232}]}
{"arg":{"channel":"books","instId":"BTC-USDT"},"action":"update","data":[{"asks":[["104501.1","0.48908184","0","2"],["104501.2","0.77866876","0","1"],["104501.3","0.00009573","0","2"],["104513.2","0.01","0","1"],["104628.8","0","0","0"],["104629.5","0","0","0"]],"bids":[["104487.9","0.6252709","0","15"],["104483.4","0","0","0"],["104480.1","0.0022149","0","2"],["104375.1","0.01059606","0","1"]],"ts":"1747171002401","checksum":2121370151,"seqId":54226720294,"prevSeqId":54226720239}]}
{"arg":{"channel":"books","instId":"BTC-USDT"},"action":"update","data":[{"asks":[["104512.8","0.13873602","0","1"],["104515.3","0","0","0"]],"bids":[["104468.1","0","0","0"],["104465.7","0.13873602","0","1"]],"ts":"1747171002501","checksum":2121370151,"seqId":54226720338,"prevSeqId":54226720294}]}
{"arg":{"channel":"books","instId":"BTC-USDT"},"action":"update","data":[{"asks":[["104501.1","0.25545249","0","2"],["104501.2","0","0","0"],["104512.8","0","0","0"],["104518.6","0.13873257","0","1"],["104590.4","0.07171","0","1"],["104592.4","0.0478","0","1"],["104602.3","0.0013452","0","1"],["104620.2","0.0026904","0","1"],["104627.8","0","0","0"],["104628.6","0","0","0"],["104628.7","0","0","0"]],"bids":[["104483.4","0.0017149","0","1"],["104480.1","0.0005","0","1"],["104468.1","0.13873257","0","1"],["104465.7","0","0","0"],["104366","0.0013452","0","1"],["104355.6","0.0026904","0","1"],["104294.1","0","0","0"],["104291.4","0","0","0"],["104290.3","0","0","0"]],"ts":"1747171002601","checksum":-1075848199,"seqId":54226720413,"prevSeqId":54226720338}]}
{"arg":{"channel":"books","instId":"BTC-USDT"},"action":"update","data":[{"asks":[["104501","0","0","0"],["104501.7","0.00478368","0","1"],["104518.6","0","0","0"],["104519.8","0.1387278","0","1"],["104572.2","5.71278197","0","1"]],"bids":[["104487.9","0.5869124","0","14"],["104471.1","0.1387278","0","1"],["104470.2","0.23584019","0","2"],["104469.8","0","0","0"],["104469","0","0","0"],["104468.1","0","0","0"],["104294.1","0.00001","0","1"],["104291.4","0.77866876","0","1"]],"ts":"1747171002701","checksum":854473795,"seqId":54226720477,"prevSeqId":54226720413}]}
{"arg":{"channel":"books","instId":"BTC-USDT"},"action":"update","data":[{"asks":[["104501.7","0","0","0"],["104502.1","0.00479368","0","2"],["104535.7","0.94462004","0","2"],["104572.2","0","0","0"],["104575.5","5.76335279","0","3"],["104627.8","0.00001104","0","1"],["104628.6","0.0001","0","1"]],"bids":[["104483.4","0","0","0"],["104480.1","0.0022149","0","2"],["104470.3","0.00478368","0","1"],["104470.2","0.23105651","0","1"],["104442.5","0.25682687","0","1"],["104415.5","0.29576464","0","2"],["104291.4","0","0","0"]],"ts":"1747171002801","checksum":1430839634,"seqId":54226720515,"prevSeqId":54226720477}]}
{"arg":{"channel":"books","instId":"BTC-USDT"},"action":"update","data":[{"asks":[["104502.1","0.00001","0","1"],["104502.5","0.00478368","0","1"],["104519.8","0","0","0"],["104520.2","0.13901615","0","2"],["104570.6","0","0","0"],["104608.5","0","0","0"],["104628.7","0.00001176","0","1"],["104628.8","0.07298372","0","1"]],"bids":[["104487.9","0.6252709","0","15"],["104472.9","0.13872635","0","1"],["104471.1","0","0","0"]],"ts":"1747171002901","checksum":2121370151,"seqId":54226720554,"prevSeqId":54226720515}]}
{"arg":{"channel":"books","instId":"BTC-USDT"},"action":"update","data":[{"asks":[["104501","0.00478368","0","1"],["104502.5","0","0","0"],["104520.2","0.0002898","0","1"],["104521.3","0.13872546","0","1"],["104591.5","0","0","0"]],"bids":[["104473.6","0.13872546","0","1"],["104472.9","0","0","0"],["104470.3","0","0","0"],["104469","0.00478368","0","1"]],"ts":"1747171003001","checksum":2121370151,"seqId":54226720564,"prevSeqId":54226720554}]}
{"arg":{"channel":"books","instId":"BTC-USDT"},"action":"update","data":[{"asks":[["104488","0.25192074","0","9"],["104496.3","0.00001","0","1"],["104496.5","0.00011435","0","1"],["104496.6","0.09630465","0","1"],["104496.8","0","0","0"],["104497","0.005","0","1"],["104497.2","0.09837297","0","1"],["104497.5","0","0","0"],["104498","0","0","0"],["104498.2","0.12187539","0","2"],["104498.5","0.234","0","1"],["104498.8","0.09416396","0","1"],["104501","0","0","0"],["104501.1","0.24118492","0","3"],["104501.5","0","0","0"],["104501.7","0.15651879","0","1"],["104501.8","0","0","0"],["104502","0","0","0"],["104502.1","0.15454236","0","3"],["104502.2","0.17410214","0","2"],["104504.7","0","0","0"],["104504.9","0.31961838","0","2"],["104505","0.22113781","0","2"],["104505.2","0","0","0"],["104505.5","0.22780147","0","1"],["104507","0","0","0"],["104507.2","0.26599019","0","1"],["104507.3","0","0","0"],["104507.6","0.23949885","0","1"],["104511","0","0","0"],["104511.3","0.2639932","0","1"],["104521.3","0","0","0"],["104524.5","0.13927052","0","2"],["104535.7","0.469538","0","1"],["104537","0.02869923","0","1"],["104541.5","0","0","0"],["104550.5","0","0","0"],["104552.4","0.00061553","0","2"],["104575.4","0.23202318","0","2"],["104629.5","0.00010997","0","1"],["104629.6","0.000096","0","1"],["104629.9","0.02300636","0","1"],["104630","0.00039338","0","2"],["104630.2","0.0004067","0","2"],["104631.1","0.00001258","0","1"]],"bids":[["104487.9","0.7240209","0","16"],["104483.4","0.0017149","0","1"],["104480.1","0.0005","0","1"],["104478.3","0.32361828","0","2"],["104477.7","0.18785176","0","2"],["104477.5","0","0","0"],["104476.3","0.09268394","0","1"],["104476","0.000015","0","1"],["104475.6","0.094725","0","1"],["104475.3","0","0","0"],["104474.6","0.15888833","0","1"],["104474.4","0.13872379","0","1"],["104474.3","0.0087017","0","1"],["104474.2","0.15776296","0","1"],["104474","0","0","0"],["104473.6","0","0","0"],["104472.7","0.16508722","0","1"],["104472.5","0.02929425","0","1"],["104470.5","0.24223951","0","1"],["104470.3","0.36908178","0","1"],["104470.2","0","0","0"],["104470","0.26041312","0","4"],["104469.7","0.00478368","0","1"],["104469","0","0","0"],["104467.8","0.42113755","0","2"],["104467.7","0.24291857","0","1"],["104467.5","0","0","0"],["104464.6","0.26817828","0","2"],["104464.3","0","0","0"],["104463.8","0.26242507","0","1"],["104463.5","0","0","0"],["104456","0.009558","0","1"],["104453.8","0","0","0"],["104423.1","0.00056666","0","1"],["104421.2","0","0","0"],["104337.1","0.00056666","0","1"],["104335.2","0.0105947","0","1"],["104297","0","0","0"],["104295.3","0","0","0"],["104295.1","0","0","0"],["104294.1","0","0","0"]],"ts":"1747171003101","checksum":-2145392616,"seqId":54226720692,"prevSeqId":54226720564}]}
{"arg":{"channel":"books","instId":"BTC-USDT"},"action":"update","data":[{"asks":[["104497.5","0.32326025","0","1"],["104498.2","0.09045634","0","1"],["104498.8","0.12282918","0","2"],["104501.6","0.00478362","0","1"],["104502.1","0.14975868","0","2"],["104524.4","0.13872457","0","1"],["104524.5","0.00054673","0","1"],["104532.1","0.09901","0","2"],["104541.5","0.0001303","0","1"],["104596.7","0.01345316","0","1"],["104597.9","0.04256829","0","1"],["104600.9","0","0","0"],["104629.6","0","0","0"],["104629.9","0","0","0"],["104630","0","0","0"],["104630.2","0","0","0"],["104631.1","0","0","0"]],"bids":[["104474.4","0","0","0"],["104474.3","0.14742627","0","2"],["104469.7","0.00478362","0","1"],["104297","0.00286","0","2"]],"ts":"1747171003201","checksum":1162568060,"seqId":54226720752,"prevSeqId":54226720692}]}
{"arg":{"channel":"books","instId":"BTC-USDT"},"action":"update","data":[{"asks":[["104488","0.37142074","0","10"],["104496.2","0.00011435","0","1"],["104496.3","0.09722288","0","2"],["104496.5","0","0","0"],["104496.6","0","0","0"],["104497","0.10532622","0","2"],["104497.2","0","0","0"],["104498","0.09435742","0","1"],["104498.2","0","0","0"],["104498.5","0.32350004","0","2"],["104498.8","0.02866522","0","1"],["104501","0.00478358","0","1"],["104501.1","0.23595178","0","3"],["104501.5","0.15178288","0","1"],["104501.6","0","0","0"],["104501.7","0","0","0"],["104501.8","0.15082318","0","1"],["104502","0.16031852","0","1"],["104502.1","0.00001","0","1"],["104502.2","0.00478491","0","1"],["104504.7","0.16193569","0","1"],["104504.9","0.34764666","0","2"],["104505","0.0599306","0","1"],["104505.2","0.25917444","0","1"],["104505.5","0","0","0"],["104507","0.24839023","0","1"],["104507.2","0","0","0"],["104507.3","0.24086179","0","1"],["104507.6","0","0","0"],["104511","0.24444941","0","1"],["104511.3","0","0","0"],["104540","0.65775086","0","9"],["104541","0.21","0","3"],["104541.5","0","0","0"],["104542","0.15002847","0","4"],["104543","0.035","0","1"]],"bids":[["104487.9","0.7240009","0","15"],["104487.6","0.02270438","0","1"],["104478.3","0.32253738","0","2"],["104477.7","0","0","0"],["104477.5","0.19043324","0","2"],["104476.3","0","0","0"],["104476","0.09614628","0","2"],["104475.6","0","0","0"],["104475.3","0.09612034","0","1"],["104474.6","0","0","0"],["104474.3","0.2986621","0","3"],["104474.2","0","0","0"],["104474","0.15438752","0","1"],["104472.7","0","0","0"],["104472.5","0.18720618","0","2"],["104470.5","0","0","0"],["104470.2","0.22863754","0","1"],["104470","0.09349006","0","3"],["104469.7","0.15542184","0","1"],["104469","0.00478358","0","1"],["104467.8","0.41223205","0","2"],["104467.7","0","0","0"],["104467.5","0.24070695","0","1"],["104464.6","0.00001","0","1"],["104464.3","0.25289135","0","1"],["104463.8","0","0","0"],["104463.5","0.25022862","0","1"]],"ts":"1747171003301","checksum":1372500094,"seqId":54226720853,"prevSeqId":54226720752}]}
{"arg":{"channel":"books","instId":"BTC-USDT"},"action":"update","data":[{"asks":[["104518","0.002","0","2"],["104519","0.001","0","1"],["104520","0.00330992","0","4"],["104521","0","0","0"],["104524.4","0","0","0"],["104524.5","0.13927054","0","2"],["104526.8","0","0","0"],["104532.1","0.09681","0","1"],["104539","0.63497897","0","4"],["104540","0.73775085","0","10"],["104541","0.05","0","1"],["104541.5","0.0001303","0","1"],["104542","0.07002848","0","3"],["104546.8","0.00300324","0","2"],["104575.8","0","0","0"],["104581.8","0.01279606","0","2"],["104629.6","0.000096","0","1"]],"bids":[["104487.9","0.6856424","0","14"],["104483.4","0","0","0"],["104480.1","0.0022149","0","2"],["104474.4","0.13872381","0","1"],["104474.3","0.15993753","0","2"],["104469.1","0.00106586","0","1"],["104468.9","0","0","0"],["104447.3","0.0022","0","1"],["104429.9","0.0022","0","1"],["104428","0","0","0"],["104410.8","0","0","0"]],"ts":"1747171003401","checksum":1988133564,"seqId":54226720901,"prevSeqId":54226720853}]}
{"arg":{"channel":"books","instId":"BTC-USDT"},"action":"update","data":[{"asks":[["104518","0","0","0"],["104519","0","0","0"],["104520","0.00530992","0","6"],["104521","0.001","0","1"],["104521.3","0.13872529","0","1"],["104524.5","0.00054673","0","1"],["104531","0.36304409","0","1"],["104535.4","0","0","0"],["104539","0.47497897","0","2"],["104540","0.65775086","0","9"],["104541","0.21","0","3"],["104542","0.15002847","0","4"],["104566.8","0.01099559","0","1"],["104629.9","0.02300636","0","1"]],"bids":[["104487.9","0.7240009","0","15"],["104483.4","0.0017149","0","1"],["104480.1","0.0005","0","1"],["104479.3","0.071777","0","1"],["104474.4","0","0","0"],["104473.6","0.13872529","0","1"],["104465.6","0.000015","0","1"],["104300.3","0","0","0"],["104297","0","0","0"]],"ts":"1747171003501","checksum":17723371,"seqId":54226720962,"prevSeqId":54226720901}]}
{"arg":{"channel":"books","instId":"BTC-USDT"},"action":"update","data":[{"asks":[["104518","0.002","0","2"],["104519","0.001","0","1"],["104520","0.00330992","0","4"],["104521","0","0","0"],["104521.3","0","0","0"],["104524.5","0.13927061","0","2"],["104526.7","0","0","0"],["104527.6","0.00013935","0","1"],["104539","0.63497897","0","4"],["104540","0.80775085","0","12"],["104541","0.085","0","2"],["104542","0.00002848","0","1"],["104543","0","0","0"],["104572.2","5.71278197","0","1"],["104575.4","0.01052914","0","1"],["104575.5","0.05057082","0","2"]],"bids":[["104487.9","0.6252509","0","14"],["104483.4","0","0","0"],["104480.1","0.0022149","0","2"],["104474.4","0.13872388","0","1"],["104473.6","0","0","0"],["104297","0.00286","0","2"]],"ts":"1747171003601","checksum":-1308111073,"seqId":54226720998,"prevSeqId":54226720962}]}
{"arg":{"channel":"books","instId":"BTC-USDT"},"action":"update","data":[{"asks":[["104501","0","0","0"],["104501.7","0.00478361","0","1"],["104524.4","0.13872441","0","1"],["104524.5","0.00054673","0","1"],["104535.4","1.43513249","0","1"],["104566.8","2.55026264","0","2"],["104572.2","0","0","0"],["104575.5","5.76335279","0","3"],["104629.9","0","0","0"]],"bids":[["104474.4","0.13872441","0","1"],["104470.2","0.23342115","0","2"],["104469","0","0","0"],["104437","0.48324487","0","1"],["104436","0","0","0"],["104390","0.47467922","0","2"],["104389","0","0","0"],["104295.3","0.001844","0","1"],["104295.1","0.000419","0","1"]],"ts":"1747171003701","checksum":-1308111073,"seqId":54226721020,"prevSeqId":54226720998}]}
{"arg":{"channel":"books","instId":"BTC-USDT"},"action":"update","data":[{"asks":[["104521.3","0.13872557","0","1"],["104524.4","0","0","0"],["104531","0.75083038","0","2"],["104566.7","0.08480075","0","1"],["104572.2","5.71604758","0","1"],["104575.5","0.05057082","0","2"],["104629.5","0","0","0"],["104629.6","0","0","0"]],"bids":[["104487.9","0.6252709","0","15"],["104474.4","0","0","0"],["104472.9","0.13872557","0","1"],["104394.6","0.24083521","0","2"],["104337.2","0.00844123","0","1"],["104303.5","0.00927386","0","1"],["104295.3","0","0","0"],["104295.1","0","0","0"]],"ts":"1747171003801","checksum":-1045177854,"seqId":54226721086,"prevSeqId":54226721020}]}
{"arg":{"channel":"books","instId":"BTC-USDT"},"action":"update","data":[{"asks":[["104518","0","0","0"],["104519","0","0","0"],["104520","0.00530992","0","6"],["104521","0.001","0","1"],["104521.3","0","0","0"],["104524.5","0.13927131","0","2"],["104531","0.36304409","0","1"],["104535.4","0","0","0"],["104539","0.00004416","0","1"],["104540","0.55775086","0","7"],["104541","0.16","0","2"],["104542","0.25002847","0","6"],["104543","0.085","0","2"],["104566.7","0","0","0"],["104566.8","0.01099559","0","1"],["104610","0.75584924","0","4"],["104629.5","0.00010997","0","1"],["104629.6","0.000096","0","1"],["104629.9","0.02300636","0","1"]],"bids":[["104474.1","0.13872458","0","1"],["104472.9","0","0","0"]],"ts":"1747171003901","checksum":-1045177854,"seqId":54226721124,"prevSeqId":54226721086}]}
{"arg":{"channel":"books","instId":"BTC-USDT"},"action":"update","data":[{"asks":[["104488","0.7674485","0","14"],["104495.9","0.00011435","0","1"],["104496","0.08983142","0","1"],["104496.2","0","0","0"],["104496.3","0.00001","0","1"],["104496.4","0.02866588","0","1"],["104496.7","0.09219836","0","1"],["104497","0.005","0","1"],["104497.7","0.46011704","0","2"],["104498","0","0","0"],["104498.2","0.08852401","0","1"],["104498.4","0.00478368","0","1"],["104498.5","0.234","0","1"],["104500.9","0.38921092","0","1"],["104501","0.77866876","0","1"],["104501.1","0.00093","0","1"],["104501.2","0.14262002","0","1"],["104501.5","0.16672181","0","1"],["104501.7","0.14865319","0","1"],["104501.8","0","0","0"],["104502","0","0","0"],["104504.7","0","0","0"],["104504.9","0.52748697","0","3"],["104505.2","0","0","0"],["104506.7","0.2639132","0","1"],["104507","0.24005705","0","1"],["104507.3","0","0","0"],["104510.7","0.31228448","0","3"],["104511","0","0","0"],["104512","0","0","0"],["104519.8","0.13872769","0","1"],["104524.5","0.00054673","0","1"],["104531.2","0.02164047","0","1"],["104541.5","0","0","0"],["104550.7","0","0","0"],["104629.9","0","0","0"]],"bids":[["104487.9","0.22811665","0","10"],["104487.2","0","0","0"],["104486.1","0.05592","0","1"],["104484.5","0","0","0"],["104483.3","0.17057288","0","1"],["104483.1","0.036","0","1"],["104482.3","0.03663489","0","2"],["104481.4","0.02671334","0","1"],["104480.1","0.0005","0","1"],["104479.7","0","0","0"],["104479.4","0.0017149","0","1"],["104478.3","0.28876851","0","2"],["104477.5","0","0","0"],["104477.2","0.17970877","0","2"],["104476","0.000015","0","1"],["104475.7","0.09667289","0","1"],["104475.3","0","0","0"],["104475","0.09569081","0","1"],["104474.6","0.03867231","0","1"],["104474.3","0.0087017","0","1"],["104474.1","0","0","0"],["104474","0.15781557","0","1"],["104473.7","0.14985456","0","1"],["104472.8","0","0","0"],["104472.5","0.02929425","0","1"],["104472.2","0.1587383","0","1"],["104472.1","0.65572756","0","2"],["104471.1","0.13872769","0","1"],["104470.3","0","0","0"],["104470.2","0","0","0"],["104469.9","0.25878416","0","1"],["104469.7","0","0","0"],["104467.8","0.21609596","0","1"],["104467.5","0","0","0"],["104467.2","0.24809912","0","1"],["104466.7","0.00478368","0","1"],["104464.3","0","0","0"],["104464","0.25705795","0","1"],["104463.5","0","0","0"],["104463.2","0.25227425","0","2"]],"ts":"1747171004001","checksum":-942057000,"seqId":54226721359,"prevSeqId":54226721124}]}
{"arg":{"channel":"books","instId":"BTC-USDT"},"action":"update","data":[{"asks":[["104488","0.4925803","0","12"],["104495.7","0.0008","0","1"],["104495.9","0","0","0"],["104496","0","0","0"],["104496.2","0.00011435","0","1"],["104496.3","0.09809197","0","2"],["104496.7","0","0","0"],["104497","0.10605639","0","2"],["104497.7","0.36908178","0","1"],["104498","0.0870317","0","1"],["104498.2","0","0","0"],["104498.4","0","0","0"],["104498.5","0.32893895","0","2"],["104501.2","0","0","0"],["104501.5","0.14945935","0","1"],["104501.7","0","0","0"],["104501.8","0.15048919","0","1"],["104502","0.15276776","0","1"],["104502.1","0.00479378","0","2"],["104504.7","0.16092841","0","1"],["104504.9","0.34085261","0","2"],["104505.2","0.25348613","0","1"],["104506.7","0","0","0"],["104507","0.24616263","0","1"],["104507.3","0.23944457","0","1"],["104510.7","0.075","0","2"],["104511","0.23571155","0","1"],["104518.6","0.13872931","0","1"],["104519.8","0","0","0"],["104537","1.02869923","0","2"],["104539.1","1.36526238","0","1"],["104552.4","0.00004887","0","1"],["104552.8","0.00056666","0","1"],["104570.4","2.52616156","0","2"],["104629.5","0","0","0"],["104629.6","0","0","0"]],"bids":[["104487.9","0.45099853","0","15"],["104484.3","0.02642709","0","1"],["104481.4","0","0","0"],["104481.3","0","0","0"],["104478.3","0.29489831","0","2"],["104477.5","0.18685345","0","2"],["104477.2","0","0","0"],["104476","0.09689369","0","2"],["104475.7","0","0","0"],["104475.3","0.09944344","0","1"],["104475","0","0","0"],["104474.3","0.17926022","0","2"],["104474","0.14644118","0","1"],["104473.7","0","0","0"],["104472.7","0.19242972","0","1"],["104472.5","0.18481004","0","2"],["104472.2","0","0","0"],["104471.1","0","0","0"],["104470.2","0.25306073","0","1"],["104469.9","0","0","0"],["104469.7","0.1682515","0","2"],["104468.9","0.13873082","0","1"],["104467.8","0.31521665","0","2"],["104467.5","0.24477832","0","1"],["104467.2","0","0","0"],["104466.7","0","0","0"],["104464.3","0.26754725","0","1"],["104464","0","0","0"],["104463.5","0.24745196","0","1"],["104463.2","0.00005","0","1"],["104457.5","0.00955786","0","1"],["104456","0","0","0"],["104454.4","0","0","0"],["104441.9","0","0","0"],["104423.4","0.03655531","0","2"],["104423.1","0","0","0"],["104337.4","0.00056666","0","1"],["104337.1","0","0","0"],["104295.3","0.001844","0","1"],["104295.1","0.000419","0","1"],["104294.1","0.00001","0","1"],["104291.4","0.77866876","0","1"],["104290.3","0.00005072","0","1"]],"ts":"1747171004101","checksum":318691639,"seqId":54226721533,"prevSeqId":54226721359}]}
{"arg":{"channel":"books","instId":"BTC-USDT"},"action":"update","data":[{"asks":[["104488","0.7265803","0","13"],["104490.2","0.002","0","1"],["104494.6","0.03113713","0","1"],["104496.2","0.09482104","0","1"],["104496.3","0.00001","0","1"],["104496.8","0.10178315","0","1"],["104497","0.005","0","1"],["104497.4","0.00011435","0","1"],["104497.8","0.09483439","0","1"],["104498","0","0","0"],["104498.3","0.10389208","0","2"],["104498.5","0.234","0","1"],["104498.8","0","0","0"],["104499.7","0.00478424","0","1"],["104501.3","0.15474585","0","3"],["104501.5","0","0","0"],["104501.7","0.1613025","0","1"],["104501.8","0.17024241","0","1"],["104502","0","0","0"],["104502.1","0.00001","0","1"],["104502.7","0.002","0","1"],["104504.7","0","0","0"],["104504.9","0.13614241","0","1"],["104505","0.31010433","0","2"],["104505.2","0","0","0"],["104506.8","0.30754068","0","2"],["104507","0","0","0"],["104507.2","0.25143608","0","1"],["104507.3","0","0","0"],["104510.8","0.26697626","0","1"],["104511","0","0","0"],["104514.7","0.13873497","0","1"],["104518.6","0","0","0"],["104537","0.02869923","0","1"],["104572.2","0","0","0"],["104575.5","5.7666184","0","3"]],"bids":[["104487.9","0.26647515","0","11"],["104484.3","0","0","0"],["104481","0.03408303","0","2"],["104479.4","0","0","0"],["104478.4","0.0017149","0","1"],["104478.3","0.09696655","0","1"],["104477.5","0","0","0"],["104477.3","0.18300372","0","2"],["104476","0.000015","0","1"],["104475.8","0.09045699","0","1"],["104475.3","0","0","0"],["104475.2","0.10059225","0","1"],["104474.3","0.0087017","0","1"],["104474.2","0.16446986","0","1"],["104474","0","0","0"],["104473.8","0.25382918","0","2"],["104472.5","0.02929425","0","1"],["104472.3","0.15716818","0","1"],["104470.2","0","0","0"],["104470","0.3517577","0","4"],["104469.7","0","0","0"],["104468.9","0","0","0"],["104467.5","0","0","0"],["104466.9","0.00478424","0","1"],["104466.1","0.13873497","0","1"],["104465.5","0.002","0","1"],["104464.3","0","0","0"],["104464.2","0.32019417","0","2"],["104463.5","0","0","0"],["104463.3","0.31557376","0","2"],["104453","0.002","0","1"],["104447.1","0","0","0"],["104424.6","0.00002963","0","1"],["104337.3","0.00095676","0","1"],["104336.5","0","0","0"],["104290","0.00028006","0","1"]],"ts":"1747171004201","checksum":-1875379886,"seqId":54226721687,"prevSeqId":54226721533}]}
{"arg":{"channel":"books","instId":"BTC-USDT"},"action":"update","data":[{"asks":[["104488","0.4925803","0","12"],["104496.1","0.00011435","0","1"],["104497.4","0","0","0"],["104502.1","0.0383685","0","2"],["104504.6","0.15405005","0","1"],["104504.9","0.35038673","0","2"],["104505.6","0.01478556","0","2"],["104506","0.00006","0","1"],["104512.3","0.13873739","0","1"],["104513.2","0","0","0"],["104514.7","0","0","0"],["104519.8","0.0001303","0","1"],["104520.7","0.0022","0","1"],["104536.2","0.47392258","0","1"],["104538.1","0.0022","0","1"],["104546.8","0.00080324","0","1"],["104572.2","5.71604758","0","1"],["104575.5","0.05057082","0","2"],["104610","0.29261492","0","3"],["104627.2","0","0","0"],["104627.8","0","0","0"],["104628.6","0","0","0"],["104628.7","0","0","0"],["104628.8","0","0","0"]],"bids":[["104487.9","0.38597515","0","12"],["104478.3","0.29353653","0","2"],["104469.6","0.16345722","0","2"],["104467.3","0.24204868","0","1"],["104466.1","0","0","0"],["104464.3","0.13873739","0","1"],["104290","0","0","0"]],"ts":"1747171004301","checksum":591348041,"seqId":54226721728,"prevSeqId":54226721687}]}
{"arg":{"channel":"books","instId":"BTC-USDT"},"action":"update","data":[{"asks":[["104488","0.49124043","0","12"],["104496.1","0","0","0"],["104496.2","0.00011435","0","1"],["104496.3","0.10236046","0","2"],["104496.8","0","0","0"],["104497","0.09843668","0","2"],["104497.8","0","0","0"],["104498","0.09593874","0","1"],["104498.3","0.00851559","0","1"],["104498.5","0.33027016","0","2"],["104499.7","0","0","0"],["104500.7","0.00478424","0","1"],["104501.3","0.00009573","0","2"],["104501.5","0.15193484","0","1"],["104501.7","0","0","0"],["104501.8","0.16088028","0","1"],["104502","0.16957832","0","1"],["104504.6","0","0","0"],["104504.7","0.16604705","0","1"],["104504.9","0.33968101","0","1"],["104505","0.0599306","0","1"],["104505.2","0.26154669","0","1"],["104506.8","0.03827676","0","1"],["104507","0.27136132","0","1"],["104507.2","0","0","0"],["104507.3","0.25269628","0","1"],["104510.6","0.13873948","0","1"],["104510.8","0","0","0"],["104511","0.26428478","0","1"],["104512.3","0","0","0"],["104520.7","0","0","0"],["104538.1","0","0","0"],["104546.8","0.00300324","0","2"],["104627.2","0.77866876","0","1"]],"bids":[["104487.9","0.43797515","0","14"],["104486.1","0.07909471","0","2"],["104485.8","0.07298372","0","1"],["104484.3","0.02756532","0","1"],["104481","0.0076569","0","1"],["104479.4","0.0017149","0","1"],["104478.4","0","0","0"],["104478.3","0.29680757","0","2"],["104477.5","0.1855868","0","2"],["104477.3","0","0","0"],["104476","0.09031716","0","2"],["104475.8","0","0","0"],["104475.3","0.10059465","0","1"],["104475.2","0","0","0"],["104474.3","0.17525477","0","2"],["104474.2","0","0","0"],["104474","0.16350279","0","1"],["104473.8","0.096716","0","1"],["104472.5","0.19471716","0","2"],["104472.3","0","0","0"],["104470.2","0.24406079","0","1"],["104470","0.09349006","0","3"],["104469.7","0.15820084","0","1"],["104469.6","0.00097","0","1"],["104468.1","0.00478424","0","1"],["104467.5","0.25441066","0","1"],["104467.3","0","0","0"],["104466.9","0","0","0"],["104464.3","0.2721022","0","1"],["104464.2","0.07298372","0","1"],["104463.5","0.26009249","0","1"],["104463.3","0.0537761","0","1"],["104462.7","0.13873948","0","1"],["104342.5","0.160777","0","1"],["104304.8","0","0","0"],["104295.1","0","0","0"],["104294.1","0","0","0"],["104291.4","0","0","0"],["104290.3","0","0","0"]],"ts":"1747171004401","checksum":-699072413,"seqId":54226721827,"prevSeqId":54226721728}]}
{"arg":{"channel":"books","instId":"BTC-USDT"},"action":"update","data":[{"asks":[["104510.6","0","0","0"],["104512.3","0.13873813","0","1"]],"bids":[["104463.7","0.13873813","0","1"],["104462.7","0","0","0"]],"ts":"1747171004501","checksum":-699072413,"seqId":54226721835,"prevSeqId":54226721827}]}
{"arg":{"channel":"books","instId":"BTC-USDT"},"action":"update","data":[{"asks":[["104500.7","0","0","0"],["104501","0.783453","0","2"],["104627.8","0.00001104","0","1"]],"bids":[["104469.6","0.00575424","0","2"],["104468.1","0","0","0"],["104295.1","0.000419","0","1"]],"ts":"1747171004601","checksum":-699072413,"seqId":54226721845,"prevSeqId":54226721835}]}
{"arg":{"channel":"books","instId":"BTC-USDT"},"action":"update","data":[{"asks":[["104494.6","0","0","0"],["104507.5","0.08607237","0","2"],["104539.1","1.40407579","0","1"],["104570.4","0.01052914","0","1"],["104572.2","5.71634103","0","1"],["104628.6","0.0001","0","1"]],"bids":[["104452.1","0.34147336","0","1"],["104450.6","1.37378902","0","1"],["104449.5","0.06152637","0","1"],["104419.2","2.90808215","0","2"],["104418.2","0","0","0"]],"ts":"1747171004701","checksum":1497381570,"seqId":54226721867,"prevSeqId":54226721845}]}
{"arg":{"channel":"books","instId":"BTC-USDT"},"action":"update","data":[{"asks":[["104488","0.72524043","0","13"],["104496","0.00011435","0","1"],["104496.1","0.09229577","0","1"],["104496.2","0","0","0"],["104496.3","0.00001","0","1"],["104496.8","0.09546465","0","1"],["104497","0.005","0","1"],["104497.7","0.46115177","0","2"],["104497.9","0.02381228","0","1"],["104498","0","0","0"],["104498.3","0.09762183","0","2"],["104498.5","0.234","0","1"],["104499.7","0.00478424","0","1"],["104501","0.77866876","0","1"],["104501.2","0.14845799","0","1"],["104501.5","0","0","0"],["104501.6","0.16886339","0","1"],["104501.8","0.16550459","0","1"],["104502","0","0","0"],["104504.5","0.16632024","0","1"],["104504.7","0","0","0"],["104504.9","0.33833243","0","2"],["104505","0.31230964","0","2"],["104505.2","0","0","0"],["104506.4","0","0","0"],["104506.8","0.30641193","0","2"],["104507","0","0","0"],["104507.1","0.24093887","0","1"],["104507.3","0","0","0"],["104510.6","0.13873955","0","1"],["104510.8","0.23761223","0","1"],["104511","0","0","0"],["104512.3","0","0","0"],["104535.7","1.06553911","0","2"],["104570.4","2.59610452","0","2"],["104583.8","0.12","0","1"],["104628.6","0","0","0"]],"bids":[["104487.9","0.24823515","0","8"],["104478.3","0.29272932","0","2"],["104477.5","0","0","0"],["104477.3","0.09995668","0","1"],["104477.2","0.09117307","0","1"],["104476","0.000015","0","1"],["104475.8","0.08880234","0","1"],["104475.3","0","0","0"],["104475.1","0.09024676","0","1"],["104474.3","0.0087017","0","1"],["104474.1","0.17033803","0","1"],["104474","0","0","0"],["104473.7","0.15242842","0","1"],["104472.5","0.02929425","0","1"],["104472.3","0.15245313","0","1"],["104470.2","0","0","0"],["104470","0.34784755","0","4"],["104469.7","0","0","0"],["104469.6","0.00097","0","1"],["104469.5","0.33917993","0","2"],["104469.2","0.01619463","0","1"],["104469.1","0","0","0"],["104468.1","0.00478424","0","1"],["104467.8","0.39550455","0","2"],["104467.5","0","0","0"],["104467.3","0.23815774","0","1"],["104464.3","0","0","0"],["104464.1","0.25422336","0","1"],["104463.7","0","0","0"],["104463.5","0","0","0"],["104463.3","0.31925159","0","2"],["104462.7","0.13873955","0","1"],["104452.1","0.87613383","0","2"],["104419.3","1.34350018","0","2"],["104419.2","2.46846548","0","1"],["104295.3","0","0","0"],["104295.1","0","0","0"]],"ts":"1747171004801","checksum":-1533604415,"seqId":54226721959,"prevSeqId":54226721867}]}
{"arg":{"channel":"books","instId":"BTC-USDT"},"action":"update","data":[{"asks":[["104499.7","0","0","0"],["104500.7","0.00478424","0","1"],["104510.6","0","0","0"],["104510.7","0.21373881","0","3"],["104628.6","0.0001","0","1"]],"bids":[["104463.4","0.13873881","0","1"],["104462.7","0","0","0"]],"ts":"1747171004901","checksum":-1533604415,"seqId":54226721973,"prevSeqId":54226721959}]}
