{"arg":{"channel":"books","instId":"BTC-USDT"},"action":"snapshot","data":[{"asks":[["104557.4","0.02180638","0","1"],["104557.9","0.09192961","0","1"],["104558","0.0816","0","1"],["104559.6","0.02256561","0","1"],["104559.8","0.00001","0","1"],["104560","0.08161","0","2"],["104560.8","0.04253408","0","1"],["104561.4","0.02867795","0","1"],["104562","0.0816","0","1"],["104562.1","0.00056666","0","1"],["104562.7","0.27966697","0","1"],["104563","0.01912593","0","1"],["104563.1","0.00044","0","1"],["104563.2","0.00521644","0","1"],["104563.8","0.00001","0","1"],["104563.9","0.03653014","0","1"],["104564","0.0866","0","2"],["104564.8","0.00067735","0","1"],["104564.9","0.19242972","0","1"],["104565.5","0.036","0","1"],["104565.9","0.05344807","0","1"],["104566","0.0816","0","1"],["104566.1","0.036","0","1"],["104566.2","0.005","0","1"],["104566.6","0.1778392","0","1"],["104566.7","0.09271354","0","1"],["104566.8","0.01","0","1"],["104566.9","0.52135173","0","1"],["104567.2","0.13369879","0","2"],["104567.7","0.00352239","0","1"],["104567.8","0.00001","0","1"],["104568","0.0816","0","1"],["104568.5","0.002","0","1"],["104568.8","0.09019352","0","1"],["104569","0.0915","0","1"],["104569.2","0.77866876","0","1"],["104569.8","0.09150052","0","1"],["104570","0.08189006","0","3"],["104570.1","0.036","0","1"],["104570.5","0.00093","0","1"],["104570.7","0.04","0","1"],["104571","0.05974447","0","2"],["104571.5","0.00478223","0","1"],["104571.8","0.05201","0","3"],["104572","0.0816","0","1"],["104572.2","0.3295616","0","2"],["104572.5","0.31427052","0","1"],["104574.3","0.00004128","0","1"],["104574.5","0.00478103","0","1"],["104574.6","0.38863185","0","1"],["104574.7","0.052","0","2"],["104575.1","0.15862182","0","1"],["104575.5","0.072","0","2"],["104575.7","0.19336972","0","3"],["104576.1","0.10465","0","1"],["104576.2","0.00478206","0","1"],["104576.5","0.005","0","1"],["104576.6","0.17769518","0","1"],["104577.2","0.25456646","0","1"],["104577.6","0.42068624","0","2"],["104577.7","0.26823531","0","1"],["104577.8","0.286","0","3"],["104578.6","0.04","0","1"],["104578.7","0.005","0","1"],["104578.8","0.00596341","0","1"],["104579.7","0.90767876","0","6"],["104580","0.05420843","0","5"],["104580.3","0.03825039","0","1"],["104580.6","0.04989601","0","1"],["104580.8","0.00286843","0","1"],["104580.9","0.00191","0","1"],["104581.3","0.23491684","0","1"],["104581.4","0.071712","0","1"],["104581.5","0.000015","0","1"],["104582.6","0.00017125","0","1"],["104582.9","0.13864379","0","1"],["104583","0.30193859","0","1"],["104583.1","0.17769518","0","1"],["104583.7","0.00001","0","1"],["104584.9","0.1778392","0","1"],["104585","0.1778392","0","1"],["104585.9","0.00711203","0","1"],["104586.1","0.38863185","0","1"],["104586.2","0.19433972","0","2"],["104586.3","0.00287","0","1"],["104587.6","0.07298372","0","1"],["104587.7","0.00001","0","1"],["104588.2","0.52482168","0","2"],["104588.3","0.234","0","1"],["104588.4","0.00056666","0","1"],["104589.3","0.26864","0","1"],["104590","0.00029006","0","2"],["104590.1","0.036","0","1"],["104590.2","0.77866876","0","1"],["104591","0.002","0","2"],["104591.6","0.00001","0","1"],["104591.9","0.00013754","0","1"],["104592","0.001015","0","2"],["104593.3","0.74937348","0","1"],["104593.8","0.1778392","0","1"],["104595.6","0.00001","0","1"],["104595.7","0.54613","0","1"],["104596.4","0.10234","0","1"],["104596.6","0.38863185","0","1"],["104596.8","0.19529972","0","2"],["104597.3","0.17769518","0","1"],["104597.5","0.052","0","2"],["104597.6","0.67772","0","1"],["104598.4","0.38167986","0","1"],["104598.6","0.052","0","2"],["104598.7","0.0095581","0","1"],["104598.9","0.0022","0","1"],["104599","0.07298372","0","1"],["104599.5","0.234","0","1"],["104599.6","0.00001","0","1"],["104600","0.00220843","0","3"],["104600.4","1.3804775","0","1"],["104601.1","0.0191285","0","1"],["104601.3","0.77866876","0","1"],["104601.4","0.052","0","2"],["104601.9","0.09564","0","1"],["104602.1","0.052","0","2"],["104602.5","0.00001501","0","1"],["104603.2","0.01434637","0","1"],["104603.6","0.00001","0","1"],["104603.9","1.34855267","0","1"],["104604.3","0.00956425","0","1"],["104605.1","0.09564","0","1"],["104605.9","0.29193486","0","1"],["104606","0.02868888","0","1"],["104607.3","0.19242972","0","1"],["104607.4","0.55554212","0","2"],["104607.5","0.00001","0","1"],["104608","2.42657","0","1"],["104608.5","0.00287","0","1"],["104609.5","0.00956425","0","1"],["104609.6","0.0004782","0","1"],["104609.7","0.67560716","0","1"],["104609.8","0.38863185","0","1"],["104610","0.23428006","0","2"],["104610.1","0.17769518","0","1"],["104610.5","0.04717439","0","1"],["104611.5","0.00001","0","1"],["104612","0.32999999","0","6"],["104612.2","0.052","0","2"],["104612.7","0.07298372","0","1"],["104613","0.17343296","0","5"],["104613.6","0.77866876","0","1"],["104614.4","0.13680169","0","1"],["104614.5","0.45373348","0","2"],["104615.5","0.00001","0","1"],["104616.7","0.00155221","0","1"],["104616.8","0.0022","0","1"],["104617.6","0.00004964","0","1"],["104619.1","0.26249015","0","1"],["104619.2","0.19242972","0","1"],["104619.5","0.00001","0","1"],["104620","0.00220843","0","3"],["104620.3","0.052","0","2"],["104620.8","0.13258332","0","1"],["104621.1","0.0004964","0","1"],["104621.3","0.02869131","0","1"],["104621.7","0.00175257","0","1"],["104621.8","0.06695","0","1"],["104622","0.052","0","2"],["104622.1","0.14337","0","1"],["104622.7","0.32958","0","2"],["104622.8","0.1147","0","1"],["104623.3","0.0008017","0","1"],["104623.4","0.00001","0","1"],["104623.5","0.00001501","0","1"],["104624.8","0.0286743","0","1"],["104624.9","0.01433357","0","1"],["104625.6","0.09558","0","1"],["104626.4","0.04358344","0","4"],["104626.7","0.38863185","0","1"],["104627.2","0.77866876","0","1"],["104627.4","0.00001","0","1"],["104628.9","0.45945197","0","1"],["104630","0.00029006","0","2"],["104630.5","0.19115","0","1"],["104630.6","0.03","0","1"],["104630.7","0.19242972","0","1"],["104631.4","0.07299372","0","2"],["104632","0.38126567","0","1"],["104632.1","0.77071","0","1"],["104633","0.49439815","0","1"],["104633.2","0.00560252","0","4"],["104633.8","0.000015","0","1"],["104633.9","0.00014488","0","1"],["104634","0.00001501","0","1"],["104635","1.20573686","0","1"],["104635.1","2.50580227","0","1"],["104635.4","0.03001","0","2"],["104636.4","6.22585949","0","1"],["104637","0.234","0","1"],["104637.7","0.38863185","0","1"],["104637.8","0.77866876","0","1"],["104638.1","0.052","0","2"],["104639","0.03","0","1"],["104639.3","0.00001","0","1"],["104640","0.05420843","0","5"],["104641.2","0.19242972","0","1"],["104643.1","0.03","0","1"],["104643.2","0.03","0","1"],["104643.3","0.00001","0","1"],["104643.8","0.07298372","0","1"],["104644.5","0.00001501","0","1"],["104647.3","0.00001","0","1"],["104648","0.06695","0","1"],["104648.2","0.35028626","0","1"],["104648.3","0.38863185","0","1"],["104649.1","0.77866876","0","1"],["104650","0.00032024","0","2"],["104650.5","0.234","0","1"],["104651","0.0477905","0","1"],["104651.3","0.00001","0","1"],["104655","0.00001501","0","1"],["104655.2","0.830738","0","2"],["104656","0.06972","0","1"],["104658.7","0.35085571","0","1"],["104658.8","0.38863185","0","1"],["104659.2","0.00001","0","1"],["104660","0.00220843","0","3"],["104660.3","0.77866876","0","1"],["104660.9","0.16664529","0","2"],["104661","0.234","0","1"],["104662.3","0.03825596","0","1"],["104663.2","0.00001","0","1"],["104663.4","0.03","0","1"],["104663.5","0.03451363","0","1"],["104663.8","0.00009282","0","1"],["104663.9","0.00017476","0","1"],["104664.1","0.08031","0","1"],["104664.5","0.04777","0","1"],["104664.8","0.5","0","1"],["104665","0.07298372","0","1"],["104665.5","0.00001501","0","1"],["104666.3","0.00126362","0","1"],["104666.5","0.01298","0","1"],["104666.6","0.000173","0","1"],["104666.8","0.01089629","0","1"],["104666.9","0.01051896","0","1"],["104667","0.01089693","0","1"],["104667.1","0.0022","0","1"],["104667.2","0.05970015","0","2"],["104667.9","0.12","0","1"],["104668.5","0.02866952","0","1"],["104669.2","0.12","0","1"],["104669.4","0.01089693","0","1"],["104670","0.00028006","0","1"],["104670.2","0.12","0","1"],["104670.6","0.01364","0","1"],["104670.7","0.01089693","0","1"],["104670.9","0.77866876","0","1"],["104671.2","0.00001","0","1"],["104671.6","0.0189","0","1"],["104671.8","0.01912754","0","1"],["104672.3","0.234","0","1"],["104673.6","0.0134883","0","1"],["104674","0.01185227","0","2"],["104675","0.97264328","0","1"],["104675.1","0.00001","0","1"],["104675.8","0.01051593","0","1"],["104675.9","0.01059702","0","1"],["104676","0.00001501","0","1"],["104676.7","0.03","0","1"],["104678.9","0.01089629","0","1"],["104679.1","0.00001","0","1"],["104679.8","0.01051593","0","1"],["104679.9","3.08215404","0","3"],["104680","0.00220843","0","3"],["104680.1","0.0011559","0","1"],["104680.9","0.01051593","0","1"],["104681.9","0.01059702","0","1"],["104682.2","0.07298372","0","1"],["104682.3","0.01051593","0","1"],["104682.6","0.0579344","0","1"],["104682.9","0.02149395","0","2"],["104683","0.77866876","0","1"],["104683.1","0.00001","0","1"],["104683.4","0.05793435","0","1"],["104683.7","0.01051593","0","1"],["104683.9","0.12","0","1"],["104684.4","0.234","0","1"],["104684.9","0.0001","0","1"],["104685.2","0.01059702","0","1"],["104685.9","0.01051593","0","1"],["104686.1","0.00001501","0","1"],["104686.5","0.00001501","0","1"],["104686.6","0.01059632","0","1"],["104686.7","0.01089693","0","1"],["104687.6","0.08352417","0","3"],["104688.2","0.03","0","1"],["104688.8","0.01059702","0","1"],["104688.9","0.0013452","0","1"],["104689.3","0.01089629","0","1"],["104689.4","0.03","0","1"],["104689.9","0.01051593","0","1"],["104690","0.00048079","0","2"],["104691","0.00001","0","1"],["104691.3","0.01089693","0","1"],["104691.4","0.01051593","0","1"],["104691.5","0.01059702","0","1"],["104691.6","0.06972","0","1"],["104692.7","0.229509","0","1"],["104693.1","0.02111249","0","2"],["104693.2","1.27618225","0","3"],["104693.3","0.02119404","0","2"],["104693.5","0.77866876","0","1"],["104695.1","0.01051593","0","1"],["104695.2","0.01051593","0","1"],["104695.7","0.01089629","0","1"],["104695.8","0.01059656","0","1"],["104695.9","0.234","0","1"],["104696.5","0.01051593","0","1"],["104696.6","0.01059702","0","1"],["104696.7","0.01051593","0","1"],["104697","0.07299872","0","2"],["104697.1","0.03","0","1"],["104697.9","0.01059656","0","1"],["104698.4","0.03","0","1"],["104699","0.00001","0","1"],["104699.3","0.01059656","0","1"],["104699.4","0.01051522","0","1"],["104699.5","0.00479878","0","2"],["104699.8","0.04634752","0","1"],["104699.9","0.01051593","0","1"],["104700","0.00321287","0","6"],["104700.6","0.01051522","0","1"],["104700.7","0.01051536","0","1"],["104701.3","0.03","0","1"],["104701.7","0.0026904","0","1"],["104702.6","0.01059656","0","1"],["104702.7","0.01059656","0","1"],["104702.8","0.01051522","0","1"],["104702.9","0.01051593","0","1"],["104703","0.01089629","0","1"],["104703.1","0.01051536","0","1"],["104703.2","0.4","0","1"],["104703.4","0.01089693","0","1"],["104704.1","0.78918398","0","2"],["104704.8","0.09078904","0","2"],["104704.9","0.0008","0","1"],["104706.2","0.01051522","0","1"],["104706.3","0.02111205","0","2"],["104707.1","0.01051536","0","1"],["104707.5","0.000015","0","1"],["104708.8","0.01089629","0","1"],["104709.2","0.01051503","0","1"],["104709.3","0.01051503","0","1"],["104709.4","0.17113422","0","2"],["104709.5","0.01089646","0","1"],["104709.6","0.01061028","0","2"],["104709.9","0.00479843","0","1"],["104710","0.00038006","0","2"],["104710.5","0.02119312","0","2"],["104711","0.07298372","0","1"],["104712","0.234","0","1"],["104712.7","0.01089629","0","1"],["104712.8","0.01401695","0","1"],["104713.1","0.00041774","0","1"],["104713.8","0.01051522","0","1"],["104713.9","0.01089693","0","1"],["104714.2","0.00001434","0","1"],["104714.8","0.77868726","0","2"],["104714.9","0.00001","0","1"],["104715.4","0.00037603","0","1"],["104716.1","0.00090524","0","1"],["104716.2","0.000078","0","1"],["104716.5","2.88986","0","1"],["104716.8","0.01059702","0","1"],["104716.9","0.01059702","0","1"],["104718","0.000015","0","1"],["104718.7","0.00001679","0","1"],["104718.9","0.07298372","0","1"],["104719.7","0.00016808","0","1"],["104719.9","0.01103616","0","2"],["104720","0.00280954","0","8"],["104720.4","0.00002219","0","1"],["104720.6","0.01089693","0","1"],["104720.7","0.01089693","0","1"],["104721.9","0.01401775","0","1"],["104722.2","0.00027824","0","7"],["104722.4","0.02119312","0","2"],["104722.5","0.234","0","1"],["104722.6","0.01034","0","1"],["104722.9","0.00001","0","1"],["104723.2","0.00017476","0","1"],["104723.6","0.01059702","0","1"],["104724.2","0.00001526","0","1"],["104724.8","0.01059702","0","1"],["104725","0.06999668","0","3"],["104725.3","0.77866876","0","1"],["104725.9","0.00014362","0","5"],["104726.4","0.00021134","0","1"],["104726.5","0.01089646","0","1"],["104726.8","0.00141996","0","3"],["104727","1.89471219","0","1"],["104727.7","0.01089693","0","1"]],"bids":[["104557.3","0.50011004","0","9"],["104556","0.10988297","0","4"],["104555.9","0.00263","0","1"],["104555.8","0.052","0","2"],["104555","0.02580209","0","1"],["104554.9","0.11092392","0","1"],["104554.8","0.052","0","2"],["104554","0.0816","0","1"],["104553.7","0.06185798","0","4"],["104552.8","0.02256561","0","1"],["104552","0.08161","0","2"],["104551.8","0.00262492","0","1"],["104551.7","0.05548788","0","1"],["104551.5","0.01","0","2"],["104551.4","0.002","0","1"],["104550.1","0.18168572","0","3"],["104550","0.08193024","0","4"],["104549.5","0.00051","0","1"],["104548","0.08161","0","2"],["104547.7","0.08921048","0","1"],["104546.8","0.00115191","0","1"],["104546.7","0.00956282","0","1"],["104546.5","0.05723784","0","1"],["104546.3","0.09744473","0","1"],["104546.2","0.071712","0","1"],["104545.8","0.00867163","0","1"],["104545.7","0.09140602","0","1"],["104545.4","0.00017476","0","1"],["104545","0.08214844","0","1"],["104544.7","0.15481377","0","1"],["104544.2","0.00098","0","1"],["104544.1","0.00001","0","1"],["104544","0.00352365","0","1"],["104542.7","0.1532422","0","1"],["104541.5","0.00478103","0","1"],["104541.4","0.0001","0","1"],["104541.2","0.03656639","0","1"],["104541.1","0.19242972","0","1"],["104541","0.07298372","0","1"],["104540.8","0.38911502","0","1"],["104540.1","0.15480425","0","2"],["104540","0.00222135","0","4"],["104539","0.01098","0","3"],["104538.9","0.01260562","0","2"],["104538.4","0.77866876","0","1"],["104538.3","0.38863185","0","1"],["104538","0.04","0","1"],["104537.7","0.2437765","0","1"],["104536.8","0.00004783","0","1"],["104536.1","0.00001","0","1"],["104536","0.00005","0","1"],["104535.9","0.00001501","0","1"],["104535.6","0.19380758","0","1"],["104535.4","0.06","0","2"],["104534.7","0.25390252","0","2"],["104533.8","0.24878442","0","2"],["104533.3","0.000173","0","1"],["104533","0.13864379","0","1"],["104532.9","0.02889794","0","1"],["104532.1","0.00001","0","1"],["104531.8","0.102332","0","1"],["104531.3","0.06781017","0","1"],["104531.2","0.123","0","4"],["104530","0.00029006","0","2"],["104529.4","0.00002905","0","1"],["104529.3","0.69345109","0","2"],["104528.6","0.00191","0","1"],["104528.4","0.19242972","0","1"],["104528.3","0.17769518","0","1"],["104528.2","0.00001","0","1"],["104528.1","0.00711203","0","1"],["104527.8","0.04826626","0","1"],["104527.7","0.38863185","0","1"],["104527.6","0.17769518","0","1"],["104526.5","0.10167569","0","2"],["104525.8","0.77866876","0","1"],["104525.7","0.35539036","0","2"],["104525.6","0.00001501","0","1"],["104525.4","0.00001501","0","1"],["104525.2","0.25365302","0","2"],["104525.1","0.17769518","0","1"],["104524.8","0.17769518","0","1"],["104524.5","0.00054717","0","1"],["104524.2","0.00001","0","1"],["104523.7","0.00286799","0","1"],["104522.7","0.45412437","0","2"],["104522.6","0.00004783","0","1"],["104521.9","0.00001","0","1"],["104520.6","0.02868855","0","1"],["104520.3","0.05913296","0","1"],["104520.2","0.00029004","0","1"],["104520","0.0033207","0","5"],["104519.9","0.33362505","0","1"],["104517.1","0.58106157","0","2"],["104516.6","0.32973","0","1"],["104516.2","0.65782","0","2"],["104516","0.00026224","0","1"],["104515.5","0.00951191","0","1"],["104515.3","0.00478223","0","1"],["104514.9","0.00001501","0","1"],["104514.1","0.75580444","0","2"],["104514","0.77866876","0","1"],["104513.8","0.04549557","0","1"],["104513.3","0.07331315","0","2"],["104512.4","0.413021","0","1"],["104512.3","0.00001","0","1"],["104512.2","0.0001","0","1"],["104511.7","1.365949","0","1"],["104511","0.0025","0","1"],["104510","0.00506195","0","2"],["104509.1","0.20877791","0","1"],["104509","0.005","0","2"],["104508.4","0.07298372","0","1"],["104508.3","0.00001","0","1"],["104508.1","0.00370382","0","2"],["104507.8","0.07657422","0","1"],["104506","0.48324487","0","1"],["104505.9","0.00006","0","1"],["104505.4","0.00844682","0","1"],["104504.4","0.00001501","0","1"],["104504.3","0.00001","0","1"],["104503.9","0.00041816","0","1"],["104503.8","0.58131575","0","2"],["104503.7","0.38863185","0","1"],["104503.5","0.77866876","0","1"],["104502.8","0.5894","0","1"],["104502.3","0.05709168","0","1"],["104502.1","0.00951595","0","1"],["104502","0.00951601","0","1"],["104501.8","0.0429","0","1"],["104501.4","0.00055553","0","2"],["104500.4","0.00001","0","1"],["104500","0.00369976","0","11"],["104499.6","0.00939305","0","1"],["104499.3","0.00007731","0","1"],["104499","0.00005062","0","1"],["104498.7","0.00287","0","1"],["104498.4","0.2139248","0","2"],["104498.3","0.14007731","0","2"],["104498","0.00365202","0","1"],["104497.7","0.00723019","0","1"],["104496.8","0.01435117","0","1"],["104496.4","0.00057666","0","2"],["104496.1","0.17769518","0","1"],["104495.7","0.0008","0","1"],["104495.1","0.00003796","0","1"],["104494.8","0.03825388","0","1"],["104494.5","0.04781424","0","1"],["104494.4","0.02489112","0","2"],["104494.2","0.03","0","1"],["104493.9","0.00001501","0","1"],["104493.3","0.19242972","0","1"],["104493.2","0.08414984","0","8"],["104493.1","0.25809812","0","2"],["104493","0.80866876","0","2"],["104492.6","0.00007308","0","1"],["104492.4","0.00001","0","1"],["104491.9","0.0022","0","1"],["104490.7","0.02103746","0","2"],["104490.1","0.03","0","1"],["104490","0.00028006","0","1"],["104488.5","0.00001","0","1"],["104487.9","0.01089578","0","1"],["104487.8","0.04207492","0","4"],["104487.3","0.01051896","0","1"],["104487.2","0.03","0","1"],["104486.5","0.01059677","0","1"],["104486.4","0.02103746","0","2"],["104486.2","0.21921299","0","1"],["104486.1","0.10135666","0","3"],["104485.9","0.554716","0","1"],["104485.8","0.01089578","0","1"],["104485.7","0.02112349","0","3"],["104484.5","0.00001","0","1"],["104483.9","0.01059652","0","1"],["104483.8","0.01059677","0","1"],["104483.7","0.01089578","0","1"],["104483.6","0.01051896","0","1"],["104483.5","0.03163398","0","3"],["104483.4","0.00001501","0","1"],["104482.8","0.39922862","0","2"],["104482.7","1.24144929","0","2"],["104482.6","0.00001","0","1"],["104482.5","0.77866876","0","1"],["104481.9","0.02103746","0","2"],["104481.8","0.07298372","0","1"],["104480.8","0.00002601","0","1"],["104480.5","0.01059652","0","1"],["104480.4","0.01089633","0","1"],["104480.3","2.5337461","0","2"],["104480.2","0.01051896","0","1"],["104480.1","0.02103746","0","2"],["104480","0.01272716","0","4"],["104479.8","0.01089578","0","1"],["104479.5","0.01051896","0","1"],["104479.3","0.00682446","0","1"],["104478.6","2.61069","0","1"],["104477.9","0.27932","0","1"],["104477.7","0.01059677","0","1"],["104477.6","1.03328162","0","1"],["104477.5","0.32231896","0","3"],["104476.5","0.00001","0","1"],["104476","0.00002208","0","1"],["104475.7","0.00002471","0","1"],["104475","0.00001441","0","1"],["104474.9","0.00002308","0","1"],["104474.5","0.01059677","0","1"],["104474.4","0.01051896","0","1"],["104474.2","3.09210803","0","6"],["104473.6","0.00139512","0","1"],["104473.3","0.00001501","0","1"],["104472.9","0.00001501","0","1"],["104472.6","0.00001","0","1"],["104472.3","0.01059677","0","1"],["104472.2","0.02111573","0","2"],["104472","0.77866876","0","1"],["104470.9","0.03","0","1"],["104470.3","0.01059652","0","1"],["104470.2","0.01051994","0","1"],["104470.1","3.0337969","0","1"],["104470","10.00028006","0","2"],["104468.7","0.01059677","0","1"],["104468.6","0.01052994","0","2"],["104468.5","0.07177","0","1"],["104468","0.01089633","0","1"],["104467.9","0.00123","0","1"],["104467.3","0.00003136","0","1"],["104467.2","0.03322566","0","3"],["104467.1","0.07298372","0","1"],["104466.6","0.000173","0","1"],["104466","0.00002018","0","1"],["104464.6","0.00001","0","1"],["104464.2","0.00049361","0","3"],["104462.4","0.00001501","0","1"],["104462.3","0.03","0","1"],["104462.1","0.19055429","0","2"],["104462","0.05","0","1"],["104461.5","0.00001987","0","1"],["104461.2","0.07298372","0","1"],["104460.7","0.00001","0","1"],["104460","0.00219843","0","2"],["104459","0.47450178","0","2"],["104458.6","0.01059652","0","1"],["104458.5","0.01052097","0","1"],["104458.4","0.01059677","0","1"],["104458.3","0.01077302","0","1"],["104457.8","0.0000101","0","1"],["104457.4","0.01089593","0","1"],["104457.3","0.01089633","0","1"],["104457.2","0.25555987","0","1"],["104457.1","0.0001","0","1"],["104456.8","0.01099235","0","2"],["104456.7","0.77867876","0","2"],["104456.1","0.0022","0","1"],["104455.5","0.0228","0","3"],["104455.4","0.0152","0","2"],["104455.3","0.0076","0","1"],["104455","0.00001008","0","1"],["104454.8","0.00006072","0","1"],["104454.4","0.0005","0","1"],["104453.9","0.03","0","1"],["104453.6","0.011","0","1"],["104453.1","0.00001","0","1"],["104452.7","0.01370056","0","1"],["104452","0.02870026","0","1"],["104451.9","0.34405316","0","2"],["104451.8","0.07298372","0","1"],["104450.4","0.01059652","0","1"],["104450.3","0.01089633","0","1"],["104450.2","0.01089578","0","1"],["104450.1","0.832359","0","1"],["104450","0.00032024","0","2"],["104449.5","0.00990999","0","2"],["104448.8","0.00001","0","1"],["104448.4","0.0077","0","1"],["104447.6","0.00001846","0","1"],["104446.8","0.00001783","0","1"],["104446.5","0.01089593","0","1"],["104446.4","0.01059677","0","1"],["104446.3","0.24265841","0","1"],["104446.2","0.77866876","0","1"],["104445.3","0.00001","0","1"],["104444.8","0.00001","0","1"],["104444.4","0.0001114","0","2"],["104443.7","0.00008121","0","1"],["104443.6","0.04089633","0","2"],["104443.3","0.00001","0","1"],["104442.8","0.00063791","0","1"],["104442.7","0.01089578","0","1"],["104442.5","0.04634752","0","1"],["104441.4","0.000015","0","1"],["104441.1","0.00002018","0","1"],["104441","0.01059666","0","1"],["104440.9","0.03472069","0","6"],["104440.2","0.01089593","0","1"],["104440","0.94696737","0","7"],["104438.9","0.01148997","0","1"],["104438.8","0.01059677","0","1"],["104438.4","0.00001002","0","1"],["104437.9","0.00046105","0","1"],["104437.8","0.01089633","0","1"],["104437.7","0.05793435","0","1"],["104437.5","0.02321488","0","2"],["104437","0.01143429","0","2"],["104436.9","0.01089578","0","1"],["104436.8","0.00001","0","1"],["104436.7","0.01089642","0","1"],["104436.1","1.42797","0","1"],["104435.8","0.19348372","0","2"],["104435.3","0.0001","0","1"],["104433.9","0.25110666","0","1"],["104432.9","0.01090593","0","2"],["104432.7","0.00008755","0","1"],["104432.6","0.01122718","0","3"],["104432.5","0.01089633","0","1"],["104432.4","0.0217922","0","2"],["104432.3","0.77866876","0","1"],["104430.7","0.00007949","0","1"],["104430.4","0.01174866","0","1"],["104430.3","0.03","0","1"],["104430","0.00028006","0","1"],["104429.6","0.00122607","0","4"],["104427.3","0.0879344","0","2"],["104426.9","0.01089593","0","1"],["104426.8","0.00017476","0","1"],["104426.7","0.12","0","1"],["104426.2","0.00001731","0","1"],["104426","0.0025","0","1"],["104425.9","0.0001","0","1"],["104425.7","0.007986","0","1"],["104425.4","0.32332817","0","1"],["104425.3","0.1913","0","1"],["104425","0.0025","0","1"],["104424.7","0.00001169","0","1"],["104424.3","0.00156669","0","1"],["104424","0.01401013","0","1"],["104423.5","0.01448485","0","1"],["104423","0.00071959","0","4"],["104422.9","0.01089593","0","1"],["104422.8","0.00094847","0","1"],["104422.7","0.01089657","0","1"],["104422.5","0.0013452","0","1"],["104421.8","0.77866876","0","1"],["104421.7","0.07298372","0","1"],["104421","0.00003591","0","3"],["104420.5","0.03","0","1"],["104420.3","0.03","0","1"],["104420","0.00276552","0","3"],["104419.4","0.00003046","0","1"],["104418.9","0.00005586","0","1"],["104418.4","0.0001","0","1"],["104418.1","0.00004752","0","1"],["104417.6","0.01089593","0","1"],["104417.5","0.0030329","0","1"],["104417.4","0.00012018","0","1"],["104417.1","0.00005919","0","1"],["104417","0.002","0","1"],["104416.6","0.00019387","0","5"],["104415.1","0.229546","0","1"],["104414.5","0.00003296","0","1"],["104413.7","0.1148746","0","2"],["104413.6","0.004782","0","1"],["104412.1","0.0026904","0","1"],["104411.6","0.00006","0","1"],["104410.8","0.00001007","0","1"],["104410","0.00029298","0","2"],["104409.4","0.77866876","0","1"],["104409.1","0.00001","0","1"],["104408.8","2.1376","0","1"],["104408.6","0.0008379","0","2"],["104408.5","0.00003352","0","1"],["104407.9","0.00002454","0","1"],["104407.5","0.03","0","1"],["104407.2","0.00001147","0","1"],["104406.5","0.03","0","1"],["104405.8","0.00001051","0","1"],["104405.1","0.00002566","0","1"],["104404.4","0.00095619","0","1"],["104404.3","0.160633","0","1"],["104404.2","0.00008559","0","1"],["104404.1","0.00005489","0","1"],["104404","0.0025956","0","2"],["104403.9","0.00050129","0","4"],["104403.4","0.00001334","0","1"],["104402.9","0.00001373","0","1"],["104402.2","0.00003809","0","1"],["104401.1","0.00001","0","1"],["104401","0.00023525","0","1"],["104400","0.112661","0","48"],["104399.9","0.0051225","0","9"],["104399.7","0.01401146","0","1"],["104399.6","0.01364893","0","1"],["104399.4","0.00041858","0","1"],["104398.8","0.77874386","0","4"],["104398.1","0.07298372","0","1"],["104398","0.00004846","0","1"],["104397.6","2.68797","0","1"],["104396.6","0.00009579","0","1"],["104396.3","0.00002839","0","1"],["104395.8","0.00001704","0","1"]],"ts":"1747170009900","checksum":-795923644,"seqId":54226035759,"prevSeqId":-1}]}
{"arg":{"channel":"books","instId":"BTC-USDT"},"action":"update","data":[{"asks":[["104557.4","0.02189638","0","2"],["104559.6","0","0","0"],["104562.5","0.02256561","0","1"],["104565.5","0","0","0"],["104566.1","0","0","0"],["104571.8","0.03601","0","2"],["104574.5","0","0","0"],["104576.4","0.00478093","0","1"],["104582.9","0","0","0"],["104584.8","0.13864213","0","1"],["104612.2","0.152","0","3"],["104622.8","0","0","0"],["104683.9","0","0","0"],["104727.8","0.01089693","0","1"],["104727.9","0.01089693","0","1"],["104728.3","0.00001564","0","1"],["104728.5","0.00001501","0","1"]],"bids":[["104557.3","0.50020004","0","10"],["104556","0.10979297","0","3"],["104548.1","0.00115191","0","1"],["104546.8","0","0","0"],["104545","0.17556059","0","2"],["104544.8","0.00478093","0","1"],["104541.5","0","0","0"],["104535.7","0.13864213","0","1"],["104535.6","0.2828402","0","2"],["104533","0","0","0"]],"ts":"1747170010000","checksum":906841948,"seqId":54226035785,"prevSeqId":54226035759}]}
{"arg":{"channel":"books","instId":"BTC-USDT"},"action":"update","data":[{"asks":[["104557.4","0","0","0"],["104557.9","0","0","0"],["104558","0","0","0"],["104559.8","0","0","0"],["104560","0","0","0"],["104560.8","0","0","0"],["104561.4","0","0","0"],["104562","0","0","0"],["104562.1","0","0","0"],["104562.5","0","0","0"],["104562.7","0","0","0"],["104563","0","0","0"],["104563.1","0","0","0"],["104563.9","0","0","0"],["104564.8","0","0","0"],["104564.9","0","0","0"],["104565.9","0","0","0"],["104566.6","0","0","0"],["104566.7","0","0","0"],["104566.9","0","0","0"],["104567.1","0.02256561","0","1"],["104567.2","0.04","0","1"],["104567.7","0","0","0"],["104567.8","0.00045","0","2"],["104568.8","0","0","0"],["104568.9","0.18321172","0","1"],["104569.2","0.00056666","0","1"],["104569.7","0.00067735","0","1"],["104569.9","0.01912475","0","1"],["104570.1","0","0","0"],["104570.5","0","0","0"],["104570.6","0.04099544","0","1"],["104570.9","0.02867795","0","1"],["104571.5","0.09063443","0","1"],["104572","0.21697417","0","3"],["104572.2","0","0","0"],["104572.5","0.2318823","0","1"],["104573.6","0.0983687","0","1"],["104574","0.00093","0","1"],["104574.3","0","0","0"],["104574.6","0","0","0"],["104574.7","0.036","0","1"],["104575.1","0","0","0"],["104575.4","0.00004128","0","1"],["104575.7","0.19243972","0","2"],["104576.1","0","0","0"],["104576.4","0","0","0"],["104577","0.31053256","0","2"],["104577.2","0","0","0"],["104577.6","0.60383369","0","1"],["104577.7","0","0","0"],["104577.8","0.27","0","2"],["104578.6","0","0","0"],["104579.2","0.00093","0","1"],["104579.8","0.16137871","0","1"],["104579.9","0.00478091","0","1"],["104580.9","0","0","0"],["104581.3","0","0","0"],["104581.4","0","0","0"],["104582","0.26505643","0","1"],["104582.4","0.1778392","0","1"],["104582.5","0.25164312","0","1"],["104582.6","0.04017125","0","2"],["104583","0.43584321","0","2"],["104584.8","0","0","0"],["104585.9","0","0","0"],["104586.1","0.6268059","0","2"],["104586.2","0.19242972","0","1"],["104588.4","0","0","0"],["104591","0","0","0"],["104591.9","0","0","0"],["104592","0.002015","0","3"],["104592.6","0.00711203","0","1"],["104593","0.001","0","1"],["104593.3","0","0","0"],["104593.7","0.13863257","0","1"],["104595.4","0.00056666","0","1"],["104595.6","0.00014754","0","2"],["104597.6","0","0","0"],["104598.4","0.75316893","0","2"],["104601.9","0","0","0"],["104612","0","0","0"],["104612.2","0.052","0","2"],["104613","0.33843296","0","8"],["104614","0.16499999","0","3"],["104616.7","0","0","0"],["104617.5","0.0015522","0","1"],["104621.7","0","0","0"],["104623.3","0.6763017","0","2"],["104624.7","0.00175256","0","1"],["104625.6","0","0","0"],["104630.5","0","0","0"],["104636.4","0","0","0"],["104660.9","0","0","0"],["104663.8","0","0","0"],["104665.4","0.00009459","0","1"],["104667.2","0.00001","0","1"],["104667.8","0.04823151","0","1"],["104716.1","0","0","0"],["104729.8","0.00002514","0","2"],["104730","0.00041646","0","4"],["104730.6","0.03","0","1"],["104730.9","0.03","0","1"],["104732.3","0.00010831","0","1"],["104732.8","0.00209352","0","1"],["104733","0.234","0","1"],["104733.1","0.3554","0","1"],["104733.3","0.07315672","0","2"],["104734.4","0.00212424","0","1"],["104734.8","0.00001","0","1"],["104734.9","0.00001009","0","1"],["104735.2","0.03","0","1"],["104735.8","0.00023574","0","1"],["104735.9","0.00002557","0","1"],["104736.3","0.77866876","0","1"],["104736.4","0.04304572","0","2"],["104736.8","0.00001014","0","1"],["104737.9","0.004782","0","1"],["104738.4","0.00001501","0","1"],["104738.5","0.03","0","1"],["104738.8","0.00001","0","1"],["104739","0.00001501","0","1"],["104739.6","0.00023506","0","1"],["104739.7","0.00001107","0","1"],["104740","0.00219843","0","2"],["104740.3","0.00005155","0","1"],["104740.5","0.00006468","0","1"]],"bids":[["104562.4","0.2031096","0","6"],["104560.8","0.70202166","0","16"],["104560.1","0.32583038","0","1"],["104560","0.17117","0","3"],["104559.9","0.052","0","2"],["104559.4","0.00350527","0","1"],["104558","0.11002114","0","2"],["104557.3","0.05209","0","3"],["104556.7","0.02256561","0","1"],["104556","0.08399106","0","2"],["104555","0","0","0"],["104554","0.18394","0","2"],["104553","0.00051","0","1"],["104552.8","0","0","0"],["104552.5","0.09134661","0","1"],["104552.1","0.00115191","0","1"],["104551.1","0.09935084","0","1"],["104550.5","0.09860392","0","1"],["104550.2","0.09077337","0","1"],["104550.1","0.07298372","0","1"],["104549.5","0.16976148","0","1"],["104548.1","0.00478091","0","1"],["104547.7","0.00098","0","1"],["104547.5","0.16934823","0","1"],["104546.4","0.000015","0","1"],["104546.3","0","0","0"],["104545.8","0.11258819","0","2"],["104545.7","0","0","0"],["104545.1","0.01072235","0","1"],["104545","0","0","0"],["104544.8","0.16311427","0","1"],["104544.7","0","0","0"],["104544.2","0","0","0"],["104543.6","0.02889794","0","1"],["104542.7","0","0","0"],["104542.5","0.25276342","0","2"],["104541.3","0.13863367","0","1"],["104540.1","0.00001","0","1"],["104539.5","0.27229479","0","1"],["104539","0.01","0","2"],["104538.9","0.002","0","1"],["104538.6","0.24404363","0","1"],["104537.7","0","0","0"],["104535.7","0","0","0"],["104535.6","0.08903262","0","1"],["104534.7","0.00094847","0","1"],["104533.8","0.00191","0","1"],["104532.9","0","0","0"],["104531.8","0","0","0"],["104529.7","0.00056666","0","1"],["104522.7","0.45355771","0","1"],["104521.9","0.00479165","0","2"],["104510","0.00028006","0","1"],["104507.7","0.00047819","0","1"],["104503.5","0.77923542","0","2"],["104501.4","0.00007731","0","1"],["104496.4","0.00001","0","1"],["104457.9","0.00010193","0","1"],["104456.8","0.01089578","0","1"],["104446.6","0.00063783","0","1"],["104442.8","0","0","0"],["104439","0.00083818","0","1"],["104437","0.01059604","0","1"],["104405.9","0.00095617","0","1"],["104404.4","0","0","0"],["104401.1","0","0","0"],["104401","0","0","0"],["104400","0","0","0"],["104399.9","0","0","0"],["104399.7","0","0","0"],["104399.6","0","0","0"],["104399.4","0","0","0"],["104398.8","0","0","0"],["104398.1","0","0","0"],["104398","0","0","0"],["104397.6","0","0","0"],["104396.6","0","0","0"],["104396.3","0","0","0"],["104395.8","0","0","0"]],"ts":"1747170010100","checksum":-255728756,"seqId":54226036479,"prevSeqId":54226035785}]}
{"arg":{"channel":"books","instId":"BTC-USDT"},"action":"update","data":[{"asks":[["104563.2","0.00533513","0","3"],["104563.8","0","0","0"],["104564","0.005","0","1"],["104566","0","0","0"],["104566.8","0","0","0"],["104567.1","0","0","0"],["104567.2","0","0","0"],["104567.8","0","0","0"],["104568.8","0.00067735","0","1"],["104568.9","0","0","0"],["104569.7","0","0","0"],["104569.9","0","0","0"],["104570.6","0","0","0"],["104570.7","0","0","0"],["104571.5","0","0","0"],["104571.6","0.04","0","1"],["104571.8","0.00001","0","1"],["104572","0.0816","0","1"],["104572.5","0.1033534","0","1"],["104573.6","0","0","0"],["104574.1","0.09287278","0","1"],["104574.6","0.10125876","0","1"],["104574.7","0","0","0"],["104575.5","0.16871508","0","3"],["104575.7","0.00001","0","1"],["104576.2","0.09215769","0","2"],["104577","0","0","0"],["104577.6","0.48231977","0","2"],["104579","0.16181685","0","1"],["104579.6","0.32897317","0","2"],["104579.7","0.12901","0","5"],["104579.8","0","0","0"],["104579.9","0","0","0"],["104580.3","0","0","0"],["104582","0","0","0"],["104582.5","0","0","0"],["104582.6","0.00017125","0","1"],["104584.6","0.2594644","0","1"],["104585.1","0.27134792","0","1"],["104585.5","0.1043","0","1"],["104586","0.00478091","0","1"],["104586.1","0.38863185","0","1"],["104586.3","0","0","0"],["104586.6","0.04","0","1"],["104587.2","0.04057085","0","1"],["104588.7","0.26399015","0","1"],["104592","0.000015","0","1"],["104593","0","0","0"],["104593.7","0","0","0"],["104595.1","0.04056777","0","1"],["104595.6","0.00001","0","1"],["104596.3","0.1386254","0","1"],["104597","0.002","0","2"],["104598","0.001","0","1"],["104598.3","0.00013762","0","1"],["104598.4","0.38167986","0","1"],["104600.4","0","0","0"],["104603.9","0","0","0"],["104607.4","0.00147012","0","1"],["104608.2","0.09564","0","1"],["104609.6","0","0","0"],["104610.5","0","0","0"],["104611.3","0.09564","0","1"],["104613","0.00843297","0","2"],["104614","0","0","0"],["104615.5","0.00048817","0","2"],["104617.5","0","0","0"],["104617.6","0.10004964","0","2"],["104619","0.33","0","6"],["104620","0.16720842","0","6"],["104620.1","0.03","0","1"],["104620.7","0.0015522","0","1"],["104622.1","0","0","0"],["104624.7","0","0","0"],["104628.8","0.00175256","0","1"],["104635","0","0","0"],["104635.1","0","0","0"],["104639.9","0.00287","0","1"],["104688.9","0.0013552","0","2"],["104740.9","0.01448251","0","1"],["104741.9","0.00008643","0","1"],["104742.1","0.03","0","1"],["104742.8","0.00001611","0","1"],["104743.1","0.00011716","0","4"],["104743.5","0.234","0","1"],["104744.3","0.00005567","0","1"],["104744.7","0.00029761","0","1"]],"bids":[["104563.1","0.70537689","0","11"],["104562.7","0.08956","0","1"],["104562.6","0.18263889","0","1"],["104562.5","0.02841992","0","1"],["104562.4","0.052","0","2"],["104562","0.0816","0","1"],["104560.8","0.052","0","2"],["104560.3","0.02256561","0","1"],["104560.2","0.02842056","0","1"],["104560.1","0","0","0"],["104560","0.08161","0","2"],["104557.8","0.07298372","0","1"],["104557.3","0.052","0","2"],["104557.2","0.00956189","0","1"],["104556.7","0","0","0"],["104556.1","0.00115191","0","1"],["104556","0.08400106","0","3"],["104555.9","0.18098879","0","2"],["104555.1","0.09519218","0","1"],["104555","0.08775273","0","1"],["104554.9","0","0","0"],["104553.7","0.15355663","0","4"],["104553.1","0.10667882","0","2"],["104552.5","0","0","0"],["104552.1","0.15945559","0","1"],["104551.5","0.1706775","0","3"],["104551.1","0","0","0"],["104550.5","0","0","0"],["104550.2","0.28084011","0","1"],["104550.1","0.243037","0","2"],["104550","0.11849663","0","5"],["104549.5","0","0","0"],["104548.1","0.1386254","0","1"],["104547.5","0","0","0"],["104546.7","0","0","0"],["104545.8","0.10161827","0","2"],["104545.1","0.2737158","0","2"],["104544.8","0","0","0"],["104542.5","0.00098","0","1"],["104542.1","0.2521181","0","1"],["104541.3","0","0","0"],["104541.2","0.26734534","0","1"],["104539.5","0","0","0"],["104538.6","0","0","0"],["104534.3","0.07324","0","1"],["104531.1","0.02868564","0","1"],["104527.8","0","0","0"],["104520.6","0","0","0"],["104515.3","0","0","0"],["104513.8","0","0","0"],["104513.3","0.00007315","0","1"],["104505","0.0478094","0","1"],["104501.4","0.01899862","0","2"],["104494.5","0","0","0"],["104486.2","0.05279819","0","1"],["104485.9","0","0","0"],["104449.6","0.0006377","0","1"],["104446.6","0","0","0"],["104441.1","0.00085823","0","2"],["104439","0","0","0"],["104401.1","0.00001","0","1"],["104401","0.00023525","0","1"],["104400","0.112661","0","48"]],"ts":"1747170010200","checksum":269262122,"seqId":54226037011,"prevSeqId":54226036479}]}
{"arg":{"channel":"books","instId":"BTC-USDT"},"action":"update","data":[{"asks":[["104568.8","0","0","0"],["104570.9","0","0","0"],["104571","0.000455","0","2"],["104571.7","0.0280818","0","1"],["104572.5","0","0","0"],["104574.1","0","0","0"],["104574.3","0.02754059","0","1"],["104574.5","0.00067735","0","1"],["104574.6","0.09397243","0","1"],["104575.1","0.09139849","0","1"],["104575.4","0","0","0"],["104575.5","0.072","0","2"],["104576.1","0.08724851","0","1"],["104576.2","0.00478206","0","1"],["104576.3","0.02256561","0","1"],["104576.6","0","0","0"],["104576.7","0.09578085","0","1"],["104577.6","0.25996571","0","2"],["104577.8","0.036","0","1"],["104579","0","0","0"],["104579.3","0.03748854","0","1"],["104579.6","0.21572022","0","2"],["104580","0.03820843","0","4"],["104580.1","0.31452687","0","2"],["104580.8","0","0","0"],["104583","0.59186998","0","3"],["104583.4","0.22916316","0","1"],["104584.6","0","0","0"],["104585.1","0.25416418","0","1"],["104585.5","0","0","0"],["104585.6","0.23847207","0","1"],["104586","0","0","0"],["104586.6","0.04286823","0","2"],["104587.5","0.00478052","0","1"],["104588.7","0","0","0"],["104588.8","0.1778392","0","1"],["104589.2","0.25678781","0","1"],["104592.6","0","0","0"],["104595.6","0.48022635","0","2"],["104596.3","0","0","0"],["104598.3","0","0","0"],["104599.4","0.13862104","0","1"],["104600.3","0.00711203","0","1"],["104601","0.00013762","0","1"],["104605.1","0","0","0"],["104608.2","0","0","0"],["104611.3","0","0","0"],["104614.4","0.18595969","0","2"],["104617.6","0.00004964","0","1"],["104618","0.1","0","1"],["104619","0","0","0"],["104620","0.00220843","0","3"],["104621","0.33","0","6"],["104621.8","0","0","0"],["104622","0.21699999","0","5"],["104622.7","0.234","0","1"],["104662.2","0.01051995","0","1"],["104663.6","0.01051995","0","1"],["104665.4","0","0","0"],["104666.2","0.01051995","0","1"],["104667.7","0.01051995","0","1"],["104680.4","6.16664823","0","1"],["104682.6","0","0","0"],["104683.4","0","0","0"],["104700.7","0","0","0"],["104703.1","0","0","0"],["104704.8","0.08027368","0","1"],["104707.1","0","0","0"],["104716.5","2.94779435","0","2"],["104718","0.0579494","0","2"],["104744.8","0.0000112","0","1"],["104746.1","0.00453577","0","1"]],"bids":[["104563.1","0.87446799","0","13"],["104562.2","0.00011839","0","1"],["104555.9","0.3420562","0","2"],["104555.7","0.00478052","0","1"],["104555.6","0.18778614","0","2"],["104555.1","0","0","0"],["104555","0","0","0"],["104554.2","0.09225653","0","1"],["104553.7","0.06173959","0","3"],["104553.6","0.09754796","0","1"],["104553.1","0","0","0"],["104552.6","0.16801501","0","1"],["104552.1","0.30082558","0","2"],["104551.5","0.01","0","2"],["104550.6","0.16610925","0","1"],["104550.2","0.18090356","0","1"],["104550.1","0.07298372","0","1"],["104548.4","0.24175625","0","1"],["104548.1","0","0","0"],["104548","0.23911162","0","3"],["104545.8","0.24044208","0","3"],["104545.6","0.24711891","0","1"],["104545.1","0.01072235","0","1"],["104542.6","0.25982562","0","1"],["104542.1","0","0","0"],["104541.7","0.25435488","0","1"],["104541.2","0","0","0"],["104523.7","0","0","0"],["104520.2","0.04645291","0","2"],["104509.5","0.00287","0","1"],["104504.5","0.01778474","0","1"],["104461.7","0.011","0","1"],["104460.8","0.00009695","0","1"],["104457.9","0","0","0"],["104453.6","0","0","0"],["104408","0.00095614","0","1"],["104405.9","0","0","0"],["104403.4","0","0","0"],["104402.9","0","0","0"],["104402.2","0","0","0"],["104401.1","0","0","0"],["104401","0","0","0"],["104400","0","0","0"]],"ts":"1747170010300","checksum":-1169421129,"seqId":54226037223,"prevSeqId":54226037011}]}
{"arg":{"channel":"books","instId":"BTC-USDT"},"action":"update","data":[{"asks":[["104569","0","0","0"],["104574.2","0.00067735","0","1"],["104574.5","0.16266184","0","2"],["104574.6","0","0","0"],["104575.1","0","0","0"],["104575.7","0.19243972","0","2"],["104576.1","0","0","0"],["104576.7","0","0","0"],["104579.2","0.77959876","0","2"],["104579.6","0.05977788","0","1"],["104580.1","0","0","0"],["104580.4","0.02867795","0","1"],["104583","0.43584321","0","2"],["104583.4","0","0","0"],["104585.1","0","0","0"],["104585.6","0","0","0"],["104586.5","0.00478043","0","1"],["104586.7","0.00191","0","1"],["104587.5","0","0","0"],["104587.6","0.17728372","0","2"],["104589","0.071712","0","1"],["104589.2","0","0","0"],["104592","0.001925","0","2"],["104597.4","0.13862364","0","1"],["104599.4","0","0","0"],["104614.6","0.554034","0","1"],["104615.9","0.00004128","0","1"],["104671.1","0.00009494","0","1"],["104674.1","0.06695","0","1"],["104677","6.16664823","0","1"],["104680.4","0","0","0"],["104746.7","0.00239084","0","1"],["104747","0.77866876","0","1"]],"bids":[["104563.1","0.8994245","0","15"],["104560.3","0","0","0"],["104558.1","0.00115191","0","1"],["104556.1","0","0","0"],["104556","0.08161","0","2"],["104555.9","0.33898766","0","2"],["104555.7","0","0","0"],["104555.6","0","0","0"],["104554.3","0.00478043","0","1"],["104554.2","0","0","0"],["104553.9","0.01105938","0","1"],["104553.6","0","0","0"],["104552.6","0","0","0"],["104552.1","0","0","0"],["104550.6","0","0","0"],["104550.1","0.21160736","0","2"],["104548.7","0.24889095","0","1"],["104548.4","0","0","0"],["104548","0.08161","0","2"],["104545.8","0.32665446","0","3"],["104545.6","0","0","0"],["104542.6","0","0","0"],["104541.7","0","0","0"],["104539.6","0.00191","0","1"],["104534.4","0.00191","0","1"],["104533.8","0","0","0"],["104528.6","0","0","0"],["104514.1","0.39545113","0","1"],["104511.7","0","0","0"],["104504.5","0","0","0"],["104493.1","0.81277612","0","3"],["104480.3","0.01059677","0","1"],["104462.5","0.00011811","0","1"],["104460.8","0","0","0"],["104449.5","0.00817215","0","1"],["104438.9","0","0","0"],["104410.9","0.0009561","0","1"],["104408","0","0","0"],["104403.4","0.00001334","0","1"],["104402.9","0.00001373","0","1"],["104402.2","0.00003809","0","1"],["104401.1","0.00001","0","1"],["104401","0.00023525","0","1"],["104400","0.112661","0","48"],["104399.9","0.0051225","0","9"],["104399.7","0.01401146","0","1"],["104399.6","0.01364893","0","1"],["104399.4","0.00041858","0","1"],["104398.8","0.77874386","0","4"],["104398.1","0.07298372","0","1"]],"ts":"1747170010400","checksum":-1424050523,"seqId":54226037451,"prevSeqId":54226037223}]}
{"arg":{"channel":"books","instId":"BTC-USDT"},"action":"update","data":[{"asks":[["104563.2","0","0","0"],["104564","0","0","0"],["104566.2","0","0","0"],["104568","0","0","0"],["104568.5","0","0","0"],["104569.2","0","0","0"],["104569.8","0","0","0"],["104570","0","0","0"],["104571","0","0","0"],["104571.6","0","0","0"],["104571.7","0","0","0"],["104572","0","0","0"],["104574","0","0","0"],["104574.2","0","0","0"],["104574.3","0","0","0"],["104574.5","0","0","0"],["104575.5","0.04","0","1"],["104575.7","0.00001","0","1"],["104576.2","0","0","0"],["104576.3","0","0","0"],["104577","0.00093","0","1"],["104577.4","0.10209049","0","1"],["104577.6","0","0","0"],["104577.8","0","0","0"],["104577.9","0.0901604","0","1"],["104578.3","0.09149799","0","1"],["104578.9","0.08730338","0","1"],["104579.2","0","0","0"],["104579.3","0","0","0"],["104579.5","0.08776042","0","1"],["104579.6","0.00067735","0","1"],["104579.7","0.00001","0","1"],["104580","0.00220843","0","3"],["104580.6","0","0","0"],["104581.5","0","0","0"],["104582.2","0.00093","0","1"],["104582.4","0.32220271","0","2"],["104582.9","0.31942522","0","2"],["104583","0","0","0"],["104583.1","0","0","0"],["104584.2","0.2719598","0","1"],["104584.3","0.04","0","1"],["104584.6","0.072","0","2"],["104585.8","0.16424996","0","1"],["104586.1","0","0","0"],["104586.5","0","0","0"],["104586.6","0","0","0"],["104587.2","0","0","0"],["104587.6","0","0","0"],["104587.9","0.25454278","0","1"],["104588.2","0","0","0"],["104588.4","0.26283371","0","1"],["104588.7","0.45073783","0","3"],["104588.8","0.2408392","0","3"],["104589","0","0","0"],["104592","0.29629934","0","4"],["104594.6","0.04","0","1"],["104596.4","0","0","0"],["104597","0","0","0"],["104597.4","0","0","0"],["104598","0","0","0"],["104602","0.002","0","2"],["104603","0.001","0","1"],["104607.2","0.78614395","0","1"],["104608","0","0","0"],["104609.6","0.13860775","0","1"],["104610.5","0.102083","0","1"],["104614.4","0.13680169","0","1"],["104614.6","1.44195289","0","1"],["104615.9","0","0","0"],["104621","0","0","0"],["104621.3","0","0","0"],["104622","0.052","0","2"],["104623","0.32999999","0","6"],["104624","0.16499999","0","3"],["104628.9","0","0","0"],["104632.3","0.02869074","0","1"],["104638.6","0.04654811","0","1"],["104645.9","2.58951579","0","1"],["104653.7","0.44883783","0","1"],["104664.5","0","0","0"],["104677","5.92465142","0","1"],["104696.9","0.08183933","0","1"],["104746.7","0","0","0"],["104747.2","0.00001055","0","1"],["104748","0.00108568","0","1"],["104748.9","0.03","0","1"],["104749.5","0.000015","0","1"],["104749.6","0.00002296","0","1"],["104749.9","0.00021362","0","1"],["104750","0.0294814","0","38"],["104750.5","0.07299861","0","2"],["104750.7","0.00049233","0","7"],["104751","0.00122988","0","1"],["104751.9","0.00001969","0","1"],["104753.2","0.0000358","0","1"],["104753.3","2.3905","0","1"],["104754","0.234","0","1"],["104754.2","0.00089983","0","1"],["104754.7","0.00001","0","1"]],"bids":[["104571.7","0.09569","0","2"],["104571.5","0.43976345","0","5"],["104570.9","0.00009","0","1"],["104569.1","0.1938","0","3"],["104568.4","0.25697","0","4"],["104566.1","0.1909","0","3"],["104564","0.01475756","0","2"],["104563.9","0.40757687","0","7"],["104563.8","1.14079255","0","15"],["104563.2","0.62959227","0","4"],["104563.1","0.523124","0","9"],["104562.7","0","0","0"],["104562.6","0","0","0"],["104562.5","0","0","0"],["104562.1","0.13860775","0","1"],["104560","0.08189006","0","3"],["104558.4","0.18928409","0","2"],["104558.3","0.02889794","0","1"],["104558.1","0","0","0"],["104558","0.0816","0","1"],["104557.8","0.00098","0","1"],["104557","0.09734413","0","1"],["104556.4","0.09256696","0","1"],["104556.2","0.00478028","0","1"],["104555.9","0.28550565","0","2"],["104555.4","0.16141579","0","1"],["104554.9","0.00011866","0","1"],["104554.3","0","0","0"],["104553.4","0.15478144","0","1"],["104553.1","0.19242972","0","1"],["104553","0","0","0"],["104552.6","0.00098","0","1"],["104551.8","0","0","0"],["104551.7","0","0","0"],["104551.1","0.23599455","0","1"],["104550.8","0.15747553","0","1"],["104550.4","0.47110074","0","1"],["104550.3","0.77866876","0","1"],["104550.2","0","0","0"],["104550.1","0.07298372","0","1"],["104550","0.08193024","0","4"],["104549","0.04","0","1"],["104548.8","0.38863185","0","1"],["104548.7","0","0","0"],["104547.7","0","0","0"],["104546.5","0","0","0"],["104545.8","0.10161827","0","2"],["104545.4","0.26281817","0","2"],["104544.5","0.25107594","0","1"],["104543.6","0","0","0"],["104543.2","0.06","0","2"],["104542.5","0","0","0"],["104539.1","0.02869074","0","1"],["104539","0.073","0","4"],["104538","0","0","0"],["104535.4","0.03","0","1"],["104534.7","0.00314847","0","2"],["104531.2","0.09","0","3"],["104528.1","0","0","0"],["104526.5","0.07298372","0","1"],["104525.9","0.59215","0","1"],["104525.2","0.67533354","0","1"],["104522.7","1.88710697","0","2"],["104521.9","0.00001","0","1"],["104520.3","0","0","0"],["104520.2","0.00029004","0","1"],["104518","0.01434826","0","1"],["104516.8","0.0022","0","1"],["104513.9","0.01677865","0","1"],["104502.8","0","0","0"],["104501.8","0.06068474","0","2"],["104496.8","0","0","0"],["104494.4","0.00939231","0","1"],["104493.1","0.25809812","0","2"],["104491.9","0","0","0"],["104491.3","2.57148346","0","1"],["104472.1","0.0022","0","1"],["104471.2","0.01912691","0","1"],["104456.1","0","0","0"],["104452.7","0","0","0"],["104443.3","0","0","0"],["104404","0","0","0"],["104403.9","0","0","0"],["104403.4","0","0","0"],["104402.9","0","0","0"],["104402.2","0","0","0"],["104401.1","0","0","0"],["104401","0","0","0"],["104400","0","0","0"],["104399.9","0","0","0"],["104399.7","0","0","0"],["104399.6","0","0","0"],["104399.4","0","0","0"],["104398.8","0","0","0"],["104398.1","0","0","0"]],"ts":"1747170010500","checksum":203635359,"seqId":54226038069,"prevSeqId":54226037451}]}
{"arg":{"channel":"books","instId":"BTC-USDT"},"action":"update","data":[{"asks":[["104571.8","0","0","0"],["104575.5","0","0","0"],["104575.7","0","0","0"],["104576.5","0.20186171","0","5"],["104577","0","0","0"],["104577.4","0","0","0"],["104577.9","0","0","0"],["104578","0.0816","0","1"],["104578.8","0","0","0"],["104578.9","0","0","0"],["104579.5","0","0","0"],["104579.6","0","0","0"],["104580","0.08380843","0","4"],["104580.4","0","0","0"],["104582.2","0","0","0"],["104582.4","0","0","0"],["104582.9","0","0","0"],["104583.8","0.02807856","0","1"],["104584.1","0.00067735","0","1"],["104584.2","0.20170952","0","2"],["104584.3","0","0","0"],["104584.6","0.04","0","1"],["104584.9","0","0","0"],["104585","0","0","0"],["104585.4","0.09951844","0","1"],["104585.8","0","0","0"],["104585.9","0.08938035","0","1"],["104586.5","0.04","0","1"],["104586.6","0.03748854","0","1"],["104586.7","0","0","0"],["104586.9","0.09462483","0","1"],["104587.5","0.09289021","0","1"],["104587.9","0","0","0"],["104588.3","0.53901759","0","3"],["104588.4","0","0","0"],["104588.7","0.04804564","0","1"],["104588.8","0.1778392","0","1"],["104590.2","0","0","0"],["104590.4","0.16632497","0","2"],["104590.9","0.33360976","0","2"],["104591.9","0.00478019","0","1"],["104592","0.05979288","0","2"],["104593","0.036","0","1"],["104593.7","0.14601192","0","1"],["104593.8","0","0","0"],["104594.1","0.24433911","0","1"],["104594.4","0.03286799","0","2"],["104594.6","0","0","0"],["104595.6","0.44154899","0","3"],["104595.7","0","0","0"],["104595.9","0.23979347","0","1"],["104596.4","0.25649684","0","1"],["104596.5","0.10439","0","1"],["104596.7","0.1778392","0","1"],["104596.8","0.19242972","0","1"],["104598.4","0.5340857","0","2"],["104598.9","0.073912","0","2"],["104600","0.25181126","0","4"],["104600.3","0","0","0"],["104600.6","0.00478119","0","1"],["104601.2","0.1778392","0","1"],["104602","0","0","0"],["104602.3","0.1778392","0","1"],["104602.6","0.04","0","1"],["104603","0","0","0"],["104603.1","0.1386165","0","1"],["104605.8","0.15436007","0","1"],["104606.5","0.1778392","0","1"],["104607.2","0","0","0"],["104608","0.002","0","2"],["104609","0.001","0","1"],["104609.6","0","0","0"],["104610.1","0.35553438","0","2"],["104610.3","0.00711203","0","1"],["104615.5","0.00001","0","1"],["104615.8","0.54639","0","1"],["104618","0","0","0"],["104618.7","0.1","0","1"],["104620.7","0","0","0"],["104623","0","0","0"],["104623.3","0.6755","0","1"],["104624","0","0","0"],["104628.8","0","0","0"],["104630","0.33029006","0","8"],["104631","0.16499999","0","3"],["104633.2","0.00479878","0","3"],["104633.8","0.0015672","0","2"],["104639.2","0.0008017","0","1"],["104639.6","2.43884","0","1"],["104641.1","0.00175256","0","1"],["104648.6","0.00080365","0","1"],["104649.7","0.11467","0","1"],["104649.9","0.00004128","0","1"],["104662.3","0","0","0"],["104671.8","0","0","0"],["104674","0.01089693","0","1"],["104677","0","0","0"],["104685.5","0.03825002","0","1"],["104690.2","0.0191253","0","1"],["104691","0","0","0"],["104723.5","0.00090772","0","1"],["104751","0","0","0"],["104754","0","0","0"],["104754.7","0","0","0"]],"bids":[["104576.4","0.64572751","0","11"],["104576.1","0.04728923","0","1"],["104576","0.0816","0","1"],["104575.6","0.02403078","0","1"],["104575.4","0.052","0","2"],["104572","0.08443972","0","2"],["104571.8","0.06436945","0","1"],["104571.7","0.052","0","2"],["104571.5","0.02841749","0","1"],["104570","0.08161","0","2"],["104569.1","0","0","0"],["104568.5","0.05244735","0","1"],["104568.4","0","0","0"],["104566.5","0.00115191","0","1"],["104566.4","0.18086895","0","2"],["104566.1","0","0","0"],["104565","0.10032568","0","1"],["104564.4","0.0927867","0","1"],["104564","0.4268443","0","1"],["104563.9","0.01905321","0","2"],["104563.8","0.292","0","3"],["104563.6","0.071712","0","1"],["104563.4","0.15175709","0","1"],["104563.2","0.24521663","0","2"],["104563.1","0.4976904","0","7"],["104562.9","0.1512057","0","1"],["104562.2","0","0","0"],["104562.1","0","0","0"],["104561.4","0.15655998","0","1"],["104560.8","0.38644854","0","4"],["104560.3","0.00478019","0","1"],["104559.1","0.25615165","0","1"],["104558.7","0.16598345","0","1"],["104558.4","0","0","0"],["104557","0","0","0"],["104556.9","0.000015","0","1"],["104556.4","0.262589","0","1"],["104556.2","0","0","0"],["104555.9","0.32821987","0","2"],["104555.4","0","0","0"],["104554.9","0.1386165","0","1"],["104554","0.10239","0","2"],["104553.9","0.1778392","0","1"],["104553.4","0.26428305","0","1"],["104552.5","0.24559881","0","1"],["104552","0.00001","0","1"],["104551.1","0","0","0"],["104550.8","0","0","0"],["104550","0.00033024","0","3"],["104548","0.00001","0","1"],["104546.3","0.06","0","2"],["104546.2","0","0","0"],["104545.4","0.00017476","0","1"],["104544.5","0","0","0"],["104542.6","0.05970903","0","1"],["104539.9","0.00478119","0","1"],["104536","0","0","0"],["104535.6","0","0","0"],["104535.4","0","0","0"],["104531.2","0.03","0","1"],["104529.8","0.00286799","0","1"],["104529.7","0.00534785","0","2"],["104525.7","0.17769518","0","1"],["104524.6","0.1778392","0","1"],["104520","0.0061907","0","6"],["104507.7","0","0","0"],["104502.4","0.07177","0","1"],["104501.8","0.0429","0","1"],["104501.4","0.00007731","0","1"],["104498.7","0","0","0"],["104498.4","0.07298372","0","1"],["104496.1","0","0","0"],["104491.6","0.27932","0","1"],["104490.7","0.02277464","0","3"],["104479.2","0.01148554","0","1"],["104477.9","0","0","0"],["104470.2","0.06845434","0","2"],["104462.6","0.00063747","0","1"],["104455.6","0.00083783","0","1"],["104449.6","0","0","0"],["104444.8","0","0","0"],["104441.1","0.00002018","0","1"],["104427.3","0.03","0","1"],["104408.5","0","0","0"],["104407.9","0","0","0"],["104407.5","0","0","0"],["104407.2","0","0","0"],["104406.5","0","0","0"],["104405.8","0","0","0"],["104405.1","0","0","0"],["104404.3","0","0","0"],["104404.2","0","0","0"],["104404.1","0","0","0"]],"ts":"1747170010600","checksum":955810447,"seqId":54226038697,"prevSeqId":54226038069}]}
{"arg":{"channel":"books","instId":"BTC-USDT"},"action":"update","data":[{"asks":[["104576.5","0.19875171","0","5"],["104578.3","0","0","0"],["104581.8","0.02807909","0","1"],["104584.2","0.19884725","0","2"],["104584.3","0.00044","0","1"],["104585.4","0","0","0"],["104585.6","0.09363266","0","1"],["104585.7","0.02256561","0","1"],["104585.9","0","0","0"],["104586.1","0.09782455","0","1"],["104586.9","0","0","0"],["104587","0.0879539","0","1"],["104587.5","0","0","0"],["104587.7","0.0915624","0","2"],["104588.3","0.75745148","0","2"],["104588.6","0.02867795","0","1"],["104589.6","0.00093","0","1"],["104590.3","0.072","0","2"],["104590.4","0.00478119","0","1"],["104590.5","0.1521282","0","1"],["104590.8","0.77866876","0","1"],["104590.9","0","0","0"],["104591.1","0.31227485","0","2"],["104591.9","0","0","0"],["104593.7","0","0","0"],["104593.8","0.00478012","0","1"],["104593.9","0.15638889","0","1"],["104594.1","0","0","0"],["104594.3","0.25650962","0","1"],["104594.4","0.06286799","0","3"],["104594.5","0.033","0","1"],["104594.8","0.00093","0","1"],["104595.6","0.44702295","0","3"],["104595.9","0","0","0"],["104596.1","0.2622708","0","1"],["104596.4","0","0","0"],["104596.6","0.6437679","0","2"],["104600","0.00220843","0","3"],["104600.2","0.26470143","0","1"],["104601","0","0","0"],["104614.3","0.0001376","0","1"],["104618.7","0","0","0"],["104620.8","0.22820332","0","2"],["104623.9","0.09562","0","1"],["104628.8","0.00047811","0","1"],["104631.3","0.1","0","1"],["104649.4","0.09556","0","1"],["104649.9","0","0","0"],["104651.2","0.19111","0","1"],["104748.9","0","0","0"],["104749.5","0","0","0"],["104749.6","0","0","0"],["104749.9","0","0","0"],["104750","0","0","0"],["104750.5","0","0","0"],["104750.7","0","0","0"],["104751.9","0","0","0"],["104753.2","0","0","0"],["104753.3","0","0","0"],["104754.2","0","0","0"]],"bids":[["104576.4","0.64581751","0","12"],["104576.1","0.06671","0","2"],["104575.7","0.02841634","0","1"],["104572","0.0816","0","1"],["104570.9","0","0","0"],["104568.6","0.00051","0","1"],["104566.7","0.00115191","0","1"],["104566.6","0.09689078","0","1"],["104566.5","0.09630309","0","1"],["104566.4","0","0","0"],["104565.2","0.09793937","0","1"],["104565","0","0","0"],["104564.6","0.09601531","0","1"],["104564.4","0","0","0"],["104564.1","0.64757598","0","1"],["104564","0","0","0"],["104563.6","0.22627366","0","2"],["104563.4","0","0","0"],["104563.1","0.4971804","0","6"],["104563","0.15148352","0","1"],["104562.9","0","0","0"],["104561.6","0.16642487","0","1"],["104561.4","0","0","0"],["104560.9","0.00478012","0","1"],["104560.8","0.3362206","0","4"],["104560.3","0","0","0"],["104559.3","0.2509502","0","1"],["104559.1","0","0","0"],["104558.9","0.1572769","0","1"],["104558.7","0","0","0"],["104557.8","0","0","0"],["104556.6","0.23788283","0","1"],["104556.4","0","0","0"],["104555.9","0.36983323","0","2"],["104553.6","0.25533451","0","1"],["104553.4","0","0","0"],["104552.7","0.26533967","0","1"],["104552.6","0","0","0"],["104552.5","0","0","0"],["104550.5","0.06","0","2"],["104546.3","0.123","0","4"],["104543.2","0.03","0","1"],["104541","0.11192372","0","2"],["104539","0.04","0","3"],["104524.1","0.00047811","0","1"],["104501.5","0.00001","0","1"],["104501.4","0","0","0"],["104499.3","0","0","0"],["104498.3","0.14","0","1"],["104493.1","0.25802081","0","1"]],"ts":"1747170010700","checksum":-563774444,"seqId":54226038860,"prevSeqId":54226038697}]}
{"arg":{"channel":"books","instId":"BTC-USDT"},"action":"update","data":[{"asks":[["104576.5","0.33466647","0","12"],["104579","0.02807984","0","1"],["104580.9","0.02256561","0","1"],["104584.2","0.29992392","0","2"],["104585.6","0","0","0"],["104585.7","0","0","0"],["104585.9","0.00355877","0","1"],["104586","0.38863185","0","1"],["104586.1","0","0","0"],["104587","0","0","0"],["104587.7","0.00001","0","1"],["104590.5","0","0","0"],["104591.1","0","0","0"],["104591.9","0.00478012","0","1"],["104593.8","0","0","0"],["104593.9","0","0","0"],["104594.3","0","0","0"],["104594.7","0.48998987","0","1"],["104595.6","0.00001","0","1"],["104596.1","0","0","0"],["104596.6","0.38863185","0","1"],["104600.2","0","0","0"],["104614.5","0.413048","0","1"],["104620.1","0","0","0"],["104621.5","0.553997","0","1"],["104641.5","0.14335","0","1"],["104663.3","0.00004128","0","1"],["104670.2","6.04465142","0","2"],["104671.1","0","0","0"],["104686.9","0.00095522","0","1"],["104723.5","0","0","0"],["104748.9","0.03","0","1"],["104749.5","0.000015","0","1"],["104749.6","0.00002296","0","1"],["104749.9","0.00021362","0","1"]],"bids":[["104576.4","0.11532935","0","6"],["104576.1","0","0","0"],["104576","0","0","0"],["104575.7","0","0","0"],["104575.6","0","0","0"],["104575.5","0.03528","0","1"],["104575.4","0.036","0","1"],["104573.8","0.02841686","0","1"],["104572.1","0.02256561","0","1"],["104571.7","0.036","0","1"],["104568.6","0.00062865","0","2"],["104566.7","0","0","0"],["104566.6","0","0","0"],["104566.5","0","0","0"],["104565.2","0","0","0"],["104564.6","0","0","0"],["104564.2","0.00115191","0","1"],["104564.1","0.28903895","0","2"],["104563.8","0.052","0","2"],["104563.6","0.071712","0","1"],["104563.3","0.00098","0","1"],["104563.2","0.00521663","0","1"],["104563.1","0.2547895","0","4"],["104563","0","0","0"],["104561.6","0","0","0"],["104560.9","0","0","0"],["104560.8","0.24098826","0","4"],["104559.3","0","0","0"],["104558.9","0","0","0"],["104558.4","0.00478012","0","1"],["104558.1","0.00098","0","1"],["104557.7","0.22847566","0","1"],["104556.6","0","0","0"],["104555.9","0.43619825","0","2"],["104554.1","0.19242972","0","1"],["104553.6","0","0","0"],["104553.1","0","0","0"],["104552.7","0","0","0"],["104551.1","0.04632457","0","1"],["104550.4","0","0","0"],["104550.3","0","0","0"],["104548.9","0.77866876","0","1"],["104544","0","0","0"],["104543.2","0","0","0"],["104539","0.01","0","2"],["104531.2","0","0","0"],["104501.4","0.0047125","0","1"],["104500","0.55834076","0","12"],["104499.3","0.0047125","0","1"],["104498.3","0.1447125","0","2"],["104493.1","0.26273331","0","2"],["104476.6","0.00009873","0","1"],["104462.5","0","0","0"],["104447.3","0.229526","0","1"],["104424.4","0.00095599","0","1"],["104415.1","0","0","0"],["104410.9","0","0","0"],["104408.5","0.00003352","0","1"],["104407.9","0.00002454","0","1"],["104407.5","0.03","0","1"],["104407.2","0.00001147","0","1"],["104406.5","0.03","0","1"],["104405.8","0.00001051","0","1"],["104405.1","0.00002566","0","1"],["104404.3","0.160633","0","1"],["104404.2","0.00008559","0","1"],["104404.1","0.00005489","0","1"]],"ts":"1747170010800","checksum":-286319381,"seqId":54226039077,"prevSeqId":54226038860}]}
{"arg":{"channel":"books","instId":"BTC-USDT"},"action":"update","data":[{"asks":[["104576.5","0.57466647","0","13"],["104577.9","0.06631894","0","1"],["104579","0","0","0"],["104584.2","0.29665368","0","2"],["104585","0.08999358","0","1"],["104585.5","0.09239422","0","1"],["104586.5","0.13661107","0","2"],["104587.1","0.09337022","0","1"],["104588.3","1.00485116","0","3"],["104588.7","0.50765603","0","2"],["104590","0.1603183","0","3"],["104590.5","0.31634307","0","2"],["104591.9","0","0","0"],["104593.3","0.52069372","0","1"],["104593.4","0.15054418","0","1"],["104593.8","0.25437094","0","1"],["104594.3","0.00478012","0","1"],["104594.7","0","0","0"],["104595.5","0.25276433","0","1"],["104596","0.25631213","0","1"],["104599.6","0.23825184","0","2"],["104600","0.00411843","0","4"],["104605.3","0.00191","0","1"],["104605.7","0.04056368","0","1"],["104620.8","0.18218805","0","2"],["104623.9","0","0","0"],["104639.3","0.09558","0","2"],["104648","0","0","0"],["104653.7","0","0","0"],["104656.7","5.92465142","0","1"],["104670.2","0.12","0","1"],["104674.1","0","0","0"],["104747","0","0","0"],["104747.2","0","0","0"],["104748","0","0","0"],["104748.9","0","0","0"],["104749.5","0","0","0"],["104749.6","0","0","0"],["104749.9","0","0","0"]],"bids":[["104576.4","0.33643181","0","9"],["104575.5","0.07064474","0","2"],["104574","0.0816","0","1"],["104566","0.18712176","0","2"],["104565.7","0.00115191","0","1"],["104564.6","0.09099645","0","1"],["104564.2","0","0","0"],["104564.1","0.26430035","0","2"],["104564","0.0917902","0","1"],["104563","0.17055844","0","1"],["104562.5","0.15792952","0","1"],["104561.6","0.00478012","0","1"],["104561","0.16436013","0","1"],["104560.8","0.21989557","0","3"],["104559.8","0.00711203","0","1"],["104558.8","0.256028","0","1"],["104558.4","0.14675756","0","1"],["104557.7","0","0","0"],["104555.9","0.29304178","0","1"],["104553","0.2601871","0","1"],["104552.9","0.00191","0","1"],["104552.1","0.24910896","0","1"],["104547.6","0.00191","0","1"],["104539.6","0","0","0"],["104534.4","0","0","0"],["104526.6","0.0490949","0","1"],["104408.8","0","0","0"],["104408.6","0","0","0"],["104408.5","0","0","0"],["104407.9","0","0","0"],["104407.5","0","0","0"],["104407.2","0","0","0"],["104406.5","0","0","0"],["104405.8","0","0","0"],["104405.1","0","0","0"],["104404.3","0","0","0"],["104404.2","0","0","0"],["104404.1","0","0","0"]],"ts":"1747170010900","checksum":405581047,"seqId":54226039261,"prevSeqId":54226039077}]}
{"arg":{"channel":"books","instId":"BTC-USDT"},"action":"update","data":[{"asks":[["104576.5","0.46386574","0","12"],["104577.9","0","0","0"],["104581.4","0.05849883","0","1"],["104581.8","0","0","0"],["104585","0.02753777","0","1"],["104585.1","0.09600435","0","1"],["104585.5","0","0","0"],["104585.6","0.09110685","0","1"],["104586.7","0.08774824","0","1"],["104590.5","0","0","0"],["104590.6","0.32912068","0","2"],["104595.5","0","0","0"],["104595.6","0.24697788","0","2"],["104596","0","0","0"],["104596.1","0.25501376","0","1"],["104617.6","0","0","0"],["104620.8","0.27780805","0","3"],["104621.1","0","0","0"],["104623.9","0.09562","0","1"],["104633.1","0.00004964","0","1"],["104643.8","0.07348012","0","2"],["104649","0.09556","0","1"],["104649.4","0","0","0"],["104684.8","0.00009686","0","1"],["104737.9","0","0","0"]],"bids":[["104576.4","0.35243181","0","10"],["104575.7","0.02841633","0","1"],["104571.5","0","0","0"],["104566.2","0.00115191","0","1"],["104566.1","0.09048903","0","1"],["104566","0.09376088","0","1"],["104565.7","0","0","0"],["104564.1","0.36166336","0","3"],["104564","0","0","0"],["104563.1","0.42408113","0","5"],["104563","0","0","0"],["104561.1","0.16243962","0","1"],["104561","0","0","0"],["104556.1","0.59181793","0","2"],["104555.9","0","0","0"],["104553.1","0.24489291","0","1"],["104553","0","0","0"],["104541.5","0.65788","0","1"],["104522.6","0","0","0"],["104516.2","0.00001","0","1"],["104408.8","2.1376","0","1"]],"ts":"1747170011000","checksum":-2056104761,"seqId":54226039330,"prevSeqId":54226039261}]}
{"arg":{"channel":"books","instId":"BTC-USDT"},"action":"update","data":[{"asks":[["104582.6","0.00122019","0","2"],["104585","0","0","0"],["104614.4","0.70398006","0","2"],["104645.8","1.19045409","0","1"],["104648.2","0","0","0"],["104679.8","0.93932622","0","2"],["104747","0.77866876","0","1"]],"bids":[["104424.1","0.00478119","0","1"],["104417.5","0","0","0"],["104413.6","0","0","0"],["104408.6","0.0008379","0","2"]],"ts":"1747170011100","checksum":1600946567,"seqId":54226039359,"prevSeqId":54226039330}]}
{"arg":{"channel":"books","instId":"BTC-USDT"},"action":"update","data":[{"asks":[["104581.9","0.02807907","0","1"],["104582.6","0.00226913","0","3"],["104585","0.0970052","0","1"],["104585.1","0","0","0"],["104585.5","0.10167562","0","1"],["104585.6","0","0","0"],["104586.4","0.09530624","0","1"],["104586.5","0.04","0","1"],["104589.9","0.16320622","0","1"],["104590","0.00029006","0","2"],["104590.5","0.30640669","0","2"],["104590.6","0","0","0"],["104593.3","0.71289009","0","3"],["104593.4","0","0","0"],["104593.7","0.25071318","0","1"],["104593.8","0","0","0"],["104595.4","0","0","0"],["104595.5","0.27144732","0","1"],["104595.6","0.00001","0","1"],["104596","0.24062433","0","1"],["104596.1","0","0","0"],["104610.1","0.35610104","0","3"],["104636.3","0.00056666","0","1"],["104695","0.00001","0","1"],["104698.8","0.00001","0","1"],["104736.7","0.00091031","0","1"],["104743.5","0","0","0"],["104744.3","0","0","0"],["104744.7","0","0","0"],["104744.8","0","0","0"],["104746.1","0","0","0"],["104747","0","0","0"]],"bids":[["104576.4","0.28708181","0","8"],["104575.7","0","0","0"],["104572.6","0.02403147","0","1"],["104570.6","0.00056666","0","1"],["104566.2","0","0","0"],["104566.1","0.00115191","0","1"],["104566","0.09718526","0","1"],["104565.9","0.08714464","0","1"],["104564.4","0.00004781","0","1"],["104564.1","0.26430035","0","2"],["104564","0.10200714","0","1"],["104563.1","0.2547895","0","4"],["104563","0.15660447","0","1"],["104562.5","0","0","0"],["104562.4","0.20151597","0","3"],["104561.1","0","0","0"],["104561","0.15885262","0","1"],["104560.8","0.2702996","0","4"],["104558.8","0","0","0"],["104558.7","0.26040196","0","1"],["104558.4","0","0","0"],["104558.3","0.1934264","0","2"],["104556.1","0.33649619","0","1"],["104556","0.32715358","0","3"],["104553.1","0","0","0"],["104553","0.25604993","0","1"],["104545.1","0","0","0"],["104544.4","0.00056666","0","1"],["104529.7","0.00478119","0","1"],["104503.5","0.77866876","0","1"],["104408.8","0","0","0"],["104408.6","0","0","0"]],"ts":"1747170011200","checksum":-164994700,"seqId":54226039430,"prevSeqId":54226039359}]}
{"arg":{"channel":"books","instId":"BTC-USDT"},"action":"update","data":[{"asks":[["104588.7","0.04804564","0","1"],["104591.5","0.46797001","0","1"],["104601.1","0","0","0"],["104603.2","0","0","0"],["104604.3","0","0","0"],["104609.5","0","0","0"],["104743.5","0.234","0","1"],["104744.3","0.00005567","0","1"],["104744.7","0.00029761","0","1"]],"bids":[["104559.8","0","0","0"],["104553.2","0.00711203","0","1"]],"ts":"1747170011300","checksum":-164994700,"seqId":54226039439,"prevSeqId":54226039430}]}
{"arg":{"channel":"books","instId":"BTC-USDT"},"action":"update","data":[{"asks":[["104581.4","0","0","0"],["104585.8","0.07298372","0","1"],["104603.1","0","0","0"],["104605.9","0.430547","0","2"],["104648","0.06694","0","1"],["104674.1","0.06694","0","1"],["104744.7","0","0","0"]],"bids":[["104558.8","0.13861214","0","1"],["104554.9","0","0","0"]],"ts":"1747170011400","checksum":2894024,"seqId":54226039450,"prevSeqId":54226039439}]}
{"arg":{"channel":"books","instId":"BTC-USDT"},"action":"update","data":[{"asks":[["104581.8","0.00101416","0","1"],["104601.1","0.00455","0","1"],["104603.2","0.00455","0","1"],["104604.3","0.00455","0","1"],["104609.5","0.00455","0","1"],["104742.1","0","0","0"],["104742.8","0","0","0"],["104743.1","0","0","0"],["104743.5","0","0","0"],["104744.3","0","0","0"]],"bids":[["104576.4","0.28996181","0","9"]],"ts":"1747170011500","checksum":128863228,"seqId":54226039467,"prevSeqId":54226039450}]}
{"arg":{"channel":"books","instId":"BTC-USDT"},"action":"update","data":[{"asks":[["104576.5","0.22386574","0","11"],["104581.8","0.00202831","0","2"],["104591.4","0.00478016","0","1"],["104594.3","0","0","0"]],"bids":[["104576","0.0816","0","1"],["104561.6","0","0","0"],["104559.5","0.00478016","0","1"],["104409.1","0","0","0"]],"ts":"1747170011600","checksum":431373458,"seqId":54226039475,"prevSeqId":54226039467}]}
{"arg":{"channel":"books","instId":"BTC-USDT"},"action":"update","data":[{"asks":[["104585","0","0","0"],["104585.4","0.09459988","0","1"],["104585.5","0","0","0"],["104585.9","0.09396803","0","2"],["104586","0","0","0"],["104586.4","0","0","0"],["104586.9","0.09703552","0","1"],["104587.1","0","0","0"],["104587.3","0.08774824","0","1"],["104587.5","0.09037517","0","1"],["104589.9","0","0","0"],["104590.4","0.16407164","0","2"],["104590.5","0","0","0"],["104590.9","0.33394274","0","2"],["104593.3","0.60930901","0","2"],["104593.7","0","0","0"],["104593.8","0.16467253","0","1"],["104594.1","0.24805749","0","1"],["104595.5","0","0","0"],["104595.9","0.27039821","0","1"],["104596","0","0","0"],["104596.4","0.27193281","0","1"],["104599.6","0.00001","0","1"],["104600","0.24620165","0","5"],["104608","0","0","0"],["104609","0","0","0"],["104611","0.002","0","2"],["104612","0.001","0","1"],["104630","0.00029006","0","2"],["104631","0","0","0"],["104633","0.82439814","0","7"],["104634","0.165015","0","4"],["104656.7","0","0","0"],["104660.1","5.92465142","0","1"],["104742.1","0.03","0","1"],["104742.8","0.00001611","0","1"]],"bids":[["104576.4","0.29264181","0","10"],["104576.1","0.10674418","0","1"],["104575.5","0","0","0"],["104566.4","0.18107614","0","2"],["104566.1","0","0","0"],["104566","0","0","0"],["104565.9","0","0","0"],["104565.1","0.00115191","0","1"],["104565","0.09607616","0","1"],["104564.6","0","0","0"],["104564.4","0.09732631","0","2"],["104564.1","0.2350635","0","2"],["104564","0","0","0"],["104563.4","0.15073261","0","1"],["104563","0","0","0"],["104562.9","0.16292884","0","1"],["104562.4","0.052","0","2"],["104561.4","0.16104353","0","1"],["104561","0","0","0"],["104560.8","0.37483686","0","4"],["104559.1","0.23914028","0","1"],["104558.8","0.28762282","0","2"],["104558.7","0","0","0"],["104558.3","0.02889794","0","1"],["104556.4","0.24895672","0","1"],["104556.1","0.3479167","0","2"],["104556","0.08161","0","2"],["104553.4","0.25465419","0","1"],["104553","0","0","0"],["104552.5","0.25665766","0","1"],["104552.1","0","0","0"],["104517","0.03249981","0","1"],["104494.8","0","0","0"]],"ts":"1747170011700","checksum":-284618389,"seqId":54226039591,"prevSeqId":54226039475}]}
{"arg":{"channel":"books","instId":"BTC-USDT"},"action":"update","data":[{"asks":[["104576.5","0.22365539","0","11"],["104577.9","0.05850371","0","1"],["104581.9","0","0","0"],["104582","0.02807904","0","1"],["104584.2","0.37938597","0","2"],["104585.4","0","0","0"],["104585.9","0","0","0"],["104586.1","0.38863185","0","1"],["104586.5","0","0","0"],["104586.9","0","0","0"],["104587.5","0","0","0"],["104587.6","0.04","0","1"],["104590.4","0.00478119","0","1"],["104590.9","0","0","0"],["104593.3","0.59699169","0","2"],["104593.8","0","0","0"],["104594.1","0","0","0"],["104595.9","0","0","0"],["104596.4","0","0","0"],["104600","0.00411843","0","4"],["104610","0.23628006","0","4"],["104611","0.001","0","1"],["104612","0","0","0"],["104632","0.64126567","0","5"],["104633","0.69439814","0","5"],["104634","0.03501501","0","2"],["104743.1","0.00011716","0","4"],["104744.3","0.00005567","0","1"],["104744.7","0.00029761","0","1"],["104744.8","0.0000112","0","1"],["104746.1","0.00453577","0","1"],["104747","0.77866876","0","1"],["104747.2","0.00001055","0","1"],["104748","0.00108568","0","1"]],"bids":[["104576.4","0.15106181","0","6"],["104576.1","0","0","0"],["104573.8","0","0","0"],["104572.6","0","0","0"],["104572.3","0.02403154","0","1"],["104566.4","0","0","0"],["104565.1","0.26602547","0","1"],["104565","0","0","0"],["104564.4","0.00004781","0","1"],["104564.2","0.00115191","0","1"],["104564.1","0","0","0"],["104563.9","0.01155321","0","1"],["104563.4","0","0","0"],["104562.9","0","0","0"],["104561.4","0","0","0"],["104560.8","0.37805734","0","4"],["104559.1","0","0","0"],["104558.8","0.13861214","0","1"],["104556.4","0","0","0"],["104556.1","0.35339857","0","2"],["104553.4","0","0","0"],["104552.5","0","0","0"],["104549","0.42767068","0","2"],["104525.2","0","0","0"],["104522.7","0.45355771","0","1"],["104449.1","0.12","0","1"],["104409.1","0.00001","0","1"],["104408.8","2.1376","0","1"],["104408.6","0.0008379","0","2"],["104408.5","0.00003352","0","1"],["104407.9","0.00002454","0","1"],["104407.5","0.03","0","1"],["104407.2","0.00001147","0","1"],["104406.5","0.03","0","1"],["104405.8","0.00001051","0","1"],["104405.1","0.00002566","0","1"],["104404.3","0.160633","0","1"]],"ts":"1747170011800","checksum":694692558,"seqId":54226039836,"prevSeqId":54226039591}]}
{"arg":{"channel":"books","instId":"BTC-USDT"},"action":"update","data":[{"asks":[["104576.5","0.46365539","0","12"],["104580.9","0","0","0"],["104582","0","0","0"],["104584.2","0.36992443","0","2"],["104585","0.09964322","0","1"],["104585.3","0.02753768","0","1"],["104585.5","0.09573917","0","1"],["104585.9","0.00362332","0","1"],["104586.5","0.09281047","0","1"],["104587.1","0.09407694","0","1"],["104590","0.16233524","0","3"],["104590.5","0.31747107","0","2"],["104593.3","0.53337982","0","2"],["104593.4","0.15040726","0","1"],["104593.7","0.25334934","0","1"],["104595.1","0","0","0"],["104595.2","0.05561368","0","1"],["104595.5","0.24436505","0","1"],["104596","0.24481712","0","1"],["104599.6","0.25132102","0","2"],["104608","0.002","0","2"],["104609","0.001","0","1"],["104610","0.23428006","0","2"],["104611","0","0","0"],["104620.8","0.18218805","0","2"],["104623.9","0","0","0"],["104630","0.26029006","0","6"],["104631","0.12999999","0","2"],["104632","0.38126567","0","1"],["104633","0.56439815","0","3"],["104647.9","0.00004128","0","1"],["104649","0","0","0"],["104663.3","0","0","0"],["104742.8","0","0","0"],["104743.1","0","0","0"],["104744.3","0","0","0"],["104744.7","0","0","0"],["104744.8","0","0","0"],["104746.1","0","0","0"],["104747","0","0","0"],["104747.2","0","0","0"],["104748","0","0","0"]],"bids":[["104576.4","0.28976181","0","9"],["104576.1","0.09821915","0","1"],["104571.8","0.0513758","0","1"],["104570","0.10564206","0","3"],["104568.6","0.00051","0","1"],["104566.1","0.00115191","0","1"],["104566","0.19202326","0","2"],["104565.1","0.18287438","0","2"],["104564.6","0.09040761","0","1"],["104564.2","0","0","0"],["104564","0.09537259","0","1"],["104563.1","0.08856639","0","3"],["104563","0.15746158","0","1"],["104562.5","0.15218594","0","1"],["104561","0.15195492","0","1"],["104560.8","0.25442928","0","4"],["104558.7","0.25218661","0","1"],["104558.4","0.16555665","0","1"],["104556.1","0.37245147","0","2"],["104556","0.34050043","0","3"],["104553","0.25051303","0","1"],["104552.1","0.23670633","0","1"],["104551.6","0.00011867","0","1"],["104409.4","0","0","0"],["104409.1","0","0","0"],["104408.8","0","0","0"],["104408.6","0","0","0"],["104408.5","0","0","0"],["104407.9","0","0","0"],["104407.5","0","0","0"],["104407.2","0","0","0"],["104406.5","0","0","0"],["104405.8","0","0","0"],["104405.1","0","0","0"],["104404.3","0","0","0"]],"ts":"1747170011900","checksum":-867448276,"seqId":54226040025,"prevSeqId":54226039836}]}
{"arg":{"channel":"books","instId":"BTC-USDT"},"action":"update","data":[{"asks":[["104576.5","0.22365539","0","11"],["104577.9","0","0","0"],["104583.8","0","0","0"],["104585.3","0","0","0"],["104587.4","0.02753712","0","1"],["104588.7","0","0","0"],["104611.4","0.04056147","0","1"],["104620.8","0.27780805","0","3"],["104623.9","0.09562","0","1"],["104742.8","0.00001611","0","1"]],"bids":[["104574.1","0.02841676","0","1"],["104570","0.08161","0","2"],["104535.2","1.43236191","0","1"],["104410.8","0","0","0"],["104410","0","0","0"]],"ts":"1747170012000","checksum":2133695182,"seqId":54226040072,"prevSeqId":54226040025}]}
{"arg":{"channel":"books","instId":"BTC-USDT"},"action":"update","data":[{"asks":[["104580.4","0.05550058","0","1"],["104585","0","0","0"],["104585.4","0.09089846","0","1"],["104585.5","0","0","0"],["104585.9","0.09915455","0","2"],["104586.5","0","0","0"],["104586.9","0.08803248","0","1"],["104587.1","0","0","0"],["104587.3","0","0","0"],["104587.5","0.10039055","0","1"],["104588.3","0.75745148","0","2"],["104590","0.00029006","0","2"],["104590.4","0.14887504","0","2"],["104590.5","0","0","0"],["104590.9","0.32147917","0","2"],["104591.4","0","0","0"],["104592.9","0.00478015","0","1"],["104593.3","0.60839185","0","2"],["104593.4","0","0","0"],["104593.7","0","0","0"],["104593.8","0.16312042","0","1"],["104594.1","0.25346664","0","1"],["104595.5","0","0","0"],["104595.9","0.27000902","0","1"],["104596","0","0","0"],["104596.4","0.25036186","0","1"],["104599.6","0.00001","0","1"],["104600","0.25508181","0","5"],["104605.6","0.13861269","0","1"],["104605.9","0.29193486","0","1"],["104610.1","0.35553438","0","2"],["104612.6","0.00056666","0","1"],["104614.3","0","0","0"],["104614.4","0.70411766","0","3"],["104626.6","0.35033662","0","1"],["104630","0.33029006","0","8"],["104631","0.16499999","0","3"],["104633","0.49439815","0","1"],["104633.8","0.000015","0","1"],["104634","0.00001501","0","1"],["104635.3","0.0015522","0","1"],["104636.3","0","0","0"],["104638.8","0.00056666","0","1"],["104641.1","0","0","0"],["104641.4","0.00175261","0","1"],["104658.7","2.08439417","0","2"],["104742.1","0","0","0"],["104742.8","0","0","0"]],"bids":[["104573.1","0.00056666","0","1"],["104570.6","0","0","0"],["104566.5","0.00115191","0","1"],["104566.4","0.1936167","0","2"],["104566.1","0","0","0"],["104566","0","0","0"],["104565.1","0.26835451","0","2"],["104565","0.0968044","0","1"],["104564.9","0.07298372","0","1"],["104564.6","0","0","0"],["104564.4","0.10121976","0","2"],["104564","0","0","0"],["104563.4","0.1640662","0","1"],["104563","0","0","0"],["104562.9","0.15002219","0","1"],["104562.5","0","0","0"],["104561.4","0.15591064","0","1"],["104561","0","0","0"],["104560.8","0.37256463","0","4"],["104560.3","0.00478015","0","1"],["104559.5","0","0","0"],["104559.1","0.23308535","0","1"],["104558.8","0.15992142","0","1"],["104558.7","0","0","0"],["104558.4","0","0","0"],["104558.1","0.13959269","0","2"],["104556.4","0.25774415","0","1"],["104556.1","0.34729506","0","2"],["104556","0.08161","0","2"],["104553.4","0.25813819","0","1"],["104553","0","0","0"],["104552.5","0.24123743","0","1"],["104552.1","0","0","0"],["104546.9","0.00056666","0","1"],["104544.4","0","0","0"],["104535.3","0.48162876","0","1"],["104501.4","0","0","0"],["104499.3","0","0","0"],["104498.3","0.14","0","1"],["104493.1","1.0815304","0","2"],["104462.6","0","0","0"],["104462.4","0.00065241","0","2"],["104410.8","0.00001007","0","1"],["104410","0.00029298","0","2"]],"ts":"1747170012100","checksum":-873247142,"seqId":54226040223,"prevSeqId":54226040072}]}
{"arg":{"channel":"books","instId":"BTC-USDT"},"action":"update","data":[{"asks":[["104580.4","0","0","0"],["104581.5","0.02256561","0","1"],["104585.4","0","0","0"],["104585.5","0.10014879","0","1"],["104590.3","0.07678015","0","3"],["104590.9","0.16658362","0","1"],["104591","0.16976162","0","1"],["104592.9","0","0","0"],["104594.1","0","0","0"],["104594.2","0.23253859","0","1"],["104594.7","0.01912049","0","1"],["104596.4","0","0","0"],["104596.5","0.34341467","0","2"],["104605.6","0","0","0"],["104606.4","0.13861182","0","1"],["104608","0","0","0"],["104609","0.002","0","2"],["104610","0.23528006","0","3"],["104649.3","0.09556","0","1"],["104684.3","0.00009192","0","1"],["104684.8","0","0","0"],["104687.1","0.00001","0","1"],["104741.9","0","0","0"]],"bids":[["104576.4","0.41886181","0","10"],["104564.5","0.09193815","0","1"],["104564.4","0.00004781","0","1"],["104563.9","0.01156321","0","2"],["104563.5","0.16673864","0","1"],["104563.4","0","0","0"],["104560.3","0","0","0"],["104559.2","0.24137814","0","1"],["104559.1","0","0","0"],["104558.9","0.13861182","0","1"],["104558.4","0.00478015","0","1"],["104558.1","0.00098","0","1"],["104553.5","0.25052688","0","1"],["104553.4","0","0","0"],["104551.4","0","0","0"],["104538.9","0","0","0"],["104425.1","0.00095598","0","1"],["104424.4","0","0","0"]],"ts":"1747170012200","checksum":-960122762,"seqId":54226040309,"prevSeqId":54226040223}]}
{"arg":{"channel":"books","instId":"BTC-USDT"},"action":"update","data":[{"asks":[["104585.5","0.12965534","0","2"],["104588.9","0.02753674","0","1"],["104590.3","0.072","0","2"],["104591.4","0.00478015","0","1"],["104605.7","0.13861266","0","1"],["104606.4","0","0","0"],["104740.9","0","0","0"]],"bids":[["104559.5","0.00478015","0","1"],["104558.9","0","0","0"],["104558.4","0.13861266","0","1"]],"ts":"1747170012300","checksum":-1514912885,"seqId":54226040332,"prevSeqId":54226040309}]}
{"arg":{"channel":"books","instId":"BTC-USDT"},"action":"update","data":[{"asks":[["104591.4","0","0","0"],["104591.5","0","0","0"],["104591.9","0.00478015","0","1"],["104595.3","0.45470388","0","1"],["104605.7","0.13861323","0","1"],["104684.2","0.00009475","0","1"],["104684.3","0","0","0"],["104736.3","0.77957557","0","2"],["104736.7","0","0","0"],["104740.9","0.01448251","0","1"]],"bids":[["104558.4","0","0","0"],["104557.4","0.13861323","0","1"],["104502.7","0.01426223","0","1"],["104500.6","0.01426223","0","1"],["104499.6","0.01895542","0","2"],["104494.4","0.01895468","0","2"],["104477.6","1.03337883","0","2"],["104476.6","0","0","0"],["104425.4","0.32428415","0","2"],["104425.1","0","0","0"]],"ts":"1747170012400","checksum":-1514912885,"seqId":54226040362,"prevSeqId":54226040332}]}
{"arg":{"channel":"books","instId":"BTC-USDT"},"action":"update","data":[{"asks":[["104581.4","0.05499895","0","1"],["104581.5","0","0","0"],["104583.5","0.0295071","0","1"],["104585.4","0.10155277","0","1"],["104585.5","0.02950655","0","1"],["104586.7","0.10687016","0","2"],["104587.4","0","0","0"],["104588.9","0","0","0"],["104589.7","0.05620395","0","1"],["104590.9","0.33364955","0","2"],["104591","0","0","0"],["104594.1","0.23053358","0","1"],["104594.2","0","0","0"],["104594.7","0","0","0"],["104596.4","0.25767482","0","1"],["104596.5","0.10439","0","1"]],"bids":[["104576.4","0.29855681","0","9"],["104574.1","0","0","0"],["104570.8","0.0280141","0","1"],["104564.5","0","0","0"],["104564.4","0.10047724","0","2"],["104563.5","0","0","0"],["104563.4","0.15070494","0","1"],["104559.2","0","0","0"],["104559.1","0.23046027","0","1"],["104557.4","0","0","0"],["104556.5","0.13861514","0","1"],["104553.5","0","0","0"],["104553.4","0.25026828","0","1"],["104538.8","0.00956126","0","1"]],"ts":"1747170012500","checksum":725171707,"seqId":54226040396,"prevSeqId":54226040362}]}
{"arg":{"channel":"books","instId":"BTC-USDT"},"action":"update","data":[{"asks":[["104576.5","0.22363627","0","11"],["104581.3","0.02256561","0","1"],["104583.5","0","0","0"],["104585.4","0","0","0"],["104585.5","0.13042858","0","2"],["104587.4","0.02709446","0","1"],["104590.9","0.16658362","0","1"],["104591","0.16330475","0","1"],["104594.1","0","0","0"],["104594.2","0.23539107","0","1"],["104596.4","0","0","0"],["104596.5","0.35214435","0","2"]],"bids":[["104576.4","0.37807181","0","10"],["104574.4","0.02753155","0","1"],["104570.8","0","0","0"],["104564.5","0.10062092","0","1"],["104564.4","0.00004781","0","1"],["104563.5","0.15290299","0","1"],["104563.4","0","0","0"],["104559.2","0.24570655","0","1"],["104559.1","0","0","0"],["104553.5","0.25502944","0","1"],["104553.4","0","0","0"],["104501.5","0","0","0"]],"ts":"1747170012600","checksum":-234152034,"seqId":54226040426,"prevSeqId":54226040396}]}
{"arg":{"channel":"books","instId":"BTC-USDT"},"action":"update","data":[{"asks":[["104673.6","0","0","0"],["104741.9","0.00008643","0","1"]],"bids":[["104576.4","0.38006181","0","11"]],"ts":"1747170012700","checksum":-658057806,"seqId":54226040428,"prevSeqId":54226040426}]}
{"arg":{"channel":"books","instId":"BTC-USDT"},"action":"update","data":[{"asks":[["104686.2","0.01348546","0","1"],["104741.9","0","0","0"]],"bids":[],"ts":"1747170012800","checksum":-658057806,"seqId":54226040430,"prevSeqId":54226040428}]}
{"arg":{"channel":"books","instId":"BTC-USDT"},"action":"update","data":[{"asks":[["104576.5","0.46363627","0","12"],["104585","0.09885746","0","1"],["104585.5","0.11926304","0","2"],["104585.9","0.00362332","0","1"],["104586.5","0.09562642","0","1"],["104586.9","0","0","0"],["104587.1","0.08761893","0","1"],["104587.5","0","0","0"],["104590","0.14937331","0","3"],["104590.4","0.00478119","0","1"],["104590.5","0.31897281","0","2"],["104590.9","0","0","0"],["104591","0","0","0"],["104593.4","0.16248037","0","1"],["104593.7","0.25857562","0","1"],["104593.8","0","0","0"],["104594.2","0","0","0"],["104595.3","0.46470388","0","2"],["104595.5","0.25771125","0","1"],["104595.9","0","0","0"],["104596","0.27153878","0","1"],["104596.5","0.10439","0","1"],["104599.6","0.24607091","0","2"],["104600","0.00411843","0","4"],["104740.9","0","0","0"]],"bids":[["104576.4","0.29050181","0","10"],["104566.5","0","0","0"],["104566.4","0","0","0"],["104566.1","0.00115191","0","1"],["104566","0.18626272","0","2"],["104565.1","0.26708654","0","2"],["104565","0","0","0"],["104564.6","0.09529584","0","1"],["104564.5","0","0","0"],["104564","0.09930138","0","1"],["104563.5","0","0","0"],["104563","0.16533789","0","1"],["104562.9","0","0","0"],["104562.5","0.14789305","0","1"],["104561.4","0","0","0"],["104561","0.1576827","0","1"],["104560.8","0.29824476","0","4"],["104559.5","0","0","0"],["104559.2","0","0","0"],["104558.8","0.00478015","0","1"],["104558.7","0.23886185","0","1"],["104558.4","0.15937334","0","1"],["104556.4","0","0","0"],["104556.1","0.42656536","0","2"],["104556","0.32518459","0","3"],["104553.5","0","0","0"],["104553","0.25983534","0","1"],["104552.5","0","0","0"],["104552.1","0.26220003","0","1"],["104409.4","0.77866876","0","1"]],"ts":"1747170012900","checksum":393516595,"seqId":54226040551,"prevSeqId":54226040430}]}
{"arg":{"channel":"books","instId":"BTC-USDT"},"action":"update","data":[{"asks":[["104582.8","0.02950731","0","1"],["104586.5","0","0","0"],["104587.1","0","0","0"],["104587.4","0","0","0"],["104590","0.00029006","0","2"],["104591.5","0.01","0","1"],["104593.4","0","0","0"],["104599.6","0.00001","0","1"],["104602.5","0.1386318","0","2"],["104605.7","0","0","0"],["104626.1","0.09562","0","1"],["104740.9","0.01448251","0","1"],["104741.9","0.00008643","0","1"]],"bids":[["104576.4","0.16504681","0","8"],["104574.4","0","0","0"],["104570","0.10962434","0","3"],["104566","0.09100997","0","1"],["104564.6","0","0","0"],["104563.9","0.00001","0","1"],["104562.5","0","0","0"],["104558.4","0","0","0"],["104556.5","0","0","0"],["104554.9","0.13861679","0","1"],["104552.1","0","0","0"],["104409.1","0.00001","0","1"],["104408.8","2.1376","0","1"],["104408.6","0.0008379","0","2"],["104408.5","0.00003352","0","1"],["104407.9","0.00002454","0","1"]],"ts":"1747170013000","checksum":-1497964174,"seqId":54226040578,"prevSeqId":54226040551}]}
{"arg":{"channel":"books","instId":"BTC-USDT"},"action":"update","data":[{"asks":[["104576.5","0.22363627","0","11"],["104582.8","0","0","0"],["104585","0","0","0"],["104585.4","0.09972609","0","1"],["104585.5","0.02950655","0","1"],["104585.9","0.1048709","0","2"],["104586.4","0.02709471","0","1"],["104586.9","0.09090151","0","1"],["104587.5","0.10027138","0","1"],["104590.4","0.15195023","0","2"],["104590.5","0","0","0"],["104590.9","0.30546715","0","2"],["104591.9","0","0","0"],["104592.9","0.00478014","0","1"],["104593.7","0","0","0"],["104593.8","0.15956654","0","1"],["104594.1","0.23409172","0","1"],["104595.5","0","0","0"],["104595.9","0.25373498","0","1"],["104596","0","0","0"],["104596.4","0.25641781","0","1"],["104600","0.24969241","0","5"],["104602.5","0.00001501","0","1"],["104605.7","0.13861547","0","1"],["104612.6","0","0","0"],["104615.1","0.00056666","0","1"],["104619.1","0.60786819","0","2"],["104638.8","0","0","0"],["104641.3","0.00056666","0","1"],["104650.9","0.32089905","0","1"],["104696.9","0","0","0"],["104740.3","0","0","0"],["104740.5","0","0","0"],["104740.9","0","0","0"],["104741.9","0","0","0"]],"bids":[["104576.4","0.30054681","0","10"],["104575.6","0.00056666","0","1"],["104573.1","0","0","0"],["104572.1","0","0","0"],["104566.4","0.180487","0","2"],["104566.1","0","0","0"],["104566","0","0","0"],["104565.2","0.00115191","0","1"],["104565.1","0.13010269","0","1"],["104565","0.09799679","0","1"],["104564.4","0.09709706","0","2"],["104564","0","0","0"],["104563.4","0.15382849","0","1"],["104563","0","0","0"],["104561.4","0.14835999","0","1"],["104561","0","0","0"],["104560.8","0.15077529","0","3"],["104560.3","0.00478014","0","1"],["104560.1","0.01103637","0","1"],["104559.1","0.23630381","0","1"],["104558.8","0.16131777","0","1"],["104558.7","0","0","0"],["104556.2","0.13861547","0","1"],["104556.1","0.19892313","0","1"],["104556","0.08161","0","2"],["104554.9","0","0","0"],["104553.4","0.24049225","0","1"],["104553","0","0","0"],["104552.5","0.26439786","0","1"],["104549.4","0.00056666","0","1"],["104546.9","0","0","0"],["104545.8","0.30372147","0","3"],["104503.8","0.73299643","0","3"],["104408.5","0","0","0"],["104407.9","0","0","0"]],"ts":"1747170013100","checksum":-1385887475,"seqId":54226040693,"prevSeqId":54226040578}]}
{"arg":{"channel":"books","instId":"BTC-USDT"},"action":"update","data":[{"asks":[["104578.7","0.007","0","2"],["104591.2","0.002","0","1"],["104740","0","0","0"]],"bids":[["104576.4","0.29855681","0","9"],["104574.1","0.002","0","1"],["104571.7","0.05856561","0","2"],["104567.9","0.00001","0","1"],["104566.5","0.00115191","0","1"],["104565.2","0","0","0"],["104565.1","0.21593449","0","2"],["104562.9","0.16159244","0","1"],["104561.6","0.002","0","1"],["104560.8","0.26534573","0","4"],["104559.9","0.05201","0","3"],["104556.4","0.24287203","0","1"],["104556.1","0.3483494","0","2"],["104410","0","0","0"],["104409.4","0","0","0"],["104409.1","0","0","0"],["104408.8","0","0","0"],["104408.6","0","0","0"]],"ts":"1747170013200","checksum":-2041664088,"seqId":54226040709,"prevSeqId":54226040693}]}
{"arg":{"channel":"books","instId":"BTC-USDT"},"action":"update","data":[{"asks":[["104576.5","0.22043627","0","10"],["104581.3","0","0","0"],["104581.4","0.07756456","0","2"],["104585.4","0","0","0"],["104585.5","0.0911302","0","1"],["104585.9","0.00362332","0","1"],["104586","0.09770755","0","1"],["104586.4","0","0","0"],["104589.4","0.02709394","0","1"],["104589.7","0","0","0"],["104590.9","0","0","0"],["104591","0.32330701","0","2"],["104592.9","0","0","0"],["104594.1","0","0","0"],["104594.2","0.24751845","0","1"],["104594.3","0.00478013","0","1"],["104595.9","0","0","0"],["104596","0.26151421","0","1"],["104596.4","0","0","0"],["104596.5","0.37505561","0","2"],["104599.4","0.04358398","0","1"],["104647.9","0","0","0"],["104740","0.00219843","0","2"],["104740.3","0.00005155","0","1"],["104740.5","0.00006468","0","1"]],"bids":[["104576.4","0.33883681","0","10"],["104575","0.0275314","0","1"],["104570","0.08161","0","2"],["104566.6","0.00115191","0","1"],["104566.5","0.09930053","0","1"],["104566.4","0.09025832","0","1"],["104564.5","0.09994494","0","1"],["104564.4","0.00004781","0","1"],["104563.5","0.15530539","0","1"],["104563.4","0","0","0"],["104562.5","0.00478013","0","1"],["104561.5","0.16548671","0","1"],["104561.4","0","0","0"],["104560.8","0.36547279","0","3"],["104560.3","0","0","0"],["104559.2","0.25978757","0","1"],["104559.1","0","0","0"],["104558.4","0.13861252","0","1"],["104556.5","0.23921158","0","1"],["104556.4","0","0","0"],["104556.2","0","0","0"],["104553.5","0.26029732","0","1"],["104553.4","0","0","0"],["104539.1","0.03825197","0","2"],["104538.8","0","0","0"],["104411.6","0","0","0"],["104410.8","0","0","0"]],"ts":"1747170013300","checksum":-1935537184,"seqId":54226040765,"prevSeqId":54226040709}]}
{"arg":{"channel":"books","instId":"BTC-USDT"},"action":"update","data":[{"asks":[["104576.5","0.22009204","0","10"],["104587.2","0.02950606","0","1"],["104605.7","0","0","0"],["104607.2","0.13861084","0","1"],["104647.9","0.00004128","0","1"],["104740.3","0","0","0"],["104740.5","0","0","0"]],"bids":[["104576.4","0.42839681","0","11"],["104559.3","0.13861084","0","1"],["104558.4","0","0","0"]],"ts":"1747170013400","checksum":1104449885,"seqId":54226040784,"prevSeqId":54226040765}]}
{"arg":{"channel":"books","instId":"BTC-USDT"},"action":"update","data":[{"asks":[["104576.5","0.22329204","0","11"],["104584.2","0.30682407","0","2"],["104585.5","0.09514183","0","1"],["104585.9","0.10234212","0","2"],["104586","0","0","0"],["104586.9","0.08857235","0","1"],["104587.5","0.09311833","0","1"],["104590.4","0.14780671","0","2"],["104590.9","0.16314207","0","1"],["104591","0.16422985","0","1"],["104591.9","0.00478011","0","1"],["104593.8","0.1623558","0","1"],["104594.2","0.23861293","0","1"],["104594.3","0","0","0"],["104595.9","0.23949284","0","1"],["104596","0","0","0"],["104596.5","0.34979954","0","2"],["104600","0.23971074","0","5"],["104614.4","0.13693929","0","2"],["104614.6","0","0","0"],["104645.8","0","0","0"],["104645.9","0","0","0"],["104647.9","0","0","0"],["104693.1","0.73637508","0","3"],["104740.3","0.00005155","0","1"],["104740.5","0.00006468","0","1"],["104740.9","0.01448251","0","1"],["104741.9","0.00008643","0","1"]],"bids":[["104576.4","0.42692599","0","10"],["104566.6","0","0","0"],["104566.5","0","0","0"],["104566.4","0.18763188","0","2"],["104565.2","0.00115191","0","1"],["104565.1","0.13010269","0","1"],["104565","0.09267633","0","1"],["104564.5","0.09787628","0","1"],["104563.5","0.15561624","0","1"],["104562.9","0.1446686","0","1"],["104562.5","0","0","0"],["104561.5","0","0","0"],["104561.4","0.14950123","0","1"],["104560.8","0.19855838","0","3"],["104560.3","0.00478011","0","1"],["104559.2","0.23129739","0","1"],["104558.8","0.14742551","0","1"],["104556.5","0","0","0"],["104556.4","0.25581103","0","1"],["104556.1","0.19892313","0","1"],["104553.5","0","0","0"],["104552.5","0.25071604","0","1"],["104535.3","0","0","0"],["104535.2","0","0","0"],["104493.1","0.25802081","0","1"],["104491.3","0","0","0"],["104411.6","0.00006","0","1"],["104410.8","0.00001007","0","1"],["104410","0.00029298","0","2"],["104409.4","0.77866876","0","1"],["104409.1","0.00001","0","1"]],"ts":"1747170013500","checksum":-606664266,"seqId":54226040926,"prevSeqId":54226040784}]}
{"arg":{"channel":"books","instId":"BTC-USDT"},"action":"update","data":[{"asks":[["104605.7","0.1386127","0","1"],["104607.2","0","0","0"],["104619.3","1.37001882","0","1"],["104647.9","0.00004128","0","1"],["104650.7","2.53031816","0","1"],["104658.7","0.35085571","0","1"],["104660.1","5.91185069","0","1"],["104740.5","0","0","0"],["104740.9","0","0","0"],["104741.9","0","0","0"]],"bids":[["104566.5","0.00115191","0","1"],["104565.2","0","0","0"],["104565.1","0.25912336","0","2"],["104560.8","0.37203279","0","4"],["104559.3","0","0","0"],["104558.1","0.1395927","0","2"],["104556.1","0.35336244","0","2"],["104553.5","0.2708842","0","1"],["104532.5","1.38828729","0","1"],["104501.1","2.56221267","0","1"],["104409.4","0","0","0"],["104409.1","0","0","0"]],"ts":"1747170013600","checksum":1003228727,"seqId":54226040948,"prevSeqId":54226040926}]}
{"arg":{"channel":"books","instId":"BTC-USDT"},"action":"update","data":[{"asks":[["104576.5","0.22357891","0","12"],["104585.3","0.02950661","0","1"],["104589.4","0","0","0"],["104620.8","0.18218805","0","2"],["104623.9","0","0","0"],["104626.1","0","0","0"],["104639.3","0.00001","0","1"],["104641.5","0","0","0"],["104648","0","0","0"],["104649.3","0","0","0"],["104649.7","0","0","0"],["104651.2","0","0","0"],["104674.1","0","0","0"],["104740.5","0.00006468","0","1"],["104740.9","0.01448251","0","1"],["104741.9","0.00008643","0","1"],["104742.1","0.03","0","1"],["104742.8","0.00001611","0","1"],["104743.1","0.00011716","0","4"],["104743.5","0.234","0","1"],["104744.3","0.00005567","0","1"]],"bids":[["104576.4","0.42846286","0","12"]],"ts":"1747170013700","checksum":-99730263,"seqId":54226040972,"prevSeqId":54226040948}]}
{"arg":{"channel":"books","instId":"BTC-USDT"},"action":"update","data":[{"asks":[["104576.5","0.10087891","0","10"],["104578","0","0","0"],["104581.4","0.05499895","0","1"],["104582","0.0816","0","1"],["104584.1","0","0","0"],["104584.2","0","0","0"],["104585.3","0","0","0"],["104585.5","0","0","0"],["104585.8","0","0","0"],["104585.9","0","0","0"],["104586","0.02256561","0","1"],["104586.1","0.1418721","0","2"],["104586.6","0","0","0"],["104586.7","0.08774824","0","1"],["104586.9","0","0","0"],["104587.2","0","0","0"],["104587.5","0","0","0"],["104587.6","0","0","0"],["104588.3","0.49089055","0","2"],["104588.8","0.09182768","0","1"],["104590.3","0","0","0"],["104590.4","0.00478119","0","1"],["104590.7","0.02709359","0","1"],["104590.9","0","0","0"],["104591","0","0","0"],["104591.9","0","0","0"],["104593","0","0","0"],["104593.3","0.57023244","0","2"],["104593.8","0","0","0"],["104594.2","0","0","0"],["104594.4","0","0","0"],["104594.5","0","0","0"],["104594.6","0.04","0","1"],["104594.8","0.02005032","0","2"],["104595.3","0.01","0","1"],["104595.9","0","0","0"],["104596.5","0.00478011","0","1"],["104598.7","0","0","0"],["104598.9","0.0022","0","1"],["104600","0.00411843","0","4"],["104601.3","1.01595245","0","2"],["104603","0.1778392","0","1"],["104605.7","0","0","0"],["104606","0","0","0"],["104609","0","0","0"],["104610","0.23428006","0","2"],["104610.6","0.00955699","0","1"],["104612","0.002","0","2"],["104612.1","0.13860468","0","1"],["104613","0.00943297","0","3"],["104614.5","0","0","0"],["104620.8","0.13258332","0","1"],["104621.5","0","0","0"],["104623","0.09562","0","1"],["104624.8","0","0","0"],["104626.1","0.09562","0","1"],["104629.7","0.4608965","0","1"],["104630","0.00029006","0","2"],["104631","0","0","0"],["104633","0.82439814","0","7"],["104634","0.165015","0","4"],["104636.7","0.02867103","0","1"],["104648.3","0.80169385","0","2"],["104650.9","0","0","0"],["104651","0","0","0"],["104655.2","0.00001","0","1"],["104662.9","0.04778504","0","1"],["104744.7","0.00029761","0","1"],["104744.8","0.0000112","0","1"],["104746.1","0.00453577","0","1"],["104747","0.77866876","0","1"],["104747.2","0.00001055","0","1"],["104748","0.00108568","0","1"],["104748.4","0.00478119","0","1"],["104748.9","0.03","0","1"],["104749.5","0.000015","0","1"],["104749.6","0.00002296","0","1"],["104749.9","0.00021362","0","1"],["104750","0.0294814","0","38"],["104750.5","0.07299861","0","2"],["104750.7","0.00049233","0","7"],["104751.9","0.00001969","0","1"],["104753.2","0.0000358","0","1"],["104753.3","2.3905","0","1"],["104754.2","0.00089983","0","1"],["104754.7","0.00001","0","1"]],"bids":[["104576.4","0.4581405","0","14"],["104576.3","0.00011837","0","1"],["104575.5","0.02801285","0","1"],["104574.2","0.07298372","0","1"],["104572.3","0","0","0"],["104571.8","0.10288061","0","2"],["104571.7","0.036","0","1"],["104567.8","0.0097982","0","2"],["104566.5","0","0","0"],["104566.4","0","0","0"],["104566.3","0.09348491","0","1"],["104565.1","0.36845664","0","2"],["104565","0.19242972","0","1"],["104564.5","0","0","0"],["104564.4","0.00482792","0","2"],["104564.3","0.13860468","0","1"],["104563.5","0","0","0"],["104562.9","0","0","0"],["104562.4","0.092","0","3"],["104561.4","0","0","0"],["104560.8","0.66139756","0","3"],["104560.3","0","0","0"],["104560.1","1.17833698","0","3"],["104559.2","0","0","0"],["104558.8","0","0","0"],["104558.1","0.00098","0","1"],["104557.2","0","0","0"],["104556.4","0","0","0"],["104556.1","0.19892313","0","1"],["104554.8","0.32440412","0","3"],["104553.8","0.25357976","0","1"],["104553.5","0","0","0"],["104553.2","0","0","0"],["104552.5","0","0","0"],["104549","0.38767068","0","1"],["104542.1","0.00478119","0","1"],["104541.6","0.02868276","0","1"],["104531.1","0","0","0"],["104529.7","0","0","0"],["104529","0.48324487","0","1"],["104526.6","0","0","0"],["104524.8","0.19661649","0","2"],["104519.3","0.1205","0","1"],["104516.7","0.01778474","0","1"],["104515.5","0.05731651","0","2"],["104506","0","0","0"],["104505","0","0","0"],["104500","0.00369976","0","11"],["104482","0.47439916","0","1"],["104473.9","0.011","0","1"],["104461.7","0","0","0"],["104459","0.00010262","0","1"],["104451.9","0.00001501","0","1"],["104450.1","0","0","0"],["104409.4","0.77866876","0","1"],["104409.1","0.00001","0","1"],["104408.8","2.1376","0","1"],["104408.6","0.0008379","0","2"],["104408.5","0.00003352","0","1"],["104407.9","0.00002454","0","1"],["104407.5","0.03","0","1"],["104407.2","0.00001147","0","1"]],"ts":"1747170013800","checksum":-2021090391,"seqId":54226041296,"prevSeqId":54226040972}]}
{"arg":{"channel":"books","instId":"BTC-USDT"},"action":"update","data":[{"asks":[["104576.5","0.07855415","0","6"],["104585.9","0.00067735","0","1"],["104586","0.12661502","0","1"],["104586.1","0","0","0"],["104587","0.09743808","0","1"],["104587.5","0.10152345","0","1"],["104588.3","0.51973416","0","2"],["104588.5","0.09707464","0","1"],["104588.8","0","0","0"],["104589.1","0.09027062","0","1"],["104591.5","0","0","0"],["104592","0.22962672","0","4"],["104592.5","0.33420079","0","2"],["104593.3","0.57517847","0","2"],["104593.5","0.03748854","0","1"],["104595.2","0","0","0"],["104595.4","0.16461911","0","1"],["104595.7","0.24181352","0","1"],["104596.5","0.072","0","2"],["104597.5","0.29954529","0","2"],["104598","0.24991788","0","1"],["104598.3","0.00477988","0","1"],["104598.8","0.071712","0","1"],["104599","0","0","0"],["104600","0.00698629","0","5"],["104600.7","0.093","0","3"],["104601.3","0.77866876","0","1"],["104601.6","0.24817666","0","1"],["104609.3","0.10443","0","1"],["104609.6","0.13860798","0","1"],["104612.1","0","0","0"],["104614.4","0.13680169","0","1"],["104615","0.00013733","0","1"],["104616.3","0.05161433","0","1"],["104624.7","0.02868713","0","1"],["104635.3","0","0","0"],["104642.9","0.06694","0","1"],["104660.1","0","0","0"],["104666.5","0","0","0"],["104666.9","5.94927968","0","2"],["104669","0.06694","0","1"],["104748.9","0","0","0"],["104749.5","0","0","0"],["104749.6","0","0","0"],["104749.9","0","0","0"],["104750","0","0","0"],["104750.5","0","0","0"],["104750.7","0","0","0"],["104751.9","0","0","0"],["104753.2","0","0","0"],["104753.3","0","0","0"],["104754.2","0","0","0"],["104754.7","0","0","0"]],"bids":[["104576.4","0.69102847","0","14"],["104571.8","0.10351838","0","2"],["104571.5","0.00711203","0","1"],["104568.1","0.00023728","0","1"],["104568","0.17898028","0","2"],["104567.8","0.00956092","0","1"],["104566.6","0.09365608","0","1"],["104566.3","0","0","0"],["104566.1","0.00477988","0","1"],["104566","0.10016311","0","1"],["104565.1","0.34690865","0","2"],["104565","0.15099166","0","1"],["104564.6","0.19242972","0","1"],["104564.5","0.14440427","0","1"],["104564.4","0.00004781","0","1"],["104564.3","0","0","0"],["104563.5","0.01103637","0","1"],["104563","0.15640337","0","1"],["104560.9","0.13860798","0","1"],["104560.8","0.50429674","0","3"],["104560.7","0.23147497","0","1"],["104560.4","0.15739974","0","1"],["104558","0.33812809","0","2"],["104556.1","0.35450075","0","2"],["104555","0.27358498","0","1"],["104554.8","0.052","0","2"],["104554.1","0.45135138","0","2"],["104553.8","0","0","0"],["104535.4","0.0459568","0","1"],["104509.1","0","0","0"],["104462.1","0.0425499","0","1"],["104411.6","0","0","0"],["104410.8","0","0","0"],["104410","0","0","0"],["104409.4","0","0","0"],["104409.1","0","0","0"],["104408.8","0","0","0"],["104408.6","0","0","0"],["104408.5","0","0","0"],["104407.9","0","0","0"],["104407.5","0","0","0"],["104407.2","0","0","0"]],"ts":"1747170013900","checksum":588871607,"seqId":54226041497,"prevSeqId":54226041296}]}
{"arg":{"channel":"books","instId":"BTC-USDT"},"action":"update","data":[{"asks":[["104576.5","0.00745415","0","5"],["104580","0.00220843","0","3"],["104581.4","0","0","0"],["104585.9","0","0","0"],["104586","0","0","0"],["104586.2","0","0","0"],["104587","0","0","0"],["104587.4","0.081","0","1"],["104587.5","0","0","0"],["104588.2","0.00067735","0","1"],["104588.3","0","0","0"],["104588.4","0.09050385","0","1"],["104588.5","0","0","0"],["104589.1","0","0","0"],["104589.8","0.09694153","0","1"],["104590.4","0.10331477","0","2"],["104590.7","0","0","0"],["104592","0.08688613","0","3"],["104592.5","0","0","0"],["104593.3","0.52343305","0","2"],["104593.9","0.15332381","0","1"],["104595.4","0","0","0"],["104595.7","0","0","0"],["104596.7","0.33936678","0","2"],["104597.5","0.036","0","1"],["104598","0","0","0"],["104598.3","0","0","0"],["104598.4","0.76100622","0","1"],["104599.4","0.3162332","0","2"],["104599.9","0.00477988","0","1"],["104600.7","0.129","0","4"],["104601.6","0","0","0"],["104602.9","0.24085229","0","1"],["104612","0","0","0"],["104613","0.00843297","0","2"],["104614","0.002","0","2"],["104615","0.00113733","0","2"],["104629.2","0.09562","0","1"],["104633","0.49439815","0","1"],["104633.4","0.553934","0","1"],["104634","0.00001501","0","1"],["104636","0.32999999","0","6"],["104637","0.39899999","0","4"],["104647.9","0","0","0"],["104675.2","0.830569","0","1"],["104748.9","0.03","0","1"],["104749.5","0.000015","0","1"],["104749.6","0.00002296","0","1"],["104749.9","0.00021362","0","1"],["104750","0.0294814","0","38"],["104750.5","0.07299861","0","2"]],"bids":[["104576.4","0.7050406","0","15"],["104571.8","0.16395145","0","2"],["104569.4","0.00023728","0","1"],["104569.3","0.09200875","0","1"],["104568.1","0.00477988","0","1"],["104568","0","0","0"],["104567.9","0.08933594","0","2"],["104567.4","0.09392273","0","1"],["104566.6","0","0","0"],["104566.4","0.16995222","0","1"],["104566.1","0","0","0"],["104566","0","0","0"],["104565.8","0.4894167","0","3"],["104565.1","0","0","0"],["104565","0","0","0"],["104564.5","0","0","0"],["104563","0","0","0"],["104561.7","0.1645964","0","1"],["104560.7","0","0","0"],["104560.4","0","0","0"],["104558.3","0","0","0"],["104558","0.0816","0","1"],["104556.4","0.26615803","0","1"],["104556.1","0.37208848","0","2"],["104555.7","0.1778392","0","1"],["104555.4","0.23545399","0","1"],["104555","0","0","0"],["104554.1","0.19242972","0","1"],["104553.7","0.23957879","0","4"],["104553","0.1778392","0","1"],["104527.6","0","0","0"],["104525.1","0","0","0"],["104524.8","0.01892131","0","1"],["104511.9","0.554578","0","1"],["104508.1","0.00004382","0","1"],["104470.1","3.8659969","0","2"],["104411.6","0.00006","0","1"],["104410.8","0.00001007","0","1"],["104410","0.00029298","0","2"]],"ts":"1747170014000","checksum":603650887,"seqId":54226041748,"prevSeqId":54226041497}]}
{"arg":{"channel":"books","instId":"BTC-USDT"},"action":"update","data":[{"asks":[["104576.5","0.07855415","0","6"],["104580","0.08380843","0","4"],["104586.1","0.02256561","0","1"],["104586.6","0.00067735","0","1"],["104587","0.234","0","1"],["104587.4","0.18143166","0","2"],["104587.9","0.10189726","0","1"],["104588.2","0","0","0"],["104588.4","0","0","0"],["104588.9","0.09189957","0","1"],["104589.3","0.52258187","0","2"],["104589.5","0.0975351","0","1"],["104589.8","0.0036219","0","1"],["104590.1","0","0","0"],["104590.4","0.00478119","0","1"],["104592","0.09127824","0","3"],["104592.4","0.15158379","0","1"],["104592.9","0.31099191","0","2"],["104593.3","0.37054255","0","1"],["104593.9","0","0","0"],["104594.2","0.02709269","0","1"],["104595.3","0","0","0"],["104595.8","0.15651181","0","1"],["104596.1","0.22842942","0","1"],["104596.7","0.1778392","0","1"],["104597.9","0.24918829","0","1"],["104598.4","1.02562891","0","2"],["104598.5","0.00477988","0","1"],["104599.4","0.04358398","0","1"],["104599.9","0","0","0"],["104602","0.25051062","0","1"],["104602.2","0.0517605","0","1"],["104602.6","0","0","0"],["104602.9","0","0","0"],["104605.8","0.22261114","0","2"],["104606.4","0.10443","0","1"],["104606.6","0.04","0","1"],["104607.9","0.03823994","0","1"],["104609.2","0.13860815","0","1"],["104609.6","0","0","0"],["104611.4","0","0","0"],["104614.9","0.00013727","0","1"],["104615","0.001","0","1"],["104615.1","0","0","0"],["104617.7","0.00056666","0","1"],["104630.6","0.69545389","0","2"],["104632","0","0","0"],["104636","0.26","0","4"],["104637","0.36399999","0","3"],["104638","0.07","0","2"],["104639","0.065","0","2"],["104641.2","0.19418233","0","2"],["104641.3","0","0","0"],["104641.4","0","0","0"],["104643.9","0.00056666","0","1"],["104648.2","0.00004128","0","1"],["104666.8","1.95016529","0","2"],["104667.8","0","0","0"],["104747.2","0","0","0"],["104748","0","0","0"],["104748.4","0","0","0"],["104748.9","0","0","0"],["104749.5","0","0","0"],["104749.6","0","0","0"],["104749.9","0","0","0"],["104750","0","0","0"],["104750.5","0","0","0"]],"bids":[["104576.4","0.71546792","0","18"],["104575.6","0","0","0"],["104571.8","0.05768024","0","1"],["104569.5","0.00023728","0","1"],["104569.4","0.05128909","0","1"],["104569.3","0","0","0"],["104568.6","0.02981447","0","2"],["104568.4","0.18836203","0","2"],["104568.1","0","0","0"],["104567.9","0.00001","0","1"],["104567.4","0","0","0"],["104567","0.09222874","0","1"],["104566.4","0.09690217","0","1"],["104566.3","0.00477988","0","1"],["104565.8","0.20117479","0","1"],["104565.4","0.16015023","0","1"],["104564.9","0.22613039","0","2"],["104563.4","0.159638","0","1"],["104561.7","0","0","0"],["104561.1","0.23641638","0","1"],["104560.9","0.13860827","0","1"],["104560.8","0.66704349","0","4"],["104560.1","1.16730061","0","2"],["104558.4","0.25615378","0","1"],["104556.4","0","0","0"],["104555.4","0","0","0"],["104554.5","0.25209171","0","1"],["104553.3","0.1778392","0","1"],["104551.1","0","0","0"],["104550.2","0.00056666","0","1"],["104549.4","0","0","0"],["104532.6","0.43683224","0","1"],["104528.3","0","0","0"],["104503.8","1.31630785","0","2"],["104410.8","0","0","0"],["104410","0","0","0"]],"ts":"1747170014100","checksum":993655055,"seqId":54226042090,"prevSeqId":54226041748}]}
{"arg":{"channel":"books","instId":"BTC-USDT"},"action":"update","data":[{"asks":[["104576.5","0.07809517","0","6"],["104586.2","0.00067735","0","1"],["104586.3","0.19242972","0","1"],["104586.6","0","0","0"],["104589.2","0.38551384","0","1"],["104589.3","0.26864","0","1"],["104595.8","0","0","0"],["104601.1","0","0","0"],["104603.2","0","0","0"],["104604.3","0","0","0"],["104609.3","0","0","0"],["104609.5","0","0","0"],["104610.5","0","0","0"],["104614","0","0","0"],["104615","0.002","0","2"],["104616","0.001","0","1"],["104623","0","0","0"],["104624.4","0.102082","0","1"],["104641.2","0.19242972","0","1"],["104642.8","0.00175261","0","1"],["104663.5","5.93876072","0","1"],["104666.8","0.01089629","0","1"],["104666.9","0.01051896","0","1"],["104684.2","0","0","0"],["104684.6","0.03854721","0","1"],["104736.2","0.00090472","0","1"],["104736.3","0.77866876","0","1"],["104747.2","0.00001055","0","1"],["104748","0.00108568","0","1"],["104748.4","0.00478119","0","1"]],"bids":[["104576.4","0.46958672","0","18"],["104571.8","0.15739154","0","2"],["104569.5","0","0","0"],["104568.7","0.00023728","0","1"],["104565.8","0.31790841","0","2"],["104560.8","0.50429674","0","3"],["104556.1","0.53974647","0","1"],["104555.4","0.25869609","0","1"],["104539.4","0.0095612","0","1"],["104539.1","0.02869074","0","1"],["104536.9","0.15604279","0","1"],["104531.3","0","0","0"],["104477.7","0.01069307","0","2"],["104477.6","1.03328162","0","1"],["104412.1","0","0","0"],["104411.6","0","0","0"]],"ts":"1747170014200","checksum":-149967007,"seqId":54226042160,"prevSeqId":54226042090}]}
{"arg":{"channel":"books","instId":"BTC-USDT"},"action":"update","data":[{"asks":[["104576.7","0.00149753","0","1"],["104587.4","0.081","0","1"],["104588.8","0.09733183","0","1"],["104588.9","0","0","0"],["104592.3","0.15459506","0","1"],["104592.4","0","0","0"],["104592.9","0.15415014","0","1"],["104595.7","0.15565122","0","1"],["104597.2","0.00477988","0","1"],["104598.4","0.76100622","0","1"],["104598.5","0","0","0"],["104605.7","0.13861266","0","1"],["104609.2","0","0","0"],["104629.5","0.0478725","0","1"],["104647.8","0.00004128","0","1"],["104648.2","0","0","0"],["104747.2","0","0","0"],["104748","0","0","0"],["104748.4","0","0","0"]],"bids":[["104576.4","0.45762904","0","17"],["104568.4","0.09459134","0","1"],["104568.3","0.08581708","0","1"],["104566.4","0","0","0"],["104566.3","0","0","0"],["104565.4","0","0","0"],["104565","0.00477988","0","1"],["104564.9","0.07298372","0","1"],["104564.8","0.15302349","0","1"],["104560.9","0","0","0"],["104560.7","0.16186744","0","1"],["104557.4","0.13861317","0","1"],["104555.4","0","0","0"],["104524.8","0","0","0"],["104516.7","0","0","0"],["104412.1","0.0026904","0","1"],["104411.6","0.00006","0","1"]],"ts":"1747170014300","checksum":-1304462277,"seqId":54226042206,"prevSeqId":54226042160}]}
{"arg":{"channel":"books","instId":"BTC-USDT"},"action":"update","data":[{"asks":[["104597.2","0","0","0"],["104597.8","0.00477988","0","1"],["104605.7","0","0","0"],["104606.5","0.31645063","0","2"],["104747.2","0.00001055","0","1"]],"bids":[["104565.9","0.00477988","0","1"],["104565","0","0","0"],["104558.5","0.13861143","0","1"],["104557.4","0","0","0"]],"ts":"1747170014400","checksum":-856848830,"seqId":54226042221,"prevSeqId":54226042206}]}
{"arg":{"channel":"books","instId":"BTC-USDT"},"action":"update","data":[{"asks":[["104587","0","0","0"],["104592","0.03150036","0","2"],["104595.6","0.00478988","0","2"],["104597.8","0","0","0"],["104598.6","0.11177788","0","3"],["104606.5","0.1778392","0","1"],["104609.5","0.0000125","0","1"],["104609.6","0.13860911","0","1"],["104636","0.33","0","6"],["104637","0.39899999","0","4"],["104638","0","0","0"],["104639","0.03","0","1"],["104748","0.00108568","0","1"]],"bids":[["104576.4","0.4722919","0","18"],["104571.5","0","0","0"],["104565.9","0","0","0"],["104563.9","0.00478988","0","2"],["104560.9","0.13860911","0","1"],["104558.5","0","0","0"],["104554.4","0.00711203","0","1"],["104410.8","0.00001007","0","1"]],"ts":"1747170014500","checksum":340678005,"seqId":54226042271,"prevSeqId":54226042221}]}
{"arg":{"channel":"books","instId":"BTC-USDT"},"action":"update","data":[{"asks":[["104576.5","0.07795174","0","6"],["104588.6","0","0","0"],["104590","0.031776","0","3"],["104595.6","0.00001","0","1"],["104596.4","0.00477988","0","1"],["104599.4","0","0","0"],["104601.1","0.0000125","0","1"],["104603.2","0.0000125","0","1"],["104604.3","0.0000125","0","1"],["104747.2","0","0","0"],["104748","0","0","0"]],"bids":[["104576.4","0.4699013","0","17"],["104522.5","0.01892131","0","1"],["104410.8","0","0","0"]],"ts":"1747170014600","checksum":1635005992,"seqId":54226042296,"prevSeqId":54226042271}]}
{"arg":{"channel":"books","instId":"BTC-USDT"},"action":"update","data":[{"asks":[["104595.2","0.02812301","0","1"],["104607.2","0.1386113","0","1"],["104609.6","0","0","0"],["104692.7","0","0","0"],["104724.8","0.24008602","0","2"]],"bids":[["104576.4","0.7099913","0","19"],["104560.9","0","0","0"],["104558.5","0.1386113","0","1"],["104551","0.00377","0","1"],["104411.6","0","0","0"]],"ts":"1747170014700","checksum":1899879310,"seqId":54226042312,"prevSeqId":54226042296}]}
{"arg":{"channel":"books","instId":"BTC-USDT"},"action":"update","data":[{"asks":[["104584.6","0","0","0"],["104587","0.234","0","1"],["104587.8","0.04","0","1"],["104587.9","0","0","0"],["104588","0.10136937","0","1"],["104588.8","0","0","0"],["104588.9","0.09379693","0","1"],["104589.5","0","0","0"],["104589.6","0.09318277","0","2"],["104592.3","0","0","0"],["104592.4","0.16185562","0","1"],["104592.9","0","0","0"],["104593","0.16126794","0","1"],["104593.3","0.51119002","0","2"],["104595.7","0","0","0"],["104595.8","0.15972668","0","1"],["104596.1","0","0","0"],["104596.2","0.24657177","0","1"],["104597.9","0","0","0"],["104598","0.24992062","0","1"],["104598.9","0.10658","0","2"],["104602","0","0","0"],["104602.1","0.30157403","0","3"],["104610.6","0.00955698","0","1"],["104747.2","0.00001055","0","1"]],"bids":[["104576.4","0.46523538","0","18"],["104571.8","0.15877923","0","2"],["104568.5","0.15250884","0","2"],["104568.4","0.09281804","0","1"],["104568.3","0","0","0"],["104567.1","0.09968616","0","1"],["104567","0","0","0"],["104565.8","0.20117479","0","1"],["104564.9","0.23202211","0","2"],["104564.8","0","0","0"],["104563.5","0.17126685","0","2"],["104563.4","0","0","0"],["104561.2","0.25045124","0","1"],["104561.1","0","0","0"],["104560.8","0.67029995","0","4"],["104560.7","0","0","0"],["104558.5","0.37842569","0","2"],["104558.4","0","0","0"],["104554.6","0.25335695","0","1"],["104554.5","0","0","0"],["104411.6","0.00006","0","1"],["104410.8","0.00001007","0","1"],["104410","0.00029298","0","2"],["104409.4","0.77866876","0","1"],["104409.1","0.00001","0","1"]],"ts":"1747170014800","checksum":1387592483,"seqId":54226042366,"prevSeqId":54226042312}]}
{"arg":{"channel":"books","instId":"BTC-USDT"},"action":"update","data":[{"asks":[["104606.4","0","0","0"],["104607.2","0","0","0"],["104609.6","0.13860957","0","1"],["104748","0.00108568","0","1"]],"bids":[["104576.4","0.45532844","0","17"],["104560.3","0.13860957","0","1"],["104558.5","0.23981439","0","1"],["104522.5","0","0","0"]],"ts":"1747170014900","checksum":-288532917,"seqId":54226042374,"prevSeqId":54226042366}]}
{"arg":{"channel":"books","instId":"BTC-USDT"},"action":"update","data":[{"asks":[["104576.5","0.07778919","0","6"],["104636","0.32999999","0","6"]],"bids":[["104576.4","0.69532844","0","18"],["104564.6","0","0","0"],["104408.8","2.1376","0","1"]],"ts":"1747170015000","checksum":1959572057,"seqId":54226042421,"prevSeqId":54226042374}]}
{"arg":{"channel":"books","instId":"BTC-USDT"},"action":"update","data":[{"asks":[["104617.7","0","0","0"],["104620.1","0.00056666","0","1"],["104637.6","1.12065013","0","1"],["104643.9","0","0","0"],["104646.4","0.00056666","0","1"],["104670.8","0.86004778","0","1"],["104747.2","0","0","0"],["104748","0","0","0"]],"bids":[["104576.4","0.45532844","0","17"],["104539.7","0.00956118","0","1"],["104539.4","0","0","0"],["104529.6","0.02868713","0","1"],["104524.7","0.19167688","0","1"],["104409.1","0","0","0"],["104408.8","0","0","0"]],"ts":"1747170015100","checksum":856458616,"seqId":54226042432,"prevSeqId":54226042421}]}
{"arg":{"channel":"books","instId":"BTC-USDT"},"action":"update","data":[{"asks":[["104614","0.002","0","2"],["104615","0.001","0","1"],["104616","0","0","0"],["104635","0.33","0","6"],["104636","0.16499999","0","3"],["104637","0.234","0","1"],["104747","0","0","0"]],"bids":[],"ts":"1747170015200","checksum":856458616,"seqId":54226042452,"prevSeqId":54226042432}]}
{"arg":{"channel":"books","instId":"BTC-USDT"},"action":"update","data":[{"asks":[["104614","0","0","0"],["104615","0.002","0","2"],["104616","0.001","0","1"],["104635","0","0","0"],["104636","0.32999999","0","6"],["104637","0.39899999","0","4"],["104646.3","0.00004128","0","1"],["104647.8","0","0","0"],["104747","0.77866876","0","1"]],"bids":[],"ts":"1747170015300","checksum":856458616,"seqId":54226042473,"prevSeqId":54226042452}]}
{"arg":{"channel":"books","instId":"BTC-USDT"},"action":"update","data":[{"asks":[["104598.9","0.10438","0","1"],["104616.8","0","0","0"],["104618","0.0022","0","1"],["104635.8","0.0022","0","1"],["104747","0","0","0"]],"bids":[],"ts":"1747170015400","checksum":856458616,"seqId":54226042479,"prevSeqId":54226042473}]}
{"arg":{"channel":"books","instId":"BTC-USDT"},"action":"update","data":[{"asks":[["104596.4","0","0","0"],["104597.9","0.00477988","0","1"]],"bids":[["104565.9","0.00477988","0","1"],["104563.9","0.00001","0","1"],["104455.4","0.1352","0","3"],["104409.4","0","0","0"]],"ts":"1747170015500","checksum":-428422816,"seqId":54226042548,"prevSeqId":54226042479}]}
{"arg":{"channel":"books","instId":"BTC-USDT"},"action":"update","data":[{"asks":[["104587.5","0.09196232","0","1"],["104593","0.32463719","0","2"],["104598.5","0.24066248","0","1"],["104635","0.17","0","4"],["104636","0.24499999","0","4"],["104637","0.31399999","0","2"],["104663.5","5.90864317","0","1"],["104744.7","0","0","0"],["104744.8","0","0","0"],["104746.1","0","0","0"]],"bids":[["104576.4","0.45523844","0","16"],["104568.7","0","0","0"],["104568.5","0.15366075","0","3"],["104566.5","0.10002635","0","1"],["104565.5","0.15898435","0","1"],["104555.5","0.25023468","0","1"],["104410.8","0","0","0"],["104410","0","0","0"]],"ts":"1747170015600","checksum":-269011981,"seqId":54226042572,"prevSeqId":54226042548}]}
{"arg":{"channel":"books","instId":"BTC-USDT"},"action":"update","data":[{"asks":[["104635","0","0","0"],["104636","0.32999999","0","6"],["104637","0.39899999","0","4"],["104744.7","0.00029761","0","1"]],"bids":[],"ts":"1747170015700","checksum":-269011981,"seqId":54226042598,"prevSeqId":54226042572}]}
{"arg":{"channel":"books","instId":"BTC-USDT"},"action":"update","data":[{"asks":[["104576.5","0.07731108","0","6"],["104588.9","0","0","0"],["104589","0.09040436","0","1"],["104592.4","0","0","0"],["104592.5","0.15441022","0","1"]],"bids":[["104568.7","0.00109748","0","1"],["104568.5","0.2473762","0","3"],["104568.4","0","0","0"],["104565","0.14850364","0","1"],["104564.9","0.07298372","0","1"],["104411.6","0","0","0"]],"ts":"1747170015800","checksum":1744998941,"seqId":54226042646,"prevSeqId":54226042598}]}
{"arg":{"channel":"books","instId":"BTC-USDT"},"action":"update","data":[{"asks":[["104578","0.0816","0","1"],["104580","0.13730843","0","5"],["104586.3","0.28658086","0","2"],["104586.8","0.09384492","0","1"],["104587.4","0","0","0"],["104587.5","0","0","0"],["104587.8","0.13375947","0","2"],["104588","0","0","0"],["104588.1","0.03148652","0","1"],["104588.4","0.08790449","0","1"],["104589","0","0","0"],["104589.6","0.00093","0","1"],["104591.3","0.145044","0","1"],["104591.8","0.33520918","0","2"],["104592","0.000015","0","1"],["104592.5","0","0","0"],["104593","0","0","0"],["104593.3","0.58514221","0","2"],["104594.6","0.20091371","0","2"],["104595","0.23236854","0","1"],["104595.8","0","0","0"],["104596.2","0","0","0"],["104596.8","0.44533658","0","2"],["104597.3","0.43423244","0","2"],["104598","0","0","0"],["104598.5","0","0","0"],["104600.9","0.26619385","0","1"],["104602.1","0.052","0","2"],["104614","0.002","0","2"],["104615","0.001","0","1"],["104616","0","0","0"],["104635","0.33","0","6"],["104636","0.16499999","0","3"],["104637","0.234","0","1"],["104744.8","0.0000112","0","1"]],"bids":[["104576.4","0.45160513","0","15"],["104574.3","0.00288261","0","1"],["104571.8","0.12730331","0","2"],["104568.7","0","0","0"],["104568.5","0.05244735","0","1"],["104567.9","0.00116191","0","2"],["104567.3","0.18764597","0","2"],["104567.1","0","0","0"],["104566.5","0","0","0"],["104565.9","0.09834764","0","2"],["104565.8","0.29062853","0","2"],["104565.5","0","0","0"],["104565.3","0.09018691","0","1"],["104565","0","0","0"],["104564.3","0.1570162","0","1"],["104563.8","0.20272955","0","3"],["104563.5","0.01103637","0","1"],["104562.3","0.15244529","0","1"],["104561.2","0","0","0"],["104560.8","0.50429674","0","3"],["104560","0.32233693","0","4"],["104559.6","0.15371298","0","1"],["104558.5","0","0","0"],["104557.3","0.30941026","0","3"],["104555.5","0","0","0"],["104554.6","0","0","0"],["104554.3","0.2473791","0","1"],["104553.4","0.26608176","0","1"],["104411.6","0.00006","0","1"]],"ts":"1747170015900","checksum":-75176124,"seqId":54226042734,"prevSeqId":54226042646}]}
{"arg":{"channel":"books","instId":"BTC-USDT"},"action":"update","data":[{"asks":[["104585","0.01","0","1"],["104597.9","0","0","0"],["104598.2","0.00477988","0","1"],["104607.8","0.13861022","0","1"],["104609.6","0","0","0"],["104620.1","0","0","0"],["104622.7","0.23456666","0","2"],["104646.4","0","0","0"],["104648.9","0.00056666","0","1"],["104650.6","0.75910595","0","1"],["104682.9","0.36190555","0","3"],["104744.8","0","0","0"]],"bids":[["104576.4","0.45034513","0","13"],["104566","0.00477988","0","1"],["104565.9","0.09356776","0","1"],["104560.3","0","0","0"],["104560.2","0.16703078","0","2"],["104540.4","0.00956111","0","1"],["104539.7","0","0","0"],["104508.5","0.04744008","0","1"],["104411.6","0","0","0"]],"ts":"1747170016100","checksum":-427280946,"seqId":54226042795,"prevSeqId":54226042734}]}
{"arg":{"channel":"books","instId":"BTC-USDT"},"action":"update","data":[{"asks":[["104578.7","0.002","0","1"],["104580","0.08380843","0","4"],["104586.3","0.19242972","0","1"],["104586.6","0.09482239","0","1"],["104586.8","0","0","0"],["104587.1","0.09412362","0","1"],["104587.8","0.04","0","1"],["104588","0.08649621","0","1"],["104588.1","0","0","0"],["104588.4","0","0","0"],["104588.7","0.09706128","0","1"],["104591.3","0","0","0"],["104591.5","0.15256096","0","1"],["104591.8","0","0","0"],["104592.1","0.31423766","0","2"],["104593.3","0.58613907","0","2"],["104594.6","0.04","0","1"],["104594.9","0.15835556","0","1"],["104595","0","0","0"],["104595.3","0.25255319","0","1"],["104595.7","0.0420689","0","1"],["104596.8","0.19242972","0","1"],["104597.1","0.24076682","0","1"],["104597.3","0.17769518","0","1"],["104597.6","0.25915356","0","1"],["104600.9","0","0","0"],["104601.2","0.44362955","0","2"],["104607.8","0.13860967","0","1"],["104743.1","0","0","0"],["104743.5","0","0","0"],["104744.3","0","0","0"],["104744.7","0","0","0"]],"bids":[["104574.3","0.00288324","0","1"],["104571.8","0.12651706","0","2"],["104567.9","0.00001","0","1"],["104567.7","0.00115191","0","1"],["104567.6","0.09835613","0","1"],["104567.5","0.086669","0","1"],["104567.3","0","0","0"],["104566.2","0.09638815","0","1"],["104565.9","0","0","0"],["104565.8","0.29522954","0","2"],["104565.6","0.10155418","0","1"],["104565.3","0","0","0"],["104564.6","0.15060742","0","1"],["104564.3","0","0","0"],["104564","0.14340962","0","1"],["104563.8","0.052","0","2"],["104562.6","0.17014343","0","1"],["104562.3","0","0","0"],["104560.8","0.67433016","0","4"],["104560.4","0.13860956","0","1"],["104560.3","0.2470799","0","1"],["104560.2","0.02842056","0","1"],["104560","0.08189006","0","3"],["104559.9","0.21773426","0","4"],["104559.6","0","0","0"],["104557.6","0.24375496","0","1"],["104557.3","0.052","0","2"],["104554.6","0.25561511","0","1"],["104554.3","0","0","0"],["104553.7","0.49996693","0","5"],["104553.4","0","0","0"],["104551.5","0.005","0","1"],["104539","0.005","0","1"],["104477.8","0.0000961","0","1"],["104477.7","0.01059677","0","1"],["104425.5","0.00095594","0","1"],["104425.4","0.32332817","0","1"],["104417.1","0","0","0"],["104417","0","0","0"],["104416.6","0","0","0"],["104414.5","0","0","0"],["104413.7","0","0","0"],["104412.1","0","0","0"]],"ts":"1747170016200","checksum":-1595404033,"seqId":54226042881,"prevSeqId":54226042795}]}
{"arg":{"channel":"books","instId":"BTC-USDT"},"action":"update","data":[{"asks":[["104602.4","0.03824154","0","1"],["104607.8","0","0","0"],["104607.9","0","0","0"],["104609.6","0.13860948","0","1"],["104619.1","0.36958567","0","1"],["104619.3","0","0","0"],["104646.3","0","0","0"],["104648.2","0.00004128","0","1"],["104650.6","0","0","0"],["104650.7","0","0","0"],["104743.1","0.00011716","0","4"],["104743.5","0.234","0","1"],["104744.3","0.00005567","0","1"]],"bids":[["104574.3","0","0","0"],["104567.9","0.00116191","0","2"],["104567.7","0","0","0"],["104532.6","0","0","0"],["104532.5","0","0","0"],["104503.8","0.19242972","0","1"],["104501.1","0","0","0"],["104417.1","0.00005919","0","1"],["104417","0.002","0","1"],["104416.6","0.00019387","0","5"],["104414.5","0.00003296","0","1"],["104413.7","0.1148746","0","2"]],"ts":"1747170016300","checksum":-1291380822,"seqId":54226042915,"prevSeqId":54226042881}]}
{"arg":{"channel":"books","instId":"BTC-USDT"},"action":"update","data":[{"asks":[["104576.5","0.00621108","0","5"],["104578","0","0","0"],["104580.4","0.05350107","0","1"],["104586","0.00067735","0","1"],["104586.2","0","0","0"],["104586.6","0","0","0"],["104587","0","0","0"],["104587.1","0","0","0"],["104588","0","0","0"],["104588.7","0","0","0"],["104591","0.02678246","0","1"],["104591.5","0","0","0"],["104592.1","0","0","0"],["104594.2","0","0","0"],["104594.9","0","0","0"],["104595.3","0","0","0"],["104597.1","0","0","0"],["104597.6","0","0","0"],["104601.2","0.1778392","0","1"],["104626.9","1.35807785","0","1"],["104658.3","2.46000868","0","1"],["104744.7","0.00029761","0","1"],["104744.8","0.0000112","0","1"],["104746.1","0.00453577","0","1"],["104747","0.77866876","0","1"],["104747.2","0.00001055","0","1"],["104748","0.00108568","0","1"],["104748.4","0.00478119","0","1"],["104748.9","0.03","0","1"],["104749.5","0.000015","0","1"]],"bids":[["104576.3","0.00360749","0","2"],["104567.9","0.00001","0","1"],["104567.7","0.00115191","0","1"],["104567.6","0","0","0"],["104567.5","0","0","0"],["104566.2","0","0","0"],["104565.6","0","0","0"],["104564.6","0","0","0"],["104564","0","0","0"],["104562.6","0","0","0"],["104560.3","0","0","0"],["104559.9","0.05201","0","3"],["104557.6","0","0","0"],["104554.6","0","0","0"],["104553.7","0.23957879","0","4"],["104540.8","0.7793963","0","2"],["104537.8","1.3864383","0","1"],["104535.4","0","0","0"],["104506.4","2.47521667","0","1"],["104412.1","0.0026904","0","1"],["104411.6","0.00006","0","1"],["104410.8","0.00001007","0","1"],["104410","0.00029298","0","2"],["104409.4","0.77866876","0","1"],["104409.1","0.00001","0","1"],["104408.8","2.1376","0","1"],["104408.6","0.0008379","0","2"]],"ts":"1747170016400","checksum":1940794474,"seqId":54226042962,"prevSeqId":54226042915}]}
{"arg":{"channel":"books","instId":"BTC-USDT"},"action":"update","data":[{"asks":[["104578.6","0.005","0","1"],["104580","0.00220843","0","3"],["104582","0","0","0"],["104586","0","0","0"],["104586.1","0","0","0"],["104586.2","0.00067735","0","1"],["104586.3","0","0","0"],["104589.2","0","0","0"],["104589.8","0","0","0"],["104590","0.10250949","0","3"],["104590.5","0.09365265","0","1"],["104591","0","0","0"],["104591.1","0.005","0","1"],["104591.4","0.09067822","0","1"],["104592.1","0.09396447","0","1"],["104593.3","0.37054255","0","1"],["104594.3","0.02678163","0","1"],["104594.9","0.14338471","0","1"],["104595.5","0.31504365","0","2"],["104595.7","0","0","0"],["104598.2","0","0","0"],["104598.3","0.15963452","0","1"],["104598.7","0.23827478","0","1"],["104598.9","0","0","0"],["104599.9","0.00477988","0","1"],["104601","0.24685905","0","1"],["104602.5","0.10437501","0","2"],["104604.6","0.25840138","0","1"],["104604.9","0.04844232","0","1"],["104609.6","0","0","0"],["104612.1","0.13860664","0","1"],["104614","0","0","0"],["104615","0","0","0"],["104616","0.002","0","2"],["104617","0.001","0","1"],["104635","0","0","0"],["104636","0","0","0"],["104637","0.56399999","0","7"],["104638","0.16499999","0","3"],["104748","0","0","0"],["104748.4","0","0","0"],["104748.9","0","0","0"],["104749.5","0","0","0"]],"bids":[["104576.4","0.45562987","0","15"],["104571.8","0.09827653","0","1"],["104571","0.08929537","0","1"],["104570.9","0.09253729","0","1"],["104569.6","0.09555306","0","1"],["104569.2","0.00115191","0","1"],["104569","0.09879115","0","1"],["104568","0.15494747","0","1"],["104567.9","0.00478988","0","2"],["104567.7","0","0","0"],["104567.4","0.14685198","0","1"],["104566","0.16557326","0","1"],["104565.8","0.2903046","0","2"],["104565.6","0.19242972","0","1"],["104563.3","0.14851301","0","2"],["104563.2","0.14382239","0","2"],["104562.5","0.005","0","1"],["104561","0.24158062","0","1"],["104560.8","0.50429674","0","3"],["104560.4","0","0","0"],["104558","0.33470556","0","2"],["104550","0.00533024","0","4"],["104529.8","0","0","0"],["104436.1","1.43275119","0","2"],["104424.1","0","0","0"],["104415.2","0.00956238","0","2"],["104411.6","0","0","0"],["104410.8","0","0","0"],["104410","0","0","0"],["104409.4","0","0","0"],["104409.1","0","0","0"],["104408.8","0","0","0"],["104408.6","0","0","0"]],"ts":"1747170016500","checksum":1253411367,"seqId":54226043367,"prevSeqId":54226042962}]}
{"arg":{"channel":"books","instId":"BTC-USDT"},"action":"update","data":[{"asks":[["104576.5","0.07671825","0","6"],["104580","0.08380843","0","4"],["104582","0.0816","0","1"],["104586.2","0.19242972","0","1"],["104586.6","0.00067735","0","1"],["104586.9","0.13576659","0","1"],["104587","0.234","0","1"],["104587.1","0.09477171","0","1"],["104587.3","0.02256561","0","1"],["104587.5","0.10121799","0","1"],["104588.5","0.09159625","0","1"],["104589.1","0.0987245","0","1"],["104589.2","0.43225493","0","1"],["104590","0.00029006","0","2"],["104590.5","0","0","0"],["104591.4","0","0","0"],["104592","0.17785524","0","3"],["104592.1","0","0","0"],["104592.5","0.16232677","0","1"],["104592.6","0.16419375","0","1"],["104593.3","0.51642719","0","2"],["104594.3","0","0","0"],["104594.9","0","0","0"],["104595.4","0.15658314","0","1"],["104595.5","0","0","0"],["104595.8","0.26142577","0","1"],["104596.4","0.00477988","0","1"],["104596.6","0.4154129","0","2"],["104597.5","0.29675891","0","2"],["104598.1","0.24065788","0","1"],["104598.3","0","0","0"],["104598.7","0","0","0"],["104598.9","0.10432","0","1"],["104599.9","0","0","0"],["104601","0","0","0"],["104601.6","0.26211597","0","1"],["104604.6","0","0","0"],["104604.9","0","0","0"],["104609.6","0.13860752","0","1"],["104612.1","0","0","0"],["104614.9","0.00013705","0","1"],["104744.3","0","0","0"],["104744.7","0","0","0"],["104744.8","0","0","0"],["104746.1","0","0","0"],["104747","0","0","0"],["104747.2","0","0","0"]],"bids":[["104576.4","0.65584296","0","15"],["104576.1","0.10111219","0","2"],["104571","0","0","0"],["104570.9","0","0","0"],["104569.6","0","0","0"],["104569.2","0","0","0"],["104569","0","0","0"],["104568.7","0.00115191","0","1"],["104568","0.18632105","0","2"],["104567.9","0.00001","0","1"],["104567.4","0","0","0"],["104566.6","0.09147176","0","1"],["104566.1","0.10203509","0","1"],["104566","0","0","0"],["104565.6","0","0","0"],["104565.3","0.002868","0","1"],["104565.1","0.16953107","0","1"],["104564.6","0.00477988","0","1"],["104564.5","0.15562184","0","1"],["104563.3","0.00098","0","1"],["104563.2","0.00521663","0","1"],["104563","0.16631391","0","1"],["104561.1","0.1386089","0","1"],["104561","0","0","0"],["104560.8","0.7461677","0","4"],["104560.4","0.15403885","0","1"],["104558","0.34572673","0","2"],["104555.1","0.26365442","0","1"],["104554.1","0.43392098","0","2"],["104413.7","0","0","0"],["104412.1","0","0","0"]],"ts":"1747170016600","checksum":-1428517800,"seqId":54226043530,"prevSeqId":54226043367}]}
{"arg":{"channel":"books","instId":"BTC-USDT"},"action":"update","data":[{"asks":[["104586.1","0.00067735","0","1"],["104586.6","0","0","0"],["104587","0.32556612","0","2"],["104587.1","0","0","0"],["104592.5","0.32025833","0","2"],["104592.6","0","0","0"],["104595.7","0.24720453","0","1"],["104595.8","0","0","0"],["104596.4","0","0","0"],["104597.4","0.00477988","0","1"],["104598","0.2430277","0","1"],["104598.1","0","0","0"],["104602.5","0.00001501","0","1"],["104614.9","0","0","0"],["104615.7","0.00013705","0","1"],["104663.5","5.94946021","0","1"],["104744.3","0.00005567","0","1"],["104744.7","0.00029761","0","1"]],"bids":[["104576.4","0.6587331","0","16"],["104576.3","0.00011837","0","1"],["104576.1","0.09821915","0","1"],["104566.1","0","0","0"],["104566","0.09371372","0","1"],["104565.9","0.00477988","0","1"],["104565.3","0","0","0"],["104565.1","0","0","0"],["104565","0.16465145","0","1"],["104564.6","0","0","0"],["104560.8","0.50429674","0","3"],["104560.7","0.24284019","0","1"],["104555.1","0","0","0"],["104555","0.26514853","0","1"],["104547.2","0.002868","0","1"],["104414.5","0","0","0"]],"ts":"1747170016700","checksum":-1399090545,"seqId":54226043600,"prevSeqId":54226043530}]}
{"arg":{"channel":"books","instId":"BTC-USDT"},"action":"update","data":[{"asks":[["104576.5","0.07651755","0","6"],["104580.4","0","0","0"],["104586.9","0","0","0"],["104587","0.234","0","1"],["104587.5","0.09880847","0","1"],["104588","0.09806374","0","1"],["104588.5","0","0","0"],["104588.9","0.08757984","0","1"],["104589.1","0","0","0"],["104589.6","0.10050454","0","2"],["104592","0.03327732","0","2"],["104592.4","0.14435918","0","1"],["104592.5","0","0","0"],["104593","0.31282549","0","2"],["104593.3","0.51489821","0","2"],["104595.4","0","0","0"],["104595.7","0","0","0"],["104595.8","0.15452337","0","1"],["104596.2","0.24841077","0","1"],["104597.5","0.036","0","1"],["104598","0.26595721","0","1"],["104598.5","0.2659468","0","1"],["104601.6","0","0","0"],["104602.1","0.2913767","0","3"],["104632.3","0","0","0"],["104644.4","0.02868713","0","1"],["104744.8","0.0000112","0","1"]],"bids":[["104571.8","0.15247706","0","2"],["104568.5","0.14913131","0","2"],["104568.4","0.09309689","0","1"],["104568","0","0","0"],["104567.1","0.09869273","0","1"],["104566.6","0","0","0"],["104566.5","0.09970252","0","1"],["104566","0","0","0"],["104565.8","0.26865877","0","2"],["104565.5","0.16962386","0","1"],["104565","0","0","0"],["104564.9","0.21629435","0","2"],["104564.5","0","0","0"],["104563.5","0.17024731","0","2"],["104563","0","0","0"],["104561.2","0.25500754","0","1"],["104560.8","0.66284183","0","4"],["104560.7","0","0","0"],["104560.4","0","0","0"],["104558.5","0.24295656","0","1"],["104558","0.0816","0","1"],["104555.5","0.27304059","0","1"],["104555","0","0","0"],["104554.6","0.23699297","0","1"],["104554.1","0.19242972","0","1"],["104414.5","0.00003296","0","1"]],"ts":"1747170016800","checksum":-1291662030,"seqId":54226043741,"prevSeqId":54226043600}]}
{"arg":{"channel":"books","instId":"BTC-USDT"},"action":"update","data":[{"asks":[],"bids":[["104576.4","0.6563425","0","15"]],"ts":"1747170016900","checksum":-1733333773,"seqId":54226043744,"prevSeqId":54226043741}]}
{"arg":{"channel":"books","instId":"BTC-USDT"},"action":"update","data":[{"asks":[["104585","0","0","0"],["104588.9","0","0","0"],["104589","0.09493522","0","1"],["104592.4","0","0","0"],["104592.5","0.15857035","0","1"],["104746.1","0.00453577","0","1"]],"bids":[["104576.4","0.41345236","0","13"],["104576.1","0.10113128","0","2"],["104568.5","0.24189384","0","3"],["104568.4","0","0","0"],["104567.4","0.01150753","0","1"],["104565","0.1612166","0","1"],["104564.9","0.07298372","0","1"],["104563.5","0.15921094","0","1"],["104532.9","0.04840171","0","1"],["104415.2","0","0","0"],["104414.5","0","0","0"]],"ts":"1747170017000","checksum":1162826798,"seqId":54226043764,"prevSeqId":54226043744}]}
{"arg":{"channel":"books","instId":"BTC-USDT"},"action":"update","data":[{"asks":[["104609.5","0.13862267","0","2"],["104609.6","0","0","0"],["104618","0","0","0"],["104622.7","0.234","0","1"],["104625.2","0.00056666","0","1"],["104626.6","0.74265389","0","2"],["104635.8","0","0","0"],["104648.9","0","0","0"],["104649.8","0.0022","0","1"],["104651.4","0.00056666","0","1"],["104658.2","1.08885832","0","1"],["104658.7","0","0","0"],["104667.1","0","0","0"],["104685.4","0.0022","0","1"],["104693.1","0.02111249","0","2"],["104747","0.77866876","0","1"]],"bids":[["104576.4","0.41637465","0","15"],["104576.1","0.09821915","0","1"],["104561.1","0","0","0"],["104560.2","0.16703073","0","2"],["104541","0.12148478","0","3"],["104540.4","0","0","0"],["104534.4","0.03654741","0","1"],["104503.8","0.61521489","0","2"],["104415.2","0.00956238","0","2"]],"ts":"1747170017100","checksum":-14826586,"seqId":54226043805,"prevSeqId":54226043764}]}
{"arg":{"channel":"books","instId":"BTC-USDT"},"action":"update","data":[{"asks":[["104587","0","0","0"],["104597.4","0","0","0"],["104598.3","0.00477988","0","1"],["104609.5","0.0000125","0","1"],["104609.6","0.13860778","0","1"]],"bids":[["104561.3","0.13860779","0","1"],["104560.2","0.02842056","0","1"],["104415.2","0","0","0"]],"ts":"1747170017200","checksum":1160995894,"seqId":54226043821,"prevSeqId":54226043805}]}
{"arg":{"channel":"books","instId":"BTC-USDT"},"action":"update","data":[{"asks":[["104598.3","0","0","0"],["104599.4","0.00477988","0","1"],["104609.6","0.13860746","0","1"]],"bids":[["104576.4","0.4291433","0","16"],["104567.5","0.00477988","0","1"],["104565.9","0","0","0"],["104562.1","0.13860746","0","1"],["104561.3","0","0","0"]],"ts":"1747170017300","checksum":732883486,"seqId":54226043836,"prevSeqId":54226043821}]}
{"arg":{"channel":"books","instId":"BTC-USDT"},"action":"update","data":[{"asks":[["104576.5","0.07589602","0","6"]],"bids":[["104576.4","0.6691433","0","17"],["104491.7","0.01059676","0","1"],["104479.2","0.0220823","0","2"],["104472","0.78926552","0","2"],["104416.6","0","0","0"]],"ts":"1747170017400","checksum":960385608,"seqId":54226043857,"prevSeqId":54226043836}]}
{"arg":{"channel":"books","instId":"BTC-USDT"},"action":"update","data":[{"asks":[["104588.2","0.07949985","0","1"],["104747","0","0","0"]],"bids":[],"ts":"1747170017500","checksum":-1451451949,"seqId":54226043862,"prevSeqId":54226043857}]}
{"arg":{"channel":"books","instId":"BTC-USDT"},"action":"update","data":[{"asks":[["104587","0.234","0","1"],["104746.1","0","0","0"]],"bids":[],"ts":"1747170017600","checksum":1377509337,"seqId":54226043865,"prevSeqId":54226043862}]}
{"arg":{"channel":"books","instId":"BTC-USDT"},"action":"update","data":[{"asks":[["104587","0","0","0"],["104746.1","0.00453577","0","1"]],"bids":[],"ts":"1747170017700","checksum":-1451451949,"seqId":54226043868,"prevSeqId":54226043865}]}
{"arg":{"channel":"books","instId":"BTC-USDT"},"action":"update","data":[{"asks":[["104576.5","0.29689602","0","9"],["104578","0.0816","0","1"],["104585.2","0.09792236","0","1"],["104585.7","0.10017933","0","1"],["104586","0.00067735","0","1"],["104586.1","0.57929746","0","2"],["104586.6","0.09780227","0","1"],["104587","0.234","0","1"],["104587.3","0.11985843","0","2"],["104587.5","0","0","0"],["104588","0","0","0"],["104589","0","0","0"],["104589.6","0.00093","0","1"],["104590.1","0.16216541","0","1"],["104590.7","0.31348016","0","2"],["104592.5","0","0","0"],["104593","0","0","0"],["104593.3","0.58843736","0","2"],["104593.5","0.18914988","0","2"],["104593.9","0.25782071","0","1"],["104595.7","0.2646741","0","1"],["104595.8","0","0","0"],["104596.1","0.00477988","0","1"],["104596.2","0.23986568","0","1"],["104598","0","0","0"],["104598.5","0","0","0"],["104598.8","0","0","0"],["104599.4","0","0","0"],["104599.8","0.25123789","0","1"],["104602.1","0.052","0","2"],["104606.4","0.13861168","0","1"],["104609.6","0","0","0"],["104624.4","0","0","0"],["104626.1","0","0","0"],["104629.2","0","0","0"],["104642.9","0","0","0"],["104663.5","6.00719798","0","1"],["104669","0","0","0"],["104747","0.77866876","0","1"],["104747.2","0.00001055","0","1"],["104748","0.00108568","0","1"]],"bids":[["104576.4","0.50826723","0","14"],["104574.2","0","0","0"],["104574.1","0.00491337","0","2"],["104571.8","0.09827653","0","1"],["104568.7","0","0","0"],["104568.5","0.05244735","0","1"],["104567.5","0.00115191","0","1"],["104567.1","0","0","0"],["104566.5","0","0","0"],["104566.2","0.0953582","0","1"],["104566.1","0.0915055","0","1"],["104565.8","0.27265808","0","2"],["104565.5","0","0","0"],["104565","0","0","0"],["104564.8","0.09392759","0","1"],["104564.2","0.09056388","0","1"],["104563.9","0.00478988","0","2"],["104563.5","0","0","0"],["104563.2","0.15976144","0","2"],["104562.6","0.15269667","0","1"],["104562.1","0","0","0"],["104561.2","0.14972491","0","1"],["104560.8","0.50429674","0","3"],["104558.9","0.25310144","0","1"],["104558.6","0.13861168","0","1"],["104558.5","0.15567742","0","1"],["104556.2","0.24044257","0","1"],["104556.1","0.38030304","0","1"],["104555.5","0","0","0"],["104554.6","0","0","0"],["104553.7","0.06173959","0","3"],["104553.2","0.23983375","0","1"],["104552.3","0.25940094","0","1"],["104548.3","0.1778392","0","1"],["104417","0","0","0"]],"ts":"1747170017800","checksum":-1478477492,"seqId":54226043975,"prevSeqId":54226043868}]}
{"arg":{"channel":"books","instId":"BTC-USDT"},"action":"update","data":[{"asks":[["104576.5","0.23372602","0","8"],["104583.2","0.02256561","0","1"],["104585.2","0","0","0"],["104585.3","0.00067735","0","1"],["104585.4","0.09398388","0","1"],["104585.7","0","0","0"],["104585.9","0.09531294","0","1"],["104586","0.27761263","0","1"],["104586.1","0.38863185","0","1"],["104586.6","0","0","0"],["104586.8","0.08931495","0","1"],["104587.3","0","0","0"],["104587.5","0.09219169","0","1"],["104587.9","0.03326362","0","1"],["104590.1","0","0","0"],["104590.3","0.14290527","0","1"],["104590.7","0.07298372","0","1"],["104590.9","0.3193015","0","2"],["104593.3","0.57800339","0","2"],["104593.5","0.03748854","0","1"],["104593.7","0.14800517","0","1"],["104593.9","0","0","0"],["104594.1","0.2301343","0","1"],["104595.6","0.00478988","0","2"],["104595.7","0","0","0"],["104595.9","0.25556919","0","1"],["104596.1","0","0","0"],["104596.2","0","0","0"],["104596.4","0.2455333","0","1"],["104599.8","0","0","0"],["104600","0.25427182","0","6"],["104602.2","0","0","0"],["104603.5","0.071707","0","1"],["104605.7","0.13861314","0","1"],["104606.4","0","0","0"],["104624.1","0.102075","0","1"],["104626.1","0.09562","0","1"],["104629.2","0.09562","0","1"],["104642.8","0","0","0"],["104643","0.00175266","0","1"],["104646.4","0.14334","0","1"],["104650.9","0.09556","0","1"],["104674.4","0.09553","0","1"],["104743.1","0","0","0"],["104743.5","0","0","0"],["104744.3","0","0","0"],["104744.7","0","0","0"],["104744.8","0","0","0"],["104746.1","0","0","0"],["104747","0","0","0"],["104747.2","0","0","0"],["104748","0","0","0"]],"bids":[["104576.4","0.35604059","0","13"],["104574.1","0.00490002","0","2"],["104567.5","0","0","0"],["104566.5","0.00115191","0","1"],["104566.4","0.08971576","0","1"],["104566.3","0.09572615","0","1"],["104566.2","0","0","0"],["104566.1","0","0","0"],["104565.8","0.27529756","0","2"],["104565","0.09373234","0","1"],["104564.8","0","0","0"],["104564.4","0.09827954","0","2"],["104564.2","0","0","0"],["104563.4","0.16363048","0","1"],["104563.2","0.00521663","0","1"],["104562.8","0.14493668","0","1"],["104562.6","0","0","0"],["104561.4","0.15755114","0","1"],["104561.2","0","0","0"],["104560.8","0.3606752","0","4"],["104560.1","0","0","0"],["104559.1","0.24493172","0","1"],["104558.9","0","0","0"],["104558.7","0.15819782","0","1"],["104558.6","0","0","0"],["104558.5","0","0","0"],["104557.4","0.13861314","0","1"],["104556.4","0.24163283","0","1"],["104556.2","0","0","0"],["104553.4","0.24278123","0","1"],["104553.2","0","0","0"],["104552.5","0.24488672","0","1"],["104552.3","0","0","0"],["104417","0.002","0","1"]],"ts":"1747170017900","checksum":349050668,"seqId":54226044087,"prevSeqId":54226043975}]}
{"arg":{"channel":"books","instId":"BTC-USDT"},"action":"update","data":[{"asks":[["104576.5","0.11422602","0","7"],["104585.3","0","0","0"],["104585.4","0","0","0"],["104585.9","0.00067735","0","1"],["104586.2","0.2829852","0","2"],["104586.7","0.18125866","0","2"],["104586.8","0","0","0"],["104587.5","0","0","0"],["104587.6","0.09378535","0","1"],["104588.2","0.16978893","0","2"],["104590.3","0","0","0"],["104590.9","0","0","0"],["104591.1","0.14972592","0","2"],["104591.7","0.31428975","0","2"],["104593.3","0.57574423","0","2"],["104593.7","0","0","0"],["104594.1","0","0","0"],["104594.5","0.15063265","0","1"],["104594.9","0.23852997","0","1"],["104595.6","0.00001","0","1"],["104595.9","0","0","0"],["104596.4","0","0","0"],["104596.7","0.41528943","0","2"],["104597.2","0.24987844","0","2"],["104600","0.00698629","0","5"],["104600.7","0.36438835","0","5"],["104642.9","0.06694","0","1"],["104669","0.06694","0","1"],["104743.1","0.00011716","0","4"],["104743.5","0.234","0","1"],["104744.3","0.00005567","0","1"]],"bids":[["104576.4","0.4193491","0","14"],["104575.1","0.00290203","0","1"],["104574.1","0.002","0","1"],["104567.3","0.00115191","0","1"],["104567.2","0.10211916","0","1"],["104567.1","0.09266153","0","1"],["104566.5","0","0","0"],["104566.4","0","0","0"],["104566.3","0","0","0"],["104565.8","0.31687827","0","2"],["104565.7","0.09373188","0","1"],["104565.2","0.09315847","0","1"],["104565.1","0.00477988","0","1"],["104565","0","0","0"],["104564.4","0.00004781","0","1"],["104564.2","0.15856052","0","1"],["104563.9","0.00001","0","1"],["104563.6","0.21646677","0","2"],["104563.4","0","0","0"],["104562.8","0","0","0"],["104562.2","0.14892794","0","1"],["104561.4","0","0","0"],["104560.8","0.36815912","0","4"],["104559.9","0.29583006","0","4"],["104559.5","0.16069861","0","1"],["104559.1","0","0","0"],["104558.7","0","0","0"],["104557.2","0.26519012","0","1"],["104556.4","0","0","0"],["104554.2","0.25543604","0","1"],["104553.4","0","0","0"],["104553.2","0.25622206","0","1"],["104552.5","0","0","0"],["104417","0","0","0"]],"ts":"1747170018000","checksum":-1039178554,"seqId":54226044168,"prevSeqId":54226044087}]}
{"arg":{"channel":"books","instId":"BTC-USDT"},"action":"update","data":[{"asks":[["104597.1","0.00477988","0","1"],["104597.2","0.24509856","0","1"],["104625.2","0","0","0"],["104627.7","0.00056666","0","1"],["104642.8","0.00175267","0","1"],["104643","0","0","0"],["104648.2","0.47514723","0","2"],["104651.4","0","0","0"],["104654","0.00056666","0","1"],["104682.9","0.02149395","0","2"],["104744.3","0","0","0"]],"bids":[["104575.1","0","0","0"],["104574.2","0.00290469","0","1"],["104567.5","0.00115191","0","1"],["104567.3","0","0","0"],["104565.3","0.00477988","0","1"],["104565.1","0","0","0"],["104557.4","0.13861317","0","1"],["104508.5","0.78407507","0","2"]],"ts":"1747170018100","checksum":523420709,"seqId":54226044193,"prevSeqId":54226044168}]}
{"arg":{"channel":"books","instId":"BTC-USDT"},"action":"update","data":[{"asks":[["104576.5","0.23342961","0","8"],["104585.3","0.00067735","0","1"],["104585.4","0.10141807","0","1"],["104585.9","0.09046603","0","1"],["104586.2","0.19242972","0","1"],["104586.7","0.08774824","0","1"],["104586.8","0.09711748","0","1"],["104587.5","0.08894492","0","1"],["104587.6","0","0","0"],["104588.2","0.07949985","0","1"],["104590.3","0.14738373","0","1"],["104590.9","0.32320577","0","2"],["104591.1","0.005","0","1"],["104591.6","0.00365958","0","2"],["104591.7","0","0","0"],["104593.3","0.58291976","0","2"],["104593.7","0.16498313","0","1"],["104594.1","0.23906931","0","1"],["104594.5","0","0","0"],["104594.9","0","0","0"],["104595.9","0.24641452","0","1"],["104596.4","0.24516287","0","1"],["104596.7","0.1778392","0","1"],["104597.1","0","0","0"],["104597.2","0","0","0"],["104597.4","0.00477988","0","1"],["104600","0.26208058","0","6"],["104600.7","0.129","0","4"],["104646.3","0.00004128","0","1"],["104648.2","0.47510595","0","1"],["104740.9","0","0","0"],["104741.9","0","0","0"],["104742.1","0","0","0"],["104742.8","0","0","0"],["104743.1","0","0","0"],["104743.5","0","0","0"]],"bids":[["104576.4","0.73790539","0","17"],["104576.3","0.00369343","0","2"],["104575.1","0.00290421","0","1"],["104574.2","0","0","0"],["104567.2","0","0","0"],["104567.1","0","0","0"],["104566.4","0.09238276","0","1"],["104566.3","0.09486499","0","1"],["104565.9","0.00477988","0","1"],["104565.8","0.27226863","0","2"],["104565.7","0","0","0"],["104565.3","0","0","0"],["104565.2","0","0","0"],["104565","0.09036523","0","1"],["104564.4","0.09948325","0","2"],["104564.2","0","0","0"],["104563.6","0.071712","0","1"],["104563.4","0.15032873","0","1"],["104562.8","0.15030539","0","1"],["104562.2","0","0","0"],["104561.4","0.15781771","0","1"],["104560.8","0.29105093","0","4"],["104559.9","0.05201","0","3"],["104559.5","0","0","0"],["104559.1","0.25214378","0","1"],["104558.7","0.16053744","0","1"],["104557.5","0.13861341","0","1"],["104557.4","0","0","0"],["104557.2","0","0","0"],["104556.4","0.26605682","0","1"],["104554.2","0","0","0"],["104553.4","0.24787626","0","1"],["104553.2","0","0","0"],["104552.5","0.26244748","0","1"],["104541.7","0.00956099","0","1"],["104541","0.11192372","0","2"],["104417.4","0","0","0"],["104417.1","0","0","0"]],"ts":"1747170018200","checksum":2095136228,"seqId":54226044298,"prevSeqId":54226044193}]}
{"arg":{"channel":"books","instId":"BTC-USDT"},"action":"update","data":[{"asks":[["104576.5","0.11392961","0","7"],["104585.3","0","0","0"],["104585.4","0","0","0"],["104585.9","0.00067735","0","1"],["104586.2","0.29039023","0","2"],["104586.7","0.08898042","0","1"],["104586.8","0","0","0"],["104587.5","0","0","0"],["104587.6","0.09760642","0","1"],["104588.2","0.16943117","0","2"],["104590.3","0","0","0"],["104590.9","0","0","0"],["104591.1","0.1505392","0","2"],["104591.7","0.32856958","0","2"],["104593.3","0.58128667","0","2"],["104593.7","0","0","0"],["104594.1","0","0","0"],["104594.5","0.15000217","0","1"],["104594.9","0.23202566","0","1"],["104595.9","0","0","0"],["104596.4","0","0","0"],["104596.7","0.41649309","0","2"],["104597.2","0.27428438","0","2"],["104597.4","0","0","0"],["104600","0.00698629","0","5"],["104600.7","0.39065675","0","5"],["104660.1","6.00719798","0","1"],["104663.5","0","0","0"],["104674.4","0","0","0"],["104740.9","0.01448251","0","1"],["104741.9","0.00008643","0","1"],["104742.1","0.03","0","1"],["104742.8","0.00001611","0","1"],["104743.1","0.00011716","0","4"],["104743.5","0.234","0","1"],["104744.3","0.00005567","0","1"]],"bids":[["104567.2","0.09186379","0","1"],["104567.1","0.08972659","0","1"],["104566.4","0","0","0"],["104566.3","0","0","0"],["104565.9","0","0","0"],["104565.8","0.32131701","0","2"],["104565.7","0.08991806","0","1"],["104565.3","0.00477988","0","1"],["104565.2","0.09743711","0","1"],["104565","0","0","0"],["104564.4","0.00004781","0","1"],["104564.2","0.15956698","0","1"],["104563.6","0.22575409","0","2"],["104563.4","0","0","0"],["104562.8","0","0","0"],["104562.2","0.15774502","0","1"],["104561.4","0","0","0"],["104560.8","0.36559257","0","4"],["104559.9","0.30936186","0","4"],["104559.5","0.16621745","0","1"],["104559.1","0","0","0"],["104558.7","0","0","0"],["104557.2","0.23758402","0","1"],["104556.4","0","0","0"],["104554.2","0.24631624","0","1"],["104553.4","0","0","0"],["104553.2","0.233298","0","1"],["104552.5","0","0","0"],["104417.4","0.00012018","0","1"]],"ts":"1747170018300","checksum":-765873733,"seqId":54226044390,"prevSeqId":54226044298}]}
{"arg":{"channel":"books","instId":"BTC-USDT"},"action":"update","data":[{"asks":[["104576.5","0.23342961","0","8"],["104586.2","0.19242972","0","1"],["104586.7","0","0","0"],["104587.6","0","0","0"],["104588.2","0.07949985","0","1"],["104588.4","0.07125","0","1"],["104591.1","0.005","0","1"],["104591.7","0","0","0"],["104594.5","0","0","0"],["104594.9","0","0","0"],["104596.7","0.1778392","0","1"],["104597.1","0.00477988","0","1"],["104597.2","0","0","0"],["104600.7","0.129","0","4"],["104605.7","0","0","0"],["104606.4","0.13861223","0","1"],["104643","0.09556","0","1"],["104743.5","0","0","0"],["104744.7","0.00029761","0","1"],["104744.8","0.0000112","0","1"],["104746.1","0.00453577","0","1"],["104747","0.77866876","0","1"]],"bids":[["104576.4","0.48034075","0","15"],["104567.2","0","0","0"],["104567.1","0","0","0"],["104565.7","0","0","0"],["104565.4","0.00477988","0","1"],["104565.3","0","0","0"],["104565.2","0","0","0"],["104564.2","0","0","0"],["104563.6","0.071712","0","1"],["104562.2","0","0","0"],["104559.9","0.05201","0","3"],["104559.5","0","0","0"],["104558.1","0.13959223","0","2"],["104557.5","0","0","0"],["104557.2","0","0","0"],["104554.2","0","0","0"],["104553.2","0","0","0"],["104417.1","0.00005919","0","1"],["104417","0.002","0","1"],["104416.6","0.00019387","0","5"],["104415.2","0.00956238","0","2"],["104414.5","0.00003296","0","1"],["104413.7","0.1148746","0","2"],["104412.1","0.0026904","0","1"],["104411.6","0.00006","0","1"],["104410.8","0.00001007","0","1"],["104410","0.00029298","0","2"],["104409.4","0.77866876","0","1"]],"ts":"1747170018400","checksum":1639220562,"seqId":54226044434,"prevSeqId":54226044390}]}
{"arg":{"channel":"books","instId":"BTC-USDT"},"action":"update","data":[{"asks":[["104585.3","0.00067735","0","1"],["104585.4","0.10051156","0","1"],["104585.9","0.09484483","0","1"],["104586.8","0.0899244","0","1"],["104587.5","0.09919918","0","1"],["104590.3","0.14329807","0","1"],["104590.9","0.31495586","0","2"],["104593.3","0.58811123","0","2"],["104593.7","0.16536543","0","1"],["104594.1","0.23539886","0","1"],["104595.9","0.26757974","0","1"],["104596.4","0.24459073","0","1"],["104600","0.27213407","0","6"],["104654.7","0.11466","0","1"],["104658.8","0.57973185","0","2"],["104740.5","0","0","0"],["104740.9","0","0","0"],["104741.9","0","0","0"],["104742.1","0","0","0"],["104742.8","0","0","0"],["104743.1","0","0","0"],["104744.3","0","0","0"],["104744.7","0","0","0"],["104744.8","0","0","0"],["104746.1","0","0","0"],["104747","0","0","0"]],"bids":[["104566.4","0.09242423","0","1"],["104566.3","0.08697192","0","1"],["104565.8","0.2812238","0","2"],["104565","0.09876694","0","1"],["104564.4","0.10048536","0","2"],["104563.4","0.15864054","0","1"],["104562.8","0.16244031","0","1"],["104561.4","0.15939696","0","1"],["104560.8","0.36058057","0","4"],["104559.1","0.23453552","0","1"],["104558.7","0.16428047","0","1"],["104556.4","0.24563187","0","1"],["104553.4","0.27094627","0","1"],["104552.5","0.2475813","0","1"],["104417.1","0","0","0"],["104417","0","0","0"],["104416.6","0","0","0"],["104415.2","0","0","0"],["104414.5","0","0","0"],["104413.7","0","0","0"],["104412.1","0","0","0"],["104411.6","0","0","0"],["104410.8","0","0","0"],["104410","0","0","0"],["104409.4","0","0","0"]],"ts":"1747170018500","checksum":623876159,"seqId":54226044474,"prevSeqId":54226044434}]}
{"arg":{"channel":"books","instId":"BTC-USDT"},"action":"update","data":[{"asks":[["104576.5","0.11392961","0","7"],["104585.3","0","0","0"],["104585.4","0","0","0"],["104585.9","0.00067735","0","1"],["104586.2","0.29117767","0","2"],["104586.7","0.0942992","0","1"],["104586.8","0","0","0"],["104587.5","0","0","0"],["104587.6","0.08642878","0","1"],["104588.2","0.17111078","0","2"],["104590.3","0","0","0"],["104590.9","0","0","0"],["104591.1","0.15203903","0","2"],["104591.7","0.32646612","0","2"],["104593.3","0.58539735","0","2"],["104593.7","0","0","0"],["104594.1","0","0","0"],["104594.5","0.16032297","0","1"],["104594.9","0.25442434","0","1"],["104595.8","0.00477988","0","1"],["104595.9","0","0","0"],["104596.4","0","0","0"],["104596.7","0.42356114","0","2"],["104597.1","0","0","0"],["104597.2","0.24341922","0","1"],["104600","0.00698629","0","5"],["104600.7","0.36240805","0","5"],["104686.2","0","0","0"],["104740.5","0.00006468","0","1"],["104740.9","0.01448251","0","1"],["104741.9","0.00008643","0","1"],["104742.1","0.03","0","1"],["104742.8","0.00001611","0","1"]],"bids":[["104576.4","0.4193491","0","14"],["104567.2","0.0994898","0","1"],["104567.1","0.09623703","0","1"],["104566.4","0","0","0"],["104566.3","0","0","0"],["104565.8","0.32307413","0","2"],["104565.7","0.09736554","0","1"],["104565.4","0","0","0"],["104565.2","0.09301681","0","1"],["104565","0","0","0"],["104564.4","0.00004781","0","1"],["104564.2","0.15683362","0","1"],["104563.9","0.00478988","0","2"],["104563.6","0.21755387","0","2"],["104563.4","0","0","0"],["104562.8","0","0","0"],["104562.2","0.1667286","0","1"],["104561.4","0","0","0"],["104560.8","0.36543692","0","4"],["104559.9","0.30727367","0","4"],["104559.5","0.16486654","0","1"],["104559.1","0","0","0"],["104558.7","0","0","0"],["104557.2","0.24050547","0","1"],["104556.4","0","0","0"],["104554.2","0.2698966","0","1"],["104553.4","0","0","0"],["104553.2","0.26776599","0","1"],["104552.5","0","0","0"],["104417.1","0.00005919","0","1"],["104417","0.002","0","1"]],"ts":"1747170018600","checksum":-1537625337,"seqId":54226044540,"prevSeqId":54226044474}]}
{"arg":{"channel":"books","instId":"BTC-USDT"},"action":"update","data":[{"asks":[["104586.2","0.2923812","0","2"],["104586.7","0.09608363","0","1"],["104587.6","0","0","0"],["104588.2","0.16786042","0","2"],["104591.1","0.005","0","1"],["104591.7","0.30353769","0","2"],["104593.3","0.37054255","0","1"],["104594.5","0.1519774","0","1"],["104594.9","0","0","0"],["104596.7","0.44754768","0","2"],["104597.2","0.23847528","0","1"],["104600.7","0.36768111","0","5"],["104686.9","0","0","0"],["104743.1","0.00011716","0","4"],["104743.5","0.234","0","1"],["104744.3","0.00005567","0","1"]],"bids":[["104567.2","0.09430321","0","1"],["104567.1","0","0","0"],["104565.8","0.14344588","0","1"],["104565.7","0.09817241","0","1"],["104565.2","0.10156093","0","1"],["104564.2","0.169556","0","1"],["104563.6","0.071712","0","1"],["104562.2","0.15381781","0","1"],["104560.8","0.18370977","0","3"],["104559.9","0.05201","0","3"],["104559.5","0.14883722","0","1"],["104558.1","0.13959173","0","2"],["104557.2","0.25505011","0","1"],["104554.2","0.2466332","0","1"],["104553.2","0.24375012","0","1"],["104490.7","0.02103746","0","2"],["104416.6","0.00019387","0","5"]],"ts":"1747170018700","checksum":109989331,"seqId":54226044662,"prevSeqId":54226044540}]}
{"arg":{"channel":"books","instId":"BTC-USDT"},"action":"update","data":[{"asks":[["104587.6","0.08978929","0","1"],["104591.1","0.16041323","0","2"],["104593.3","0.51227915","0","2"],["104594.9","0.24953512","0","1"],["104595.8","0","0","0"],["104597.1","0.00477988","0","1"],["104606.4","0.13861194","0","1"],["104619.1","0","0","0"],["104623.3","0","0","0"],["104655.7","0.67359","0","1"],["104656","0","0","0"],["104697.2","0.00095513","0","1"],["104720.9","0.01348217","0","1"],["104743.5","0","0","0"],["104744.3","0","0","0"]],"bids":[["104567.1","0.08766336","0","1"],["104565.8","0.28207034","0","2"],["104565.3","0.00477988","0","1"],["104563.9","0.00001","0","1"],["104563.6","0.22056067","0","2"],["104560.8","0.58447814","0","3"],["104560","0.86055882","0","4"],["104559.9","0.30385353","0","4"],["104558.1","0.13959194","0","2"],["104482.8","0.40096595","0","3"],["104479.2","0.01059676","0","1"],["104417","0","0","0"],["104416.6","0","0","0"]],"ts":"1747170018800","checksum":1078885446,"seqId":54226044703,"prevSeqId":54226044662}]}
{"arg":{"channel":"books","instId":"BTC-USDT"},"action":"update","data":[{"asks":[["104576.5","0.23320013","0","8"],["104585.3","0.00067735","0","1"],["104585.4","0.09342253","0","1"],["104585.9","0.09156589","0","1"],["104586.2","0.19242972","0","1"],["104586.7","0","0","0"],["104587.5","0.0957502","0","1"],["104587.6","0","0","0"],["104588.2","0.07949985","0","1"],["104590.9","0.32512512","0","2"],["104591.1","0.005","0","1"],["104591.7","0","0","0"],["104593.3","0.584058","0","2"],["104593.7","0.1580851","0","1"],["104594.1","0.23682827","0","1"],["104594.5","0","0","0"],["104594.9","0","0","0"],["104595.9","0.24858152","0","1"],["104596.4","0.2559291","0","1"],["104596.7","0.1778392","0","1"],["104597.1","0","0","0"],["104597.2","0.00477988","0","1"],["104600","0.24492801","0","6"],["104600.7","0.129","0","4"],["104606.3","0.13861224","0","1"],["104606.4","0","0","0"],["104682.9","0.06391669","0","3"],["104742.8","0","0","0"],["104743.1","0","0","0"]],"bids":[["104576.4","0.73615318","0","17"],["104575.1","0.00290381","0","1"],["104567.2","0","0","0"],["104567.1","0","0","0"],["104566.4","0.09410356","0","1"],["104565.8","0.27870283","0","2"],["104565.7","0","0","0"],["104565.3","0","0","0"],["104565.2","0","0","0"],["104565.1","0.00477988","0","1"],["104565","0.09723398","0","1"],["104564.4","0.1023071","0","2"],["104564.2","0","0","0"],["104563.6","0.071712","0","1"],["104563.4","0.16997532","0","1"],["104562.2","0","0","0"],["104561.4","0.1677621","0","1"],["104560.8","0.57174675","0","4"],["104559.9","0.05201","0","3"],["104559.5","0","0","0"],["104559.1","0.2371311","0","1"],["104558.7","0.15977545","0","1"],["104558.1","0.13959228","0","2"],["104557.2","0","0","0"],["104556.4","0.27009418","0","1"],["104554.2","0","0","0"],["104553.4","0.25588081","0","1"],["104553.2","0","0","0"],["104552.5","0.2616218","0","1"],["104479.8","0.02238125","0","2"],["104417","0.002","0","1"]],"ts":"1747170019000","checksum":-2080184717,"seqId":54226044811,"prevSeqId":54226044703}]}
{"arg":{"channel":"books","instId":"BTC-USDT"},"action":"update","data":[{"asks":[["104586.9","0.09094712","0","1"],["104590.1","0.03326293","0","1"],["104590.4","0.16555191","0","2"],["104627.7","0","0","0"],["104628.2","0.00056666","0","1"],["104654","0","0","0"],["104654.5","0.00056666","0","1"],["104741.9","0","0","0"],["104742.1","0","0","0"]],"bids":[["104566.4","0.18194606","0","2"],["104562.9","0.15748959","0","1"],["104560.8","0.41731084","0","3"],["104560","0.08189006","0","3"],["104417","0","0","0"]],"ts":"1747170019100","checksum":-1644291522,"seqId":54226044822,"prevSeqId":54226044811}]}
{"arg":{"channel":"books","instId":"BTC-USDT"},"action":"update","data":[{"asks":[["104576.5","0.23237858","0","7"],["104619.1","0.19957694","0","1"],["104658.2","2.50704674","0","2"],["104670.8","0","0","0"],["104679.8","0.01051593","0","1"]],"bids":[["104576.4","0.49615318","0","16"],["104551.5","0","0","0"],["104542.5","0.00956092","0","1"],["104541.7","0","0","0"],["104539","0","0","0"],["104498.5","0.08210057","0","1"],["104417","0.002","0","1"]],"ts":"1747170019200","checksum":1676531329,"seqId":54226044836,"prevSeqId":54226044822}]}
{"arg":{"channel":"books","instId":"BTC-USDT"},"action":"update","data":[{"asks":[["104594.5","0.00477988","0","1"],["104597.2","0","0","0"],["104605.7","0.13861332","0","1"],["104606.3","0","0","0"]],"bids":[["104565.1","0","0","0"],["104562.6","0.00477988","0","1"],["104558.1","0.00098","0","1"],["104557.4","0.13861332","0","1"],["104417","0","0","0"]],"ts":"1747170019300","checksum":1979629437,"seqId":54226044846,"prevSeqId":54226044836}]}
{"arg":{"channel":"books","instId":"BTC-USDT"},"action":"update","data":[{"asks":[["104576.5","0.11287858","0","6"],["104578.6","0.01","0","2"],["104585.3","0","0","0"],["104585.4","0","0","0"],["104585.9","0.00067735","0","1"],["104586.2","0.28612066","0","2"],["104586.6","0.10069003","0","1"],["104586.9","0","0","0"],["104587.5","0","0","0"],["104587.6","0.09355612","0","1"],["104588.2","0.17462784","0","2"],["104590.4","0.00478119","0","1"],["104590.9","0","0","0"],["104591.1","0.15677035","0","3"],["104591.6","0.1560055","0","3"],["104591.7","0.16796161","0","1"],["104593.3","0.57919118","0","2"],["104593.7","0","0","0"],["104594.1","0","0","0"],["104594.5","0.14814672","0","1"],["104594.9","0.22850049","0","1"],["104595.9","0","0","0"],["104596.4","0","0","0"],["104596.6","0.66104153","0","3"],["104597.2","0.25424297","0","2"],["104600","0.00698629","0","5"],["104600.7","0.37957641","0","5"],["104605.7","0","0","0"],["104606.4","0.13861173","0","1"],["104741.9","0.00008643","0","1"],["104742.1","0.03","0","1"],["104742.8","0.00001611","0","1"],["104743.1","0.00011716","0","4"]],"bids":[["104576.4","0.4193491","0","14"],["104567.1","0.18498345","0","2"],["104566.4","0","0","0"],["104565.8","0.30296871","0","2"],["104565.7","0.09060159","0","1"],["104565.2","0.0977313","0","1"],["104565.1","0.00477988","0","1"],["104565","0","0","0"],["104564.4","0.00004781","0","1"],["104564.2","0.16503763","0","1"],["104563.6","0.23461828","0","2"],["104563.4","0","0","0"],["104562.9","0","0","0"],["104562.6","0","0","0"],["104562.5","0.01","0","2"],["104562.1","0.16542939","0","1"],["104561.4","0","0","0"],["104560.8","0.28233327","0","4"],["104559.9","0.28226225","0","4"],["104559.5","0.1533718","0","1"],["104559.1","0","0","0"],["104558.7","0","0","0"],["104558.1","0.1395917","0","2"],["104557.4","0","0","0"],["104557.1","0.25341738","0","1"],["104556.4","0","0","0"],["104554.2","0.2492719","0","1"],["104553.4","0","0","0"],["104553.2","0.26355723","0","1"],["104552.5","0","0","0"],["104550","0.01033024","0","5"],["104417","0.002","0","1"],["104416.6","0.00019387","0","5"]],"ts":"1747170019400","checksum":-822007141,"seqId":54226044946,"prevSeqId":54226044846}]}
{"arg":{"channel":"books","instId":"BTC-USDT"},"action":"update","data":[{"asks":[["104658.2","1.08885832","0","1"],["104660.1","6.04958785","0","1"]],"bids":[],"ts":"1747170019600","checksum":-822007141,"seqId":54226044951,"prevSeqId":54226044946}]}
{"arg":{"channel":"books","instId":"BTC-USDT"},"action":"update","data":[{"asks":[["104597.2","0.24946309","0","1"],["104598.3","0.00477988","0","1"],["104743.1","0","0","0"]],"bids":[["104565.9","0.00477988","0","1"],["104565.1","0","0","0"]],"ts":"1747170019700","checksum":2083755264,"seqId":54226044955,"prevSeqId":54226044951}]}
{"arg":{"channel":"books","instId":"BTC-USDT"},"action":"update","data":[{"asks":[["104576.5","0.11256209","0","6"],["104709.4","0.01051522","0","1"]],"bids":[["104576.4","0.6593491","0","15"],["104575.5","0.0309191","0","2"],["104575.1","0","0","0"],["104567.5","0","0","0"],["104567.2","0.00115191","0","1"],["104415.2","0.00956238","0","2"]],"ts":"1747170019800","checksum":1810240993,"seqId":54226044983,"prevSeqId":54226044955}]}
{"arg":{"channel":"books","instId":"BTC-USDT"},"action":"update","data":[{"asks":[["104588.2","0.09512799","0","1"],["104697.2","0","0","0"],["104743.1","0.00011716","0","4"]],"bids":[["104482.8","0.39922862","0","2"],["104479.8","0.01089578","0","1"]],"ts":"1747170019900","checksum":-1231369035,"seqId":54226044988,"prevSeqId":54226044983}]}
{"arg":{"channel":"books","instId":"BTC-USDT"},"action":"update","data":[{"asks":[],"bids":[["104575.5","0.02801285","0","1"],["104575.1","0.00290407","0","1"],["104567.5","0.00115191","0","1"],["104567.2","0","0","0"],["104415.2","0","0","0"]],"ts":"1747170020000","checksum":1777636584,"seqId":54226044994,"prevSeqId":54226044988}]}
{"arg":{"channel":"books","instId":"BTC-USDT"},"action":"update","data":[{"asks":[["104596.7","0.18261908","0","2"],["104598.3","0","0","0"],["104605.7","0.1386137","0","1"],["104606.4","0","0","0"],["104619.4","0.00056666","0","1"],["104628.2","0","0","0"],["104645.7","0.00056666","0","1"],["104654.5","0","0","0"],["104743.5","0.234","0","1"]],"bids":[["104575.5","0.03091691","0","2"],["104575.1","0","0","0"],["104567.5","0","0","0"],["104567.2","0.00115191","0","1"],["104565.9","0","0","0"],["104565","0.00477988","0","1"],["104558.1","0.00098","0","1"],["104557.4","0.1386137","0","1"],["104551.6","0","0","0"],["104551.1","0.00011867","0","1"],["104532.9","0","0","0"],["104530.7","0.04695777","0","1"]],"ts":"1747170020100","checksum":-481090584,"seqId":54226045026,"prevSeqId":54226044994}]}
{"arg":{"channel":"books","instId":"BTC-USDT"},"action":"update","data":[{"asks":[["104584.3","0.02762898","0","2"],["104592","0.000015","0","1"]],"bids":[["104543.2","0.00956086","0","1"],["104542.5","0","0","0"]],"ts":"1747170020200","checksum":1432860571,"seqId":54226045030,"prevSeqId":54226045026}]}
{"arg":{"channel":"books","instId":"BTC-USDT"},"action":"update","data":[{"asks":[["104658.2","2.51191356","0","2"],["104743.5","0","0","0"],["104744.3","0.00005567","0","1"]],"bids":[["104575.5","0.03091529","0","2"],["104567.5","0.00115191","0","1"],["104567.2","0","0","0"]],"ts":"1747170020300","checksum":1353442801,"seqId":54226045050,"prevSeqId":54226045030}]}
{"arg":{"channel":"books","instId":"BTC-USDT"},"action":"update","data":[{"asks":[["104576.5","0.23206209","0","7"],["104583.1","0.0465","0","1"],["104585.3","0.00067735","0","1"],["104585.4","0.09585299","0","1"],["104585.9","0.09462573","0","1"],["104586.2","0.19242972","0","1"],["104586.6","0","0","0"],["104586.8","0.08573936","0","1"],["104587.5","0.09061068","0","1"],["104587.6","0","0","0"],["104588.2","0","0","0"],["104590.3","0.1541356","0","1"],["104590.9","0.32774929","0","2"],["104591.1","0.01","0","2"],["104591.6","0.00365958","0","2"],["104591.7","0","0","0"],["104593.3","0.58572396","0","2"],["104593.7","0.1539244","0","1"],["104594.1","0.23302245","0","1"],["104594.5","0","0","0"],["104594.9","0","0","0"],["104595.8","0.00477988","0","1"],["104595.9","0.25855265","0","1"],["104596.4","0.25947767","0","1"],["104596.6","0.4154129","0","2"],["104596.7","0.1778392","0","1"],["104597.2","0","0","0"],["104600","0.24540091","0","6"],["104600.7","0.129","0","4"],["104691.6","0.07067518","0","2"],["104693.1","0.18733838","0","3"],["104741.9","0","0","0"],["104742.1","0","0","0"],["104742.8","0","0","0"],["104743.1","0","0","0"],["104744.3","0","0","0"]],"bids":[["104576.4","0.37748093","0","14"],["104575.5","0.02801285","0","1"],["104575.1","0.00290243","0","1"],["104567.1","0","0","0"],["104566.4","0.09437948","0","1"],["104566.3","0.08640806","0","1"],["104565.8","0.28203481","0","2"],["104565.7","0","0","0"],["104565.2","0","0","0"],["104565","0.09079995","0","1"],["104564.4","0.10110216","0","2"],["104564.2","0","0","0"],["104563.9","0.00478988","0","2"],["104563.6","0.071712","0","1"],["104563.4","0.16614431","0","1"],["104562.8","0.15999011","0","1"],["104562.1","0","0","0"],["104561.4","0.15215396","0","1"],["104560.8","0.36162378","0","4"],["104559.9","0.05201","0","3"],["104559.5","0","0","0"],["104559.1","0.23902417","0","1"],["104558.7","0.15184832","0","1"],["104557.1","0","0","0"],["104556.4","0.25705126","0","1"],["104554.2","0","0","0"],["104554.1","0","0","0"],["104553.4","0.27339118","0","1"],["104553.2","0","0","0"],["104552.5","0.26199447","0","1"],["104500.7","0.01059676","0","1"],["104497.8","0.01059676","0","1"],["104488","0.01059676","0","1"],["104487.7","0.00173739","0","1"],["104477.1","0.01148577","0","1"],["104474.6","0.01059676","0","1"],["104468.5","0.08236676","0","2"],["104418.4","0","0","0"],["104418.1","0","0","0"],["104417.6","0","0","0"],["104417.4","0","0","0"],["104417.1","0","0","0"],["104417","0","0","0"],["104416.6","0","0","0"]],"ts":"1747170020400","checksum":-657505974,"seqId":54226045140,"prevSeqId":54226045050}]}
{"arg":{"channel":"books","instId":"BTC-USDT"},"action":"update","data":[{"asks":[["104580.5","0.02256561","0","1"],["104583.2","0","0","0"],["104589.4","0.0191212","0","1"],["104594","0.00477988","0","1"],["104594.8","0.00093","0","1"],["104595.8","0","0","0"],["104615","0.002","0","2"],["104616","0.001","0","1"],["104617","0","0","0"],["104629.2","0","0","0"],["104636","0.33","0","6"],["104637","0.39899999","0","4"],["104638","0","0","0"]],"bids":[["104576.4","0.33632067","0","14"],["104575.1","0","0","0"],["104574.2","0.00290124","0","1"],["104563.9","0.00001","0","1"],["104562.1","0.00477988","0","1"],["104557.4","0","0","0"],["104556.5","0.13861408","0","1"],["104549","0.09169266","0","1"],["104548.9","0","0","0"],["104548.8","0","0","0"],["104487.9","0.09848362","0","2"],["104486.2","0","0","0"],["104418.4","0.0001","0","1"],["104418.1","0.00004752","0","1"]],"ts":"1747170020500","checksum":2135899224,"seqId":54226045193,"prevSeqId":54226045140}]}
{"arg":{"channel":"books","instId":"BTC-USDT"},"action":"update","data":[{"asks":[["104576.5","0.11237086","0","6"],["104585.4","0","0","0"],["104585.9","0","0","0"],["104586.1","0.47852276","0","2"],["104586.6","0.09702037","0","1"],["104586.8","0","0","0"],["104587.5","0","0","0"],["104587.6","0.09488019","0","1"],["104588.2","0.09604555","0","1"],["104590.3","0","0","0"],["104590.9","0","0","0"],["104591.1","0.16327309","0","3"],["104591.6","0.32386739","0","4"],["104593.3","0.37054255","0","1"],["104593.7","0","0","0"],["104594","0","0","0"],["104594.1","0","0","0"],["104594.4","0.14979506","0","1"],["104594.8","0.2538472","0","2"],["104595.9","0","0","0"],["104596.4","0.00477988","0","1"],["104596.6","0.65714334","0","3"],["104597.1","0.26858846","0","1"],["104600","0.00698629","0","5"],["104600.7","0.38468683","0","5"],["104615","0","0","0"],["104616","0.002","0","2"],["104617","0.001","0","1"],["104636","0","0","0"],["104637","0.56399999","0","7"],["104638","0.16499999","0","3"],["104741.9","0.00008643","0","1"],["104742.1","0.03","0","1"],["104742.8","0.00001611","0","1"],["104743.1","0.00011716","0","4"],["104743.5","0.234","0","1"]],"bids":[["104576.4","0.68168833","0","15"],["104575.1","0.00290036","0","1"],["104574.2","0","0","0"],["104573.9","0.02256561","0","1"],["104567.9","0.00116191","0","2"],["104567.5","0","0","0"],["104567.1","0.18438808","0","2"],["104566.4","0","0","0"],["104566.3","0","0","0"],["104565.8","0.14344588","0","1"],["104565.7","0.09793979","0","1"],["104565.1","0.10000558","0","1"],["104565","0","0","0"],["104564.4","0.00004781","0","1"],["104564.1","0.15685238","0","1"],["104563.7","0.00477988","0","1"],["104563.6","0.23463883","0","2"],["104563.4","0","0","0"],["104562.8","0","0","0"],["104562.1","0.16962212","0","1"],["104561.4","0","0","0"],["104560.8","0.18370979","0","3"],["104559.8","0.2288229","0","1"],["104559.4","0.16113761","0","2"],["104559.1","0","0","0"],["104558.7","0","0","0"],["104557.4","0.13861397","0","1"],["104557.1","0.24990348","0","1"],["104556.5","0","0","0"],["104556.4","0","0","0"],["104554.1","0.43815755","0","2"],["104553.4","0","0","0"],["104552.5","0","0","0"],["104549.1","0.38863185","0","1"],["104548.9","0.77866876","0","1"],["104417.6","0.01089593","0","1"]],"ts":"1747170020600","checksum":1965071294,"seqId":54226045455,"prevSeqId":54226045193}]}
{"arg":{"channel":"books","instId":"BTC-USDT"},"action":"update","data":[{"asks":[["104585.3","0","0","0"],["104585.9","0.00067735","0","1"],["104593.3","0.58240406","0","2"],["104623","0.09562","0","1"],["104743.5","0","0","0"]],"bids":[["104576.4","0.44168833","0","14"],["104565.8","0.3328422","0","2"],["104560.8","0.35815435","0","4"],["104553.2","0.23648816","0","1"],["104417.6","0","0","0"]],"ts":"1747170020700","checksum":1706967480,"seqId":54226045464,"prevSeqId":54226045455}]}
{"arg":{"channel":"books","instId":"BTC-USDT"},"action":"update","data":[{"asks":[["104585","0.03392214","0","1"],["104587.9","0","0","0"]],"bids":[],"ts":"1747170020900","checksum":-198972664,"seqId":54226045468,"prevSeqId":54226045464}]}
{"arg":{"channel":"books","instId":"BTC-USDT"},"action":"update","data":[{"asks":[["104605.7","0","0","0"],["104606.4","0.13861211","0","1"]],"bids":[["104576.4","0.39638905","0","13"],["104558.1","0.13959211","0","2"],["104557.4","0","0","0"],["104417.6","0.01089593","0","1"]],"ts":"1747170021000","checksum":1456958790,"seqId":54226045476,"prevSeqId":54226045468}]}
{"arg":{"channel":"books","instId":"BTC-USDT"},"action":"update","data":[{"asks":[["104619.4","0","0","0"],["104619.6","0.00056666","0","1"],["104645.7","0","0","0"],["104645.9","0.00056666","0","1"],["104691.6","0.06972","0","1"]],"bids":[["104575.5","0.03091509","0","2"],["104575.1","0","0","0"],["104567.9","0.00001","0","1"],["104567.5","0.00115191","0","1"],["104487.7","0","0","0"],["104477.1","0","0","0"],["104417.4","0.00012018","0","1"],["104417.1","0.00005919","0","1"]],"ts":"1747170021100","checksum":-1953765733,"seqId":54226045488,"prevSeqId":54226045476}]}
{"arg":{"channel":"books","instId":"BTC-USDT"},"action":"update","data":[{"asks":[],"bids":[["104544.2","0.00956077","0","1"],["104543.2","0","0","0"],["104515.5","0.0478046","0","1"],["104506","0.00844203","0","1"],["104505.4","0","0","0"]],"ts":"1747170021200","checksum":-1953765733,"seqId":54226045494,"prevSeqId":54226045488}]}
{"arg":{"channel":"books","instId":"BTC-USDT"},"action":"update","data":[{"asks":[],"bids":[["104575.6","0.00290223","0","1"],["104575.5","0.02801285","0","1"],["104515.6","0.00951207","0","1"],["104417.4","0","0","0"],["104417.1","0","0","0"]],"ts":"1747170021300","checksum":-278634589,"seqId":54226045498,"prevSeqId":54226045494}]}
{"arg":{"channel":"books","instId":"BTC-USDT"},"action":"update","data":[{"asks":[["104576.5","0.1120075","0","6"],["104596.4","0","0","0"],["104597.2","0.00477988","0","1"],["104624.2","0.04951091","0","1"],["104629.5","0","0","0"],["104641.1","0.1556624","0","1"],["104743.1","0","0","0"]],"bids":[["104575.6","0","0","0"],["104575.5","0.03091508","0","2"],["104565.2","0.00477988","0","1"],["104563.7","0","0","0"],["104560.8","0.68653841","0","3"],["104560.1","1.16730061","0","2"]],"ts":"1747170021400","checksum":-858717994,"seqId":54226045524,"prevSeqId":54226045498}]}
{"arg":{"channel":"books","instId":"BTC-USDT"},"action":"update","data":[{"asks":[["104597.2","0","0","0"],["104598.3","0.00477988","0","1"],["104693.6","0.00095516","0","1"],["104742.8","0","0","0"]],"bids":[["104565.9","0.00477988","0","1"],["104565.2","0","0","0"],["104485.7","0.02286091","0","4"],["104475.1","0.01148598","0","1"],["104417.6","0","0","0"]],"ts":"1747170021500","checksum":-390446708,"seqId":54226045532,"prevSeqId":54226045524}]}
{"arg":{"channel":"books","instId":"BTC-USDT"},"action":"update","data":[{"asks":[["104606.4","0.13861149","0","1"]],"bids":[["104558.1","0.13959149","0","2"]],"ts":"1747170021600","checksum":-390446708,"seqId":54226045544,"prevSeqId":54226045532}]}
{"arg":{"channel":"books","instId":"BTC-USDT"},"action":"update","data":[{"asks":[["104605.7","0.13861311","0","1"],["104606.4","0","0","0"],["104738.5","0","0","0"],["104742.8","0.00001611","0","1"]],"bids":[["104558.1","0.00098","0","1"],["104557.4","0.13861311","0","1"],["104540.8","0.38911502","0","1"],["104539.8","1.4079721","0","1"],["104537.8","0","0","0"],["104418.1","0","0","0"]],"ts":"1747170021700","checksum":-390446708,"seqId":54226045553,"prevSeqId":54226045544}]}
{"arg":{"channel":"books","instId":"BTC-USDT"},"action":"update","data":[{"asks":[["104576.5","0.2315075","0","7"],["104581.9","0.24","0","1"],["104585.3","0.00067735","0","1"],["104585.4","0.08941408","0","1"],["104585.9","0.09103665","0","1"],["104586.1","0.38863185","0","1"],["104586.6","0","0","0"],["104586.8","0.09536533","0","1"],["104587.5","0.08745176","0","1"],["104587.6","0","0","0"],["104588.2","0","0","0"],["104590.3","0.15880246","0","1"],["104590.9","0.33455967","0","2"],["104591.1","0.01","0","2"],["104591.6","0.00365958","0","2"],["104593.3","0.57911247","0","2"],["104593.7","0.16133184","0","1"],["104594.1","0.2508022","0","1"],["104594.4","0","0","0"],["104594.8","0.00093","0","1"],["104595.9","0.24422402","0","1"],["104596.4","0.24570113","0","1"],["104596.6","0.4154129","0","2"],["104597.1","0","0","0"],["104597.2","0.00477988","0","1"],["104598.3","0","0","0"],["104600","0.24480874","0","6"],["104600.7","0.129","0","4"],["104605.7","0","0","0"],["104606.4","0.13861224","0","1"],["104670.8","0.05298623","0","1"],["104740","0","0","0"],["104740.3","0","0","0"],["104740.5","0","0","0"],["104740.9","0","0","0"],["104741.9","0","0","0"],["104742.1","0","0","0"],["104742.8","0","0","0"]],"bids":[["104576.4","0.35592469","0","13"],["104575.5","0.02801285","0","1"],["104575.1","0.00289923","0","1"],["104567.9","0.00116191","0","2"],["104567.5","0","0","0"],["104567.1","0","0","0"],["104566.4","0.1013726","0","1"],["104566.3","0.08683477","0","1"],["104565.9","0","0","0"],["104565.8","0.27220699","0","2"],["104565.7","0","0","0"],["104565.1","0","0","0"],["104565","0.09842724","0","2"],["104564.4","0.09117556","0","2"],["104564.1","0","0","0"],["104563.6","0.071712","0","1"],["104563.4","0.15657808","0","1"],["104562.8","0.14387613","0","1"],["104562.1","0","0","0"],["104561.4","0.15362093","0","1"],["104559.8","0","0","0"],["104559.4","0.00350527","0","1"],["104559.1","0.23421855","0","1"],["104558.7","0.15765501","0","1"],["104558.1","0.13959224","0","2"],["104557.4","0","0","0"],["104557.1","0","0","0"],["104556.4","0.25478431","0","1"],["104554.1","0.19242972","0","1"],["104553.4","0.23968585","0","1"],["104553.2","0","0","0"],["104552.5","0.25175694","0","1"],["104418.4","0","0","0"]],"ts":"1747170021800","checksum":37795755,"seqId":54226045629,"prevSeqId":54226045553}]}
{"arg":{"channel":"books","instId":"BTC-USDT"},"action":"update","data":[{"asks":[["104597.2","0","0","0"],["104598.3","0.00477988","0","1"],["104606.4","0.13861194","0","1"],["104693.6","0","0","0"],["104740","0.00219843","0","2"]],"bids":[["104575.2","0.00289922","0","1"],["104575.1","0","0","0"],["104565.9","0.00477988","0","1"],["104565","0.09364736","0","1"],["104558.8","0.13861194","0","1"],["104558.1","0.00098","0","1"],["104485.7","0.02112349","0","3"],["104475.1","0","0","0"],["104418.9","0","0","0"]],"ts":"1747170021900","checksum":229884840,"seqId":54226045653,"prevSeqId":54226045629}]}
{"arg":{"channel":"books","instId":"BTC-USDT"},"action":"update","data":[{"asks":[["104626.6","0.35033662","0","1"],["104626.9","0","0","0"],["104658.3","0","0","0"],["104740.3","0.00005155","0","1"],["104740.5","0.00006468","0","1"]],"bids":[["104575.2","0","0","0"],["104574.2","0.00289921","0","1"],["104539.8","0","0","0"],["104508.5","0.04744008","0","1"],["104506.4","0","0","0"],["104418.9","0.00005586","0","1"],["104418.4","0.0001","0","1"]],"ts":"1747170022000","checksum":1045703924,"seqId":54226045661,"prevSeqId":54226045653}]}
{"arg":{"channel":"books","instId":"BTC-USDT"},"action":"update","data":[{"asks":[["104582.6","0.00017125","0","1"],["104596.4","0.25048101","0","2"],["104598.3","0","0","0"],["104605.7","0.13861268","0","1"],["104606.4","0","0","0"],["104619.6","0","0","0"],["104619.8","0.00056666","0","1"],["104625.8","1.38594591","0","1"],["104645.9","0","0","0"],["104646.1","0.00056666","0","1"],["104657.2","2.46859012","0","1"],["104740.5","0","0","0"]],"bids":[["104574.2","0.00289903","0","1"],["104565.9","0","0","0"],["104564.5","0.00477988","0","1"],["104560.8","0.49429699","0","3"],["104560.1","0.38863185","0","1"],["104558.8","0","0","0"],["104556.5","0.13861433","0","1"],["104547.2","0","0","0"],["104545.3","0.00956067","0","1"],["104544.2","0","0","0"],["104539.8","1.39294339","0","1"],["104524.8","0.002868","0","1"],["104508.4","2.59918392","0","2"],["104418.4","0","0","0"]],"ts":"1747170022100","checksum":-1634338679,"seqId":54226045710,"prevSeqId":54226045661}]}
{"arg":{"channel":"books","instId":"BTC-USDT"},"action":"update","data":[{"asks":[["104576.5","0.23129714","0","7"],["104582.4","0.0241677","0","1"],["104585","0","0","0"],["104586.8","0","0","0"],["104590.3","0","0","0"],["104596.4","0.24570113","0","1"],["104596.6","0.42019278","0","3"],["104634","1.00001501","0","2"],["104740.5","0.00006468","0","1"],["104740.9","0.01448251","0","1"]],"bids":[["104575.5","0","0","0"],["104572.3","0.03230162","0","1"],["104571.8","0.06663065","0","1"],["104569.4","0","0","0"],["104567.9","0.00001","0","1"],["104567.5","0.00115191","0","1"],["104566.3","0","0","0"],["104565.1","0.00477988","0","1"],["104564.5","0","0","0"],["104562.8","0","0","0"],["104557.4","0.13861397","0","1"],["104556.5","0","0","0"],["104551.1","0.0551699","0","2"],["104418.4","0.0001","0","1"],["104418.1","0.00004752","0","1"]],"ts":"1747170022200","checksum":72231609,"seqId":54226045745,"prevSeqId":54226045710}]}
{"arg":{"channel":"books","instId":"BTC-USDT"},"action":"update","data":[{"asks":[["104586.9","0.09697653","0","1"],["104590.4","0.16717344","0","2"],["104693.6","0.00095516","0","1"],["104740.5","0","0","0"],["104740.9","0","0","0"]],"bids":[["104566.4","0.18828441","0","2"],["104562.9","0.14578015","0","1"],["104485.7","0.02286091","0","4"],["104475.1","0.01148598","0","1"],["104418.4","0","0","0"],["104418.1","0","0","0"]],"ts":"1747170022300","checksum":-1596638038,"seqId":54226045753,"prevSeqId":54226045745}]}
{"arg":{"channel":"books","instId":"BTC-USDT"},"action":"update","data":[{"asks":[["104605.7","0.13861288","0","1"],["104625.7","0.80788142","0","1"],["104626.6","0","0","0"],["104684.3","0.00009599","0","1"],["104740.3","0","0","0"]],"bids":[["104558.1","0.13959288","0","2"],["104557.4","0","0","0"],["104540.8","0.7769795","0","2"],["104508.5","0.79936869","0","2"],["104477.8","0","0","0"],["104477.6","1.03337868","0","2"],["104425.5","0","0","0"],["104425.1","0.00095595","0","1"],["104418.4","0.0001","0","1"],["104418.1","0.00004752","0","1"]],"ts":"1747170022400","checksum":-1596638038,"seqId":54226045775,"prevSeqId":54226045753}]}
{"arg":{"channel":"books","instId":"BTC-USDT"},"action":"update","data":[{"asks":[["104596.6","0.4154129","0","2"],["104597.2","0.00477988","0","1"],["104605.7","0","0","0"],["104606.4","0.1386121","0","1"],["104740","0","0","0"]],"bids":[["104558.1","0.13959217","0","2"]],"ts":"1747170022500","checksum":-1596638038,"seqId":54226045783,"prevSeqId":54226045775}]}
{"arg":{"channel":"books","instId":"BTC-USDT"},"action":"update","data":[{"asks":[["104583.1","0","0","0"],["104594.5","0.00477988","0","1"],["104597.2","0","0","0"],["104634","0.00001501","0","1"],["104740","0.00219843","0","2"]],"bids":[["104565.1","0","0","0"],["104562.6","0.00477988","0","1"]],"ts":"1747170022600","checksum":-1636036854,"seqId":54226045791,"prevSeqId":54226045783}]}
{"arg":{"channel":"books","instId":"BTC-USDT"},"action":"update","data":[{"asks":[["104594.5","0","0","0"],["104595.1","0.00477988","0","1"],["104605.7","0.13861246","0","1"],["104606.4","0","0","0"]],"bids":[["104563.5","0.00477988","0","1"],["104562.6","0","0","0"],["104558.1","0.13959246","0","2"]],"ts":"1747170022700","checksum":-1636036854,"seqId":54226045803,"prevSeqId":54226045791}]}
{"arg":{"channel":"books","instId":"BTC-USDT"},"action":"update","data":[{"asks":[["104588.5","0.06825","0","1"],["104605.7","0","0","0"],["104606.4","0.13861222","0","1"],["104740","0","0","0"]],"bids":[],"ts":"1747170022800","checksum":-1636036854,"seqId":54226045806,"prevSeqId":54226045803}]}
{"arg":{"channel":"books","instId":"BTC-USDT"},"action":"update","data":[{"asks":[["104595.1","0","0","0"],["104596.7","0.18261908","0","2"],["104606.4","0","0","0"],["104607.2","0.13861122","0","1"],["104740","0.00219843","0","2"]],"bids":[["104565.1","0.00477988","0","1"],["104563.5","0","0","0"],["104559.2","0.13861122","0","1"],["104558.1","0.00098","0","1"],["104418.1","0","0","0"]],"ts":"1747170022900","checksum":493892282,"seqId":54226045814,"prevSeqId":54226045806}]}
{"arg":{"channel":"books","instId":"BTC-USDT"},"action":"update","data":[{"asks":[["104576.5","0.22923169","0","6"],["104587.9","0.00262383","0","1"],["104596.7","0.1778392","0","1"],["104597.2","0.00477988","0","1"],["104605.7","0.13861289","0","1"],["104607.2","0","0","0"],["104739.7","0","0","0"],["104740","0","0","0"]],"bids":[["104563.2","0","0","0"],["104559.2","0","0","0"],["104558.1","0.13959289","0","2"],["104418.1","0.00004752","0","1"],["104417.6","0.01089593","0","1"]],"ts":"1747170023000","checksum":-1667252680,"seqId":54226045842,"prevSeqId":54226045814}]}
{"arg":{"channel":"books","instId":"BTC-USDT"},"action":"update","data":[{"asks":[["104576.5","0.10973169","0","5"],["104619.8","0","0","0"],["104620.1","0.00056666","0","1"],["104646.1","0","0","0"],["104646.3","0.00060794","0","2"],["104739.7","0.00001107","0","1"]],"bids":[["104576.4","0.36116404","0","14"]],"ts":"1747170023100","checksum":-476367992,"seqId":54226045848,"prevSeqId":54226045842}]}
{"arg":{"channel":"books","instId":"BTC-USDT"},"action":"update","data":[{"asks":[["104585.3","0","0","0"],["104585.4","0","0","0"],["104585.9","0.00067735","0","1"],["104586.1","0.48938324","0","2"],["104586.6","0.10167345","0","1"],["104586.9","0","0","0"],["104587.5","0","0","0"],["104587.6","0.09670081","0","1"],["104588.2","0.09067488","0","1"],["104590.4","0.00478119","0","1"],["104590.9","0","0","0"],["104591.1","0.17134948","0","3"],["104591.6","0.34070361","0","4"],["104593.3","0.57803208","0","2"],["104593.7","0","0","0"],["104594.1","0","0","0"],["104594.4","0.16378376","0","1"],["104594.8","0.2518903","0","2"],["104595.9","0","0","0"],["104596.4","0","0","0"],["104596.6","0.65554493","0","3"],["104597.1","0.2435818","0","1"],["104600","0.00698629","0","5"],["104600.7","0.36800002","0","5"],["104740","0.00219843","0","2"],["104740.3","0.00005155","0","1"],["104740.5","0.00006468","0","1"],["104740.9","0.01448251","0","1"]],"bids":[["104576.4","0.3120684","0","13"],["104574.2","0.00289886","0","1"],["104573.3","0.07298372","0","1"],["104571.8","0.1145852","0","2"],["104567.9","0.00116191","0","2"],["104567.6","0.002868","0","1"],["104567.5","0","0","0"],["104567.1","0.18474325","0","2"],["104566.4","0","0","0"],["104565.8","0.32205359","0","2"],["104565.7","0.09513551","0","1"],["104565.1","0.09428139","0","2"],["104565","0","0","0"],["104564.4","0.00004781","0","1"],["104564.1","0.1701609","0","1"],["104563.6","0.21885185","0","2"],["104563.4","0","0","0"],["104562.9","0","0","0"],["104562.1","0.1546635","0","1"],["104561.4","0","0","0"],["104560.8","0.46863109","0","4"],["104559.8","0.23810911","0","1"],["104559.4","0.15816402","0","2"],["104559.1","0","0","0"],["104558.7","0","0","0"],["104557.1","0.27179503","0","1"],["104556.4","0","0","0"],["104554.1","0.46470571","0","2"],["104553.4","0","0","0"],["104553.2","0.23805013","0","1"],["104552.5","0","0","0"],["104546.5","0.00956056","0","1"],["104545.3","0","0","0"],["104524.8","0","0","0"],["104417.4","0.00012018","0","1"],["104417.1","0.00005919","0","1"],["104417","0.002","0","1"]],"ts":"1747170023200","checksum":555318739,"seqId":54226045922,"prevSeqId":54226045848}]}
{"arg":{"channel":"books","instId":"BTC-USDT"},"action":"update","data":[{"asks":[["104581.9","0","0","0"],["104597.2","0","0","0"],["104598.3","0.00477988","0","1"],["104741.9","0.00008643","0","1"]],"bids":[["104575.1","0.00289884","0","1"],["104574.2","0","0","0"],["104567.6","0","0","0"],["104565.9","0.00477988","0","1"],["104565.1","0.08950151","0","1"],["104547.4","0.002868","0","1"],["104417","0","0","0"]],"ts":"1747170023300","checksum":862235165,"seqId":54226045933,"prevSeqId":54226045922}]}
{"arg":{"channel":"books","instId":"BTC-USDT"},"action":"update","data":[{"asks":[["104576.5","0.10950796","0","3"],["104582.4","0","0","0"],["104585.8","0.00067735","0","1"],["104585.9","0.03127572","0","1"],["104590.7","0","0","0"],["104594.4","0","0","0"],["104594.5","0.16517982","0","1"],["104598.3","0","0","0"],["104599.4","0.00477988","0","1"],["104605.7","0","0","0"],["104609.6","0.13861034","0","1"],["104650.4","0.1332765","0","1"],["104660.1","0","0","0"],["104663.5","6.38746715","0","1"],["104736.2","0","0","0"],["104742.1","0.03","0","1"]],"bids":[["104576.4","0.65126868","0","16"],["104576.2","0.00290333","0","1"],["104575.1","0","0","0"],["104567.5","0.00477988","0","1"],["104565.9","0","0","0"],["104560.8","0.68118965","0","3"],["104560.3","0.77866876","0","1"],["104560.1","0.52724219","0","2"],["104559.5","0.16601423","0","1"],["104559.4","0.00350527","0","1"],["104558.1","0.00098","0","1"],["104549","0.31669987","0","2"],["104477.6","1.03328162","0","1"],["104476.6","0.00011101","0","1"],["104417.6","0","0","0"],["104417.4","0","0","0"],["104417.1","0","0","0"]],"ts":"1747170023400","checksum":-508069011,"seqId":54226045990,"prevSeqId":54226045933}]}
