{"arg":{"channel":"books","instId":"BTC-USDT"},"action":"update","data":[{"asks":[["104595.4","0.02256561","0","1"],["104597.9","0","0","0"],["104602.5","0.00361194","0","2"],["104645","0","0","0"],["104646","0.22999999","0","4"],["104647","0.21499999","0","4"],["104750","0.0294814","0","38"]],"bids":[["104591.9","0.6619899","0","12"],["104587.5","0.00362973","0","1"],["104546.8","1.43012562","0","1"],["104515.5","2.5352493","0","1"],["104424.3","0","0","0"],["104424","0","0","0"],["104423.5","0","0","0"]],"ts":"1747170042800","checksum":-116247916,"seqId":54226056639,"prevSeqId":54226056588}]}
{"arg":{"channel":"books","instId":"BTC-USDT"},"action":"update","data":[{"asks":[["104592","0.70600171","0","10"],["104604.1","0.00477933","0","1"],["104609.3","0.2523378","0","1"],["104615.5","0.13860943","0","2"],["104617.6","0","0","0"]],"bids":[["104591.9","0.5471899","0","11"],["104587.5","0","0","0"],["104585.8","0","0","0"],["104584.9","0","0","0"],["104584.1","0.0047794","0","1"],["104581.6","0.12552716","0","2"],["104576.9","0","0","0"],["104572.1","0.00477933","0","1"],["104567.7","0.13859943","0","1"],["104424.3","0.00156669","0","1"],["104424","0.01401013","0","1"]],"ts":"1747170042900","checksum":1195691695,"seqId":54226056710,"prevSeqId":54226056639}]}
{"arg":{"channel":"books","instId":"BTC-USDT"},"action":"update","data":[{"asks":[["104604.1","0","0","0"],["104604.7","0.00477933","0","1"],["104615.5","0.13860997","0","2"],["104624","0.002","0","2"],["104625","0.001","0","1"],["104626","0","0","0"],["104646","0.32999999","0","6"],["104647","0.16499999","0","3"],["104648","0","0","0"],["104750.5","0.07299861","0","2"]],"bids":[["104591.9","0.5472099","0","12"],["104586.6","0.102063","0","1"],["104579.2","0","0","0"],["104572.8","0.00477933","0","1"],["104572.1","0","0","0"],["104567.7","0.13859997","0","1"],["104565","0.19242972","0","1"],["104559.4","0.77866876","0","1"],["104558.7","0.04095465","0","1"],["104424.3","0","0","0"],["104424","0","0","0"]],"ts":"1747170043000","checksum":1767011631,"seqId":54226056757,"prevSeqId":54226056710}]}
{"arg":{"channel":"books","instId":"BTC-USDT"},"action":"update","data":[{"asks":[["104604.7","0","0","0"],["104605.4","0.00477933","0","1"],["104615","0.14060051","0","2"],["104615.5","0.00001","0","1"],["104639.1","0.00056666","0","1"],["104639.3","0.00001","0","1"],["104656.3","0.00136836","0","2"],["104656.6","0","0","0"],["104699.7","0.00009429","0","1"],["104699.9","0","0","0"]],"bids":[["104590.4","0.02256561","0","1"],["104573.4","0.00477933","0","1"],["104572.8","0","0","0"],["104569.7","0.00955843","0","1"],["104569","0","0","0"],["104567.7","0","0","0"],["104567","0.13860051","0","1"],["104559.8","0.38863185","0","1"],["104493.1","0.2581176","0","2"],["104492.7","0","0","0"],["104424.7","0","0","0"]],"ts":"1747170043100","checksum":-1234318200,"seqId":54226056779,"prevSeqId":54226056757}]}
{"arg":{"channel":"books","instId":"BTC-USDT"},"action":"update","data":[{"asks":[["104605.4","0","0","0"],["104606.4","0.00477933","0","1"],["104615","0.002","0","1"],["104617.6","0.13859932","0","1"],["104645","0.07","0","2"],["104646","0.29499999","0","5"],["104647","0.12999999","0","2"],["104750","0","0","0"],["104750.5","0","0","0"]],"bids":[["104574.4","0.00477933","0","1"],["104573.4","0","0","0"],["104567.7","0.13859932","0","1"],["104567","0","0","0"]],"ts":"1747170043200","checksum":-1234318200,"seqId":54226056792,"prevSeqId":54226056779}]}
{"arg":{"channel":"books","instId":"BTC-USDT"},"action":"update","data":[{"asks":[["104592","0.69644075","0","10"],["104606.4","0","0","0"],["104607.9","0.00477933","0","1"]],"bids":[["104576.9","0.19242972","0","1"],["104576.1","0.00477933","0","1"],["104574.4","0","0","0"],["104425","0","0","0"]],"ts":"1747170043400","checksum":-346793275,"seqId":54226056806,"prevSeqId":54226056792}]}
{"arg":{"channel":"books","instId":"BTC-USDT"},"action":"update","data":[{"asks":[["104592","0.93644075","0","11"],["104647","1.12999999","0","3"]],"bids":[],"ts":"1747170043500","checksum":-231412643,"seqId":54226056812,"prevSeqId":54226056806}]}
{"arg":{"channel":"books","instId":"BTC-USDT"},"action":"update","data":[{"asks":[["104617.6","0","0","0"],["104619","0.13859641","0","1"]],"bids":[["104570.1","0.13859641","0","1"],["104567.7","0","0","0"]],"ts":"1747170043700","checksum":-231412643,"seqId":54226056816,"prevSeqId":54226056812}]}
{"arg":{"channel":"books","instId":"BTC-USDT"},"action":"update","data":[{"asks":[["104617.6","0.13859811","0","1"],["104619","0","0","0"]],"bids":[["104570.1","0","0","0"],["104568.7","0.13859811","0","1"],["104559.9","0.56048298","0","5"],["104519.9","1.80794475","0","2"]],"ts":"1747170043800","checksum":-231412643,"seqId":54226056822,"prevSeqId":54226056816}]}
{"arg":{"channel":"books","instId":"BTC-USDT"},"action":"update","data":[{"asks":[["104613.8","0.4472945","0","1"],["104614.2","0.5461","0","1"],["104615.5","0.13860955","0","2"],["104617.6","0","0","0"],["104634.7","0","0","0"],["104638.9","0.00056666","0","1"],["104639.1","0","0","0"],["104656.2","0.00056666","0","1"],["104656.3","0.0008017","0","1"]],"bids":[["104582.4","0.00011863","0","1"],["104576.3","0.00835439","0","2"],["104576.1","0","0","0"],["104570.4","0.00955837","0","1"],["104569.7","0","0","0"],["104568.7","0","0","0"],["104567.7","0.13859955","0","1"]],"ts":"1747170044100","checksum":-1395323449,"seqId":54226056858,"prevSeqId":54226056822}]}
{"arg":{"channel":"books","instId":"BTC-USDT"},"action":"update","data":[{"asks":[["104615.5","0.00001","0","1"],["104617.6","0.13859935","0","1"],["104699.4","0.01060638","0","2"],["104699.7","0","0","0"]],"bids":[["104576.3","0.00357506","0","1"],["104576.1","0.00477933","0","1"],["104568.7","0.13859889","0","1"],["104567.7","0","0","0"],["104493.2","0.08424629","0","9"],["104493.1","0.25802081","0","1"],["104425.3","0","0","0"]],"ts":"1747170044200","checksum":-1395323449,"seqId":54226056882,"prevSeqId":54226056858}]}
{"arg":{"channel":"books","instId":"BTC-USDT"},"action":"update","data":[{"asks":[["104606.5","0.18261853","0","2"],["104607.9","0","0","0"],["104617.6","0.13859937","0","1"],["104630.6","0.60176089","0","2"],["104633.2","1.34147878","0","5"],["104655.7","0","0","0"],["104750","0.0294814","0","38"],["104750.5","0.07299861","0","2"]],"bids":[["104591.9","0.5471899","0","11"],["104586.8","0.00348248","0","1"],["104576.1","0","0","0"],["104574.7","0.00477933","0","1"],["104568.7","0","0","0"],["104567.7","0.13859938","0","1"],["104425.7","0","0","0"]],"ts":"1747170044400","checksum":1445978848,"seqId":54226056901,"prevSeqId":54226056882}]}
{"arg":{"channel":"books","instId":"BTC-USDT"},"action":"update","data":[{"asks":[["104606.5","0.1778392","0","1"],["104607.2","0.00477933","0","1"],["104750.5","0","0","0"]],"bids":[],"ts":"1747170044700","checksum":1445978848,"seqId":54226056913,"prevSeqId":54226056901}]}
{"arg":{"channel":"books","instId":"BTC-USDT"},"action":"update","data":[{"asks":[["104607.2","0","0","0"],["104607.9","0.00477933","0","1"],["104630.6","0.22945347","0","1"],["104633.2","0.67313878","0","4"]],"bids":[["104576.1","0.00477933","0","1"],["104574.7","0","0","0"],["104568.7","0.13859789","0","1"],["104567.7","0","0","0"],["104549","0.83415846","0","2"]],"ts":"1747170044800","checksum":1445978848,"seqId":54226056924,"prevSeqId":54226056913}]}
{"arg":{"channel":"books","instId":"BTC-USDT"},"action":"update","data":[{"asks":[],"bids":[["104591.9","0.5482999","0","12"],["104586.8","0","0","0"],["104584.1","0.00477938","0","1"],["104425.7","0.007986","0","1"]],"ts":"1747170044900","checksum":1249452188,"seqId":54226056931,"prevSeqId":54226056924}]}
{"arg":{"channel":"books","instId":"BTC-USDT"},"action":"update","data":[{"asks":[["104607.5","0.00478933","0","2"],["104607.9","0","0","0"],["104750.5","0.07299861","0","2"]],"bids":[["104576.1","0","0","0"],["104575.5","0.00477933","0","1"]],"ts":"1747170045000","checksum":1249452188,"seqId":54226056935,"prevSeqId":54226056931}]}
{"arg":{"channel":"books","instId":"BTC-USDT"},"action":"update","data":[{"asks":[["104638.5","0.00056666","0","1"],["104638.9","0","0","0"],["104655.7","0.00056666","0","1"],["104656.2","0","0","0"]],"bids":[["104591.9","0.5450999","0","11"]],"ts":"1747170045100","checksum":-762925366,"seqId":54226056940,"prevSeqId":54226056935}]}
{"arg":{"channel":"books","instId":"BTC-USDT"},"action":"update","data":[{"asks":[["104607.2","0.00477933","0","1"],["104607.5","0.00001","0","1"],["104615.5","0.13860982","0","2"],["104617.6","0","0","0"]],"bids":[["104584.1","0","0","0"],["104583.9","0.00477939","0","1"],["104575.5","0","0","0"],["104574.7","0.00477933","0","1"],["104568.7","0","0","0"],["104567.7","0.13859982","0","1"]],"ts":"1747170045200","checksum":-224052496,"seqId":54226056963,"prevSeqId":54226056940}]}
{"arg":{"channel":"books","instId":"BTC-USDT"},"action":"update","data":[{"asks":[["104607.2","0","0","0"],["104607.9","0.00477933","0","1"],["104615","0","0","0"],["104615.5","0.13860996","0","2"],["104627.5","0","0","0"],["104635.8","0","0","0"],["104667.1","0.16909918","0","1"],["104667.2","0.00001","0","1"],["104673.5","2.05855351","0","3"],["104750.7","0.00049233","0","7"],["104751.5","0.01448136","0","1"],["104751.9","0.00001969","0","1"]],"bids":[["104588.7","0","0","0"],["104584.1","0.0047794","0","1"],["104583.9","0","0","0"],["104576.2","0","0","0"],["104576.1","0.00477933","0","1"],["104574.7","0","0","0"],["104567.7","0.13859996","0","1"],["104549","0.46418494","0","1"],["104546.8","0","0","0"],["104519.9","1.19699424","0","1"],["104515.5","0","0","0"],["104425.3","0.1913","0","1"],["104425","0.0025","0","1"],["104424.7","0.00001169","0","1"],["104424.3","0.00156669","0","1"]],"ts":"1747170045300","checksum":1752807520,"seqId":54226056989,"prevSeqId":54226056963}]}
{"arg":{"channel":"books","instId":"BTC-USDT"},"action":"update","data":[{"asks":[["104615.5","0.00001","0","1"],["104617.5","0.13859879","0","1"],["104634.5","1.39627361","0","1"],["104665.9","2.55157477","0","1"],["104750.7","0","0","0"],["104751.5","0","0","0"],["104751.9","0","0","0"]],"bids":[["104568.8","0.13859879","0","1"],["104567.7","0","0","0"],["104546.7","1.41423391","0","1"],["104519.9","1.83275499","0","2"],["104515.4","2.61795009","0","1"],["104424.7","0","0","0"],["104424.3","0","0","0"]],"ts":"1747170045400","checksum":1752807520,"seqId":54226057006,"prevSeqId":54226056989}]}
{"arg":{"channel":"books","instId":"BTC-USDT"},"action":"update","data":[{"asks":[["104592","0.46244075","0","9"],["104607.9","0","0","0"],["104608.5","0.00477933","0","1"],["104617.5","0","0","0"],["104617.6","0.13859936","0","1"]],"bids":[["104576.7","0.00477933","0","1"],["104576.1","0","0","0"],["104568.8","0","0","0"],["104567.7","0.13860013","0","1"],["104493.3","0.19252672","0","2"],["104493.2","0.08414984","0","8"],["104441","0.01155252","0","2"],["104440.3","0","0","0"],["104424.7","0.00001169","0","1"]],"ts":"1747170045500","checksum":-466167097,"seqId":54226057028,"prevSeqId":54226057006}]}
{"arg":{"channel":"books","instId":"BTC-USDT"},"action":"update","data":[{"asks":[["104592","0.69644075","0","10"]],"bids":[["104568.7","0.13859718","0","1"],["104567.7","0","0","0"]],"ts":"1747170045700","checksum":1656858575,"seqId":54226057041,"prevSeqId":54226057028}]}
{"arg":{"channel":"books","instId":"BTC-USDT"},"action":"update","data":[{"asks":[["104592","0.46244075","0","9"],["104617.6","0","0","0"],["104619","0.13859643","0","1"],["104630.6","0.40125889","0","2"],["104699.3","0.01059656","0","1"]],"bids":[["104570.1","0.13859643","0","1"],["104568.7","0","0","0"],["104549","0.82939094","0","2"],["104491.2","0","0","0"],["104424.3","0.00156669","0","1"]],"ts":"1747170045800","checksum":-466167097,"seqId":54226057051,"prevSeqId":54226057041}]}
{"arg":{"channel":"books","instId":"BTC-USDT"},"action":"update","data":[{"asks":[["104607.2","0.00477933","0","1"],["104608.5","0","0","0"],["104617.6","0.13859774","0","1"],["104619","0","0","0"],["104699.2","0.01348541","0","1"],["104699.6","0.00095511","0","1"],["104750","0","0","0"],["104750.5","0","0","0"]],"bids":[["104591.9","0.57945227","0","11"],["104585.2","0.00477939","0","1"],["104585.1","0.03122798","0","1"],["104584.1","0","0","0"],["104576.7","0","0","0"],["104574.7","0.00477933","0","1"],["104570.1","0","0","0"],["104568.7","0.13859774","0","1"],["104564.7","0","0","0"],["104490","0.01176441","0","2"]],"ts":"1747170045900","checksum":-1906633542,"seqId":54226057075,"prevSeqId":54226057051}]}
{"arg":{"channel":"books","instId":"BTC-USDT"},"action":"update","data":[{"asks":[["104647","0.12999999","0","2"]],"bids":[],"ts":"1747170046000","checksum":-1906633542,"seqId":54226057085,"prevSeqId":54226057075}]}
{"arg":{"channel":"books","instId":"BTC-USDT"},"action":"update","data":[{"asks":[["104638","0.00056666","0","1"],["104638.5","0","0","0"],["104655.3","0.00056666","0","1"],["104655.7","0","0","0"]],"bids":[["104570.5","0.00955836","0","1"],["104570.4","0","0","0"]],"ts":"1747170046100","checksum":-1906633542,"seqId":54226057091,"prevSeqId":54226057085}]}
{"arg":{"channel":"books","instId":"BTC-USDT"},"action":"update","data":[{"asks":[["104615","0.002","0","1"],["104627.5","0.002","0","1"],["104699.4","0.01051522","0","1"],["104749.6","0","0","0"],["104749.9","0","0","0"]],"bids":[["104589.6","0.00211836","0","2"],["104585.8","0.00477938","0","1"],["104585.2","0","0","0"],["104577.1","0.002","0","1"],["104574.7","0.00477936","0","1"],["104572.2","0.77866876","0","1"],["104572.1","0.38863185","0","1"],["104493.3","0.19242972","0","1"],["104492.7","0.000099","0","1"],["104441","0.01059666","0","1"],["104440.3","0.00095585","0","1"],["104425.7","0","0","0"],["104425.3","0","0","0"],["104425","0","0","0"],["104424.7","0","0","0"],["104424.3","0","0","0"]],"ts":"1747170046200","checksum":-264388696,"seqId":54226057114,"prevSeqId":54226057091}]}
{"arg":{"channel":"books","instId":"BTC-USDT"},"action":"update","data":[{"asks":[],"bids":[["104576.8","0.63418344","0","1"],["104574.8","0.00477936","0","1"],["104574.7","0","0","0"]],"ts":"1747170046300","checksum":-264388696,"seqId":54226057121,"prevSeqId":54226057114}]}
{"arg":{"channel":"books","instId":"BTC-USDT"},"action":"update","data":[{"asks":[["104605.6","0.01","0","1"],["104609.2","0.1778392","0","1"],["104675","0.98316034","0","2"],["104676.3","0.01051706","0","1"],["104678.6","0.01055834","0","2"],["104679.9","3.07147706","0","2"],["104682","0.01051706","0","1"],["104684.1","0.01051706","0","1"],["104699.4","0","0","0"],["104699.7","0.00009114","0","1"],["104700.6","0","0","0"],["104702.8","0","0","0"],["104704.1","0.77866876","0","1"],["104706.2","0.01089674","0","1"],["104709.6","0.00009506","0","1"],["104748.9","0","0","0"],["104749.5","0","0","0"]],"bids":[["104591.9","0.58056227","0","12"]],"ts":"1747170046400","checksum":976947692,"seqId":54226057137,"prevSeqId":54226057121}]}
{"arg":{"channel":"books","instId":"BTC-USDT"},"action":"update","data":[{"asks":[["104592","0.46194075","0","9"],["104607.2","0","0","0"],["104609.1","0.00477936","0","1"],["104617.6","0.13859737","0","1"],["104638.7","0","0","0"],["104641.8","0","0","0"],["104669","0","0","0"],["104695.2","0","0","0"],["104748.9","0.03","0","1"],["104749.5","0.000015","0","1"],["104749.6","0.00002296","0","1"],["104749.9","0.00021362","0","1"]],"bids":[["104586.8","0.00354773","0","1"],["104577.2","0.00477936","0","1"],["104574.8","0","0","0"],["104568.7","0.13859737","0","1"],["104561","0.02266985","0","1"],["104560.9","0","0","0"],["104425.9","0","0","0"]],"ts":"1747170046500","checksum":-881845497,"seqId":54226057161,"prevSeqId":54226057137}]}
{"arg":{"channel":"books","instId":"BTC-USDT"},"action":"update","data":[{"asks":[["104592","0.44594075","0","8"],["104617.6","0.13859662","0","1"],["104635.7","0","0","0"],["104750","0.0294814","0","38"]],"bids":[["104570.1","0.13859644","0","1"],["104568.7","0","0","0"]],"ts":"1747170046600","checksum":1332603377,"seqId":54226057171,"prevSeqId":54226057161}]}
{"arg":{"channel":"books","instId":"BTC-USDT"},"action":"update","data":[{"asks":[["104699.7","0","0","0"],["104701.2","0.00010679","0","1"]],"bids":[["104585.8","0.00477937","0","1"],["104570.1","0","0","0"],["104568.7","0.13859718","0","1"],["104492.7","0","0","0"],["104492.5","0.00009674","0","1"],["104440.3","0","0","0"],["104440.1","0.00095584","0","1"]],"ts":"1747170046700","checksum":-2058213412,"seqId":54226057189,"prevSeqId":54226057171}]}
{"arg":{"channel":"books","instId":"BTC-USDT"},"action":"update","data":[{"asks":[["104617.6","0","0","0"],["104619","0.13859658","0","1"],["104634.4","1.71224058","0","1"],["104665.8","0.96547736","0","1"],["104667.1","0","0","0"],["104673.5","1.464386","0","2"],["104750","0","0","0"]],"bids":[["104586.1","0.00477937","0","1"],["104585.8","0","0","0"],["104570.1","0.13859661","0","1"],["104568.7","0","0","0"]],"ts":"1747170046800","checksum":94077230,"seqId":54226057203,"prevSeqId":54226057189}]}
{"arg":{"channel":"books","instId":"BTC-USDT"},"action":"update","data":[{"asks":[["104592","0.40994075","0","7"],["104609.1","0","0","0"],["104609.6","0.00477936","0","1"]],"bids":[["104586.1","0","0","0"],["104585.8","0.00477934","0","1"]],"ts":"1747170046900","checksum":-516716969,"seqId":54226057210,"prevSeqId":54226057203}]}
{"arg":{"channel":"books","instId":"BTC-USDT"},"action":"update","data":[{"asks":[["104593.9","0.24","0","1"],["104647","1.12999999","0","3"],["104749.9","0","0","0"]],"bids":[],"ts":"1747170047000","checksum":-1427639083,"seqId":54226057217,"prevSeqId":54226057210}]}
{"arg":{"channel":"books","instId":"BTC-USDT"},"action":"update","data":[{"asks":[["104609.1","0.00477936","0","1"],["104609.6","0","0","0"],["104617.6","0.13859665","0","1"],["104619","0","0","0"],["104637.1","0.00056666","0","1"],["104638","0","0","0"],["104654.4","0.00056666","0","1"],["104655.3","0","0","0"]],"bids":[["104586.1","0.00477936","0","1"],["104585.8","0","0","0"],["104570.1","0","0","0"],["104568.7","0.13859739","0","1"]],"ts":"1747170047100","checksum":1609583154,"seqId":54226057233,"prevSeqId":54226057217}]}
{"arg":{"channel":"books","instId":"BTC-USDT"},"action":"update","data":[{"asks":[],"bids":[["104586.1","0","0","0"],["104585.8","0.00477936","0","1"],["104570.1","0.13859682","0","1"],["104568.7","0","0","0"]],"ts":"1747170047200","checksum":2085271810,"seqId":54226057238,"prevSeqId":54226057233}]}
{"arg":{"channel":"books","instId":"BTC-USDT"},"action":"update","data":[{"asks":[["104592","0.40985949","0","7"],["104607.2","0.00477936","0","1"],["104609.1","0","0","0"],["104617.6","0","0","0"],["104619","0.13859638","0","1"]],"bids":[["104586.8","0","0","0"],["104585.8","0","0","0"],["104585.2","0.0047793","0","1"],["104577.2","0","0","0"],["104574.7","0.00477936","0","1"],["104570.1","0.13859638","0","1"],["104425.9","0.0001","0","1"]],"ts":"1747170047300","checksum":280496998,"seqId":54226057259,"prevSeqId":54226057238}]}
{"arg":{"channel":"books","instId":"BTC-USDT"},"action":"update","data":[{"asks":[["104592","0.17997949","0","5"],["104593.9","0","0","0"],["104595.4","0","0","0"],["104595.6","0.00001","0","1"],["104595.7","0","0","0"],["104595.8","0","0","0"],["104597.7","0","0","0"],["104600.6","0","0","0"],["104601.1","0.0000125","0","1"],["104602","0","0","0"],["104602.6","0","0","0"],["104605.5","0","0","0"],["104606.1","0","0","0"],["104607.2","0","0","0"],["104608.9","0","0","0"],["104609.1","0.00477936","0","1"],["104609.3","0","0","0"],["104611.1","0","0","0"],["104611.6","0","0","0"],["104615.1","0","0","0"],["104619","0","0","0"],["104620.2","0.13859439","0","1"],["104749.9","0.00021362","0","1"],["104750","0.0294814","0","38"],["104750.5","0.07299861","0","2"],["104750.7","0.00049233","0","7"],["104751.5","0.01448136","0","1"],["104751.9","0.00001969","0","1"],["104753.2","0.0000358","0","1"],["104753.3","2.3905","0","1"],["104754.2","0.00089983","0","1"],["104754.7","0.00001","0","1"],["104755","0.00001787","0","1"],["104755.1","0.00010283","0","1"],["104756","0.00001103","0","1"],["104757.5","0.77866876","0","1"],["104757.6","0.00001017","0","1"]],"bids":[["104591.9","0.58795227","0","12"],["104586.1","0.00299125","0","1"],["104585.2","0","0","0"],["104581.6","0.03250173","0","1"],["104581.5","0","0","0"],["104580.1","0","0","0"],["104579.6","0","0","0"],["104578.6","0","0","0"],["104578","0.0816","0","1"],["104577.2","0.00477936","0","1"],["104576.6","0","0","0"],["104574.7","0","0","0"],["104574.3","0","0","0"],["104573.9","0","0","0"],["104572.1","0.52722624","0","2"],["104571.6","0","0","0"],["104570.1","0","0","0"],["104568.6","0","0","0"],["104567.6","0","0","0"],["104425.7","0.007986","0","1"],["104425.3","0.1913","0","1"],["104425","0.0025","0","1"],["104424.7","0.00001169","0","1"],["104424.3","0.00156669","0","1"],["104424","0.01401013","0","1"],["104423.5","0.01448485","0","1"],["104423","0.00071959","0","4"],["104422.9","0.01089593","0","1"],["104422.8","0.00094847","0","1"],["104422.7","0.01089657","0","1"]],"ts":"1747170047400","checksum":-350396770,"seqId":54226057322,"prevSeqId":54226057259}]}
{"arg":{"channel":"books","instId":"BTC-USDT"},"action":"update","data":[{"asks":[["104594.3","0","0","0"],["104595.5","0","0","0"],["104595.9","0","0","0"],["104598.4","0.00067735","0","1"],["104598.5","0.24","0","1"],["104598.6","0.02722615","0","1"],["104601.3","0.09920543","0","1"],["104601.8","0.13429996","0","2"],["104602.5","0.00001501","0","1"],["104602.7","0.09710818","0","1"],["104603.4","0.09746363","0","1"],["104603.6","0.31317212","0","3"],["104606.2","0.15211974","0","1"],["104606.8","0.33427952","0","2"],["104609.1","0","0","0"],["104609.5","0.00479186","0","2"],["104609.6","0.14808055","0","1"],["104610","0.51735841","0","5"],["104611.8","0.24908338","0","1"],["104612.3","0.25866529","0","1"],["104615.9","0.24636833","0","2"],["104620.2","0","0","0"],["104621.9","0.13859217","0","1"],["104624","0","0","0"],["104625","0","0","0"],["104626","0.002","0","2"],["104627","0.001","0","1"],["104645","0","0","0"],["104646","0","0","0"],["104647","0.22999999","0","4"],["104648","0.21499999","0","4"],["104649","0.05","0","1"],["104754.2","0","0","0"],["104754.7","0","0","0"],["104755","0","0","0"],["104755.1","0","0","0"],["104756","0","0","0"],["104757.5","0","0","0"],["104757.6","0","0","0"]],"bids":[["104588.2","0.00299618","0","1"],["104587","0.02665136","0","1"],["104586.8","0.002868","0","1"],["104586.1","0","0","0"],["104583.1","0","0","0"],["104582.4","0.00127054","0","2"],["104582.3","0.092869","0","1"],["104582.2","0.45367149","0","3"],["104580.9","0.10002488","0","1"],["104580.3","0.09221345","0","1"],["104579.3","0.15368694","0","1"],["104578.7","0.16144033","0","1"],["104577.4","0.00477936","0","1"],["104577.3","0.16421991","0","1"],["104577.2","0","0","0"],["104575","0.25355804","0","1"],["104574.6","0.14685579","0","2"],["104573.4","0.13859217","0","1"],["104572.3","0.24337557","0","1"],["104572.1","0.38863185","0","1"],["104572","0.31735418","0","3"],["104569.3","0.26060329","0","1"],["104568.4","0.24748096","0","1"],["104549.2","0","0","0"],["104425.3","0","0","0"],["104425","0","0","0"],["104424.7","0","0","0"],["104424.3","0","0","0"],["104424","0","0","0"],["104423.5","0","0","0"],["104423","0","0","0"],["104422.9","0","0","0"],["104422.8","0","0","0"],["104422.7","0","0","0"]],"ts":"1747170047500","checksum":-151846056,"seqId":54226057468,"prevSeqId":54226057322}]}
{"arg":{"channel":"books","instId":"BTC-USDT"},"action":"update","data":[{"asks":[["104592","0.29947949","0","6"],["104596.5","0.02417705","0","2"],["104597.4","0.02256561","0","1"],["104600.7","0.09089906","0","1"],["104601.2","0.09271555","0","1"],["104601.3","0","0","0"],["104601.8","0.04","0","1"],["104602.2","0.13265927","0","2"],["104602.7","0","0","0"],["104602.8","0.09289486","0","1"],["104603.4","0","0","0"],["104603.6","0.13045822","0","2"],["104605.7","0.15721802","0","1"],["104606.2","0.32572325","0","2"],["104606.8","0","0","0"],["104607.5","0.00478935","0","2"],["104609","0.14820977","0","1"],["104609.4","0.27441282","0","3"],["104609.5","0.0000125","0","1"],["104609.6","0","0","0"],["104610","0.27252802","0","4"],["104611.2","0.27260223","0","1"],["104611.7","0.27253963","0","1"],["104611.8","0","0","0"],["104612.3","0","0","0"],["104615.3","0.26529571","0","1"],["104615.9","0.00286746","0","1"],["104620.7","0.13859253","0","1"],["104621.9","0","0","0"],["104623","0.002","0","2"],["104624","0.001","0","1"],["104626","0","0","0"],["104627","0","0","0"],["104644","0.07","0","2"],["104645","0.135","0","3"],["104646","0.20999999","0","3"],["104647","0.07999999","0","1"],["104648","0","0","0"],["104649","0","0","0"],["104751.9","0","0","0"],["104753.2","0","0","0"],["104753.3","0","0","0"]],"bids":[["104582.4","0.00011863","0","1"],["104582.3","0.00115191","0","1"],["104582.2","0.17947789","0","1"],["104581.7","0.19516672","0","2"],["104580.9","0","0","0"],["104580.3","0.09061558","0","1"],["104579.7","0.10041533","0","1"],["104579.3","0","0","0"],["104578.7","0.15765737","0","1"],["104578.2","0.14323942","0","1"],["104577.4","0","0","0"],["104577.3","0","0","0"],["104576.7","0.16192825","0","1"],["104575.5","0.00477935","0","1"],["104575","0","0","0"],["104574.6","0.00056666","0","1"],["104574.4","0.237972","0","1"],["104574","0.24739674","0","2"],["104573.4","0","0","0"],["104572.4","0.14359283","0","2"],["104572.3","0","0","0"],["104572","0.17683303","0","2"],["104571.7","0.27474906","0","2"],["104569.3","0","0","0"],["104568.7","0.248137","0","1"],["104568.4","0","0","0"],["104567.8","0.24418411","0","1"],["104425.3","0.1913","0","1"]],"ts":"1747170047600","checksum":-1541107659,"seqId":54226057582,"prevSeqId":54226057468}]}
{"arg":{"channel":"books","instId":"BTC-USDT"},"action":"update","data":[{"asks":[["104603.6","0.320041","0","3"],["104607.5","0.00001","0","1"],["104608.5","0.00477935","0","1"],["104623","0","0","0"],["104624","0.002","0","2"],["104625","0.001","0","1"],["104644","0","0","0"],["104645","0.07","0","2"],["104646","0.29499999","0","5"],["104647","0.12999999","0","2"],["104699.7","0.00009273","0","1"],["104701.2","0","0","0"]],"bids":[["104587","0","0","0"],["104582.2","0.36083163","0","2"],["104579.6","0.0564907","0","1"],["104576.5","0.00477935","0","1"],["104575.5","0","0","0"],["104572","0.38424995","0","3"],["104492.7","0.00010156","0","1"],["104492.5","0","0","0"],["104440.3","0.00095583","0","1"],["104440.1","0","0","0"]],"ts":"1747170047700","checksum":-1310724703,"seqId":54226057622,"prevSeqId":54226057582}]}
{"arg":{"channel":"books","instId":"BTC-USDT"},"action":"update","data":[{"asks":[],"bids":[["104591.9","0.61078227","0","13"]],"ts":"1747170047800","checksum":-387467792,"seqId":54226057623,"prevSeqId":54226057622}]}
{"arg":{"channel":"books","instId":"BTC-USDT"},"action":"update","data":[{"asks":[["104596.8","0.19242972","0","1"],["104634.5","0","0","0"],["104665.9","0","0","0"],["104751.9","0.00001969","0","1"]],"bids":[["104546.7","0","0","0"],["104425","0.0025","0","1"]],"ts":"1747170048000","checksum":1013525486,"seqId":54226057627,"prevSeqId":54226057623}]}
{"arg":{"channel":"books","instId":"BTC-USDT"},"action":"update","data":[{"asks":[["104608.5","0","0","0"],["104609.1","0.00477935","0","1"],["104620.7","0.13859281","0","1"],["104635.6","1.36674756","0","1"],["104636.7","0.00056666","0","1"],["104637.1","0","0","0"],["104654","0.00056666","0","1"],["104654.4","0","0","0"],["104665.8","0.20000492","0","1"],["104667","2.49689722","0","1"],["104678.5","0.00004128","0","1"],["104678.6","0.01051706","0","1"],["104750.7","0","0","0"],["104751.5","0","0","0"],["104751.9","0","0","0"]],"bids":[["104588.2","0.00477923","0","1"],["104587.1","0.07298372","0","1"],["104577.2","0.00477935","0","1"],["104576.5","0","0","0"],["104573.4","0.13859274","0","1"],["104572.4","0.005","0","1"],["104570.6","0.00955835","0","1"],["104570.5","0","0","0"],["104549","0.46418494","0","1"],["104546.8","1.4283237","0","1"],["104519.9","1.19699424","0","1"],["104515.5","2.56525436","0","1"],["104515.4","0","0","0"],["104425.7","0","0","0"],["104425.3","0","0","0"],["104425","0","0","0"]],"ts":"1747170048100","checksum":-1344963526,"seqId":54226057673,"prevSeqId":54226057627}]}
{"arg":{"channel":"books","instId":"BTC-USDT"},"action":"update","data":[{"asks":[["104592","0.17997949","0","5"],["104600.7","0","0","0"],["104601.2","0","0","0"],["104601.3","0.09290212","0","1"],["104601.8","0.14207233","0","2"],["104602.2","0.03748854","0","1"],["104602.7","0.09550519","0","1"],["104602.8","0","0","0"],["104603.4","0.08890735","0","1"],["104605.7","0","0","0"],["104606.2","0.1521913","0","1"],["104606.8","0.31795778","0","2"],["104609","0","0","0"],["104609.1","0","0","0"],["104609.3","0.00477935","0","1"],["104609.4","0.03693","0","2"],["104609.6","0.16122","0","1"],["104610","0.52119342","0","5"],["104611.2","0","0","0"],["104611.7","0","0","0"],["104611.8","0.24692068","0","1"],["104612.3","0.2683297","0","1"],["104615.3","0","0","0"],["104615.9","0.23931347","0","2"],["104620.7","0.13859279","0","1"],["104699.4","0.00009109","0","1"],["104699.7","0","0","0"],["104750.7","0.00049233","0","7"]],"bids":[["104582.4","0.00127054","0","2"],["104582.3","0.09674644","0","1"],["104582.2","0.44904933","0","3"],["104581.7","0","0","0"],["104580.9","0.09897888","0","1"],["104580.3","0.10084065","0","1"],["104579.7","0","0","0"],["104579.3","0.15273251","0","1"],["104578.7","0.1577913","0","1"],["104578.2","0","0","0"],["104577.3","0.16897281","0","1"],["104576.7","0","0","0"],["104575","0.23398231","0","1"],["104574.6","0.15918232","0","2"],["104574.4","0","0","0"],["104574","0.0816","0","1"],["104573.4","0","0","0"],["104572.4","0.14359279","0","2"],["104572.3","0.24924531","0","1"],["104572","0.31384546","0","3"],["104571.7","0.036","0","1"],["104569.3","0.26449365","0","1"],["104568.7","0","0","0"],["104568.4","0.25795197","0","1"],["104567.8","0","0","0"],["104549","0.83361788","0","2"],["104519.9","1.81694627","0","2"],["104493.2","0.08424621","0","9"],["104492.7","0","0","0"],["104425.7","0.007986","0","1"],["104425.3","0.1913","0","1"]],"ts":"1747170048200","checksum":-1605421382,"seqId":54226057748,"prevSeqId":54226057673}]}
{"arg":{"channel":"books","instId":"BTC-USDT"},"action":"update","data":[{"asks":[["104608.5","0.00477935","0","1"],["104609.3","0","0","0"],["104619.1","0.33817158","0","2"],["104620.7","0","0","0"],["104635.6","1.46852056","0","2"],["104636.5","0","0","0"],["104751.5","0.01448136","0","1"],["104751.9","0.00001969","0","1"]],"bids":[["104577.2","0","0","0"],["104576.5","0.00477935","0","1"],["104572.4","0.005","0","1"],["104571.8","0.13859464","0","1"],["104425.3","0","0","0"]],"ts":"1747170048300","checksum":-1605421382,"seqId":54226057765,"prevSeqId":54226057748}]}
{"arg":{"channel":"books","instId":"BTC-USDT"},"action":"update","data":[{"asks":[["104619.1","0.19957694","0","1"],["104620.2","0.1385946","0","1"],["104751.9","0","0","0"]],"bids":[["104493.3","0.1925255","0","2"],["104493.2","0.08414984","0","8"],["104441","0.01155249","0","2"],["104440.3","0","0","0"],["104425.3","0.1913","0","1"]],"ts":"1747170048400","checksum":-1605421382,"seqId":54226057774,"prevSeqId":54226057765}]}
{"arg":{"channel":"books","instId":"BTC-USDT"},"action":"update","data":[{"asks":[["104592","0.41293519","0","7"],["104596.6","0.00067735","0","1"],["104596.7","0.24","0","1"],["104598.4","0","0","0"],["104598.5","0","0","0"],["104600.6","0.0918856","0","1"],["104601.1","0.09957239","0","2"],["104601.3","0","0","0"],["104601.8","0.04","0","1"],["104602","0.09728397","0","1"],["104602.6","0.08773223","0","1"],["104602.7","0","0","0"],["104603.4","0","0","0"],["104603.6","0.31818157","0","3"],["104605.5","0.15322414","0","1"],["104606.1","0.32829838","0","2"],["104606.2","0","0","0"],["104606.8","0","0","0"],["104608.9","0.16454408","0","1"],["104609.3","0.25042625","0","1"],["104609.6","0","0","0"],["104610","0.27252802","0","4"],["104611.1","0.24082363","0","1"],["104611.6","0.2659631","0","1"],["104611.8","0","0","0"],["104612.3","0","0","0"],["104615.1","0.26221501","0","1"],["104615.9","0.00286746","0","1"],["104620.2","0.13859377","0","1"],["104648","1","0","1"],["104750.5","0","0","0"],["104750.7","0","0","0"],["104751.5","0","0","0"]],"bids":[["104582.4","0.00011863","0","1"],["104582.3","0.00115191","0","1"],["104582.2","0.37985759","0","2"],["104581.6","0.13342678","0","2"],["104581.5","0.09247784","0","1"],["104580.9","0","0","0"],["104580.3","0","0","0"],["104580.1","0.09316085","0","1"],["104579.6","0.14612422","0","2"],["104579.3","0","0","0"],["104578.7","0","0","0"],["104578.6","0.16777843","0","1"],["104578","0.2316479","0","2"],["104577.3","0","0","0"],["104576.6","0.1655085","0","1"],["104575","0","0","0"],["104574.6","0.00056666","0","1"],["104574.3","0.25205437","0","1"],["104573.9","0.15455925","0","1"],["104572.4","0.14359377","0","2"],["104572.3","0","0","0"],["104572","0.39299596","0","3"],["104571.8","0","0","0"],["104571.6","0.24816898","0","1"],["104569.3","0","0","0"],["104568.6","0.24154146","0","1"],["104568.4","0","0","0"],["104567.6","0.26186413","0","1"],["104425","0.0025","0","1"]],"ts":"1747170048500","checksum":195794025,"seqId":54226057857,"prevSeqId":54226057774}]}
{"arg":{"channel":"books","instId":"BTC-USDT"},"action":"update","data":[{"asks":[["104600.6","0.09333912","0","1"],["104601.1","0.09160182","0","2"],["104602","0.0925115","0","1"],["104602.6","0.09847984","0","1"],["104603.6","0.31783991","0","3"],["104605.5","0.1593841","0","1"],["104606.1","0.32099956","0","2"],["104608.5","0","0","0"],["104608.8","0.00477935","0","1"],["104608.9","0.16692423","0","1"],["104609.3","0.24212124","0","1"],["104611.1","0.24912527","0","1"],["104611.6","0.25811634","0","1"],["104615.1","0.24525526","0","1"],["104620.2","0.13859375","0","1"],["104681.3","0.03","0","1"],["104689.4","0","0","0"]],"bids":[["104591.9","0.60228227","0","12"],["104582.2","0.37773393","0","2"],["104581.6","0.12718274","0","2"],["104581.5","0.0946426","0","1"],["104580.1","0.09446457","0","1"],["104579.6","0.15161963","0","2"],["104578.6","0.15622094","0","1"],["104578","0.22862731","0","2"],["104577.2","0.00477935","0","1"],["104576.6","0.16699784","0","1"],["104576.5","0","0","0"],["104574.3","0.25630754","0","1"],["104573.9","0.15912499","0","1"],["104572.4","0.005","0","1"],["104572.3","0.13859375","0","1"],["104572","0.32608662","0","3"],["104571.6","0.27059792","0","1"],["104568.6","0.26579817","0","1"],["104567.6","0.26274525","0","1"],["104453.9","0","0","0"]],"ts":"1747170048600","checksum":1722023207,"seqId":54226058003,"prevSeqId":54226057857}]}
{"arg":{"channel":"books","instId":"BTC-USDT"},"action":"update","data":[{"asks":[["104604.3","0.0035998","0","2"],["104613.8","0.27634249","0","1"],["104614.2","0","0","0"],["104634.1","0.5461","0","1"]],"bids":[["104586.8","0.00647455","0","2"],["104584.7","0.02818458","0","1"],["104582.5","0.00115191","0","1"],["104582.3","0","0","0"],["104581.6","0.09468101","0","1"],["104562.5","0.65075","0","1"],["104545.8","0.00867163","0","1"],["104541.5","0","0","0"],["104493.3","0.19242972","0","1"],["104493.2","0.08424668","0","9"],["104441","0.01059666","0","1"],["104440.3","0.00095583","0","1"],["104425.3","0","0","0"],["104425","0","0","0"]],"ts":"1747170048700","checksum":-558214674,"seqId":54226058027,"prevSeqId":54226058003}]}
{"arg":{"channel":"books","instId":"BTC-USDT"},"action":"update","data":[{"asks":[["104597.4","0.02359019","0","2"]],"bids":[["104591.9","0.57945227","0","11"],["104588.2","0.00299929","0","1"]],"ts":"1747170048800","checksum":-1420323864,"seqId":54226058030,"prevSeqId":54226058027}]}
{"arg":{"channel":"books","instId":"BTC-USDT"},"action":"update","data":[{"asks":[["104592","0","0","0"],["104594","0","0","0"],["104594.1","0.0811","0","3"],["104596","0","0","0"],["104596.5","0.00021936","0","1"],["104596.6","0","0","0"],["104596.7","0","0","0"],["104596.8","0","0","0"],["104597.4","0.00204917","0","2"],["104598","0.0816","0","1"],["104598.3","0","0","0"],["104598.6","0","0","0"],["104598.8","0","0","0"],["104598.9","0","0","0"],["104600","0.08380843","0","4"],["104600.3","0.00067735","0","1"],["104600.4","0","0","0"],["104600.6","0","0","0"],["104601.1","0.0000125","0","1"],["104601.4","0","0","0"],["104601.8","0.0675558","0","2"],["104601.9","0.00044","0","1"],["104602","0","0","0"],["104602.1","0","0","0"],["104602.5","0","0","0"],["104602.6","0","0","0"],["104603","0","0","0"],["104603.6","0.00001","0","1"],["104604.2","0","0","0"],["104604.3","0.0000125","0","1"],["104604.6","0","0","0"],["104605.2","0.09111814","0","3"],["104605.5","0.09760212","0","1"],["104606","0.09820359","0","1"],["104606.1","0","0","0"],["104607","0.09690746","0","1"],["104607.2","0.00092","0","1"],["104607.3","0","0","0"],["104607.5","0.00479025","0","2"],["104607.6","0.12751881","0","2"],["104608.8","0","0","0"],["104608.9","0","0","0"],["104609.3","0","0","0"],["104609.4","0.036","0","1"],["104609.8","0","0","0"],["104610","0.23429006","0","3"],["104610.5","0.15864156","0","1"],["104610.6","0.1778392","0","1"],["104610.9","0.04535476","0","1"],["104611","0.33668885","0","2"],["104611.1","0","0","0"],["104611.5","0.1778492","0","2"],["104611.6","0","0","0"],["104612.4","0.00092","0","1"],["104613.8","0.20276591","0","1"],["104613.9","0.43166572","0","2"],["104614.2","0.26011001","0","1"],["104614.6","0.04","0","1"],["104615.1","0","0","0"],["104615.9","0.04110304","0","2"],["104616","0.27218828","0","1"],["104616.5","0.26623218","0","1"],["104617.6","0.00668929","0","2"],["104619.9","0","0","0"],["104620.1","0.23963923","0","1"],["104620.2","0","0","0"],["104624","0","0","0"],["104624.4","0.13858895","0","1"],["104625","0","0","0"],["104627","0.002","0","2"],["104628","0.001","0","1"],["104635.6","0.101773","0","1"],["104645","0","0","0"],["104646","0","0","0"],["104647","0","0","0"],["104648","0.22999999","0","4"],["104649","0.21499999","0","4"],["104650","0.49963116","0","4"],["104652.9","0","0","0"],["104654.6","0","0","0"],["104667","0","0","0"],["104673.5","0.19107","0","1"],["104673.6","0","0","0"],["104703.1","0.39519581","0","1"],["104750.5","0.07299861","0","2"],["104750.7","0.00049233","0","7"],["104751.5","0.01448136","0","1"],["104751.9","0.00001969","0","1"],["104753.2","0.0000358","0","1"],["104753.3","2.3905","0","1"],["104754","0.234","0","1"],["104754.2","0.00089983","0","1"],["104754.7","0.00001","0","1"],["104755","0.00001787","0","1"],["104755.1","0.00010283","0","1"],["104756","0.00001103","0","1"],["104757.5","0.77866876","0","1"],["104757.6","0.00001017","0","1"],["104757.7","0.00002193","0","1"],["104758","0.00013459","0","1"],["104758.5","0.00003192","0","3"],["104758.6","0.00094804","0","1"],["104758.7","0.00028146","0","4"],["104758.8","0.06976784","0","6"]],"bids":[["104594","0.88721325","0","19"],["104592.1","0.46480068","0","1"],["104592","0.24477909","0","2"],["104591.9","0.45269703","0","8"],["104590.4","0","0","0"],["104588.2","0.19242972","0","1"],["104588.1","0","0","0"],["104587.8","0.00001","0","1"],["104586.5","0.1955715","0","2"],["104586.2","0.00051","0","1"],["104585.1","0.12844402","0","2"],["104584.7","0","0","0"],["104584.5","0.1011919","0","1"],["104584.1","0.00477929","0","1"],["104583.5","0.15368927","0","1"],["104583.2","0","0","0"],["104583","0.1532479","0","1"],["104582.2","0.17947789","0","1"],["104581.6","0","0","0"],["104581.5","0.16759797","0","1"],["104580.9","0.00098","0","1"],["104580.1","0","0","0"],["104579.6","0.0564907","0","1"],["104579.2","0.25684604","0","1"],["104578.9","0.16539617","0","1"],["104578.6","0","0","0"],["104578","0.0816","0","1"],["104577.9","0.00001501","0","1"],["104577.2","0","0","0"],["104576.6","0","0","0"],["104576.1","0.13858895","0","1"],["104575.7","0.00098","0","1"],["104574.3","0","0","0"],["104574.1","0","0","0"],["104573.9","0","0","0"],["104573.5","0.27228418","0","1"],["104572.7","0","0","0"],["104572.3","0","0","0"],["104572","0.16468229","0","2"],["104571.6","0","0","0"],["104570","0.00529006","0","3"],["104568.6","0","0","0"],["104567.6","0","0","0"],["104567.5","0","0","0"],["104565.4","0","0","0"],["104562.8","0.05970903","0","1"],["104562.2","0","0","0"],["104542.6","0","0","0"],["104541.4","0.00297","0","2"],["104520","0.0033207","0","5"],["104472.8","0.00001","0","1"],["104468.6","0.01051994","0","1"],["104467.9","0","0","0"],["104427.2","0.00478039","0","1"],["104427.1","0.00478039","0","1"],["104425.3","0.1913","0","1"],["104425","0.0025","0","1"]],"ts":"1747170048900","checksum":-1972967969,"seqId":54226058416,"prevSeqId":54226058030}]}
{"arg":{"channel":"books","instId":"BTC-USDT"},"action":"update","data":[{"asks":[["104599.5","0.05480104","0","2"],["104600.3","0","0","0"],["104602.2","0","0","0"],["104603.6","0.02756532","0","2"],["104604.7","0.00067735","0","1"],["104604.9","0.09975849","0","1"],["104605.4","0.23783659","0","3"],["104605.5","0","0","0"],["104606","0","0","0"],["104606.3","0.08969225","0","1"],["104607","0.0982924","0","1"],["104607.6","0.04","0","1"],["104608.6","0.063","0","2"],["104608.7","0.19242972","0","1"],["104609","0.03912507","0","1"],["104609.8","0.14717433","0","1"],["104610.4","0.31692384","0","2"],["104610.5","0","0","0"],["104611","0","0","0"],["104613.2","0.15678427","0","1"],["104613.6","1.01181372","0","2"],["104613.8","0.34738997","0","2"],["104613.9","0.26864","0","1"],["104614.2","0","0","0"],["104615.4","0.25947019","0","1"],["104615.5","0.00478924","0","2"],["104615.9","0.30518397","0","3"],["104616","0","0","0"],["104616.5","0","0","0"],["104617.6","0.00191","0","1"],["104619.5","0.24955591","0","2"],["104620.1","0","0","0"],["104622.9","0.00191","0","1"],["104624.4","0","0","0"],["104625.5","0.13858756","0","1"],["104627","0","0","0"],["104628","0","0","0"],["104629","0.002","0","2"],["104629.9","0","0","0"],["104630","0.00129006","0","3"],["104631.3","0.00013665","0","1"],["104641.6","0","0","0"],["104648","0","0","0"],["104649","0","0","0"],["104650","0.77963116","0","9"],["104651","0.16499999","0","3"],["104655.6","0","0","0"],["104658.4","0","0","0"],["104658.5","0","0","0"],["104659.4","0.00175275","0","1"],["104693.9","6.82914691","0","1"],["104759.3","0.00001392","0","1"],["104760","0.01036163","0","9"],["104760.3","0.00001006","0","1"]],"bids":[["104594","0.87531142","0","19"],["104592.6","0.00301157","0","1"],["104592.5","0.00239023","0","1"],["104592.1","0.16048665","0","1"],["104592","0","0","0"],["104591.9","0.44122203","0","7"],["104590.5","0.02457512","0","1"],["104588.9","0.02818345","0","1"],["104588.2","0","0","0"],["104587.2","0.00115191","0","1"],["104586.7","0.23927024","0","2"],["104586.5","0","0","0"],["104585.9","0.0987474","0","1"],["104585.8","0.08568716","0","1"],["104585.1","0.03122798","0","1"],["104584.5","0.08950805","0","1"],["104584.1","0","0","0"],["104583.9","0.09645723","0","1"],["104583.5","0","0","0"],["104583","0.00477924","0","1"],["104582.9","0.15617924","0","1"],["104582.5","0","0","0"],["104582.3","0.14424553","0","1"],["104582.2","0.27734976","0","2"],["104581.5","0","0","0"],["104580.9","0.15895196","0","2"],["104579.2","0","0","0"],["104578.9","0","0","0"],["104578.6","0.23073119","0","1"],["104578.2","0.15410135","0","1"],["104577","0.13858756","0","1"],["104576.1","0","0","0"],["104575.9","0.24736521","0","1"],["104573.5","0","0","0"],["104572.9","0.27109853","0","1"],["104572","0.33811715","0","2"],["104570.5","0.00191","0","1"],["104565.2","0.00191","0","1"],["104541.7","0.00047803","0","1"],["104535.5","0","0","0"],["104480.9","0.0006368","0","1"],["104478.7","0","0","0"],["104473.7","0.00083716","0","1"],["104471","0","0","0"],["104448.1","0.00478039","0","1"],["104436.1","0","0","0"],["104426.2","0","0","0"],["104426","0","0","0"],["104425.9","0","0","0"],["104425.7","0","0","0"],["104425.3","0","0","0"],["104425","0","0","0"]],"ts":"1747170049000","checksum":-945905879,"seqId":54226058619,"prevSeqId":54226058416}]}
{"arg":{"channel":"books","instId":"BTC-USDT"},"action":"update","data":[{"asks":[["104594.1","0.07619","0","3"],["104596","0.0816","0","1"],["104604.2","0.09063477","0","1"],["104604.7","0.10166621","0","2"],["104604.9","0","0","0"],["104605.1","0.13054023","0","1"],["104605.4","0","0","0"],["104605.6","0.08755187","0","1"],["104605.7","0.02256561","0","1"],["104606.3","0.08779134","0","1"],["104606.6","0.005","0","1"],["104607","0","0","0"],["104609.1","0.14627151","0","1"],["104609.6","0.38863185","0","1"],["104609.7","0.99521542","0","3"],["104609.8","0","0","0"],["104610.4","0.01","0","1"],["104612.5","0.15614643","0","1"],["104612.9","0.23781722","0","1"],["104613.2","0","0","0"],["104613.6","0.77866876","0","1"],["104613.8","0.20276591","0","1"],["104615.2","0.25868452","0","1"],["104615.4","0","0","0"],["104615.9","0.04110304","0","2"],["104618.8","0.23319024","0","1"],["104619.5","0.00001","0","1"],["104631.3","0","0","0"],["104632.9","0.00013665","0","1"],["104635.7","1.41383141","0","1"],["104636.7","0","0","0"],["104639","0.03056666","0","2"],["104646.4","0.00047803","0","1"],["104654","0","0","0"],["104656.3","0.00136836","0","2"],["104667","2.59893636","0","1"],["104751.8","0.00090893","0","1"],["104758.6","0","0","0"],["104758.7","0","0","0"],["104758.8","0","0","0"],["104759.3","0","0","0"],["104760","0","0","0"],["104760.3","0","0","0"]],"bids":[["104594","0.87874608","0","21"],["104591.9","0.44065537","0","6"],["104590.5","0","0","0"],["104589.1","0.012","0","1"],["104586.8","0.00360655","0","1"],["104586.7","0.11938553","0","1"],["104585.9","0","0","0"],["104585.8","0","0","0"],["104585.7","0","0","0"],["104585.2","0.09672004","0","1"],["104585.1","0.12507412","0","2"],["104584.5","0","0","0"],["104583.9","0","0","0"],["104583.8","0.09228159","0","2"],["104583.2","0.09520775","0","1"],["104582.9","0","0","0"],["104582.3","0","0","0"],["104582.2","0.34274068","0","2"],["104581.6","0.16299887","0","1"],["104580.9","0.00098","0","1"],["104578.6","0","0","0"],["104578.2","0","0","0"],["104577.9","0.28386594","0","3"],["104577.5","0.16277562","0","1"],["104576.8","0.45768482","0","1"],["104576.7","0.00056666","0","1"],["104575.9","0","0","0"],["104574.6","0","0","0"],["104572.9","0","0","0"],["104572.4","0","0","0"],["104572.2","1.01965439","0","2"],["104572","0.07447546","0","1"],["104570.7","0.00955834","0","1"],["104570.6","0","0","0"],["104559.9","0.55548298","0","4"],["104426.2","0.00001731","0","1"],["104426","0.0025","0","1"],["104425.9","0.0001","0","1"],["104425.7","0.007986","0","1"],["104425.3","0.1913","0","1"],["104425","0.0025","0","1"],["104424.7","0.00001169","0","1"],["104424.3","0.00156669","0","1"]],"ts":"1747170049100","checksum":162379326,"seqId":54226058782,"prevSeqId":54226058619}]}
{"arg":{"channel":"books","instId":"BTC-USDT"},"action":"update","data":[{"asks":[["104597.6","0.02980161","0","1"],["104601.8","0.04","0","1"],["104604.1","0.09011925","0","1"],["104604.2","0","0","0"],["104604.5","0.00067735","0","1"],["104604.6","0.23352857","0","2"],["104604.7","0","0","0"],["104605.1","0","0","0"],["104605.6","0.08878667","0","1"],["104606.2","0.0914423","0","1"],["104606.3","0","0","0"],["104609.1","0.15519289","0","1"],["104609.6","0.71247744","0","3"],["104609.7","0.67560716","0","1"],["104612.5","0.16039913","0","1"],["104612.8","0.27716315","0","2"],["104612.9","0","0","0"],["104613.4","0.00477909","0","1"],["104614.6","0.28705176","0","2"],["104615.1","0.26229202","0","1"],["104615.2","0","0","0"],["104615.5","0.00001","0","1"],["104618.7","0.25903944","0","1"],["104618.8","0","0","0"],["104624.4","0.13858984","0","1"],["104625.5","0","0","0"],["104678.5","0","0","0"],["104679.5","0.00004128","0","1"],["104699.4","0","0","0"],["104751.8","0","0","0"],["104753.9","0.00089774","0","1"]],"bids":[["104592.6","0","0","0"],["104590.1","0.003007","0","1"],["104587.2","0","0","0"],["104587.1","0","0","0"],["104586.8","0.00475846","0","2"],["104586.7","0.06967759","0","1"],["104585.2","0","0","0"],["104585.1","0.22038033","0","3"],["104583.8","0.00001","0","1"],["104583.7","0.08911059","0","1"],["104583.2","0","0","0"],["104583.1","0.09358057","0","1"],["104583","0","0","0"],["104582.4","0","0","0"],["104582.2","0.17947789","0","1"],["104582.1","0.23217202","0","3"],["104581.6","0.14324512","0","1"],["104581","0.00477909","0","1"],["104580.1","0.1544484","0","1"],["104577.9","0.04512194","0","2"],["104577.8","0.22874421","0","1"],["104577.5","0.14635985","0","1"],["104577","0","0","0"],["104575.5","0.13858984","0","1"],["104575.1","0.25345212","0","1"],["104572.2","0.77866876","0","1"],["104572.1","0.63041445","0","2"],["104571.2","0.25342997","0","1"],["104494.5","0.00010926","0","1"],["104493.2","0.08414984","0","8"],["104442.8","0.00095583","0","1"],["104440.3","0","0","0"],["104424.7","0","0","0"],["104424.3","0","0","0"]],"ts":"1747170049200","checksum":-1701075674,"seqId":54226058891,"prevSeqId":54226058782}]}
{"arg":{"channel":"books","instId":"BTC-USDT"},"action":"update","data":[{"asks":[["104594.1","0.0762","0","4"],["104598.2","0.19242972","0","1"],["104602.4","0.02256561","0","1"],["104602.7","0.00067735","0","1"],["104602.8","0.23360438","0","1"],["104602.9","0.77866876","0","1"],["104604","0.10013702","0","1"],["104604.1","0","0","0"],["104604.5","0.09130012","0","1"],["104604.6","0.14029022","0","1"],["104605.4","0.08941404","0","1"],["104605.6","0","0","0"],["104605.7","0","0","0"],["104606","0.08853516","0","1"],["104606.2","0","0","0"],["104608.9","0.14747621","0","1"],["104609.1","0","0","0"],["104609.5","0.33172357","0","3"],["104609.6","0.38863185","0","1"],["104612.3","0.15964709","0","1"],["104612.5","0","0","0"],["104612.7","0.32025067","0","2"],["104612.8","0.03","0","1"],["104614.5","0.26206271","0","2"],["104614.6","0.04","0","1"],["104615","0.24302104","0","2"],["104615.1","0","0","0"],["104618.5","0.26540901","0","1"],["104618.7","0","0","0"],["104624.4","0.13858914","0","1"],["104628","0.002","0","2"],["104629","0.001","0","1"],["104630","0.00029006","0","2"],["104649","0.33","0","6"],["104650","0.61463115","0","6"],["104651","0","0","0"],["104677","6.83376155","0","1"],["104693.9","0","0","0"],["104757.6","0","0","0"],["104757.7","0","0","0"],["104758","0","0","0"],["104758.5","0","0","0"]],"bids":[["104591.9","0.43642537","0","4"],["104590.1","0.00477904","0","1"],["104586.7","0.13350855","0","1"],["104585.1","0.03122798","0","1"],["104585","0.10007259","0","1"],["104584.9","0.08624659","0","1"],["104583.7","0","0","0"],["104583.5","0.09080327","0","1"],["104583.1","0","0","0"],["104583","0.09139012","0","1"],["104582.2","0.26868827","0","1"],["104582.1","0.08125761","0","2"],["104582","0.16746576","0","1"],["104581.6","0","0","0"],["104581.4","0.15363633","0","1"],["104580.1","0","0","0"],["104580","0.15118468","0","3"],["104577.8","0","0","0"],["104577.7","0.26075704","0","1"],["104577.5","0","0","0"],["104577.3","0.15243856","0","1"],["104576.1","0.13858914","0","1"],["104575.5","0","0","0"],["104575.1","0","0","0"],["104575","0.24098715","0","1"],["104572.1","0.38863185","0","1"],["104572","0.40940287","0","2"],["104571.2","0","0","0"],["104571","0.32008409","0","3"],["104425","0","0","0"]],"ts":"1747170049300","checksum":-1599701024,"seqId":54226059078,"prevSeqId":54226058891}]}
{"arg":{"channel":"books","instId":"BTC-USDT"},"action":"update","data":[{"asks":[["104613.8","0.41800452","0","2"],["104622.6","0.13859053","0","1"],["104624.4","0","0","0"],["104628","0","0","0"],["104629","0.002","0","2"],["104630","0.00129006","0","3"],["104649","0","0","0"],["104650","0.77963115","0","9"],["104651","0.16499999","0","3"],["104757.6","0.00001017","0","1"]],"bids":[["104582.2","0.4312722","0","2"],["104576.1","0","0","0"],["104574.1","0.13859053","0","1"]],"ts":"1747170049400","checksum":-287678984,"seqId":54226059101,"prevSeqId":54226059078}]}
{"arg":{"channel":"books","instId":"BTC-USDT"},"action":"update","data":[{"asks":[["104596.2","0.005","0","1"],["104603.9","0.09581635","0","1"],["104604","0","0","0"],["104604.4","0.30379514","0","2"],["104604.5","0","0","0"],["104604.6","0","0","0"],["104608.7","0.19742972","0","2"],["104609.4","0.34179769","0","3"],["104609.5","0.0000125","0","1"],["104613.8","0.42078321","0","2"],["104614.4","0.23872783","0","1"],["104614.5","0.00478052","0","1"],["104614.9","0.26883768","0","1"],["104615","0.002","0","1"],["104757.5","0","0","0"],["104757.6","0","0","0"]],"bids":[["104592.5","0","0","0"],["104588.9","0","0","0"],["104587","0.02457595","0","1"],["104585","0","0","0"],["104584.9","0.18019731","0","2"],["104583","0","0","0"],["104582.9","0.09516303","0","1"],["104582","0","0","0"],["104581.9","0.16456256","0","1"],["104580","0.00029006","0","2"],["104579.9","0.16847667","0","1"],["104575","0","0","0"],["104574.9","0.24664595","0","1"],["104572.4","0.005","0","1"],["104572","0.14877825","0","1"],["104571.9","0.23904924","0","2"],["104563.2","0.00724989","0","1"],["104561","0","0","0"],["104559.9","0.56048298","0","5"]],"ts":"1747170049500","checksum":959153534,"seqId":54226059141,"prevSeqId":54226059101}]}
{"arg":{"channel":"books","instId":"BTC-USDT"},"action":"update","data":[{"asks":[["104594.1","0.1989","0","6"],["104603.2","0.09877259","0","2"],["104603.7","0.09801961","0","1"],["104603.9","0","0","0"],["104604.4","0.21896011","0","2"],["104604.7","0.08591742","0","1"],["104605.3","0.09341845","0","1"],["104605.4","0","0","0"],["104606","0","0","0"],["104608.2","0.16109629","0","1"],["104608.7","0.51988038","0","4"],["104608.9","0","0","0"],["104609.4","0.036","0","1"],["104611.6","0.1634252","0","1"],["104611.9","0.23801327","0","1"],["104612.3","0","0","0"],["104612.7","0.07298372","0","1"],["104613.7","0.24676448","0","1"],["104613.8","0.33770887","0","2"],["104614.2","0.26095249","0","1"],["104614.4","0","0","0"],["104614.9","0","0","0"],["104617.8","0.23510757","0","1"],["104618.5","0","0","0"],["104756","0","0","0"]],"bids":[["104594","0.58432925","0","17"],["104590.1","0","0","0"],["104589.7","0.00477917","0","1"],["104586.8","0.00360655","0","1"],["104586.7","0.1363649","0","2"],["104586.6","0","0","0"],["104584.9","0","0","0"],["104584.3","0.00115191","0","1"],["104584.2","0.19126195","0","2"],["104583.5","0","0","0"],["104582.9","0","0","0"],["104582.8","0.09270822","0","1"],["104582.2","0.39438533","0","3"],["104582.1","0.00955961","0","1"],["104581.9","0","0","0"],["104581.4","0","0","0"],["104581.2","0.16059706","0","1"],["104580.7","0.18260047","0","2"],["104579.9","0","0","0"],["104579.2","0.15514772","0","1"],["104577.7","0","0","0"],["104577.3","0","0","0"],["104576.9","0.23455227","0","1"],["104576.8","0.25662608","0","2"],["104576.6","0.15283239","0","1"],["104574.9","0","0","0"],["104574.2","0.26977233","0","1"],["104572.2","0","0","0"],["104572.1","0","0","0"],["104572","0.21523002","0","2"],["104571.9","0.00001","0","1"],["104571.2","0.24624537","0","1"],["104571","0.06","0","2"],["104570.3","0.26482506","0","1"],["104425","0.0025","0","1"],["104424.7","0.00001169","0","1"],["104424.3","0.00156669","0","1"]],"ts":"1747170049600","checksum":2088055354,"seqId":54226059228,"prevSeqId":54226059141}]}
{"arg":{"channel":"books","instId":"BTC-USDT"},"action":"update","data":[{"asks":[["104594.1","0.0794","0","5"],["104597.8","0.00067735","0","1"],["104597.9","0.38863185","0","1"],["104598.4","0.46586329","0","1"],["104598.5","0.47049796","0","1"],["104602.7","0","0","0"],["104602.8","0","0","0"],["104603.2","0.0000125","0","1"],["104603.7","0","0","0"],["104603.9","0.09768628","0","1"],["104604.4","0.23176503","0","2"],["104604.7","0","0","0"],["104605.3","0.09484599","0","1"],["104606","0.09322411","0","1"],["104608.2","0","0","0"],["104608.7","0.19742972","0","2"],["104608.8","0.14295479","0","1"],["104609.4","0.34360796","0","3"],["104611.6","0","0","0"],["104611.9","0","0","0"],["104612.2","0.21723726","0","3"],["104612.6","0.32062073","0","2"],["104613.7","0","0","0"],["104613.8","0.4180632","0","2"],["104614.2","0","0","0"],["104614.4","0.25199151","0","1"],["104614.9","0.24682493","0","1"],["104617.8","0","0","0"],["104618.5","0.2650914","0","1"],["104620.7","0.138593","0","1"],["104622.6","0","0","0"],["104647.9","0","0","0"],["104650","0.33032023","0","8"],["104656.7","0.01970158","0","1"],["104656.9","0.02083819","0","1"],["104673.6","6.83376155","0","1"],["104677","0","0","0"],["104755.1","0","0","0"]],"bids":[["104589.7","0.00477919","0","1"],["104588.2","0.101773","0","1"],["104586.7","0.18496942","0","2"],["104585.2","0.00115191","0","1"],["104584.9","0.09598979","0","1"],["104584.8","0.09294396","0","1"],["104584.3","0","0","0"],["104584.2","0","0","0"],["104583.5","0.08834648","0","1"],["104582.9","0.16755311","0","2"],["104582.8","0","0","0"],["104582.2","0.42988012","0","2"],["104581.9","0.16932086","0","1"],["104581.3","0.14731671","0","1"],["104581.2","0","0","0"],["104580.7","0.02930447","0","1"],["104579.9","0.16852064","0","1"],["104579.2","0","0","0"],["104577.6","0.25984945","0","1"],["104577.2","0.16303226","0","1"],["104576.9","0","0","0"],["104576.8","0.15381705","0","1"],["104576.6","0","0","0"],["104574.9","0.26152871","0","1"],["104574.2","0","0","0"],["104574.1","0","0","0"],["104572.1","0.138593","0","1"],["104572","0.21538611","0","2"],["104571.9","0.2608971","0","2"],["104571.2","0","0","0"],["104571","0.31070361","0","3"],["104570.3","0","0","0"],["104424.7","0","0","0"],["104424.3","0","0","0"]],"ts":"1747170049700","checksum":-1077108146,"seqId":54226059315,"prevSeqId":54226059228}]}
{"arg":{"channel":"books","instId":"BTC-USDT"},"action":"update","data":[{"asks":[["104594.1","0.0762","0","4"],["104605.3","0","0","0"],["104605.4","0.08578903","0","1"],["104608.8","0","0","0"],["104608.9","0.15251891","0","1"],["104611.4","0.0047792","0","1"],["104613.4","0","0","0"]],"bids":[["104594","0.60436125","0","17"],["104586.8","0.00475846","0","2"],["104585.2","0","0","0"],["104584.9","0.19403427","0","2"],["104584.8","0","0","0"],["104581.4","0.14477259","0","1"],["104581.3","0","0","0"],["104581","0","0","0"],["104578.6","0.0047792","0","1"],["104560.5","0.002868","0","1"],["104466.2","0.12","0","1"]],"ts":"1747170049800","checksum":-1308685748,"seqId":54226059338,"prevSeqId":54226059315}]}
{"arg":{"channel":"books","instId":"BTC-USDT"},"action":"update","data":[{"asks":[["104599.7","0.02256561","0","1"],["104602.4","0","0","0"],["104648","1","0","1"],["104665.8","0.95468522","0","2"],["104673.6","0","0","0"],["104677","6.78324487","0","1"],["104755","0","0","0"]],"bids":[["104594","0.69392125","0","18"],["104544.1","0.2373239","0","2"],["104449.1","0","0","0"],["104424.7","0.00001169","0","1"]],"ts":"1747170049900","checksum":-1980674344,"seqId":54226059348,"prevSeqId":54226059338}]}
{"arg":{"channel":"books","instId":"BTC-USDT"},"action":"update","data":[{"asks":[["104607","0.01","0","1"],["104699.2","0","0","0"],["104699.6","0","0","0"],["104755","0.00001787","0","1"]],"bids":[["104591.9","0.43629458","0","3"]],"ts":"1747170050000","checksum":-1909829216,"seqId":54226059352,"prevSeqId":54226059348}]}
{"arg":{"channel":"books","instId":"BTC-USDT"},"action":"update","data":[{"asks":[["104594.1","0.0794","0","5"],["104604.3","0.21971032","0","2"],["104604.4","0.0982445","0","1"],["104605.3","0.08593915","0","1"],["104605.4","0","0","0"],["104608.8","0.14863468","0","1"],["104608.9","0","0","0"],["104611.4","0","0","0"],["104612.1","0.00477917","0","1"],["104620.7","0.13859314","0","1"],["104638.7","0.00056666","0","1"],["104639","0.03","0","1"],["104656","0.00056666","0","1"],["104656.3","0.0008017","0","1"],["104667.9","0","0","0"],["104669.2","0","0","0"],["104670.2","0.01059655","0","1"],["104705","0.01348429","0","1"],["104705.4","0.00095506","0","1"],["104754.7","0","0","0"],["104755","0","0","0"]],"bids":[["104594","0.69405204","0","19"],["104590.1","0.00477911","0","1"],["104589.7","0","0","0"],["104584.9","0.09598979","0","1"],["104584.8","0.09183361","0","1"],["104581.4","0","0","0"],["104581.3","0.15164984","0","1"],["104580","0.00506923","0","3"],["104578.6","0","0","0"],["104570.9","0.00955832","0","1"],["104570.7","0","0","0"]],"ts":"1747170050100","checksum":-233894295,"seqId":54226059387,"prevSeqId":54226059352}]}
{"arg":{"channel":"books","instId":"BTC-USDT"},"action":"update","data":[{"asks":[["104594.1","0.0762","0","4"],["104597.8","0","0","0"],["104597.9","0.00067735","0","1"],["104605.3","0","0","0"],["104605.4","0.08871178","0","1"],["104608.8","0","0","0"],["104608.9","0.15829375","0","1"],["104610.4","0","0","0"],["104612.2","0.052","0","2"],["104612.3","0.15025655","0","1"],["104612.6","0.071695","0","1"],["104612.7","0.32011805","0","2"],["104620.7","0.13859252","0","1"],["104648","0","0","0"],["104754.7","0.00001","0","1"],["104755","0.00001787","0","1"]],"bids":[["104584.9","0.19156833","0","2"],["104584.8","0","0","0"],["104581.4","0.15805145","0","1"],["104581.3","0","0","0"],["104578.1","0.19242972","0","1"],["104577.7","0.23215996","0","1"],["104577.6","0","0","0"],["104577.3","0.15088378","0","1"],["104577.2","0","0","0"],["104573.4","0.13859252","0","1"],["104572.1","0","0","0"]],"ts":"1747170050200","checksum":1908129597,"seqId":54226059419,"prevSeqId":54226059387}]}
{"arg":{"channel":"books","instId":"BTC-USDT"},"action":"update","data":[{"asks":[["104612.1","0","0","0"],["104613.4","0.00477916","0","1"],["104620.7","0.13859278","0","1"]],"bids":[["104594","0.69406204","0","20"],["104590.1","0.00300226","0","1"],["104581.5","0.00477916","0","1"],["104580","0.00029006","0","2"],["104573.4","0","0","0"],["104572.1","0.13859278","0","1"],["104424.7","0","0","0"]],"ts":"1747170050300","checksum":1940997051,"seqId":54226059437,"prevSeqId":54226059419}]}
{"arg":{"channel":"books","instId":"BTC-USDT"},"action":"update","data":[{"asks":[],"bids":[["104588.3","0.00115191","0","1"],["104587.8","0.07299372","0","2"],["104586.8","0.00360655","0","1"],["104576.8","0.38954996","0","2"],["104572.3","0.38863185","0","1"],["104572.2","0.13859283","0","1"],["104572.1","0","0","0"],["104572","0.43090759","0","1"],["104569.9","0.77866876","0","1"],["104425.7","0","0","0"],["104425.3","0","0","0"],["104425","0","0","0"]],"ts":"1747170050400","checksum":1357340792,"seqId":54226059450,"prevSeqId":54226059437}]}
{"arg":{"channel":"books","instId":"BTC-USDT"},"action":"update","data":[{"asks":[["104620.7","0","0","0"],["104621.9","0.13859242","0","1"]],"bids":[["104573.4","0.13859242","0","1"],["104572.2","0","0","0"]],"ts":"1747170050500","checksum":1357340792,"seqId":54226059466,"prevSeqId":54226059450}]}
{"arg":{"channel":"books","instId":"BTC-USDT"},"action":"update","data":[{"asks":[["104654.2","0.0022","0","1"],["104685.4","0","0","0"],["104698.9","0.0022","0","1"],["104755","0","0","0"]],"bids":[],"ts":"1747170050600","checksum":1357340792,"seqId":54226059470,"prevSeqId":54226059466}]}
{"arg":{"channel":"books","instId":"BTC-USDT"},"action":"update","data":[{"asks":[],"bids":[["104590.1","0.00477906","0","1"]],"ts":"1747170050700","checksum":2132127094,"seqId":54226059474,"prevSeqId":54226059470}]}
{"arg":{"channel":"books","instId":"BTC-USDT"},"action":"update","data":[{"asks":[["104606","0.09672015","0","2"]],"bids":[],"ts":"1747170050800","checksum":2132127094,"seqId":54226059477,"prevSeqId":54226059474}]}
{"arg":{"channel":"books","instId":"BTC-USDT"},"action":"update","data":[{"asks":[["104620.7","0.13859295","0","1"],["104621.9","0","0","0"],["104655.7","0.61817102","0","1"],["104693.1","0.70384793","0","2"],["104754.7","0","0","0"]],"bids":[["104573.4","0","0","0"],["104572.4","0.14359295","0","2"],["104566.8","0.39951603","0","4"],["104425.7","0.007986","0","1"]],"ts":"1747170051000","checksum":2132127094,"seqId":54226059488,"prevSeqId":54226059477}]}
{"event":"subscribe","arg":{"channel":"books","instId":"BTC-USDT"},"connId":"fea9f979"}
{"arg":{"channel":"books","instId":"BTC-USDT"},"action":"snapshot","data":[{"asks":[["104458.4","1.59414935","0","36"],["104458.6","0.08956","0","1"],["104459","0.6108026","0","6"],["104459.1","1.88876467","0","9"],["104459.7","0.09988546","0","2"],["104459.8","0.011578","0","2"],["104460","0.25001","0","3"],["104460.1","0.71171086","0","8"],["104460.2","0.39252501","0","2"],["104461.2","0.09695781","0","1"],["104461.5","0.02400825","0","1"],["104461.8","0.09565085","0","1"],["104462.1","0.05209157","0","2"],["104462.2","0.005","0","1"],["104462.6","0.0047854","0","1"],["104462.7","0.13880188","0","1"],["104462.8","0.00521914","0","1"],["104463.4","0.19242972","0","1"],["104463.8","0.03829085","0","1"],["104464","0.14873112","0","1"],["104464.1","0.05209157","0","2"],["104464.5","0.00001","0","1"],["104464.7","0.15498454","0","1"],["104464.9","0.03403459","0","1"],["104465","0.29193486","0","1"],["104465.2","0.31317788","0","2"],["104466","0.04528223","0","2"],["104466.7","0.0001303","0","1"],["104466.8","0.02718728","0","1"],["104468","0.55530885","0","3"],["104468.1","0.44915812","0","4"],["104468.5","0.25423678","0","2"],["104468.7","0.04","0","1"],["104469.3","0.02486597","0","1"],["104469.4","0.00044","0","1"],["104470","0.00029006","0","2"],["104470.1","0.05209157","0","2"],["104470.2","0.24500149","0","1"],["104470.7","0.25268817","0","1"],["104470.9","0.05209157","0","2"],["104471.9","0.05209157","0","2"],["104472.5","0.00001","0","1"],["104473.1","0.77866876","0","1"],["104473.2","0.25339829","0","1"],["104473.9","0.6332815","0","3"],["104474.1","0.05209157","0","2"],["104474.2","0.00056666","0","1"],["104474.3","0.26526036","0","1"],["104474.7","0.00593","0","2"],["104475.2","0.04","0","1"],["104476","0.02592074","0","2"],["104476.1","0.05209157","0","2"],["104476.4","0.00001","0","1"],["104476.5","0.000015","0","1"],["104477","0.005","0","1"],["104477.3","0.00478642","0","1"],["104478.7","0.39116708","0","2"],["104479.9","0.02213238","0","2"],["104480","0.00220843","0","3"],["104480.1","0.28609157","0","3"],["104480.2","0.56595","0","1"],["104480.4","0.00001","0","1"],["104480.7","0.17796783","0","1"],["104481","0.04","0","1"],["104481.2","0.08422929","0","3"],["104481.7","0.00478642","0","1"],["104481.8","0.05982112","0","1"],["104482.2","0.00956875","0","1"],["104482.5","0.10653","0","1"],["104482.6","0.00191","0","1"],["104484.4","0.00001","0","1"],["104484.7","0.02392054","0","1"],["104485","0.6190888","0","1"],["104485.1","0.77866876","0","1"],["104485.2","0.17796783","0","1"],["104485.4","0.129","0","4"],["104485.5","0.00004781","0","1"],["104485.6","0.59760307","0","3"],["104485.7","0.016","0","1"],["104485.9","0.00287106","0","1"],["104486","0.17796783","0","1"],["104486.1","0.03609157","0","1"],["104486.2","0.00287106","0","1"],["104486.3","0.00287106","0","1"],["104486.4","0.17796783","0","1"],["104486.5","0.00287106","0","1"],["104487","0.002015","0","3"],["104487.5","0.02230591","0","1"],["104487.7","0.17796783","0","1"],["104487.8","0.00191","0","1"],["104488","0.001","0","1"],["104488.3","0.00373804","0","2"],["104488.4","0.00221","0","2"],["104488.5","0.002","0","1"],["104489.4","0.18721271","0","1"],["104489.5","0.005","0","1"],["104490","0.00029006","0","2"],["104490.2","0.29193486","0","1"],["104491.9","0.28609157","0","3"],["104492.3","0.00001","0","1"],["104493.3","0.00287","0","1"],["104494.7","0.100128","0","1"],["104495.1","0.53043481","0","2"],["104495.2","0.07298372","0","1"],["104495.3","0.17796783","0","1"],["104495.7","0.0084908","0","1"],["104496.1","0.00952917","0","1"],["104496.2","0.19242972","0","1"],["104496.3","0.00001","0","1"],["104497.2","0.77866876","0","1"],["104497.3","0.4252708","0","2"],["104497.5","0.00001501","0","1"],["104498.6","0.00013972","0","1"],["104499.3","0.47004433","0","1"],["104500","0.00220843","0","3"],["104500.3","0.00001","0","1"],["104500.8","0.0455262","0","1"],["104501.3","0.00004785","0","1"],["104501.9","0.00001946","0","1"],["104503.9","0.00287","0","1"],["104504.2","0.00001","0","1"],["104505","0.96694196","0","3"],["104505.6","0.0022","0","1"],["104505.7","1.39959421","0","1"],["104506.9","0.19242972","0","1"],["104507","0.304","0","3"],["104508","0.035015","0","2"],["104508.1","0.26864","0","1"],["104508.2","0.00001","0","1"],["104508.3","0.05049657","0","3"],["104508.9","0.17796783","0","1"],["104509","0.1","0","2"],["104509.5","0.77866876","0","1"],["104509.7","1.2086423","0","2"],["104509.8","0.36908178","0","1"],["104509.9","0.6867","0","1"],["104510","0.21029005","0","5"],["104510.1","0.036","0","1"],["104511","0.07999999","0","1"],["104511.2","0.1106896","0","1"],["104511.3","0.554581","0","1"],["104511.4","0.02871854","0","1"],["104512.2","0.00001","0","1"],["104513.2","0.02871914","0","1"],["104513.4","0.036","0","1"],["104514.3","2.51461","0","1"],["104514.8","0.1","0","1"],["104515.4","0.00287","0","1"],["104516.1","0.00001","0","1"],["104516.3","0.03647863","0","2"],["104517.6","0.04398272","0","4"],["104518.5","0.00001501","0","1"],["104518.6","0.19242972","0","1"],["104519.5","0.00004968","0","1"],["104520","0.00220843","0","3"],["104520.1","0.00001","0","1"],["104520.2","0.78897017","0","1"],["104520.3","0.2868017","0","4"],["104520.4","0.36908178","0","1"],["104520.6","0.29193486","0","1"],["104522.6","0.1778392","0","1"],["104524.1","0.00001","0","1"],["104524.5","0.77866876","0","1"],["104524.8","0.052","0","2"],["104524.9","0.01434731","0","1"],["104525","0.49439815","0","1"],["104525.9","0.052","0","2"],["104526.2","0.00080366","0","1"],["104526.9","1.96486805","0","2"],["104528.1","0.05201","0","3"],["104528.2","6.74230096","0","1"],["104529.2","0.00001501","0","1"],["104529.5","0.10898372","0","2"],["104529.9","0.19242972","0","1"],["104530","0.00028006","0","1"],["104530.1","0.036","0","1"],["104530.3","0.0004968","0","1"],["104530.9","0.036","0","1"],["104532","0.00001","0","1"],["104533.3","0.000173","0","1"],["104534.4","0.04784375","0","1"],["104535","0.03","0","1"],["104535.2","0.036","0","1"],["104535.8","0.77866876","0","1"],["104536","0.00001","0","1"],["104536.1","0.05127715","0","2"],["104536.4","0.234","0","1"],["104536.6","0.000345","0","1"],["104537","2.496934","0","1"],["104537.1","0.413386","0","1"],["104538.4","0.07298372","0","1"],["104538.7","0.000345","0","1"],["104539.5","0.00001501","0","1"],["104539.8","0.000345","0","1"],["104540","1.00222843","0","6"],["104540.9","0.36908178","0","1"],["104541.1","0.19242972","0","1"],["104542.6","3.05983","0","1"],["104542.9","0.83283","0","1"],["104544","0.00001","0","1"],["104545","0.000345","0","1"],["104545.4","0.00017476","0","1"],["104545.5","0.016","0","1"],["104546","0.03186","0","1"],["104546.3","0.77866876","0","1"],["104547.5","0.07974","0","1"],["104547.7","0.25","0","2"],["104547.9","0.00001","0","1"],["104548.1","0.00841158","0","1"],["104549.2","0.29193486","0","1"],["104550","0.09606525","0","4"],["104551.1","0.016","0","1"],["104551.9","0.00001","0","1"],["104552.1","0.016","0","1"],["104552.3","0.06981","0","1"],["104553.2","0.09573","0","1"],["104553.3","0.28806972","0","2"],["104554.1","0.29193486","0","1"],["104555.9","0.00001","0","1"],["104556.2","0.03","0","1"],["104556.6","0.11477","0","1"],["104557","0.03","0","1"],["104557.2","0.12061934","0","1"],["104557.3","0.79466876","0","2"],["104559","0.01052734","0","1"],["104559.1","0.234","0","1"],["104559.8","0.00001","0","1"],["104560","0.00220843","0","3"],["104560.4","0.01052734","0","1"],["104560.5","0.030015","0","2"],["104561.3","0.03","0","1"],["104561.6","0.03","0","1"],["104561.7","0.20173397","0","1"],["104561.8","0.36908178","0","1"],["104562.4","0.831466","0","1"],["104563.1","0.0135011","0","1"],["104563.3","0.01052734","0","1"],["104563.4","0.01089602","0","1"],["104563.5","0.05128675","0","1"],["104563.8","0.00001","0","1"],["104564.2","0.19127","0","1"],["104565.4","0.02105468","0","2"],["104565.5","0.010529","0","1"],["104565.6","0.01034","0","1"],["104566.2","0.00095633","0","1"],["104567","0.01052734","0","1"],["104567.1","0.01089602","0","1"],["104567.2","0.010529","0","1"],["104567.7","0.00009561","0","1"],["104567.8","0.00001","0","1"],["104568.6","0.03118091","0","1"],["104569.2","0.01052734","0","1"],["104569.8","0.01089602","0","1"],["104570","0.02133806","0","3"],["104570.1","1.02326432","0","3"],["104570.2","0.01914537","0","1"],["104571","0.000015","0","1"],["104571.3","0.01052734","0","1"],["104571.4","0.01089602","0","1"],["104571.5","0.010529","0","1"],["104571.8","0.03829797","0","2"],["104572.1","0.0106966","0","1"],["104573.3","0.05793435","0","1"],["104573.6","0.01052734","0","1"],["104573.7","0.010529","0","1"],["104573.8","0.12","0","1"],["104574.1","0.01052734","0","1"],["104574.2","0.01059613","0","1"],["104575.2","0.01052734","0","1"],["104575.3","0.01089602","0","1"],["104575.4","0.010529","0","1"],["104575.6","0.07298372","0","1"],["104575.7","0.00001","0","1"],["104576.5","0.01059613","0","1"],["104576.6","0.01059613","0","1"],["104577.2","0.02119226","0","2"],["104577.3","0.01052777","0","1"],["104577.4","0.010529","0","1"],["104577.7","0.01052734","0","1"],["104577.8","0.14869446","0","2"],["104579","0.01052777","0","1"],["104579.2","0.01052734","0","1"],["104579.7","0.00001","0","1"],["104580","0.00219843","0","2"],["104580.1","0.01059613","0","1"],["104580.2","0.01059613","0","1"],["104581.5","0.00003002","0","2"],["104581.7","0.02105468","0","2"],["104581.8","0.01052734","0","1"],["104581.9","0.01052777","0","1"],["104582","0.01059556","0","1"],["104582.3","0.77866876","0","1"],["104584.5","0.01052777","0","1"],["104584.7","1.25507","0","1"],["104584.8","0.00125969","0","1"],["104585.3","0.0579344","0","1"],["104586.1","0.01052734","0","1"],["104586.2","0.0698","0","1"],["104586.9","0.01059638","0","1"],["104587.3","0.01099591","0","1"],["104587.4","0.05737","0","1"],["104587.5","0.01089602","0","1"],["104587.7","0.00001","0","1"],["104587.8","0.12","0","1"],["104588.2","0.0322","0","2"],["104588.3","0.51052777","0","2"],["104588.8","0.01194076","0","2"],["104589.2","0.01059613","0","1"],["104589.3","0.01059613","0","1"],["104589.4","0.01052734","0","1"],["104589.8","0.234","0","1"],["104590","0.00028006","0","1"],["104590.2","0.01059556","0","1"],["104592","0.07299872","0","2"],["104593","0.77866876","0","1"],["104595.6","0.00001","0","1"],["104598.1","0.01089602","0","1"],["104598.2","0.01059638","0","1"],["104598.4","0.22972","0","1"],["104598.6","0.0001","0","1"],["104598.9","0.01059638","0","1"],["104599.2","0.0026904","0","1"],["104599.9","0.000173","0","1"],["104600","0.00322287","0","7"],["104600.2","0.0008","0","1"],["104601.1","0.03178839","0","3"],["104601.2","0.01089628","0","1"],["104601.5","0.00449585","0","2"],["104602.5","0.00001501","0","1"],["104603.2","0.01089628","0","1"],["104603.6","0.77866876","0","1"],["104604.7","0.00017476","0","1"],["104605.6","0.01089602","0","1"],["104605.7","0.01059638","0","1"],["104605.8","0.01059638","0","1"],["104605.9","0.01059638","0","1"],["104607","0.97264328","0","1"],["104607.4","0.234","0","1"],["104607.5","0.00001","0","1"],["104607.6","0.04634752","0","1"],["104608.4","0.00041816","0","1"],["104609.6","0.01059613","0","1"],["104609.7","0.01059618","0","1"],["104609.8","0.01089628","0","1"],["104609.9","0.03208854","0","3"],["104610","0.29221492","0","2"],["104610.2","0.027","0","1"],["104611.7","0.01089602","0","1"],["104611.8","0.01059638","0","1"],["104612","0.00011471","0","1"],["104614.7","2.88986","0","1"],["104615","0.01089628","0","1"],["104615.1","0.77866876","0","1"],["104615.3","0.29193486","0","1"],["104615.5","0.00001","0","1"],["104617.5","0.01089628","0","1"],["104617.6","0.4","0","1"],["104618.1","0.234","0","1"],["104618.5","0.01403746","0","1"],["104619.3","0.02179204","0","2"],["104619.4","0.01089628","0","1"],["104619.9","0.00090502","0","1"],["104620","0.00224524","0","3"],["104620.5","0.160778","0","1"],["104622","0.02189226","0","2"],["104622.1","0.06975","0","1"],["104623.4","0.00001","0","1"],["104623.5","0.000015","0","1"],["104623.7","0.01089602","0","1"],["104625","0.0000103","0","1"],["104625.7","0.0001","0","1"],["104626.4","0.01908652","0","2"],["104627.2","0.77866876","0","1"],["104628","0.01403883","0","1"],["104628.8","0.07298372","0","1"],["104629.5","0.00010997","0","1"],["104630","0.00028006","0","1"],["104631.4","0.00001","0","1"],["104633","1.89471219","0","1"],["104633.2","0.04783921","0","4"],["104633.9","0.00014488","0","1"],["104637","0.234","0","1"],["104637.2","0.03","0","1"],["104637.8","0.77866876","0","1"],["104640","0.00220843","0","3"],["104641.3","0.03","0","1"],["104642.5","0.0003067","0","1"],["104642.7","0.03","0","1"],["104642.8","0.0288065","0","3"],["104643.3","0.00124092","0","2"],["104643.8","0.07298372","0","1"],["104644.5","0.00001501","0","1"],["104646.7","0.00094804","0","1"],["104646.9","0.04449518","0","2"],["104647.3","0.00957305","0","2"],["104647.5","0.234","0","1"],["104649.1","0.77866876","0","1"],["104649.4","0.00239301","0","1"],["104650","0.00080639","0","3"],["104651.2","0.03","0","1"]],"bids":[["104458.3","0.01077302","0","1"],["104457.8","0.0100101","0","3"],["104457.1","0.0001","0","1"],["104455","0.00001008","0","1"],["104454.8","0.00006072","0","1"],["104454.3","0.00004786","0","1"],["104453.1","0.00001","0","1"],["104452.2","0.0005","0","1"],["104451.4","0.0026287","0","1"],["104450","0.00033024","0","3"],["104449.6","0.0095704","0","1"],["104448.8","0.00001","0","1"],["104447.6","0.00001846","0","1"],["104447.2","0.002","0","1"],["104446.9","0.00098","0","1"],["104446.8","0.00001783","0","1"],["104446.7","0.00030064","0","1"],["104446.3","0.00005","0","1"],["104445.3","0.01","0","2"],["104444.9","0.00030064","0","1"],["104444.8","0.00001","0","1"],["104444.4","0.0001114","0","2"],["104444","0.00004787","0","1"],["104443.7","0.00008121","0","1"],["104443.5","0.01756487","0","1"],["104443.3","0.00001","0","1"],["104441.7","0.00098","0","1"],["104441.3","0.22266268","0","1"],["104441.1","0.00002018","0","1"],["104440.9","0.00199377","0","5"],["104440.7","0.19025387","0","2"],["104440.4","0.0000125","0","1"],["104440.3","0.04","0","1"],["104440.2","0.413376","0","1"],["104440","0.00432258","0","6"],["104439.6","0.00874998","0","1"],["104439.5","0.05270547","0","2"],["104439.3","0.19329816","0","3"],["104438.7","0.13817302","0","2"],["104438.4","0.00001002","0","1"],["104438.3","0.0000125","0","1"],["104437.9","0.00046105","0","1"],["104437.7","0.15980642","0","1"],["104437.5","0.04236132","0","3"],["104437.3","0.0000125","0","1"],["104437.2","0.16058088","0","1"],["104436.8","0.00001","0","1"],["104436.6","0.36594109","0","1"],["104436.3","0.01093967","0","1"],["104435.7","0.15583316","0","1"],["104435.5","0.00191","0","1"],["104435.3","0.0001","0","1"],["104434.4","0.000015","0","1"],["104434.2","0.000015","0","1"],["104433.5","0.23960567","0","2"],["104433.1","0.15956117","0","1"],["104432.7","0.17805538","0","2"],["104432.6","0.00033148","0","2"],["104432","0.0000125","0","1"],["104431.4","0.31271169","0","1"],["104431","0.06022355","0","1"],["104430.7","0.00007949","0","1"],["104430.3","0.00191","0","1"],["104430","0.00029006","0","2"],["104429.6","0.00122607","0","4"],["104429.5","0.19242972","0","1"],["104428.9","0.00001","0","1"],["104427.9","0.17796783","0","1"],["104427.7","0.25915523","0","1"],["104426.9","0.17796783","0","1"],["104426.8","0.23336448","0","2"],["104426.3","0.02871701","0","1"],["104426.2","0.00058397","0","2"],["104426.1","0.29357401","0","1"],["104425.9","0.0001","0","1"],["104425.8","0.05713504","0","1"],["104424.9","0.00001","0","1"],["104424.8","0.17796783","0","1"],["104424.7","0.00001169","0","1"],["104424.3","0.00156669","0","1"],["104424","0.000015","0","1"],["104423.7","0.00004788","0","1"],["104423.6","0.17796783","0","1"],["104423","0.00031959","0","3"],["104422.9","0.00952197","0","1"],["104422.8","0.77961723","0","2"],["104421.7","0.07298372","0","1"],["104421","0.00713293","0","3"],["104420.6","0.36908178","0","1"],["104420.4","0.68528","0","1"],["104420","0.00277552","0","4"],["104419.4","0.00003046","0","1"],["104418.9","0.00005586","0","1"],["104418.4","0.0001","0","1"],["104418.2","0.0095242","0","1"],["104418.1","0.04857722","0","3"],["104417.7","0.19242972","0","1"],["104417.4","0.00012018","0","1"],["104417.3","0.07344","0","1"],["104417.2","0.00522","0","1"],["104417.1","0.00005919","0","1"],["104417","0.00001","0","1"],["104416.7","0.17796783","0","1"],["104416.6","0.00019387","0","5"],["104415.5","0.60049","0","1"],["104414.9","0.00739284","0","1"],["104414.8","0.13880188","0","1"],["104414.7","0.01905106","0","2"],["104414.5","0.00003296","0","1"],["104414.4","0.00861804","0","1"],["104413.8","0.07668254","0","2"],["104413.6","0.000015","0","1"],["104413.1","0.02871807","0","1"],["104412.8","0.0022","0","1"],["104412.2","0.00007379","0","1"],["104412.1","0.00056666","0","1"],["104411.7","0.00047863","0","1"],["104411.6","0.00006","0","1"],["104411.2","0.0001872","0","2"],["104410.8","0.00001007","0","1"],["104410","0.00029298","0","2"],["104409.7","0.52343443","0","2"],["104409.6","0.54704961","0","2"],["104409.4","0.77866876","0","1"],["104409.1","0.00001","0","1"],["104408.6","0.0008379","0","2"],["104408.5","0.00003352","0","1"],["104407.9","0.00002454","0","1"],["104407.5","0.00478652","0","1"],["104407.4","0.00287","0","1"],["104407.2","0.03103147","0","2"],["104407","0.48324487","0","1"],["104406.7","0.0489755","0","1"],["104405.8","0.00001051","0","1"],["104405.1","0.00003566","0","2"],["104404.2","0.00008559","0","1"],["104404.1","0.19248461","0","2"],["104404","0.0001056","0","2"],["104403.9","0.00050129","0","4"],["104403.4","0.00001334","0","1"],["104403.2","0.000015","0","1"],["104402.9","0.00001373","0","1"],["104402.2","0.27782809","0","2"],["104401.2","0.01436431","0","1"],["104401","0.00023525","0","1"],["104400","0.112671","0","49"],["104399.9","0.0051225","0","9"],["104399.4","0.00041858","0","1"],["104399.3","0.28722621","0","1"],["104398.8","0.77874386","0","4"],["104398.1","0.07298372","0","1"],["104398","0.00004846","0","1"],["104397.7","0.03","0","1"],["104397.2","0.00001","0","1"],["104396.6","0.00009579","0","1"],["104396.3","0.00002839","0","1"],["104395.8","0.00001704","0","1"],["104395.6","0.04703936","0","1"],["104395.5","0.0022","0","1"],["104394.6","0.00005067","0","1"],["104394.2","0.002881","0","2"],["104394.1","0.35507529","0","1"],["104393.9","0.00030478","0","1"],["104393.8","0.32719","0","1"],["104393.3","0.00005057","0","1"],["104393.2","0.44766772","0","1"],["104392.8","0.000015","0","1"],["104391.3","0.00001234","0","1"],["104391.2","0.0008","0","1"],["104390.8","0.03828934","0","1"],["104390.5","0.19242972","0","1"],["104390","0.55591808","0","4"],["104389.2","0.00001","0","1"],["104388.8","0.00292077","0","2"],["104388.7","0.36908178","0","1"],["104388.4","1.1943101","0","1"],["104388.3","0.77866876","0","1"],["104388.2","0.00123","0","1"],["104387.8","0.00261695","0","1"],["104387","0.0481651","0","2"],["104386.9","0.00093383","0","2"],["104386.8","0.00005522","0","1"],["104386.7","0.00012605","0","2"],["104386.3","0.00041848","0","2"],["104386.2","0.00003798","0","1"],["104385.9","2.62108924","0","2"],["104385.7","0.00004476","0","3"],["104385.5","0.00014367","0","3"],["104385.3","0.00019205","0","2"],["104384.9","0.00003456","0","1"],["104384.8","0.00006878","0","4"],["104384.7","0.00016998","0","7"],["104384.4","0.00002118","0","2"],["104383.9","0.01059588","0","1"],["104383.8","0.02195879","0","4"],["104383.7","0.00001855","0","1"],["104383.6","0.03","0","1"],["104383.4","0.07298372","0","1"],["104383.3","0.00090892","0","2"],["104383.2","0.00001016","0","1"],["104382.9","0.00162841","0","7"],["104382.8","0.00001537","0","1"],["104382.4","0.000015","0","1"],["104382.3","0.00052775","0","2"],["104382.2","0.00483056","0","1"],["104382","0.000015","0","1"],["104381.7","0.03","0","1"],["104381.4","0.00003468","0","1"],["104381.2","0.00001042","0","1"],["104380.9","0.00013167","0","2"],["104380.7","0.00001015","0","1"],["104380.6","0.00001095","0","1"],["104380.4","0.00001008","0","1"],["104380.2","0.01053013","0","1"],["104380.1","0.02179146","0","2"],["104380","0.00260964","0","6"],["104379.8","0.00003579","0","1"],["104379.7","0.00117685","0","7"],["104379.6","0.00015483","0","1"],["104379.2","0.00364215","0","1"],["104379","0.00213643","0","19"],["104378.9","0.01053013","0","1"],["104378.8","0.00014788","0","2"],["104378.7","0.00002991","0","2"],["104378.2","0.0000647","0","1"],["104377.7","0.00031738","0","2"],["104377.5","0.00001721","0","1"],["104377.3","0.00001","0","1"],["104377.2","0.00011481","0","2"],["104377","0.01066326","0","4"],["104376.9","0.00003197","0","2"],["104376.7","0.04212052","0","4"],["104376.6","0.02179146","0","2"],["104376.5","0.01053013","0","1"],["104376.4","0.29093002","0","1"],["104376.3","0.77866876","0","1"],["104376.1","0.00001055","0","1"],["104376","0.01053013","0","1"],["104375.9","0.0005","0","1"],["104375.6","0.00004285","0","3"],["104375.3","0.00009581","0","1"],["104375.2","0.01059588","0","1"],["104375.1","0.02187938","0","6"],["104375","0.04703539","0","28"],["104374.9","0.00137841","0","3"],["104374.8","0.00002462","0","1"],["104374.7","0.00003352","0","1"],["104374.3","0.00005897","0","2"],["104374.2","0.00011824","0","4"],["104374.1","0.01062593","0","2"],["104374","0.02179146","0","2"],["104373.8","0.00003133","0","1"],["104373.4","0.00001","0","1"],["104373.2","0.2224979","0","2"],["104373.1","0.1913","0","1"],["104372.9","0.0001","0","1"],["104372.8","0.01053013","0","1"],["104372.7","0.00068148","0","4"],["104372.5","0.00002032","0","1"],["104372","0.000015","0","1"],["104371.5","0.02107942","0","3"],["104371.4","0.00107652","0","1"],["104371.2","0.00001005","0","1"],["104371.1","0.36919508","0","3"],["104370.8","0.03","0","1"],["104370.7","0.00017245","0","2"],["104370.6","0.00007547","0","2"],["104370.4","0.00014732","0","3"],["104370.2","0.00008475","0","1"],["104370.1","0.0210706","0","3"],["104370","0.00279079","0","3"],["104369.7","0.00011878","0","1"],["104369.5","0.00001844","0","1"],["104369.4","0.00001","0","1"],["104369.3","0.02107118","0","3"],["104369.2","0.02179146","0","2"],["104369.1","0.03","0","1"],["104369","0.00513171","0","7"],["104368.8","0.00029081","0","1"],["104368.6","0.00011489","0","1"],["104368.4","0.00248305","0","2"],["104368.3","1.55245","0","1"],["104368.1","0.02112617","0","2"],["104368","0.00001325","0","1"],["104367.8","0.03004192","0","2"],["104367.5","0.00017476","0","1"],["104367.1","0.0000204","0","2"],["104367","0.00004129","0","1"],["104366.7","0.02106026","0","2"],["104366.6","0.00723657","0","6"],["104366.4","0.00004917","0","4"],["104366.3","0.07200198","0","2"],["104366.2","0.00001014","0","1"],["104365.9","0.01053013","0","1"],["104365.8","0.79975372","0","5"],["104365.6","0.07298372","0","1"],["104365.4","0.00001","0","1"],["104365.2","0.00002245","0","2"],["104365","0.01074618","0","2"],["104364.8","0.0000442","0","3"],["104364.7","0.00023879","0","6"],["104364.1","0.02106026","0","2"],["104364","0.94264479","0","1"],["104363.8","0.12","0","1"],["104363.6","0.00067469","0","3"],["104363.2","0.02112601","0","2"],["104363.1","0.12","0","1"],["104362.7","0.00003474","0","1"],["104362.3","0.00002774","0","1"],["104361.6","0.000015","0","1"],["104361.4","0.0001581","0","1"],["104361.1","0.00010202","0","1"],["104360.7","0.01053013","0","1"],["104360.6","0.01166","0","1"],["104360","0.47777638","0","8"],["104359.9","0.00007315","0","1"],["104359.8","0.02872566","0","1"],["104359.7","3.04688562","0","2"],["104359.6","0.00001006","0","1"],["104359.4","0.00780718","0","2"],["104359.2","0.00002034","0","1"],["104359","0.00107109","0","1"],["104358.9","0.0000109","0","1"],["104358.1","0.0076","0","1"],["104357.9","0.01053013","0","1"],["104357.8","0.00276576","0","1"],["104357.6","0.00764376","0","2"],["104357.5","0.00001","0","1"],["104357.4","0.833098","0","1"],["104357.1","0.00060965","0","5"],["104356.9","0.00010228","0","1"],["104356.5","0.00173881","0","1"],["104356.4","0.02179146","0","2"],["104356.3","0.00139014","0","2"],["104356.2","0.00050052","0","1"],["104355.9","0.00026366","0","1"],["104355.8","0.00002622","0","1"],["104355.7","0.00016295","0","6"],["104355.6","0.00001834","0","1"],["104355.5","0.02119192","0","2"],["104355.4","0.01245981","0","1"],["104355.3","0.77866876","0","1"],["104355","0.00001","0","1"],["104354.3","0.0000836","0","1"],["104354.2","0.03","0","1"],["104353.9","0.00001047","0","1"],["104353.3","0.00071426","0","1"],["104353.1","0.14001347","0","2"],["104353","0.00001786","0","1"],["104352.9","0.00004457","0","2"],["104352.5","0.00225069","0","2"],["104352.4","0.00006108","0","2"],["104352.3","0.1205","0","1"],["104352.2","0.00001192","0","1"],["104351.9","0.0000148","0","1"],["104351.8","0.038","0","5"],["104351.6","0.00027555","0","2"],["104351.3","0.00041933","0","6"],["104351.2","0.0004565","0","2"],["104351","0.00024788","0","3"],["104350.8","0.00001409","0","1"],["104350.6","0.000041","0","4"],["104350.5","0.0002956","0","4"],["104350.4","0.00002874","0","1"],["104350","0.00066557","0","7"],["104349.8","0.00485003","0","5"],["104349.7","0.0138107","0","2"],["104349.6","0.00013933","0","3"],["104349.5","0.00001","0","1"],["104349.3","0.01396461","0","3"],["104348.9","0.0005829","0","5"],["104348.7","0.00002108","0","1"],["104348.5","0.02672785","0","1"],["104348.3","0.01059604","0","1"],["104348.1","0.00001628","0","1"],["104348","0.00009539","0","4"],["104347.8","0.00004913","0","1"],["104347.4","0.00002015","0","1"],["104347","0.00004795","0","2"],["104346.6","0.00002944","0","1"],["104346.5","0.02179146","0","2"],["104346.4","0.00002257","0","1"],["104346.1","0.00004967","0","1"],["104346","0.0115002","0","1"],["104345.6","0.00001","0","1"],["104345.5","0.07298372","0","1"],["104345.2","0.00002936","0","2"],["104344.9","0.00005134","0","1"],["104344.6","0.00009273","0","2"],["104344.4","0.77867979","0","2"],["104344.2","0.00031787","0","2"],["104344","0.00024924","0","1"],["104343.7","0.00004887","0","1"],["104343.6","0.00001018","0","1"],["104343.4","0.00030712","0","2"],["104343.3","0.00023233","0","3"],["104342.9","0.00004791","0","1"],["104342.8","0.00076959","0","3"],["104342.6","0.0000203","0","1"],["104342.4","0.0078311","0","2"]],"ts":"1747170428100","checksum":-1754915905,"seqId":54226324624,"prevSeqId":-1}]}
{"arg":{"channel":"books","instId":"BTC-USDT"},"action":"update","data":[{"asks":[["104450.1","1.14925573","0","23"],["104451","0.08956","0","1"],["104451.4","0.74061242","0","1"],["104451.5","0.50365786","0","6"],["104452.2","0.01976092","0","2"],["104452.3","0.05209157","0","2"],["104452.9","0.01","0","1"],["104453.5","0.29193486","0","1"],["104456.3","0.09097931","0","1"],["104456.8","0.08961595","0","1"],["104457.2","0.28609157","0","3"],["104457.6","0.00478547","0","1"],["104457.7","0.09123502","0","1"],["104458.1","0.00001505","0","1"],["104458.2","0.68841584","0","1"],["104458.3","0.00711203","0","1"],["104458.4","0.34187316","0","5"],["104458.5","0.77866876","0","1"],["104458.6","0","0","0"],["104458.9","0.02782266","0","1"],["104459","0","0","0"],["104459.1","0.05209157","0","2"],["104459.6","0.04","0","1"],["104459.7","0","0","0"],["104459.8","0.071868","0","2"],["104460","0.14881553","0","3"],["104460.1","0.44660709","0","5"],["104460.2","0.29193486","0","1"],["104461.2","0.16135111","0","1"],["104461.5","0","0","0"],["104461.8","0.17010108","0","1"],["104462.6","0","0","0"],["104462.7","0","0","0"],["104462.8","0","0","0"],["104463.3","0.28093491","0","2"],["104463.8","0","0","0"],["104464","0","0","0"],["104464.7","0","0","0"],["104464.9","0","0","0"],["104465","0.2366294","0","1"],["104465.2","0","0","0"],["104466","0.04529724","0","3"],["104466.2","0.00044","0","1"],["104466.5","0.0001303","0","1"],["104466.7","0","0","0"],["104468.1","0.28609157","0","3"],["104468.2","0.04","0","1"],["104468.5","0.00001","0","1"],["104468.7","0","0","0"],["104469.3","0.06486597","0","2"],["104469.4","0","0","0"],["104470.2","0","0","0"],["104470.7","0","0","0"],["104471.5","0.00093","0","1"],["104473.2","0.28939829","0","2"],["104473.9","0.5615115","0","2"],["104474.3","0","0","0"],["104474.7","0.005","0","1"],["104475.2","0","0","0"],["104476.7","0.00093","0","1"],["104477.4","0.093","0","3"],["104478.9","0.02393298","0","1"],["104479.9","0.02120238","0","1"],["104480.3","0.00287","0","1"],["104480.5","0.17796783","0","1"],["104481","0.002","0","2"],["104481.5","0.00287111","0","1"],["104481.7","0.00765753","0","2"],["104482","0.001","0","1"],["104482.5","0.10940111","0","2"],["104485.4","0.099","0","3"],["104485.5","0.68674781","0","2"],["104485.9","0","0","0"],["104486","0.44660783","0","2"],["104486.2","0","0","0"],["104486.3","0","0","0"],["104486.5","0","0","0"],["104487","0.000015","0","1"],["104488","0","0","0"],["104492.4","0.17796783","0","1"],["104493.6","0.05014701","0","1"],["104498.6","0","0","0"],["104499.2","0.15636069","0","2"],["104500.8","0","0","0"],["104502","0.07","0","2"],["104503","0.29499999","0","5"],["104504","0.12999999","0","2"],["104504.9","0.0108949","0","1"],["104507","0.234","0","1"],["104507.9","0.11010639","0","1"],["104508","0.000015","0","1"],["104508.1","0","0","0"],["104508.9","0","0","0"],["104509","0","0","0"],["104509.5","0.78956366","0","2"],["104509.7","0.51915349","0","1"],["104509.9","0","0","0"],["104510","0.00029006","0","2"],["104510.6","0.00047865","0","1"],["104511","0","0","0"],["104511.2","0","0","0"],["104511.3","0","0","0"],["104514.5","0.1","0","1"],["104514.8","0","0","0"],["104515.4","0","0","0"],["104516.3","0.036","0","1"],["104517.7","0.01527715","0","1"],["104522.6","0","0","0"],["104524.8","6.85980244","0","3"],["104526.9","0","0","0"],["104528.2","0","0","0"],["104529.5","0.07298372","0","1"],["104530.1","0","0","0"],["104530.9","0","0","0"],["104535.2","0","0","0"],["104536.1","0","0","0"],["104550","0.00033525","0","3"],["104550.1","0.03829524","0","1"],["104551.1","0","0","0"],["104552.1","0","0","0"],["104553.2","0","0","0"],["104553.3","0.09564","0","1"],["104557.3","0.77866876","0","1"],["104562.4","0","0","0"],["104570","0.35514057","0","4"],["104571.8","0.00001","0","1"],["104575.7","0","0","0"],["104579.7","0","0","0"],["104607.8","0.03","0","1"],["104622","0.01099598","0","1"],["104623.7","0","0","0"],["104639.3","0.00010253","0","1"],["104642.2","0.00039325","0","1"],["104649.4","0","0","0"],["104649.9","0.01076817","0","1"],["104651.3","0.00001","0","1"],["104652","0.0025","0","1"],["104652.4","0.03","0","1"]],"bids":[["104458.3","0","0","0"],["104457.8","0","0","0"],["104457.1","0","0","0"],["104455","0","0","0"],["104454.8","0","0","0"],["104454.3","0","0","0"],["104453.1","0","0","0"],["104452.2","0","0","0"],["104451.4","0","0","0"],["104450","0.08193024","0","4"],["104449.6","0","0","0"],["104448.8","0","0","0"],["104448","0.0816","0","1"],["104447.9","0.00957055","0","1"],["104446.9","0","0","0"],["104446.7","0","0","0"],["104446.3","0","0","0"],["104444.9","0","0","0"],["104444.8","0","0","0"],["104443.5","0","0","0"],["104441.7","0","0","0"],["104441.4","0.00630064","0","2"],["104441.3","0.07795519","0","1"],["104440.7","0","0","0"],["104440.3","0","0","0"],["104440.2","0","0","0"],["104439.5","0","0","0"],["104439.3","0.10066666","0","2"],["104438.7","0.03826158","0","1"],["104437.7","0","0","0"],["104437.5","0.07529366","0","4"],["104437.3","0.09991558","0","2"],["104437.2","0.09765215","0","1"],["104436.8","0.17636001","0","3"],["104436.6","0","0","0"],["104436.3","0","0","0"],["104435.7","0","0","0"],["104435.5","0","0","0"],["104435.4","0.00478601","0","1"],["104434.1","0.00005","0","1"],["104433.7","0.15587184","0","1"],["104433.5","0.00001","0","1"],["104433.1","0","0","0"],["104431.6","0.33110332","0","2"],["104431.5","0.04093967","0","2"],["104431.4","0","0","0"],["104430.3","0","0","0"],["104430","0.23021467","0","3"],["104428.8","0.033","0","1"],["104428.7","0.02508872","0","1"],["104427.7","0","0","0"],["104427.4","0.03","0","1"],["104427.3","0.292967","0","2"],["104426.8","0.00017476","0","1"],["104426.1","0.45405565","0","2"],["104425.8","0","0","0"],["104424.9","0.00479547","0","2"],["104421.7","0","0","0"],["104421","0.0000209","0","2"],["104420.7","0.15315122","0","1"],["104420.6","0","0","0"],["104420.4","0","0","0"],["104415.5","0","0","0"],["104414.8","0","0","0"],["104413.8","0.00001","0","1"],["104412.8","0","0","0"],["104411.7","0","0","0"],["104409.8","0.13880553","0","1"],["104407.4","0","0","0"],["104406.7","0","0","0"],["104406.2","0.413443","0","1"],["104406","0.00047865","0","1"],["104402.2","0.00003809","0","1"],["104399.5","0.04760103","0","1"],["104399.2","0.00287","0","1"],["104397.7","0","0","0"],["104395.5","0","0","0"],["104394.2","0.00001","0","1"],["104390","0.00069308","0","3"],["104388.4","0","0","0"],["104385.9","0.00022924","0","1"],["104384.2","0.0022","0","1"],["104383.9","0","0","0"],["104382.1","0.27779","0","1"],["104375.2","0","0","0"],["104368.3","0","0","0"],["104363.2","0.01053013","0","1"],["104361.9","0.002871","0","1"],["104361.5","0.00009629","0","1"],["104361.1","0","0","0"],["104359.3","0.01053051","0","1"],["104357.6","0.01817427","0","3"],["104357.4","0","0","0"],["104355.9","0.00313366","0","2"],["104355.5","0.01059604","0","1"],["104352.5","0.00005069","0","1"],["104349.8","0.00705003","0","6"],["104346.9","2.67","0","1"],["104345.6","0.00065079","0","2"],["104342.3","0.00002108","0","1"],["104342.1","0.00022221","0","1"],["104342","0.01059526","0","1"],["104341.6","0.0001427","0","2"],["104341.3","0.00001374","0","1"],["104341.2","0.00003833","0","1"],["104340.9","0.00023787","0","1"],["104340.8","0.000015","0","1"],["104340.4","1.55245","0","1"],["104340","0.0382158","0","10"],["104339.9","0.00053439","0","2"],["104339.6","0.00011038","0","2"],["104339.5","0.00009595","0","2"],["104339","0.00004182","0","2"],["104338.9","0.00003005","0","1"],["104338.7","0.00227746","0","14"],["104338.2","0.00027662","0","1"],["104338.1","0.00054717","0","1"],["104337.8","0.00005635","0","2"],["104337.7","0.00001","0","1"],["104337.6","0.00003583","0","1"],["104337.5","0.00001007","0","1"],["104337.4","0.00001106","0","1"],["104337.3","0.00135561","0","2"],["104336.7","0.00003678","0","1"]],"ts":"1747170428200","checksum":1373612383,"seqId":54226325735,"prevSeqId":54226324624}]}
{"arg":{"channel":"books","instId":"BTC-USDT"},"action":"update","data":[{"asks":[["104450.1","1.33933636","0","24"],["104451.3","0.35232946","0","1"],["104451.4","0.00521945","0","1"],["104451.5","0.50361001","0","5"],["104452.2","0.01914694","0","1"],["104455.4","0.02718728","0","1"],["104455.7","0.09868396","0","1"],["104456.2","0.09717528","0","1"],["104456.3","0","0","0"],["104456.8","0","0","0"],["104457.1","0.00152861","0","1"],["104457.2","0.37575598","0","4"],["104457.6","0","0","0"],["104457.7","0","0","0"],["104457.8","0.08921443","0","1"],["104458.1","0","0","0"],["104459.5","0.00478559","0","1"],["104459.8","0.071778","0","1"],["104460","0.01001","0","2"],["104460.7","0.161832","0","1"],["104461.2","0.32936262","0","2"],["104461.8","0","0","0"],["104463.3","0.31755096","0","2"],["104464.1","0.20858473","0","3"],["104464.4","0.25239345","0","1"],["104465","0","0","0"],["104465.9","0.13879864","0","1"],["104466.2","0.2715854","0","2"],["104466.7","0.27152115","0","1"],["104466.8","0","0","0"],["104470.3","0.25227785","0","1"],["104471.8","0.00478697","0","1"],["104472.5","0.10634","0","2"],["104473.2","0.32839829","0","3"],["104477.4","0.129","0","4"],["104478.9","0.02680431","0","2"],["104479.1","0.00287133","0","1"],["104479.4","0.00287122","0","1"],["104479.9","0","0","0"],["104481","0","0","0"],["104481.2","0.039","0","1"],["104481.5","0","0","0"],["104481.7","0","0","0"],["104482","0.002","0","2"],["104482.5","0.10653","0","1"],["104483","0.001","0","1"],["104485.4","0.069","0","2"],["104487.5","0","0","0"],["104491.8","0.00013981","0","1"],["104493.2","0.02120238","0","1"],["104499.2","0.15622088","0","1"],["104501.1","0.02230591","0","1"],["104502","0.22999999","0","4"],["104503","0.21499999","0","4"],["104504","0.05","0","1"],["104506.2","0.1","0","1"],["104508.3","0.05129827","0","4"],["104510.6","0","0","0"],["104514.5","0","0","0"],["104520.3","0.286","0","3"],["104524.8","0.052","0","2"],["104528.1","0.11903","0","4"],["104548.5","6.85046326","0","1"],["104554.2","0.06702","0","1"],["104639.7","0.00239325","0","1"],["104642.2","0","0","0"],["104649.1","0","0","0"],["104649.9","0","0","0"],["104650","0","0","0"],["104651.2","0","0","0"],["104651.3","0","0","0"],["104652","0","0","0"],["104652.4","0","0","0"]],"bids":[["104450","0.08202024","0","5"],["104447.9","0","0","0"],["104441.4","0","0","0"],["104441.3","0","0","0"],["104440.4","0","0","0"],["104440","0.00695171","0","7"],["104439.6","0","0","0"],["104439.5","0.06716889","0","1"],["104438.7","0","0","0"],["104438.3","0","0","0"],["104437.6","0.00030064","0","1"],["104437.4","0.00917832","0","1"],["104437.3","0","0","0"],["104437.2","0","0","0"],["104436.8","0.2840967","0","3"],["104436.7","0.18051123","0","2"],["104435.6","0.00478615","0","1"],["104435.4","0","0","0"],["104435.3","0.0892926","0","2"],["104434.7","0.09078695","0","1"],["104433.7","0.25899212","0","2"],["104433.2","0.14549931","0","1"],["104432","0","0","0"],["104431.7","0.15352668","0","1"],["104431.6","0.43839958","0","3"],["104431.5","0.10920125","0","4"],["104430.4","0.04","0","1"],["104430","0.00029006","0","2"],["104429.9","0.02761675","0","1"],["104429.7","0.071778","0","1"],["104429.4","0.25568077","0","1"],["104429.1","0.15289935","0","1"],["104427.9","0.22781362","0","2"],["104427.5","0.00478559","0","1"],["104427.3","0.063","0","2"],["104426.7","0.23859429","0","1"],["104424.9","0.00001","0","1"],["104423.7","0.24734171","0","2"],["104422.8","1.01772673","0","3"],["104417.8","0.13879864","0","1"],["104409.8","0","0","0"],["104406","0","0","0"],["104405.1","1.37963488","0","3"],["104373.8","2.4392604","0","2"],["104363.8","0","0","0"],["104363.1","0","0","0"],["104361.5","0","0","0"],["104345.6","0.00001","0","1"]],"ts":"1747170428300","checksum":-179316780,"seqId":54226326120,"prevSeqId":54226325735}]}
{"arg":{"channel":"books","instId":"BTC-USDT"},"action":"update","data":[{"asks":[["104450.1","1.11682536","0","24"],["104451.3","0.25792146","0","1"],["104451.5","0.07718029","0","3"],["104453.4","0.00152861","0","1"],["104455.7","0","0","0"],["104455.9","0.09489298","0","1"],["104456.2","0","0","0"],["104456.4","0.0991538","0","1"],["104457.1","0","0","0"],["104457.2","0.28609157","0","3"],["104457.3","0.08935762","0","1"],["104457.8","0","0","0"],["104457.9","0.00044","0","1"],["104458","0.09257509","0","1"],["104458.2","0.33454603","0","1"],["104458.4","0.33038516","0","4"],["104458.5","0","0","0"],["104460","0.78867876","0","3"],["104460.7","0","0","0"],["104460.8","0.15147636","0","1"],["104461.2","0","0","0"],["104461.4","0.31838029","0","2"],["104461.9","0.0001303","0","1"],["104463.2","0.00093","0","1"],["104463.3","0.38464547","0","2"],["104464.1","0.05209157","0","2"],["104464.2","0.14938976","0","1"],["104464.4","0","0","0"],["104464.6","0.25034065","0","1"],["104465.9","0","0","0"],["104466.2","0","0","0"],["104466.4","0.2425604","0","1"],["104466.5","0","0","0"],["104466.7","0","0","0"],["104466.9","0.2438972","0","1"],["104467.9","0.13879605","0","1"],["104468.4","0.00093","0","1"],["104470.3","0","0","0"],["104470.5","0.26731869","0","1"],["104471.5","0","0","0"],["104476.7","0","0","0"],["104478.8","0.00287133","0","1"],["104478.9","0.02393298","0","1"],["104479.1","0","0","0"],["104479.4","0","0","0"],["104481.2","0","0","0"],["104482.5","0","0","0"],["104485.4","0","0","0"],["104490.4","0.09574","0","1"],["104493.6","0.14588701","0","2"],["104499.3","1.02468933","0","2"],["104504.8","0.1","0","1"],["104506.2","0","0","0"],["104515.7","0.14352","0","1"],["104518.2","0.09568","0","1"],["104541.1","1.02406472","0","2"],["104548.5","0","0","0"],["104555.2","6.86682439","0","1"],["104567.7","0","0","0"],["104614.6","0.00090238","0","1"],["104619.9","0","0","0"],["104639.7","0","0","0"],["104639.9","0.00239325","0","1"]],"bids":[["104450","0.08522024","0","6"],["104447.9","0.00957055","0","1"],["104442.2","0.0005","0","1"],["104439.6","0.10887299","0","1"],["104439.5","0","0","0"],["104436.9","0.09924087","0","3"],["104436.8","0.59255662","0","3"],["104436.7","0","0","0"],["104435.6","0","0","0"],["104435.5","0.09336931","0","1"],["104435.3","0.0001","0","1"],["104434.9","0.09941059","0","1"],["104434.7","0","0","0"],["104433.9","0.15387679","0","1"],["104433.7","0.100141","0","1"],["104433.3","0.92184318","0","2"],["104433.2","0","0","0"],["104431.9","0.16132583","0","1"],["104431.7","0.00098","0","1"],["104431.6","0.4634883","0","4"],["104430.6","0.0000125","0","1"],["104429.6","0.25022203","0","5"],["104429.4","0","0","0"],["104429.2","0.15553375","0","1"],["104429.1","0","0","0"],["104428.7","0","0","0"],["104428.5","0.0000125","0","1"],["104427.5","0.00479809","0","2"],["104426.9","0.43237276","0","2"],["104426.7","0","0","0"],["104423.9","0.24769288","0","1"],["104423.7","0.00004788","0","1"],["104423","0.24809544","0","4"],["104422.8","0.77961723","0","2"],["104422.3","0.0000125","0","1"],["104418.2","0.14832025","0","2"],["104417.8","0","0","0"],["104417.2","0","0","0"],["104399.5","0","0","0"],["104378","0.555289","0","1"],["104367.1","0.00005004","0","3"],["104337.4","0","0","0"],["104337.3","0","0","0"],["104336.7","0","0","0"]],"ts":"1747170428400","checksum":-1790047063,"seqId":54226326315,"prevSeqId":54226326120}]}
{"arg":{"channel":"books","instId":"BTC-USDT"},"action":"update","data":[{"asks":[["104450.1","1.09209675","0","22"],["104451.3","0.18788654","0","1"],["104453.2","0.02782417","0","1"],["104453.4","0","0","0"],["104455.9","0","0","0"],["104456.4","0","0","0"],["104457.1","0.00165891","0","2"],["104457.3","0","0","0"],["104457.8","0.09133019","0","1"],["104458","0","0","0"],["104458.2","0.49268579","0","2"],["104458.3","0.10745935","0","2"],["104459.2","0.0918344","0","1"],["104459.9","0.09438537","0","1"],["104460","0.01001","0","2"],["104460.8","0","0","0"],["104461.4","0","0","0"],["104461.9","0","0","0"],["104462.7","0.15549453","0","1"],["104463.3","0.52119058","0","4"],["104464.2","0","0","0"],["104464.6","0","0","0"],["104466.1","0.1592733","0","1"],["104466.4","0","0","0"],["104466.5","0.25348098","0","1"],["104466.9","0","0","0"],["104467.9","0","0","0"],["104468.3","0.25759447","0","1"],["104468.8","0.25566497","0","1"],["104470","0.13908281","0","3"],["104470.5","0","0","0"],["104472.4","0.2331616","0","1"],["104474.1","0.10744557","0","3"],["104649.1","0.77866876","0","1"],["104649.9","0.01076817","0","1"],["104650","0.00080639","0","3"]],"bids":[["104450","0.20472024","0","7"],["104447.9","0","0","0"],["104443","0.03003295","0","1"],["104440.7","0.00030064","0","1"],["104440.6","0.18490164","0","1"],["104440.5","0.19242972","0","1"],["104439.6","0.00957132","0","1"],["104438.8","0.09046625","0","1"],["104438.7","0.09387142","0","1"],["104438","0.00478602","0","1"],["104437.6","0","0","0"],["104437.5","0.04236132","0","3"],["104437.4","0.10953844","0","2"],["104436.9","0.00098","0","1"],["104436.8","0.43856503","0","3"],["104435.8","0.15576115","0","1"],["104435.5","0","0","0"],["104435.2","0.15433814","0","1"],["104434.9","0","0","0"],["104433.9","0","0","0"],["104433.8","0.16220987","0","1"],["104433.3","0.77866876","0","1"],["104431.9","0","0","0"],["104431.5","0.35444817","0","5"],["104431.1","0.14623987","0","1"],["104429.6","0.00122607","0","4"],["104429.2","0","0","0"],["104428.8","0.28738805","0","2"],["104427.9","0.17796783","0","1"],["104426.9","0.17796783","0","1"],["104425.8","0.25887548","0","1"],["104424.9","0.24805043","0","2"],["104423.9","0","0","0"],["104423","0.00031959","0","3"],["104420.8","0.13879275","0","1"],["104418.2","0.0095242","0","1"],["104417.2","0.00033","0","1"],["104367.1","0.0000204","0","2"],["104362.8","0.00002964","0","1"],["104351.4","0.00009814","0","1"],["104338.9","0","0","0"],["104338.7","0","0","0"],["104338.2","0","0","0"],["104338.1","0","0","0"],["104337.8","0","0","0"],["104337.7","0","0","0"],["104337.6","0","0","0"],["104337.5","0","0","0"]],"ts":"1747170428500","checksum":2135673413,"seqId":54226326477,"prevSeqId":54226326315}]}
{"arg":{"channel":"books","instId":"BTC-USDT"},"action":"update","data":[{"asks":[["104482.6","0","0","0"],["104487.8","0","0","0"],["104536.6","0","0","0"],["104545.1","6.86682439","0","1"],["104555.2","0","0","0"],["104651.2","0.03","0","1"],["104651.3","0.00001","0","1"],["104652","0.0025","0","1"]],"bids":[["104450","0.20484288","0","8"],["104439.4","0.00478596","0","1"],["104438","0","0","0"],["104426.6","0.00711203","0","1"],["104426.5","0.00191","0","1"],["104421.3","0.00191","0","1"],["104417.2","0","0","0"],["104408","0.00478697","0","1"],["104339.6","0","0","0"],["104339.5","0","0","0"],["104339","0","0","0"]],"ts":"1747170428600","checksum":-609760336,"seqId":54226326495,"prevSeqId":54226326477}]}
{"arg":{"channel":"books","instId":"BTC-USDT"},"action":"update","data":[{"asks":[["104451.3","0.30559976","0","2"],["104456.2","0.09973159","0","1"],["104456.7","0.10197218","0","1"],["104457.6","0.09691313","0","1"],["104457.8","0","0","0"],["104458.2","0.81431121","0","2"],["104458.3","0.00711203","0","1"],["104459.2","0","0","0"],["104459.9","0","0","0"],["104460","0.78867876","0","3"],["104461.1","0.15141511","0","1"],["104461.7","0.32510493","0","2"],["104462.7","0","0","0"],["104463.3","0.3601863","0","2"],["104464.5","0.16552574","0","2"],["104464.9","0.25867007","0","1"],["104466.1","0","0","0"],["104466.5","0","0","0"],["104466.7","0.23885749","0","1"],["104467.2","0.24974514","0","1"],["104468.3","0","0","0"],["104468.8","0","0","0"],["104470.7","0.26162466","0","1"],["104472.4","0","0","0"],["104473.6","0.00191","0","1"],["104478.8","0.00478133","0","2"],["104484.7","0","0","0"],["104502.3","0.00047869","0","1"],["104510","0.00028006","0","1"],["104521.4","6.86682439","0","1"],["104529","0.0121944","0","1"],["104545.1","0","0","0"],["104651.3","0","0","0"],["104652","0","0","0"]],"bids":[["104450","0.08534288","0","7"],["104440.6","0.12685978","0","1"],["104438.8","0","0","0"],["104438.7","0","0","0"],["104437.4","0.00917832","0","1"],["104437.2","0.09528902","0","1"],["104437.1","0.09178616","0","1"],["104436.8","0.49620347","0","3"],["104435.8","0","0","0"],["104435.7","0.12226658","0","2"],["104435.2","0.09199529","0","1"],["104434.2","0.16938986","0","2"],["104433.8","0","0","0"],["104433.6","0.15025659","0","1"],["104432.2","0.15482957","0","1"],["104431.6","0.43839958","0","3"],["104431.5","0.10920125","0","4"],["104431.1","0","0","0"],["104429.9","0.26902198","0","2"],["104429.5","0.3588835","0","2"],["104428.8","0.033","0","1"],["104427.2","0.26921781","0","1"],["104425.8","0","0","0"],["104424.9","0.00001","0","1"],["104424.2","0.24411627","0","1"],["104423.2","0.2665261","0","1"],["104422.9","0","0","0"],["104339.9","0","0","0"]],"ts":"1747170428700","checksum":-872168466,"seqId":54226326571,"prevSeqId":54226326495}]}
{"arg":{"channel":"books","instId":"BTC-USDT"},"action":"update","data":[{"asks":[["104451.4","0.03304412","0","2"],["104456.1","0.09974277","0","1"],["104456.2","0","0","0"],["104456.6","0.09513148","0","1"],["104456.7","0","0","0"],["104461.6","0.31885999","0","2"],["104461.7","0","0","0"],["104463.3","0.21360551","0","1"],["104466.6","0.23803471","0","1"],["104466.7","0","0","0"],["104467.1","0.2505539","0","1"],["104467.2","0","0","0"],["104511.4","0","0","0"],["104513.3","0.09568","0","1"],["104516.6","0.11481","0","1"],["104521.3","0.01053134","0","1"],["104524.3","0.02106268","0","2"],["104524.4","0.19134","0","1"],["104525.8","0.01053134","0","1"],["104528","0.01053134","0","1"],["104529.8","0.01053134","0","1"],["104534.3","0.02106268","0","2"],["104536.3","0.01053134","0","1"],["104538.3","0.01053134","0","1"],["104539.9","0.01053134","0","1"],["104542.5","0.01053134","0","1"],["104545.4","0.0107061","0","2"],["104547.4","0.01053134","0","1"],["104553.3","0","0","0"],["104556.6","0","0","0"],["104561.7","0","0","0"],["104564.2","0","0","0"],["104587.4","0","0","0"],["104646.7","0","0","0"],["104646.9","0","0","0"],["104647.3","0","0","0"],["104647.5","0","0","0"],["104649.1","0","0","0"],["104649.9","0","0","0"],["104650","0","0","0"],["104651.2","0","0","0"]],"bids":[["104450","0.08214288","0","6"],["104441.1","0.03005368","0","2"],["104440.1","0.00478596","0","1"],["104439.4","0","0","0"],["104438","0.04836347","0","1"],["104437.2","0","0","0"],["104437.1","0.18397297","0","2"],["104435.2","0","0","0"],["104435.1","0.09229945","0","1"],["104434.2","0.000015","0","1"],["104434.1","0.16456334","0","2"],["104432.2","0","0","0"],["104432.1","0.15864923","0","1"],["104427.2","0","0","0"],["104424.2","0","0","0"],["104424.1","0.24203514","0","1"],["104404.6","0.00003","0","1"],["104397.7","0.00047869","0","1"],["104397.4","0.0494011","0","1"],["104379.4","0.00952827","0","1"],["104369.4","0.01054134","0","2"],["104368.1","0.03165751","0","3"],["104366.7","0.0315916","0","3"],["104365.1","0.01053134","0","1"],["104362","0.01053134","0","1"],["104360.8","0.01053134","0","1"],["104358.2","0.01053134","0","1"],["104341.6","0","0","0"],["104341.3","0","0","0"],["104341.2","0","0","0"],["104340.9","0","0","0"],["104340.8","0","0","0"],["104340.4","0","0","0"],["104340","0","0","0"]],"ts":"1747170428800","checksum":1680466644,"seqId":54226326641,"prevSeqId":54226326571}]}
{"arg":{"channel":"books","instId":"BTC-USDT"},"action":"update","data":[{"asks":[["104456.1","0","0","0"],["104456.2","0.1021177","0","1"],["104456.6","0","0","0"],["104456.7","0.10147347","0","1"],["104458.2","0.71685648","0","1"],["104458.3","0.09592003","0","2"],["104461.6","0","0","0"],["104461.7","0.33524256","0","2"],["104466.6","0","0","0"],["104466.7","0.25715371","0","1"],["104467.1","0","0","0"],["104467.2","0.25843711","0","1"],["104470.7","0","0","0"],["104470.8","0.25656634","0","1"],["104563.8","0.12001","0","2"]],"bids":[["104450","0.08534288","0","7"],["104437.2","0.09649104","0","1"],["104437.1","0.09178616","0","1"],["104435.8","0.09860463","0","1"],["104435.7","0","0","0"],["104435.2","0.09361848","0","1"],["104435.1","0","0","0"],["104434.2","0.17010341","0","2"],["104434.1","0.00005","0","1"],["104432.2","0.1680467","0","1"],["104432.1","0","0","0"],["104427.2","0.26684743","0","1"],["104424.2","0.27299566","0","1"],["104424.1","0","0","0"],["104423.3","0.25972923","0","1"],["104423.2","0","0","0"],["104411.2","0.00010524","0","1"],["104342.1","0","0","0"],["104342","0","0","0"]],"ts":"1747170428900","checksum":222683954,"seqId":54226326690,"prevSeqId":54226326641}]}
{"arg":{"channel":"books","instId":"BTC-USDT"},"action":"update","data":[{"asks":[["104463.3","0.35525515","0","2"],["104587.8","0","0","0"],["104646.7","0.00094804","0","1"]],"bids":[["104435.8","0.12369335","0","2"],["104411.2","0","0","0"],["104367.7","0.00013602","0","1"],["104367.6","0.00015448","0","1"],["104342.3","0","0","0"]],"ts":"1747170429000","checksum":222683954,"seqId":54226326702,"prevSeqId":54226326690}]}
{"arg":{"channel":"books","instId":"BTC-USDT"},"action":"update","data":[{"asks":[["104450.1","1.09266341","0","23"],["104457.6","0","0","0"],["104457.7","0.09251677","0","1"],["104460.1","0.44604043","0","4"],["104461.1","0","0","0"],["104461.2","0.16197315","0","1"],["104462.7","0.02392578","0","1"],["104468.6","0.00056666","0","1"],["104474.2","0","0","0"],["104497","1","0","1"],["104644.5","0","0","0"],["104646.7","0","0","0"]],"bids":[["104450","0.08749011","0","9"],["104440.7","0.00508659","0","2"],["104440.1","0","0","0"],["104437.2","0.18242723","0","2"],["104437.1","0","0","0"],["104433.7","0.26125482","0","2"],["104433.6","0","0","0"],["104426.2","0.00001731","0","1"],["104412.1","0","0","0"],["104406.9","0.00056666","0","1"],["104389.9","0.00004789","0","1"],["104388.4","0.00056666","0","1"],["104342.3","0.00002108","0","1"]],"ts":"1747170429100","checksum":600494761,"seqId":54226326726,"prevSeqId":54226326702}]}
{"arg":{"channel":"books","instId":"BTC-USDT"},"action":"update","data":[{"asks":[["104450.1","1.33266341","0","24"],["104457.6","0.09691728","0","1"],["104457.7","0","0","0"],["104458.4","0.09038516","0","3"],["104459.5","0","0","0"],["104460","0.77867876","0","2"],["104461.1","0.15812977","0","2"],["104461.2","0","0","0"],["104467.4","0.00478697","0","1"],["104477.3","0","0","0"],["104495.1","0.73330539","0","1"],["104528","0.13291966","0","2"],["104557.2","0.32270964","0","2"],["104609.6","0.01148547","0","2"],["104614.6","0","0","0"],["104644.5","0.00001501","0","1"],["104646.7","0.00094804","0","1"]],"bids":[["104450","0.08429011","0","8"],["104440.7","0.00030064","0","1"],["104440.1","0.00478595","0","1"],["104437.2","0.09649104","0","1"],["104437.1","0.09785283","0","1"],["104433.7","0.100141","0","1"],["104433.6","0.15769195","0","1"],["104428","0.00478574","0","1"],["104427.5","0.0000125","0","1"],["104405.2","0.47625651","0","1"],["104373.9","0.94550733","0","1"],["104373.2","0.01053013","0","1"],["104343.3","0","0","0"],["104342.9","0","0","0"],["104342.8","0","0","0"],["104342.6","0","0","0"],["104342.4","0","0","0"],["104342.3","0","0","0"]],"ts":"1747170429200","checksum":-158330737,"seqId":54226326761,"prevSeqId":54226326726}]}
{"arg":{"channel":"books","instId":"BTC-USDT"},"action":"update","data":[{"asks":[["104457.6","0","0","0"],["104457.7","0.08728048","0","1"],["104461.1","0.00478574","0","1"],["104461.2","0.16283555","0","1"],["104510","0.00029006","0","2"],["104540","1.00221843","0","5"],["104646.7","0","0","0"]],"bids":[["104450","0.085364","0","9"],["104448","0.08265484","0","2"],["104440.6","0.13164573","0","2"],["104440.1","0","0","0"],["104437.2","0.19463632","0","2"],["104437.1","0","0","0"],["104433.7","0.26288031","0","2"],["104433.6","0","0","0"],["104414.7","0.00952512","0","1"],["104353.1","0.00001347","0","1"],["104343.3","0.00023233","0","3"],["104342.9","0.00004791","0","1"],["104342.8","0.00076959","0","3"]],"ts":"1747170429300","checksum":329195093,"seqId":54226326782,"prevSeqId":54226326761}]}
{"arg":{"channel":"books","instId":"BTC-USDT"},"action":"update","data":[{"asks":[],"bids":[["104396.6","0.68537579","0","2"],["104391.7","0.60049","0","1"],["104371.2","0.00954256","0","2"],["104342.8","0","0","0"]],"ts":"1747170429400","checksum":329195093,"seqId":54226326785,"prevSeqId":54226326782}]}
{"arg":{"channel":"books","instId":"BTC-USDT"},"action":"update","data":[{"asks":[],"bids":[["104440.6","0.12685978","0","1"],["104440.1","0.00478595","0","1"],["104418.2","0","0","0"],["104374.7","0.00956416","0","2"]],"ts":"1747170429500","checksum":-984587884,"seqId":54226326790,"prevSeqId":54226326785}]}
{"arg":{"channel":"books","instId":"BTC-USDT"},"action":"update","data":[{"asks":[["104456.1","0.09761261","0","1"],["104456.2","0","0","0"],["104456.6","0.09840102","0","1"],["104456.7","0","0","0"],["104457.6","0.08725815","0","1"],["104457.7","0","0","0"],["104458.2","0.8107958","0","2"],["104458.3","0.00711203","0","1"],["104460","0.77895882","0","3"],["104461.1","0.15230088","0","2"],["104461.2","0","0","0"],["104461.6","0.32028077","0","2"],["104461.7","0","0","0"],["104463.3","0.3599405","0","2"],["104464.4","0.1554766","0","1"],["104464.5","0.00001","0","1"],["104464.8","0.23994247","0","1"],["104464.9","0","0","0"],["104466.6","0.25178312","0","1"],["104466.7","0","0","0"],["104467.1","0.25667756","0","1"],["104467.2","0","0","0"],["104470.7","0.24960758","0","1"],["104470.8","0","0","0"],["104500","0.00224861","0","4"]],"bids":[["104450","0.079274","0","6"],["104437.2","0","0","0"],["104437.1","0.18793948","0","2"],["104436.8","0.49738161","0","3"],["104435.8","0.02508872","0","1"],["104435.7","0.0922218","0","1"],["104435.2","0","0","0"],["104435.1","0.09400114","0","1"],["104434.2","0.000015","0","1"],["104434.1","0.16836069","0","2"],["104433.7","0.100141","0","1"],["104433.6","0.16192688","0","1"],["104432.2","0","0","0"],["104432.1","0.1511008","0","1"],["104429.9","0.02761675","0","1"],["104429.8","0.23744307","0","1"],["104429.5","0.19242972","0","1"],["104429.4","0.14624898","0","1"],["104427.2","0","0","0"],["104427.1","0.25462991","0","1"],["104424.2","0","0","0"],["104424.1","0.26634336","0","1"],["104423.3","0","0","0"],["104423.2","0.24383183","0","1"],["104343.6","0","0","0"],["104343.4","0","0","0"],["104343.3","0","0","0"],["104342.9","0","0","0"]],"ts":"1747170429600","checksum":-580776698,"seqId":54226326859,"prevSeqId":54226326790}]}
{"arg":{"channel":"books","instId":"BTC-USDT"},"action":"update","data":[{"asks":[["104457.7","0.03619102","0","1"],["104466","0.00910622","0","2"],["104644.5","0","0","0"]],"bids":[["104440.6","0.13164573","0","2"],["104440.1","0","0","0"],["104356.5","0","0","0"],["104346","0","0","0"],["104343.6","0.00001018","0","1"],["104343.4","0.00030712","0","2"],["104343.3","0.00023233","0","3"]],"ts":"1747170429700","checksum":1441904978,"seqId":54226326873,"prevSeqId":54226326859}]}
{"arg":{"channel":"books","instId":"BTC-USDT"},"action":"update","data":[{"asks":[["104455.9","0.09561093","0","1"],["104456.1","0","0","0"],["104456.4","0.09766483","0","1"],["104456.6","0","0","0"],["104457.4","0.08907729","0","1"],["104457.6","0","0","0"],["104458","0.09415844","0","1"],["104458.2","0.71685648","0","1"],["104458.3","0","0","0"],["104460.9","0.14242393","0","1"],["104461.1","0","0","0"],["104461.4","0.33372892","0","2"],["104461.6","0","0","0"],["104462.6","0.00478574","0","1"],["104463.3","0.24053895","0","1"],["104464.3","0.15751896","0","1"],["104464.4","0","0","0"],["104464.6","0.25289173","0","1"],["104464.8","0","0","0"],["104466.3","0.00711203","0","1"],["104466.4","0.23863905","0","1"],["104466.6","0","0","0"],["104466.9","0.27067408","0","1"],["104467.1","0","0","0"],["104467.9","0.13879557","0","1"],["104470","0.00029006","0","2"],["104470.5","0.24271119","0","1"],["104470.7","0","0","0"],["104642.8","0","0","0"],["104643.3","0","0","0"],["104643.8","0","0","0"]],"bids":[["104440.7","0","0","0"],["104440.6","0","0","0"],["104440.5","0","0","0"],["104440.1","0.00478595","0","1"],["104438.5","0.00030064","0","1"],["104437.1","0","0","0"],["104436.9","0.17973524","0","3"],["104436.8","0.2949015","0","3"],["104435.8","0","0","0"],["104435.7","0","0","0"],["104435.5","0.09800078","0","1"],["104435.1","0","0","0"],["104434.9","0.08976722","0","1"],["104434.1","0.00005","0","1"],["104433.9","0.1608774","0","1"],["104433.6","0","0","0"],["104433.4","0.16209795","0","1"],["104433.3","0","0","0"],["104432.1","0","0","0"],["104431.9","0.16058766","0","1"],["104431","0","0","0"],["104430.5","0.00478574","0","1"],["104429.8","0","0","0"],["104429.6","0.2386083","0","5"],["104429.4","0","0","0"],["104429.3","0.16644552","0","1"],["104428","0","0","0"],["104427.1","0","0","0"],["104426.9","0.44972918","0","2"],["104424.1","0","0","0"],["104423.9","0.27031896","0","1"],["104423.2","0","0","0"],["104423","0.26451286","0","4"],["104420.8","0","0","0"],["104418.2","0.13879557","0","1"],["104414.8","0.01411892","0","1"],["104342.9","0.00004791","0","1"],["104342.8","0.00076959","0","3"],["104342.6","0.0000203","0","1"],["104342.4","0.0078311","0","2"],["104342.3","0.00002108","0","1"],["104342.1","0.00022221","0","1"]],"ts":"1747170430000","checksum":80650000,"seqId":54226326982,"prevSeqId":54226326873}]}
{"arg":{"channel":"books","instId":"BTC-USDT"},"action":"update","data":[{"asks":[["104455.8","0.09234971","0","1"],["104455.9","0","0","0"],["104456.3","0.09369676","0","1"],["104456.4","0","0","0"],["104457.2","0.37768296","0","4"],["104457.4","0","0","0"],["104457.8","0.09181179","0","1"],["104458","0","0","0"],["104460.6","0.00001","0","1"],["104460.7","0.16165042","0","1"],["104460.9","0","0","0"],["104461.3","0.30867541","0","2"],["104461.4","0","0","0"],["104461.9","0.00478574","0","1"],["104462.6","0","0","0"],["104463.3","0.38165713","0","2"],["104464.1","0.21921736","0","3"],["104464.3","0","0","0"],["104464.5","0.22869191","0","2"],["104464.6","0","0","0"],["104466.3","0.24504436","0","2"],["104466.4","0","0","0"],["104466.8","0.24873934","0","1"],["104466.9","0","0","0"],["104470.3","0.2370962","0","1"],["104470.5","0","0","0"],["104478.3","0.00287133","0","1"],["104478.8","0.00191","0","1"],["104488.4","0.00234987","0","3"],["104491.8","0","0","0"],["104642.8","0.0288065","0","3"],["104643.3","0.00124092","0","2"],["104643.8","0.07298372","0","1"]],"bids":[["104443","0","0","0"],["104440.1","0","0","0"],["104439.4","0.06691822","0","2"],["104438.5","0","0","0"],["104438.1","0.00030064","0","1"],["104436.9","0.00098","0","1"],["104436.8","0.40044423","0","4"],["104436.7","0.09523928","0","1"],["104435.5","0","0","0"],["104435.3","0.09326278","0","2"],["104434.9","0","0","0"],["104434.8","0.09527897","0","1"],["104433.9","0","0","0"],["104433.8","0.16945025","0","1"],["104433.7","0.12522972","0","2"],["104433.4","0","0","0"],["104433.2","0.14997757","0","1"],["104431.9","0","0","0"],["104431.8","0.1635914","0","1"],["104430.5","0","0","0"],["104429.8","0.05022941","0","2"],["104429.6","0.00122607","0","4"],["104429.5","0.43423779","0","2"],["104429.3","0","0","0"],["104429.1","0.16118985","0","1"],["104426.9","0.17796783","0","1"],["104426.8","0.25911196","0","2"],["104423.9","0","0","0"],["104423.8","0.25726657","0","1"],["104423","0.00031959","0","3"],["104422.8","1.01856921","0","3"],["104421","0.06024445","0","3"],["104406.9","0","0","0"],["104406.3","0.00056666","0","1"],["104388.4","0","0","0"],["104387.7","0.00056666","0","1"],["104349.1","0.00173881","0","1"]],"ts":"1747170430100","checksum":-911002063,"seqId":54226327166,"prevSeqId":54226326982}]}
{"arg":{"channel":"books","instId":"BTC-USDT"},"action":"update","data":[{"asks":[["104450.1","1.09266341","0","23"],["104451.4","0.00521945","0","1"],["104453.4","0.00152861","0","1"],["104454.4","0.03089194","0","1"],["104455.8","0","0","0"],["104456","0.1004056","0","1"],["104456.3","0","0","0"],["104456.5","0.10202275","0","1"],["104457.1","0.0001303","0","1"],["104457.2","0.28609157","0","3"],["104457.4","0.09051488","0","1"],["104457.8","0","0","0"],["104460.7","0","0","0"],["104460.9","0.15149048","0","1"],["104461.3","0","0","0"],["104461.5","0.32563369","0","2"],["104463.3","0.09273524","0","1"],["104464.1","0.05209157","0","2"],["104464.3","0.15940843","0","1"],["104464.5","0.00001","0","1"],["104464.7","0.24105094","0","1"],["104466.3","0.00711203","0","1"],["104466.5","0.23932486","0","1"],["104466.8","0","0","0"],["104467","0.23939386","0","1"],["104467.9","0","0","0"],["104469.2","0.13879317","0","1"],["104470.3","0","0","0"],["104498.8","0.02872184","0","1"],["104499.2","0.44477634","0","2"],["104541","1.49585315","0","1"],["104570.9","0.00001","0","1"],["104609.5","0.00088871","0","1"],["104609.6","0.01059613","0","1"],["104639.9","0","0","0"],["104640","0","0","0"],["104641.3","0","0","0"],["104642.5","0","0","0"],["104642.7","0","0","0"],["104642.8","0","0","0"],["104643.3","0","0","0"],["104643.8","0","0","0"]],"bids":[["104450","0.082474","0","7"],["104442.8","0.03044483","0","1"],["104439.4","0.07307841","0","3"],["104438.1","0","0","0"],["104438","0.00030064","0","1"],["104437","0.09717115","0","1"],["104436.9","0.09390818","0","2"],["104436.8","0.53142997","0","2"],["104436.7","0","0","0"],["104436.5","0.04413889","0","1"],["104435.3","0.0001","0","1"],["104435","0.09242036","0","1"],["104434.8","0","0","0"],["104434","0.14973575","0","1"],["104433.8","0","0","0"],["104433.4","0.15236577","0","1"],["104433.3","0.77866876","0","1"],["104433.2","0","0","0"],["104432","0.14923252","0","1"],["104431.8","0","0","0"],["104431.6","0.33110332","0","2"],["104429.8","0.00478574","0","1"],["104429.7","0.30206134","0","2"],["104429.5","0.19242972","0","1"],["104429.3","0.15315033","0","1"],["104429.1","0","0","0"],["104427","0.24682614","0","1"],["104426.8","0.00017476","0","1"],["104424","0.2556161","0","2"],["104423.8","0","0","0"],["104422.8","0.77961723","0","2"],["104421.1","0.13879408","0","1"],["104418.2","0","0","0"],["104399.3","0.45519565","0","2"],["104342.3","0","0","0"],["104342.1","0","0","0"]],"ts":"1747170430200","checksum":-1895542509,"seqId":54226327270,"prevSeqId":54226327166}]}
{"arg":{"channel":"books","instId":"BTC-USDT"},"action":"update","data":[{"asks":[["104458.1","0.08798903","0","1"],["104463.3","0.34489676","0","2"],["104469.2","0","0","0"],["104470","0.13908286","0","3"],["104470.6","0.26502917","0","1"],["104639.3","0","0","0"]],"bids":[["104439.6","0.01435727","0","2"],["104439.5","0.00030064","0","1"],["104439.4","0.09468065","0","1"],["104438","0","0","0"],["104435.6","0.08850835","0","1"],["104431.6","0.48367839","0","3"],["104423.1","0.26161461","0","1"],["104421.1","0.13879419","0","1"],["104342.6","0","0","0"],["104342.4","0","0","0"]],"ts":"1747170430300","checksum":-1529982199,"seqId":54226327305,"prevSeqId":54226327270}]}
{"arg":{"channel":"books","instId":"BTC-USDT"},"action":"update","data":[{"asks":[["104453.4","0","0","0"],["104456","0","0","0"],["104456.1","0.09066724","0","1"],["104456.5","0","0","0"],["104456.6","0.10103964","0","1"],["104457","0.0001303","0","1"],["104457.1","0.00152861","0","1"],["104457.4","0","0","0"],["104457.6","0.08965395","0","1"],["104458.1","0","0","0"],["104458.2","0.8141917","0","2"],["104460.9","0","0","0"],["104461.1","0.15388625","0","1"],["104461.5","0","0","0"],["104461.6","0.31670554","0","2"],["104463.3","0.34320322","0","2"],["104464.3","0","0","0"],["104464.5","0.15036874","0","2"],["104464.7","0","0","0"],["104464.9","0.23106618","0","1"],["104466.5","0","0","0"],["104466.6","0.2509981","0","1"],["104467","0","0","0"],["104467.1","0.24110993","0","1"],["104469.2","0.13879437","0","1"],["104470","0.00029006","0","2"],["104470.6","0","0","0"],["104470.7","0.26742321","0","1"],["104505","0.47953102","0","2"],["104505.7","0","0","0"],["104537","0","0","0"],["104557.2","0.32280182","0","3"],["104639.3","0.00010253","0","1"],["104639.7","0.00239325","0","1"],["104640","0.00220843","0","3"]],"bids":[["104450","0.079274","0","6"],["104444.5","0.03044435","0","1"],["104439.4","0.09513821","0","2"],["104437.1","0.19184701","0","2"],["104437","0","0","0"],["104436.9","0.00098","0","1"],["104436.8","0.49546776","0","3"],["104436.5","0","0","0"],["104435.7","0.09433529","0","1"],["104435.6","0","0","0"],["104435.1","0.09292527","0","1"],["104435","0","0","0"],["104434.1","0.15949555","0","2"],["104434","0","0","0"],["104433.6","0.14752652","0","1"],["104433.4","0","0","0"],["104432.1","0.16694916","0","1"],["104432","0","0","0"],["104431.6","0.49628305","0","3"],["104429.9","0.26877718","0","2"],["104429.7","0.071778","0","1"],["104429.5","0.35714391","0","2"],["104429.3","0","0","0"],["104427.1","0.2664007","0","1"],["104427","0","0","0"],["104424.1","0.26143782","0","1"],["104424","0.000015","0","1"],["104423.2","0.2658919","0","1"],["104423.1","0","0","0"],["104421.1","0.13879437","0","1"],["104405.2","0","0","0"],["104405.1","0.00003566","0","2"],["104373.9","0","0","0"],["104373.8","0.00003133","0","1"],["104362.8","0","0","0"],["104362.1","0.00002964","0","1"],["104342.6","0.0000203","0","1"],["104342.4","0.0078311","0","2"],["104342.3","0.00002108","0","1"]],"ts":"1747170430400","checksum":-892525771,"seqId":54226327396,"prevSeqId":54226327305}]}
{"arg":{"channel":"books","instId":"BTC-USDT"},"action":"update","data":[{"asks":[["104456.4","0.0001303","0","1"],["104457","0","0","0"],["104461","0.00478574","0","1"],["104461.9","0","0","0"],["104467.9","0.13879492","0","1"],["104469.2","0","0","0"],["104495.9","1.36428081","0","1"],["104527.2","2.42273252","0","1"],["104639.7","0","0","0"],["104640","0","0","0"]],"bids":[["104439.6","0.00957132","0","1"],["104438.5","0.00478592","0","1"],["104433.7","0.02508872","0","1"],["104429.8","0","0","0"],["104429.7","0","0","0"],["104428.9","0.00479574","0","2"],["104421.1","0","0","0"],["104418.2","0.13879492","0","1"],["104407.4","1.38260245","0","1"],["104376","2.46161764","0","2"]],"ts":"1747170430500","checksum":2147015280,"seqId":54226327418,"prevSeqId":54226327396}]}
{"arg":{"channel":"books","instId":"BTC-USDT"},"action":"update","data":[{"asks":[["104456.4","0","0","0"],["104457.1","0.00165891","0","2"],["104467.9","0.13879496","0","1"],["104557.2","0.32270964","0","2"],["104558.9","0.00011205","0","1"],["104609.5","0","0","0"],["104609.7","0.01148667","0","2"],["104639.7","0.00239325","0","1"]],"bids":[["104439.5","0.00508663","0","2"],["104438.5","0","0","0"],["104429.6","0.10136707","0","5"],["104426.2","0.07179731","0","2"],["104420.8","0.13879472","0","1"],["104418.2","0","0","0"],["104342.1","0.00022221","0","1"]],"ts":"1747170430600","checksum":-1061984590,"seqId":54226327453,"prevSeqId":54226327418}]}
{"arg":{"channel":"books","instId":"BTC-USDT"},"action":"update","data":[{"asks":[["104461","0","0","0"],["104463.1","0.00478574","0","1"],["104467.9","0","0","0"],["104469.2","0.13879404","0","1"]],"bids":[["104430.5","0.00478574","0","1"],["104428.9","0.00001","0","1"],["104421.1","0.13879404","0","1"],["104420.8","0","0","0"],["104342.1","0","0","0"]],"ts":"1747170430700","checksum":-1061984590,"seqId":54226327473,"prevSeqId":54226327453}]}
{"arg":{"channel":"books","instId":"BTC-USDT"},"action":"update","data":[{"asks":[["104450.1","1.07666341","0","22"],["104451.5","0.06118029","0","2"],["104452.3","0.03609157","0","1"],["104453.2","0","0","0"],["104456.1","0.03089144","0","1"],["104456.6","0","0","0"],["104457.6","0","0","0"],["104458.2","0.71685648","0","1"],["104461.1","0","0","0"],["104461.6","0","0","0"],["104462","0.00478574","0","1"],["104463.1","0","0","0"],["104463.3","0.27562705","0","2"],["104464.5","0.00001","0","1"],["104464.9","0","0","0"],["104466.6","0","0","0"],["104467.1","0","0","0"],["104469.2","0","0","0"],["104470.7","0","0","0"],["104471.8","0.14357781","0","2"],["104640","0.00220843","0","3"],["104641.3","0.03","0","1"],["104642.5","0.0003067","0","1"],["104642.7","0.03","0","1"],["104642.8","0.0288065","0","3"],["104643.3","0.00124092","0","2"],["104643.8","0.07298372","0","1"],["104644.5","0.00001501","0","1"],["104646.7","0.00094804","0","1"],["104646.9","0.04449518","0","2"]],"bids":[["104450","0.082474","0","7"],["104440.1","0.00478587","0","1"],["104439.5","0.00030064","0","1"],["104439.4","0.15253656","0","2"],["104437.1","0","0","0"],["104436.8","0.48899755","0","3"],["104435.7","0","0","0"],["104435.1","0","0","0"],["104434.1","0.00005","0","1"],["104433.6","0","0","0"],["104432.1","0","0","0"],["104430.5","0","0","0"],["104429.9","0.02761675","0","1"],["104429.5","0.19242972","0","1"],["104429","0.00478574","0","1"],["104427.1","0","0","0"],["104424.1","0","0","0"],["104423.7","0.13883872","0","2"],["104423.2","0","0","0"],["104421.1","0","0","0"],["104342.1","0.00022221","0","1"],["104342","0.01059526","0","1"],["104341.6","0.0001427","0","2"],["104341.3","0.00001374","0","1"],["104341.2","0.00003833","0","1"],["104340.9","0.00023787","0","1"],["104340.8","0.000015","0","1"],["104340.4","1.55245","0","1"]],"ts":"1747170430800","checksum":-1195745304,"seqId":54226327594,"prevSeqId":54226327473}]}
{"arg":{"channel":"books","instId":"BTC-USDT"},"action":"update","data":[{"asks":[["104452.5","0.03278854","0","1"],["104453.4","0.00152861","0","1"],["104455.9","0.09066354","0","1"],["104456.1","0","0","0"],["104457.1","0.0001303","0","1"],["104459.5","0.00478574","0","1"],["104461.4","0.15983208","0","1"],["104462","0","0","0"],["104463.3","0.35762748","0","2"],["104464.6","0.26157143","0","1"],["104466.9","0.25619446","0","1"],["104470","0.13908222","0","3"],["104471.8","0.00478697","0","1"],["104485.5","0.6867","0","1"],["104639.7","0","0","0"],["104639.9","0.00239325","0","1"],["104643.3","0","0","0"],["104643.8","0","0","0"],["104644.5","0","0","0"],["104646.7","0","0","0"],["104646.9","0","0","0"]],"bids":[["104450","0.079274","0","6"],["104444.6","0.03044432","0","1"],["104444.5","0","0","0"],["104441.1","0.00002018","0","1"],["104440.1","0","0","0"],["104439.6","0.01435727","0","2"],["104439.4","0.11015095","0","2"],["104437.1","0.04413864","0","1"],["104436.8","0.33955654","0","2"],["104434.9","0.10141762","0","1"],["104433.9","0.15071106","0","1"],["104431.6","0.47818099","0","3"],["104429.6","0.25730069","0","5"],["104429","0","0","0"],["104428","0.00478574","0","1"],["104426.2","0.00001731","0","1"],["104423.9","0.25723057","0","1"],["104423.7","0.00004788","0","1"],["104421.1","0.13879216","0","1"],["104341.2","0","0","0"],["104340.9","0","0","0"],["104340.8","0","0","0"],["104340.4","0","0","0"]],"ts":"1747170430900","checksum":-830644716,"seqId":54226327730,"prevSeqId":54226327594}]}
{"arg":{"channel":"books","instId":"BTC-USDT"},"action":"update","data":[{"asks":[["104455.9","0","0","0"],["104456","0.09755796","0","1"],["104456.4","0.09781568","0","1"],["104457.4","0.09066284","0","1"],["104458","0.10019385","0","1"],["104460.9","0.14990942","0","1"],["104461.4","0.16260359","0","1"],["104461.5","0.16435844","0","1"],["104463.3","0.34624598","0","2"],["104464.3","0.15372226","0","1"],["104464.6","0","0","0"],["104464.7","0.23885654","0","1"],["104466.4","0.25179202","0","1"],["104466.9","0","0","0"],["104467","0.24173777","0","1"],["104470.5","0.23409296","0","1"],["104637.8","0","0","0"],["104639.3","0","0","0"],["104639.9","0","0","0"],["104640","0","0","0"],["104641.3","0","0","0"],["104642.5","0","0","0"],["104642.7","0","0","0"],["104642.8","0","0","0"]],"bids":[["104444.6","0","0","0"],["104441.6","0.03283982","0","1"],["104439.4","0.11096876","0","2"],["104436.9","0.19087028","0","3"],["104436.8","0.47343964","0","3"],["104435.5","0.09679879","0","1"],["104435","0.09932402","0","1"],["104434.9","0","0","0"],["104434","0.15882318","0","1"],["104433.9","0","0","0"],["104433.4","0.16343919","0","1"],["104431.9","0.16951054","0","1"],["104431.6","0.49298891","0","3"],["104429.7","0.33365483","0","2"],["104429.6","0.00122607","0","4"],["104429.3","0.14616247","0","1"],["104426.9","0.43122341","0","2"],["104426.2","0.07179731","0","2"],["104424","0.25076764","0","2"],["104423.9","0","0","0"],["104423","0.26264439","0","4"],["104342.1","0","0","0"],["104342","0","0","0"],["104341.6","0","0","0"],["104341.3","0","0","0"]],"ts":"1747170431000","checksum":1519809125,"seqId":54226327831,"prevSeqId":54226327730}]}
{"arg":{"channel":"books","instId":"BTC-USDT"},"action":"update","data":[{"asks":[["104452.5","0","0","0"],["104455.7","0.03089154","0","1"],["104456","0","0","0"],["104456.1","0.09079367","0","1"],["104456.4","0","0","0"],["104456.6","0.09060475","0","2"],["104457.4","0","0","0"],["104457.6","0.08911212","0","1"],["104458","0","0","0"],["104458.2","0.80619696","0","2"],["104460.9","0","0","0"],["104461.1","0.14871056","0","1"],["104461.4","0","0","0"],["104461.5","0","0","0"],["104461.6","0.32955288","0","2"],["104463.3","0.35818315","0","2"],["104464.3","0","0","0"],["104464.4","0.15640733","0","1"],["104464.7","0","0","0"],["104464.8","0.24355523","0","1"],["104466.4","0","0","0"],["104466.6","0.24360152","0","1"],["104467","0","0","0"],["104467.1","0.27349421","0","1"],["104470.5","0","0","0"],["104470.7","0.24585921","0","1"],["104476","0.02392074","0","1"],["104488.5","0","0","0"],["104637.8","0.77866876","0","1"],["104639.3","0.00010253","0","1"],["104639.7","0.00239325","0","1"]],"bids":[["104450","0.082474","0","7"],["104447.2","0","0","0"],["104444.5","0.03044433","0","1"],["104441.6","0","0","0"],["104439.7","0.00478598","0","1"],["104439.6","0.00957132","0","1"],["104439.4","0.11235628","0","2"],["104437.1","0.23865398","0","3"],["104436.9","0.00098","0","1"],["104436.8","0.33955654","0","2"],["104435.7","0.09154804","0","1"],["104435.5","0","0","0"],["104435.1","0.10046598","0","1"],["104435","0","0","0"],["104434.1","0.15576021","0","2"],["104434","0","0","0"],["104433.6","0.14905843","0","1"],["104433.4","0","0","0"],["104432.1","0.16437117","0","1"],["104431.9","0","0","0"],["104431.6","0.49842092","0","3"],["104429.8","0.24615887","0","1"],["104429.7","0.100141","0","1"],["104429.4","0.15441825","0","1"],["104429.3","0","0","0"],["104427.1","0.25545988","0","1"],["104426.9","0.17796783","0","1"],["104424.1","0.23916586","0","1"],["104424","0.000015","0","1"],["104423.2","0.24893683","0","1"],["104423","0.00031959","0","3"],["104406.3","0","0","0"],["104405.5","0.00056666","0","1"],["104387.7","0","0","0"],["104386.9","0.00150049","0","3"],["104342.4","0","0","0"],["104342.3","0","0","0"]],"ts":"1747170431100","checksum":869593805,"seqId":54226327918,"prevSeqId":54226327831}]}
{"arg":{"channel":"books","instId":"BTC-USDT"},"action":"update","data":[{"asks":[["104450.1","1.07733406","0","23"],["104450.6","0.00267734","0","1"],["104456.1","0.09657936","0","1"],["104456.6","0.09870273","0","2"],["104457.6","0.09667876","0","1"],["104458.2","0.80655786","0","2"],["104461.1","0.14881057","0","1"],["104461.6","0.31542039","0","2"],["104463.3","0.35037007","0","2"],["104464.4","0.16191331","0","1"],["104464.8","0.23136889","0","1"],["104466.6","0.26721259","0","1"],["104467.1","0.23936078","0","1"],["104470.7","0.26707022","0","1"],["104488.4","0.00221","0","2"],["104489.3","0.00013991","0","1"],["104495.1","1.12584736","0","2"],["104527.1","0.85236747","0","1"],["104528","0.01053134","0","1"],["104555","0.97264328","0","1"],["104557.2","0","0","0"],["104570","0.02133806","0","3"],["104607","0","0","0"],["104639.3","0","0","0"],["104639.7","0","0","0"]],"bids":[["104439.4","0.11218537","0","2"],["104437.1","0.23808429","0","3"],["104435.7","0.09088475","0","1"],["104435.1","0.09243744","0","1"],["104434.1","0.15832984","0","2"],["104433.6","0.15353879","0","1"],["104432.1","0.15789843","0","1"],["104431.6","0.49866042","0","3"],["104429.8","0.25470599","0","1"],["104429.4","0.14688359","0","1"],["104427.1","0.25024732","0","1"],["104424.1","0.2717036","0","1"],["104423.2","0.26143347","0","1"],["104409.7","1.02852973","0","1"],["104407","0","0","0"],["104398","0.48329333","0","2"],["104376.4","0.95987902","0","2"],["104364","0","0","0"],["104360","0.00337722","0","7"],["104351","0.47464704","0","4"],["104342.4","0.0078311","0","2"],["104342.3","0.00002108","0","1"]],"ts":"1747170431200","checksum":-1511976979,"seqId":54226328059,"prevSeqId":54226327918}]}
{"arg":{"channel":"books","instId":"BTC-USDT"},"action":"update","data":[{"asks":[["104456.1","0.09110257","0","1"],["104456.6","0.08995423","0","2"],["104457.6","0.09152513","0","1"],["104458.2","0.80528507","0","2"],["104461.1","0.15974904","0","1"],["104461.6","0.32790604","0","2"],["104463.3","0.34807334","0","2"],["104464.4","0.14963952","0","1"],["104464.8","0.24236797","0","1"],["104466.6","0.24975816","0","1"],["104467.1","0.25043413","0","1"],["104470.7","0.25941104","0","1"],["104521.4","0","0","0"],["104524.8","6.92550804","0","3"],["104639.3","0.00010253","0","1"]],"bids":[["104439.7","0.00478593","0","1"],["104439.4","0.11194451","0","2"],["104437.1","0.23728142","0","3"],["104435.7","0.09684698","0","1"],["104435.1","0.09010157","0","1"],["104434.1","0.16917868","0","2"],["104433.6","0.1455007","0","1"],["104432.1","0.15339961","0","1"],["104431.6","0.51075161","0","3"],["104429.8","0.25644014","0","1"],["104429.4","0.16624542","0","1"],["104427.1","0.26945532","0","1"],["104424.1","0.25770531","0","1"],["104423.2","0.25711012","0","1"]],"ts":"1747170431300","checksum":-1171159400,"seqId":54226328139,"prevSeqId":54226328059}]}
{"arg":{"channel":"books","instId":"BTC-USDT"},"action":"update","data":[{"asks":[["104452.6","0.03278851","0","1"],["104455.7","0","0","0"],["104455.9","0.10109684","0","1"],["104456.1","0","0","0"],["104456.4","0.08936198","0","1"],["104456.6","0.00001","0","1"],["104457.4","0.09618454","0","1"],["104457.6","0","0","0"],["104458","0.08985958","0","1"],["104458.2","0.71685648","0","1"],["104459.5","0","0","0"],["104460.9","0.15245618","0","1"],["104461.1","0","0","0"],["104461.4","0.32333377","0","2"],["104461.6","0","0","0"],["104462.6","0.00478574","0","1"],["104463.3","0.28053019","0","2"],["104464.3","0.16069069","0","1"],["104464.4","0","0","0"],["104464.6","0.26014985","0","1"],["104464.8","0","0","0"],["104466.4","0.26668044","0","1"],["104466.6","0","0","0"],["104466.9","0.24621541","0","1"],["104467.1","0","0","0"],["104470.5","0.2664657","0","1"],["104470.7","0","0","0"],["104637.8","0","0","0"],["104639.3","0","0","0"]],"bids":[["104444.5","0","0","0"],["104440.5","0.03284018","0","1"],["104439.7","0","0","0"],["104439.5","0.00508657","0","2"],["104439.4","0.11084717","0","2"],["104437.1","0.04413864","0","1"],["104436.9","0.190465","0","3"],["104435.7","0","0","0"],["104435.5","0.09114622","0","1"],["104435.1","0","0","0"],["104434.9","0.09154531","0","1"],["104434.1","0.00005","0","1"],["104433.9","0.16586811","0","1"],["104433.6","0","0","0"],["104433.4","0.14796635","0","1"],["104432.1","0","0","0"],["104431.9","0.14974536","0","1"],["104431.6","0.50259256","0","3"],["104430.5","0.00478574","0","1"],["104429.8","0","0","0"],["104429.6","0.25442278","0","5"],["104429.4","0","0","0"],["104429.3","0.16116555","0","1"],["104428","0","0","0"],["104427.1","0","0","0"],["104426.9","0.42854959","0","2"],["104424.1","0","0","0"],["104423.9","0.2527097","0","1"],["104423.2","0","0","0"],["104423","0.25709715","0","4"],["104407.8","0.00001","0","1"],["104342.1","0.00022221","0","1"],["104342","0.01059526","0","1"]],"ts":"1747170431400","checksum":-928776669,"seqId":54226328266,"prevSeqId":54226328139}]}
{"arg":{"channel":"books","instId":"BTC-USDT"},"action":"update","data":[{"asks":[["104452.6","0","0","0"],["104455.8","0.03089152","0","1"],["104455.9","0","0","0"],["104456.2","0.09475005","0","1"],["104456.4","0","0","0"],["104456.7","0.09734457","0","1"],["104457.4","0","0","0"],["104457.6","0.08654422","0","1"],["104458","0","0","0"],["104458.2","0.80728529","0","2"],["104460.9","0","0","0"],["104461.1","0.1469281","0","1"],["104461.4","0","0","0"],["104461.7","0.31374697","0","2"],["104463.3","0.35973017","0","2"],["104464.3","0","0","0"],["104464.5","0.15471918","0","2"],["104464.6","0","0","0"],["104464.9","0.25722037","0","1"],["104466.4","0","0","0"],["104466.7","0.24745736","0","1"],["104466.9","0","0","0"],["104467.2","0.24991105","0","1"],["104470.5","0","0","0"],["104470.7","0.23721638","0","1"],["104482","0","0","0"],["104483","0","0","0"],["104484","0.002","0","2"],["104485","0.6200888","0","2"],["104502","0","0","0"],["104503","0","0","0"],["104504","0.33","0","6"],["104505","0.64453101","0","5"],["104507.3","0.00004969","0","1"],["104519.5","0","0","0"],["104637.8","0.77866876","0","1"],["104639.3","0.00010253","0","1"],["104639.7","0.00239325","0","1"],["104640","0.00220843","0","3"],["104641.3","0.03","0","1"]],"bids":[["104444.7","0.03044429","0","1"],["104439.5","0.00030064","0","1"],["104439.4","0.09827344","0","2"],["104438.5","0.00478594","0","1"],["104437.2","0.09568155","0","1"],["104437.1","0.09780898","0","1"],["104436.9","0.00098","0","1"],["104435.7","0.09609819","0","1"],["104435.5","0","0","0"],["104435.2","0.0972516","0","1"],["104434.9","0","0","0"],["104434.2","0.15496342","0","2"],["104433.9","0","0","0"],["104433.6","0.14403299","0","1"],["104433.4","0","0","0"],["104432.2","0.16977588","0","1"],["104431.9","0","0","0"],["104431.6","0.50629452","0","3"],["104429.9","0.2792098","0","2"],["104429.6","0.00122607","0","4"],["104429.5","0.35311368","0","2"],["104429.3","0","0","0"],["104427.2","0.24374224","0","1"],["104426.9","0.17796783","0","1"],["104424.2","0.23983771","0","1"],["104423.9","0","0","0"],["104423.2","0.2660312","0","1"],["104423","0.00031959","0","3"],["104362.1","0","0","0"],["104342.1","0","0","0"],["104342","0","0","0"]],"ts":"1747170431500","checksum":-165568020,"seqId":54226328368,"prevSeqId":54226328266}]}
{"arg":{"channel":"books","instId":"BTC-USDT"},"action":"update","data":[{"asks":[["104458.2","0.71685648","0","1"],["104458.3","0.09392732","0","1"],["104464.9","0.25922037","0","2"],["104470.7","0","0","0"],["104470.8","0.24794302","0","1"],["104477.4","0.131","0","5"],["104639.7","0","0","0"],["104639.9","0.00239325","0","1"],["104641.3","0","0","0"]],"bids":[["104447.7","0.002","0","1"],["104436.8","0.46741177","0","3"],["104435.8","0.09979394","0","1"],["104435.7","0","0","0"],["104435.2","0.0992516","0","2"],["104423.3","0.23999278","0","1"],["104423.2","0","0","0"],["104342.3","0","0","0"]],"ts":"1747170431600","checksum":268524505,"seqId":54226328389,"prevSeqId":54226328368}]}
{"arg":{"channel":"books","instId":"BTC-USDT"},"action":"update","data":[{"asks":[],"bids":[["104362.1","0.00002964","0","1"],["104342.4","0","0","0"]],"ts":"1747170431800","checksum":268524505,"seqId":54226328394,"prevSeqId":54226328389}]}
{"arg":{"channel":"books","instId":"BTC-USDT"},"action":"update","data":[{"asks":[],"bids":[["104439.4","0.10305937","0","3"],["104438.5","0","0","0"],["104342.4","0.0078311","0","2"]],"ts":"1747170431900","checksum":2077130868,"seqId":54226328397,"prevSeqId":54226328394}]}
{"arg":{"channel":"books","instId":"BTC-USDT"},"action":"update","data":[{"asks":[],"bids":[["104439.4","0.09827344","0","2"],["104438.5","0.00478593","0","1"],["104437.7","0.00868363","0","1"],["104362.1","0","0","0"],["104342.4","0","0","0"]],"ts":"1747170432000","checksum":-1064480160,"seqId":54226328402,"prevSeqId":54226328397}]}
{"arg":{"channel":"books","instId":"BTC-USDT"},"action":"update","data":[{"asks":[["104462.1","0.05687731","0","3"],["104462.6","0","0","0"],["104469.2","0.1387935","0","1"],["104470","0.00029006","0","2"]],"bids":[["104405.7","0.00056666","0","1"],["104405.5","0","0","0"],["104387.1","0.00056666","0","1"],["104386.9","0.00093383","0","2"],["104342.6","0","0","0"]],"ts":"1747170432100","checksum":-1064480160,"seqId":54226328411,"prevSeqId":54226328402}]}
{"arg":{"channel":"books","instId":"BTC-USDT"},"action":"update","data":[{"asks":[["104450.1","1.31733406","0","24"],["104453.4","0","0","0"],["104456.2","0","0","0"],["104456.4","0.09769057","0","1"],["104456.7","0","0","0"],["104457.1","0.00165891","0","2"],["104457.4","0.09441861","0","1"],["104457.6","0","0","0"],["104458","0.08932296","0","1"],["104458.3","0","0","0"],["104460.9","0.14853569","0","1"],["104461.1","0","0","0"],["104461.4","0.16243643","0","1"],["104461.7","0","0","0"],["104463.3","0.39619085","0","2"],["104464.3","0.14882449","0","1"],["104464.5","0.00001","0","1"],["104464.7","0.23496221","0","1"],["104464.9","0.002","0","1"],["104466.4","0.26342837","0","1"],["104466.7","0","0","0"],["104467.2","0","0","0"],["104467.9","0.13879487","0","1"],["104469.2","0","0","0"],["104470.5","0.26525324","0","1"],["104470.8","0","0","0"],["104485","0.85407523","0","3"],["104520.2","2.29186338","0","2"],["104521.4","6.87350804","0","1"],["104524.8","0.052","0","2"],["104527.1","0","0","0"],["104541","0","0","0"],["104554","0.26115546","0","1"],["104641.3","0.03","0","1"]],"bids":[["104450","0.079274","0","6"],["104444.7","0","0","0"],["104439.4","0.11548603","0","2"],["104438","0.0510315","0","1"],["104437.2","0","0","0"],["104437.1","0","0","0"],["104436.9","0.19281099","0","3"],["104436.8","0.33955654","0","2"],["104435.8","0","0","0"],["104435.5","0.08915021","0","1"],["104435.2","0.002","0","1"],["104434.2","0.000015","0","1"],["104433.6","0","0","0"],["104433.4","0.15916126","0","1"],["104432.2","0","0","0"],["104431.9","0.15041372","0","1"],["104431.6","0.4912186","0","3"],["104429.9","0.02761675","0","1"],["104429.7","0.32960656","0","2"],["104429.5","0.19242972","0","1"],["104429.3","0.15412805","0","1"],["104427.2","0","0","0"],["104426.9","0.42140506","0","2"],["104424.2","0","0","0"],["104423.3","0","0","0"],["104423","0.2642028","0","4"],["104421.1","0","0","0"],["104418.2","0.13879487","0","1"],["104404.2","0.06241696","0","2"],["104373.2","0.22395706","0","2"],["104342.6","0.0000203","0","1"],["104342.4","0.0078311","0","2"],["104342.3","0.00002108","0","1"],["104342.1","0.00022221","0","1"]],"ts":"1747170432200","checksum":368824255,"seqId":54226328499,"prevSeqId":54226328411}]}
{"arg":{"channel":"books","instId":"BTC-USDT"},"action":"update","data":[{"asks":[["104455.9","0.09733188","0","1"],["104461.4","0.32035206","0","2"],["104463.3","0.28239296","0","1"],["104464.2","0.1632476","0","1"],["104464.3","0","0","0"],["104464.6","0.25813517","0","1"],["104464.7","0","0","0"],["104466.9","0.26904194","0","1"],["104640","0","0","0"],["104641.3","0","0","0"]],"bids":[["104436.8","0.46775251","0","3"],["104434.9","0.09859186","0","1"],["104433.9","0.16962159","0","1"],["104429.7","0.100141","0","1"],["104429.6","0.23205693","0","5"],["104429.3","0","0","0"],["104429.2","0.16031136","0","1"],["104423.9","0.25767988","0","1"],["104420.8","0.13879474","0","1"],["104418.2","0","0","0"],["104342.4","0","0","0"],["104342.3","0","0","0"],["104342.1","0","0","0"]],"ts":"1747170432300","checksum":-1973516667,"seqId":54226328521,"prevSeqId":54226328499}]}
{"arg":{"channel":"books","instId":"BTC-USDT"},"action":"update","data":[{"asks":[["104456.6","0.0001403","0","2"],["104457.1","0.00152861","0","1"],["104462","0.00478574","0","1"],["104462.1","0.05209157","0","2"],["104467.9","0","0","0"],["104469.2","0.13879441","0","1"],["104520.2","0.78897017","0","1"],["104521.4","0","0","0"],["104528.2","6.86393521","0","1"],["104557.2","0.00009223","0","1"],["104558.9","0","0","0"],["104609.7","0.01059618","0","1"],["104639.9","0","0","0"]],"bids":[["104421.1","0.13879441","0","1"],["104420.8","0","0","0"],["104362.1","0.00002964","0","1"],["104342.6","0","0","0"]],"ts":"1747170432400","checksum":1741326327,"seqId":54226328547,"prevSeqId":54226328521}]}
{"arg":{"channel":"books","instId":"BTC-USDT"},"action":"update","data":[{"asks":[["104521.4","6.86393521","0","1"],["104528.2","0","0","0"]],"bids":[["104430.5","0","0","0"],["104430","0.0050758","0","3"],["104393.2","0","0","0"],["104342.6","0.0000203","0","1"],["104342.4","0.0078311","0","2"]],"ts":"1747170432500","checksum":1741326327,"seqId":54226328552,"prevSeqId":54226328547}]}
{"arg":{"channel":"books","instId":"BTC-USDT"},"action":"update","data":[{"asks":[["104455.9","0.09516926","0","1"],["104456.4","0.10031418","0","1"],["104457.4","0.08679844","0","1"],["104458","0.09070704","0","1"],["104460.9","0.16212393","0","1"],["104461.4","0.31946457","0","2"],["104462","0","0","0"],["104462.6","0.00478574","0","1"],["104463.3","0.2739289","0","2"],["104464.2","0.15941806","0","1"],["104464.6","0.23428746","0","1"],["104466.4","0.23730951","0","1"],["104466.9","0.24716303","0","1"],["104469.2","0.13879433","0","1"],["104470.5","0.26065185","0","1"]],"bids":[["104439.4","0.1125514","0","2"],["104438.5","0.00478592","0","1"],["104438.2","0.05103144","0","1"],["104438","0","0","0"],["104436.9","0.18302896","0","3"],["104436.8","0.33955654","0","2"],["104435.5","0.08943242","0","1"],["104434.9","0.09776826","0","1"],["104433.9","0.15680955","0","1"],["104433.4","0.14278196","0","1"],["104431.9","0.15070228","0","1"],["104431.6","0.49924276","0","3"],["104430.5","0.00478574","0","1"],["104430","0.00029006","0","2"],["104429.6","0.24097737","0","5"],["104429.2","0.15974692","0","1"],["104426.9","0.43224764","0","2"],["104423.9","0.23962606","0","1"],["104423","0.24029398","0","4"],["104421.1","0.13879433","0","1"],["104389.5","0.45254372","0","1"],["104342.6","0","0","0"],["104342.4","0","0","0"]],"ts":"1747170432600","checksum":-730364057,"seqId":54226328633,"prevSeqId":54226328552}]}
{"arg":{"channel":"books","instId":"BTC-USDT"},"action":"update","data":[{"asks":[["104450.1","1.31645439","0","24"],["104494.6","0.11161369","0","1"],["104507.9","0","0","0"]],"bids":[["104450","0.082474","0","7"],["104437.7","0","0","0"],["104342.6","0.0000203","0","1"]],"ts":"1747170432700","checksum":743507565,"seqId":54226328642,"prevSeqId":54226328633}]}
{"arg":{"channel":"books","instId":"BTC-USDT"},"action":"update","data":[{"asks":[["104455.9","0","0","0"],["104456.1","0.09962317","0","1"],["104456.4","0","0","0"],["104456.6","0.09549932","0","3"],["104457.4","0","0","0"],["104457.6","0.09336025","0","1"],["104458","0","0","0"],["104458.2","0.80516741","0","2"],["104460.9","0","0","0"],["104461.1","0.15028237","0","1"],["104461.4","0","0","0"],["104461.6","0.33687536","0","2"],["104462","0.00478574","0","1"],["104462.6","0","0","0"],["104463.3","0.09333524","0","1"],["104464.2","0","0","0"],["104464.4","0.15679887","0","1"],["104464.6","0","0","0"],["104464.8","0.24813564","0","1"],["104466.4","0","0","0"],["104466.6","0.24687745","0","1"],["104466.9","0","0","0"],["104467.1","0.27030229","0","1"],["104470.5","0","0","0"],["104470.7","0.2500132","0","1"],["104639.7","0.00239325","0","1"],["104640","0.00220843","0","3"]],"bids":[["104444.4","0.02745439","0","3"],["104440.5","0","0","0"],["104439.4","0.0601104","0","1"],["104437.1","0.19750727","0","2"],["104436.9","0.00098","0","1"],["104435.7","0.09233065","0","1"],["104435.5","0","0","0"],["104435.1","0.09779563","0","1"],["104434.9","0","0","0"],["104434.1","0.15588971","0","2"],["104433.9","0","0","0"],["104433.6","0.15293223","0","1"],["104433.4","0","0","0"],["104432.1","0.16816179","0","1"],["104431.9","0","0","0"],["104431.6","0.33110332","0","2"],["104430.5","0","0","0"],["104430","0.0050758","0","3"],["104429.8","0.24328755","0","1"],["104429.6","0.00122607","0","4"],["104429.4","0.14638746","0","1"],["104429.2","0","0","0"],["104427.1","0.2525178","0","1"],["104426.9","0.17796783","0","1"],["104424.1","0.25248467","0","1"],["104423.9","0","0","0"],["104423.2","0.2520237","0","1"],["104423","0.00031959","0","3"],["104342.6","0","0","0"]],"ts":"1747170432800","checksum":-124918774,"seqId":54226328729,"prevSeqId":54226328642}]}
{"arg":{"channel":"books","instId":"BTC-USDT"},"action":"update","data":[{"asks":[["104457.6","0.08848585","0","1"],["104461.1","0.15333919","0","1"],["104463.3","0.35830261","0","2"],["104639.7","0","0","0"],["104639.9","0.00239325","0","1"]],"bids":[["104439.4","0.1145838","0","2"],["104437.1","0.19005372","0","2"],["104436.8","0.46778892","0","3"],["104433.6","0.16010461","0","1"],["104431.6","0.49576719","0","3"]],"ts":"1747170432900","checksum":-1901297880,"seqId":54226328743,"prevSeqId":54226328729}]}
{"arg":{"channel":"books","instId":"BTC-USDT"},"action":"update","data":[{"asks":[["104450.1","1.31942379","0","25"],["104462","0","0","0"],["104462.6","0.00478574","0","1"],["104469.2","0","0","0"],["104470","0.13908291","0","3"],["104641.3","0.03","0","1"]],"bids":[["104430.5","0.00478574","0","1"],["104430","0.00029006","0","2"],["104405.7","0","0","0"],["104404.9","0.00056666","0","1"],["104387.1","0","0","0"],["104386.4","0.00056666","0","1"],["104342.8","0","0","0"]],"ts":"1747170433100","checksum":-1244026950,"seqId":54226328756,"prevSeqId":54226328743}]}
{"arg":{"channel":"books","instId":"BTC-USDT"},"action":"update","data":[{"asks":[["104450.1","1.24832379","0","24"],["104454.4","0","0","0"],["104455.8","0.06178304","0","2"],["104456.1","0","0","0"],["104456.6","0.0001403","0","2"],["104457.6","0","0","0"],["104457.9","0.09652702","0","2"],["104458.2","0.34290349","0","1"],["104458.4","0.19002704","0","4"],["104460","0.00029006","0","2"],["104461.1","0","0","0"],["104461.6","0","0","0"],["104462.6","0","0","0"],["104463.1","0.00478574","0","1"],["104463.3","0.30262705","0","2"],["104463.4","0.51465113","0","3"],["104464.4","0","0","0"],["104464.8","0","0","0"],["104466.2","0.16294819","0","1"],["104466.6","0.25135943","0","1"],["104467.1","0","0","0"],["104468.4","0.25024746","0","2"],["104468.9","0.26321674","0","1"],["104470","0.00029006","0","2"],["104470.7","0","0","0"],["104471.8","0.14357752","0","2"],["104482","0.002","0","2"],["104483","0.001","0","1"],["104484","0","0","0"],["104485","0.85307523","0","2"],["104489.4","0.31800121","0","2"],["104491.8","0.11101561","0","1"],["104494.6","0","0","0"],["104502","0.23","0","4"],["104503","0.21499999","0","4"],["104504","0.05","0","1"],["104505","0.47953102","0","2"],["104520.2","2.59705909","0","2"],["104553.2","0.01350168","0","1"],["104563.1","0","0","0"],["104566.2","0","0","0"],["104630","0.00151107","0","2"],["104642.5","0.0003067","0","1"],["104642.7","0.03","0","1"],["104642.8","0.0288065","0","3"],["104643.3","0.00001","0","1"],["104643.8","0.07298372","0","1"]],"bids":[["104450","0.201974","0","8"],["104444.5","0.01872354","0","1"],["104442.8","0","0","0"],["104442.6","0.03431832","0","1"],["104440.1","0.00478589","0","1"],["104439.4","0.16689044","0","2"],["104438.9","0.09894365","0","1"],["104438.5","0","0","0"],["104437.1","0","0","0"],["104436.9","0.09459146","0","2"],["104436.8","0.48039412","0","3"],["104435.9","0.15523179","0","1"],["104435.7","0","0","0"],["104435.1","0","0","0"],["104434.1","0.00005","0","1"],["104433.9","0.16517875","0","1"],["104433.6","0","0","0"],["104432.1","0","0","0"],["104431.6","0.57334406","0","4"],["104431.2","0.16213851","0","1"],["104430.5","0","0","0"],["104429.8","0","0","0"],["104429.4","0","0","0"],["104428.9","0.2452115","0","2"],["104427.1","0","0","0"],["104425.9","0.27095692","0","2"],["104424.2","0.36908178","0","1"],["104424.1","0","0","0"],["104423.7","0.13883843","0","2"],["104423.2","0","0","0"],["104421.1","0","0","0"],["104389.6","0.49742651","0","1"],["104349.1","0","0","0"],["104342.8","0.00076959","0","3"],["104342.6","0.0000203","0","1"],["104342.4","0.0078311","0","2"],["104342.3","0.00002108","0","1"],["104342.1","0.00022221","0","1"],["104342","0.01059526","0","1"]],"ts":"1747170433200","checksum":2143050916,"seqId":54226328966,"prevSeqId":54226328756}]}
{"arg":{"channel":"books","instId":"BTC-USDT"},"action":"update","data":[{"asks":[["104453.8","0.03268829","0","1"],["104455.8","0.03089152","0","1"],["104459.3","0.09623747","0","1"],["104459.9","0.10032543","0","1"],["104460.1","0.42117335","0","3"],["104462.6","0.00478574","0","1"],["104462.8","0.14639","0","1"],["104463.1","0","0","0"],["104470.8","0.1387917","0","1"],["104471.8","0.00478697","0","1"],["104472.4","0.24694444","0","1"],["104495.1","0.73330539","0","1"],["104495.9","0","0","0"],["104527.2","0","0","0"],["104642.7","0","0","0"],["104642.8","0","0","0"],["104643.3","0","0","0"],["104643.8","0","0","0"]],"bids":[["104444.5","0","0","0"],["104439.4","0.15819037","0","2"],["104438.8","0.0885576","0","1"],["104437.4","0.10155538","0","2"],["104435.3","0.14378902","0","2"],["104431.6","0.56855832","0","3"],["104430.5","0.00478574","0","1"],["104424.9","0.24908087","0","2"],["104423.7","0.00004788","0","1"],["104422.9","0.1387917","0","1"],["104409.7","0","0","0"],["104407.4","0","0","0"],["104376.4","0.29093002","0","1"],["104376","0.01053013","0","1"]],"ts":"1747170433300","checksum":1554759898,"seqId":54226329078,"prevSeqId":54226328966}]}
{"arg":{"channel":"books","instId":"BTC-USDT"},"action":"update","data":[{"asks":[["104459.8","0.07656374","0","2"],["104462.6","0","0","0"],["104495.9","1.42670541","0","1"],["104527.2","2.53927775","0","1"],["104642.5","0","0","0"]],"bids":[["104430.5","0","0","0"],["104428","0.00478574","0","1"],["104406.5","1.38836362","0","1"],["104375.2","2.45440762","0","1"],["104342.1","0","0","0"],["104342","0","0","0"]],"ts":"1747170433400","checksum":-1007346004,"seqId":54226329087,"prevSeqId":54226329078}]}
{"arg":{"channel":"books","instId":"BTC-USDT"},"action":"update","data":[{"asks":[["104470","0.13908218","0","3"],["104470.8","0","0","0"],["104482","0","0","0"],["104483","0","0","0"],["104484","0.002","0","2"],["104485","0.85407523","0","3"],["104502","0","0","0"],["104503","0.1","0","2"],["104504","0.28","0","5"],["104505","0.59453101","0","4"],["104642.5","0.0003067","0","1"],["104642.7","0.03","0","1"],["104642.8","0.0288065","0","3"]],"bids":[["104441","0.00478591","0","1"],["104440.1","0","0","0"],["104422.9","0","0","0"],["104421.2","0.13879219","0","1"]],"ts":"1747170433500","checksum":-219878363,"seqId":54226329124,"prevSeqId":54226329087}]}
{"arg":{"channel":"books","instId":"BTC-USDT"},"action":"update","data":[{"asks":[["104459.8","0.071778","0","1"],["104462","0.00478574","0","1"],["104469.2","0.13879301","0","1"],["104470","0.00029006","0","2"],["104482","0.002","0","2"],["104483","0.001","0","1"],["104484","0","0","0"],["104485","0.85307523","0","2"],["104502","0.23","0","4"],["104503","0.21499999","0","4"],["104504","0.05","0","1"],["104505","0.47953102","0","2"],["104641.3","0","0","0"],["104642.5","0","0","0"],["104642.7","0","0","0"],["104642.8","0","0","0"]],"bids":[["104437.4","0.1266441","0","3"],["104433.7","0","0","0"],["104429","0.00478574","0","1"],["104428","0","0","0"],["104421.2","0","0","0"],["104421.1","0.13879301","0","1"],["104342.1","0.00022221","0","1"]],"ts":"1747170433600","checksum":1254151574,"seqId":54226329165,"prevSeqId":54226329124}]}
{"arg":{"channel":"books","instId":"BTC-USDT"},"action":"update","data":[{"asks":[["104453.8","0","0","0"],["104457.9","0.00044","0","1"],["104458","0.09613341","0","1"],["104458.4","0.09038516","0","3"],["104458.5","0.09308829","0","1"],["104459.3","0","0","0"],["104459.5","0.09592243","0","1"],["104459.9","0","0","0"],["104460.1","0.51129635","0","4"],["104461","0.04164162","0","1"],["104462.8","0","0","0"],["104463","0.14416976","0","1"],["104463.3","0.29566702","0","2"],["104463.4","0.19242972","0","1"],["104463.5","0.32222788","0","2"],["104466.2","0","0","0"],["104466.3","0.16691881","0","2"],["104466.6","0","0","0"],["104466.7","0.23129428","0","1"],["104468.4","0.00093","0","1"],["104468.5","0.25915917","0","2"],["104468.9","0","0","0"],["104469","0.25629321","0","1"],["104472.4","0","0","0"],["104472.6","0.24458149","0","1"],["104640","0","0","0"]],"bids":[["104446.1","0.02734255","0","1"],["104441.2","0.00478591","0","1"],["104441","0","0","0"],["104439.4","0.17470083","0","2"],["104439","0.1815949","0","2"],["104438.9","0","0","0"],["104438.8","0","0","0"],["104437.6","0.09407042","0","1"],["104437.4","0.03426704","0","2"],["104437","0.09626991","0","1"],["104436.9","0.00098","0","1"],["104436.8","0.33955654","0","2"],["104436","0.15781095","0","1"],["104435.9","0","0","0"],["104435.5","0.14467074","0","1"],["104435.3","0.0001","0","1"],["104434","0.15231197","0","1"],["104433.9","0","0","0"],["104431.7","0.23128754","0","2"],["104431.6","0.28273687","0","1"],["104431.3","0.1633674","0","1"],["104431.2","0","0","0"],["104429","0.26366323","0","2"],["104428.9","0.00001","0","1"],["104426","0.24098164","0","1"],["104425.9","0.0001","0","1"],["104425.1","0.26554903","0","1"],["104424.9","0.00001","0","1"],["104422","0.07298372","0","1"],["104342.9","0","0","0"],["104342.8","0","0","0"],["104342.6","0","0","0"],["104342.4","0","0","0"],["104342.3","0","0","0"],["104342.1","0","0","0"]],"ts":"1747170433700","checksum":-317335581,"seqId":54226329227,"prevSeqId":54226329165}]}
{"arg":{"channel":"books","instId":"BTC-USDT"},"action":"update","data":[{"asks":[["104453.9","0.03268827","0","1"],["104456.9","0.03072114","0","1"],["104457.9","0.09580917","0","2"],["104458","0","0","0"],["104458.4","0.1875786","0","4"],["104458.5","0","0","0"],["104458.9","0","0","0"],["104459.4","0.08960666","0","1"],["104459.5","0","0","0"],["104460","0.09740425","0","3"],["104460.1","0.42117335","0","3"],["104461","0","0","0"],["104462.9","0.14581494","0","1"],["104463","0","0","0"],["104463.3","0.30265028","0","2"],["104463.4","0.50899712","0","3"],["104463.5","0","0","0"],["104464.4","0.04889724","0","1"],["104466.2","0.1633231","0","1"],["104466.3","0.00711203","0","1"],["104466.6","0.25139969","0","1"],["104466.7","0","0","0"],["104468","0.51172789","0","2"],["104468.4","0.24132599","0","2"],["104468.5","0.00001","0","1"],["104468.9","0.24389964","0","1"],["104469","0","0","0"],["104472.5","0.34076232","0","3"],["104472.6","0","0","0"],["104639.7","0.00239325","0","1"],["104639.9","0","0","0"],["104640","0.00220843","0","3"],["104641.3","0.03","0","1"]],"bids":[["104446.1","0","0","0"],["104444.5","0.01872354","0","1"],["104441.2","0","0","0"],["104441","0.00478589","0","1"],["104440.4","0.24390327","0","2"],["104440.3","0.19242972","0","1"],["104440.2","0.05103046","0","1"],["104439.5","0","0","0"],["104439.4","0","0","0"],["104439","0","0","0"],["104438.9","0.18089826","0","2"],["104438.2","0","0","0"],["104437.6","0","0","0"],["104437.5","0.13905881","0","4"],["104437","0","0","0"],["104436.9","0.09635309","0","2"],["104436.8","0.4794466","0","3"],["104436","0","0","0"],["104435.9","0.1591839","0","1"],["104435.5","0","0","0"],["104435.4","0.15939437","0","1"],["104434","0","0","0"],["104433.9","0.16561675","0","1"],["104433.6","0.04622105","0","1"],["104431.7","0.00098","0","1"],["104431.6","0.53169491","0","2"],["104431.3","0","0","0"],["104431.2","0.15576776","0","1"],["104429","0.00478574","0","1"],["104428.9","0.25595047","0","2"],["104426","0","0","0"],["104425.9","0.26796905","0","2"],["104425.1","0","0","0"],["104425","0.24392468","0","1"],["104342.9","0.00004791","0","1"],["104342.8","0.00076959","0","3"]],"ts":"1747170433800","checksum":628566814,"seqId":54226329305,"prevSeqId":54226329227}]}
{"arg":{"channel":"books","instId":"BTC-USDT"},"action":"update","data":[{"asks":[["104452.9","0.0348692","0","2"],["104469.3","0.04","0","1"],["104639.7","0","0","0"],["104639.9","0.00239325","0","1"]],"bids":[["104440.5","0.00030064","0","1"],["104440.4","0.24360263","0","1"],["104437.4","0.00917832","0","1"],["104342.8","0","0","0"]],"ts":"1747170433900","checksum":-1148825485,"seqId":54226329314,"prevSeqId":54226329305}]}
{"arg":{"channel":"books","instId":"BTC-USDT"},"action":"update","data":[{"asks":[["104458","0.67817699","0","1"],["104458.1","0.77866876","0","1"],["104458.2","0","0","0"],["104459.3","0.088906","0","1"],["104459.4","0","0","0"],["104459.9","0.09762961","0","1"],["104460","0.00029006","0","2"],["104460.1","0.42595909","0","4"],["104462","0","0","0"],["104462.8","0.14472608","0","1"],["104462.9","0","0","0"],["104472.4","0.25178624","0","1"],["104472.5","0.10634","0","2"],["104640","0","0","0"],["104641.3","0","0","0"]],"bids":[["104444.5","0","0","0"],["104441","0","0","0"],["104440.6","0.0047859","0","1"],["104440.4","0.18116657","0","1"],["104440.3","0","0","0"],["104438.9","0.0948649","0","1"],["104438.8","0.09778393","0","1"],["104437.5","0.04236132","0","3"],["104437.4","0.09907213","0","2"],["104435.4","0","0","0"],["104435.3","0.158636","0","2"],["104429","0","0","0"],["104428","0.00478574","0","1"],["104425","0","0","0"],["104424.9","0.26360533","0","2"],["104424.2","0","0","0"],["104406.9","0.002871","0","1"],["104361.9","0","0","0"],["104342.8","0.00076959","0","3"],["104342.6","0.0000203","0","1"],["104342.4","0.0078311","0","2"],["104342.3","0.00002108","0","1"]],"ts":"1747170434000","checksum":1894150890,"seqId":54226329347,"prevSeqId":54226329314}]}
{"arg":{"channel":"books","instId":"BTC-USDT"},"action":"update","data":[{"asks":[["104450.1","1.00832379","0","23"],["104456.6","0.00001","0","1"],["104456.8","0.00165891","0","2"],["104457.1","0","0","0"],["104457.2","0.37977399","0","4"],["104457.6","0.09170171","0","1"],["104457.9","0.00044","0","1"],["104458.2","0.0248692","0","1"],["104458.4","0.09038516","0","3"],["104458.6","0.09235083","0","1"],["104459.2","0.09332261","0","1"],["104459.3","0","0","0"],["104459.9","0","0","0"],["104460","0.0050758","0","3"],["104460.1","0.42117335","0","3"],["104462.1","0.20713744","0","3"],["104462.2","0","0","0"],["104462.6","0.15332544","0","1"],["104462.7","0.17838232","0","2"],["104462.8","0","0","0"],["104463.3","0.2818673","0","2"],["104463.4","0.19242972","0","1"],["104465.5","0.15807723","0","1"],["104465.9","0.23420284","0","1"],["104466.2","0","0","0"],["104466.6","0","0","0"],["104467.6","0.23933973","0","1"],["104468.2","0.29639315","0","2"],["104468.4","0.00093","0","1"],["104468.9","0","0","0"],["104469.2","0.13879404","0","1"],["104471.7","0.24332799","0","1"],["104472.4","0","0","0"],["104474.7","0","0","0"],["104639.7","0.00239325","0","1"],["104639.9","0","0","0"]],"bids":[["104450","0.150374","0","7"],["104445.3","0.005","0","1"],["104440.7","0.00478593","0","1"],["104440.6","0.00030064","0","1"],["104440.5","0.12071623","0","1"],["104440.4","0","0","0"],["104438.9","0","0","0"],["104438.8","0","0","0"],["104438.1","0.18304818","0","2"],["104437.4","0.03426704","0","2"],["104436.9","0.00098","0","1"],["104436.8","0.33955654","0","2"],["104436.7","0.09626226","0","1"],["104436.2","0.09240914","0","1"],["104435.9","0","0","0"],["104435.3","0.0001","0","1"],["104435.2","0.1571592","0","2"],["104434.6","0.15864544","0","1"],["104433.9","0","0","0"],["104433.1","0.16245245","0","1"],["104431.6","0.44449953","0","2"],["104431.2","0","0","0"],["104430.9","0.24084593","0","1"],["104430.5","0.14629014","0","1"],["104428.9","0.00001","0","1"],["104428.1","0.24019081","0","1"],["104425.9","0.0001","0","1"],["104425.2","0.24349699","0","1"],["104424.9","0.00001","0","1"],["104424.2","0.24364412","0","1"],["104404.9","0","0","0"],["104404.1","0.19305127","0","3"],["104386.4","0","0","0"],["104385.5","0.00071033","0","4"],["104342.6","0","0","0"],["104342.4","0","0","0"],["104342.3","0","0","0"]],"ts":"1747170434100","checksum":-673069076,"seqId":54226329460,"prevSeqId":54226329347}]}
{"arg":{"channel":"books","instId":"BTC-USDT"},"action":"update","data":[{"asks":[["104457.2","0.28609157","0","3"],["104457.6","0","0","0"],["104458.4","0.18136889","0","4"],["104458.6","0","0","0"],["104458.9","0.09847872","0","1"],["104459.2","0","0","0"],["104459.9","0.09154741","0","1"],["104460.5","0.08770164","0","1"],["104462.1","0.05209157","0","2"],["104462.6","0","0","0"],["104462.7","0.02392578","0","1"],["104463.3","0.3552127","0","2"],["104463.4","0.3478717","0","2"],["104463.9","0.33621142","0","2"],["104465.5","0","0","0"],["104465.9","0","0","0"],["104466.8","0.15568392","0","1"],["104467.2","0.25916093","0","1"],["104467.6","0","0","0"],["104468.2","0.04","0","1"],["104468.9","0.27173535","0","1"],["104469.4","0.24073956","0","1"],["104471.7","0","0","0"],["104473","0.24021547","0","1"],["104495.1","1.14457474","0","2"],["104550.2","0.00095647","0","1"],["104639.3","0","0","0"],["104639.7","0","0","0"]],"bids":[["104450","0.273074","0","9"],["104440.7","0","0","0"],["104440.6","0.00508656","0","2"],["104440.5","0.17905484","0","2"],["104439.6","0","0","0"],["104439.4","0.1956155","0","2"],["104439.2","0.00957135","0","1"],["104438.1","0","0","0"],["104438","0.09539511","0","1"],["104437.4","0.12459376","0","3"],["104436.8","0.51744565","0","3"],["104436.7","0","0","0"],["104436.4","0.16341921","0","1"],["104436.2","0","0","0"],["104435.9","0.1437839","0","1"],["104435.2","0.002","0","1"],["104434.6","0","0","0"],["104434.4","0.15878507","0","2"],["104433.1","0","0","0"],["104432.2","0.23820886","0","1"],["104431.8","0.15563451","0","1"],["104431.6","0.41548393","0","2"],["104430.9","0","0","0"],["104430.5","0","0","0"],["104429.4","0.26474779","0","1"],["104428.1","0","0","0"],["104426.4","0.27105565","0","1"],["104425.5","0.25000523","0","1"],["104425.2","0","0","0"],["104424.2","0","0","0"],["104409.5","0.78660204","0","1"],["104406.9","0","0","0"],["104385.1","0.002871","0","1"],["104376.4","0.96087505","0","2"],["104352.8","0.00173869","0","1"]],"ts":"1747170434200","checksum":-1299790906,"seqId":54226329539,"prevSeqId":54226329460}]}
{"arg":{"channel":"books","instId":"BTC-USDT"},"action":"update","data":[{"asks":[["104457.2","0.38520735","0","4"],["104457.7","0.13309547","0","2"],["104458.4","0.09038516","0","3"],["104458.7","0.09034854","0","1"],["104458.9","0","0","0"],["104459.3","0.0935447","0","1"],["104459.9","0","0","0"],["104460.5","0","0","0"],["104462.2","0.14276738","0","1"],["104462.7","0.34213109","0","3"],["104463.3","0.28450487","0","2"],["104463.4","0.19242972","0","1"],["104463.9","0","0","0"],["104465.5","0.16678818","0","1"],["104465.9","0.25962285","0","1"],["104466.8","0","0","0"],["104467.2","0","0","0"],["104467.7","0.24439446","0","1"],["104468.2","0.27954084","0","2"],["104468.9","0","0","0"],["104469.2","0","0","0"],["104469.4","0","0","0"],["104470","0.13908295","0","3"],["104471.8","0.26761941","0","2"],["104473","0","0","0"],["104563.5","0","0","0"],["104568","0.11426484","0","1"],["104639.3","0.00010253","0","1"],["104639.7","0.00239325","0","1"],["104640","0.00220843","0","3"],["104641.3","0.03","0","1"]],"bids":[["104450","0.153574","0","8"],["104440.8","0.00030064","0","1"],["104440.7","0.13314477","0","1"],["104440.6","0.19721564","0","2"],["104440.5","0","0","0"],["104439.4","0","0","0"],["104438.2","0.18418725","0","2"],["104438","0","0","0"],["104437.4","0.03426704","0","2"],["104436.8","0.43983155","0","3"],["104436.4","0","0","0"],["104436.2","0.10189492","0","1"],["104435.9","0","0","0"],["104435.2","0.16222034","0","2"],["104434.7","0.1451933","0","1"],["104434.4","0.000015","0","1"],["104433.2","0.15855406","0","1"],["104432.2","0","0","0"],["104431.8","0","0","0"],["104431.6","0.45375445","0","2"],["104430.9","0.24402175","0","1"],["104430.5","0.14721985","0","1"],["104429.4","0","0","0"],["104428.2","0.27213022","0","1"],["104426.4","0","0","0"],["104425.5","0","0","0"],["104425.2","0.24934424","0","1"],["104424.3","0.23783357","0","2"],["104422.1","0.13879289","0","1"],["104421.1","0","0","0"]],"ts":"1747170434300","checksum":1862860001,"seqId":54226329611,"prevSeqId":54226329539}]}
{"arg":{"channel":"books","instId":"BTC-USDT"},"action":"update","data":[{"asks":[["104457.2","0.28609157","0","3"],["104457.7","0.03619102","0","1"],["104458.4","0.18720546","0","4"],["104458.7","0","0","0"],["104458.9","0.09207182","0","1"],["104459.3","0","0","0"],["104459.9","0.09470914","0","1"],["104460.5","0.09494153","0","1"],["104462.2","0","0","0"],["104462.7","0.02392578","0","1"],["104463.3","0.3410295","0","2"],["104463.4","0.34820507","0","2"],["104463.9","0.31499688","0","2"],["104465.5","0","0","0"],["104465.9","0","0","0"],["104466.8","0.14723745","0","1"],["104467.2","0.24121126","0","1"],["104467.7","0","0","0"],["104468.2","0.04","0","1"],["104468.9","0.25516103","0","1"],["104469.2","0.13879328","0","1"],["104469.4","0.24640296","0","1"],["104470","0.00029006","0","2"],["104471.8","0.00478697","0","1"],["104473","0.25948734","0","1"],["104557.2","0","0","0"],["104561.2","0.00009892","0","1"],["104639.3","0","0","0"],["104639.7","0","0","0"],["104640","0","0","0"],["104641.3","0","0","0"]],"bids":[["104450","0.273074","0","9"],["104440.9","0.00677969","0","6"],["104440.7","0.22813928","0","2"],["104440.6","0.19242972","0","1"],["104439.4","0.18872366","0","2"],["104438.2","0","0","0"],["104438","0.09168139","0","1"],["104437.4","0.126288","0","3"],["104436.8","0.5317786","0","3"],["104436.4","0.16990693","0","1"],["104436.2","0","0","0"],["104435.9","0.16329049","0","1"],["104435.2","0.002","0","1"],["104434.7","0","0","0"],["104434.4","0.16042445","0","2"],["104433.2","0","0","0"],["104432.2","0.25139883","0","1"],["104431.8","0.16258736","0","1"],["104431.6","0.39872511","0","2"],["104430.9","0","0","0"],["104430.5","0","0","0"],["104429.4","0.23763348","0","1"],["104428.2","0","0","0"],["104426.4","0.24230723","0","1"],["104425.5","0.2593094","0","1"],["104425.2","0","0","0"],["104424.3","0.00156669","0","1"],["104422.1","0","0","0"],["104421.1","0.13879328","0","1"],["104407.8","0","0","0"],["104351.4","0","0","0"],["104348.1","0.00011293","0","2"],["104342.6","0.0000203","0","1"]],"ts":"1747170434400","checksum":-1098511745,"seqId":54226329684,"prevSeqId":54226329611}]}
{"arg":{"channel":"books","instId":"BTC-USDT"},"action":"update","data":[{"asks":[["104466.3","0","0","0"],["104469.2","0","0","0"],["104470","0.1390826","0","3"],["104471.1","0.00711203","0","1"],["104639.3","0.00010253","0","1"]],"bids":[["104446","0.03209956","0","1"],["104442.6","0","0","0"],["104422.1","0.13879254","0","1"],["104421.1","0","0","0"],["104362.1","0","0","0"],["104342.4","0.0078311","0","2"]],"ts":"1747170434500","checksum":-813792190,"seqId":54226329699,"prevSeqId":54226329684}]}
{"arg":{"channel":"books","instId":"BTC-USDT"},"action":"update","data":[{"asks":[["104457.4","0.08957653","0","1"],["104457.9","0.094349","0","2"],["104458.4","0.09038516","0","3"],["104458.8","0.08990444","0","1"],["104458.9","0","0","0"],["104459.3","0.00478574","0","1"],["104459.4","0.08752138","0","1"],["104459.9","0","0","0"],["104460","0.00029006","0","2"],["104460.5","0","0","0"],["104462.3","0.15872094","0","1"],["104462.9","0.33454953","0","2"],["104463.3","0.27586627","0","2"],["104463.4","0.19242972","0","1"],["104463.9","0","0","0"],["104465.7","0.14588353","0","1"],["104466.1","0.25655471","0","1"],["104466.8","0","0","0"],["104467.2","0","0","0"],["104467.9","0.24668397","0","1"],["104468.4","0.24326793","0","2"],["104468.8","0.1387937","0","1"],["104468.9","0","0","0"],["104469.4","0","0","0"],["104470","0.00029006","0","2"],["104471.9","0.30582879","0","3"],["104473","0","0","0"],["104482","0","0","0"],["104483","0","0","0"],["104484","0.002","0","2"],["104485","0.85407523","0","3"],["104502","0","0","0"],["104503","0","0","0"],["104504","0.33","0","6"],["104505","0.64453101","0","5"],["104560.3","0.00009567","0","1"],["104561.2","0","0","0"],["104614.6","0.00090504","0","1"],["104639.7","0.00239325","0","1"]],"bids":[["104450","0.153574","0","8"],["104440.9","0.00199377","0","5"],["104440.7","0.20083458","0","2"],["104440.3","0.00478594","0","1"],["104439.4","0","0","0"],["104438.4","0.10137156","0","2"],["104438.3","0.08675174","0","1"],["104438","0","0","0"],["104437.4","0.03426704","0","2"],["104436.9","0.09426704","0","2"],["104436.8","0.33955654","0","2"],["104436.4","0.09183017","0","1"],["104435.9","0","0","0"],["104435.4","0.15593273","0","1"],["104434.8","0.16063546","0","1"],["104434.4","0.000015","0","1"],["104433.4","0.15392058","0","1"],["104432.2","0","0","0"],["104431.8","0","0","0"],["104431.6","0.45126499","0","2"],["104431.1","0.25435213","0","1"],["104430.7","0.15331812","0","2"],["104429.4","0","0","0"],["104428.4","0.24748288","0","1"],["104428","0","0","0"],["104427.5","0.00479824","0","2"],["104426.4","0","0","0"],["104425.5","0","0","0"],["104425.4","0.26358525","0","1"],["104424.4","0.26210842","0","1"],["104422.1","0","0","0"],["104421.1","0.1387937","0","1"],["104348.8","0.00009616","0","1"],["104348.1","0.00001628","0","1"],["104342.4","0","0","0"]],"ts":"1747170434600","checksum":650406563,"seqId":54226329813,"prevSeqId":54226329699}]}
{"arg":{"channel":"books","instId":"BTC-USDT"},"action":"update","data":[{"asks":[["104457.4","0","0","0"],["104457.9","0.00044","0","1"],["104458.5","0.09241513","0","1"],["104458.8","0","0","0"],["104459","0.00478574","0","1"],["104459.3","0","0","0"],["104459.4","0","0","0"],["104462","0.16075529","0","1"],["104462.3","0","0","0"],["104462.9","0","0","0"],["104463.3","0.35419711","0","2"],["104465.4","0.15501638","0","1"],["104465.7","0","0","0"],["104466.1","0","0","0"],["104467.9","0","0","0"],["104468.4","0.00093","0","1"],["104468.8","0","0","0"],["104469.2","0.13879313","0","1"],["104471.9","0.05209157","0","2"],["104477.1","0.00287133","0","1"],["104478.3","0","0","0"],["104640","0.00220843","0","3"],["104641.3","0.03","0","1"],["104642.5","0.0003067","0","1"],["104642.7","0.03","0","1"],["104642.8","0.0288065","0","3"]],"bids":[["104450","0.150374","0","7"],["104446","0","0","0"],["104444.4","0.0001114","0","2"],["104443.1","0.01046174","0","1"],["104443","0.03437247","0","1"],["104440.7","0.13314477","0","1"],["104440.3","0","0","0"],["104439.4","0.00478597","0","1"],["104438.4","0.00001002","0","1"],["104438.3","0","0","0"],["104438","0.09780254","0","1"],["104436.9","0.00098","0","1"],["104436.8","0.46745725","0","3"],["104436.4","0","0","0"],["104435.4","0","0","0"],["104434.8","0","0","0"],["104434.5","0.1440518","0","1"],["104433.4","0","0","0"],["104431.6","0.48448955","0","3"],["104431.1","0","0","0"],["104430.7","0.00007949","0","1"],["104430.4","0.1974117","0","2"],["104428.4","0","0","0"],["104427.5","0.0000125","0","1"],["104427.4","0.03478574","0","2"],["104425.4","0","0","0"],["104424.4","0","0","0"],["104421.1","0.13879313","0","1"],["104342.4","0.0078311","0","2"],["104342.3","0.01152169","0","2"],["104342.1","0.00022221","0","1"],["104342","0.01059526","0","1"],["104341.6","0.0001427","0","2"],["104341.3","0.00001374","0","1"]],"ts":"1747170434700","checksum":1319680552,"seqId":54226329951,"prevSeqId":54226329813}]}
{"arg":{"channel":"books","instId":"BTC-USDT"},"action":"update","data":[{"asks":[["104455.8","0","0","0"],["104457.3","0.09299922","0","1"],["104457.7","0.12773871","0","2"],["104458.1","0","0","0"],["104458.5","0","0","0"],["104458.7","0.09212329","0","1"],["104459","0","0","0"],["104459.1","0.09856613","0","3"],["104459.3","0.08888742","0","1"],["104459.5","0.00478574","0","1"],["104462","0","0","0"],["104462.2","0.15895492","0","1"],["104462.5","0.77866876","0","1"],["104462.7","0.19387649","0","2"],["104462.8","0.16541856","0","1"],["104463.3","0.09333524","0","1"],["104465.4","0","0","0"],["104465.6","0.15348873","0","1"],["104466","0.25938874","0","3"],["104467.7","0.26024267","0","1"],["104467.9","0.13879485","0","1"],["104468.3","0.25947865","0","1"],["104469.2","0","0","0"],["104471.8","0.27187158","0","2"],["104559.7","0.00009435","0","1"],["104560.3","0","0","0"],["104611.9","0.0009082","0","1"],["104614.6","0","0","0"],["104639.7","0","0","0"],["104639.9","0.00239325","0","1"],["104641.3","0","0","0"],["104642.5","0","0","0"],["104642.7","0","0","0"],["104642.8","0","0","0"]],"bids":[["104444.6","0.03209999","0","1"],["104438.2","0.18371059","0","2"],["104438","0","0","0"],["104436.8","0.43060269","0","3"],["104436.3","0.09164038","0","1"],["104435.3","0.1580912","0","2"],["104434.7","0.1492011","0","1"],["104434.5","0","0","0"],["104433.2","0.15656629","0","1"],["104431.6","0.28273687","0","1"],["104431","0.23560666","0","1"],["104430.6","0.16697978","0","2"],["104430.4","0.04","0","1"],["104427.5","0.00479824","0","2"],["104427.4","0.03","0","1"],["104425.3","0.25317633","0","1"],["104424.3","0.2624185","0","2"],["104421.1","0","0","0"],["104418.2","0.13879485","0","1"],["104349","0.00010121","0","1"],["104348.8","0","0","0"],["104342.3","0","0","0"],["104342.1","0","0","0"],["104342","0","0","0"],["104341.6","0","0","0"],["104341.3","0","0","0"]],"ts":"1747170434800","checksum":116790260,"seqId":54226330053,"prevSeqId":54226329951}]}
{"arg":{"channel":"books","instId":"BTC-USDT"},"action":"update","data":[{"asks":[["104450.1","1.33842314","0","25"],["104456.8","0.0001303","0","1"],["104457.1","0.00152861","0","1"],["104457.3","0","0","0"],["104457.6","0.10114125","0","1"],["104457.7","0.03619102","0","1"],["104458.1","0.09852998","0","1"],["104458.6","0.00478574","0","1"],["104458.7","0","0","0"],["104459.1","0.19039672","0","4"],["104459.3","0","0","0"],["104459.5","0","0","0"],["104459.7","0.09286321","0","1"],["104462.2","0","0","0"],["104462.6","0.1606762","0","1"],["104462.7","0.02392578","0","1"],["104462.8","0","0","0"],["104463","0.005","0","1"],["104463.1","0.32726998","0","2"],["104463.3","0.17221619","0","1"],["104465.4","0.13879871","0","1"],["104465.6","0","0","0"],["104466","0.17392944","0","3"],["104466.3","0.24088537","0","1"],["104467.7","0","0","0"],["104467.9","0","0","0"],["104468.1","0.55783755","0","4"],["104468.3","0","0","0"],["104468.6","0.24606722","0","2"],["104471.8","0.00478697","0","1"],["104472.2","0.23647595","0","1"],["104475.5","0.005","0","1"],["104503","0.1","0","2"],["104504","0.28","0","5"],["104505","0.59453101","0","4"],["104554","0","0","0"],["104639.9","0","0","0"],["104640","0","0","0"]],"bids":[["104450","0.14569013","0","7"],["104447.8","0.005","0","1"],["104446","0.0816","0","1"],["104444.6","0","0","0"],["104443.1","0","0","0"],["104440.8","0","0","0"],["104440.7","0","0","0"],["104440.6","0","0","0"],["104439.4","0.00030064","0","1"],["104438.8","0.004786","0","1"],["104438.6","0.18295928","0","2"],["104438.2","0","0","0"],["104437.4","0.00917832","0","1"],["104437.2","0.09091892","0","1"],["104436.8","0.11559504","0","2"],["104436.6","0.09902683","0","1"],["104436.3","0","0","0"],["104435.6","0.16928915","0","1"],["104435.3","0.0051","0","2"],["104435.1","0.14727354","0","1"],["104434.7","0","0","0"],["104433.6","0.2121975","0","2"],["104433.3","0","0","0"],["104433.2","0","0","0"],["104432.8","0.03851916","0","1"],["104431.3","0.24392294","0","1"],["104431","0.15542395","0","1"],["104430.6","0.0000125","0","1"],["104428.6","0.2609186","0","1"],["104427.5","0.0000125","0","1"],["104427","0.00478574","0","1"],["104425.6","0.26473601","0","1"],["104425.3","0","0","0"],["104424.7","0.2574523","0","2"],["104424.3","0.00156669","0","1"],["104418.2","0","0","0"],["104417.8","0.13879873","0","1"],["104342.6","0","0","0"],["104342.4","0","0","0"]],"ts":"1747170434900","checksum":1640851951,"seqId":54226330241,"prevSeqId":54226330053}]}
{"arg":{"channel":"books","instId":"BTC-USDT"},"action":"update","data":[{"asks":[["104458.4","0.05209157","0","2"],["104463","0.3596087","0","2"],["104463.3","0","0","0"],["104464.2","0.03829323","0","1"],["104465.4","0","0","0"],["104465.9","0.13879949","0","1"],["104482","0.002","0","2"],["104483","0.001","0","1"],["104484","0","0","0"],["104485","0.85307523","0","2"],["104502","0.23","0","4"],["104503","0.21499999","0","4"],["104504","0.05","0","1"],["104505","0.47953102","0","2"],["104637.8","0","0","0"],["104639.3","0","0","0"]],"bids":[["104436.8","0.24142078","0","3"],["104431.6","0.45282255","0","2"],["104417.8","0","0","0"],["104416.8","0.13879937","0","1"],["104362.1","0.00002964","0","1"],["104342.8","0","0","0"]],"ts":"1747170435000","checksum":-832688074,"seqId":54226330284,"prevSeqId":54226330241}]}
{"arg":{"channel":"books","instId":"BTC-USDT"},"action":"update","data":[{"asks":[],"bids":[["104439.5","0.00030064","0","1"],["104439.4","0.13735388","0","2"],["104438.8","0","0","0"],["104435.3","0.03018872","0","3"],["104404.1","0.19248461","0","2"],["104403.2","0.00058166","0","2"],["104385.5","0.00014367","0","3"],["104384.7","0.00073664","0","8"]],"ts":"1747170435100","checksum":1053092572,"seqId":54226330313,"prevSeqId":54226330284}]}
{"arg":{"channel":"books","instId":"BTC-USDT"},"action":"update","data":[{"asks":[],"bids":[["104439.4","0.13256788","0","1"],["104438.7","0.00478599","0","1"],["104436.8","0.46681981","0","2"],["104433.7","0.77866876","0","1"],["104343.3","0","0","0"],["104342.9","0","0","0"]],"ts":"1747170435200","checksum":435820082,"seqId":54226330321,"prevSeqId":54226330313}]}
{"arg":{"channel":"books","instId":"BTC-USDT"},"action":"update","data":[{"asks":[["104456.6","0.00153861","0","2"],["104456.7","0.09235758","0","1"],["104457.1","0.0998418","0","1"],["104457.6","0.00478574","0","1"],["104458.1","0.09202403","0","1"],["104458.6","0","0","0"],["104458.7","0.09752833","0","1"],["104459.1","0.09856613","0","3"],["104459.7","0","0","0"],["104461.6","0.15961248","0","1"],["104462.1","0.21394203","0","3"],["104462.2","0.16348445","0","1"],["104462.6","0","0","0"],["104463","0.33464903","0","3"],["104463.1","0","0","0"],["104464","0.13880072","0","1"],["104465","0.16235686","0","1"],["104465.4","0.26057938","0","1"],["104465.9","0","0","0"],["104466","0.00910622","0","2"],["104466.3","0","0","0"],["104467.1","0.25590791","0","1"],["104467.7","0.24946607","0","1"],["104468.1","0.28609157","0","3"],["104468.6","0.00056666","0","1"],["104471.2","0.26632869","0","1"],["104472.2","0","0","0"],["104509.7","0.85922311","0","2"],["104520.2","0.78897017","0","1"],["104541","0.99196903","0","1"],["104628.6","0.234","0","1"],["104633","0","0","0"],["104633.2","0","0","0"],["104633.9","0","0","0"],["104637","0","0","0"],["104637.2","0","0","0"]],"bids":[["104450","0.07453376","0","6"],["104439.2","0","0","0"],["104438.6","0","0","0"],["104438","0.00957146","0","1"],["104437.6","0.18923617","0","2"],["104437.2","0","0","0"],["104436.8","0.28388986","0","3"],["104436.6","0","0","0"],["104436.2","0.09773712","0","1"],["104435.7","0.10134956","0","1"],["104435.6","0","0","0"],["104435.1","0","0","0"],["104434.7","0.16146152","0","1"],["104434.1","0.16251282","0","2"],["104433.7","0","0","0"],["104433.6","0.04622105","0","1"],["104432.6","0.16424911","0","3"],["104431.6","0.44659651","0","2"],["104431.3","0","0","0"],["104431","0","0","0"],["104430.4","0.27641199","0","2"],["104430","0.1466192","0","3"],["104428.6","0","0","0"],["104427.6","0.26155663","0","1"],["104427","0","0","0"],["104425.6","0","0","0"],["104424.9","0.00479574","0","2"],["104424.7","0.26126209","0","2"],["104423.7","0.25410819","0","2"],["104416.8","0","0","0"],["104414.8","0","0","0"],["104413.2","0.13880072","0","1"],["104383.5","0.12756946","0","1"],["104343.3","0.00023233","0","3"],["104342.9","0.00004791","0","1"],["104342.8","0.00076959","0","3"],["104342.6","0.0000203","0","1"],["104342.4","0.0078311","0","2"],["104342.3","0.01152169","0","2"]],"ts":"1747170435300","checksum":-1562440435,"seqId":54226330426,"prevSeqId":54226330321}]}
{"arg":{"channel":"books","instId":"BTC-USDT"},"action":"update","data":[{"asks":[["104448.1","1.43282676","0","26"],["104448.2","0.29193486","0","1"],["104449.9","0.23087896","0","1"],["104450","0.44244972","0","4"],["104450.1","0.53029828","0","7"],["104451","0","0","0"],["104451.3","0","0","0"],["104451.5","0.03609157","0","1"],["104452.9","0.0248692","0","1"],["104453.3","0.00152861","0","1"],["104453.4","0.28525035","0","2"],["104454.2","0.02671815","0","1"],["104455.4","0.12144938","0","2"],["104455.9","0.09254428","0","1"],["104456.6","0.00001","0","1"],["104456.7","0","0","0"],["104456.9","0.08691274","0","1"],["104457.1","0","0","0"],["104457.5","0.09195393","0","1"],["104458","0.46903933","0","1"],["104458.1","0","0","0"],["104458.7","0","0","0"],["104460.2","0","0","0"],["104460.4","0.14452269","0","1"],["104460.9","0.32439895","0","2"],["104461.6","0","0","0"],["104462.1","0.05209157","0","2"],["104462.2","0","0","0"],["104463","0.32937927","0","3"],["104463.7","0.15555275","0","1"],["104464.1","0.3099654","0","3"],["104465","0","0","0"],["104465.4","0","0","0"],["104465.9","0.24367523","0","1"],["104466.4","0.24141003","0","1"],["104467.1","0","0","0"],["104467.7","0","0","0"],["104469.2","0.26274137","0","1"],["104470","0.25315668","0","3"],["104471.2","0","0","0"],["104481","0.002","0","2"],["104482","0.001","0","1"],["104483","0","0","0"],["104502","0.1","0","2"],["104503","0.27999999","0","5"],["104504","0.11499999","0","2"],["104528.1","0.08303","0","3"],["104631.4","0","0","0"]],"bids":[["104450","0","0","0"],["104448","0.15375484","0","3"],["104439.5","0","0","0"],["104439.4","0","0","0"],["104438.5","0.00030064","0","1"],["104437.6","0","0","0"],["104436.8","0.28079417","0","3"],["104436.4","0.18273177","0","2"],["104436.2","0","0","0"],["104435.7","0","0","0"],["104435","0.08920344","0","1"],["104434.7","0","0","0"],["104434.4","0.09673789","0","2"],["104434.1","0.00005","0","1"],["104433.4","0.16509345","0","1"],["104432.9","0.14285813","0","1"],["104432.6","0.00033148","0","2"],["104431.6","0.42213876","0","2"],["104431.4","0.15785413","0","1"],["104430.4","0.04","0","1"],["104430","0.00029006","0","2"],["104429.1","0.24176893","0","1"],["104428.7","0.16314889","0","1"],["104427.6","0","0","0"],["104426.4","0.26529724","0","1"],["104424.7","0.00001169","0","1"],["104423.7","0.00004788","0","1"],["104423.4","0.25049066","0","1"],["104422.5","0.2519877","0","1"],["104421.6","0.00383063","0","1"],["104413.3","0.0502988","0","1"],["104385.1","0","0","0"],["104352.2","0.00288292","0","2"],["104342.8","0","0","0"],["104342.6","0","0","0"],["104342.4","0","0","0"],["104342.3","0","0","0"]],"ts":"1747170435400","checksum":-1886858009,"seqId":54226330733,"prevSeqId":54226330426}]}
{"arg":{"channel":"books","instId":"BTC-USDT"},"action":"update","data":[{"asks":[["104448.1","1.66979616","0","28"],["104450.1","0.52732888","0","6"],["104450.6","0","0","0"],["104451.5","0.07003478","0","2"],["104453.2","0.00943463","0","1"],["104454.2","0","0","0"],["104457.1","0.00478574","0","1"],["104457.6","0","0","0"],["104476.7","0.00287139","0","1"],["104477.1","0","0","0"],["104481","0","0","0"],["104482","0","0","0"],["104484","0.002","0","2"],["104485","0.85407523","0","3"],["104487.6","0.00013995","0","1"],["104489.3","0","0","0"],["104497","0","0","0"],["104502","0","0","0"],["104502.8","0.1","0","1"],["104503","0","0","0"],["104504","0.32999999","0","6"],["104504.8","0","0","0"],["104505","0.64453101","0","5"],["104512.2","0.00081369","0","2"],["104526.2","0","0","0"],["104550.1","0","0","0"],["104577.5","0.03829656","0","1"],["104631.4","0.00001","0","1"],["104633","1.89471219","0","1"],["104633.2","0.04783921","0","4"],["104633.9","0.00014488","0","1"],["104637.2","0.03","0","1"],["104637.8","0.77866876","0","1"]],"bids":[["104440.3","0.06788929","0","1"],["104438.8","0.00030064","0","1"],["104438.5","0","0","0"],["104438","0","0","0"],["104437.6","0.0095715","0","1"],["104436.8","0.49041125","0","2"],["104435.3","0.0051","0","2"],["104433.5","0.77867876","0","2"],["104432","0.02508872","0","1"],["104413.4","0.1388004","0","1"],["104413.3","0","0","0"],["104413.2","0","0","0"],["104389.5","0","0","0"],["104361","0.45439639","0","1"],["104342.9","0","0","0"]],"ts":"1747170435500","checksum":-821728187,"seqId":54226330832,"prevSeqId":54226330733}]}
{"arg":{"channel":"books","instId":"BTC-USDT"},"action":"update","data":[{"asks":[["104448.1","1.44290819","0","28"],["104456.5","0.0001303","0","1"],["104456.8","0","0","0"],["104463.7","0","0","0"],["104463.8","0.14779208","0","1"],["104464","0","0","0"],["104465.8","0.13879947","0","1"],["104471.1","0","0","0"],["104476.7","0","0","0"],["104549.9","0.03829656","0","1"],["104567.3","0.229789","0","1"],["104577.5","0","0","0"],["104598.4","0","0","0"],["104639.1","0.234","0","1"],["104639.3","0.00010253","0","1"]],"bids":[["104448","0.15384484","0","4"],["104439.4","0.00030064","0","1"],["104438.8","0","0","0"],["104436.8","0.29190864","0","2"],["104433.5","0.00001","0","1"],["104428.8","0.19160398","0","2"],["104428.7","0","0","0"],["104426.6","0","0","0"],["104421","0.06735648","0","4"],["104416.8","0.13879947","0","1"],["104413.4","0","0","0"],["104389.6","0","0","0"],["104362.1","0","0","0"],["104360.9","0.00002964","0","1"],["104342.9","0.00004791","0","1"],["104342.8","0.00076959","0","3"],["104342.6","0.0000203","0","1"]],"ts":"1747170435600","checksum":2072301922,"seqId":54226330878,"prevSeqId":54226330832}]}
{"arg":{"channel":"books","instId":"BTC-USDT"},"action":"update","data":[{"asks":[["104448.1","1.43579616","0","27"],["104457.1","0","0","0"],["104462","0.00478574","0","1"],["104465.8","0.13879919","0","1"],["104476.5","0.00288639","0","2"],["104483","0.002","0","2"],["104484","0.001","0","1"],["104485","0.85307523","0","2"],["104503","0.33","0","6"],["104504","0.16499999","0","3"],["104505","0.47953102","0","2"],["104541.4","0.0001","0","1"],["104637.8","0","0","0"],["104639.1","0","0","0"],["104639.3","0","0","0"]],"bids":[["104436.8","0.48902194","0","3"],["104433.7","0.77866876","0","1"],["104429.2","0.00478574","0","1"],["104424.9","0.00001","0","1"],["104417.4","0.13891937","0","2"],["104416.8","0","0","0"],["104342.6","0","0","0"]],"ts":"1747170435700","checksum":730467953,"seqId":54226330932,"prevSeqId":54226330878}]}
