{"arg":{"channel":"books","instId":"BTC-USDT"},"action":"update","data":[{"asks":[["104441.9","0.00478685","0","1"],["104442.9","0","0","0"],["104450","0.13911976","0","3"],["104451.4","0","0","0"],["104464.6","0.00014049","0","1"],["104467.4","0","0","0"],["104473.2","0","0","0"],["104474.5","0","0","0"],["104484.6","0.00004969","0","1"],["104495.3","0.1153369","0","2"],["104505.9","0","0","0"],["104507.3","0","0","0"],["104530.3","0.0022","0","1"],["104614.7","2.88986","0","1"],["104615.1","0.77866876","0","1"],["104615.3","0.29193486","0","1"],["104615.5","0.00001","0","1"]],"bids":[["104424.1","0","0","0"],["104419.5","0.00478681","0","1"],["104419","0","0","0"],["104418.5","0.00030064","0","1"],["104410.3","0.00005","0","1"],["104409","0.00478685","0","1"],["104403.5","0","0","0"],["104401.8","0.13881935","0","1"],["104386.4","0","0","0"],["104381.8","0","0","0"],["104372.5","0.00002032","0","1"],["104371.4","0.00164318","0","2"],["104365.1","0.00287405","0","1"],["104350.5","0.0002956","0","4"],["104343.4","0.00030712","0","2"],["104342.3","0.00058774","0","2"],["104329.9","0.00001038","0","1"]],"ts":"1747170450100","checksum":-1050797844,"seqId":54226344702,"prevSeqId":54226344638}]}
{"arg":{"channel":"books","instId":"BTC-USDT"},"action":"update","data":[{"asks":[["104449","0.16610223","0","1"],["104468","0.86582801","0","1"],["104473","1.41863684","0","1"],["104476","0","0","0"],["104479","0.32999999","0","6"],["104504.3","2.54094289","0","1"],["104615.3","0","0","0"],["104615.5","0","0","0"]],"bids":[["104419.5","0","0","0"],["104419","0.00478689","0","1"],["104381.8","1.41095079","0","1"],["104350.5","2.61247033","0","5"],["104329.9","0","0","0"]],"ts":"1747170450200","checksum":480919191,"seqId":54226344742,"prevSeqId":54226344702}]}
{"arg":{"channel":"books","instId":"BTC-USDT"},"action":"update","data":[{"asks":[["104448","0.00287224","0","1"],["104457","0.17796783","0","1"],["104458","0","0","0"],["104460","0.00420843","0","5"],["104461","0.001","0","1"],["104479","0","0","0"],["104480","0.00221843","0","4"],["104481","0.33","0","6"],["104482","0.16499999","0","3"],["104614.7","0","0","0"],["104615.1","0","0","0"]],"bids":[],"ts":"1747170450300","checksum":480919191,"seqId":54226344791,"prevSeqId":54226344742}]}
{"arg":{"channel":"books","instId":"BTC-USDT"},"action":"update","data":[{"asks":[["104449.1","0","0","0"],["104614.7","2.88986","0","1"]],"bids":[],"ts":"1747170450400","checksum":480919191,"seqId":54226344795,"prevSeqId":54226344791}]}
{"arg":{"channel":"books","instId":"BTC-USDT"},"action":"update","data":[{"asks":[["104449.1","0.0001303","0","1"],["104450","0.13911921","0","3"],["104458","0.002","0","2"],["104459","0.001","0","1"],["104460","0.00220843","0","3"],["104461","0","0","0"],["104479","0.26","0","4"],["104480","0.13221842","0","6"],["104481","0.07","0","2"],["104482","0.035","0","1"],["104610.2","0","0","0"],["104612","0","0","0"],["104614.7","0","0","0"]],"bids":[["104402.4","0.13881915","0","1"],["104401.8","0","0","0"]],"ts":"1747170450500","checksum":480919191,"seqId":54226344823,"prevSeqId":54226344795}]}
{"arg":{"channel":"books","instId":"BTC-USDT"},"action":"update","data":[{"asks":[["104426.1","0.28157622","0","12"],["104434.6","0.093336","0","1"],["104434.7","0","0","0"],["104435.1","0.09873637","0","1"],["104435.2","0","0","0"],["104439.3","0.04338244","0","2"],["104440.1","0.38447554","0","4"],["104440.2","0","0","0"],["104443.3","0.2297791","0","1"],["104443.4","0","0","0"],["104445.1","0.23756224","0","1"],["104445.2","0","0","0"],["104445.6","1.02867765","0","2"],["104445.7","0.56595","0","1"],["104448.9","0.13882056","0","1"],["104450","0.00030006","0","2"],["104479","0.33","0","6"],["104480","0.16721842","0","7"],["104481","0","0","0"],["104482","0","0","0"],["104610.2","0.027","0","1"],["104612","0.00011471","0","1"]],"bids":[["104415.7","0","0","0"],["104415.6","0.18642184","0","3"],["104415","0.20731506","0","2"],["104413.7","0","0","0"],["104413.6","0.095336","0","2"],["104412.7","0","0","0"],["104412.6","0.15221353","0","1"],["104410.8","0.50799308","0","3"],["104410.7","0.77866876","0","1"],["104410.6","0.16869171","0","1"],["104408.4","0","0","0"],["104408.3","0.24644309","0","1"],["104405.7","0","0","0"],["104405.6","0.23773831","0","1"],["104402.7","0","0","0"],["104402.6","0.27355262","0","1"],["104402.4","0","0","0"],["104401.3","0.13882056","0","1"],["104329.9","0.00001038","0","1"]],"ts":"1747170450600","checksum":-1994148674,"seqId":54226344884,"prevSeqId":54226344823}]}
{"arg":{"channel":"books","instId":"BTC-USDT"},"action":"update","data":[{"asks":[["104432.8","0.00001","0","1"],["104433","0.02750745","0","1"],["104445.8","0","0","0"],["104448.7","0.00001","0","1"],["104448.8","0.16610223","0","1"],["104449","0","0","0"],["104457","0.17996783","0","3"],["104458","0.001","0","1"],["104459","0","0","0"],["104473.8","0.70849188","0","1"],["104478","0.33","0","6"],["104479","0.16499999","0","3"],["104480","0.00221843","0","4"],["104610","0","0","0"],["104610.2","0","0","0"],["104612","0","0","0"]],"bids":[["104419","0.00478684","0","1"],["104382.1","0.56951872","0","1"],["104329.9","0","0","0"]],"ts":"1747170450700","checksum":-1347466822,"seqId":54226344917,"prevSeqId":54226344884}]}
{"arg":{"channel":"books","instId":"BTC-USDT"},"action":"update","data":[{"asks":[["104430.8","0.02750802","0","1"],["104435.3","0","0","0"],["104441.1","0.00478685","0","1"],["104441.9","0","0","0"],["104442.9","0.15012072","0","1"],["104443","0","0","0"],["104447.3","0.30492529","0","2"],["104448.8","0","0","0"],["104448.9","0","0","0"],["104478","0.26","0","4"],["104479","0.19999999","0","4"],["104480","0.03721843","0","5"],["104610","0.29270107","0","3"]],"bids":[["104424.6","0.00601038","0","2"],["104422.7","0","0","0"],["104420.5","0.0280276","0","2"],["104420.1","0.02387872","0","1"],["104419","0","0","0"],["104418.6","0.00478691","0","1"],["104409.7","0.04613958","0","2"],["104409","0","0","0"],["104408.4","0.00478685","0","1"],["104408","0","0","0"],["104407.9","0.1597304","0","2"],["104401.3","0","0","0"],["104399.5","0.55500474","0","2"],["104329.9","0.00001038","0","1"],["104329.8","0.07302275","0","4"]],"ts":"1747170450800","checksum":983778853,"seqId":54226344976,"prevSeqId":54226344917}]}
{"arg":{"channel":"books","instId":"BTC-USDT"},"action":"update","data":[{"asks":[["104426.1","0.52157622","0","13"],["104427.9","0.24","0","1"],["104431.6","0.71512286","0","2"],["104431.7","0","0","0"],["104431.8","0","0","0"],["104433.9","0.09105304","0","1"],["104434.4","0.09810441","0","1"],["104434.6","0","0","0"],["104435.1","0","0","0"],["104435.3","0.08686023","0","1"],["104436","0.08987098","0","1"],["104436.1","0","0","0"],["104436.7","0.00001","0","1"],["104437.1","0.2843023","0","2"],["104438.8","0.14462254","0","1"],["104439.4","0.36553829","0","4"],["104439.6","0","0","0"],["104440.1","0.05209157","0","2"],["104442.1","0.85270727","0","5"],["104442.2","0.14900867","0","1"],["104442.6","0.24906301","0","1"],["104442.9","0","0","0"],["104443.3","0","0","0"],["104444.4","0.25079903","0","1"],["104444.9","0.31227426","0","2"],["104445.1","0","0","0"],["104445.6","0.77866876","0","1"],["104448.5","0.23393327","0","1"],["104449.2","0.03589513","0","1"],["104457","0.17796783","0","1"],["104458","0.002","0","2"],["104459","0.001","0","1"],["104478","0","0","0"],["104479","0.32999999","0","6"],["104480","0.16721842","0","7"],["104505.2","0.47060865","0","1"],["104535.7","0","0","0"],["104610","0","0","0"]],"bids":[["104426","0.14393927","0","14"],["104418.6","0","0","0"],["104418.5","0","0","0"],["104418.3","0.00030064","0","1"],["104417.5","0.00478691","0","1"],["104415.6","0.00957352","0","1"],["104415","0.27359209","0","2"],["104414.9","0.09962723","0","2"],["104414.8","0.08696131","0","1"],["104414.2","0","0","0"],["104413.6","0.000015","0","1"],["104413.5","0.09219203","0","1"],["104412.9","0.09904629","0","1"],["104412.6","0","0","0"],["104412.1","0","0","0"],["104411.9","0.15990385","0","1"],["104411.3","0.16243979","0","2"],["104410.8","0.35671988","0","2"],["104410.6","0","0","0"],["104409.9","0.16230503","0","1"],["104408.7","0.00478685","0","1"],["104408.4","0","0","0"],["104408.3","0","0","0"],["104407.9","0.00002454","0","1"],["104407.6","0.23472462","0","1"],["104407.2","0.14910438","0","2"],["104405.6","0","0","0"],["104404.9","0.58348552","0","3"],["104402.6","0","0","0"],["104401.9","0.25419906","0","1"],["104401.7","0","0","0"],["104401","0.24747599","0","2"],["104329.6","0.00001647","0","1"]],"ts":"1747170450900","checksum":1351718890,"seqId":54226345078,"prevSeqId":54226344976}]}
{"arg":{"channel":"books","instId":"BTC-USDT"},"action":"update","data":[{"asks":[["104426.1","0.28157622","0","12"],["104427.8","0.27873458","0","1"],["104428","0.02508872","0","1"],["104430.8","0","0","0"],["104431.6","0.62341233","0","3"],["104433.9","0","0","0"],["104434.4","0","0","0"],["104434.5","0.08984959","0","1"],["104434.9","0.09885188","0","1"],["104435.3","0","0","0"],["104435.9","0.12450128","0","3"],["104436","0","0","0"],["104436.5","0.08967737","0","1"],["104437.1","0.28550309","0","2"],["104438.3","0.05356026","0","1"],["104438.8","0","0","0"],["104439.4","0.20302761","0","3"],["104439.9","0.1618119","0","1"],["104440","0.14962403","0","3"],["104442.1","0.80880467","0","5"],["104442.2","0","0","0"],["104442.6","0","0","0"],["104442.8","0.16027023","0","1"],["104443.2","0.26176657","0","1"],["104444.4","0","0","0"],["104444.9","0.3088366","0","2"],["104445.5","0.24262431","0","1"],["104447.3","0.16610223","0","1"],["104448.5","0","0","0"],["104448.9","0.1388201","0","1"],["104449","0.26085282","0","1"],["104452.6","0.099963","0","2"],["104474.9","0","0","0"]],"bids":[["104426","0.23574927","0","14"],["104424.9","0.02387764","0","1"],["104420.1","0","0","0"],["104418.2","0","0","0"],["104417.5","0.00478692","0","1"],["104415.6","0.06308282","0","2"],["104415.4","0.18781293","0","2"],["104415","0.22438189","0","2"],["104414.9","0.00098","0","1"],["104414.8","0","0","0"],["104414","0.10009637","0","1"],["104413.5","0.10244079","0","1"],["104412.9","0","0","0"],["104412.5","0.16926972","0","1"],["104411.9","0.1583496","0","1"],["104411.3","0.005","0","1"],["104410.4","0.15011752","0","1"],["104409.9","0","0","0"],["104409.7","0.00098","0","1"],["104408.2","0.35348528","0","3"],["104407.8","0.15880399","0","1"],["104407.6","0","0","0"],["104407.2","0.00001147","0","1"],["104405.4","0.27099997","0","1"],["104404.9","0.3392344","0","2"],["104402.5","0.26439669","0","1"],["104401.9","0","0","0"],["104401.6","0.1388201","0","1"],["104401.5","0.25426942","0","1"],["104401","0.00023525","0","1"],["104399.5","0.41618168","0","1"],["104382.1","0","0","0"],["104382","0.000015","0","1"],["104376","0.48324487","0","1"],["104335","0.00010095","0","1"],["104329.9","0","0","0"],["104329.8","0","0","0"],["104329.6","0","0","0"]],"ts":"1747170451000","checksum":-500608642,"seqId":54226345264,"prevSeqId":54226345078}]}
{"arg":{"channel":"books","instId":"BTC-USDT"},"action":"update","data":[{"asks":[["104434.9","0","0","0"],["104435","0.09642061","0","1"],["104435.9","0.03424552","0","2"],["104436","0.08822543","0","1"],["104436.5","0","0","0"],["104436.6","0.10039059","0","1"],["104439.4","0.05209157","0","2"],["104439.5","0.15793541","0","1"],["104439.9","0","0","0"],["104440","0.31952706","0","4"],["104442.8","0","0","0"],["104442.9","0.15913199","0","1"],["104444.9","0.04","0","1"],["104445","0.30858106","0","3"],["104449","0","0","0"],["104449.1","0.26643369","0","2"],["104457","0.17996783","0","3"],["104458","0.001","0","1"],["104459","0","0","0"],["104478","0.23","0","4"],["104479","0.21499999","0","4"],["104480","0.05221843","0","5"]],"bids":[["104420.5","0.01525134","0","1"],["104418.2","0.0047869","0","1"],["104417.5","0","0","0"],["104415.5","0.18980918","0","2"],["104415.4","0","0","0"],["104415","0.20984916","0","2"],["104414.1","0.09564174","0","1"],["104414","0","0","0"],["104412","0.14777855","0","1"],["104411.9","0","0","0"],["104410.5","0.15512662","0","1"],["104410.4","0","0","0"],["104407.9","0.15089784","0","2"],["104407.8","0","0","0"],["104405.5","0.26506185","0","1"],["104405.4","0","0","0"],["104401.6","0.40181362","0","2"],["104401.5","0","0","0"],["104371.4","0.00107652","0","1"],["104370.1","0.000577","0","2"],["104342.3","0.00002108","0","1"],["104341.1","0.00056666","0","1"],["104329.9","0.00001038","0","1"]],"ts":"1747170451100","checksum":-2030032965,"seqId":54226345361,"prevSeqId":54226345264}]}
{"arg":{"channel":"books","instId":"BTC-USDT"},"action":"update","data":[{"asks":[["104427.8","0.1439522","0","1"],["104427.9","0","0","0"],["104439.3","0.02393114","0","1"],["104478","0.33","0","6"],["104479","0.16499999","0","3"],["104480","0.00221843","0","4"],["104606.7","0.00037885","0","1"]],"bids":[["104418.2","0.00478686","0","1"],["104355.1","0","0","0"],["104329.8","0.07302275","0","4"]],"ts":"1747170451200","checksum":1207740030,"seqId":54226345381,"prevSeqId":54226345361}]}
{"arg":{"channel":"books","instId":"BTC-USDT"},"action":"update","data":[{"asks":[["104426.1","0.28127634","0","12"],["104433.3","0.01945099","0","1"],["104448.9","0","0","0"],["104449","0.13882112","0","1"],["104457","0.17796783","0","1"],["104458","0.002","0","2"],["104459","0.001","0","1"],["104478","0","0","0"],["104479","0.32999999","0","6"],["104480","0.16721842","0","7"],["104609.9","0","0","0"]],"bids":[["104418.2","0.00478692","0","1"],["104401.6","0.26299352","0","1"],["104400.8","0.13882112","0","1"],["104329.8","0","0","0"]],"ts":"1747170451300","checksum":-1826696804,"seqId":54226345428,"prevSeqId":54226345381}]}
{"arg":{"channel":"books","instId":"BTC-USDT"},"action":"update","data":[{"asks":[["104438.2","0.00478685","0","1"],["104441.1","0","0","0"],["104457","0.17996783","0","3"],["104458","0.001","0","1"],["104459","0","0","0"],["104478","0.33","0","6"],["104479","0.16499999","0","3"],["104480","0.00221843","0","4"]],"bids":[["104408.7","0","0","0"],["104405.6","0.00478685","0","1"]],"ts":"1747170451400","checksum":-1826696804,"seqId":54226345449,"prevSeqId":54226345428}]}
{"arg":{"channel":"books","instId":"BTC-USDT"},"action":"update","data":[{"asks":[["104438.2","0","0","0"],["104439.3","0.02871799","0","2"],["104609.9","0.01089628","0","1"]],"bids":[["104407","0.00478685","0","1"],["104405.6","0","0","0"],["104355.1","0.00002965","0","1"],["104329.9","0","0","0"]],"ts":"1747170451500","checksum":-1826696804,"seqId":54226345460,"prevSeqId":54226345449}]}
{"arg":{"channel":"books","instId":"BTC-USDT"},"action":"update","data":[{"asks":[],"bids":[["104397.7","0.00002","0","2"],["104330","0","0","0"]],"ts":"1747170451600","checksum":-1826696804,"seqId":54226345464,"prevSeqId":54226345460}]}
{"arg":{"channel":"books","instId":"BTC-USDT"},"action":"update","data":[{"asks":[["104426.1","0.52127634","0","13"],["104430.5","0","0","0"],["104430.6","0.00152861","0","1"],["104431.6","0.53335627","0","2"],["104434.4","0.09150225","0","1"],["104434.5","0","0","0"],["104434.9","0.0939797","0","1"],["104435","0","0","0"],["104435.8","0.0873643","0","1"],["104436","0","0","0"],["104436.5","0.09797308","0","1"],["104436.6","0","0","0"],["104437.1","0.15299061","0","1"],["104438.2","0.00478685","0","1"],["104439.3","0.18163943","0","2"],["104439.5","0","0","0"],["104439.9","0.31395805","0","2"],["104440","0.00030006","0","2"],["104442.7","0.16367402","0","1"],["104442.9","0","0","0"],["104443.1","0.25277505","0","1"],["104443.2","0","0","0"],["104444.9","0.30158734","0","2"],["104445","0.04185417","0","2"],["104445.4","0.25951706","0","1"],["104445.5","0","0","0"],["104449","0.3986232","0","2"],["104449.1","0.0001303","0","1"],["104457","0.17796783","0","1"],["104458","0.002","0","2"],["104459","0.001","0","1"],["104478","0","0","0"],["104479","0.32999999","0","6"],["104480","0.16721842","0","7"],["104499.2","1.00807876","0","1"],["104609.9","0","0","0"]],"bids":[["104418.3","0","0","0"],["104418.2","0.00030064","0","1"],["104417.5","0.00478693","0","1"],["104415.5","0","0","0"],["104415.4","0.09947732","0","1"],["104415.3","0.08677266","0","1"],["104415","0.06300106","0","1"],["104414.1","0","0","0"],["104414","0.09088112","0","1"],["104413.5","0","0","0"],["104413.4","0.10183593","0","1"],["104412.5","0","0","0"],["104412.4","0.16669549","0","1"],["104412","0","0","0"],["104411.8","0.14566524","0","1"],["104410.5","0","0","0"],["104410.4","0.15073304","0","1"],["104408.2","0.10227281","0","2"],["104408.1","0.24539734","0","1"],["104407.9","0.00002454","0","1"],["104407.7","0.16273308","0","1"],["104407","0","0","0"],["104405.5","0","0","0"],["104405.4","0.25205203","0","1"],["104405","0.00478685","0","1"],["104404.9","0.21150927","0","1"],["104402.5","0","0","0"],["104402.4","0.2581167","0","1"],["104401.6","0","0","0"],["104401.5","0.26077747","0","1"],["104377.8","0.69947766","0","1"],["104330.8","0","0","0"],["104330.4","0","0","0"],["104330.3","0","0","0"]],"ts":"1747170451900","checksum":-1087638961,"seqId":54226345554,"prevSeqId":54226345464}]}
{"arg":{"channel":"books","instId":"BTC-USDT"},"action":"update","data":[{"asks":[["104431.6","0.62990305","0","3"],["104437.1","0.29861411","0","2"]],"bids":[["104415","0.21731414","0","2"],["104404.9","0.38094916","0","2"]],"ts":"1747170452000","checksum":-68032012,"seqId":54226345559,"prevSeqId":54226345554}]}
{"arg":{"channel":"books","instId":"BTC-USDT"},"action":"update","data":[{"asks":[["104437.5","0.00478685","0","1"],["104438.2","0.16959818","0","1"],["104446.5","0.13882327","0","1"],["104447.3","0","0","0"],["104449","0.25980208","0","1"],["104609.8","0","0","0"]],"bids":[["104422.2","0.02387826","0","1"],["104420.5","0","0","0"],["104418.8","0.01287355","0","1"],["104418.7","0.02508872","0","1"],["104418.5","0.00030064","0","1"],["104418.2","0","0","0"],["104417.3","0","0","0"],["104412.2","0","0","0"],["104405.5","0.00478685","0","1"],["104405","0","0","0"],["104400.8","0","0","0"],["104399.6","0","0","0"],["104399.1","0.13882368","0","1"],["104370.1","0.00001034","0","1"],["104368.6","0.00068155","0","2"],["104341.1","0","0","0"],["104339.5","0.00066261","0","3"],["104330.8","0.00005735","0","1"],["104330.4","0.000015","0","1"]],"ts":"1747170452100","checksum":-366262967,"seqId":54226345611,"prevSeqId":54226345559}]}
{"arg":{"channel":"books","instId":"BTC-USDT"},"action":"update","data":[{"asks":[["104437.5","0","0","0"],["104439.2","0.00478685","0","1"],["104445.6","0.91749313","0","2"],["104446.5","0","0","0"],["104609.8","0.01089628","0","1"]],"bids":[["104424.9","0","0","0"],["104418.8","0.01317419","0","2"],["104418.5","0","0","0"],["104411.9","0.19242972","0","1"],["104407.8","0.00478685","0","1"],["104405.5","0","0","0"],["104399.1","0","0","0"],["104398.3","0.13882437","0","1"],["104330.3","0.00173904","0","1"]],"ts":"1747170452200","checksum":1958747521,"seqId":54226345673,"prevSeqId":54226345611}]}
{"arg":{"channel":"books","instId":"BTC-USDT"},"action":"update","data":[{"asks":[["104426.1","0.28127634","0","12"],["104428","0","0","0"],["104430.7","0","0","0"],["104431.6","0.26405405","0","2"],["104434.3","0.10114748","0","1"],["104434.4","0","0","0"],["104434.8","0.10073645","0","1"],["104434.9","0","0","0"],["104435.7","0.0890729","0","1"],["104435.8","0","0","0"],["104436.4","0.09063842","0","1"],["104436.5","0","0","0"],["104439.1","0.00478685","0","1"],["104439.2","0.15885492","0","1"],["104439.3","0.02393114","0","1"],["104439.8","0.32644521","0","2"],["104439.9","0","0","0"],["104442.6","0.15777113","0","1"],["104442.7","0","0","0"],["104443","0.25442574","0","1"],["104443.1","0","0","0"],["104444.8","0.27093929","0","1"],["104444.9","0.04","0","1"],["104445.3","0.30885356","0","2"],["104445.4","0","0","0"],["104445.6","0.77866876","0","1"],["104447.3","0.13882282","0","1"],["104448.9","0.25703345","0","1"],["104449","0","0","0"],["104473","0","0","0"],["104479","0.33","0","6"],["104504.3","0","0","0"],["104609.9","0.01089628","0","1"],["104610","0.29270107","0","3"]],"bids":[["104426","0.24576927","0","15"],["104421.2","0.02238514","0","1"],["104421.1","0.02833255","0","1"],["104418.8","0.00030064","0","1"],["104415.4","0","0","0"],["104415.3","0.10131382","0","1"],["104415.2","0.09630889","0","1"],["104415","0.21200095","0","2"],["104414","0","0","0"],["104413.9","0.10013426","0","2"],["104413.4","0","0","0"],["104413.3","0.09239885","0","1"],["104412.4","0","0","0"],["104412.3","0.15498939","0","1"],["104411.8","0","0","0"],["104411.7","0.14911217","0","1"],["104410.4","0","0","0"],["104410.3","0.15002486","0","2"],["104410.2","0","0","0"],["104408.1","0","0","0"],["104408","0.23254577","0","1"],["104407.8","0","0","0"],["104407.7","0","0","0"],["104407.6","0.15025978","0","1"],["104407","0.00478685","0","1"],["104405.4","0.36225331","0","1"],["104405.3","0.25678397","0","1"],["104404.9","0","0","0"],["104402.4","0","0","0"],["104402.3","0.31345212","0","2"],["104401.5","0","0","0"],["104401.4","0.25044732","0","1"],["104399.6","0.13882282","0","1"],["104398.3","0","0","0"],["104330","0.00356554","0","4"],["104329.9","0.00001038","0","1"]],"ts":"1747170452300","checksum":2114272460,"seqId":54226345877,"prevSeqId":54226345673}]}
{"arg":{"channel":"books","instId":"BTC-USDT"},"action":"update","data":[{"asks":[["104427.8","0","0","0"],["104428","0.02204352","0","1"],["104430.6","0","0","0"],["104431.5","0.00152861","0","1"],["104431.6","0.2316072","0","2"],["104434.3","0","0","0"],["104434.6","0.09028801","0","1"],["104434.8","0","0","0"],["104435.1","0.10199389","0","1"],["104435.7","0","0","0"],["104436","0.09339958","0","1"],["104436.4","0","0","0"],["104436.7","0.0897615","0","2"],["104438.2","0.17438503","0","2"],["104439.1","0","0","0"],["104439.2","0","0","0"],["104439.5","0.14520382","0","1"],["104439.8","0","0","0"],["104440.1","0.35978366","0","4"],["104442.1","0.55302923","0","4"],["104442.6","0","0","0"],["104442.9","0.1671971","0","1"],["104443","0","0","0"],["104443.3","0.2501486","0","1"],["104444.8","0","0","0"],["104445.1","0.25284397","0","1"],["104445.3","0.04","0","1"],["104445.6","0.26204126","0","1"],["104445.7","0","0","0"],["104447.4","0.56486703","0","2"],["104448.9","0","0","0"],["104449.2","0.27284095","0","2"],["104451.4","0.77866876","0","1"],["104458","0","0","0"],["104459","0","0","0"],["104460","0.00420843","0","5"],["104461","0.001","0","1"],["104464.6","0.56400049","0","2"],["104468","0.50420294","0","1"],["104479","0","0","0"],["104480","0.00221843","0","4"],["104481","0.33","0","6"],["104482","0.16499999","0","3"],["104535.7","0.3676891","0","1"],["104610.2","0.027","0","1"],["104612","0.00011471","0","1"],["104614.7","2.88986","0","1"]],"bids":[["104424.2","0.02761497","0","1"],["104419","0.00030064","0","1"],["104418.8","0","0","0"],["104418.2","0.00478692","0","1"],["104417.5","0","0","0"],["104415.6","0.15390931","0","3"],["104415.5","0.08682038","0","1"],["104415.3","0","0","0"],["104415.2","0","0","0"],["104415","0.16636673","0","2"],["104414.2","0.09561665","0","1"],["104413.9","0.00926752","0","1"],["104413.6","0.09055054","0","2"],["104413.3","0","0","0"],["104412.6","0.16171542","0","1"],["104412.3","0","0","0"],["104412","0.14910089","0","1"],["104411.7","0","0","0"],["104410.8","0.50330935","0","3"],["104410.6","0.1571109","0","1"],["104410.3","0.00005","0","1"],["104408.3","0.26103773","0","1"],["104408","0","0","0"],["104407.9","0.15597283","0","2"],["104407.6","0","0","0"],["104407","0","0","0"],["104405.7","0.00478685","0","1"],["104405.6","0.2642071","0","1"],["104405.4","0.32754834","0","2"],["104405.3","0","0","0"],["104402.6","0.2459096","0","1"],["104402.3","0.071789","0","1"],["104401.7","0.23317343","0","1"],["104401.4","0","0","0"],["104399.6","0.5079046","0","2"],["104329.9","0","0","0"]],"ts":"1747170452400","checksum":1450651939,"seqId":54226346010,"prevSeqId":54226345877}]}
{"arg":{"channel":"books","instId":"BTC-USDT"},"action":"update","data":[{"asks":[["104426.6","0.02508872","0","1"],["104428","0.07747558","0","2"],["104431.4","0.00152861","0","1"],["104431.5","0.19242972","0","1"],["104434.5","0.10220119","0","1"],["104434.6","0","0","0"],["104435","0.10219084","0","1"],["104435.1","0","0","0"],["104436.6","0.09308588","0","1"],["104436.7","0.00001","0","1"],["104440","0.31262301","0","4"],["104440.1","0.05209157","0","2"],["104442.1","0.48760588","0","5"],["104442.8","0.16265032","0","1"],["104442.9","0","0","0"],["104443.2","0.24954908","0","1"],["104443.3","0","0","0"],["104445","0.3004777","0","3"],["104445.1","0","0","0"],["104445.5","0.24542269","0","1"],["104445.6","0","0","0"],["104449.1","0.24658245","0","2"],["104449.2","0.03589513","0","1"],["104464.5","0.00015052","0","2"],["104464.6","0.56386","0","1"],["104472.8","1.39333015","0","1"],["104504.2","2.55487686","0","2"],["104610.2","0","0","0"],["104612","0","0","0"],["104614.7","0","0","0"]],"bids":[["104415.6","0.34425066","0","3"],["104415.5","0.18893816","0","2"],["104415","0","0","0"],["104414.2","0","0","0"],["104414.1","0.09028048","0","1"],["104413.6","0.000015","0","1"],["104413.5","0.10221408","0","1"],["104412.6","0","0","0"],["104412.5","0.1611394","0","1"],["104410.8","0.35671988","0","2"],["104410.6","0","0","0"],["104410.5","0.15752925","0","1"],["104408.3","0","0","0"],["104408.2","0.34631977","0","3"],["104407.9","0.00002454","0","1"],["104407.8","0.14853414","0","1"],["104405.6","0","0","0"],["104405.5","0.2566537","0","1"],["104402.6","0","0","0"],["104402.5","0.27077764","0","1"],["104401.7","0","0","0"],["104401.6","0.26700149","0","1"]],"ts":"1747170452500","checksum":2077378359,"seqId":54226346068,"prevSeqId":54226346010}]}
{"arg":{"channel":"books","instId":"BTC-USDT"},"action":"update","data":[{"asks":[["104428.5","0","0","0"],["104438.2","0.16959818","0","1"],["104441.1","0.00478685","0","1"],["104447.3","0","0","0"],["104448","0.14169372","0","2"],["104458","0.002","0","2"],["104459","0.001","0","1"],["104460","0.00220843","0","3"],["104461","0","0","0"],["104478","0.16","0","2"],["104479","0.24999999","0","5"],["104480","0.08721843","0","6"],["104481","0","0","0"],["104482","0","0","0"]],"bids":[["104409","0.00478685","0","1"],["104405.7","0","0","0"],["104400.1","0.13882148","0","1"],["104399.6","0.36908178","0","1"],["104389.2","0.00221","0","2"],["104371.7","0.0022","0","1"],["104362.9","0","0","0"],["104330","0","0","0"]],"ts":"1747170452600","checksum":-941519453,"seqId":54226346142,"prevSeqId":54226346068}]}
{"arg":{"channel":"books","instId":"BTC-USDT"},"action":"update","data":[{"asks":[["104424.1","0.88005869","0","14"],["104424.6","0.45755015","0","1"],["104426","0.33424397","0","4"],["104426.1","0.36384449","0","7"],["104428","0","0","0"],["104428.1","0.05524195","0","2"],["104428.8","0.00001","0","1"],["104431.4","0.36908178","0","1"],["104431.6","0.41772831","0","2"],["104431.9","0.00044","0","1"],["104433.2","0.00478685","0","1"],["104434.5","0","0","0"],["104434.6","0.234","0","1"],["104435","0","0","0"],["104435.9","0.03379552","0","1"],["104436","0","0","0"],["104436.6","0","0","0"],["104436.9","0.59797615","0","1"],["104437","0.77866876","0","1"],["104437.1","0","0","0"],["104437.2","0.00093","0","1"],["104439.5","0","0","0"],["104440","0.00030006","0","2"],["104441.1","0","0","0"],["104441.2","0.05209157","0","2"],["104442.1","0.32935142","0","5"],["104442.4","0.00093","0","1"],["104442.8","0","0","0"],["104443.2","0","0","0"],["104444.8","0.13882629","0","1"],["104445","0.04185417","0","2"],["104445.5","0","0","0"],["104446.4","0","0","0"],["104447.6","0.00669798","0","2"],["104448","0.00287224","0","1"],["104449.1","0.0001303","0","1"],["104450.5","0.129","0","4"],["104451.6","0","0","0"],["104452.7","0.00287202","0","1"],["104452.8","0.00191","0","1"],["104452.9","0.19242972","0","1"],["104456.8","0","0","0"],["104457","0.17996783","0","3"],["104458","0.001","0","1"],["104459","0","0","0"],["104461.7","0.17796783","0","1"],["104474.1","0.016","0","1"],["104478","0.33","0","6"],["104479","0.16499999","0","3"],["104480","0.00221843","0","4"],["104492.4","0","0","0"],["104505.2","0","0","0"],["104535.7","0","0","0"],["104610.2","0.027","0","1"],["104612","0.00011471","0","1"],["104612.9","0.00001168","0","1"]],"bids":[["104426","0","0","0"],["104425.9","0","0","0"],["104424.7","0","0","0"],["104424.6","0","0","0"],["104424.3","0","0","0"],["104424.2","0","0","0"],["104424","0.06531109","0","2"],["104421.7","0.02833237","0","1"],["104421.2","0","0","0"],["104421.1","0","0","0"],["104420.2","0","0","0"],["104419","0","0","0"],["104418.7","0","0","0"],["104418.2","0","0","0"],["104416.4","0.00030064","0","1"],["104416.2","0.0005","0","1"],["104415.7","0.1009732","0","2"],["104415.6","0.0535093","0","1"],["104415.5","0","0","0"],["104414.9","0","0","0"],["104414.6","0.00478702","0","1"],["104414.1","0","0","0"],["104413.6","0.0095887","0","2"],["104413.5","0","0","0"],["104412.5","0","0","0"],["104412.1","0.04812654","0","1"],["104412","0","0","0"],["104411.9","0","0","0"],["104410.9","0.00098","0","1"],["104410.8","0.23889088","0","3"],["104410.7","0","0","0"],["104410.5","0","0","0"],["104409.7","0","0","0"],["104409","0","0","0"],["104408.2","0.02928909","0","1"],["104407.8","0","0","0"],["104405.7","0.00098","0","1"],["104405.5","0","0","0"],["104405.4","0.21008393","0","1"],["104404.5","0","0","0"],["104402.5","0","0","0"],["104402.3","0","0","0"],["104401.6","0","0","0"],["104401.5","0.23886941","0","1"],["104401.3","0.00478685","0","1"],["104400.5","0.00191","0","1"],["104400.1","0","0","0"],["104399.6","0","0","0"],["104399.5","0.59255523","0","2"],["104399.3","0","0","0"],["104397.6","0.00383151","0","1"],["104397.1","0.13882629","0","1"],["104395.3","0.00191","0","1"],["104393.3","0.07187957","0","3"],["104330","0.00356554","0","4"],["104329.9","0.00001038","0","1"],["104329.8","0.07302275","0","4"],["104329.6","0.00001647","0","1"],["104329.4","0.0002877","0","1"],["104329.1","0.00006852","0","2"],["104329","0.4750314","0","2"],["104328","0.00007452","0","2"],["104327.9","0.00006107","0","1"],["104327.8","0.00237644","0","3"],["104327.7","0.00040824","0","1"],["104327.4","0.00004651","0","2"],["104327.3","0.00001012","0","1"],["104327.2","0.00035213","0","6"],["104327.1","0.00004932","0","1"],["104326.8","0.00001246","0","1"],["104326.6","0.01034","0","1"],["104326.4","0.00007615","0","1"]],"ts":"1747170452700","checksum":-528889997,"seqId":54226346620,"prevSeqId":54226346142}]}
{"arg":{"channel":"books","instId":"BTC-USDT"},"action":"update","data":[{"asks":[["104424.1","0.88302809","0","15"],["104425.1","0.00114512","0","1"],["104425.9","0.00152861","0","1"],["104426","0.33271536","0","3"],["104426.1","0.35608509","0","5"],["104427.9","0.16676191","0","1"],["104430.6","0.09847566","0","1"],["104431.1","0.11863041","0","2"],["104431.6","0.41775457","0","2"],["104432.1","0.08964239","0","1"],["104432.7","0.08935767","0","1"],["104433.2","0","0","0"],["104435.6","0.18455161","0","2"],["104435.8","0.00478685","0","1"],["104436.1","0.31734638","0","2"],["104436.9","0.61536282","0","2"],["104438.2","0","0","0"],["104438.3","0","0","0"],["104438.9","0.20239511","0","3"],["104439.3","0.26698899","0","2"],["104441.1","0.27023152","0","1"],["104441.6","0.2620954","0","1"],["104445.2","0.23402116","0","1"],["104446.5","0.1059","0","1"],["104479.8","0.1","0","1"],["104480.8","0","0","0"],["104580.6","0","0","0"],["104591","0","0","0"],["104608.4","0","0","0"],["104608.7","0","0","0"],["104609.8","0","0","0"],["104609.9","0","0","0"],["104610","0","0","0"],["104610.2","0","0","0"],["104612","0","0","0"],["104612.9","0","0","0"]],"bids":[["104415.9","0.02508872","0","1"],["104415.7","0.32622006","0","1"],["104411.7","0.77866876","0","1"],["104411.6","0.21862463","0","4"],["104410.8","0.18103768","0","3"],["104410.2","0.09346889","0","1"],["104409.6","0.0907606","0","1"],["104408.6","0.16150043","0","3"],["104408.1","0.1626457","0","1"],["104406.6","0.16145306","0","1"],["104405.4","0.36584624","0","2"],["104404.3","0.2606528","0","1"],["104404","0.00489245","0","3"],["104403.9","0.1566042","0","5"],["104401.6","0.25698914","0","1"],["104401.5","0","0","0"],["104401.3","0","0","0"],["104398.6","0.26908391","0","1"],["104397.7","0.25105935","0","3"],["104332.3","0","0","0"],["104327.3","0","0","0"],["104327.2","0","0","0"],["104327.1","0","0","0"],["104326.8","0","0","0"],["104326.6","0","0","0"],["104326.4","0","0","0"]],"ts":"1747170452800","checksum":-73302556,"seqId":54226346764,"prevSeqId":54226346620}]}
{"arg":{"channel":"books","instId":"BTC-USDT"},"action":"update","data":[{"asks":[["104424.1","0.88781809","0","16"],["104431.1","0.09335808","0","1"],["104438","0.05043662","0","1"],["104472.8","0","0","0"],["104478.8","0.1","0","1"],["104479.8","0","0","0"],["104504.2","0.00001","0","1"],["104572.1","0","0","0"],["104584.4","0.00090205","0","1"],["104586","0","0","0"],["104608.4","0.00041816","0","1"]],"bids":[["104424","0.06540109","0","3"],["104411.8","0.19242972","0","1"],["104381.8","0","0","0"],["104355.1","0","0","0"],["104353.4","0.00002965","0","1"],["104350.5","0.0002956","0","4"]],"ts":"1747170452900","checksum":1661491295,"seqId":54226346803,"prevSeqId":54226346764}]}
{"arg":{"channel":"books","instId":"BTC-USDT"},"action":"update","data":[{"asks":[["104424.1","0.89931009","0","17"],["104426.1","0.34459309","0","4"],["104435.8","0.02423784","0","2"],["104446.6","0","0","0"],["104447.3","0.0001303","0","1"],["104449.1","0","0","0"],["104473","1.39367938","0","1"],["104504.3","2.48044325","0","1"],["104608.4","0","0","0"]],"bids":[["104414.3","0.00854618","0","1"],["104383.1","1.36203253","0","1"],["104353.4","0","0","0"],["104353","0.00004751","0","2"],["104351.7","2.50325995","0","1"],["104327.7","0","0","0"],["104327.4","0","0","0"]],"ts":"1747170453000","checksum":-1790163724,"seqId":54226346822,"prevSeqId":54226346803}]}
{"arg":{"channel":"books","instId":"BTC-USDT"},"action":"update","data":[{"asks":[["104424.1","0.89987675","0","18"],["104426.1","0.34429139","0","4"],["104438.3","0.03830038","0","1"],["104443.6","0","0","0"],["104454.2","0.00056666","0","1"],["104455.2","0","0","0"],["104585.7","0.16083","0","1"],["104607.8","0","0","0"]],"bids":[["104368.6","0.00011489","0","1"],["104363.7","0.00056666","0","1"],["104339.5","0.00009595","0","2"],["104333.7","0.00056666","0","1"],["104327.9","0","0","0"],["104327.8","0","0","0"]],"ts":"1747170453100","checksum":42294278,"seqId":54226346849,"prevSeqId":54226346822}]}
{"arg":{"channel":"books","instId":"BTC-USDT"},"action":"update","data":[{"asks":[["104425.9","0","0","0"],["104431","0.00152861","0","1"],["104432.9","0.02377734","0","1"],["104435.9","0","0","0"],["104444","0.13882806","0","1"],["104444.8","0","0","0"],["104464.9","0","0","0"],["104477.4","0","0","0"],["104561.4","0.0013452","0","1"],["104571.8","0.0027004","0","2"],["104607.8","0.03","0","1"]],"bids":[["104400","0.012661","0","47"],["104397.1","0","0","0"],["104395.3","0.14073806","0","2"],["104329.3","0.0013452","0","1"]],"ts":"1747170453200","checksum":-1897751084,"seqId":54226346866,"prevSeqId":54226346849}]}
{"arg":{"channel":"books","instId":"BTC-USDT"},"action":"update","data":[{"asks":[["104424.1","0.89973421","0","18"]],"bids":[["104409.2","0.04","0","1"],["104328","0","0","0"]],"ts":"1747170453300","checksum":564455058,"seqId":54226346869,"prevSeqId":54226346866}]}
{"arg":{"channel":"books","instId":"BTC-USDT"},"action":"update","data":[{"asks":[["104501.1","0","0","0"],["104575.5","6.86287145","0","1"]],"bids":[["104424","0.06542109","0","4"],["104365.1","0","0","0"],["104329.8","0.0758968","0","5"],["104328","0.00007452","0","2"]],"ts":"1747170453400","checksum":-99893131,"seqId":54226346874,"prevSeqId":54226346869}]}
{"arg":{"channel":"books","instId":"BTC-USDT"},"action":"update","data":[{"asks":[["104442.1","0.46434648","0","4"],["104446.8","0.45702617","0","1"],["104499.3","0","0","0"],["104572.2","6.9068223","0","1"],["104575.5","0","0","0"]],"bids":[],"ts":"1747170453500","checksum":-99893131,"seqId":54226346883,"prevSeqId":54226346874}]}
{"arg":{"channel":"books","instId":"BTC-USDT"},"action":"update","data":[{"asks":[["104437.7","0.00478817","0","1"],["104438.4","0.002","0","1"],["104447.6","0.00191","0","1"],["104450.9","0.002","0","1"],["104607.4","0","0","0"],["104607.5","0","0","0"],["104607.8","0","0","0"]],"bids":[["104421.7","0.03033237","0","2"],["104409.2","0.042","0","2"]],"ts":"1747170453600","checksum":-1329680977,"seqId":54226346897,"prevSeqId":54226346883}]}
{"arg":{"channel":"books","instId":"BTC-USDT"},"action":"update","data":[{"asks":[["104501.1","6.9068223","0","1"],["104572.2","0","0","0"],["104600.3","0.234","0","1"],["104606.7","0","0","0"]],"bids":[],"ts":"1747170453700","checksum":-1329680977,"seqId":54226346901,"prevSeqId":54226346897}]}
{"arg":{"channel":"books","instId":"BTC-USDT"},"action":"update","data":[{"asks":[["104424.1","0.82140294","0","17"]],"bids":[],"ts":"1747170453800","checksum":-1300685738,"seqId":54226346907,"prevSeqId":54226346901}]}
{"arg":{"channel":"books","instId":"BTC-USDT"},"action":"update","data":[{"asks":[["104435.8","0.01945099","0","1"],["104436.9","0.6201497","0","3"],["104437","0","0","0"],["104468","0.85928139","0","2"],["104606.7","0.00037885","0","1"]],"bids":[["104424","0.18493109","0","6"],["104416","0.00478713","0","1"],["104414.6","0","0","0"],["104405.5","0.00478688","0","1"],["104404","0.0001056","0","2"],["104397.7","0.25104935","0","2"],["104383.2","0.5227096","0","2"],["104328","0","0","0"]],"ts":"1747170453900","checksum":1060695458,"seqId":54226346922,"prevSeqId":54226346907}]}
{"arg":{"channel":"books","instId":"BTC-USDT"},"action":"update","data":[{"asks":[["104424.1","0.29909294","0","11"],["104424.6","0","0","0"],["104426.1","0.05235653","0","3"],["104426.6","0","0","0"],["104430.6","0","0","0"],["104431","0","0","0"],["104431.1","0","0","0"],["104431.4","0","0","0"],["104431.5","0.00152861","0","1"],["104431.6","0.33690328","0","2"],["104432.1","0","0","0"],["104432.4","0.09449346","0","1"],["104432.7","0","0","0"],["104432.9","0.116085","0","2"],["104433.9","0.09442563","0","1"],["104434.5","0.09977647","0","1"],["104435.6","0.04","0","1"],["104436.1","0","0","0"],["104436.9","0.37545855","0","2"],["104437.4","0.14363088","0","1"],["104437.9","0.32044749","0","2"],["104438.2","0.00478688","0","1"],["104438.9","0.05209157","0","2"],["104439.3","0.02393114","0","1"],["104440.8","0.1559409","0","1"],["104441.1","0.24913832","0","1"],["104441.6","0","0","0"],["104441.7","0.19242972","0","1"],["104442","0","0","0"],["104442.9","0.25620435","0","1"],["104443.4","0.26936757","0","1"],["104444","0","0","0"],["104445.2","0","0","0"],["104445.8","0.13882453","0","1"],["104447","0.24497861","0","1"],["104447.4","0.32032345","0","1"],["104451.4","0","0","0"],["104457","0.17796783","0","1"],["104458","0","0","0"],["104459","0.002","0","2"],["104460","0.00320843","0","4"],["104476.9","0.000015","0","1"],["104478","0","0","0"],["104479","0","0","0"],["104480","0.33221843","0","10"],["104481","0.16499999","0","3"],["104499.2","1.18437733","0","2"],["104535.7","0.29138221","0","1"],["104607.5","0.00001","0","1"]],"bids":[["104424","0.21254614","0","7"],["104422.3","0.04074319","0","1"],["104417.5","0.00478712","0","1"],["104417.1","0.00035983","0","2"],["104416.4","0","0","0"],["104416","0","0","0"],["104413.4","0.19234605","0","2"],["104412.1","0","0","0"],["104412","0.09208867","0","1"],["104411.6","0.03775997","0","2"],["104411.4","0.09696021","0","1"],["104410.8","0.30283443","0","3"],["104410.4","0.15668657","0","1"],["104410.2","0","0","0"],["104409.9","0.1483192","0","1"],["104409.6","0","0","0"],["104408.6","0.0008379","0","2"],["104408.4","0.16945559","0","1"],["104408.1","0","0","0"],["104406.6","0","0","0"],["104406.1","0.22978184","0","1"],["104405.8","0.15332558","0","3"],["104405.5","0","0","0"],["104405.4","0.33569822","0","2"],["104404.3","0","0","0"],["104403.9","0.00050129","0","4"],["104403.4","0.26038716","0","3"],["104403.2","0.07299872","0","2"],["104401.6","0","0","0"],["104400.4","0.26670847","0","1"],["104399.5","1.22481419","0","4"],["104398.6","0","0","0"],["104398.3","0.13882453","0","1"],["104397.7","0.00001","0","1"],["104395.3","0.00191","0","1"]],"ts":"1747170454000","checksum":383876303,"seqId":54226347173,"prevSeqId":54226346922}]}
{"arg":{"channel":"books","instId":"BTC-USDT"},"action":"update","data":[{"asks":[["104424.1","0.29207494","0","10"],["104424.6","0.02508872","0","1"],["104425.9","0.31170931","0","2"],["104427.9","0","0","0"],["104431.1","0.00152861","0","1"],["104431.2","0.19242972","0","1"],["104431.5","0","0","0"],["104431.6","0.33527863","0","2"],["104432.4","0","0","0"],["104432.9","0.02377734","0","1"],["104433.7","0.0957173","0","1"],["104433.9","0","0","0"],["104434.5","0","0","0"],["104436.8","0.36908178","0","1"],["104436.9","0.64080953","0","1"],["104437.2","0.16043403","0","2"],["104437.3","0.00478688","0","1"],["104437.4","0","0","0"],["104437.9","0","0","0"],["104438.2","0","0","0"],["104440.6","0.16326562","0","1"],["104440.7","0.77867876","0","2"],["104440.8","0","0","0"],["104441.1","0","0","0"],["104442.9","0","0","0"],["104443.4","0","0","0"],["104445.8","0.13882486","0","1"],["104447","0","0","0"],["104447.4","0.4610148","0","2"],["104451.4","0.77866876","0","1"],["104462.9","0.00014053","0","1"],["104464.5","0.00001","0","1"],["104527.9","0.01059617","0","1"],["104535.7","0","0","0"],["104539.8","0.01059617","0","1"],["104547.1","0.01059617","0","1"],["104607.8","0.03","0","1"]],"bids":[["104422.3","0","0","0"],["104421.7","0.002","0","1"],["104417.1","0.00005919","0","1"],["104416.7","0.00030064","0","1"],["104415.9","0","0","0"],["104415.7","0.16036451","0","2"],["104413.4","0","0","0"],["104413.2","0.09327736","0","1"],["104413.1","0.04812612","0","1"],["104412","0","0","0"],["104411.8","0","0","0"],["104411.7","0","0","0"],["104411.4","0","0","0"],["104410.8","0.30161556","0","3"],["104410.4","0","0","0"],["104409.9","0","0","0"],["104409.7","0.14299388","0","1"],["104408.4","0","0","0"],["104406.1","0","0","0"],["104405.8","0.00001051","0","1"],["104405.6","0.15304707","0","1"],["104405.5","0.00478688","0","1"],["104405.4","0.20977678","0","2"],["104403.4","0.02204107","0","2"],["104401.2","0","0","0"],["104401","0.19266497","0","2"],["104400.4","0","0","0"],["104399.5","0.59255523","0","2"],["104398.3","0.13882427","0","1"],["104397.7","0","0","0"],["104383.2","0.00001016","0","1"],["104383.1","0","0","0"],["104380.3","0.002874","0","1"],["104363.7","0","0","0"],["104363.5","0.01009453","0","2"],["104351.7","0","0","0"],["104333.7","0","0","0"],["104333.4","0.00056666","0","1"],["104329.8","0.07302275","0","4"],["104328","0.00007452","0","2"],["104327.9","0.00006107","0","1"],["104327.8","0.00237644","0","3"],["104327.7","0.00040824","0","1"],["104327.4","0.00004651","0","2"],["104327.3","0.00001012","0","1"],["104327.2","0.00035213","0","6"],["104327.1","0.00004932","0","1"],["104326.8","0.00001246","0","1"],["104326.6","0.01034","0","1"]],"ts":"1747170454100","checksum":-1797494001,"seqId":54226347367,"prevSeqId":54226347173}]}
{"arg":{"channel":"books","instId":"BTC-USDT"},"action":"update","data":[{"asks":[["104432.4","0.08996529","0","1"],["104432.9","0.11613727","0","2"],["104433.7","0","0","0"],["104433.9","0.08787397","0","1"],["104434.5","0.10038031","0","1"],["104436.9","0.62815861","0","2"],["104437.2","0.00093","0","1"],["104437.3","0","0","0"],["104437.4","0.14355375","0","1"],["104437.6","0.10293268","0","5"],["104437.9","0.33016049","0","2"],["104440.6","0","0","0"],["104440.7","0.93618624","0","3"],["104441.1","0.23055822","0","1"],["104442.9","0.24806505","0","1"],["104443.4","0.2503293","0","1"],["104447","0.24582302","0","1"],["104531.9","0.00009969","0","1"],["104533.4","0","0","0"],["104604.4","0","0","0"],["104604.7","0","0","0"],["104605.6","0","0","0"],["104606.7","0","0","0"],["104607.5","0","0","0"],["104607.8","0","0","0"]],"bids":[["104422.3","0.03224348","0","1"],["104417.5","0","0","0"],["104417.2","0.00741709","0","2"],["104415.7","0.28546122","0","1"],["104413.4","0.18378654","0","2"],["104413.2","0","0","0"],["104412","0.09729748","0","1"],["104411.9","0.77866876","0","1"],["104411.4","0.09362324","0","1"],["104410.8","0.30965356","0","3"],["104410.4","0.16665937","0","1"],["104409.9","0.15169261","0","1"],["104409.7","0","0","0"],["104408.4","0.16514207","0","1"],["104406.1","0.23117069","0","1"],["104406","0.00478688","0","1"],["104405.7","0.16241546","0","2"],["104405.6","0","0","0"],["104405.5","0","0","0"],["104405.4","0.33488471","0","1"],["104403.4","0.27119117","0","3"],["104400.4","0.25306479","0","1"],["104399.5","0.84518419","0","3"],["104398.3","0","0","0"],["104397.5","0.13882488","0","1"],["104380.3","0","0","0"],["104357.3","0.002874","0","1"],["104327.4","0","0","0"],["104327.3","0","0","0"],["104327.2","0","0","0"],["104327.1","0","0","0"],["104326.8","0","0","0"],["104326.6","0","0","0"]],"ts":"1747170454200","checksum":225267745,"seqId":54226347528,"prevSeqId":54226347367}]}
{"arg":{"channel":"books","instId":"BTC-USDT"},"action":"update","data":[{"asks":[["104458","0.002","0","2"],["104459","0.001","0","1"],["104460","0.00220843","0","3"],["104478","0.33","0","6"],["104479","0.16499999","0","3"],["104480","0.00221843","0","4"],["104481","0","0","0"],["104603.2","0","0","0"],["104603.6","0","0","0"]],"bids":[["104417.3","0.01294329","0","1"],["104417.1","0.00035983","0","2"],["104416.8","0.02508872","0","1"],["104416.7","0","0","0"],["104415.7","0.41991966","0","2"],["104412","0.2897272","0","2"],["104384.2","1.43822728","0","1"],["104352.9","2.60279128","0","3"],["104327.8","0","0","0"],["104327.7","0","0","0"]],"ts":"1747170454300","checksum":1345332866,"seqId":54226347560,"prevSeqId":54226347528}]}
{"arg":{"channel":"books","instId":"BTC-USDT"},"action":"update","data":[{"asks":[["104424.1","0.28058294","0","9"],["104478","0.07","0","2"],["104479","0.035","0","1"],["104480","0.26221843","0","8"],["104481","0.12999999","0","2"],["104534.7","0.12","0","1"],["104602.5","0","0","0"],["104603.1","0","0","0"]],"bids":[],"ts":"1747170454400","checksum":883419367,"seqId":54226347586,"prevSeqId":54226347560}]}
{"arg":{"channel":"books","instId":"BTC-USDT"},"action":"update","data":[{"asks":[["104424.1","0.25621294","0","9"],["104432.4","0","0","0"],["104432.9","0.02377734","0","1"],["104433.9","0","0","0"],["104434.5","0","0","0"],["104436.9","0.42242814","0","1"],["104437.4","0","0","0"],["104437.5","0.00478688","0","1"],["104437.6","0.0981458","0","4"],["104437.9","0","0","0"],["104440.7","0.77867876","0","2"],["104441.1","0","0","0"],["104442.9","0","0","0"],["104443.4","0","0","0"],["104445.8","0","0","0"],["104446.7","0.13882324","0","1"],["104447","0","0","0"],["104447.3","0","0","0"],["104478","0.33","0","6"],["104479","0.16499999","0","3"],["104480","0.00221843","0","4"],["104481","0","0","0"],["104563.3","0.01052734","0","1"],["104602.5","0.00001501","0","1"],["104603.1","0.00001531","0","1"],["104603.2","0.01089628","0","1"],["104603.6","0.77866876","0","1"],["104604.4","2.51209","0","1"],["104604.7","0.00017476","0","1"],["104605.6","0.01089602","0","1"],["104606.7","0.00037885","0","1"],["104607.5","0.00001","0","1"],["104607.8","0.03","0","1"]],"bids":[["104417.4","0.00490725","0","2"],["104417.2","0.00262999","0","1"],["104413.4","0","0","0"],["104412","0.19242972","0","1"],["104411.4","0","0","0"],["104410.8","0.05207507","0","2"],["104410.4","0","0","0"],["104409.9","0","0","0"],["104408.4","0","0","0"],["104406.1","0","0","0"],["104406","0","0","0"],["104405.8","0.00479739","0","2"],["104405.7","0.00098","0","1"],["104405.4","0.21187841","0","1"],["104403.4","0.02204107","0","2"],["104400.4","0","0","0"],["104399.6","0.36908178","0","1"],["104399.5","0.59255523","0","2"],["104399.1","0.13882364","0","1"],["104397.5","0","0","0"],["104327.8","0.00237644","0","3"],["104327.7","0.00040824","0","1"],["104327.4","0.00004651","0","2"],["104327.3","0.00001012","0","1"],["104327.2","0.00035213","0","6"],["104327.1","0.00004932","0","1"],["104326.8","0.00001246","0","1"]],"ts":"1747170454500","checksum":-1935441234,"seqId":54226347707,"prevSeqId":54226347586}]}
{"arg":{"channel":"books","instId":"BTC-USDT"},"action":"update","data":[{"asks":[],"bids":[["104424","0.25974727","0","8"]],"ts":"1747170454600","checksum":-364299593,"seqId":54226347714,"prevSeqId":54226347707}]}
{"arg":{"channel":"books","instId":"BTC-USDT"},"action":"update","data":[{"asks":[["104424.1","0.25981407","0","10"],["104445.8","0.13882428","0","1"],["104446.7","0","0","0"]],"bids":[["104399.1","0","0","0"],["104398.3","0.13882428","0","1"]],"ts":"1747170454700","checksum":-994953800,"seqId":54226347719,"prevSeqId":54226347714}]}
{"arg":{"channel":"books","instId":"BTC-USDT"},"action":"update","data":[{"asks":[["104445.8","0","0","0"],["104446.4","0.13882349","0","1"],["104447.3","0.0001303","0","1"],["104607.8","0","0","0"]],"bids":[["104399.1","0.13882349","0","1"],["104398.3","0","0","0"]],"ts":"1747170454800","checksum":-994953800,"seqId":54226347727,"prevSeqId":54226347719}]}
{"arg":{"channel":"books","instId":"BTC-USDT"},"action":"update","data":[{"asks":[["104424.1","0.49981407","0","11"],["104436.8","0.37386866","0","2"],["104437.5","0","0","0"],["104446.2","0.13882377","0","1"],["104446.4","0","0","0"],["104607.8","0.03","0","1"]],"bids":[["104422.3","0","0","0"],["104417.4","0.00012018","0","1"],["104417.3","0.01773028","0","2"],["104417.1","0.00005919","0","1"],["104416.9","0.00030064","0","1"],["104405.8","0.00001051","0","1"],["104404.9","0.00478688","0","1"],["104399.1","0","0","0"],["104398.3","0.13882377","0","1"],["104384.3","0.56778447","0","1"],["104327.1","0","0","0"],["104326.8","0","0","0"]],"ts":"1747170454900","checksum":1740307027,"seqId":54226347742,"prevSeqId":54226347727}]}
{"arg":{"channel":"books","instId":"BTC-USDT"},"action":"update","data":[{"asks":[["104431","0.00152861","0","1"],["104431.1","0.02605391","0","1"],["104433","0","0","0"],["104445.8","0.13882477","0","1"],["104446.2","0","0","0"]],"bids":[["104417.3","0.01294329","0","1"],["104417","0.00479701","0","2"],["104398.3","0","0","0"],["104397.5","0.13882477","0","1"]],"ts":"1747170455000","checksum":687558612,"seqId":54226347752,"prevSeqId":54226347742}]}
{"arg":{"channel":"books","instId":"BTC-USDT"},"action":"update","data":[{"asks":[],"bids":[["104424","0.14024727","0","7"],["104422.3","0.03224348","0","1"],["104417.1","0.00035983","0","2"],["104417","0.00001","0","1"],["104416.9","0.00478702","0","1"],["104366.5","0.00056666","0","1"],["104363.5","0.00952787","0","1"],["104336.5","0.02193699","0","5"],["104333.4","0","0","0"],["104327.2","0","0","0"]],"ts":"1747170455100","checksum":1656599127,"seqId":54226347765,"prevSeqId":54226347752}]}
{"arg":{"channel":"books","instId":"BTC-USDT"},"action":"update","data":[{"asks":[["104429.4","0.02605433","0","1"],["104432.9","0","0","0"],["104445.8","0","0","0"],["104447.3","0.13895254","0","2"],["104608.4","0.00041816","0","1"]],"bids":[["104424","0.25974727","0","8"],["104417.2","0.007417","0","2"],["104416.9","0","0","0"],["104399.7","0.13882224","0","1"],["104397.5","0","0","0"],["104353","0.00001786","0","1"],["104327.2","0.00035213","0","6"]],"ts":"1747170455200","checksum":409353861,"seqId":54226347797,"prevSeqId":54226347765}]}
{"arg":{"channel":"books","instId":"BTC-USDT"},"action":"update","data":[{"asks":[["104445.8","0.13882429","0","1"],["104447.3","0.0001303","0","1"],["104608.4","0","0","0"]],"bids":[["104424","0.14024727","0","7"],["104417.2","0.00262999","0","1"],["104416.9","0.00478697","0","1"],["104399.7","0","0","0"],["104398.3","0.13882429","0","1"],["104327.2","0","0","0"]],"ts":"1747170455300","checksum":-493007094,"seqId":54226347809,"prevSeqId":54226347797}]}
{"arg":{"channel":"books","instId":"BTC-USDT"},"action":"update","data":[{"asks":[["104436.7","0.00479688","0","2"],["104436.8","0.36908178","0","1"]],"bids":[["104416.9","0","0","0"],["104416.4","0.00478701","0","1"],["104404.9","0","0","0"],["104404","0.00489248","0","3"],["104330.3","0","0","0"],["104327.2","0.00035213","0","6"],["104327.1","0.00004932","0","1"]],"ts":"1747170455400","checksum":-1461856917,"seqId":54226347824,"prevSeqId":54226347809}]}
{"arg":{"channel":"books","instId":"BTC-USDT"},"action":"update","data":[{"asks":[["104436.7","0.00001","0","1"],["104439.2","0.00478688","0","1"],["104607.8","0","0","0"]],"bids":[["104422.3","0","0","0"],["104417.1","0.00005919","0","1"],["104416.9","0.00030064","0","1"],["104407","0.00478688","0","1"],["104404","0.0001056","0","2"],["104353.1","0.00004312","0","2"],["104327.1","0","0","0"]],"ts":"1747170455500","checksum":1950836385,"seqId":54226347834,"prevSeqId":54226347824}]}
{"arg":{"channel":"books","instId":"BTC-USDT"},"action":"update","data":[{"asks":[["104431.4","0.09019877","0","1"],["104431.9","0.09246446","0","2"],["104432.8","0.09023086","0","2"],["104433.5","0.08879125","0","1"],["104436.3","0.15738031","0","1"],["104436.9","0.73886916","0","3"],["104439.7","0.15525046","0","1"],["104440.1","0.28386766","0","3"],["104441.9","0.25495398","0","1"],["104442.4","0.2420127","0","2"],["104446","0.23651646","0","1"],["104603.6","0","0","0"],["104604.4","0","0","0"],["104604.7","0","0","0"],["104605.6","0","0","0"],["104606.7","0","0","0"],["104607.5","0","0","0"]],"bids":[["104424","0.11263222","0","6"],["104421.1","0.02279798","0","1"],["104421","0.02971953","0","2"],["104417.3","0","0","0"],["104416.7","0.00478711","0","1"],["104416.4","0","0","0"],["104412.4","0.09966151","0","1"],["104412.3","0.08948205","0","1"],["104411","0.08992782","0","1"],["104410.8","0.20888193","0","3"],["104410.4","0.09212499","0","1"],["104409.4","0.15148467","0","1"],["104408.8","0.17305501","0","2"],["104407.4","0.15293172","0","1"],["104405.4","0.3837075","0","2"],["104405.1","0.25136115","0","3"],["104404.7","0.17954255","0","2"],["104402.4","0.26496515","0","1"],["104399.4","1.04329876","0","3"],["104398.5","0.23667518","0","1"],["104329","0","0","0"],["104328","0","0","0"],["104327.9","0","0","0"],["104327.8","0","0","0"],["104327.7","0","0","0"],["104327.4","0","0","0"],["104327.3","0","0","0"],["104327.2","0","0","0"]],"ts":"1747170455600","checksum":1625250132,"seqId":54226347916,"prevSeqId":54226347834}]}
{"arg":{"channel":"books","instId":"BTC-USDT"},"action":"update","data":[{"asks":[],"bids":[["104416.7","0","0","0"],["104416.4","0.00478711","0","1"]],"ts":"1747170455700","checksum":-496603443,"seqId":54226347921,"prevSeqId":54226347916}]}
