{"arg":{"channel":"books","instId":"BTC-USDT"},"action":"update","data":[{"asks":[["104448.1","1.66979616","0","28"],["104455.4","0.02718728","0","1"],["104455.9","0","0","0"],["104456.9","0","0","0"],["104457.5","0","0","0"],["104460.4","0","0","0"],["104460.9","0","0","0"],["104462.8","0.15570221","0","1"],["104463.8","0","0","0"],["104464","0.13880016","0","1"],["104464.1","0.05209157","0","2"],["104465.8","0","0","0"],["104465.9","0","0","0"],["104466.3","0.00711203","0","1"],["104466.4","0","0","0"],["104470","0.00029006","0","2"],["104483","0","0","0"],["104484","0.002","0","2"],["104485","0.85407523","0","3"],["104503","0","0","0"],["104504","0.32999999","0","6"],["104505","0.64453101","0","5"],["104521.4","0","0","0"],["104585.7","6.86643296","0","1"],["104637.8","0.77866876","0","1"],["104639.1","0.234","0","1"],["104639.3","0.00010253","0","1"],["104639.7","0.00239325","0","1"],["104640","0.00220843","0","3"],["104641.3","0.03","0","1"],["104642.5","0.0003067","0","1"],["104642.7","0.03","0","1"]],"bids":[["104440.3","0","0","0"],["104439.4","0","0","0"],["104438.5","0.00030064","0","1"],["104436.4","0","0","0"],["104435","0","0","0"],["104434.4","0.000015","0","1"],["104433.4","0","0","0"],["104432.9","0","0","0"],["104431.4","0","0","0"],["104429.1","0","0","0"],["104428.8","0.033","0","1"],["104427.8","0.1526236","0","1"],["104426.4","0","0","0"],["104426.2","0.00001731","0","1"],["104423.4","0","0","0"],["104422.5","0","0","0"],["104417.4","0.00012018","0","1"],["104413.5","0.05029863","0","1"],["104413.4","0.13880018","0","1"],["104342.6","0.0000203","0","1"],["104342.4","0.0078311","0","2"],["104342.3","0.01152169","0","2"],["104342.1","0.00022221","0","1"],["104342","0.01059526","0","1"],["104341.6","0.0001427","0","2"],["104341.3","0.00001374","0","1"]],"ts":"1747170435800","checksum":-2083053342,"seqId":54226331022,"prevSeqId":54226330932}]}
{"arg":{"channel":"books","instId":"BTC-USDT"},"action":"update","data":[{"asks":[["104448.1","1.44290819","0","28"],["104450.1","0.29332888","0","5"],["104453.4","0.27898646","0","2"],["104455.4","0.11971011","0","2"],["104455.9","0.0923304","0","1"],["104456.9","0.09238924","0","1"],["104457.5","0.09905484","0","1"],["104460.4","0.15919296","0","1"],["104460.9","0.30954194","0","2"],["104462.8","0","0","0"],["104463","0.35621265","0","3"],["104463.8","0.15405381","0","1"],["104464","0","0","0"],["104464.1","0.28530921","0","3"],["104465.8","0.13879913","0","1"],["104465.9","0.24922106","0","1"],["104466.3","0","0","0"],["104466.4","0.25473106","0","1"],["104470","0.23695913","0","3"],["104476.3","0.00287139","0","1"],["104476.5","0.000015","0","1"],["104493.6","0.05014701","0","1"],["104502.5","0.02872242","0","1"],["104509.4","0.01089559","0","1"],["104513.2","0","0","0"],["104552.9","0.01914828","0","1"],["104570.2","0","0","0"],["104585.7","6.88522264","0","1"],["104622","0","0","0"],["104639.1","0","0","0"],["104639.3","0","0","0"],["104639.7","0","0","0"],["104640","0","0","0"],["104641.3","0","0","0"],["104642.5","0","0","0"],["104642.7","0","0","0"]],"bids":[["104440.3","0.0678893","0","1"],["104438.7","0","0","0"],["104438","0.00478601","0","1"],["104436.8","0.49465981","0","3"],["104436.4","0.1829705","0","2"],["104436.1","0.00870083","0","1"],["104435","0.09686379","0","1"],["104434.4","0.08970543","0","2"],["104433.4","0.16267516","0","1"],["104432.9","0.1632027","0","1"],["104431.4","0.15628545","0","1"],["104429.1","0.24081542","0","1"],["104428.8","0.18961638","0","2"],["104427.8","0","0","0"],["104426.4","0.26744165","0","1"],["104423.4","0.25187613","0","1"],["104422.5","0.23697836","0","1"],["104421","0.06024445","0","3"],["104417.4","0.13891931","0","2"],["104416.4","0.00711203","0","1"],["104413.5","0","0","0"],["104413.4","0","0","0"],["104408","0","0","0"],["104407.5","0","0","0"],["104405.8","0.00479757","0","2"],["104396.8","0.00478706","0","1"],["104342.8","0","0","0"],["104342.6","0","0","0"],["104342.4","0","0","0"],["104342.3","0","0","0"],["104342.1","0","0","0"],["104342","0","0","0"],["104341.6","0","0","0"],["104341.3","0","0","0"]],"ts":"1747170435900","checksum":-688095728,"seqId":54226331131,"prevSeqId":54226331022}]}
{"arg":{"channel":"books","instId":"BTC-USDT"},"action":"update","data":[{"asks":[["104451.5","0.03609157","0","1"],["104454.4","0.02671811","0","1"],["104582.3","7.6638914","0","2"],["104585.7","0","0","0"]],"bids":[["104424.9","0.071795","0","2"]],"ts":"1747170436000","checksum":1194147240,"seqId":54226331148,"prevSeqId":54226331131}]}
{"arg":{"channel":"books","instId":"BTC-USDT"},"action":"update","data":[{"asks":[["104448.1","1.44347485","0","29"],["104449.9","0.10552844","0","1"],["104450","0.20244972","0","3"],["104450.1","0.05276222","0","3"],["104455.3","0.0001303","0","1"],["104455.4","0.02718728","0","1"],["104455.5","0.09112909","0","1"],["104456.5","0","0","0"],["104460.9","0.1570978","0","1"],["104461","0.15171411","0","1"],["104464.1","0.05209157","0","2"],["104464.2","0.27883803","0","2"],["104466.4","0","0","0"],["104466.5","0.23897476","0","1"],["104466.6","0.00056666","0","1"],["104468.6","0","0","0"],["104487.3","0.09574","0","1"],["104495.1","0.41126935","0","1"],["104495.9","0","0","0"],["104527.2","0","0","0"],["104578.9","6.88522264","0","1"],["104582.3","0.77866876","0","1"],["104637.2","0","0","0"],["104637.8","0","0","0"]],"bids":[["104448","0.15704484","0","5"],["104437.6","0","0","0"],["104436.7","0.00957158","0","1"],["104434.5","0.10054693","0","1"],["104434.4","0.000015","0","1"],["104433.5","0.1549547","0","2"],["104433.4","0","0","0"],["104429.6","0.00601181","0","5"],["104429.2","0.2571235","0","1"],["104429.1","0","0","0"],["104423.5","0.2730875","0","1"],["104423.4","0","0","0"],["104418.2","0.13879804","0","1"],["104417.4","0.00012018","0","1"],["104409.5","0","0","0"],["104406.5","0","0","0"],["104403.2","0.000015","0","1"],["104400.7","0.00056666","0","1"],["104384.7","0.00016998","0","7"],["104382.2","0.00539722","0","2"],["104376.4","0.29093002","0","1"],["104375.2","0","0","0"],["104360.9","0","0","0"],["104360.1","0.00002964","0","1"],["104342.8","0.00076959","0","3"],["104342.6","0.0000203","0","1"]],"ts":"1747170436100","checksum":90779926,"seqId":54226331209,"prevSeqId":54226331148}]}
{"arg":{"channel":"books","instId":"BTC-USDT"},"action":"update","data":[{"asks":[["104448.1","1.43636282","0","28"],["104453.1","0.00711203","0","1"],["104455.4","0.12718023","0","2"],["104455.5","0","0","0"],["104460.9","0.32771245","0","2"],["104461","0","0","0"],["104464.1","0.29925348","0","3"],["104464.2","0.03829323","0","1"],["104465.8","0.13879852","0","1"],["104466.4","0.2597467","0","1"],["104466.5","0","0","0"],["104494.4","1.41824168","0","1"],["104525.8","2.560051","0","2"],["104528.2","6.88522264","0","1"],["104559.7","0","0","0"],["104578.9","0","0","0"],["104609.5","0.00090415","0","1"],["104611.9","0","0","0"],["104637.2","0.03","0","1"]],"bids":[["104448","0.15384484","0","4"],["104438","0","0","0"],["104437.6","0.00478599","0","1"],["104435.2","0.02708872","0","2"],["104434.5","0","0","0"],["104434.4","0.09478058","0","2"],["104433.6","0","0","0"],["104433.5","0.00001","0","1"],["104433.4","0.17107144","0","1"],["104432","0","0","0"],["104429.6","0.00122607","0","4"],["104429.2","0.00478574","0","1"],["104429.1","0.22879021","0","1"],["104423.5","0","0","0"],["104423.4","0.26190397","0","1"],["104418.2","0","0","0"],["104417.8","0.13879852","0","1"],["104404.4","1.36550374","0","1"],["104373.1","2.69776684","0","2"],["104349","0","0","0"],["104348.4","0.00009605","0","1"]],"ts":"1747170436200","checksum":-86905454,"seqId":54226331278,"prevSeqId":54226331209}]}
{"arg":{"channel":"books","instId":"BTC-USDT"},"action":"update","data":[{"asks":[["104450","0.01002","0","2"],["104455.4","0.02718728","0","1"],["104455.5","0.08993996","0","1"],["104455.9","0","0","0"],["104456","0.09619946","0","1"],["104456.9","0","0","0"],["104457.5","0","0","0"],["104457.6","0.0928721","0","1"],["104459","0.00478574","0","1"],["104460.4","0","0","0"],["104460.9","0","0","0"],["104461","0.31775647","0","2"],["104462","0","0","0"],["104463","0.40536198","0","3"],["104464.1","0.05209157","0","2"],["104464.2","0.27804866","0","2"],["104465.8","0","0","0"],["104465.9","0","0","0"],["104466","0.27048194","0","3"],["104466.4","0.13879728","0","1"],["104466.5","0.25236291","0","1"],["104470","0.00029006","0","2"],["104470.1","0.29946528","0","3"],["104475.9","0.00287139","0","1"],["104476.3","0","0","0"],["104483","0.002","0","2"],["104484","0.001","0","1"],["104485","0.85307523","0","2"],["104494.3","0.9637372","0","1"],["104495.1","0","0","0"],["104503","0.33","0","6"],["104504","0.16499999","0","3"],["104505","0.47953102","0","2"],["104521.4","6.88522264","0","1"],["104525.7","0.89836302","0","1"],["104528.2","0","0","0"],["104637.2","0","0","0"]],"bids":[["104448","0.15704484","0","5"],["104441.6","0.03179744","0","1"],["104439.4","0.00030064","0","1"],["104438.5","0","0","0"],["104436.5","0.09127634","0","1"],["104436.4","0","0","0"],["104435.1","0.08939374","0","1"],["104435","0","0","0"],["104434.5","0.09157301","0","1"],["104434.4","0.000015","0","1"],["104433.5","0.16176959","0","2"],["104433.4","0","0","0"],["104432.9","0","0","0"],["104431.5","0.26077875","0","5"],["104431.4","0","0","0"],["104429.2","0.24167782","0","1"],["104429.1","0","0","0"],["104427","0.00478574","0","1"],["104426.5","0.24235864","0","2"],["104426.4","0","0","0"],["104423.5","0.24105539","0","1"],["104423.4","0","0","0"],["104422.6","0.24942427","0","1"],["104422.5","0","0","0"],["104418.2","0.13879728","0","1"],["104417.8","0","0","0"],["104409.7","0.53276891","0","1"],["104373.2","0.94921874","0","3"],["104342.4","0.0078311","0","2"]],"ts":"1747170436300","checksum":-1223055432,"seqId":54226331382,"prevSeqId":54226331278}]}
{"arg":{"channel":"books","instId":"BTC-USDT"},"action":"update","data":[{"asks":[["104448.1","1.08723595","0","24"],["104449.9","0.04779953","0","1"],["104450.1","0.03676222","0","2"],["104453.4","0.20252333","0","1"],["104455.5","0","0","0"],["104456","0","0","0"],["104456.5","0.09420137","0","1"],["104457","0.09846766","0","1"],["104457.6","0","0","0"],["104457.9","0.08944445","0","2"],["104458.6","0.09240562","0","1"],["104461","0","0","0"],["104461.4","0.145303","0","1"],["104462","0.31669384","0","2"],["104463","0.35401433","0","3"],["104463.8","0","0","0"],["104464.2","0.03829323","0","1"],["104464.8","0.15666269","0","1"],["104465.2","0.23044171","0","1"],["104466","0.00910622","0","2"],["104466.4","0","0","0"],["104466.5","0","0","0"],["104467","0.24670712","0","1"],["104467.5","0.24137601","0","1"],["104467.9","0.13879485","0","1"],["104470.1","0.05209157","0","2"],["104471.1","0.24635884","0","1"],["104631.4","0","0","0"],["104633","0","0","0"],["104633.2","0","0","0"],["104633.9","0","0","0"]],"bids":[["104448","0.27654484","0","6"],["104444.9","0.02882813","0","1"],["104441.6","0","0","0"],["104440.6","0.00030064","0","1"],["104440.5","0.12274977","0","1"],["104440.4","0.19242972","0","1"],["104440.3","0","0","0"],["104439.4","0","0","0"],["104438.5","0.00478593","0","1"],["104437.6","0","0","0"],["104437.5","0.14351976","0","4"],["104437.4","0.10505846","0","2"],["104436.8","0.47725867","0","3"],["104436.5","0","0","0"],["104436.1","0.10805047","0","2"],["104435.5","0.10241327","0","1"],["104435.1","0","0","0"],["104434.5","0.15285922","0","1"],["104433.9","0.14940229","0","1"],["104433.5","0.00001","0","1"],["104432.5","0.16132301","0","1"],["104431.6","0.45139295","0","2"],["104431.5","0.10920125","0","4"],["104430.2","0.25719853","0","1"],["104429.8","0.1576312","0","1"],["104429.2","0","0","0"],["104428.8","0.033","0","1"],["104427.5","0.24779495","0","2"],["104427.4","0.03478574","0","2"],["104427","0","0","0"],["104426.5","0.00191","0","1"],["104424.5","0.26594119","0","1"],["104423.6","0.41687913","0","2"],["104423.5","0","0","0"],["104422.6","0","0","0"],["104418.2","0.13879485","0","1"],["104342.4","0","0","0"]],"ts":"1747170436400","checksum":-668218163,"seqId":54226331500,"prevSeqId":54226331382}]}
{"arg":{"channel":"books","instId":"BTC-USDT"},"action":"update","data":[{"asks":[["104449.2","0.00267734","0","1"],["104467.9","0","0","0"],["104469.1","0.13879431","0","1"],["104495","1","0","1"],["104521.4","0","0","0"],["104528.2","6.88522264","0","1"],["104556.1","0.00009334","0","1"],["104628.8","0","0","0"],["104629.5","0","0","0"],["104630","0","0","0"]],"bids":[["104421.1","0.13879431","0","1"],["104418.2","0","0","0"]],"ts":"1747170436500","checksum":-850504903,"seqId":54226331514,"prevSeqId":54226331500}]}
{"arg":{"channel":"books","instId":"BTC-USDT"},"action":"update","data":[{"asks":[["104467.9","0.13879485","0","1"],["104469.1","0","0","0"],["104521.4","6.88522264","0","1"],["104528.2","0","0","0"]],"bids":[["104421.1","0","0","0"],["104418.2","0.13879485","0","1"]],"ts":"1747170436700","checksum":-850504903,"seqId":54226331521,"prevSeqId":54226331514}]}
{"arg":{"channel":"books","instId":"BTC-USDT"},"action":"update","data":[{"asks":[],"bids":[["104438.5","0","0","0"],["104438","0.00478593","0","1"]],"ts":"1747170436800","checksum":-1585038509,"seqId":54226331523,"prevSeqId":54226331521}]}
{"arg":{"channel":"books","instId":"BTC-USDT"},"action":"update","data":[{"asks":[["104521.4","0","0","0"],["104524.8","6.96016454","0","3"],["104628.8","0.07298372","0","1"]],"bids":[["104438","0.00478592","0","1"],["104401.2","0.01723531","0","2"],["104375.9","0","0","0"],["104352.2","0.00001192","0","1"],["104342.4","0.0078311","0","2"]],"ts":"1747170436900","checksum":-599034260,"seqId":54226331535,"prevSeqId":54226331523}]}
{"arg":{"channel":"books","instId":"BTC-USDT"},"action":"update","data":[{"asks":[["104521.4","6.90816454","0","1"],["104524.8","0.052","0","2"],["104628.8","0","0","0"]],"bids":[["104438.5","0.00478592","0","1"],["104438","0","0","0"]],"ts":"1747170437000","checksum":942363387,"seqId":54226331540,"prevSeqId":54226331535}]}
{"arg":{"channel":"books","instId":"BTC-USDT"},"action":"update","data":[{"asks":[["104477","0","0","0"],["104489.5","0","0","0"],["104628.8","0.07298372","0","1"],["104629.5","0.00010997","0","1"]],"bids":[["104445.3","0","0","0"],["104436.7","0","0","0"],["104435.4","0.0095717","0","1"],["104401.3","0.00056666","0","1"],["104400.7","0","0","0"],["104382.8","0.00058203","0","2"],["104382.2","0.00483056","0","1"],["104361","0","0","0"],["104342.3","0.01152169","0","2"],["104342.1","0.00022221","0","1"]],"ts":"1747170437100","checksum":-1969876985,"seqId":54226331550,"prevSeqId":54226331540}]}
{"arg":{"channel":"books","instId":"BTC-USDT"},"action":"update","data":[{"asks":[["104452.7","0.00152861","0","1"],["104452.8","0.3273825","0","1"],["104452.9","0.21729892","0","2"],["104453.3","0","0","0"],["104453.4","0","0","0"],["104521.4","0","0","0"],["104528.2","6.90816454","0","1"]],"bids":[["104438.5","0.00478593","0","1"],["104414.5","0.46461104","0","2"]],"ts":"1747170437200","checksum":-1454632755,"seqId":54226331564,"prevSeqId":54226331550}]}
{"arg":{"channel":"books","instId":"BTC-USDT"},"action":"update","data":[{"asks":[["104448.1","0.93180595","0","21"],["104452.9","0.0248692","0","1"],["104453.1","0","0","0"],["104453.2","0","0","0"],["104453.9","0","0","0"],["104457.1","0.03091878","0","1"],["104459","0","0","0"],["104459.5","0.00478574","0","1"],["104462.5","0","0","0"],["104467.9","0","0","0"],["104469.1","0.13879434","0","1"],["104471.8","0.011899","0","2"],["104483","0","0","0"],["104484","0","0","0"],["104486","0.44860783","0","4"],["104487","0.001015","0","2"],["104490","0.00030006","0","3"],["104503","0","0","0"],["104504","0","0","0"],["104506","0.33","0","6"],["104507","0.39899999","0","4"],["104515.6","0.19317991","0","1"],["104521.4","6.90816454","0","1"],["104528.2","0","0","0"],["104541","0","0","0"],["104546.2","0.26837252","0","1"],["104588.8","0.01059556","0","1"],["104599.2","0","0","0"],["104630","0.00151107","0","2"],["104631.4","0.00001","0","1"],["104633","1.89471219","0","1"],["104633.2","0.04783921","0","4"],["104633.9","0.00014488","0","1"],["104637.2","0.03","0","1"]],"bids":[["104448","0.27964484","0","7"],["104439.4","0.0047859","0","1"],["104438.5","0","0","0"],["104428","0.00478574","0","1"],["104427.4","0.03","0","1"],["104426.2","0.36909909","0","2"],["104421.1","0.13879434","0","1"],["104418.2","0","0","0"],["104404.5","0.47303946","0","1"],["104404.2","0.00008559","0","1"],["104342.3","0","0","0"],["104342.1","0","0","0"]],"ts":"1747170437300","checksum":-1536907859,"seqId":54226331632,"prevSeqId":54226331564}]}
{"arg":{"channel":"books","instId":"BTC-USDT"},"action":"update","data":[{"asks":[["104458","0.29247062","0","1"],["104459.5","0","0","0"],["104460.1","0.05209157","0","2"],["104461.3","0.00478574","0","1"],["104607.7","0.00090602","0","1"],["104609.5","0","0","0"]],"bids":[["104349","0.00010211","0","1"],["104348.4","0","0","0"]],"ts":"1747170437400","checksum":-2117606709,"seqId":54226331680,"prevSeqId":54226331632}]}
{"arg":{"channel":"books","instId":"BTC-USDT"},"action":"update","data":[{"asks":[["104448.1","0.6063988","0","18"],["104452.8","0.2371585","0","1"],["104454.4","0","0","0"],["104456.5","0","0","0"],["104456.6","0.09427865","0","2"],["104457.5","0.03091867","0","1"],["104457.9","0.00044","0","1"],["104458","0.38327688","0","2"],["104461.3","0","0","0"],["104461.4","0.00478576","0","1"],["104461.5","0.1507519","0","1"],["104462","0.15535299","0","1"],["104462.1","0.21839783","0","3"],["104463","0.3625506","0","3"],["104464.8","0","0","0"],["104464.9","0.16864785","0","2"],["104465.2","0","0","0"],["104465.3","0.25114726","0","1"],["104467.5","0","0","0"],["104467.6","0.26591507","0","1"],["104469.1","0","0","0"],["104470","0.13908287","0","3"],["104495","0","0","0"],["104637.8","0.77866876","0","1"],["104639.1","0.234","0","1"],["104639.3","0.00010253","0","1"],["104639.7","0.00239325","0","1"]],"bids":[["104448","0.29585327","0","9"],["104446.7","0.02882763","0","1"],["104443","0","0","0"],["104441.2","0.00478588","0","1"],["104439.4","0","0","0"],["104437.5","0.23630265","0","5"],["104437.4","0.00917832","0","1"],["104435.6","0.09427474","0","1"],["104435.5","0","0","0"],["104434.6","0.16242937","0","1"],["104434.5","0","0","0"],["104434","0.15235533","0","1"],["104433.9","0","0","0"],["104430.3","0.23857932","0","1"],["104430.2","0","0","0"],["104429.9","0.1945068","0","2"],["104429.8","0","0","0"],["104429.7","0.10492676","0","2"],["104428","0","0","0"],["104424.6","0.24417961","0","1"],["104424.5","0","0","0"],["104422.1","0.13879281","0","1"],["104421.1","0","0","0"],["104342.3","0.01152169","0","2"],["104342.1","0.00022221","0","1"]],"ts":"1747170437500","checksum":1326292552,"seqId":54226331795,"prevSeqId":54226331680}]}
{"arg":{"channel":"books","instId":"BTC-USDT"},"action":"update","data":[{"asks":[["104448.1","0.55162065","0","17"],["104452.7","0","0","0"],["104456.5","0.00152861","0","1"],["104461.4","0","0","0"],["104461.9","0.77866876","0","1"],["104464","0.00478576","0","1"],["104483","0.002","0","2"],["104484","0.001","0","1"],["104486","0.44660783","0","2"],["104487","0.000015","0","1"],["104503","0.26","0","4"],["104504","0.12999999","0","2"],["104506","0.07","0","2"],["104507","0.269","0","2"],["104637.2","0","0","0"],["104637.8","0","0","0"],["104639.1","0","0","0"],["104639.3","0","0","0"],["104639.7","0","0","0"]],"bids":[["104431.8","0.00478576","0","1"],["104429.7","0.100141","0","1"],["104410.2","0.0022","0","1"],["104392.6","0.0022","0","1"],["104384.2","0","0","0"],["104356.5","0.01059571","0","1"],["104349.8","0.00485003","0","5"],["104348.8","0.0022","0","1"],["104342.9","0.01064362","0","2"],["104342.6","0","0","0"],["104342.4","0","0","0"],["104342.3","0","0","0"],["104342.1","0","0","0"]],"ts":"1747170437600","checksum":-1014114988,"seqId":54226331846,"prevSeqId":54226331795}]}
{"arg":{"channel":"books","instId":"BTC-USDT"},"action":"update","data":[{"asks":[["104448.1","0.50795686","0","16"],["104455.2","0.02950417","0","1"],["104457.5","0","0","0"],["104458","0.58200726","0","3"],["104461.8","0.36908178","0","1"],["104463.1","0.00478576","0","1"],["104464","0","0","0"],["104469.1","0.1387932","0","1"],["104470","0.00029006","0","2"],["104521.4","0","0","0"],["104528.2","6.90816454","0","1"],["104633.2","0","0","0"],["104633.9","0","0","0"]],"bids":[["104440.5","0.17158907","0","2"],["104437.9","0.02554977","0","2"],["104435.2","0.002","0","1"],["104431.8","0","0","0"],["104430.5","0.00478576","0","1"],["104422.1","0","0","0"],["104421.1","0.1387932","0","1"],["104360.1","0","0","0"],["104342.6","0.0000203","0","1"]],"ts":"1747170437700","checksum":1499551981,"seqId":54226331899,"prevSeqId":54226331846}]}
{"arg":{"channel":"books","instId":"BTC-USDT"},"action":"update","data":[{"asks":[["104448.1","0.53977653","0","18"],["104524.8","6.94552391","0","3"],["104528.2","0","0","0"],["104580.6","0.0013452","0","1"],["104591","0.0026904","0","1"],["104633","0","0","0"]],"bids":[["104448","0.29586327","0","10"],["104360.1","0.00002964","0","1"],["104342.6","0","0","0"]],"ts":"1747170437800","checksum":516176063,"seqId":54226331910,"prevSeqId":54226331899}]}
{"arg":{"channel":"books","instId":"BTC-USDT"},"action":"update","data":[{"asks":[["104452.6","0.00152861","0","1"],["104452.7","0.19242972","0","1"],["104456.5","0","0","0"],["104463","0.3675506","0","4"],["104475.5","0.01","0","2"],["104524.8","0.052","0","2"],["104528.2","6.89352391","0","1"],["104630","0","0","0"],["104631.4","0","0","0"]],"bids":[["104445.8","0.005","0","1"],["104433.3","0.005","0","1"],["104360.1","0","0","0"],["104342.8","0","0","0"]],"ts":"1747170437900","checksum":1434203093,"seqId":54226331926,"prevSeqId":54226331910}]}
{"arg":{"channel":"books","instId":"BTC-USDT"},"action":"update","data":[{"asks":[["104448.1","0.55581001","0","19"],["104503","0.33","0","6"],["104504","0.16499999","0","3"],["104506","0","0","0"],["104507","0.234","0","1"],["104524.8","6.94552391","0","3"],["104528.2","0","0","0"],["104630","0.00151107","0","2"],["104631.4","0.00001","0","1"]],"bids":[],"ts":"1747170438000","checksum":-156806702,"seqId":54226331941,"prevSeqId":54226331926}]}
{"arg":{"channel":"books","instId":"BTC-USDT"},"action":"update","data":[{"asks":[["104448.1","0.53977653","0","18"],["104455.1","0.0001303","0","1"],["104455.3","0","0","0"],["104462","0.16013876","0","2"],["104463.1","0","0","0"],["104467.9","0.13879517","0","1"],["104469.1","0","0","0"],["104487.2","0.00013997","0","1"],["104487.6","0","0","0"],["104521.4","6.89352391","0","1"],["104524.8","0.052","0","2"]],"bids":[["104444.5","0.24","0","1"],["104440.4","0","0","0"],["104435.4","0","0","0"],["104434.2","0.00958681","0","2"],["104430.5","0.00478577","0","1"],["104421.1","0","0","0"],["104418.2","0.1387954","0","1"],["104407.5","0.00056666","0","1"],["104401.3","0","0","0"],["104389","0.00056666","0","1"],["104382.8","0.00001537","0","1"],["104360.1","0.00002964","0","1"],["104342.9","0","0","0"]],"ts":"1747170438100","checksum":-1309256972,"seqId":54226331981,"prevSeqId":54226331941}]}
{"arg":{"channel":"books","instId":"BTC-USDT"},"action":"update","data":[{"asks":[["104462","0.15535299","0","1"],["104462.6","0.00478577","0","1"],["104556.1","0","0","0"]],"bids":[["104420.8","0.13879484","0","1"],["104418.2","0","0","0"],["104349.4","0.00009674","0","1"],["104349","0","0","0"]],"ts":"1747170438200","checksum":-1309256972,"seqId":54226331998,"prevSeqId":54226331981}]}
{"arg":{"channel":"books","instId":"BTC-USDT"},"action":"update","data":[{"asks":[["104520.2","2.21701432","0","2"],["104525.7","0","0","0"],["104633","1.89471219","0","1"]],"bids":[["104420.8","0","0","0"],["104418.2","0.13879485","0","1"],["104414.6","0.1506348","0","1"],["104378.1","0.45303474","0","1"],["104376.4","0","0","0"],["104343.3","0","0","0"]],"ts":"1747170438300","checksum":-1309256972,"seqId":54226332028,"prevSeqId":54226331998}]}
{"arg":{"channel":"books","instId":"BTC-USDT"},"action":"update","data":[{"asks":[["104448.1","0.55100767","0","17"],["104467.9","0.13879494","0","1"],["104550.2","0","0","0"],["104553.2","0","0","0"],["104630","0.00028006","0","1"],["104633.2","0.04783921","0","4"],["104633.9","0.00014488","0","1"]],"bids":[["104444.5","0","0","0"],["104418.2","0.13879494","0","1"],["104352.8","0","0","0"],["104343.3","0.00023233","0","3"],["104342.9","0.01064362","0","2"]],"ts":"1747170438400","checksum":-1772854990,"seqId":54226332050,"prevSeqId":54226332028}]}
{"arg":{"channel":"books","instId":"BTC-USDT"},"action":"update","data":[{"asks":[["104448.1","0.51978932","0","16"],["104520.2","0.78897017","0","1"],["104521.4","0","0","0"],["104528.2","6.89352391","0","1"],["104554","0.40848244","0","1"],["104604.8","0.01349496","0","1"],["104605.2","0.00095597","0","1"],["104633","0","0","0"],["104633.2","0","0","0"],["104633.9","0","0","0"]],"bids":[["104420.8","0.1387948","0","1"],["104418.2","0","0","0"]],"ts":"1747170438500","checksum":-1935246450,"seqId":54226332067,"prevSeqId":54226332050}]}
{"arg":{"channel":"books","instId":"BTC-USDT"},"action":"update","data":[{"asks":[["104448.1","0.55460716","0","18"],["104521.4","6.89352391","0","1"],["104528.2","0","0","0"]],"bids":[["104440.7","0.00030064","0","1"],["104440.6","0.19242972","0","1"],["104420.8","0","0","0"],["104418.2","0.13879501","0","1"],["104342.9","0","0","0"]],"ts":"1747170438600","checksum":-1037937510,"seqId":54226332079,"prevSeqId":54226332067}]}
{"arg":{"channel":"books","instId":"BTC-USDT"},"action":"update","data":[{"asks":[["104461.4","0.00478577","0","1"],["104461.9","0.78345582","0","2"],["104462.6","0","0","0"],["104471.8","0.00711203","0","1"]],"bids":[["104430.5","0","0","0"],["104428","0.00478577","0","1"]],"ts":"1747170438700","checksum":-1037937510,"seqId":54226332087,"prevSeqId":54226332079}]}
{"arg":{"channel":"books","instId":"BTC-USDT"},"action":"update","data":[{"asks":[["104467.9","0","0","0"],["104469.1","0.13879444","0","1"]],"bids":[["104428.9","0.00479577","0","2"],["104428","0","0","0"],["104421.1","0.13879444","0","1"],["104418.2","0","0","0"],["104342.9","0.01064362","0","2"]],"ts":"1747170438800","checksum":-1037937510,"seqId":54226332093,"prevSeqId":54226332087}]}
{"arg":{"channel":"books","instId":"BTC-USDT"},"action":"update","data":[{"asks":[["104448.1","0.52642276","0","16"],["104494.3","0","0","0"],["104494.4","0","0","0"],["104525.8","0.01053134","0","1"],["104633","1.89471219","0","1"],["104633.2","0.04783921","0","4"]],"bids":[["104404.5","0","0","0"],["104404.4","0","0","0"],["104373.2","0.22395706","0","2"],["104373.1","0.1913","0","1"],["104342.8","0.00076959","0","3"],["104342.6","0.0000203","0","1"]],"ts":"1747170438900","checksum":-1874983878,"seqId":54226332108,"prevSeqId":54226332093}]}
{"arg":{"channel":"books","instId":"BTC-USDT"},"action":"update","data":[{"asks":[["104494.5","1.39578086","0","1"],["104521.4","0","0","0"],["104524.8","6.98529597","0","3"],["104525.9","2.51598521","0","3"]],"bids":[["104406.9","1.3923043","0","1"],["104375.6","2.44171578","0","4"],["104342.6","0","0","0"]],"ts":"1747170439000","checksum":-1874983878,"seqId":54226332117,"prevSeqId":54226332108}]}
{"arg":{"channel":"books","instId":"BTC-USDT"},"action":"update","data":[{"asks":[["104448.1","0.91236539","0","19"],["104452.6","0.0273424","0","2"],["104456.5","0.08970517","0","1"],["104456.6","0.00001","0","1"],["104457.1","0","0","0"],["104457.9","0.09448816","0","2"],["104458","0.491201","0","2"],["104460","0.00507583","0","3"],["104461.4","0.15105392","0","1"],["104461.5","0","0","0"],["104462","0.32616613","0","2"],["104462.1","0.05209157","0","2"],["104463","0.39219577","0","4"],["104464.8","0.14867378","0","1"],["104464.9","0.002","0","1"],["104465.2","0.23412949","0","1"],["104465.3","0","0","0"],["104466.6","0","0","0"],["104467.5","0.24482929","0","2"],["104467.6","0","0","0"],["104467.9","0.13879482","0","1"],["104469.1","0","0","0"],["104604.8","0","0","0"],["104605.2","0","0","0"],["104633.9","0.00014488","0","1"],["104637.2","0.03","0","1"],["104637.8","0.77866876","0","1"]],"bids":[["104448","0.27986327","0","9"],["104446.7","0","0","0"],["104444.9","0","0","0"],["104443.1","0.03138263","0","1"],["104440.8","0.00030064","0","1"],["104440.7","0.18663722","0","1"],["104440.5","0","0","0"],["104440.2","0","0","0"],["104437.5","0.14351976","0","4"],["104437.4","0.10097597","0","2"],["104435.6","0","0","0"],["104435.5","0.09498166","0","1"],["104434.6","0","0","0"],["104434.5","0.15476526","0","1"],["104434","0","0","0"],["104433.9","0.15135739","0","1"],["104430.3","0","0","0"],["104430.2","0.23181022","0","1"],["104429.9","0.02761675","0","1"],["104429.8","0.14576052","0","1"],["104428.9","0.00001","0","1"],["104428","0.00478577","0","1"],["104424.6","0","0","0"],["104424.5","0.27019914","0","1"],["104421.1","0","0","0"],["104418.2","0.13879485","0","1"],["104414.6","0","0","0"],["104414.5","0.00003296","0","1"],["104407.7","0.00056666","0","1"],["104407.5","0","0","0"],["104405","0.47126418","0","1"],["104389","0","0","0"],["104388.3","0.77923542","0","2"],["104342.6","0.0000203","0","1"]],"ts":"1747170439100","checksum":-1259911913,"seqId":54226332191,"prevSeqId":54226332117}]}
{"arg":{"channel":"books","instId":"BTC-USDT"},"action":"update","data":[{"asks":[["104452.5","0.00152861","0","1"],["104452.6","0","0","0"],["104521.4","6.93329597","0","1"],["104524.8","0.052","0","2"],["104637.8","0","0","0"]],"bids":[["104441.2","0.00478592","0","1"],["104437.9","0.07743059","0","3"],["104434.2","0.000015","0","1"],["104433.4","0.00957188","0","1"],["104342.6","0","0","0"]],"ts":"1747170439200","checksum":3485478,"seqId":54226332223,"prevSeqId":54226332191}]}
{"arg":{"channel":"books","instId":"BTC-USDT"},"action":"update","data":[{"asks":[["104448.1","0.90847146","0","18"],["104452.5","0","0","0"],["104452.6","0.00152861","0","1"],["104455.8","0.0287656","0","1"],["104460","0.00029006","0","2"],["104462.6","0.00478577","0","1"],["104467.9","0","0","0"],["104468.1","0.42488609","0","4"],["104481","0.002","0","2"],["104482","0.001","0","1"],["104483","0","0","0"],["104484","0","0","0"],["104494.4","0.95699895","0","1"],["104501","0.23","0","4"],["104502","0.21499999","0","4"],["104503","0.05","0","1"],["104504","0","0","0"],["104505.3","0.413491","0","1"],["104537.1","0","0","0"],["104541","1.38786641","0","1"],["104551.8","0.00095646","0","1"],["104631.4","0","0","0"],["104633","0","0","0"],["104633.2","0","0","0"],["104633.9","0","0","0"],["104637.2","0","0","0"]],"bids":[["104445.2","0.03119051","0","1"],["104430.5","0.00478577","0","1"],["104428","0","0","0"],["104420.8","0.13879452","0","1"],["104418.2","0","0","0"],["104409.7","0.88403409","0","2"],["104378.1","1.12890728","0","2"],["104360.1","0","0","0"],["104351.4","0.00173872","0","1"],["104349.4","0","0","0"]],"ts":"1747170439300","checksum":1260000738,"seqId":54226332277,"prevSeqId":54226332223}]}
{"arg":{"channel":"books","instId":"BTC-USDT"},"action":"update","data":[{"asks":[["104448.1","0.47891225","0","13"],["104449.9","0","0","0"],["104452.6","0","0","0"],["104452.7","0.00152861","0","1"],["104452.8","0","0","0"],["104457.9","0.00044","0","1"],["104458","0","0","0"],["104461.4","0","0","0"],["104461.9","0.00478706","0","1"],["104462.6","0","0","0"],["104464","0.00478577","0","1"],["104464.8","0","0","0"],["104468.1","0.28609157","0","3"],["104469.1","0.13879421","0","1"],["104551.5","0.01350184","0","1"],["104628.8","0.07421474","0","2"],["104631.4","0.00001","0","1"],["104633","1.89471219","0","1"],["104633.2","0.04783921","0","4"],["104633.9","0.00014488","0","1"]],"bids":[["104448","0.29586327","0","10"],["104437.4","0.00917832","0","1"],["104433.9","0","0","0"],["104432.8","0","0","0"],["104431.8","0.00478577","0","1"],["104430.5","0","0","0"],["104429.8","0","0","0"],["104421.1","0.13879421","0","1"],["104420.8","0","0","0"],["104360.1","0.00002964","0","1"],["104342.6","0.0000203","0","1"],["104342.4","0.0078311","0","2"]],"ts":"1747170439400","checksum":-1028256480,"seqId":54226332316,"prevSeqId":54226332277}]}
{"arg":{"channel":"books","instId":"BTC-USDT"},"action":"update","data":[{"asks":[["104448.1","0.47189425","0","12"],["104452.2","0","0","0"],["104452.7","0","0","0"],["104453.3","0.00152861","0","1"],["104453.4","0.25551127","0","1"],["104455.1","0","0","0"],["104456.5","0","0","0"],["104456.6","0.0908302","0","2"],["104457","0","0","0"],["104457.1","0.09586193","0","1"],["104458.1","0.08648532","0","1"],["104458.4","0.07123683","0","3"],["104458.6","0.21222737","0","1"],["104458.7","0.09418599","0","1"],["104459.1","0.05209157","0","2"],["104461.6","0.14577001","0","1"],["104461.8","0","0","0"],["104462","0","0","0"],["104462.1","0.36826454","0","4"],["104463","0.37153361","0","4"],["104465","0.1660008","0","1"],["104465.2","0","0","0"],["104465.4","0.25194302","0","1"],["104467","0","0","0"],["104467.1","0.27184693","0","1"],["104467.5","0.00056666","0","1"],["104467.6","0.24911746","0","1"],["104469.1","0","0","0"],["104470","0.13908271","0","3"],["104471.1","0","0","0"],["104471.2","0.25371534","0","1"],["104471.7","0.0001303","0","1"],["104479.8","0.04344627","0","1"],["104481","0","0","0"],["104482","0","0","0"],["104483","0.002","0","2"],["104484","0.001","0","1"],["104496","1","0","1"],["104501","0","0","0"],["104502","0","0","0"],["104503","0.33","0","6"],["104504","0.16499999","0","3"],["104521.4","0","0","0"],["104528.2","6.93329597","0","1"],["104555.8","0.00009618","0","1"],["104633","0","0","0"],["104633.2","0","0","0"],["104633.9","0","0","0"]],"bids":[["104448","0.3317717","0","11"],["104446.9","0.03119001","0","1"],["104446.1","0.04497709","0","1"],["104441.2","0.00478572","0","1"],["104437.9","0.05234187","0","2"],["104437.6","0.18168949","0","2"],["104437.5","0.02321488","0","2"],["104436.2","0.09349139","0","1"],["104436.1","0.00870083","0","1"],["104435.6","0.09815607","0","1"],["104435.5","0","0","0"],["104434.6","0.15862302","0","1"],["104434.5","0","0","0"],["104434.1","0.15360832","0","2"],["104432.6","0.15884934","0","3"],["104432.5","0","0","0"],["104430.4","0.27531493","0","2"],["104430.2","0","0","0"],["104430","0.16475411","0","3"],["104427.6","0.26139287","0","1"],["104427.5","0.0000125","0","1"],["104424.6","0.25641916","0","1"],["104424.5","0","0","0"],["104423.7","0.25820678","0","2"],["104423.6","0.17796783","0","1"],["104422.1","0.13879265","0","1"],["104421.1","0","0","0"],["104377","0.0106929","0","5"],["104360.1","0","0","0"],["104349","0.00010169","0","1"],["104342.8","0","0","0"],["104342.6","0","0","0"],["104342.4","0","0","0"]],"ts":"1747170439500","checksum":-222298633,"seqId":54226332474,"prevSeqId":54226332316}]}
{"arg":{"channel":"books","instId":"BTC-USDT"},"action":"update","data":[{"asks":[["104448.1","0.55310936","0","14"],["104450","0.04426944","0","3"],["104458.1","0","0","0"],["104458.6","0.57375511","0","2"],["104458.7","0","0","0"],["104461.5","0.77866876","0","1"],["104461.6","0","0","0"],["104462","0.36908178","0","1"],["104462.9","0.00478584","0","1"],["104464","0","0","0"],["104465","0","0","0"],["104465.4","0","0","0"],["104471.2","0","0","0"],["104481","0.002","0","2"],["104482","0.001","0","1"],["104483","0","0","0"],["104484","0","0","0"],["104496","0","0","0"],["104501","0.23","0","4"],["104502","0.21499999","0","4"],["104503","0.05","0","1"],["104504","0","0","0"],["104521.4","6.93329597","0","1"],["104528.2","0","0","0"],["104554","0","0","0"],["104633","1.89471219","0","1"],["104633.2","0.04783921","0","4"],["104633.9","0.00014488","0","1"],["104637.2","0.03","0","1"],["104637.8","0.77866876","0","1"]],"bids":[["104448","0.29586327","0","10"],["104446.1","0","0","0"],["104439.7","0.02508872","0","1"],["104437.6","0.09502202","0","1"],["104436.2","0","0","0"],["104434.1","0.00005","0","1"],["104431.8","0","0","0"],["104430.5","0.00478584","0","1"],["104430.4","0.04","0","1"],["104430","0.00029006","0","2"],["104423.7","0.00004788","0","1"],["104342.8","0.00076959","0","3"]],"ts":"1747170439600","checksum":-1438834060,"seqId":54226332525,"prevSeqId":54226332474}]}
{"arg":{"channel":"books","instId":"BTC-USDT"},"action":"update","data":[{"asks":[["104448.1","0.52800517","0","14"],["104458","0.09209295","0","1"],["104458.6","0.66750793","0","3"],["104461.5","0.93062283","0","2"],["104463","0.36950097","0","4"],["104464.9","0.1674298","0","2"],["104465.3","0.25052432","0","1"],["104471.1","0.23731307","0","1"],["104633.9","0","0","0"],["104637.2","0","0","0"],["104637.8","0","0","0"]],"bids":[["104442.3","0.00478589","0","1"],["104441.2","0","0","0"],["104440.8","0","0","0"],["104440.7","0.1201806","0","1"],["104440.6","0","0","0"],["104440.1","0.00030064","0","1"],["104437.5","0.11035267","0","3"],["104436.1","0.10407491","0","2"],["104434","0.15958383","0","1"],["104430.3","0.23141143","0","1"],["104429.9","0.17720739","0","2"],["104423.6","0.41569213","0","2"],["104342.8","0","0","0"]],"ts":"1747170439700","checksum":-930465265,"seqId":54226332556,"prevSeqId":54226332525}]}
{"arg":{"channel":"books","instId":"BTC-USDT"},"action":"update","data":[{"asks":[["104448.1","0.55162141","0","15"],["104452.6","0.00152861","0","1"],["104452.7","0.19242972","0","1"],["104453.3","0","0","0"],["104469.1","0.13879314","0","1"],["104470","0.00029006","0","2"],["104521.4","0","0","0"],["104528.2","6.93329597","0","1"],["104633","0","0","0"],["104633.2","0","0","0"]],"bids":[["104442.3","0","0","0"],["104441.2","0.00478589","0","1"],["104422.1","0","0","0"],["104421.1","0.13879314","0","1"]],"ts":"1747170439800","checksum":633171520,"seqId":54226332570,"prevSeqId":54226332556}]}
{"arg":{"channel":"books","instId":"BTC-USDT"},"action":"update","data":[{"asks":[["104452.7","0","0","0"],["104462.9","0","0","0"],["104464","0.00478584","0","1"],["104521.4","6.91649271","0","1"],["104528.2","0","0","0"],["104633","1.89471219","0","1"]],"bids":[["104442.3","0.0047859","0","1"],["104441.2","0","0","0"],["104431.8","0.00478584","0","1"],["104430.5","0","0","0"]],"ts":"1747170439900","checksum":1138379419,"seqId":54226332581,"prevSeqId":54226332570}]}
{"arg":{"channel":"books","instId":"BTC-USDT"},"action":"update","data":[{"asks":[["104448.1","0.50422899","0","13"],["104452.6","0","0","0"],["104453.3","0.00152861","0","1"],["104458.6","0.62841654","0","3"],["104461.5","0.15195407","0","1"],["104461.9","0.78345582","0","2"],["104469.1","0.13879317","0","1"],["104481","0","0","0"],["104482","0","0","0"],["104483","0.002","0","2"],["104484","0.001","0","1"],["104501","0","0","0"],["104502","0","0","0"],["104503","0.33","0","6"],["104504","0.16499999","0","3"],["104521.4","0","0","0"],["104524.8","6.96849271","0","3"],["104633.2","0.04783921","0","4"],["104633.9","0.00014488","0","1"]],"bids":[["104421.1","0.13879317","0","1"]],"ts":"1747170440000","checksum":-612617887,"seqId":54226332637,"prevSeqId":54226332581}]}
{"arg":{"channel":"books","instId":"BTC-USDT"},"action":"update","data":[{"asks":[["104448.1","0.54515461","0","15"],["104463.3","0.00478584","0","1"],["104464","0","0","0"],["104469.1","0.13879312","0","1"],["104524.8","0.052","0","2"],["104528.2","6.91649271","0","1"],["104633.9","0","0","0"]],"bids":[["104433.4","0","0","0"],["104432.7","0.18762733","0","3"],["104431.8","0","0","0"],["104431.7","0.00576584","0","2"],["104421.2","0.13879312","0","1"],["104421.1","0","0","0"],["104408.5","0.00060018","0","2"],["104407.7","0","0","0"],["104389.1","0.00056666","0","1"],["104388.3","0.77866876","0","1"],["104342.8","0.00076959","0","3"],["104342.6","0.0000203","0","1"]],"ts":"1747170440100","checksum":1173846383,"seqId":54226332708,"prevSeqId":54226332637}]}
{"arg":{"channel":"books","instId":"BTC-USDT"},"action":"update","data":[{"asks":[["104463.3","0","0","0"],["104464","0.00478584","0","1"],["104481","0.002","0","2"],["104482","0.001","0","1"],["104483","0","0","0"],["104484","0","0","0"],["104501","0.07","0","2"],["104502","0.135","0","3"],["104503","0.21","0","3"],["104504","0.07999999","0","1"],["104633","0","0","0"],["104633.2","0","0","0"]],"bids":[["104431.8","0.00478584","0","1"],["104431.7","0.00098","0","1"],["104349.4","0.00009584","0","1"],["104349","0","0","0"],["104342.6","0","0","0"]],"ts":"1747170440200","checksum":1173846383,"seqId":54226332731,"prevSeqId":54226332708}]}
{"arg":{"channel":"books","instId":"BTC-USDT"},"action":"update","data":[{"asks":[["104448.1","0.52006589","0","14"],["104463.1","0.00478584","0","1"],["104464","0","0","0"],["104469.1","0.13879354","0","1"],["104481","0","0","0"],["104482","0","0","0"],["104483","0.002","0","2"],["104484","0.001","0","1"],["104501","0","0","0"],["104502","0","0","0"],["104503","0.33","0","6"],["104504","0.16499999","0","3"],["104525.8","1.378746","0","2"],["104633","1.89471219","0","1"],["104633.2","0.04783921","0","4"]],"bids":[["104431.8","0","0","0"],["104430.5","0.00478584","0","1"],["104421.2","0","0","0"],["104421.1","0.13879354","0","1"],["104405.1","0.20464226","0","3"]],"ts":"1747170440300","checksum":2063047463,"seqId":54226332780,"prevSeqId":54226332731}]}
{"arg":{"channel":"books","instId":"BTC-USDT"},"action":"update","data":[{"asks":[["104448.1","0.50422899","0","13"],["104469.1","0.13879361","0","1"],["104524.8","6.96849271","0","3"],["104525.8","0.01053134","0","1"],["104528.2","0","0","0"],["104541","0","0","0"],["104557.2","0.33778706","0","1"],["104633.9","0.00014488","0","1"]],"bids":[["104421.1","0.13879361","0","1"]],"ts":"1747170440400","checksum":-612617887,"seqId":54226332848,"prevSeqId":54226332780}]}
{"arg":{"channel":"books","instId":"BTC-USDT"},"action":"update","data":[{"asks":[["104448.1","0.54547654","0","15"],["104467.9","0.13879486","0","1"],["104469.1","0","0","0"],["104481","0.002","0","2"],["104482","0.001","0","1"],["104483","0","0","0"],["104484","0","0","0"],["104501","0.07","0","2"],["104502","0.29499999","0","5"],["104503","0.12999999","0","2"],["104504","0","0","0"],["104633.9","0","0","0"]],"bids":[["104442.3","0","0","0"],["104441.2","0.00478585","0","1"],["104430.5","0.00478585","0","1"],["104421.1","0","0","0"],["104420.8","0.13879477","0","1"]],"ts":"1747170440500","checksum":-1861891528,"seqId":54226332896,"prevSeqId":54226332848}]}
{"arg":{"channel":"books","instId":"BTC-USDT"},"action":"update","data":[{"asks":[["104467.9","0","0","0"],["104469.1","0.13879421","0","1"],["104496","1","0","1"],["104524.8","0.052","0","2"],["104528.2","6.91649271","0","1"],["104633","0","0","0"],["104633.2","0","0","0"]],"bids":[["104442.3","0.00478588","0","1"],["104441.2","0","0","0"],["104431.6","0.4561788","0","3"],["104430.5","0","0","0"],["104421.1","0.13879421","0","1"],["104420.8","0","0","0"],["104342.6","0.0000203","0","1"]],"ts":"1747170440600","checksum":-2097450458,"seqId":54226332907,"prevSeqId":54226332896}]}
{"arg":{"channel":"books","instId":"BTC-USDT"},"action":"update","data":[{"asks":[["104501","0.23","0","4"],["104502","0.21499999","0","4"],["104503","0.05","0","1"]],"bids":[["104448","0.29592327","0","11"]],"ts":"1747170440700","checksum":1981661832,"seqId":54226332912,"prevSeqId":54226332907}]}
{"arg":{"channel":"books","instId":"BTC-USDT"},"action":"update","data":[{"asks":[],"bids":[["104377","0.01066326","0","4"]],"ts":"1747170440800","checksum":1981661832,"seqId":54226332916,"prevSeqId":54226332912}]}
{"arg":{"channel":"books","instId":"BTC-USDT"},"action":"update","data":[{"asks":[["104456.5","0.09205866","0","1"],["104456.6","0.00001","0","1"],["104457","0.09762126","0","1"],["104457.1","0","0","0"],["104461.4","0.00478585","0","1"],["104462","0.67366019","0","3"],["104462.1","0.05209157","0","2"],["104463","0.37768653","0","4"],["104463.1","0","0","0"],["104464.8","0.15451997","0","1"],["104464.9","0.002","0","1"],["104465.2","0.25323451","0","1"],["104465.3","0","0","0"],["104467","0.24104182","0","1"],["104467.1","0","0","0"],["104467.5","0.27191948","0","2"],["104467.6","0","0","0"],["104481","0","0","0"],["104482","0","0","0"],["104483","0.002","0","2"],["104484","0.001","0","1"],["104501","0","0","0"],["104502","0","0","0"],["104503","0.33","0","6"],["104504","0.16499999","0","3"]],"bids":[["104448","0.27672812","0","11"],["104437.6","0","0","0"],["104437.5","0.21235221","0","4"],["104435.6","0","0","0"],["104435.5","0.10030974","0","1"],["104434.6","0","0","0"],["104434.5","0.16237723","0","1"],["104432.6","0.00033148","0","2"],["104432.5","0.15417655","0","1"],["104431.6","0.44886225","0","2"],["104430.3","0","0","0"],["104430.2","0.25738253","0","1"],["104429.9","0.02761675","0","1"],["104429.8","0.14745279","0","1"],["104428.9","0.00479585","0","2"],["104427.6","0","0","0"],["104427.5","0.2493536","0","2"],["104424.6","0","0","0"],["104424.5","0.25782321","0","1"]],"ts":"1747170440900","checksum":-857223044,"seqId":54226332985,"prevSeqId":54226332916}]}
{"arg":{"channel":"books","instId":"BTC-USDT"},"action":"update","data":[{"asks":[["104448.1","0.5492097","0","15"],["104452.8","0.00152861","0","1"],["104452.9","0.21729892","0","2"],["104453.3","0","0","0"],["104469.1","0.13879336","0","1"],["104496","0","0","0"],["104524.8","6.96849271","0","3"],["104528.2","0","0","0"],["104633","1.89471219","0","1"],["104633.2","0.04783921","0","4"]],"bids":[["104428.9","0.00001","0","1"],["104428","0.00478585","0","1"],["104421.1","0.13879336","0","1"],["104342.6","0","0","0"]],"ts":"1747170441000","checksum":-153341411,"seqId":54226333057,"prevSeqId":54226332985}]}
{"arg":{"channel":"books","instId":"BTC-USDT"},"action":"update","data":[{"asks":[["104448.1","0.67070362","0","17"],["104453.2","0.02802287","0","1"],["104456.4","0.09831992","0","1"],["104456.5","0","0","0"],["104456.9","0.09073877","0","1"],["104457","0","0","0"],["104457.9","0.0924896","0","2"],["104458","0","0","0"],["104458.5","0.09166696","0","1"],["104458.6","0.53466372","0","2"],["104459.5","0.00478585","0","1"],["104461.4","0.16094065","0","1"],["104461.5","0","0","0"],["104461.9","1.1095953","0","4"],["104462","0.36908178","0","1"],["104463","0.41370551","0","4"],["104464.8","0.15114333","0","1"],["104465.1","0.23699859","0","1"],["104465.2","0","0","0"],["104466.9","0.37927042","0","2"],["104467","0","0","0"],["104467.4","0.277587","0","2"],["104467.5","0.00056666","0","1"],["104469.1","0","0","0"],["104471","0.25797221","0","1"],["104471.1","0","0","0"],["104474.1","0.05209157","0","2"],["104524.8","0.052","0","2"],["104528.2","6.90104886","0","1"],["104633.2","0","0","0"]],"bids":[["104448","0.26072812","0","10"],["104446.9","0","0","0"],["104445.2","0","0","0"],["104442.3","0","0","0"],["104441","0.02803716","0","1"],["104440.7","0","0","0"],["104440.2","0.00478593","0","1"],["104440.1","0","0","0"],["104439.5","0.00030064","0","1"],["104439.4","0.10229271","0","2"],["104437.5","0.02321488","0","2"],["104437.4","0.18709008","0","3"],["104436.8","0.47870694","0","3"],["104436.1","0.00870083","0","1"],["104436","0.09536119","0","1"],["104435.5","0","0","0"],["104435.4","0.08939583","0","1"],["104434.6","0.05408221","0","1"],["104434.5","0","0","0"],["104434.4","0.16336928","0","2"],["104434","0","0","0"],["104433.9","0.16196678","0","1"],["104432.5","0","0","0"],["104432.4","0.16462221","0","1"],["104431.6","0.4470891","0","2"],["104430.2","0","0","0"],["104430.1","0.23180993","0","1"],["104429.8","0.16412762","0","1"],["104428","0","0","0"],["104427.5","0.00479835","0","2"],["104427.4","0.28232838","0","2"],["104426.2","0.00001731","0","1"],["104424.5","0","0","0"],["104424.4","0.25870641","0","1"],["104423.6","0.17796783","0","1"],["104423.5","0.26031803","0","1"],["104421.1","0","0","0"],["104418.2","0.1387971","0","1"],["104414.8","0.01411892","0","1"],["104409.1","0.00057666","0","2"],["104408.5","0.00003352","0","1"],["104389.7","0.00056666","0","1"],["104389.1","0","0","0"],["104377","0.0106929","0","5"],["104342.8","0","0","0"]],"ts":"1747170441100","checksum":-1836886624,"seqId":54226333250,"prevSeqId":54226333057}]}
{"arg":{"channel":"books","instId":"BTC-USDT"},"action":"update","data":[{"asks":[["104459.5","0","0","0"],["104460","0.00507591","0","3"],["104464.7","0.14643452","0","1"],["104464.8","0","0","0"],["104524.8","6.95304886","0","3"],["104528.2","0","0","0"],["104629.8","0.00037885","0","1"],["104633.2","0.04783921","0","4"]],"bids":[["104448","0.25755812","0","7"],["104432.7","0.17805538","0","2"],["104432","0.00957201","0","1"],["104429.8","0","0","0"],["104429.7","0.24926442","0","2"],["104428","0.00478585","0","1"],["104427.5","0.0000125","0","1"],["104342.9","0","0","0"]],"ts":"1747170441200","checksum":-1782306116,"seqId":54226333269,"prevSeqId":54226333250}]}
{"arg":{"channel":"books","instId":"BTC-USDT"},"action":"update","data":[{"asks":[["104453.2","0","0","0"],["104465.7","0.05701232","0","1"],["104524.8","0.052","0","2"],["104528.2","6.90104886","0","1"],["104633.2","0","0","0"]],"bids":[["104377","0.01066326","0","4"],["104349.4","0","0","0"],["104342.9","0.01064362","0","2"]],"ts":"1747170441300","checksum":-770466162,"seqId":54226333277,"prevSeqId":54226333269}]}
{"arg":{"channel":"books","instId":"BTC-USDT"},"action":"update","data":[{"asks":[["104525.8","1.31937245","0","2"]],"bids":[["104445.6","0.02389496","0","1"],["104439.8","0.00030064","0","1"],["104439.5","0","0","0"],["104437.9","0.00046105","0","1"],["104388.8","0.36353493","0","3"],["104377.1","0.00002964","0","1"],["104343.3","0","0","0"],["104342.9","0","0","0"]],"ts":"1747170441400","checksum":1041493870,"seqId":54226333287,"prevSeqId":54226333277}]}
{"arg":{"channel":"books","instId":"BTC-USDT"},"action":"update","data":[{"asks":[["104460","0.00507592","0","3"],["104466.9","0.24047332","0","1"],["104467.3","0.13879567","0","1"],["104524.8","6.95304886","0","3"],["104525.8","0.01053134","0","1"],["104528.2","0","0","0"]],"bids":[["104418.2","0.13879567","0","1"],["104349.4","0.00009645","0","1"],["104343.4","0","0","0"]],"ts":"1747170441500","checksum":1041493870,"seqId":54226333305,"prevSeqId":54226333287}]}
{"arg":{"channel":"books","instId":"BTC-USDT"},"action":"update","data":[{"asks":[["104452.2","0.01914629","0","1"],["104455.4","0.1246966","0","2"],["104455.9","0.09392272","0","1"],["104456.4","0","0","0"],["104456.9","0.09282861","0","1"],["104457.5","0.09892372","0","1"],["104457.9","0.00044","0","1"],["104458.3","0.00478583","0","1"],["104458.4","0.05209157","0","2"],["104458.5","0","0","0"],["104460","0.00029006","0","2"],["104460.4","0.14372017","0","1"],["104460.9","0.31503492","0","2"],["104461.4","0","0","0"],["104461.9","0.78345582","0","2"],["104463","0.42766645","0","4"],["104463.7","0.15801988","0","1"],["104464.1","0.3031875","0","3"],["104464.7","0","0","0"],["104465.1","0","0","0"],["104465.6","0.13879846","0","1"],["104465.9","0.25261225","0","1"],["104466.4","0.24822997","0","1"],["104466.9","0","0","0"],["104467.3","0","0","0"],["104467.4","0.00478697","0","1"],["104470","0.25818371","0","3"],["104471","0","0","0"],["104524.8","0.052","0","2"],["104528.2","6.90104886","0","1"],["104630","0","0","0"],["104631.4","0","0","0"],["104633","0","0","0"]],"bids":[["104448","0.13805812","0","6"],["104440.2","0","0","0"],["104439.8","0","0","0"],["104439.7","0","0","0"],["104439.6","0.0047859","0","1"],["104439.5","0.00030064","0","1"],["104439.4","0.04628199","0","1"],["104437.4","0.00917832","0","1"],["104436.8","0.28431218","0","3"],["104436.4","0.19565796","0","2"],["104436","0","0","0"],["104435.4","0","0","0"],["104435","0.09132911","0","1"],["104434.4","0.1015845","0","2"],["104433.9","0","0","0"],["104433.7","0","0","0"],["104433.4","0.16615","0","1"],["104432.9","0.16204445","0","1"],["104432.4","0","0","0"],["104431.6","0.42140219","0","2"],["104431.4","0.1635588","0","1"],["104430.1","0","0","0"],["104429.7","0.100141","0","1"],["104429.1","0.24429631","0","1"],["104428.7","0.15478778","0","1"],["104428","0","0","0"],["104427.4","0.03","0","1"],["104426.6","0.00478583","0","1"],["104426.4","0.25193483","0","1"],["104424.4","0","0","0"],["104423.5","0","0","0"],["104423.4","0.23948508","0","1"],["104422.5","0.26267032","0","1"],["104418.2","0","0","0"],["104417.8","0.13879846","0","1"],["104343.6","0","0","0"]],"ts":"1747170441600","checksum":-275303026,"seqId":54226333405,"prevSeqId":54226333305}]}
{"arg":{"channel":"books","instId":"BTC-USDT"},"action":"update","data":[{"asks":[["104448.1","0.76026362","0","18"],["104453.4","0.2835341","0","2"],["104455.2","0.13080749","0","2"],["104455.4","0.02718728","0","1"],["104455.7","0.09635343","0","1"],["104455.9","0","0","0"],["104456.7","0.0886761","0","1"],["104456.9","0","0","0"],["104457.3","0.09368089","0","1"],["104457.5","0","0","0"],["104458.1","0.00478583","0","1"],["104458.3","0","0","0"],["104460.2","0.1605181","0","1"],["104460.4","0","0","0"],["104460.7","0.32031812","0","2"],["104460.9","0","0","0"],["104463","0.33579712","0","4"],["104463.6","0.15679197","0","1"],["104463.7","0","0","0"],["104463.9","0.25026936","0","1"],["104464.1","0.05209157","0","2"],["104465.6","0","0","0"],["104465.7","0.23754654","0","1"],["104465.9","0","0","0"],["104466.2","0.25368106","0","1"],["104466.4","0","0","0"],["104467.9","0.13879704","0","1"],["104469.8","0.2482717","0","1"],["104470","0.00029006","0","2"],["104481","0.002","0","2"],["104482","0.001","0","1"],["104483","0","0","0"],["104484","0","0","0"],["104494.4","0.5382647","0","1"],["104494.5","0","0","0"],["104501","0.23","0","4"],["104502","0.21499999","0","4"],["104503","0.05","0","1"],["104504","0","0","0"],["104525.9","0.052","0","2"],["104629.8","0","0","0"]],"bids":[["104448","0.14090812","0","7"],["104445.6","0","0","0"],["104436.8","0.29054298","0","3"],["104436.4","0","0","0"],["104436.2","0.18229106","0","2"],["104435","0","0","0"],["104434.8","0.09067131","0","1"],["104434.4","0.000015","0","1"],["104434.2","0.09474849","0","2"],["104433.4","0","0","0"],["104433.2","0.15638534","0","1"],["104432.9","0","0","0"],["104432.8","0.05408313","0","1"],["104432.7","0.3374114","0","3"],["104431.6","0.41931299","0","2"],["104431.4","0","0","0"],["104431.2","0.16551098","0","1"],["104429.1","0","0","0"],["104428.9","0.23628698","0","2"],["104428.7","0","0","0"],["104428.6","0.15867677","0","1"],["104426.4","0","0","0"],["104426.2","0.26221754","0","2"],["104423.4","0","0","0"],["104423.2","0.26610893","0","1"],["104422.5","0","0","0"],["104422.3","0.23832375","0","2"],["104418.2","0.13879704","0","1"],["104417.8","0","0","0"],["104409.7","0.53276891","0","1"],["104406.9","0","0","0"],["104401.2","0.01436431","0","1"],["104378.1","0.45303474","0","1"],["104375.6","0.00004285","0","3"],["104369.1","0.032871","0","2"],["104343.6","0.00001018","0","1"],["104343.4","0.00030712","0","2"],["104343.3","0.00023233","0","3"],["104342.9","0.01064362","0","2"],["104342.8","0.00076959","0","3"]],"ts":"1747170441700","checksum":-79622124,"seqId":54226333513,"prevSeqId":54226333405}]}
{"arg":{"channel":"books","instId":"BTC-USDT"},"action":"update","data":[{"asks":[["104453.4","0.30627847","0","3"],["104455.2","0","0","0"],["104455.7","0","0","0"],["104456.7","0","0","0"],["104457.3","0","0","0"],["104458.1","0","0","0"],["104459","0.00478584","0","1"],["104460.2","0","0","0"],["104460.7","0","0","0"],["104463","0.42835551","0","4"],["104463.6","0","0","0"],["104463.9","0","0","0"],["104465.5","0.05701239","0","1"],["104465.7","0","0","0"],["104466.2","0","0","0"],["104469.8","0","0","0"],["104494.5","1.43091549","0","1"],["104525.8","2.54060271","0","2"],["104528.2","6.86656501","0","1"],["104629.8","0.00037885","0","1"],["104630","0.00028006","0","1"],["104631.4","0.00001","0","1"],["104633","1.89471219","0","1"],["104633.2","0.04783921","0","4"],["104633.9","0.00014488","0","1"],["104637.2","0.03","0","1"],["104637.8","0.77866876","0","1"],["104639.3","0.00010253","0","1"]],"bids":[["104444.9","0.02389513","0","1"],["104436.8","0.27856169","0","3"],["104436.2","0","0","0"],["104434.8","0","0","0"],["104434.6","0","0","0"],["104434.2","0.000015","0","1"],["104433.2","0","0","0"],["104432.7","0.17805538","0","2"],["104431.6","0.41806611","0","2"],["104431.2","0","0","0"],["104428.9","0.00001","0","1"],["104428.6","0","0","0"],["104427","0.00478584","0","1"],["104426.6","0","0","0"],["104426.2","0.00001731","0","1"],["104423.2","0","0","0"],["104422.3","0.0000125","0","1"],["104404.1","1.59256865","0","3"],["104372.7","2.50447107","0","5"],["104342.6","0.0000203","0","1"],["104342.4","0.0078311","0","2"],["104342.3","0.00002108","0","1"],["104342.1","0.00022221","0","1"],["104342","0.01059526","0","1"],["104341.6","0.0001427","0","2"]],"ts":"1747170441800","checksum":1575381316,"seqId":54226333676,"prevSeqId":54226333513}]}
{"arg":{"channel":"books","instId":"BTC-USDT"},"action":"update","data":[{"asks":[["104451.3","0.02802339","0","1"],["104452.7","0.00152861","0","1"],["104452.8","0.32085236","0","1"],["104453.4","0.02802283","0","1"],["104455.1","0.10126022","0","1"],["104457.6","0.00478584","0","1"],["104459","0","0","0"],["104460.6","0.16629594","0","2"],["104463","0.41042968","0","4"],["104463.4","0.35689029","0","2"],["104463.7","0.13880046","0","1"],["104463.8","0.25321964","0","1"],["104465.5","0","0","0"],["104466.1","0.24631534","0","1"],["104467.9","0","0","0"],["104475.7","0.00287139","0","1"],["104475.9","0","0","0"],["104633.9","0","0","0"],["104637.2","0","0","0"],["104637.8","0","0","0"],["104639.3","0","0","0"]],"bids":[["104444.9","0","0","0"],["104443.1","0","0","0"],["104440","0.03498914","0","8"],["104439.6","0","0","0"],["104438.2","0.00478607","0","1"],["104438","0.04826454","0","1"],["104436.8","0.28948557","0","3"],["104436.7","0.01914664","0","1"],["104436.1","0","0","0"],["104434.5","0.02508872","0","1"],["104434.1","0.09005731","0","2"],["104433.1","0.16368765","0","1"],["104431.6","0.41690553","0","2"],["104430.4","0","0","0"],["104428.8","0.27657576","0","2"],["104428.4","0.15931602","0","1"],["104428.1","0.04","0","1"],["104427","0","0","0"],["104426.1","0.7072064","0","3"],["104424.9","0.00479584","0","2"],["104423.1","0.25778679","0","1"],["104418.2","0","0","0"],["104414.9","0.1461933","0","2"],["104405","0","0","0"],["104384.2","0.46355156","0","1"],["104341.6","0","0","0"]],"ts":"1747170441900","checksum":-1367215999,"seqId":54226333946,"prevSeqId":54226333676}]}
{"arg":{"channel":"books","instId":"BTC-USDT"},"action":"update","data":[{"asks":[["104448.1","1.01428214","0","20"],["104451.3","0","0","0"],["104455.1","0.00918691","0","1"],["104455.2","0.09544819","0","1"],["104455.7","0.09642867","0","1"],["104456.7","0.08791332","0","1"],["104457.3","0.08863723","0","1"],["104457.6","0","0","0"],["104458.5","0.00478585","0","1"],["104460.2","0.14284603","0","1"],["104460.6","0.00001","0","1"],["104460.7","0.33982072","0","2"],["104463","0.16038555","0","3"],["104463.4","0.19242972","0","1"],["104463.5","0.14723239","0","1"],["104463.7","0","0","0"],["104463.8","0","0","0"],["104463.9","0.24113014","0","1"],["104464.7","0.05701284","0","1"],["104465.7","0.24035004","0","1"],["104466.1","0","0","0"],["104466.2","0.27024563","0","1"],["104467.9","0.1387987","0","1"],["104469.8","0.2550867","0","1"],["104521.4","6.86656501","0","1"],["104528.2","0","0","0"],["104628","0","0","0"],["104628.6","0","0","0"],["104628.8","0","0","0"],["104629.5","0","0","0"],["104629.8","0","0","0"],["104630","0","0","0"],["104631.4","0","0","0"],["104633","0","0","0"],["104633.2","0","0","0"]],"bids":[["104443.4","0.02389547","0","1"],["104440","0.00695171","0","7"],["104439.5","0","0","0"],["104438.5","0.00030064","0","1"],["104436.8","0.156056","0","2"],["104436.2","0.19639544","0","2"],["104434.8","0.08794844","0","1"],["104434.2","0.09027413","0","2"],["104434.1","0.00005","0","1"],["104433.2","0.16755039","0","1"],["104433.1","0","0","0"],["104432.7","0.34155544","0","3"],["104431.6","0.28273687","0","1"],["104431.2","0.16418344","0","1"],["104428.9","0.23720223","0","2"],["104428.8","0.033","0","1"],["104428.5","0.16082074","0","2"],["104428.4","0","0","0"],["104426.6","0.00478585","0","1"],["104426.2","0.25900361","0","2"],["104426.1","0.45405565","0","2"],["104424.9","0.00001","0","1"],["104423.6","0.24975483","0","2"],["104423.2","0.23975417","0","1"],["104423.1","0","0","0"],["104422.3","0.2436919","0","2"],["104417.8","0.1387987","0","1"],["104414.9","0.00739284","0","1"],["104342.6","0","0","0"],["104342.4","0","0","0"],["104342.3","0","0","0"],["104342.1","0","0","0"],["104342","0","0","0"]],"ts":"1747170442000","checksum":888278814,"seqId":54226334049,"prevSeqId":54226333946}]}
{"arg":{"channel":"books","instId":"BTC-USDT"},"action":"update","data":[{"asks":[["104456.7","0","0","0"],["104458.5","0","0","0"],["104458.9","0.05296087","0","1"],["104459.5","0.00478585","0","1"],["104460.2","0","0","0"],["104463","0.42436621","0","4"],["104464.7","0","0","0"],["104465.6","0.13879843","0","1"],["104467.9","0","0","0"],["104628","0.01403883","0","1"],["104628.8","0.07421474","0","2"]],"bids":[["104439.5","0.00030064","0","1"],["104438.5","0","0","0"],["104438.2","0","0","0"],["104438.1","0.00478605","0","1"],["104436.8","0.49988781","0","2"],["104436.2","0.10143289","0","1"],["104433.3","0.78366876","0","2"],["104432.7","0.17805538","0","2"],["104432","0","0","0"],["104431.6","0.4212645","0","2"],["104431.3","0.00957208","0","1"],["104427.5","0.00479835","0","2"],["104426.6","0","0","0"],["104417.8","0.13879843","0","1"],["104409.6","0.54761627","0","3"],["104409.1","0.00001","0","1"],["104390.2","0.00056666","0","1"],["104389.7","0","0","0"],["104377.1","0","0","0"],["104342.6","0.0000203","0","1"],["104342.4","0.0078311","0","2"]],"ts":"1747170442100","checksum":1511108771,"seqId":54226334127,"prevSeqId":54226334049}]}
{"arg":{"channel":"books","instId":"BTC-USDT"},"action":"update","data":[{"asks":[["104455.1","0.1059943","0","2"],["104455.2","0","0","0"],["104455.6","0.10139795","0","1"],["104455.7","0","0","0"],["104456.6","0.09495936","0","2"],["104457.2","0.38513014","0","4"],["104457.3","0","0","0"],["104460.1","0.21042691","0","3"],["104460.6","0.33648448","0","3"],["104460.7","0","0","0"],["104463","0.39452192","0","4"],["104464.9","0","0","0"],["104465.6","0.25600418","0","1"],["104465.7","0","0","0"],["104465.8","0.13879756","0","1"],["104466.1","0.26695299","0","1"],["104466.2","0","0","0"],["104469.7","0.26564795","0","1"],["104469.8","0","0","0"],["104477.4","0.129","0","4"],["104607.4","0.23490238","0","2"],["104607.7","0","0","0"],["104628.6","0.234","0","1"],["104629.5","0.00010997","0","1"],["104629.8","0.00037885","0","1"],["104630","0.00028006","0","1"],["104631.4","0.00001","0","1"]],"bids":[["104448","0.13805812","0","6"],["104447.7","0","0","0"],["104439.5","0","0","0"],["104438.1","0.00030064","0","1"],["104437.6","0.00478596","0","1"],["104436.8","0.48717885","0","3"],["104436.2","0","0","0"],["104436.1","0.19182469","0","2"],["104435.2","0","0","0"],["104434.8","0","0","0"],["104434.7","0.09030501","0","1"],["104434.2","0.000015","0","1"],["104434.1","0.09466761","0","2"],["104433.2","0","0","0"],["104433.1","0.16163986","0","1"],["104432.6","0.14418559","0","3"],["104431.2","0","0","0"],["104431.1","0.15039136","0","1"],["104426.2","0.00001731","0","1"],["104426.1","0.69795282","0","3"],["104423.2","0","0","0"],["104423.1","0.24107711","0","1"],["104422.3","0.0000125","0","1"],["104422.2","0.23785195","0","1"],["104418.5","0.13879756","0","1"],["104417.8","0","0","0"],["104377.1","0.00002964","0","1"],["104349.6","0.00023587","0","4"],["104349.4","0","0","0"],["104342.3","0.00002108","0","1"]],"ts":"1747170442200","checksum":551936262,"seqId":54226334244,"prevSeqId":54226334127}]}
{"arg":{"channel":"books","instId":"BTC-USDT"},"action":"update","data":[{"asks":[["104459.5","0","0","0"],["104461.8","0.00478585","0","1"],["104463.4","0.3524607","0","2"],["104463.5","0","0","0"],["104463.8","0.24467015","0","1"],["104463.9","0","0","0"],["104465.8","0","0","0"],["104467.9","0.13879612","0","1"],["104633","1.89471219","0","1"]],"bids":[["104448","0.13485812","0","5"],["104429","0.00478585","0","1"],["104428.9","0.00001","0","1"],["104428.8","0.26877991","0","2"],["104428.5","0.0000125","0","1"],["104428.4","0.16566008","0","1"],["104427.5","0.0000125","0","1"],["104418.5","0","0","0"],["104418.2","0.13879612","0","1"],["104377.1","0","0","0"],["104342.3","0","0","0"]],"ts":"1747170442300","checksum":565668010,"seqId":54226334264,"prevSeqId":54226334244}]}
{"arg":{"channel":"books","instId":"BTC-USDT"},"action":"update","data":[{"asks":[["104466","0.14790374","0","3"],["104467.9","0","0","0"],["104633.2","0.04783921","0","4"]],"bids":[["104377.1","0.00002964","0","1"],["104342.4","0","0","0"]],"ts":"1747170442400","checksum":565668010,"seqId":54226334268,"prevSeqId":54226334264}]}
{"arg":{"channel":"books","instId":"BTC-USDT"},"action":"update","data":[{"asks":[["104465.5","0.13879897","0","1"],["104466","0.00910622","0","2"],["104520.2","2.45636951","0","2"],["104633.2","0","0","0"]],"bids":[["104418.2","0","0","0"],["104417.4","0.13891915","0","2"],["104405.1","0.45685109","0","4"],["104398","0.00004846","0","1"],["104396","0.48324487","0","1"],["104377.1","0","0","0"],["104373.2","0.94841557","0","3"],["104351","0.00024788","0","3"],["104349","0.47439916","0","1"]],"ts":"1747170442500","checksum":565668010,"seqId":54226334281,"prevSeqId":54226334268}]}
{"arg":{"channel":"books","instId":"BTC-USDT"},"action":"update","data":[{"asks":[["104455.1","0.00918691","0","1"],["104460.6","0.16913523","0","2"],["104463.4","0.19242972","0","1"],["104463.5","0.14971993","0","1"],["104463.8","0","0","0"],["104464.9","0.002","0","1"],["104466.1","0","0","0"],["104477.4","0.131","0","5"]],"bids":[["104448","0.13711812","0","6"],["104445.7","0.002","0","1"],["104438.5","0.00030064","0","1"],["104438.1","0","0","0"],["104434.1","0.00005","0","1"],["104433.2","0.002","0","1"],["104433.1","0","0","0"],["104428.8","0.033","0","1"],["104428.5","0.16146242","0","2"],["104428.4","0","0","0"],["104423.1","0","0","0"],["104377.1","0.00002964","0","1"]],"ts":"1747170442600","checksum":-1592656218,"seqId":54226334302,"prevSeqId":54226334281}]}
{"arg":{"channel":"books","instId":"BTC-USDT"},"action":"update","data":[{"asks":[["104456.6","0.00001","0","1"],["104460.1","0.05209157","0","2"],["104463","0.3943715","0","4"],["104463.5","0","0","0"],["104633.2","0.04783921","0","4"]],"bids":[["104445.1","0.02409495","0","1"],["104441","0","0","0"],["104438.5","0","0","0"],["104438.1","0.00030064","0","1"],["104436.1","0.10129874","0","1"],["104432.6","0.00033148","0","2"],["104428.5","0.0000125","0","1"]],"ts":"1747170442700","checksum":-409267262,"seqId":54226334334,"prevSeqId":54226334302}]}
{"arg":{"channel":"books","instId":"BTC-USDT"},"action":"update","data":[{"asks":[["104455.3","0.08983102","0","1"],["104455.6","0","0","0"],["104455.8","0.12636767","0","2"],["104456.7","0.0969099","0","1"],["104457.2","0.28609157","0","3"],["104457.4","0.09969034","0","1"],["104460.2","0.14372986","0","1"],["104460.6","0.00001","0","1"],["104460.7","0.00478585","0","1"],["104460.8","0.32650066","0","2"],["104461.8","0","0","0"],["104463","0.40627389","0","4"],["104463.6","0.15081467","0","1"],["104464","0.2546166","0","1"],["104465.6","0","0","0"],["104465.8","0.2617166","0","1"],["104466.3","0.26730592","0","1"],["104469.7","0","0","0"],["104469.9","0.2662055","0","1"],["104520.2","0.78897017","0","1"],["104521.4","0","0","0"],["104524.8","6.89063617","0","3"],["104554","0.4085113","0","1"],["104628.8","0","0","0"],["104629.5","0","0","0"],["104629.8","0","0","0"],["104630","0","0","0"],["104631.4","0","0","0"],["104633","0","0","0"],["104633.2","0","0","0"]],"bids":[["104438.5","0.00030064","0","1"],["104438.1","0","0","0"],["104436.3","0.0959811","0","1"],["104436.2","0.08595119","0","1"],["104436.1","0","0","0"],["104434.9","0.09780084","0","1"],["104434.7","0","0","0"],["104434.3","0.09102939","0","1"],["104433.3","0.93760063","0","3"],["104432.7","0.32822311","0","3"],["104431.3","0.17584033","0","2"],["104431.1","0","0","0"],["104429.1","0.00478585","0","1"],["104429","0.23263145","0","1"],["104428.6","0.16328733","0","1"],["104426.3","0.28875703","0","2"],["104426.1","0.45405565","0","2"],["104423.3","0.26885172","0","1"],["104422.4","0.23301871","0","1"],["104422.2","0","0","0"],["104343.3","0","0","0"],["104342.9","0","0","0"],["104342.8","0","0","0"],["104342.6","0","0","0"]],"ts":"1747170442800","checksum":1201890162,"seqId":54226334384,"prevSeqId":54226334334}]}
{"arg":{"channel":"books","instId":"BTC-USDT"},"action":"update","data":[{"asks":[["104460.7","0","0","0"],["104461.8","0.00478585","0","1"]],"bids":[],"ts":"1747170442900","checksum":1201890162,"seqId":54226334390,"prevSeqId":54226334384}]}
{"arg":{"channel":"books","instId":"BTC-USDT"},"action":"update","data":[{"asks":[["104448.1","0.8290645","0","20"],["104455.3","0","0","0"],["104455.8","0.0287656","0","1"],["104456.4","0.10159156","0","1"],["104456.7","0","0","0"],["104456.9","0.09769638","0","1"],["104457.4","0","0","0"],["104457.9","0.08989376","0","2"],["104458.5","0.09208501","0","1"],["104460.2","0","0","0"],["104460.8","0","0","0"],["104461.4","0.14912733","0","1"],["104461.9","1.1149363","0","4"],["104463","0.4006679","0","4"],["104463.6","0","0","0"],["104464","0","0","0"],["104464.8","0.15431601","0","1"],["104465.1","0.26131541","0","1"],["104465.5","0","0","0"],["104465.8","0","0","0"],["104466.3","0","0","0"],["104466.9","0.25327852","0","1"],["104467.4","0.2516464","0","2"],["104467.9","0.13879677","0","1"],["104469.9","0","0","0"],["104471","0.25404716","0","1"],["104496","1","0","1"],["104628.8","0.07421474","0","2"]],"bids":[["104448","0.25981812","0","8"],["104439.5","0.00030064","0","1"],["104439.4","0.07740896","0","2"],["104438.5","0.00478589","0","1"],["104437.6","0","0","0"],["104437.4","0.19997367","0","3"],["104436.8","0.47339439","0","3"],["104436.3","0","0","0"],["104436.2","0","0","0"],["104436","0.08843993","0","1"],["104435.4","0.0927059","0","1"],["104434.9","0","0","0"],["104434.4","0.14951861","0","2"],["104434.3","0","0","0"],["104433.9","0.14615513","0","1"],["104433.3","0.78366876","0","2"],["104432.7","0.17805538","0","2"],["104432.4","0.16591729","0","1"],["104431.3","0.00957208","0","1"],["104430.1","0.25486554","0","1"],["104429.8","0.14790974","0","1"],["104429","0","0","0"],["104428.6","0","0","0"],["104427.4","0.278344","0","2"],["104426.3","0.02871701","0","1"],["104424.4","0.26151596","0","1"],["104423.5","0.24157431","0","1"],["104423.3","0","0","0"],["104422.4","0","0","0"],["104418.2","0.13879677","0","1"],["104417.4","0.00012018","0","1"],["104343.4","0","0","0"]],"ts":"1747170443000","checksum":-700710491,"seqId":54226334458,"prevSeqId":54226334390}]}
{"arg":{"channel":"books","instId":"BTC-USDT"},"action":"update","data":[{"asks":[["104448.1","0.7395045","0","19"],["104496","0","0","0"],["104629.5","0.00010997","0","1"]],"bids":[["104448","0.25982812","0","9"],["104431.3","0","0","0"],["104430.7","0.00965162","0","2"],["104410.1","0.00056666","0","1"],["104409.6","0.54704961","0","2"],["104390.7","0.00056666","0","1"],["104390.2","0","0","0"]],"ts":"1747170443100","checksum":-1372604613,"seqId":54226334467,"prevSeqId":54226334458}]}
{"arg":{"channel":"books","instId":"BTC-USDT"},"action":"update","data":[{"asks":[["104448.1","0.73945759","0","19"],["104518","6.83863617","0","1"],["104524.8","0.052","0","2"],["104629.5","0","0","0"]],"bids":[],"ts":"1747170443200","checksum":2137410715,"seqId":54226334471,"prevSeqId":54226334467}]}
{"arg":{"channel":"books","instId":"BTC-USDT"},"action":"update","data":[{"asks":[["104448.1","0.76021671","0","18"],["104455.3","0.09336181","0","1"],["104455.8","0.12684405","0","2"],["104456.4","0","0","0"],["104456.7","0.0960618","0","1"],["104456.9","0","0","0"],["104457.4","0.09379461","0","1"],["104457.9","0.00044","0","1"],["104458.5","0","0","0"],["104460.2","0.15660916","0","1"],["104460.8","0.30273339","0","2"],["104461.4","0","0","0"],["104461.9","0.78345582","0","2"],["104463","0.40571696","0","4"],["104463.6","0.15919139","0","1"],["104464","0.23012053","0","1"],["104464.8","0","0","0"],["104465.1","0","0","0"],["104465.8","0.26444836","0","1"],["104466.3","0.23871476","0","1"],["104466.9","0","0","0"],["104467.4","0.00478697","0","1"],["104469.9","0.25548578","0","1"],["104471","0","0","0"],["104628.6","0","0","0"],["104628.8","0","0","0"]],"bids":[["104448","0.13712812","0","7"],["104439.4","0.04628199","0","1"],["104438.5","0","0","0"],["104438.1","0.00478589","0","1"],["104437.4","0.00917832","0","1"],["104436.8","0.48594801","0","3"],["104436.3","0.09057962","0","1"],["104436.2","0.0918551","0","1"],["104436","0","0","0"],["104435.4","0","0","0"],["104434.9","0.09810912","0","1"],["104434.4","0.000015","0","1"],["104434.3","0.09754882","0","1"],["104433.9","0","0","0"],["104433.3","0.93522748","0","3"],["104432.7","0.33297126","0","3"],["104432.4","0","0","0"],["104431.6","0.41805893","0","2"],["104431.3","0.14984959","0","1"],["104430.1","0","0","0"],["104429.8","0","0","0"],["104429","0.24568115","0","1"],["104428.6","0.14639582","0","1"],["104427.4","0.03","0","1"],["104426.3","0.30083187","0","2"],["104424.4","0","0","0"],["104423.5","0","0","0"],["104423.3","0.27145458","0","1"],["104422.4","0.24911109","0","1"],["104343.6","0","0","0"]],"ts":"1747170443300","checksum":745177972,"seqId":54226334534,"prevSeqId":54226334471}]}
{"arg":{"channel":"books","instId":"BTC-USDT"},"action":"update","data":[{"asks":[["104465.7","0.13879785","0","1"],["104467.9","0","0","0"],["104555.8","0","0","0"],["104607.4","0.234","0","1"],["104609.5","0.00090595","0","1"]],"bids":[["104349.6","0.00013933","0","3"],["104348.2","0.00009729","0","1"],["104343.7","0","0","0"]],"ts":"1747170443400","checksum":745177972,"seqId":54226334546,"prevSeqId":54226334534}]}
{"arg":{"channel":"books","instId":"BTC-USDT"},"action":"update","data":[{"asks":[["104448.1","0.72151716","0","18"],["104455.3","0","0","0"],["104455.8","0.0287656","0","1"],["104456.4","0.10109419","0","1"],["104456.7","0","0","0"],["104456.9","0.0895364","0","1"],["104457.4","0","0","0"],["104457.9","0.08683251","0","2"],["104458.5","0.09473617","0","1"],["104460.2","0","0","0"],["104460.8","0","0","0"],["104461.4","0.14270402","0","1"],["104461.9","1.09841868","0","4"],["104463","0.36840198","0","4"],["104463.6","0","0","0"],["104464","0","0","0"],["104464.8","0.14961496","0","1"],["104465.1","0.23447417","0","1"],["104465.7","0","0","0"],["104465.8","0","0","0"],["104466.3","0","0","0"],["104466.9","0.24666474","0","1"],["104467.4","0.26323369","0","2"],["104467.9","0.1387951","0","1"],["104469.9","0","0","0"],["104471","0.24301254","0","1"],["104494.4","0.90025625","0","2"],["104541","1.25737082","0","1"],["104557.2","0","0","0"],["104628.6","0.234","0","1"],["104628.8","0.07421474","0","2"]],"bids":[["104448","0.25982812","0","9"],["104439.4","0.10475571","0","2"],["104438.5","0.0047859","0","1"],["104438.1","0","0","0"],["104437.4","0.19007682","0","3"],["104436.8","0.47840676","0","3"],["104436.3","0","0","0"],["104436.2","0","0","0"],["104436","0.09331404","0","1"],["104435.4","0.09042236","0","1"],["104434.9","0","0","0"],["104434.4","0.15997607","0","2"],["104434.3","0","0","0"],["104433.9","0.16303129","0","1"],["104433.3","0.78366876","0","2"],["104432.7","0.17805538","0","2"],["104432.4","0.152701","0","1"],["104431.6","0.45161869","0","2"],["104431.3","0","0","0"],["104430.1","0.24847688","0","1"],["104429.8","0.16507834","0","1"],["104429","0","0","0"],["104428.6","0","0","0"],["104427.4","0.2702372","0","2"],["104426.3","0.02871701","0","1"],["104424.4","0.26860347","0","1"],["104423.7","0.36912966","0","2"],["104423.5","0.2580922","0","1"],["104423.3","0","0","0"],["104422.4","0","0","0"],["104418.2","0.1387951","0","1"],["104384.3","0.28222813","0","1"],["104383.5","0","0","0"],["104343.7","0.00004887","0","1"]],"ts":"1747170443500","checksum":-1999245422,"seqId":54226334629,"prevSeqId":54226334546}]}
{"arg":{"channel":"books","instId":"BTC-USDT"},"action":"update","data":[{"asks":[],"bids":[["104430","0.00507591","0","3"],["104429.1","0","0","0"],["104343.6","0.00001018","0","1"]],"ts":"1747170443600","checksum":-1999245422,"seqId":54226334639,"prevSeqId":54226334629}]}
{"arg":{"channel":"books","instId":"BTC-USDT"},"action":"update","data":[{"asks":[["104448.1","0.76021671","0","18"],["104455.3","0.1003146","0","1"],["104455.8","0.12422422","0","2"],["104456.4","0","0","0"],["104456.9","0","0","0"],["104457.4","0.10020477","0","1"],["104457.9","0.00044","0","1"],["104458.5","0","0","0"],["104460.8","0.3375981","0","2"],["104461.4","0","0","0"],["104461.9","0.78345582","0","2"],["104463","0.41408367","0","4"],["104464","0.24091429","0","1"],["104464.8","0","0","0"],["104465.1","0","0","0"],["104465.8","0.25523272","0","1"],["104466.3","0.24847176","0","1"],["104466.9","0","0","0"],["104467.4","0.00478697","0","1"],["104469.9","0.24464375","0","1"],["104471","0","0","0"],["104628.6","0","0","0"],["104629.5","0.00010997","0","1"],["104629.8","0.00037885","0","1"]],"bids":[["104448","0.13712812","0","7"],["104439.4","0.04628199","0","1"],["104437.4","0.00917832","0","1"],["104436.8","0.4882751","0","3"],["104436.3","0.09600227","0","1"],["104436","0","0","0"],["104435.4","0","0","0"],["104434.9","0.09347848","0","1"],["104434.4","0.000015","0","1"],["104434.3","0.09126075","0","1"],["104433.9","0","0","0"],["104433.3","0.94920399","0","3"],["104432.4","0","0","0"],["104431.6","0.42735453","0","2"],["104431.3","0.16909477","0","1"],["104430.1","0","0","0"],["104429.8","0","0","0"],["104429","0.25156113","0","1"],["104427.4","0.03","0","1"],["104426.3","0.28478682","0","2"],["104424.4","0","0","0"],["104423.5","0","0","0"],["104423.3","0.23860531","0","1"],["104422.4","0.25618749","0","1"],["104343.4","0.00030712","0","2"]],"ts":"1747170443700","checksum":-15588456,"seqId":54226334705,"prevSeqId":54226334639}]}
{"arg":{"channel":"books","instId":"BTC-USDT"},"action":"update","data":[{"asks":[["104448.1","0.78104323","0","19"],["104456.7","0.08630964","0","1"],["104458.1","0.00478585","0","1"],["104460.2","0.16167007","0","1"],["104461.8","0","0","0"],["104463.6","0.15803189","0","1"],["104464","0.37971423","0","2"],["104467.9","0","0","0"],["104475.2","0.00287139","0","1"],["104475.6","0.00287139","0","1"],["104475.7","0","0","0"],["104501","0.33","0","6"],["104502","0.16499999","0","3"],["104503","0","0","0"],["104518","0","0","0"],["104524.8","6.89063617","0","3"],["104568.1","0.04634752","0","1"],["104607.6","0","0","0"],["104628.6","0.234","0","1"],["104629.5","0","0","0"],["104629.8","0","0","0"]],"bids":[["104438.5","0","0","0"],["104437.5","0.02800082","0","3"],["104436.8","0.31997323","0","2"],["104436.2","0.09471808","0","1"],["104433.3","0.17053523","0","2"],["104432.7","0.33322601","0","3"],["104430","0.00029006","0","2"],["104428.6","0.15710832","0","1"],["104426.2","0.00480316","0","2"],["104423.6","0.17796783","0","1"],["104418.2","0","0","0"],["104416.8","0.13879994","0","1"],["104415","0.05797705","0","1"],["104414.8","0","0","0"],["104384.3","0","0","0"],["104384.2","0","0","0"],["104343.3","0.00023233","0","3"]],"ts":"1747170443800","checksum":-284155857,"seqId":54226334780,"prevSeqId":54226334705}]}
{"arg":{"channel":"books","instId":"BTC-USDT"},"action":"update","data":[{"asks":[["104456.7","0.0889913","0","1"],["104457.6","0.00478585","0","1"],["104458.1","0","0","0"],["104460.2","0.15253097","0","1"],["104463.6","0.16157956","0","1"],["104464","0.24091429","0","1"],["104464.3","0.13879962","0","1"],["104518","6.8721197","0","1"],["104524.8","0.052","0","2"],["104628.6","0","0","0"],["104628.8","0","0","0"]],"bids":[["104436.8","0.50054634","0","3"],["104436.2","0.09673508","0","1"],["104433.4","0.77866876","0","1"],["104432.7","0.33449862","0","3"],["104428.6","0.16702908","0","1"],["104426.2","0.00001731","0","1"],["104424.9","0.00479585","0","2"],["104423.7","0.44091766","0","3"],["104416.8","0.13879962","0","1"],["104415","0","0","0"]],"ts":"1747170443900","checksum":783652145,"seqId":54226334831,"prevSeqId":54226334780}]}
{"arg":{"channel":"books","instId":"BTC-USDT"},"action":"update","data":[{"asks":[["104448.1","1.02583323","0","21"]],"bids":[["104439.5","0","0","0"],["104438.5","0.00030064","0","1"]],"ts":"1747170444000","checksum":-1725433538,"seqId":54226334838,"prevSeqId":54226334831}]}
{"arg":{"channel":"books","instId":"BTC-USDT"},"action":"update","data":[{"asks":[["104455.7","0.09970261","0","1"],["104455.8","0.0287656","0","1"],["104457.1","0.00478585","0","1"],["104457.3","0.10015511","0","1"],["104457.4","0","0","0"],["104457.6","0","0","0"],["104460.7","0.16413742","0","1"],["104460.8","0.16802868","0","1"],["104463.9","0.13880055","0","1"],["104464.3","0","0","0"],["104465.7","0.2663853","0","1"],["104465.8","0","0","0"],["104469.8","0.25695413","0","1"],["104469.9","0","0","0"],["104474.9","0.099944","0","1"],["104480","0.00420843","0","5"],["104481","0.001","0","1"],["104482","0","0","0"],["104494.7","0","0","0"],["104628","0","0","0"]],"bids":[["104448","0.13485812","0","5"],["104437.5","0.02800085","0","3"],["104436.3","0","0","0"],["104436.2","0.19795035","0","2"],["104434.9","0","0","0"],["104434.8","0.08792321","0","1"],["104431.3","0","0","0"],["104431.2","0.16712205","0","1"],["104430.7","0.00007949","0","1"],["104430.1","0.00957219","0","1"],["104426.3","0.02871701","0","1"],["104426.2","0.26491902","0","2"],["104422.4","0","0","0"],["104422.3","0.26690572","0","2"],["104416.8","0","0","0"],["104413.2","0.13880111","0","1"],["104410.6","0.00056666","0","1"],["104410.1","0","0","0"],["104391.2","0.00136666","0","2"],["104390.7","0","0","0"],["104342.9","0.01064362","0","2"],["104342.8","0.00076959","0","3"]],"ts":"1747170444100","checksum":-1814457994,"seqId":54226334899,"prevSeqId":54226334838}]}
{"arg":{"channel":"books","instId":"BTC-USDT"},"action":"update","data":[{"asks":[["104450.1","0.03609157","0","1"],["104453.4","0","0","0"],["104455.1","0","0","0"],["104455.3","0.09345081","0","1"],["104455.7","0","0","0"],["104455.8","0.12050888","0","2"],["104456.7","0","0","0"],["104456.8","0.09194062","0","1"],["104457.1","0","0","0"],["104457.3","0","0","0"],["104457.4","0.09953697","0","1"],["104457.6","0.00478585","0","1"],["104457.9","0.02510616","0","2"],["104458.9","0","0","0"],["104460.2","0","0","0"],["104460.3","0.15448991","0","1"],["104460.7","0","0","0"],["104460.8","0.3238197","0","2"],["104463","0.19541916","0","3"],["104463.6","0.15513099","0","1"],["104463.9","0","0","0"],["104464","0.24233614","0","1"],["104465.7","0","0","0"],["104465.8","0.2663388","0","1"],["104466.3","0.2392928","0","1"],["104467.6","0.05272916","0","1"],["104467.9","0.13879552","0","1"],["104469.8","0","0","0"],["104469.9","0.25000791","0","1"],["104496","1","0","1"],["104518","0","0","0"],["104521.4","6.8721197","0","1"],["104628","0.01403883","0","1"],["104628.6","0.234","0","1"],["104628.8","0.07421474","0","2"]],"bids":[["104448","0.13805812","0","6"],["104438.1","0.00478593","0","1"],["104437.5","0.02321488","0","2"],["104436.8","0.22085562","0","2"],["104436.3","0.18808584","0","2"],["104436.2","0","0","0"],["104434.9","0.09645276","0","1"],["104434.8","0.04879182","0","1"],["104434.3","0.09079761","0","1"],["104433.3","0.17245242","0","2"],["104432.8","0.1621536","0","1"],["104432.7","0.17805538","0","2"],["104431.6","0.28273687","0","1"],["104431.3","0.16143391","0","1"],["104431.2","0","0","0"],["104429","0.23123854","0","1"],["104428.6","0.1456512","0","1"],["104426.2","0.00001731","0","1"],["104423.3","0.23965522","0","1"],["104422.4","0.23683086","0","1"],["104422.3","0.0000125","0","1"],["104418.2","0.13879552","0","1"],["104413.2","0","0","0"],["104343.3","0","0","0"],["104342.9","0","0","0"],["104342.8","0","0","0"]],"ts":"1747170444200","checksum":627944132,"seqId":54226335045,"prevSeqId":54226334899}]}
{"arg":{"channel":"books","instId":"BTC-USDT"},"action":"update","data":[{"asks":[["104463","0.41994311","0","4"],["104475.1","0.00287139","0","1"],["104475.2","0","0","0"],["104475.6","0","0","0"],["104629.5","0.00010997","0","1"]],"bids":[["104438.1","0.00478592","0","1"],["104436.8","0.50286281","0","3"],["104431.6","0.41554232","0","2"],["104426.3","0.30109749","0","2"],["104409.6","0.99823089","0","3"]],"ts":"1747170444300","checksum":-989287421,"seqId":54226335058,"prevSeqId":54226335045}]}
{"arg":{"channel":"books","instId":"BTC-USDT"},"action":"update","data":[{"asks":[["104496","0","0","0"],["104518","6.8721197","0","1"],["104521.4","0","0","0"],["104608.3","0.00090768","0","1"],["104609.5","0","0","0"],["104629.8","0.00037885","0","1"]],"bids":[["104348.9","0.0006798","0","6"],["104348.2","0","0","0"],["104343.3","0.00023233","0","3"]],"ts":"1747170444400","checksum":-989287421,"seqId":54226335067,"prevSeqId":54226335058}]}
{"arg":{"channel":"books","instId":"BTC-USDT"},"action":"update","data":[{"asks":[["104466.2","0.13879712","0","1"],["104467.9","0","0","0"],["104494.4","0.5382647","0","1"],["104494.5","0","0","0"],["104515.6","2.23066833","0","2"],["104525.8","0.01053134","0","1"],["104541","0","0","0"],["104554","0","0","0"],["104630","0.00028006","0","1"],["104631.4","0.00001","0","1"],["104633","1.89471219","0","1"]],"bids":[["104405.1","0.00003566","0","2"],["104404.2","0.06241696","0","2"],["104404.1","0.19248461","0","2"],["104373.2","0.22395706","0","2"],["104372.7","0.00068148","0","4"]],"ts":"1747170444500","checksum":-989287421,"seqId":54226335081,"prevSeqId":54226335067}]}
{"arg":{"channel":"books","instId":"BTC-USDT"},"action":"update","data":[{"asks":[["104457.6","0","0","0"],["104458.1","0.00478585","0","1"],["104466.2","0","0","0"],["104467.5","0.13936267","0","2"],["104493.3","1.39862722","0","2"],["104524.7","2.5487385","0","1"],["104556.1","0.00009491","0","1"],["104633","0","0","0"]],"bids":[["104448","0.13960812","0","7"],["104439.5","0.00030064","0","1"],["104438.5","0","0","0"],["104426.4","0.00478585","0","1"],["104424.9","0.00001","0","1"],["104418.2","0.13879601","0","1"],["104402.4","1.38127118","0","1"],["104373.2","0.96542298","0","3"],["104371.1","2.92967603","0","4"],["104343.4","0","0","0"],["104343.3","0","0","0"]],"ts":"1747170444600","checksum":-226672390,"seqId":54226335114,"prevSeqId":54226335081}]}
{"arg":{"channel":"books","instId":"BTC-USDT"},"action":"update","data":[{"asks":[["104453.4","0.02576277","0","1"],["104455.3","0","0","0"],["104455.8","0.0287656","0","1"],["104456.8","0","0","0"],["104457.4","0","0","0"],["104457.6","0.00478585","0","1"],["104458.1","0","0","0"],["104460.3","0","0","0"],["104460.8","0","0","0"],["104463","0.40548332","0","4"],["104463.6","0","0","0"],["104464","0","0","0"],["104465.8","0","0","0"],["104466.3","0","0","0"],["104467.6","0","0","0"],["104469.9","0","0","0"],["104633","1.89471219","0","1"],["104633.2","0.04783921","0","4"],["104633.9","0.00014488","0","1"],["104637.2","0.03","0","1"],["104637.8","0.77866876","0","1"],["104639.3","0.00010253","0","1"],["104639.7","0.00239325","0","1"],["104640","0.00220843","0","3"],["104641.3","0.03","0","1"],["104642.5","0.0003067","0","1"]],"bids":[["104448","0.13640812","0","6"],["104439.4","0.10740731","0","2"],["104436.8","0.48335268","0","3"],["104436.3","0","0","0"],["104434.9","0","0","0"],["104434.3","0","0","0"],["104433.3","0.005","0","1"],["104432.8","0","0","0"],["104431.6","0.44736861","0","2"],["104431.3","0","0","0"],["104429","0","0","0"],["104428.6","0","0","0"],["104426.4","0","0","0"],["104426.3","0.02871701","0","1"],["104424.9","0.00479585","0","2"],["104423.7","0.36912966","0","2"],["104423.3","0","0","0"],["104422.4","0","0","0"],["104377.1","0","0","0"],["104343.4","0.00030712","0","2"],["104343.3","0.00023233","0","3"],["104342.9","0.01064362","0","2"],["104342.8","0.00076959","0","3"],["104342.6","0.0000203","0","1"],["104342.4","0.0078311","0","2"],["104342.3","0.00002108","0","1"],["104342.1","0.00022221","0","1"],["104342","0.01059526","0","1"],["104341.6","0.0001427","0","2"],["104341.3","0.00001374","0","1"]],"ts":"1747170444700","checksum":597327435,"seqId":54226335222,"prevSeqId":54226335114}]}
{"arg":{"channel":"books","instId":"BTC-USDT"},"action":"update","data":[{"asks":[["104455.1","0.00935378","0","1"],["104455.3","0.10057993","0","1"],["104455.8","0.12802287","0","2"],["104456.7","0.09411295","0","1"],["104457.4","0.09196095","0","1"],["104460.2","0.14300382","0","1"],["104460.8","0.3139826","0","2"],["104463","0.41211168","0","4"],["104463.6","0.16403809","0","1"],["104464","0.2539301","0","1"],["104465.7","0.13879903","0","1"],["104465.8","0.2475462","0","1"],["104466.3","0.26420825","0","1"],["104467.5","0.00056666","0","1"],["104469.9","0.24449505","0","1"],["104474.6","0.00287139","0","1"],["104475.1","0","0","0"],["104514.7","6.86956177","0","1"],["104515.6","0.19317991","0","1"],["104518","0","0","0"],["104546.2","0.40383194","0","2"],["104630","0","0","0"],["104631.4","0","0","0"],["104633","0","0","0"],["104633.2","0","0","0"],["104633.9","0","0","0"],["104637.2","0","0","0"],["104637.8","0","0","0"],["104639.3","0","0","0"],["104639.7","0","0","0"],["104640","0","0","0"],["104641.3","0","0","0"],["104642.5","0","0","0"]],"bids":[["104439.5","0","0","0"],["104439.4","0.04628199","0","1"],["104438.5","0.00030064","0","1"],["104438.1","0","0","0"],["104437","0.00478596","0","1"],["104436.8","0.49783905","0","3"],["104436.3","0.08970728","0","1"],["104436.2","0.08898488","0","1"],["104434.9","0.09617291","0","1"],["104434.8","0.05742288","0","2"],["104434.3","0.10250865","0","1"],["104433.3","0.15620799","0","2"],["104432.7","0.33767005","0","3"],["104431.6","0.42474733","0","2"],["104431.3","0.1615407","0","1"],["104429","0.25426196","0","1"],["104428.6","0.15320435","0","1"],["104426.3","0.28471788","0","2"],["104423.7","0.44091766","0","3"],["104423.3","0.25337586","0","1"],["104422.4","0.26287993","0","1"],["104418.2","0","0","0"],["104417.4","0.13891921","0","2"],["104342.8","0","0","0"],["104342.6","0","0","0"],["104342.4","0","0","0"],["104342.3","0","0","0"],["104342.1","0","0","0"],["104342","0","0","0"],["104341.6","0","0","0"],["104341.3","0","0","0"]],"ts":"1747170444800","checksum":80362681,"seqId":54226335297,"prevSeqId":54226335222}]}
{"arg":{"channel":"books","instId":"BTC-USDT"},"action":"update","data":[{"asks":[["104458","0.03829359","0","1"],["104463.9","0.13880018","0","1"],["104464.2","0","0","0"],["104465.7","0","0","0"]],"bids":[["104417.4","0.00012018","0","1"],["104413.2","0.13880018","0","1"],["104342.9","0","0","0"]],"ts":"1747170444900","checksum":80362681,"seqId":54226335329,"prevSeqId":54226335297}]}
{"arg":{"channel":"books","instId":"BTC-USDT"},"action":"update","data":[{"asks":[["104454.4","0.0983896","0","1"],["104454.9","0.10203465","0","1"],["104455.3","0","0","0"],["104455.8","0.11595941","0","2"],["104456.5","0.09280512","0","1"],["104456.7","0","0","0"],["104457.4","0","0","0"],["104459.3","0.14445767","0","1"],["104459.9","0.31796906","0","2"],["104460.2","0","0","0"],["104460.8","0","0","0"],["104462.7","0.18401322","0","2"],["104463","0.3470603","0","4"],["104463.1","0.23037077","0","1"],["104463.6","0","0","0"],["104463.9","0","0","0"],["104464","0","0","0"],["104464.3","0.13879963","0","1"],["104464.9","0.24152456","0","2"],["104465.4","0.26022277","0","1"],["104465.8","0","0","0"],["104466.3","0","0","0"],["104469","0.23699951","0","1"],["104469.9","0","0","0"],["104630","0.00028006","0","1"],["104631.4","0.00001","0","1"]],"bids":[["104448","0.06483678","0","5"],["104439.5","0.00030064","0","1"],["104438.5","0","0","0"],["104436.8","0.50061629","0","3"],["104436.3","0","0","0"],["104436.2","0","0","0"],["104435.4","0.09191559","0","1"],["104435.3","0.09153071","0","3"],["104434.9","0","0","0"],["104434.3","0","0","0"],["104434","0.09591219","0","1"],["104433.4","0.86842939","0","2"],["104433.3","0.005","0","1"],["104432.7","0.17805538","0","2"],["104432.4","0.16574923","0","1"],["104431.8","0.15905443","0","1"],["104431.6","0.41804616","0","2"],["104431.3","0","0","0"],["104430.4","0.15464085","0","1"],["104429","0","0","0"],["104428.6","0","0","0"],["104428.1","0.26862362","0","2"],["104427.7","0.1634053","0","1"],["104426.3","0.02871701","0","1"],["104426.1","0.67573903","0","1"],["104425.4","0.26531283","0","1"],["104423.3","0","0","0"],["104422.4","0.27010894","0","1"],["104421.5","0.2442153","0","1"],["104416.8","0.13879963","0","1"],["104413.2","0","0","0"]],"ts":"1747170445000","checksum":1070975007,"seqId":54226335413,"prevSeqId":54226335329}]}
{"arg":{"channel":"books","instId":"BTC-USDT"},"action":"update","data":[{"asks":[["104464","0.13880021","0","1"],["104464.3","0","0","0"]],"bids":[["104448","0.06327556","0","4"],["104437.6","0.00478597","0","1"],["104437.4","0","0","0"],["104437","0","0","0"],["104430.1","0","0","0"],["104429.5","0.20200196","0","2"],["104416.8","0","0","0"],["104413.2","0.13880021","0","1"],["104411","0.00056666","0","1"],["104410.6","0","0","0"],["104391.6","0.00056666","0","1"],["104391.2","0.0008","0","1"],["104377.1","0.00002964","0","1"]],"ts":"1747170445100","checksum":1323770627,"seqId":54226335443,"prevSeqId":54226335413}]}
{"arg":{"channel":"books","instId":"BTC-USDT"},"action":"update","data":[{"asks":[["104448.1","1.02581807","0","21"],["104563.3","0.13052734","0","2"]],"bids":[],"ts":"1747170445200","checksum":2015435700,"seqId":54226335458,"prevSeqId":54226335443}]}
{"arg":{"channel":"books","instId":"BTC-USDT"},"action":"update","data":[{"asks":[["104455.8","0.0287656","0","1"],["104455.9","0.0969144","0","1"],["104459.3","0","0","0"],["104459.4","0.15857611","0","1"],["104577.8","0.02869446","0","1"],["104631.4","0","0","0"]],"bids":[["104448","0.06647556","0","5"],["104438","0.05305051","0","2"],["104437.6","0","0","0"],["104435.4","0.18100093","0","2"],["104435.3","0.0051","0","2"],["104431.9","0.15881466","0","1"],["104431.8","0","0","0"],["104342.9","0.01064362","0","2"]],"ts":"1747170445300","checksum":1489169015,"seqId":54226335478,"prevSeqId":54226335458}]}
{"arg":{"channel":"books","instId":"BTC-USDT"},"action":"update","data":[{"asks":[["104454.4","0","0","0"],["104454.9","0","0","0"],["104455.2","0.09518548","0","1"],["104455.7","0.09523841","0","1"],["104455.9","0","0","0"],["104456.5","0","0","0"],["104456.7","0.08650682","0","1"],["104457.3","0.09989829","0","1"],["104459.4","0","0","0"],["104459.9","0","0","0"],["104460.2","0.16209695","0","1"],["104460.7","0.32452472","0","2"],["104462.7","0.02392578","0","1"],["104463","0.34187649","0","3"],["104463.1","0","0","0"],["104463.6","0.15460216","0","1"],["104463.9","0.24513792","0","1"],["104464.9","0.002","0","1"],["104465.4","0","0","0"],["104465.7","0.26187792","0","1"],["104466.2","0.24980631","0","1"],["104469","0","0","0"],["104469.8","0.2456196","0","1"],["104475.5","0.005","0","1"],["104495","1","0","1"],["104529","0","0","0"],["104531","0.01436119","0","1"],["104538.7","0","0","0"],["104539.8","0","0","0"],["104545","0","0","0"]],"bids":[["104448","0.13757556","0","6"],["104447.8","0","0","0"],["104439.5","0","0","0"],["104438.1","0.00030064","0","1"],["104438","0.04826454","0","1"],["104437.6","0.00478594","0","1"],["104437.3","0.00923166","0","1"],["104436.8","0.49914303","0","3"],["104436.2","0.18767602","0","2"],["104435.4","0","0","0"],["104435.3","0.0001","0","1"],["104434.8","0.15710926","0","3"],["104434.2","0.09189513","0","2"],["104434","0","0","0"],["104433.4","0.77866876","0","1"],["104433.2","0.15543011","0","2"],["104432.7","0.33429467","0","3"],["104432.4","0","0","0"],["104431.9","0","0","0"],["104431.2","0.16061371","0","1"],["104430.6","0","0","0"],["104430.4","0","0","0"],["104428.9","0.23901946","0","2"],["104428.6","0.1590478","0","1"],["104428.5","0","0","0"],["104428.1","0.04","0","1"],["104427.7","0","0","0"],["104427.5","0","0","0"],["104426.2","0.25926767","0","2"],["104426.1","0.49860487","0","1"],["104425.4","0","0","0"],["104423.2","0.25919996","0","1"],["104422.4","0","0","0"],["104422.3","0.24042587","0","2"],["104422.2","0.0000125","0","1"],["104421.5","0","0","0"],["104420.1","0.0000125","0","1"],["104419.1","0.0000125","0","1"],["104342.8","0.00076959","0","3"],["104342.6","0.0000203","0","1"],["104342.4","0.0078311","0","2"],["104342.3","0.00002108","0","1"]],"ts":"1747170445400","checksum":-1904688345,"seqId":54226335612,"prevSeqId":54226335478}]}
{"arg":{"channel":"books","instId":"BTC-USDT"},"action":"update","data":[{"asks":[["104471.7","0","0","0"],["104489.4","0.69016081","0","1"],["104495","0","0","0"],["104520.2","1.41881274","0","2"],["104528.9","0.01914826","0","1"],["104532.1","0.00957413","0","1"],["104537.3","0.00957413","0","1"],["104630","0","0","0"]],"bids":[["104404.2","0.46900689","0","3"]],"ts":"1747170445500","checksum":-1904688345,"seqId":54226335630,"prevSeqId":54226335612}]}
{"arg":{"channel":"books","instId":"BTC-USDT"},"action":"update","data":[{"asks":[["104455.2","0","0","0"],["104455.3","0.09293437","0","1"],["104460.7","0.15462814","0","1"],["104460.8","0.15436163","0","1"],["104463.9","0","0","0"],["104464","0.3804733","0","2"],["104466.2","0","0","0"],["104466.3","0.24158159","0","1"],["104471.7","0.0001303","0","1"],["104528.9","0","0","0"],["104531","0","0","0"],["104532.1","0","0","0"],["104537.3","0","0","0"],["104630","0.00028006","0","1"],["104631.4","0.00001","0","1"],["104633","1.89471219","0","1"]],"bids":[["104448","0.0646887","0","5"],["104434.5","0","0","0"],["104434.3","0.09731095","0","1"],["104434.2","0.000015","0","1"],["104433.4","0","0","0"],["104433.3","0.17298084","0","2"],["104433.2","0.002","0","1"],["104429.5","0.00957224","0","1"],["104429","0.24374026","0","1"],["104428.9","0.00001","0","1"],["104423.7","0.07183588","0","2"],["104423.3","0.26038373","0","1"],["104423.2","0","0","0"],["104409.6","0.62914911","0","2"],["104402.5","0.36908178","0","1"],["104359.8","0.39780744","0","2"],["104342.3","0","0","0"]],"ts":"1747170445600","checksum":1996014729,"seqId":54226335671,"prevSeqId":54226335630}]}
{"arg":{"channel":"books","instId":"BTC-USDT"},"action":"update","data":[{"asks":[["104445.9","1.46631441","0","19"],["104446","0.52110366","0","1"],["104446.1","0.23401505","0","2"],["104447.7","0.36917178","0","2"],["104448","0.27466849","0","3"],["104448.1","0.32550635","0","7"],["104450","0.00002","0","1"],["104452.2","0","0","0"],["104452.6","0.00001","0","1"],["104453.4","0","0","0"],["104453.7","0.00044","0","1"],["104453.9","0.09128397","0","1"],["104454.4","0.1010497","0","1"],["104455.2","0.00478604","0","1"],["104455.3","0.0892673","0","1"],["104455.7","0","0","0"],["104455.8","0","0","0"],["104456","0.09000238","0","1"],["104456.2","0.04","0","1"],["104456.7","0","0","0"],["104457.3","0","0","0"],["104457.6","0","0","0"],["104457.9","0","0","0"],["104458.1","0.0401287","0","1"],["104458.5","0.13880734","0","1"],["104458.8","0.19310194","0","2"],["104459","0.00093","0","1"],["104459.4","0.31151915","0","2"],["104459.5","0.17796783","0","1"],["104459.6","0","0","0"],["104460.2","0","0","0"],["104460.7","0","0","0"],["104460.8","0","0","0"],["104462.2","0.15289785","0","1"],["104462.4","0.0527318","0","1"],["104462.6","0.23488066","0","1"],["104463","0.23503752","0","3"],["104463.2","0","0","0"],["104463.6","0","0","0"],["104464","0","0","0"],["104464.2","0.00093","0","1"],["104464.3","0.03588936","0","1"],["104464.4","0.25942388","0","1"],["104464.9","0.25040966","0","2"],["104465.7","0","0","0"],["104466.3","0","0","0"],["104468.3","0.10632","0","1"],["104468.4","0","0","0"],["104468.5","0.2652253","0","2"],["104469.3","0","0","0"],["104469.4","0.00191","0","1"],["104469.8","0","0","0"],["104471.7","0","0","0"],["104472.1","0.05271388","0","1"],["104473.6","0","0","0"],["104473.8","0.00287142","0","1"],["104474.6","0.00191","0","1"],["104476","0","0","0"],["104477","0.002","0","2"],["104478","0.001","0","1"],["104478.8","0","0","0"],["104479.8","0","0","0"],["104480","0.00220843","0","3"],["104480.7","0","0","0"],["104481","0","0","0"],["104498","0.17","0","4"],["104499","0.085","0","2"],["104501","0","0","0"],["104502","0.16","0","2"],["104502.3","0","0","0"],["104502.8","0","0","0"],["104503","0.07999999","0","1"],["104514.7","0","0","0"],["104520.5","0.00658495","0","1"],["104525.9","0.016","0","1"],["104528.9","0.00658495","0","1"],["104547.7","0.234","0","1"],["104570.9","0","0","0"],["104631.4","0","0","0"],["104633","0","0","0"]],"bids":[["104448","0","0","0"],["104447.6","0","0","0"],["104446.8","0","0","0"],["104446","0","0","0"],["104445.8","0.1988","0","4"],["104445.1","0","0","0"],["104444","0.08164787","0","2"],["104443.4","0","0","0"],["104442.2","0","0","0"],["104442","0.0816","0","1"],["104439.9","0.03241868","0","1"],["104439.4","0","0","0"],["104438.1","0","0","0"],["104438","0.0005","0","1"],["104437.6","0","0","0"],["104437.3","0","0","0"],["104436.9","0","0","0"],["104436.8","0.00001","0","1"],["104436.2","0","0","0"],["104435","0.00508661","0","2"],["104434.9","0.10213815","0","1"],["104434.8","0.09062224","0","1"],["104434.4","0","0","0"],["104434.3","0","0","0"],["104434.2","0","0","0"],["104433.5","0.08986984","0","2"],["104433.3","0.005","0","1"],["104432.9","0.10018052","0","1"],["104432.7","0.00106755","0","2"],["104431.9","0.16227957","0","1"],["104431.7","0","0","0"],["104431.6","0","0","0"],["104431.3","0.16155621","0","1"],["104431.2","0","0","0"],["104429.9","0.18485925","0","2"],["104429.5","0","0","0"],["104429","0","0","0"],["104428.9","0.04880457","0","2"],["104428.6","0","0","0"],["104428.1","0","0","0"],["104427.6","0.25315423","0","1"],["104427.5","0.00098","0","1"],["104427.2","0.16133752","0","1"],["104426.5","0","0","0"],["104426.4","0.19841382","0","1"],["104426.2","0.04001731","0","2"],["104426.1","0","0","0"],["104424.9","0.27013658","0","2"],["104423.7","0.00483392","0","2"],["104423.3","0","0","0"],["104422.8","0.00094847","0","1"],["104422.3","0.0019225","0","2"],["104422","0","0","0"],["104421.9","0.24120467","0","1"],["104421.6","0","0","0"],["104421.3","0","0","0"],["104421","0.24764562","0","3"],["104418.5","0.17796783","0","1"],["104417.7","0","0","0"],["104417.1","0.00196919","0","2"],["104414.8","0.03056986","0","2"],["104414.7","0.20195484","0","2"],["104413.2","0","0","0"],["104410.9","0.06022355","0","1"],["104410.2","0","0","0"],["104409.8","0.13880734","0","1"],["104409.7","0.18844375","0","1"],["104409.6","0.17796783","0","1"],["104409.4","0","0","0"],["104404.2","0.06241696","0","2"],["104402.5","0","0","0"],["104402.4","0","0","0"],["104395.6","0","0","0"],["104392.6","0","0","0"],["104381.8","0.0022","0","1"],["104380.7","0.45257682","0","2"],["104378.2","0.19249442","0","2"],["104377.7","0.04413062","0","3"],["104373.2","0.22395706","0","2"],["104371.1","0.36919508","0","3"],["104348.8","0","0","0"],["104346.7","0.0022","0","1"],["104342.3","0.00002108","0","1"],["104342.1","0.00022221","0","1"],["104342","0.01059526","0","1"],["104341.6","0.0001427","0","2"],["104341.3","0.00001374","0","1"],["104341.2","0.00003833","0","1"],["104340.9","0.01173863","0","2"],["104340.8","0.000015","0","1"],["104340.4","1.55245","0","1"],["104340","0.0382158","0","10"],["104339.9","0.00053439","0","2"],["104339.6","0.00011038","0","2"],["104339.5","0.00009595","0","2"],["104339","0.00004182","0","2"],["104338.9","0.00003005","0","1"],["104338.7","0.00227746","0","14"],["104338.2","0.00027662","0","1"],["104338.1","0.00054717","0","1"],["104337.8","0.00005635","0","2"],["104337.7","0.00001","0","1"]],"ts":"1747170445700","checksum":795454806,"seqId":54226336343,"prevSeqId":54226335671}]}
{"arg":{"channel":"books","instId":"BTC-USDT"},"action":"update","data":[{"asks":[["104441","0.90448779","0","15"],["104441.1","0.01711203","0","2"],["104441.2","1.75124959","0","16"],["104442.1","0.05209157","0","2"],["104442.2","0.29193486","0","1"],["104443.4","0.01149","0","1"],["104444","0.25","0","2"],["104444.1","0.29209157","0","3"],["104445.8","0.24","0","1"],["104445.9","0.07420838","0","4"],["104446","0","0","0"],["104446.1","0.234","0","1"],["104447.6","0.38918411","0","1"],["104448","0.25","0","2"],["104448.1","0.29265823","0","4"],["104448.7","0.0955212","0","1"],["104449.2","0.1042683","0","2"],["104449.5","0.03662634","0","1"],["104449.6","0.02576372","0","1"],["104450.1","0.12355611","0","2"],["104450.7","0.09731911","0","1"],["104451.5","0.06075924","0","2"],["104452.6","0.04001","0","2"],["104452.7","0","0","0"],["104452.8","0.21719773","0","1"],["104452.9","0.19242972","0","1"],["104453.4","0.00478611","0","1"],["104453.5","0","0","0"],["104453.6","0.14536448","0","1"],["104453.9","0","0","0"],["104454.2","0.30475727","0","2"],["104454.4","0","0","0"],["104455.2","0","0","0"],["104455.3","0","0","0"],["104455.4","0","0","0"],["104455.5","0.000015","0","1"],["104456","0","0","0"],["104456.2","0","0","0"],["104457","0.16033202","0","1"],["104457.1","0.13880977","0","1"],["104457.4","0.24906878","0","1"],["104457.7","0","0","0"],["104458.5","0","0","0"],["104458.8","0.04","0","1"],["104459.2","0.25139183","0","1"],["104459.4","0","0","0"],["104459.7","0.26485594","0","1"],["104460.1","0.1048245","0","3"],["104462.2","0","0","0"],["104462.4","0","0","0"],["104462.6","0","0","0"],["104462.7","0","0","0"],["104463","0.09824551","0","2"],["104463.2","0.23485275","0","1"],["104464.4","0","0","0"],["104464.9","0.002","0","1"],["104466.9","0.02120238","0","1"],["104468.5","0.02231591","0","2"],["104471.5","0.0028715","0","1"],["104471.7","0.0001303","0","1"],["104471.8","0","0","0"],["104471.9","0.05496307","0","3"],["104472.1","0.05558535","0","2"],["104472.5","0.00001","0","1"],["104473.8","0","0","0"],["104477","0","0","0"],["104478","0.002","0","2"],["104479","0.001","0","1"],["104493.2","0","0","0"],["104498","0","0","0"],["104498.1","0.00047871","0","1"],["104499","0.32999999","0","6"],["104499.2","0.32805769","0","2"],["104500","0.1672486","0","7"],["104500.6","0.1","0","1"],["104501.1","0","0","0"],["104502","0","0","0"],["104503","0","0","0"],["104516.3","0","0","0"],["104520.3","0.25","0","2"],["104524.8","0.016","0","1"],["104545.5","0","0","0"],["104546.2","0.26837252","0","1"],["104547.2","0.03829735","0","1"],["104549.9","0","0","0"],["104567.8","0","0","0"],["104603.1","0.00001531","0","1"],["104604.4","2.51209","0","1"],["104629.5","0","0","0"],["104629.8","0","0","0"],["104630","0","0","0"]],"bids":[["104445.8","0","0","0"],["104445.7","0","0","0"],["104444.4","0","0","0"],["104444","0","0","0"],["104443.7","0","0","0"],["104443.3","0","0","0"],["104442","0","0","0"],["104441.1","0","0","0"],["104440.9","0.07309377","0","6"],["104440","0.08855171","0","8"],["104439.6","0.03110136","0","1"],["104438","0.0816","0","1"],["104436","0.03110243","0","1"],["104435","0","0","0"],["104434.9","0","0","0"],["104434.8","0","0","0"],["104434.1","0","0","0"],["104433.5","0.00001","0","1"],["104432.9","0","0","0"],["104432.8","0.00030064","0","1"],["104432.7","0.00008755","0","1"],["104431.9","0","0","0"],["104431.6","0.00478623","0","1"],["104431.5","0.06","0","2"],["104431.3","0","0","0"],["104430","0.28954945","0","4"],["104429.9","0","0","0"],["104429.7","0.18977586","0","2"],["104429.6","0.09105658","0","5"],["104429.5","0.00957224","0","1"],["104428.2","0.08898592","0","1"],["104427.7","0.10180043","0","1"],["104427.6","0","0","0"],["104427.5","0","0","0"],["104427.2","0","0","0"],["104427","0.19242972","0","1"],["104426.9","0","0","0"],["104426.7","0.15260756","0","1"],["104426.4","0.13216919","0","1"],["104426.3","0","0","0"],["104426.1","0.14368229","0","1"],["104424.9","0.00001","0","1"],["104424.7","0.1543889","0","2"],["104424.5","0.02508872","0","1"],["104424.4","0.01093967","0","1"],["104423.7","0.00004788","0","1"],["104422.4","0.246588","0","1"],["104422.3","0.0000125","0","1"],["104422.2","0.02930159","0","2"],["104422","0.15680757","0","1"],["104421.9","0","0","0"],["104421.1","0.77866876","0","1"],["104421","0.23577284","0","3"],["104420.9","0.00478611","0","1"],["104420.7","0","0","0"],["104417.1","0.00005919","0","1"],["104416.7","0.42291896","0","2"],["104416.4","0","0","0"],["104415.4","0.071788","0","1"],["104414.8","0.08626366","0","1"],["104414.2","0.02872301","0","1"],["104410","0.36937476","0","3"],["104409.9","0.46582092","0","1"],["104409.8","0.77866876","0","1"],["104409.7","0","0","0"],["104409.6","0","0","0"],["104409.4","0.00711203","0","1"],["104407.3","0.13880977","0","1"],["104399.4","0.36950036","0","2"],["104399.2","0","0","0"],["104396","0","0","0"],["104392","0.48324487","0","1"],["104382.2","0.24455406","0","2"],["104377.1","0","0","0"],["104365.9","0.28514733","0","2"],["104349.5","0","0","0"],["104349","0","0","0"],["104345","0.47439916","0","1"],["104337.6","0.00003583","0","1"],["104337.5","0.00001007","0","1"],["104337.4","0.00001106","0","1"],["104337.3","0.00001041","0","1"],["104336.8","0.02119142","0","2"],["104336.7","0.00003678","0","1"],["104336.5","0.01090084","0","3"],["104336.4","0.09801498","0","1"]],"ts":"1747170445800","checksum":-1008375627,"seqId":54226337099,"prevSeqId":54226336343}]}
{"arg":{"channel":"books","instId":"BTC-USDT"},"action":"update","data":[{"asks":[["104439.4","0.88769429","0","20"],["104439.6","0.08956","0","1"],["104439.9","0.56500209","0","1"],["104440","0.01235178","0","3"],["104440.1","0.05218157","0","3"],["104440.9","0.00152861","0","1"],["104441","0.19242972","0","1"],["104441.1","0","0","0"],["104441.2","0.07718029","0","3"],["104441.5","0.0257657","0","1"],["104444","0.24","0","1"],["104445","0.02999322","0","1"],["104445.9","0.05688157","0","3"],["104446.7","0.09661725","0","1"],["104447.2","0.10185401","0","2"],["104447.4","0.82242435","0","1"],["104447.5","0.77866876","0","1"],["104447.6","0","0","0"],["104447.7","0.36908178","0","1"],["104448.1","0.38920498","0","5"],["104448.7","0","0","0"],["104448.8","0.08782602","0","1"],["104449.2","0","0","0"],["104449.6","0","0","0"],["104450","0.00030006","0","2"],["104450.1","0.03609157","0","1"],["104450.7","0.03829614","0","1"],["104450.9","0.04013149","0","1"],["104451.3","0.00478618","0","1"],["104451.4","0","0","0"],["104451.5","0.03609157","0","1"],["104451.6","0.14552189","0","1"],["104452.2","0.32341488","0","2"],["104452.5","0.39295907","0","3"],["104452.8","0","0","0"],["104453.4","0","0","0"],["104453.6","0","0","0"],["104453.7","0","0","0"],["104454.2","0","0","0"],["104455","0.15925308","0","1"],["104455.4","0.24876053","0","1"],["104457","0","0","0"],["104457.1","0.19863097","0","2"],["104457.2","0.5491181","0","4"],["104457.4","0","0","0"],["104457.7","0.26749832","0","2"],["104458","0","0","0"],["104458.1","0","0","0"],["104458.6","0.76117756","0","1"],["104459","0","0","0"],["104459.2","0","0","0"],["104459.6","0.17796783","0","1"],["104459.7","0","0","0"],["104460","0.00220843","0","3"],["104460.1","0.05209157","0","2"],["104460.3","0.17796783","0","1"],["104461.3","0.24382687","0","1"],["104462.8","0.56595","0","1"],["104463","0.14816518","0","4"],["104463.2","0","0","0"],["104463.4","0.29874972","0","2"],["104464.2","0","0","0"],["104466.2","0.075","0","2"],["104468.3","0","0","0"],["104468.5","0.02518751","0","3"],["104469","0.0028716","0","1"],["104469.1","0.0001303","0","1"],["104469.4","0.00478","0","2"],["104470.2","0.06","0","2"],["104470.3","0.033","0","1"],["104470.4","0.036","0","1"],["104471.5","0","0","0"],["104471.7","0","0","0"],["104471.9","0.05209157","0","2"],["104472.1","0.05271388","0","1"],["104473.2","0.29239829","0","2"],["104475","0.002","0","2"],["104475.5","0.01","0","2"],["104476","0.001","0","1"],["104477.4","0.101","0","4"],["104478","0","0","0"],["104478.7","0.13328051","0","1"],["104479","0","0","0"],["104480.2","0","0","0"],["104481.8","0","0","0"],["104485.2","0","0","0"],["104485.8","0.04629474","0","1"],["104487.7","0","0","0"],["104489.1","0.554699","0","1"],["104493","0.16","0","2"],["104493.6","0","0","0"],["104494","0.24999999","0","5"],["104495","0.085","0","2"],["104498.1","0","0","0"],["104498.8","0.12872184","0","2"],["104499","0","0","0"],["104499.2","0.15622088","0","1"],["104499.3","0.47004433","0","1"],["104500","0.00224861","0","4"],["104500.6","0","0","0"],["104503.9","0","0","0"],["104509.6","2.43686381","0","2"],["104509.7","0","0","0"],["104510.1","0","0","0"],["104511.3","6.83745018","0","1"],["104513.4","0","0","0"],["104520.2","0","0","0"],["104528","0.12043682","0","2"],["104541.1","0.831635","0","1"],["104545.5","0.02876116","0","1"],["104546.2","0","0","0"],["104554.9","0.0000949","0","1"],["104556.1","0","0","0"],["104568.6","0","0","0"],["104605.7","0.01149982","0","2"],["104608.3","0","0","0"],["104628.6","0","0","0"],["104629.5","0.00010997","0","1"]],"bids":[["104440.9","0","0","0"],["104440","0","0","0"],["104439.9","0","0","0"],["104439.6","0","0","0"],["104439.3","0.09429397","0","2"],["104437.1","0.005","0","1"],["104436.7","0","0","0"],["104436","0.0816","0","1"],["104433.4","0.03110321","0","1"],["104432.8","0","0","0"],["104431.6","0","0","0"],["104431.5","0.0005","0","1"],["104430.1","0.00030064","0","1"],["104430","0.16002712","0","4"],["104429.7","0.100141","0","1"],["104429.6","0.00122607","0","4"],["104429.5","0","0","0"],["104429","0.00478659","0","1"],["104428.9","0.05837687","0","3"],["104428.8","0","0","0"],["104428.6","0.00262957","0","1"],["104428.2","0","0","0"],["104427.9","0","0","0"],["104427.7","0.09837733","0","1"],["104427.6","0.08890512","0","1"],["104427.4","0","0","0"],["104427.3","0","0","0"],["104427.1","0.0095738","0","1"],["104427","0","0","0"],["104426.7","0","0","0"],["104426.5","0.19242972","0","1"],["104426.4","0.22870485","0","2"],["104426.3","0.09355544","0","1"],["104426.2","0.00099731","0","2"],["104426.1","0","0","0"],["104425.7","0.09612581","0","1"],["104424.8","0","0","0"],["104424.7","0.16544432","0","2"],["104424.6","0.005","0","1"],["104424.5","0","0","0"],["104424.4","0","0","0"],["104424.1","0.15179524","0","1"],["104423.6","0","0","0"],["104423.4","0.00005","0","1"],["104422.7","0.19094632","0","2"],["104422.4","0","0","0"],["104422","0","0","0"],["104421.4","0.02508872","0","1"],["104421.2","0.32734614","0","2"],["104421.1","0.03769997","0","1"],["104421","0.0010009","0","3"],["104420.9","0","0","0"],["104420.4","0.23177129","0","1"],["104420","0.16143544","0","5"],["104419.7","0.04","0","1"],["104418.6","0.00478618","0","1"],["104418.5","0.20796783","0","2"],["104417.7","0.24452382","0","1"],["104417.3","0","0","0"],["104416.7","0.17796783","0","1"],["104416.5","0.01093967","0","1"],["104415.4","0","0","0"],["104414.9","0.3806481","0","3"],["104414.8","0","0","0"],["104414.7","0.47069973","0","3"],["104414.2","0","0","0"],["104414.1","0.04016601","0","1"],["104414","0.17796783","0","1"],["104413.8","0.23551921","0","2"],["104413.1","0","0","0"],["104412.7","0.17796783","0","1"],["104412.2","0.17804162","0","2"],["104410.1","0.17796783","0","1"],["104410","0.00030298","0","3"],["104407.3","0.13880985","0","1"],["104404.2","0.46475754","0","3"],["104403.4","0.02204107","0","2"],["104402","1.36710667","0","1"],["104401","0.02895665","0","2"],["104397.7","0","0","0"],["104397.4","0","0","0"],["104395.9","0.07344","0","1"],["104390.8","0","0","0"],["104388.6","0.00047873","0","1"],["104388.3","0.95663659","0","2"],["104388.2","0","0","0"],["104387","0.00030165","0","1"],["104378.1","0","0","0"],["104378","0","0","0"],["104377.8","0.31395271","0","1"],["104377.6","0.00123","0","1"],["104374.9","0.04927705","0","5"],["104373.2","0.85960997","0","3"],["104373.1","0","0","0"],["104370.7","2.39924339","0","3"],["104369.1","0.03","0","1"],["104368.4","0.04078235","0","3"],["104367.8","0.50784628","0","3"],["104367.7","0.55548002","0","2"],["104365.9","0.01053013","0","1"],["104360.6","0","0","0"],["104359.8","1.31770815","0","3"],["104348.9","0.0005829","0","5"],["104346.7","0.0023002","0","2"],["104336.3","0.00009584","0","1"],["104336.2","0.833267","0","1"],["104335.8","0.00001618","0","1"],["104335.4","0.00001","0","1"],["104335.2","0.00002014","0","2"],["104335","0.00010095","0","1"]],"ts":"1747170445900","checksum":11707272,"seqId":54226337890,"prevSeqId":54226337099}]}
{"arg":{"channel":"books","instId":"BTC-USDT"},"action":"update","data":[{"asks":[["104439.4","0.89918529","0","21"],["104439.9","0.21092027","0","1"],["104440.9","0","0","0"],["104441","0","0","0"],["104441.5","0","0","0"],["104442.9","0.02576535","0","1"],["104443.4","0","0","0"],["104444","0","0","0"],["104444.1","0.05209157","0","2"],["104445.8","0.00152861","0","1"],["104445.9","0.05209157","0","2"],["104446.7","0","0","0"],["104446.9","0.09129697","0","1"],["104447.2","0.00044","0","1"],["104447.4","0.5371262","0","3"],["104447.5","0","0","0"],["104448","0.01","0","1"],["104448.1","0.05265823","0","3"],["104448.3","0.09641629","0","1"],["104448.8","0","0","0"],["104449","0.09458728","0","1"],["104450.9","0","0","0"],["104451.6","0","0","0"],["104451.8","0.15030569","0","1"],["104452.2","0","0","0"],["104452.4","0.31235096","0","2"],["104452.5","0.40220137","0","3"],["104455","0","0","0"],["104455.2","0.14956207","0","1"],["104455.4","0","0","0"],["104455.6","0.25447686","0","1"],["104456.4","0.05273481","0","1"],["104457.2","0.28609157","0","3"],["104457.4","0.24507409","0","1"],["104457.7","0.00093","0","1"],["104457.9","0.26643133","0","1"],["104461.3","0","0","0"],["104461.5","0.25350307","0","1"],["104467.5","0.00343829","0","2"],["104468.3","0.00287163","0","1"],["104468.5","0.02231591","0","2"],["104469","0","0","0"],["104474","0.002","0","2"],["104475","0.001","0","1"],["104476","0","0","0"],["104477.4","0.038","0","2"],["104490.4","0","0","0"],["104493","0","0","0"],["104494","0","0","0"],["104494.1","0.1","0","1"],["104495","0.33","0","6"],["104496","0.16499999","0","3"],["104496.5","0.0008017","0","1"],["104498.8","0.02872184","0","1"],["104501.9","0.06703946","0","2"],["104508.3","0.05049657","0","3"],["104522.6","0.01436239","0","1"],["104523.7","0.00957493","0","1"],["104524.3","0.51565629","0","3"],["104551.7","0.0000921","0","1"],["104554.2","0","0","0"],["104554.9","0","0","0"],["104602.4","0.00090762","0","1"],["104605.7","0.01059638","0","1"],["104628.6","0.234","0","1"],["104629.5","0","0","0"]],"bids":[["104439.3","0.09109397","0","1"],["104435.3","0.03252009","0","2"],["104430","0.1851975","0","4"],["104427.9","0.10116846","0","1"],["104427.8","0.09145104","0","1"],["104427.7","0","0","0"],["104427.6","0","0","0"],["104426.5","0.28997677","0","2"],["104426.4","0.19873975","0","1"],["104426.3","0","0","0"],["104425.9","0.08951497","0","2"],["104425.7","0","0","0"],["104424.9","0.16168833","0","2"],["104424.7","0.00001169","0","1"],["104424.3","0.15417774","0","2"],["104424.1","0","0","0"],["104422.9","0.16529203","0","1"],["104422.7","0.03","0","1"],["104421.4","0.80375748","0","2"],["104421.2","0.34434882","0","2"],["104420.6","0.25564102","0","1"],["104420.4","0","0","0"],["104420.2","0.16022693","0","1"],["104420","0.00277552","0","4"],["104417.9","0.24763466","0","1"],["104417.7","0","0","0"],["104415.7","0.071788","0","1"],["104414.9","0.52080002","0","3"],["104414.7","0.20195484","0","2"],["104414","0.42776487","0","2"],["104413.8","0.00001","0","1"],["104409.9","0.8349027","0","2"],["104374.9","0.04924741","0","4"],["104346.7","0.0022","0","1"]],"ts":"1747170446000","checksum":-957142709,"seqId":54226338162,"prevSeqId":54226337890}]}
{"arg":{"channel":"books","instId":"BTC-USDT"},"action":"update","data":[{"asks":[["104439.4","0.902498","0","24"],["104440.1","0.05209157","0","2"],["104442.9","0","0","0"],["104445","0.05575806","0","2"],["104448.1","0.05209157","0","2"],["104448.3","0","0","0"],["104448.4","0.08732137","0","1"],["104450.4","0.04528384","0","1"],["104451.3","0","0","0"],["104451.4","0.00478624","0","1"],["104451.8","0","0","0"],["104451.9","0.15849003","0","1"],["104456.3","0.1388108","0","1"],["104457.1","0.05982112","0","1"],["104462.4","0.00056666","0","1"],["104462.9","0.0001303","0","1"],["104467.5","0.00287163","0","1"],["104469.1","0","0","0"],["104472","0.002","0","2"],["104473","0.001","0","1"],["104473.2","0.25339829","0","1"],["104474","0","0","0"],["104475","0","0","0"],["104477.4","0.002","0","1"],["104478.6","0.00014006","0","1"],["104487.2","0","0","0"],["104509.6","0.91574266","0","1"],["104511.3","0","0","0"],["104524.3","1.17228629","0","4"],["104534.2","0.02967193","0","1"],["104535.7","0.40937698","0","1"],["104539.9","0.05836134","0","2"],["104543.8","0.07174","0","1"],["104547.3","0.00009145","0","1"],["104551.7","0","0","0"],["104627.2","0","0","0"],["104628","0","0","0"],["104628.6","0","0","0"],["104628.8","0","0","0"]],"bids":[["104439.3","0.09461397","0","4"],["104430.1","0.0050871","0","2"],["104429","0","0","0"],["104428.9","0.04880457","0","2"],["104428.5","0.00957233","0","1"],["104427.9","0.19379574","0","2"],["104427.8","0","0","0"],["104426.4","0.40749791","0","2"],["104424.4","0.14282141","0","1"],["104424.3","0.02665541","0","2"],["104422.2","0.05930159","0","3"],["104421.4","0.77866876","0","1"],["104418.1","0.08157722","0","4"],["104418","0.063","0","2"],["104411","0","0","0"],["104396.2","0.00056666","0","1"],["104391.6","0","0","0"],["104383.6","0","0","0"],["104373.3","0.00056666","0","1"],["104372","0.030015","0","2"],["104368.7","0.00002964","0","1"],["104335","0","0","0"]],"ts":"1747170446100","checksum":-2113064008,"seqId":54226338313,"prevSeqId":54226338162}]}
{"arg":{"channel":"books","instId":"BTC-USDT"},"action":"update","data":[{"asks":[["104456.3","0","0","0"],["104457","0.13881012","0","1"],["104462.9","0.0020403","0","2"],["104468.1","0.28800157","0","4"],["104469.4","0.00287","0","1"],["104472","0","0","0"],["104473","0","0","0"],["104474","0.002","0","2"],["104474.6","0","0","0"],["104475","0.001","0","1"],["104505","2.58134573","0","3"],["104507.9","6.83745018","0","1"],["104524.3","0.02106268","0","2"],["104535.7","0","0","0"],["104547.3","0","0","0"],["104598.8","0.00090315","0","1"],["104602.4","0","0","0"],["104627.2","0.77866876","0","1"],["104628","0.01403883","0","1"]],"bids":[["104418.6","0.00478624","0","1"],["104415.8","0.00191","0","1"],["104410.6","0.00191","0","1"],["104381.7","0","0","0"],["104355.6","0.01055076","0","2"],["104354.3","0.01061602","0","2"],["104352.4","0.0105935","0","3"],["104335.2","0","0","0"]],"ts":"1747170446200","checksum":-2113064008,"seqId":54226338387,"prevSeqId":54226338313}]}
{"arg":{"channel":"books","instId":"BTC-USDT"},"action":"update","data":[{"asks":[["104439.4","0.9054674","0","25"],["104446.5","0.01944732","0","1"],["104484.1","0.09575","0","1"],["104491.6","0.00047874","0","1"],["104626.4","0","0","0"],["104627.2","0","0","0"],["104628","0","0","0"]],"bids":[["104415","0.40859235","0","1"],["104414.9","0.2671097","0","2"],["104372","0.060015","0","3"],["104340.9","0.01183436","0","3"],["104335.4","0","0","0"]],"ts":"1747170446300","checksum":-266912496,"seqId":54226338397,"prevSeqId":54226338387}]}
{"arg":{"channel":"books","instId":"BTC-USDT"},"action":"update","data":[{"asks":[["104456.3","0.13881112","0","1"],["104457","0","0","0"],["104457.5","0.00478746","0","1"],["104467.4","0","0","0"],["104474","0","0","0"],["104475","0.002","0","2"],["104476","0.001","0","1"],["104495","0","0","0"],["104496","0.32999999","0","6"],["104497","0.16499999","0","3"],["104501.3","0","0","0"],["104626.4","0.01908652","0","2"]],"bids":[["104390.5","0.23811671","0","2"],["104351.4","0","0","0"],["104340.9","0.0003336","0","2"],["104335.4","0.00001","0","1"]],"ts":"1747170446400","checksum":-266912496,"seqId":54226338427,"prevSeqId":54226338397}]}
{"arg":{"channel":"books","instId":"BTC-USDT"},"action":"update","data":[{"asks":[["104439.4","0.9950274","0","26"],["104439.5","0.19242972","0","1"],["104439.6","0","0","0"],["104439.9","0.51622045","0","1"],["104445.5","0.00152861","0","1"],["104445.6","0.77866876","0","1"],["104445.7","0.071788","0","1"],["104445.8","0","0","0"],["104447.9","0.00478624","0","1"],["104448.3","0.09489769","0","1"],["104448.4","0","0","0"],["104451.4","0","0","0"],["104451.8","0.15479261","0","1"],["104451.9","0","0","0"],["104452.8","0.13881479","0","1"],["104456.3","0","0","0"],["104458.6","0.80117756","0","2"],["104459.8","0","0","0"],["104466","0.00001501","0","1"],["104467","0.00287163","0","1"],["104467.5","0","0","0"],["104468.2","0","0","0"],["104468.3","0","0","0"],["104474","0.002","0","2"],["104475","0.001","0","1"],["104476","0","0","0"],["104493","1","0","1"],["104495","0.33","0","6"],["104496","0.16499999","0","3"],["104497","0","0","0"],["104504.9","0.02179079","0","2"],["104515.6","0","0","0"],["104540","0.00221843","0","4"],["104545.4","0.0686405","0","3"],["104585.3","0","0","0"],["104611.8","0","0","0"],["104619.4","0","0","0"],["104627.2","0.77866876","0","1"],["104628","0.01403883","0","1"],["104628.6","0.234","0","1"],["104628.8","0.07421474","0","2"]],"bids":[["104439.3","0.09141397","0","3"],["104430.1","0.00030064","0","1"],["104428.8","0.00930158","0","1"],["104427.9","0.10116846","0","1"],["104427.8","0.09050953","0","1"],["104427.2","0.00478644","0","1"],["104426.5","0.09754705","0","1"],["104424.4","0","0","0"],["104424.3","0.1511516","0","2"],["104418.6","0","0","0"],["104418.1","0.07205376","0","3"],["104415.9","0.00478624","0","1"],["104414.9","0.25971686","0","1"],["104414.7","0.19242972","0","1"],["104414.4","0","0","0"],["104412.2","0.17796783","0","1"],["104409.4","0","0","0"],["104407.3","0","0","0"],["104405.8","0.00001051","0","1"],["104404.3","0.13881473","0","1"],["104400","0.11745846","0","50"],["104383.8","0.00016733","0","2"],["104380.1","0","0","0"],["104377","0.00006722","0","3"],["104376.6","0","0","0"],["104375.1","0.00008792","0","4"],["104374","0","0","0"],["104369.5","0.01091484","0","2"],["104369.2","0","0","0"],["104368.1","0.02106147","0","2"],["104366.3","0.08289838","0","3"],["104363.5","0.00952787","0","1"],["104362.1","0.0108964","0","1"],["104360.1","0.02042593","0","2"],["104359.8","1.32641558","0","4"],["104359.3","0.01818724","0","3"],["104358.3","0.0108964","0","1"],["104358.1","0","0","0"],["104356.4","0","0","0"],["104355.5","0","0","0"],["104354.4","0.0108964","0","1"],["104348.3","0","0","0"],["104346.5","0","0","0"],["104342","0","0","0"],["104341.4","0.00173882","0","1"],["104340.5","0.02179229","0","2"],["104340","0.00552861","0","7"],["104335.4","0.00761","0","2"],["104335.2","0.00002014","0","2"],["104335","0.00010095","0","1"],["104334.9","0.00002766","0","1"]],"ts":"1747170446500","checksum":1417619681,"seqId":54226338592,"prevSeqId":54226338427}]}
{"arg":{"channel":"books","instId":"BTC-USDT"},"action":"update","data":[{"asks":[["104433.4","1.23083986","0","17"],["104433.5","0.63746749","0","2"],["104433.8","0.29193486","0","1"],["104433.9","0.77866876","0","1"],["104434.4","0.03001988","0","1"],["104435.5","0.02999322","0","1"],["104436.4","0.09736045","0","1"],["104436.6","0.04528982","0","1"],["104436.9","0.09969834","0","1"],["104437.1","0.98699626","0","1"],["104437.2","0.70886178","0","3"],["104437.6","0.61465277","0","5"],["104437.9","0.09425627","0","1"],["104438.1","0.00009","0","1"],["104438.5","0.08908932","0","1"],["104438.8","0.13883463","0","1"],["104438.9","0.05209157","0","2"],["104439","0.011491","0","1"],["104439.1","0.00301145","0","2"],["104439.3","0.06352172","0","1"],["104439.4","0.06041763","0","5"],["104439.9","0","0","0"],["104440.1","0.06588599","0","3"],["104441.1","0.00478624","0","1"],["104441.2","0.05209157","0","2"],["104441.4","0.21061545","0","2"],["104441.9","0.32337897","0","2"],["104442.1","0.54824116","0","3"],["104442.2","0","0","0"],["104442.4","0.04","0","1"],["104443.2","0.00044","0","1"],["104444.8","0.15994067","0","1"],["104444.9","0.04","0","1"],["104445","0.03831289","0","2"],["104445.1","0.23241745","0","1"],["104445.3","0.04","0","1"],["104445.5","0","0","0"],["104446.9","0.25450665","0","1"],["104447.2","0","0","0"],["104447.4","0.41939824","0","2"],["104447.9","0","0","0"],["104448.2","0","0","0"],["104448.3","0","0","0"],["104448.5","0.00093","0","1"],["104449","0","0","0"],["104449.5","0","0","0"],["104450.7","0","0","0"],["104451","0.25462609","0","1"],["104451.8","0","0","0"],["104452.4","0","0","0"],["104452.5","0.21796231","0","1"],["104452.6","0.00001","0","1"],["104452.8","0","0","0"],["104453.3","0.26274137","0","1"],["104453.7","0.00093","0","1"],["104455.2","0","0","0"],["104455.6","0","0","0"],["104456.4","0","0","0"],["104456.7","0.17796783","0","1"],["104457","0.17796783","0","1"],["104457.4","0","0","0"],["104457.7","0","0","0"],["104457.9","0","0","0"],["104458.6","0.76117756","0","1"],["104458.8","0","0","0"],["104460","0.10851843","0","4"],["104461.5","0","0","0"],["104463","0.20116999","0","3"],["104464.7","0.00957036","0","1"],["104464.8","0.02230591","0","1"],["104465.9","0.17796783","0","1"],["104467","0","0","0"],["104468.5","0.00001","0","1"],["104472.1","0","0","0"],["104475.3","0.04799461","0","1"],["104482.2","0","0","0"],["104484.1","0","0","0"],["104485.6","0.5615115","0","2"],["104485.8","0","0","0"],["104486","0.26864","0","1"],["104486.1","0","0","0"],["104486.4","0","0","0"],["104487.3","0","0","0"],["104489.1","0","0","0"],["104490.8","0.02871108","0","1"],["104491.9","0.27872484","0","3"],["104494.1","0","0","0"],["104495.3","0","0","0"],["104498","0.49439815","0","1"],["104500.8","0.01435057","0","1"],["104501.9","0.00001946","0","1"],["104502.5","0","0","0"],["104505","0.47953102","0","2"],["104507.9","0","0","0"],["104508.3","0.02179032","0","2"],["104509.6","0","0","0"],["104510.5","0.06983","0","1"],["104511.8","0.07959","0","1"],["104513.3","0","0","0"],["104514.2","0.45627188","0","1"],["104515.7","0","0","0"],["104516.6","0","0","0"],["104517","0.0478518","0","1"],["104517.9","1.11421282","0","1"],["104518.2","0","0","0"],["104524.4","0","0","0"],["104524.9","0","0","0"],["104525","0","0","0"],["104525.9","0","0","0"],["104528.1","0.00001","0","1"],["104529.5","0.16865372","0","2"],["104533.5","0.01914989","0","1"],["104534.4","0","0","0"],["104534.8","0.11479","0","1"],["104536.5","0.07175","0","1"],["104539.4","0.0287049","0","1"],["104539.9","0.01053134","0","1"],["104541.1","0","0","0"],["104543.8","0.19131","0","1"],["104547.5","0","0","0"],["104552.9","0","0","0"],["104559.8","0","0","0"],["104561.8","0","0","0"],["104577.8","0","0","0"],["104594.2","0.35345","0","1"],["104601.1","0.01059613","0","1"],["104605.7","0","0","0"],["104605.8","0","0","0"],["104605.9","0","0","0"],["104608.7","0.00478755","0","1"],["104609.6","0","0","0"],["104609.7","0","0","0"],["104609.9","0.01089628","0","1"],["104611.7","0","0","0"],["104615","0","0","0"],["104617.5","0","0","0"],["104619.3","0","0","0"],["104622.4","0.00239358","0","1"],["104626.4","0.0143","0","1"],["104629.5","0.00010997","0","1"],["104629.6","0.0096711","0","3"],["104629.8","0.00037885","0","1"],["104629.9","0.02300636","0","1"],["104630","0.00028006","0","1"]],"bids":[["104439.3","0","0","0"],["104438.4","0","0","0"],["104438","0","0","0"],["104437.9","0","0","0"],["104437.5","0","0","0"],["104437.1","0","0","0"],["104436.8","0","0","0"],["104436","0","0","0"],["104435.3","0","0","0"],["104433.5","0","0","0"],["104433.4","0","0","0"],["104431.5","0","0","0"],["104430.1","0","0","0"],["104430","0.00029006","0","2"],["104429.7","0","0","0"],["104428.9","0.00001","0","1"],["104428.8","0","0","0"],["104428.5","0","0","0"],["104428","0.0816","0","1"],["104427.9","0","0","0"],["104427.8","0","0","0"],["104427.2","0","0","0"],["104426.5","0","0","0"],["104426.4","0","0","0"],["104426.2","0.00001731","0","1"],["104425.9","0.0001","0","1"],["104425.5","0.0005","0","1"],["104425.1","0.00030064","0","1"],["104424.9","0.00001","0","1"],["104424.3","0.00156669","0","1"],["104424","0","0","0"],["104423.3","0.0191493","0","1"],["104422.9","0","0","0"],["104422.7","0","0","0"],["104422.2","0.0000125","0","1"],["104421.4","0","0","0"],["104421.2","0","0","0"],["104421.1","0","0","0"],["104421","0.0000209","0","2"],["104420.6","0","0","0"],["104420.2","0.00098","0","1"],["104419.7","0","0","0"],["104418.7","0.00478659","0","1"],["104418.5","0.17796783","0","1"],["104418.1","0.03905376","0","2"],["104418","0","0","0"],["104417.9","0","0","0"],["104417.4","0.18120398","0","3"],["104416.7","0","0","0"],["104416","0.09468873","0","1"],["104415.9","0","0","0"],["104415.8","0","0","0"],["104415.7","0","0","0"],["104415.4","0.09799427","0","1"],["104415","0.09601927","0","1"],["104414.9","0","0","0"],["104414.7","0","0","0"],["104414.5","0.00008084","0","2"],["104414.4","0.16473368","0","1"],["104414","0","0","0"],["104413.9","0.14939596","0","1"],["104412.7","0","0","0"],["104412.4","0.15811749","0","1"],["104412.2","0","0","0"],["104411.6","0.03775997","0","2"],["104410.6","0","0","0"],["104410.5","0.14280357","0","2"],["104410.1","0.25314674","0","1"],["104409.9","0","0","0"],["104409.8","0.15404988","0","1"],["104408.7","0.00478624","0","1"],["104408.2","0.02928909","0","1"],["104407.4","0.26392781","0","1"],["104406.2","0","0","0"],["104404.4","0.25424372","0","1"],["104404.3","0","0","0"],["104404.1","0.00005489","0","1"],["104402","0.0454416","0","1"],["104401.2","0","0","0"],["104400","0.112661","0","48"],["104399.4","0.00041858","0","1"],["104399.3","0.11732273","0","1"],["104398.8","0.0000751","0","3"],["104398.1","0","0","0"],["104397.4","0.17796783","0","1"],["104396.8","0","0","0"],["104396.6","0.00009579","0","1"],["104396.4","0.17796783","0","1"],["104395.1","0.17796783","0","1"],["104394.1","0.15644865","0","1"],["104392","0","0","0"],["104391.7","0","0","0"],["104390.6","0.13883463","0","1"],["104390.5","0.19242972","0","1"],["104388.7","0","0","0"],["104383","0.09052118","0","1"],["104382.2","0.00483056","0","1"],["104382","0.48325987","0","2"],["104380.7","0.00001015","0","1"],["104379.2","0","0","0"],["104377.8","0.46440794","0","2"],["104377.1","0.01436757","0","1"],["104376.7","0.02106026","0","2"],["104376.5","0","0","0"],["104376.1","0.68529055","0","2"],["104376","0","0","0"],["104374.1","0.0000958","0","1"],["104371.9","0.01562119","0","1"],["104371.2","0.61003256","0","3"],["104370.7","0.00017245","0","2"],["104368.7","0","0","0"],["104367.7","0.00013602","0","1"],["104366.3","0.01106838","0","2"],["104365.9","0.20295985","0","2"],["104359.8","1.29768992","0","3"],["104356.5","0","0","0"],["104355.4","0.26152031","0","2"],["104351.8","0","0","0"],["104349.7","0.00001063","0","1"],["104347","0.36912973","0","3"],["104345","0","0","0"],["104343.6","0.07187018","0","2"],["104342.9","0.00004791","0","1"],["104338.8","0.02106522","0","2"],["104338.2","0.01080923","0","2"],["104336.8","0","0","0"],["104336.5","0.02137033","0","4"],["104336.2","0","0","0"],["104335","0.47450011","0","2"],["104334.7","0.00001137","0","1"],["104334.6","0.00003958","0","1"],["104334.3","0.00191691","0","1"],["104333.9","0.77867918","0","2"],["104333.5","0.00051032","0","2"],["104333.3","0.05953838","0","60"],["104333.2","0.00056399","0","1"],["104332.9","0.01975707","0","5"],["104332.7","0.00001263","0","1"],["104332.4","0.00001018","0","1"],["104332.3","0.0013452","0","1"],["104332.2","0.00003223","0","1"],["104332","0.0000395","0","1"],["104331.9","0.0004067","0","2"],["104331.6","0.0000424","0","1"],["104331.5","0.02179229","0","2"],["104331.1","0.01151984","0","2"],["104330.8","0.00005735","0","1"],["104330.4","0.000015","0","1"],["104330","0.00356554","0","4"],["104329.9","0.00001038","0","1"],["104329.8","0.07302275","0","4"],["104329.6","0.00001647","0","1"],["104329.4","0.0002877","0","1"],["104329.1","0.00006852","0","2"],["104329","0.00063224","0","1"],["104328","0.00007452","0","2"],["104327.9","0.00006107","0","1"],["104327.8","0.00017644","0","2"],["104327.7","0.00040824","0","1"],["104327.4","0.00004651","0","2"],["104327.3","0.00001012","0","1"],["104327.2","0.00035213","0","6"],["104327.1","0.00004932","0","1"],["104326.8","0.00001246","0","1"],["104326.4","0.00007615","0","1"]],"ts":"1747170446600","checksum":-1435472749,"seqId":54226339712,"prevSeqId":54226338592}]}
{"arg":{"channel":"books","instId":"BTC-USDT"},"action":"update","data":[{"asks":[["104428.1","1.08094587","0","19"],["104428.4","0.08758646","0","1"],["104428.5","0.29193486","0","1"],["104430","0.00002","0","1"],["104431.8","0.03002061","0","1"],["104433.1","0.00152861","0","1"],["104433.2","0.50634186","0","1"],["104433.3","0.09772076","0","1"],["104433.4","0.09503529","0","5"],["104433.5","0.32654754","0","2"],["104434.4","0","0","0"],["104436.4","0","0","0"],["104436.6","0","0","0"],["104436.9","0","0","0"],["104437.1","0.40602365","0","1"],["104437.2","0.60308178","0","2"],["104437.6","0.08871791","0","3"],["104437.9","0","0","0"],["104438.5","0","0","0"],["104438.8","0.16645269","0","1"],["104439.1","0.0429964","0","2"],["104439.4","0.05265823","0","3"],["104440","0.00741209","0","3"],["104440.1","0.05209157","0","2"],["104440.7","0.00001","0","1"],["104441.1","0","0","0"],["104441.4","0.04855676","0","1"],["104441.7","0.16111562","0","1"],["104441.9","0","0","0"],["104442.1","0.74685519","0","4"],["104442.4","0","0","0"],["104443.3","0.00478657","0","1"],["104443.4","0.13882778","0","1"],["104443.5","0.25940796","0","1"],["104444.3","0.24007145","0","1"],["104444.7","0.00001","0","1"],["104444.8","0","0","0"],["104445","0.000015","0","1"],["104445.1","0","0","0"],["104445.7","0.637738","0","2"],["104446.5","0.04337541","0","2"],["104446.9","0","0","0"],["104447.4","0.32032345","0","1"],["104447.7","0.54704961","0","2"],["104448","0","0","0"],["104450.5","0.10631","0","1"],["104451","0","0","0"],["104451.6","0.00191","0","1"],["104451.8","0.075","0","2"],["104452.5","0.32439242","0","2"],["104454.7","0.03987675","0","1"],["104455.8","0.10631","0","1"],["104455.9","0.093","0","3"],["104456","0.036","0","1"],["104456.8","0.00191","0","1"],["104457.8","0.00287","0","1"],["104458.6","0.55365027","0","1"],["104460","0.00220843","0","3"],["104462.8","0","0","0"],["104462.9","0.0001303","0","1"],["104463","0.40145439","0","4"],["104463.4","0.19242972","0","1"],["104463.9","0.6867","0","1"],["104464","0.002","0","2"],["104464.3","0","0","0"],["104465","0.001","0","1"],["104466.2","0.039","0","1"],["104467.5","0.26864","0","1"],["104468.1","0.28609157","0","3"],["104468.9","0.0022","0","1"],["104470.2","0.03","0","1"],["104471.8","0.00014004","0","1"],["104474","0","0","0"],["104475","0","0","0"],["104478.6","0","0","0"],["104478.7","0.88564718","0","2"],["104480.1","0.25","0","2"],["104480.5","0","0","0"],["104481.2","2.51461","0","1"],["104485","0.7190888","0","3"],["104485.5","0","0","0"],["104486","0.20999999","0","3"],["104486.4","0.0022","0","1"],["104487","0.08001499","0","2"],["104488.4","0.00001","0","1"],["104489","0.10930735","0","1"],["104491.6","0","0","0"],["104491.8","0","0","0"],["104493.3","1.39575722","0","1"],["104495","0.07","0","2"],["104495.4","0.00080381","0","1"],["104496","0.035","0","1"],["104498.8","0","0","0"],["104499.2","1.04171728","0","2"],["104503.4","3.0508","0","1"],["104505","0.07298372","0","1"],["104505.6","0","0","0"],["104506.8","0.50913601","0","1"],["104509.2","0.83283","0","1"],["104509.7","0.15564055","0","1"],["104512.2","0.00001","0","1"],["104514.2","0","0","0"],["104514.3","0","0","0"],["104517.7","0","0","0"],["104517.9","0","0","0"],["104524.8","0","0","0"],["104528","0.01053134","0","1"],["104529.9","0","0","0"],["104530.3","0.0026968","0","2"],["104534.2","0","0","0"],["104540","0.00220843","0","3"],["104542.9","0","0","0"],["104551","1.25507","0","1"],["104555.9","0","0","0"],["104584.7","0","0","0"],["104588.2","0.03","0","1"],["104622.4","0","0","0"],["104623.3","0.00239358","0","1"],["104629.6","0","0","0"],["104629.8","0","0","0"],["104629.9","0","0","0"],["104630","0","0","0"]],"bids":[["104433.3","0","0","0"],["104433.2","0","0","0"],["104432.7","0","0","0"],["104432.6","0","0","0"],["104430.7","0","0","0"],["104430","0","0","0"],["104429.6","0","0","0"],["104428.9","0","0","0"],["104428.6","0","0","0"],["104428","0.09437238","0","3"],["104425.5","0","0","0"],["104425.1","0","0","0"],["104423.4","0","0","0"],["104422.4","0.03364478","0","1"],["104420.2","0","0","0"],["104420.1","0.020016","0","2"],["104420","0.03642106","0","5"],["104419.5","0.00030064","0","1"],["104418.7","0","0","0"],["104418.5","0","0","0"],["104418.2","0.02962768","0","1"],["104418.1","0.00004752","0","1"],["104417.4","0.00012018","0","1"],["104417.2","0.00741697","0","2"],["104416.5","0","0","0"],["104416","0","0","0"],["104415.4","0","0","0"],["104415","0.07923206","0","1"],["104414.4","0","0","0"],["104413.9","0","0","0"],["104412.4","0","0","0"],["104412.3","0.09115043","0","1"],["104411.3","0.16828225","0","1"],["104410.6","0.00478657","0","1"],["104410.5","0.18451925","0","2"],["104410.3","0.00005","0","1"],["104410.1","0","0","0"],["104409.8","0","0","0"],["104409.7","0.01081621","0","1"],["104409","0.16914097","0","1"],["104408.9","0.03","0","1"],["104408.8","0.03","0","1"],["104408.7","0","0","0"],["104408","0.04","0","1"],["104407.4","0","0","0"],["104407.2","0.00001147","0","1"],["104406.7","0.14772126","0","1"],["104404.8","0.195945","0","4"],["104404.7","0.03","0","1"],["104404.6","0","0","0"],["104404.5","0.15279273","0","1"],["104404.4","0","0","0"],["104404.2","0.00008559","0","1"],["104404","0.2563641","0","3"],["104402.3","0.071789","0","1"],["104402","0","0","0"],["104401.6","0.00383136","0","1"],["104401.3","0.2483659","0","1"],["104401.2","0.19242972","0","1"],["104400.7","0.17796783","0","1"],["104399.5","0.41618168","0","1"],["104399.4","0.77908734","0","2"],["104399.3","0","0","0"],["104398.2","0.17796783","0","1"],["104397","0.04544376","0","1"],["104396","0.13882778","0","1"],["104395.2","0.16509055","0","1"],["104394.8","0.17796783","0","1"],["104394.1","0","0","0"],["104393.8","0","0","0"],["104393.3","0.00008057","0","2"],["104390.6","0","0","0"],["104388.6","0","0","0"],["104383","0.31819674","0","1"],["104382.2","0.37391234","0","2"],["104382.1","0","0","0"],["104381","0.00047877","0","1"],["104380.2","0","0","0"],["104378.9","0","0","0"],["104376.7","0","0","0"],["104375.9","0.413506","0","1"],["104373.2","0.3289234","0","1"],["104372.8","0","0","0"],["104371.5","0.00001916","0","1"],["104370.1","0.00001034","0","1"],["104369.3","0.00001092","0","1"],["104368.2","0.00002964","0","1"],["104368.1","0.01053134","0","1"],["104367.8","0.38069192","0","3"],["104366.7","0.01053134","0","1"],["104365.9","0.19242972","0","1"],["104365.8","0.77869346","0","3"],["104364.1","0","0","0"],["104363.2","0","0","0"],["104361","0.27779","0","1"],["104360.7","0","0","0"],["104357.9","0","0","0"],["104350.1","0.02106712","0","2"],["104349.8","0.33136003","0","6"],["104348.8","0.0036403","0","1"],["104347.1","0.01053356","0","1"],["104345.6","0.01054356","0","2"],["104344.5","0.01053356","0","1"],["104343.7","0.01058243","0","2"],["104342.9","0.01058147","0","2"],["104340.6","0.01053356","0","1"],["104340.4","0","0","0"],["104340","0.00553861","0","8"],["104338.9","0.01056361","0","2"],["104336.6","0.01053356","0","1"],["104326.3","0.00988866","0","4"],["104326.1","0.02701026","0","1"],["104325.8","0.00001","0","1"],["104325.7","0.00043373","0","2"],["104325.6","0.00001","0","1"]],"ts":"1747170446700","checksum":173431329,"seqId":54226340546,"prevSeqId":54226339712}]}
{"arg":{"channel":"books","instId":"BTC-USDT"},"action":"update","data":[{"asks":[["104428.1","0.9456117","0","19"],["104428.4","0","0","0"],["104428.5","0","0","0"],["104428.6","0.00522006","0","1"],["104431.8","0.06004122","0","2"],["104433.2","0.21734981","0","1"],["104433.3","0","0","0"],["104433.4","0.06688157","0","4"],["104433.5","0.09254754","0","1"],["104433.9","0","0","0"],["104435.3","0.09352909","0","1"],["104435.9","0.00045","0","1"],["104436.7","0.09501559","0","1"],["104437.1","0.29255111","0","1"],["104437.2","0.36908178","0","1"],["104437.4","0.09420863","0","1"],["104438.1","0","0","0"],["104438.8","0","0","0"],["104439.1","0.04","0","1"],["104440","0.00030006","0","2"],["104440.2","0.14772456","0","1"],["104440.8","0.15974769","0","1"],["104441.2","0.05302157","0","3"],["104441.7","0","0","0"],["104442","0.0047867","0","1"],["104442.5","0.04855625","0","1"],["104443.2","0","0","0"],["104443.3","0","0","0"],["104443.4","0","0","0"],["104443.6","0.14759553","0","1"],["104444","0.23973911","0","1"],["104444.3","0","0","0"],["104446.3","0.2641593","0","1"],["104446.4","0.00093","0","1"],["104447.2","0.13882326","0","1"],["104448.5","0","0","0"],["104449.9","0.24676501","0","1"],["104450.4","0","0","0"],["104451.1","0.00711203","0","1"],["104453.7","0","0","0"],["104454.7","0.04274869","0","2"],["104455.8","0","0","0"],["104461","0.01379442","0","1"],["104462.9","0","0","0"],["104464.8","0","0","0"],["104466.8","0.00014004","0","1"],["104468.5","0.09577","0","2"],["104470.2","0","0","0"],["104470.3","0","0","0"],["104471.6","0.09576","0","1"],["104471.8","0","0","0"],["104473.2","0.38245279","0","2"],["104476.3","0.554767","0","1"],["104478.2","0.02230591","0","1"],["104480.3","0.00334879","0","2"],["104482.8","0.1","0","1"],["104485","0.70764299","0","5"],["104486","0.12999999","0","2"],["104487","0.000015","0","1"],["104509.7","0.45327867","0","2"],["104518.1","0.831818","0","1"],["104542.8","0.00009316","0","1"],["104628","0","0","0"],["104628.6","0","0","0"],["104628.8","0","0","0"],["104629.5","0","0","0"]],"bids":[["104428","0.24646238","0","7"],["104423.3","0","0","0"],["104422.8","0.03459312","0","2"],["104422.4","0","0","0"],["104420.2","0.0005","0","1"],["104420.1","0.01499341","0","2"],["104420","0.00277552","0","4"],["104419.5","0","0","0"],["104419","0.00030064","0","1"],["104418.5","0.0047869","0","1"],["104417.2","0.01181597","0","2"],["104416.2","0.09032828","0","1"],["104415","0.43844844","0","1"],["104414.9","0.09123121","0","2"],["104414.3","0.09549432","0","1"],["104413.3","0.15833567","0","1"],["104412.7","0.14870851","0","1"],["104412.4","0.19242972","0","1"],["104412.3","0","0","0"],["104411.3","0","0","0"],["104411","0.77866876","0","1"],["104410.6","0","0","0"],["104410.5","0.15094453","0","1"],["104409.9","0.02508872","0","1"],["104409.7","0.00098","0","1"],["104409.1","0.0047967","0","2"],["104409","0.3978134","0","2"],["104408.6","0.16569644","0","3"],["104408.2","0.10227281","0","2"],["104408","0","0","0"],["104406.9","0.04","0","1"],["104406.7","0","0","0"],["104404.7","0.04081621","0","2"],["104404.5","0.2835215","0","3"],["104403.3","0.24344411","0","1"],["104402.4","0.23831795","0","1"],["104402.2","0.00715012","0","2"],["104401.3","0","0","0"],["104399.6","0.36908178","0","1"],["104399.3","0.00191","0","1"],["104398.3","0.13882326","0","1"],["104396","0","0","0"],["104388.8","0.65394317","0","4"],["104386.2","1.35852873","0","2"],["104381","0","0","0"],["104374.5","0.04092","0","1"],["104372","0.030015","0","2"],["104368.2","0","0","0"],["104367.8","0.35069192","0","2"],["104359.4","0.00011389","0","1"],["104355.4","0.94723582","0","3"],["104355","0.555421","0","2"],["104354.9","2.3894936","0","1"],["104349.3","0.00032461","0","2"],["104340.9","0.00023787","0","1"],["104326.8","0","0","0"],["104326.4","0","0","0"],["104326.3","0","0","0"],["104326.1","0","0","0"],["104325.8","0","0","0"],["104325.7","0","0","0"],["104325.6","0","0","0"]],"ts":"1747170446800","checksum":1540777897,"seqId":54226340924,"prevSeqId":54226340546}]}
{"arg":{"channel":"books","instId":"BTC-USDT"},"action":"update","data":[{"asks":[["104428.1","0.75318198","0","18"],["104428.5","0.0029964","0","1"],["104433.2","0.14454216","0","1"],["104433.4","0.06209157","0","3"],["104435.3","0","0","0"],["104436.7","0","0","0"],["104437.1","0.40589703","0","2"],["104437.3","0.08833063","0","1"],["104437.4","0","0","0"],["104440.2","0","0","0"],["104440.8","0.14381688","0","1"],["104443.6","0","0","0"],["104444","0","0","0"],["104444.2","0.14637431","0","1"],["104446.3","0","0","0"],["104447.2","0","0","0"],["104449.9","0","0","0"],["104450","0.13912107","0","3"],["104451.4","0.0001303","0","1"],["104461","0","0","0"],["104466.2","0","0","0"],["104470.4","0","0","0"],["104494.7","0.14355","0","1"],["104496.6","0.0957","0","1"],["104499.7","0.06","0","2"],["104503.9","0.09","0","3"],["104509.7","0.11347254","0","1"],["104518","0.30794135","0","1"],["104520.5","0.34639108","0","2"],["104524.7","0","0","0"],["104524.8","6.81800673","0","1"],["104538.2","0.00009606","0","1"],["104542.8","0","0","0"],["104598.8","0","0","0"],["104628","0.01403883","0","1"],["104628.8","0.07421474","0","2"],["104629.5","0.00010997","0","1"],["104629.6","0.0096711","0","3"]],"bids":[["104426.4","0.03364349","0","1"],["104422.8","0.00094847","0","1"],["104420.5","0.01914968","0","1"],["104420.1","0.00031314","0","2"],["104419.5","0.00478683","0","1"],["104419","0","0","0"],["104418.5","0","0","0"],["104418.3","0.03975142","0","2"],["104416.8","0.09586461","0","1"],["104416.2","0","0","0"],["104414.9","0.00098","0","1"],["104414.3","0","0","0"],["104413.3","0.15280155","0","1"],["104412.7","0","0","0"],["104410.5","0.22054057","0","2"],["104409.2","0.16335718","0","1"],["104409","0.16914097","0","1"],["104408.6","0.0008379","0","2"],["104404.5","0.39188144","0","3"],["104403.3","0","0","0"],["104402.4","0","0","0"],["104401.1","0.13882101","0","1"],["104398.3","0","0","0"],["104378.5","0.04603253","0","1"],["104372","0.000015","0","1"],["104370.8","0","0","0"],["104361","0.30779","0","2"],["104357","0.00002964","0","1"],["104356.8","0.03","0","1"],["104327.1","0","0","0"]],"ts":"1747170446900","checksum":-2009091245,"seqId":54226341179,"prevSeqId":54226340924}]}
{"arg":{"channel":"books","instId":"BTC-USDT"},"action":"update","data":[{"asks":[["104428.1","0.53819122","0","19"],["104432.2","0.071789","0","1"],["104433.2","0.15980886","0","2"],["104433.5","0","0","0"],["104436.3","0.09511048","0","1"],["104437.1","0.29255111","0","1"],["104437.3","0","0","0"],["104437.7","0.09503352","0","1"],["104438.3","0.09965546","0","1"],["104439.3","0","0","0"],["104440.8","0","0","0"],["104441.2","0.2031417","0","4"],["104441.8","0.14929991","0","1"],["104443.5","0","0","0"],["104444.2","0","0","0"],["104444.6","0.16197635","0","1"],["104445","0.24892872","0","2"],["104445.7","0.56595","0","1"],["104447.3","0.24871377","0","1"],["104450.8","0.25347596","0","1"],["104451.4","0","0","0"],["104473.2","0.78733926","0","1"],["104475.6","1.38108837","0","1"],["104494.4","0.85459938","0","2"],["104499.2","1.7870072","0","1"],["104501.1","6.81800673","0","1"],["104501.9","0.06704946","0","2"],["104503.3","0.01053356","0","1"],["104504.8","0.01053356","0","1"],["104506.7","0.01053356","0","1"],["104506.8","0","0","0"],["104508.2","0.01054356","0","2"],["104509.1","0.01053356","0","1"],["104511.7","0.01053356","0","1"],["104516.9","0.03160068","0","3"],["104518","0","0","0"],["104519.9","0.01053356","0","1"],["104520.5","0.00658495","0","1"],["104522.5","0.01053356","0","1"],["104524.8","0.01053356","0","1"],["104528.1","0.06704","0","2"],["104623.5","0","0","0"],["104625","0","0","0"],["104625.7","0","0","0"],["104626.4","0","0","0"],["104627.2","0","0","0"],["104628","0","0","0"],["104628.8","0","0","0"],["104629.5","0","0","0"],["104629.6","0","0","0"]],"bids":[["104428","0.24657238","0","8"],["104424.4","0.24","0","1"],["104420.2","0.00080064","0","2"],["104420.1","0.0000125","0","1"],["104418.3","0.039701","0","2"],["104417.2","0.10751253","0","3"],["104416.8","0","0","0"],["104415.8","0.09170642","0","1"],["104415.3","0.09860946","0","1"],["104414.3","0.15161605","0","1"],["104413.7","0.15701339","0","1"],["104413.3","0","0","0"],["104412.9","0.02508872","0","1"],["104410.5","0.15094453","0","1"],["104410","0.25953154","0","4"],["104409.9","0","0","0"],["104409.6","0.16214099","0","1"],["104409.2","0","0","0"],["104409","0","0","0"],["104404.5","0.27189073","0","2"],["104404.3","0.24931845","0","1"],["104404","0.0001056","0","2"],["104403.3","0.23436998","0","1"],["104386.3","0.00520646","0","3"],["104383.1","0.00287154","0","1"],["104377.3","0.00479798","0","2"],["104352.3","0.13103356","0","2"],["104350.2","0.01053356","0","1"],["104349","0.01053356","0","1"],["104347.2","0.01053356","0","1"],["104345.7","0.01053356","0","1"],["104344.6","0.01062629","0","3"],["104343","0.01053356","0","1"],["104341.5","0.01053356","0","1"],["104339","0.01057538","0","3"],["104336.7","0.01057034","0","2"],["104335.1","0.01053356","0","1"],["104333.3","0.05666738","0","59"],["104329.8","0","0","0"],["104329.6","0","0","0"],["104329.4","0","0","0"],["104329.1","0","0","0"],["104329","0","0","0"],["104328","0","0","0"],["104327.9","0","0","0"],["104327.8","0","0","0"],["104327.7","0","0","0"],["104327.4","0","0","0"],["104327.3","0","0","0"],["104327.2","0","0","0"]],"ts":"1747170447000","checksum":604867485,"seqId":54226341347,"prevSeqId":54226341179}]}
{"arg":{"channel":"books","instId":"BTC-USDT"},"action":"update","data":[{"asks":[["104428.1","0.53875788","0","20"],["104432.1","0.16597827","0","1"],["104433.2","0","0","0"],["104435.8","0.09547363","0","1"],["104436.3","0","0","0"],["104437.2","0.46140722","0","2"],["104437.7","0","0","0"],["104437.8","0.09323974","0","1"],["104438.3","0","0","0"],["104439.4","0.05209157","0","2"],["104440","0.00508676","0","3"],["104440.7","0.14940583","0","2"],["104441.2","0.05302157","0","3"],["104441.3","0.16153615","0","1"],["104441.8","0","0","0"],["104442","0","0","0"],["104444.1","0.21192131","0","3"],["104444.5","0.26145228","0","1"],["104444.6","0","0","0"],["104445","0.000015","0","1"],["104446.8","0.25605854","0","1"],["104447.3","0","0","0"],["104450.3","0.246591","0","1"],["104450.8","0","0","0"],["104451.4","0.0001303","0","1"],["104456.1","0.00056666","0","1"],["104462.4","0","0","0"],["104541.7","0.12","0","1"],["104573.8","0","0","0"],["104623.5","0.000015","0","1"]],"bids":[["104428","0.237","0","7"],["104424.4","0","0","0"],["104420.6","0.00478679","0","1"],["104419.5","0","0","0"],["104418.3","0.04079408","0","2"],["104417.6","0.00957333","0","1"],["104417.2","0.01181597","0","2"],["104416.7","0.08976682","0","1"],["104415.8","0","0","0"],["104415.3","0.09405902","0","1"],["104414.8","0.10165352","0","1"],["104414.3","0","0","0"],["104413.8","0.15579669","0","2"],["104413.7","0","0","0"],["104413.2","0.15950576","0","1"],["104410.5","0.17637775","0","2"],["104410","0.00030298","0","3"],["104409.6","0","0","0"],["104409.5","0.25631586","0","1"],["104409.1","0.14846459","0","2"],["104407","0.0047867","0","1"],["104404.5","0.32581754","0","3"],["104404.3","0","0","0"],["104403.8","0.25828979","0","1"],["104403.3","0","0","0"],["104402.8","0.25810952","0","1"],["104396.2","0","0","0"],["104389","0.47217283","0","1"],["104376.3","0.77923542","0","2"],["104373.3","0","0","0"],["104348.3","0.00056666","0","1"],["104329.9","0","0","0"]],"ts":"1747170447100","checksum":-1939969092,"seqId":54226341467,"prevSeqId":54226341347}]}
{"arg":{"channel":"books","instId":"BTC-USDT"},"action":"update","data":[{"asks":[["104428.1","0.55024988","0","21"],["104431.7","0.00152861","0","1"],["104433.1","0","0","0"],["104439","0","0","0"],["104449.2","0.03589513","0","1"],["104452","0.00478798","0","1"],["104461.9","0.77866876","0","1"],["104485","0.77764299","0","7"],["104486","0.16499999","0","3"],["104491.9","0.37442484","0","4"],["104495","0","0","0"],["104495.3","0.11484","0","1"],["104496","0","0","0"],["104502.8","0.19138","0","1"],["104529.5","0.07298372","0","1"],["104534.8","0","0","0"],["104535.7","0.00009863","0","1"],["104538.2","0","0","0"],["104543.8","0","0","0"],["104625","0.0000103","0","1"]],"bids":[["104422.3","0","0","0"],["104421.1","0.00478675","0","1"],["104420.6","0","0","0"],["104420.2","0.0005","0","1"],["104420.1","0.00031314","0","2"],["104375.8","0.00047879","0","1"]],"ts":"1747170447200","checksum":-1035904813,"seqId":54226341534,"prevSeqId":54226341467}]}
{"arg":{"channel":"books","instId":"BTC-USDT"},"action":"update","data":[{"asks":[["104435","0.01914938","0","1"],["104437.8","0","0","0"],["104437.9","0.08790355","0","1"],["104450.3","0","0","0"],["104450.4","0.26573035","0","1"],["104462","0.37108178","0","3"],["104463","0.40245439","0","5"],["104464","0","0","0"],["104465","0","0","0"],["104473.2","0.42081935","0","1"],["104475.6","0","0","0"],["104483","0.33","0","6"],["104484","0.16499999","0","3"],["104485","0.44764299","0","1"],["104486","0","0","0"],["104493.3","0","0","0"],["104499.2","1.83102302","0","2"],["104625.7","0.0001","0","1"],["104626.4","0.0143","0","1"]],"bids":[["104428","0.23715314","0","8"],["104415.4","0.09705464","0","1"],["104415.3","0","0","0"],["104402.9","0.25613209","0","2"],["104402.8","0","0","0"],["104388.8","0.36353493","0","3"],["104386.2","0.00003798","0","1"],["104355.4","0.39701104","0","2"],["104354.9","0","0","0"],["104329.9","0.00001038","0","1"],["104329.8","0.07302275","0","4"]],"ts":"1747170447300","checksum":-1269912993,"seqId":54226341588,"prevSeqId":54226341534}]}
{"arg":{"channel":"books","instId":"BTC-USDT"},"action":"update","data":[{"asks":[["104473.2","0.79624887","0","2"],["104474.5","1.42677315","0","1"],["104505.9","2.6416597","0","1"],["104587.4","0.00090547","0","1"],["104625","0","0","0"],["104625.7","0","0","0"],["104626.4","0","0","0"]],"bids":[["104408.3","0.00020622","0","1"],["104383.9","0.69799573","0","1"],["104383.8","1.38411575","0","3"],["104383","0","0","0"],["104352.5","2.44516683","0","2"],["104329.8","0","0","0"]],"ts":"1747170447400","checksum":-1269912993,"seqId":54226341645,"prevSeqId":54226341588}]}
{"arg":{"channel":"books","instId":"BTC-USDT"},"action":"update","data":[{"asks":[["104475","1","0","1"],["104520.5","0","0","0"],["104522.6","0","0","0"],["104523.7","0","0","0"],["104528.9","0","0","0"],["104625","0.0000103","0","1"],["104625.7","0.0001","0","1"],["104626.4","0.0143","0","1"]],"bids":[["104428","0.23716314","0","9"],["104426.8","0.00117639","0","2"],["104424.6","0.00601038","0","2"],["104408.3","0","0","0"],["104329.8","0.07302275","0","4"]],"ts":"1747170447500","checksum":1946616460,"seqId":54226341656,"prevSeqId":54226341645}]}
{"arg":{"channel":"books","instId":"BTC-USDT"},"action":"update","data":[{"asks":[["104428.1","0.54323188","0","20"],["104431.7","0","0","0"],["104431.8","0","0","0"],["104432","0.00152861","0","1"],["104433.7","0.02378021","0","1"],["104435.3","0.0300196","0","1"],["104435.8","0","0","0"],["104436.1","0.09102708","0","1"],["104437.2","0.36908178","0","1"],["104437.6","0.18490361","0","4"],["104437.9","0","0","0"],["104438.2","0.09072369","0","1"],["104440.7","0.00001","0","1"],["104441.1","0.15545371","0","1"],["104441.3","0","0","0"],["104441.6","0.15514309","0","1"],["104444.1","0.05209157","0","2"],["104444.4","0.15123309","0","1"],["104444.5","0","0","0"],["104444.8","0.2425732","0","1"],["104446.8","0","0","0"],["104447.1","0.25875931","0","1"],["104450.4","0","0","0"],["104450.7","0.25208598","0","1"],["104514.9","0.01617493","0","1"],["104517","0.06221574","0","2"],["104518.1","0.84139396","0","2"],["104523.3","0.00957596","0","1"],["104623.4","0","0","0"],["104623.5","0","0","0"],["104625","0","0","0"],["104625.7","0","0","0"],["104626.4","0","0","0"]],"bids":[["104426.8","0.00317964","0","4"],["104424.6","0.03965444","0","3"],["104418.3","0.04097276","0","2"],["104417.1","0.0904216","0","2"],["104416.7","0","0","0"],["104415.7","0.0921006","0","1"],["104415.4","0","0","0"],["104415.1","0.09569899","0","1"],["104414.8","0","0","0"],["104414.1","0.19487768","0","2"],["104413.8","0.00001","0","1"],["104413.6","0.15338488","0","2"],["104413.2","0","0","0"],["104410.5","0.17413482","0","2"],["104409.8","0.24960825","0","1"],["104409.5","0","0","0"],["104409.4","0.14768578","0","1"],["104409.1","0.00001","0","1"],["104404.5","0.328543","0","3"],["104404.1","0.26677256","0","2"],["104403.8","0","0","0"],["104403.2","0.25878151","0","2"],["104402.9","0.00001373","0","1"],["104329.6","0.00001647","0","1"],["104329.4","0.0002877","0","1"]],"ts":"1747170447600","checksum":1698370363,"seqId":54226341722,"prevSeqId":54226341656}]}
{"arg":{"channel":"books","instId":"BTC-USDT"},"action":"update","data":[{"asks":[["104466.9","0","0","0"],["104480.4","0.02121238","0","2"],["104487.4","0.02872789","0","1"],["104490","0.00029006","0","2"],["104622.4","0.00239358","0","1"],["104623.3","0","0","0"]],"bids":[],"ts":"1747170447700","checksum":1698370363,"seqId":54226341730,"prevSeqId":54226341722}]}
{"arg":{"channel":"books","instId":"BTC-USDT"},"action":"update","data":[{"asks":[["104428.1","0.63279188","0","21"],["104431.5","0.02378071","0","1"],["104431.7","0.00152861","0","1"],["104431.8","0.18412843","0","1"],["104432","0","0","0"],["104432.1","0","0","0"],["104433.4","0.05209157","0","2"],["104433.5","0.09629001","0","1"],["104434","0.09663987","0","1"],["104435","0.11045861","0","2"],["104435.6","0.0915581","0","1"],["104436.1","0","0","0"],["104437.1","0.42263548","0","2"],["104437.6","0.08871791","0","3"],["104438.2","0","0","0"],["104438.5","0.15575482","0","1"],["104439","0.31932804","0","2"],["104440","0.00030006","0","2"],["104441.1","0.0047867","0","1"],["104441.4","0","0","0"],["104441.6","0","0","0"],["104441.8","0.15097593","0","1"],["104442.2","0.23260671","0","1"],["104444","0.2480865","0","1"],["104444.4","0","0","0"],["104444.5","0.24482597","0","1"],["104444.8","0","0","0"],["104447.1","0","0","0"],["104448.1","0.29919416","0","3"],["104450.7","0","0","0"],["104473.2","1.09915085","0","1"],["104476","0.16610223","0","1"],["104489","0","0","0"],["104499.2","1.00445699","0","1"],["104509.7","0","0","0"],["104587.4","0","0","0"],["104587.6","0.00090448","0","1"],["104610","0.29270107","0","3"],["104622.4","0","0","0"]],"bids":[["104428","0.11766314","0","8"],["104426.4","0","0","0"],["104424.6","0.00601038","0","2"],["104422.9","0.02962635","0","1"],["104421.1","0","0","0"],["104420.1","0.0000125","0","1"],["104419.7","0.00030064","0","1"],["104419.6","0.00478683","0","1"],["104418.3","0.01256232","0","1"],["104417.1","0.00005919","0","1"],["104415.7","0","0","0"],["104415.1","0","0","0"],["104415","0.46130814","0","2"],["104414.5","0.19362345","0","4"],["104414.1","0.04016601","0","1"],["104413.6","0.000015","0","1"],["104413.1","0.09407007","0","1"],["104412.5","0.10223515","0","1"],["104412.4","0","0","0"],["104411.7","0.19242972","0","1"],["104411.5","0.15351283","0","1"],["104411","0.93427862","0","2"],["104410.5","0.23209888","0","2"],["104410","0.04678426","0","4"],["104409.8","0","0","0"],["104409.5","0.15685608","0","1"],["104409.4","0","0","0"],["104408.7","0.0047867","0","1"],["104407.2","0.25383103","0","2"],["104407","0","0","0"],["104406.8","0.16146667","0","1"],["104404.7","0.03","0","1"],["104404.6","0.30615561","0","1"],["104404.5","0.24697775","0","2"],["104404.1","0.00005489","0","1"],["104403.2","0.000015","0","1"],["104401.5","0.26199614","0","1"],["104400.6","0.24866562","0","1"],["104399.6","0","0","0"],["104370","0.00280079","0","4"],["104357","0","0","0"],["104329.8","0","0","0"],["104329.6","0","0","0"],["104329.4","0","0","0"]],"ts":"1747170447800","checksum":1799709420,"seqId":54226341964,"prevSeqId":54226341730}]}
{"arg":{"channel":"books","instId":"BTC-USDT"},"action":"update","data":[{"asks":[["104428.1","0.72574154","0","21"],["104428.8","0.01427461","0","1"],["104428.9","0.02378131","0","1"],["104431.8","0.35346805","0","2"],["104433.5","0","0","0"],["104433.7","0.77866876","0","1"],["104434","0","0","0"],["104435","0","0","0"],["104435.6","0","0","0"],["104436.3","0.09708927","0","1"],["104437.1","0.29255111","0","1"],["104438.5","0","0","0"],["104438.8","0.0047867","0","1"],["104439","0","0","0"],["104439.8","0.15885173","0","1"],["104441.1","0","0","0"],["104441.8","0","0","0"],["104442.2","0","0","0"],["104443.2","0.16278511","0","1"],["104444","0","0","0"],["104444.5","0","0","0"],["104447.6","0.00478798","0","1"],["104448.1","0.05209157","0","2"],["104457","0.17996783","0","3"],["104457.5","0","0","0"],["104458","0.001","0","1"],["104462","0.36908178","0","1"],["104463","0.40145439","0","4"],["104478","0.33","0","6"],["104479","0.16499999","0","3"],["104483","0","0","0"],["104484","0","0","0"],["104622.4","0.00239358","0","1"],["104623.4","0.00001","0","1"],["104623.5","0.000015","0","1"],["104625","0.0000103","0","1"]],"bids":[["104428","0.08516314","0","6"],["104426","0.0816","0","1"],["104424","0.0816","0","1"],["104422.9","0","0","0"],["104420.2","0.02448924","0","2"],["104420.1","0.00031314","0","2"],["104419.7","0","0","0"],["104419.6","0","0","0"],["104418.3","0","0","0"],["104417.5","0.02962787","0","1"],["104417.2","0.00262999","0","1"],["104416.7","0.00478702","0","1"],["104415.8","0.08854681","0","1"],["104415","0.45086004","0","2"],["104414.5","0.00008084","0","2"],["104413.1","0","0","0"],["104412.5","0","0","0"],["104412.4","0.19242972","0","1"],["104412.3","0.1634584","0","1"],["104411.7","0","0","0"],["104411.5","0","0","0"],["104411","0.77866876","0","1"],["104410.5","0.19458722","0","2"],["104410","0.00030298","0","3"],["104409.5","0","0","0"],["104408.7","0","0","0"],["104408.2","0.26258633","0","3"],["104407.2","0.00001147","0","1"],["104407","0.04648261","0","1"],["104406.8","0","0","0"],["104404.9","0.0047867","0","1"],["104404.6","0.3243966","0","2"],["104404.5","0.00191","0","1"],["104401.5","0","0","0"],["104400.6","0","0","0"],["104389","0","0","0"],["104383.1","0","0","0"],["104357","0.00002964","0","1"],["104344.8","0.002874","0","1"],["104329.8","0.07302275","0","4"],["104329.6","0.00001647","0","1"],["104329.5","0.00009744","0","1"],["104329.4","0.0002877","0","1"]],"ts":"1747170447900","checksum":-571470930,"seqId":54226342224,"prevSeqId":54226341964}]}
{"arg":{"channel":"books","instId":"BTC-USDT"},"action":"update","data":[{"asks":[["104428.1","1.3180386","0","26"],["104428.8","0","0","0"],["104428.9","0","0","0"],["104431.7","0","0","0"],["104431.8","0.18412843","0","1"],["104432.2","0.10180951","0","2"],["104433.3","0.00152861","0","1"],["104433.7","0","0","0"],["104436.3","0","0","0"],["104436.5","0.09687428","0","1"],["104437.1","0.40848045","0","2"],["104439.8","0","0","0"],["104440","0.16036438","0","3"],["104442.5","0","0","0"],["104443.2","0","0","0"],["104443.4","0.16244265","0","1"],["104446","0.13882401","0","1"],["104450","0.00030006","0","2"],["104457","0.17796783","0","1"],["104458","0.002","0","2"],["104458.2","0","0","0"],["104459","0.001","0","1"],["104478","0","0","0"],["104479","0.32999999","0","6"],["104480","0.16720842","0","6"],["104499.2","1.13454136","0","1"],["104587.5","0.0118005","0","2"],["104587.6","0","0","0"],["104622.4","0","0","0"],["104623.3","0.00239358","0","1"],["104625.7","0.0001","0","1"],["104626.4","0.0143","0","1"],["104627.2","0.77866876","0","1"],["104628","0.01403883","0","1"],["104628.8","0.07421474","0","2"],["104629.5","0.00010997","0","1"]],"bids":[["104428","0.08184314","0","3"],["104420.3","0.00030064","0","1"],["104420.2","0.06661306","0","3"],["104420.1","0.0000125","0","1"],["104418","0.02962772","0","1"],["104417.6","0","0","0"],["104417.5","0","0","0"],["104417.2","0.00741708","0","2"],["104416.7","0","0","0"],["104416","0.08604039","0","1"],["104415.8","0","0","0"],["104414.8","0.00862458","0","1"],["104412.5","0.15323771","0","1"],["104412.4","0","0","0"],["104412.3","0","0","0"],["104411","0","0","0"],["104410.9","0","0","0"],["104410.5","0.18924533","0","2"],["104408.4","0.16229695","0","1"],["104408.2","0.10227281","0","2"],["104404.6","0.32592368","0","2"],["104401.1","0","0","0"],["104399","0.06022355","0","1"],["104398.3","0.13882401","0","1"],["104329.5","0","0","0"],["104329.1","0.00006852","0","2"],["104329","0.00063224","0","1"]],"ts":"1747170448000","checksum":-230261358,"seqId":54226342503,"prevSeqId":54226342224}]}
{"arg":{"channel":"books","instId":"BTC-USDT"},"action":"update","data":[{"asks":[["104428.1","1.29425712","0","25"],["104431.7","0.00152861","0","1"],["104433.3","0","0","0"],["104435.1","0.10029141","0","1"],["104435.5","0.12661909","0","2"],["104436.4","0.00478682","0","1"],["104436.5","0.09246914","0","1"],["104437.1","0.50080477","0","3"],["104437.6","0.0981458","0","4"],["104438.8","0","0","0"],["104440","0.16219102","0","3"],["104440.5","0.15311113","0","1"],["104440.6","0.1595546","0","1"],["104441.7","0.04184046","0","1"],["104443.4","0.15830621","0","1"],["104443.8","0.23470433","0","1"],["104445.4","0.13882478","0","1"],["104445.5","0.25948254","0","1"],["104446","0","0","0"],["104446.1","0.473658","0","2"],["104446.3","0.075","0","2"],["104449.6","0.23379321","0","1"],["104450.5","0.23531","0","5"],["104451.8","0.039","0","1"],["104453.6","0.00287194","0","1"],["104453.7","0.00287194","0","1"],["104454.7","0.03987675","0","1"],["104455.9","0.063","0","2"],["104466.8","0","0","0"],["104467.4","0.00014018","0","1"],["104490.6","0.01527715","0","1"],["104622.1","0","0","0"],["104623.3","0","0","0"],["104623.4","0","0","0"],["104623.5","0","0","0"],["104625","0","0","0"],["104625.7","0","0","0"],["104626.4","0","0","0"],["104627.2","0","0","0"],["104628","0","0","0"],["104628.8","0","0","0"],["104629.5","0","0","0"]],"bids":[["104428","0.08504314","0","4"],["104420.7","0.00030064","0","1"],["104420.6","0.07634984","0","1"],["104420.4","0.03364541","0","1"],["104420.3","0","0","0"],["104420.2","0.0005","0","1"],["104418","0","0","0"],["104417.6","0.00957333","0","1"],["104417.2","0.00262999","0","1"],["104416.7","0.00478711","0","1"],["104416","0.18372095","0","2"],["104415","0.40708536","0","2"],["104414.6","0.09534222","0","1"],["104414.1","0.13856879","0","2"],["104413.9","0.00926752","0","1"],["104413.1","0.15812915","0","1"],["104412.5","0.35583209","0","2"],["104411.2","0.77866876","0","1"],["104411","0.1562938","0","1"],["104410.5","0.18971283","0","2"],["104408.8","0.28507505","0","2"],["104408.4","0.14932634","0","1"],["104408.3","0.00017567","0","1"],["104406","0.2554455","0","1"],["104404.9","0","0","0"],["104404.6","0.27713359","0","2"],["104404","0.00489242","0","3"],["104403.1","0.24874014","0","1"],["104402.1","0.25402382","0","1"],["104398.3","0","0","0"],["104397.5","0.13882478","0","1"],["104377.2","0.00068147","0","3"],["104376.3","0.77866876","0","1"],["104349.2","0.00056666","0","1"],["104348.3","0","0","0"],["104331.5","0","0","0"],["104331.1","0","0","0"],["104330.8","0","0","0"],["104330.4","0","0","0"],["104330","0","0","0"],["104329.9","0","0","0"],["104329.8","0","0","0"],["104329.6","0","0","0"],["104329.4","0","0","0"],["104329.1","0","0","0"],["104329","0","0","0"]],"ts":"1747170448100","checksum":-565203839,"seqId":54226342787,"prevSeqId":54226342503}]}
{"arg":{"channel":"books","instId":"BTC-USDT"},"action":"update","data":[{"asks":[["104426.1","1.34592158","0","21"],["104426.7","0.2895817","0","1"],["104426.8","0.19242972","0","1"],["104426.9","0.00009","0","1"],["104428","0.24","0","1"],["104428.1","0.64659159","0","10"],["104428.9","0.03321234","0","1"],["104431.7","0","0","0"],["104432.2","0.071789","0","1"],["104433.1","0.09283929","0","1"],["104433.5","0.09721538","0","1"],["104433.7","0.00152861","0","1"],["104434.4","0.00478682","0","1"],["104434.5","0.09709243","0","1"],["104435.1","0.09677351","0","1"],["104435.5","0.02999322","0","1"],["104435.6","0.04","0","1"],["104436.4","0","0","0"],["104436.5","0","0","0"],["104437.1","0.29255111","0","1"],["104438","0.14831456","0","1"],["104438.5","0.15184471","0","1"],["104438.6","0.15749939","0","1"],["104439.1","0","0","0"],["104440","0.00030006","0","2"],["104440.5","0","0","0"],["104440.6","0","0","0"],["104441.4","0.16676685","0","1"],["104441.8","0.22914912","0","1"],["104443.4","0","0","0"],["104443.8","0","0","0"],["104444.1","0.29340153","0","3"],["104444.8","0.13882648","0","1"],["104445.4","0","0","0"],["104445.5","0","0","0"],["104446.1","0.234","0","1"],["104446.6","0.01944732","0","1"],["104447.6","0.26890733","0","2"],["104449.6","0","0","0"],["104453.6","0","0","0"],["104453.7","0","0","0"],["104455.9","0","0","0"],["104463","0.39645439","0","3"],["104475.5","0.005","0","1"],["104476.1","0.016","0","1"],["104482.8","0","0","0"],["104486.1","0.00017476","0","1"],["104499.2","0.71073124","0","1"],["104520.3","0.234","0","1"],["104587.5","0.01089602","0","1"],["104617.6","0","0","0"],["104618.1","0","0","0"],["104618.5","0","0","0"],["104620","0","0","0"],["104620.5","0","0","0"]],"bids":[["104428","0","0","0"],["104427.1","0","0","0"],["104426.8","0","0","0"],["104426.2","0","0","0"],["104424.9","0","0","0"],["104422","0.0816","0","1"],["104421","0.0000109","0","1"],["104420.7","0","0","0"],["104420.6","0","0","0"],["104419","0.00030064","0","1"],["104418.3","0.01267897","0","1"],["104417.6","0","0","0"],["104416.7","0","0","0"],["104416.3","0.00957479","0","1"],["104416","0","0","0"],["104415.7","0.00478709","0","1"],["104415.6","0.00957352","0","1"],["104414.6","0","0","0"],["104414.1","0.04016601","0","1"],["104414","0.18275885","0","2"],["104413.1","0","0","0"],["104412.6","0.09791216","0","1"],["104412.5","0.19242972","0","1"],["104412.1","0.09016168","0","1"],["104411.1","0.15278935","0","1"],["104411","0","0","0"],["104410.5","0.24950164","0","2"],["104409","0.14991967","0","1"],["104408.8","0.03","0","1"],["104408.4","0","0","0"],["104406.8","0.25284324","0","1"],["104406.4","0.15168014","0","1"],["104406","0","0","0"],["104404.9","0.21150927","0","1"],["104404.6","0","0","0"],["104404","0.0001056","0","2"],["104403.1","0","0","0"],["104402.4","0.00478682","0","1"],["104402.1","0","0","0"],["104401.6","0","0","0"],["104401.1","0.24021299","0","1"],["104401","0.00023525","0","1"],["104400.1","0.23788569","0","1"],["104397.5","0","0","0"],["104396.5","0.13882648","0","1"],["104390.2","0.02872437","0","1"],["104381.8","0","0","0"],["104374.9","0.00137841","0","3"],["104369.4","0.00001","0","1"],["104368.1","0","0","0"],["104366.7","0","0","0"],["104365.1","0","0","0"],["104364.1","0.04787395","0","1"],["104362.9","0.0022","0","1"],["104362","0","0","0"],["104360.8","0","0","0"],["104358.2","0","0","0"],["104346.7","0","0","0"],["104341.6","0.01067647","0","3"],["104340.1","0.01053377","0","1"],["104338.3","0.01053377","0","1"],["104331.5","0.02179229","0","2"],["104331.1","0.01151984","0","2"],["104330.8","0.00005735","0","1"],["104330.4","0.000015","0","1"],["104330","0.00356554","0","4"]],"ts":"1747170448200","checksum":298497045,"seqId":54226343166,"prevSeqId":54226342787}]}
{"arg":{"channel":"books","instId":"BTC-USDT"},"action":"update","data":[{"asks":[["104426.1","1.33739898","0","21"],["104428.1","0.63883219","0","8"],["104433","0.09105422","0","1"],["104433.1","0","0","0"],["104433.3","0.00152861","0","1"],["104433.5","0.09128812","0","1"],["104433.7","0","0","0"],["104434.4","0.09264453","0","1"],["104434.5","0","0","0"],["104435","0.00478685","0","1"],["104435.1","0.0979849","0","1"],["104437.9","0.16209876","0","1"],["104438","0","0","0"],["104438.5","0.33630473","0","2"],["104438.6","0","0","0"],["104441.3","0.14832101","0","1"],["104441.4","0","0","0"],["104441.7","0.27008638","0","2"],["104441.8","0","0","0"],["104443.5","0.27078509","0","1"],["104444","0.25101343","0","1"],["104444.1","0.05209157","0","2"],["104447.6","0.23967743","0","2"],["104451.8","0","0","0"],["104452.9","0.19530171","0","2"],["104456","0","0","0"],["104457","0.17996783","0","3"],["104458","0.001","0","1"],["104459","0","0","0"],["104480.8","0.1","0","1"],["104483.2","0.0008017","0","1"],["104496.5","0","0","0"],["104617.6","0.4","0","1"],["104617.9","0.234","0","1"]],"bids":[["104420.5","0","0","0"],["104419","0","0","0"],["104418.5","0.00030064","0","1"],["104414","0.09509436","0","1"],["104413.9","0.09776219","0","2"],["104412.6","0.08857979","0","1"],["104412.1","0","0","0"],["104412","0.09087511","0","1"],["104411.1","0","0","0"],["104411","0.1573212","0","1"],["104410.5","0.09497257","0","1"],["104410.4","0.15385311","0","1"],["104409","0.15416364","0","1"],["104406.8","0","0","0"],["104406.7","0.2450335","0","1"],["104406.4","0","0","0"],["104406.3","0.16011305","0","1"],["104404.9","0.33273415","0","2"],["104404","0.25905872","0","3"],["104401.1","0","0","0"],["104401","0.26871564","0","2"],["104400.1","0.2527735","0","1"],["104329.9","0.00001038","0","1"]],"ts":"1747170448300","checksum":-2054744147,"seqId":54226343278,"prevSeqId":54226343166}]}
{"arg":{"channel":"books","instId":"BTC-USDT"},"action":"update","data":[{"asks":[["104426.1","1.34227898","0","23"],["104426.9","0","0","0"],["104428.9","0","0","0"],["104433","0","0","0"],["104433.3","0.0936241","0","2"],["104433.5","0","0","0"],["104433.7","0.09615949","0","1"],["104434.4","0","0","0"],["104434.7","0.09624857","0","1"],["104435.1","0","0","0"],["104435.3","0.12048598","0","2"],["104437.9","0","0","0"],["104438.2","0.15209261","0","1"],["104438.5","0","0","0"],["104438.7","0.14907076","0","1"],["104438.8","0.16240055","0","1"],["104441.3","0","0","0"],["104441.6","0.15059808","0","1"],["104441.7","0.04184046","0","1"],["104442","0.23320499","0","1"],["104442.3","0.04184025","0","1"],["104443.5","0","0","0"],["104443.7","0.25803732","0","1"],["104444","0","0","0"],["104444.3","0.24272758","0","1"],["104444.8","0","0","0"],["104445.5","0.13882483","0","1"],["104447.6","0.00478798","0","1"],["104447.8","0.26331143","0","1"],["104533.4","0.00009132","0","1"],["104535.7","0","0","0"]],"bids":[["104426","0.08489","0","3"],["104422.7","0.02372243","0","1"],["104420.5","0.02390883","0","1"],["104419.2","0.00030064","0","1"],["104418.5","0","0","0"],["104418.3","0","0","0"],["104414.2","0.19354273","0","2"],["104414","0","0","0"],["104413.9","0.00926752","0","1"],["104412.8","0.09259801","0","1"],["104412.6","0","0","0"],["104412.3","0.09009555","0","1"],["104412","0","0","0"],["104411.3","0.15842611","0","1"],["104411","0","0","0"],["104410.7","0.15268533","0","1"],["104410.5","0.10163393","0","1"],["104410.4","0","0","0"],["104409.2","0.15965905","0","1"],["104409","0","0","0"],["104407","0.22991202","0","1"],["104406.7","0","0","0"],["104406.6","0.15401906","0","1"],["104406.3","0","0","0"],["104404.9","0.34227184","0","2"],["104404.2","0.26440943","0","2"],["104404","0.0001056","0","2"],["104401.3","0.2727384","0","1"],["104401","0.00023525","0","1"],["104400.3","0.2593525","0","1"],["104400.1","0","0","0"],["104397.5","0.13882483","0","1"],["104396.5","0","0","0"],["104329.9","0","0","0"]],"ts":"1747170448400","checksum":1727318896,"seqId":54226343448,"prevSeqId":54226343278}]}
{"arg":{"channel":"books","instId":"BTC-USDT"},"action":"update","data":[{"asks":[["104433.2","0.00152861","0","1"],["104433.3","0.09209549","0","1"],["104437.1","0.49097244","0","2"],["104617.9","0","0","0"]],"bids":[["104426","0.08491","0","4"],["104410.5","0.21178562","0","2"],["104384.3","0.47399351","0","1"],["104330","0","0","0"]],"ts":"1747170448500","checksum":-1517970306,"seqId":54226343457,"prevSeqId":54226343448}]}
{"arg":{"channel":"books","instId":"BTC-USDT"},"action":"update","data":[{"asks":[["104426.1","1.10827898","0","22"],["104427.9","0.00152861","0","1"],["104433.2","0","0","0"],["104449.1","0.0001303","0","1"],["104451.4","0","0","0"],["104491.8","0.01099581","0","1"],["104494.3","0.01099581","0","1"],["104502.9","0.01099581","0","1"],["104504.7","0.01099581","0","1"],["104556.9","0.01099581","0","1"],["104614.7","0","0","0"],["104615.1","0","0","0"],["104615.3","0","0","0"],["104615.5","0","0","0"],["104617.6","0","0","0"]],"bids":[["104426","0.08517462","0","5"],["104357","0","0","0"],["104355.1","0.00002965","0","1"],["104349.3","0.01132042","0","3"],["104347.3","0.01099581","0","1"],["104343.6","0.08286599","0","3"],["104331","0.01099581","0","1"],["104330.8","0","0","0"],["104330.4","0","0","0"]],"ts":"1747170448600","checksum":1155218649,"seqId":54226343483,"prevSeqId":54226343457}]}
{"arg":{"channel":"books","instId":"BTC-USDT"},"action":"update","data":[{"asks":[["104426.1","1.0862694","0","21"],["104446.5","0.02392809","0","1"],["104586","0.00091079","0","1"],["104612","0","0","0"]],"bids":[["104415.7","0.00478713","0","1"]],"ts":"1747170448700","checksum":-450058789,"seqId":54226343493,"prevSeqId":54226343483}]}
{"arg":{"channel":"books","instId":"BTC-USDT"},"action":"update","data":[{"asks":[["104426.1","0.7751694","0","19"],["104426.7","0.04167435","0","1"],["104426.8","0","0","0"],["104427.9","0","0","0"],["104428","0","0","0"],["104428.1","0.10689733","0","6"],["104433.3","0","0","0"],["104433.7","0.00152861","0","1"],["104434.1","0.09350281","0","1"],["104434.6","0.09688972","0","1"],["104434.7","0","0","0"],["104435","0","0","0"],["104435.3","0.0300196","0","1"],["104435.6","0.13531724","0","2"],["104436.2","0.09638776","0","1"],["104437","0.00478685","0","1"],["104437.1","0.29255111","0","1"],["104438.2","0","0","0"],["104438.7","0","0","0"],["104438.8","0","0","0"],["104439.1","0.15029104","0","1"],["104439.6","0.31633768","0","2"],["104441.6","0","0","0"],["104442","0","0","0"],["104442.5","0.15665036","0","1"],["104442.8","0.23973302","0","1"],["104443.7","0","0","0"],["104444.3","0","0","0"],["104444.6","0.2526635","0","1"],["104445.1","0.26757049","0","1"],["104445.5","0","0","0"],["104447.3","0.13882313","0","1"],["104447.8","0","0","0"],["104448.7","0.25681273","0","1"],["104499.2","0.95863859","0","2"],["104612","0.00011471","0","1"],["104614.7","2.88986","0","1"],["104615.1","0.77866876","0","1"]],"bids":[["104426","0.20467462","0","6"],["104416.4","0.0047871","0","1"],["104415.7","0","0","0"],["104415.1","0.18587023","0","2"],["104414.2","0","0","0"],["104413.7","0.09891014","0","1"],["104413.1","0.09882006","0","1"],["104412.8","0","0","0"],["104412.3","0","0","0"],["104412.1","0.16453006","0","1"],["104411.6","0.20084564","0","3"],["104411.3","0","0","0"],["104410.7","0","0","0"],["104410.5","0.22663901","0","2"],["104410.1","0.16272091","0","1"],["104409.2","0","0","0"],["104407.8","0.26121273","0","1"],["104407.5","0.15240899","0","1"],["104407","0","0","0"],["104406.6","0","0","0"],["104405.1","0.26794616","0","3"],["104404.9","0.33074011","0","2"],["104404.2","0.00008559","0","1"],["104404","0.00489245","0","3"],["104402.4","0","0","0"],["104402.1","0.2390661","0","1"],["104401.3","0","0","0"],["104401.2","0.43892856","0","2"],["104400.3","0","0","0"],["104399.5","0.55500481","0","2"],["104397.5","0","0","0"],["104330.8","0.00005735","0","1"],["104330.4","0.000015","0","1"],["104330","0.00356554","0","4"],["104329.9","0.00001038","0","1"]],"ts":"1747170448800","checksum":251487963,"seqId":54226343586,"prevSeqId":54226343493}]}
{"arg":{"channel":"books","instId":"BTC-USDT"},"action":"update","data":[{"asks":[["104426.1","0.26951756","0","10"],["104426.7","0","0","0"],["104428","0.02221352","0","1"],["104428.1","0.06580861","0","4"],["104431.5","0","0","0"],["104431.7","0.00152861","0","1"],["104433.7","0","0","0"],["104434.1","0","0","0"],["104434.6","0","0","0"],["104435.4","0.03379567","0","1"],["104435.6","0.04","0","1"],["104436.2","0.09052624","0","1"],["104437","0","0","0"],["104437.2","0","0","0"],["104438.4","0.00478685","0","1"],["104438.5","0.005","0","1"],["104439.1","0","0","0"],["104439.5","0","0","0"],["104439.6","0","0","0"],["104439.7","0.14665768","0","1"],["104442","0.19242972","0","1"],["104442.5","0","0","0"],["104442.8","0","0","0"],["104443.1","0.16199143","0","1"],["104444.6","0","0","0"],["104445.1","0","0","0"],["104445.6","0","0","0"],["104447.3","0","0","0"],["104448.7","0","0","0"],["104450","0.13911923","0","3"],["104451","0.005","0","1"],["104457","0.17796783","0","1"],["104458","0","0","0"],["104459","0.002","0","2"],["104460","0.00320843","0","4"],["104479","0","0","0"],["104480","0.00220843","0","3"],["104481","0.33","0","6"],["104482","0.16499999","0","3"],["104535.7","0.18883976","0","1"],["104542.6","0","0","0"],["104615.3","0.29193486","0","1"],["104615.5","0.00001","0","1"],["104617.6","0.4","0","1"],["104618.5","0.01403746","0","1"],["104620","0.00224524","0","3"],["104620.5","0.160778","0","1"],["104622.1","0.06975","0","1"]],"bids":[["104426","0.28854633","0","13"],["104424.5","0.02372201","0","1"],["104424.1","0.05797526","0","1"],["104423.8","0.005","0","1"],["104420.5","0.01525134","0","1"],["104420.4","0","0","0"],["104420.1","0.00031314","0","2"],["104419.2","0","0","0"],["104419","0.00478702","0","1"],["104417.3","0.02508872","0","1"],["104416.4","0","0","0"],["104415.7","0.08617142","0","1"],["104415.1","0","0","0"],["104413.7","0","0","0"],["104413.1","0","0","0"],["104412.9","0","0","0"],["104412.2","0.1516957","0","1"],["104412.1","0","0","0"],["104411.6","0.03775997","0","2"],["104411.3","0.005","0","1"],["104410.5","0","0","0"],["104410.1","0","0","0"],["104408.6","0.16379736","0","3"],["104408.1","0.15991523","0","1"],["104407.8","0","0","0"],["104407.5","0","0","0"],["104405.9","0.00478685","0","1"],["104405.1","0.00003566","0","2"],["104404","0.0001056","0","2"],["104402.4","0.13881917","0","1"],["104402.1","0","0","0"],["104401.2","0.19242972","0","1"],["104399.6","0.36908178","0","1"],["104399.5","0.41618168","0","1"],["104332.9","0.00060713","0","4"],["104329.8","0.07302275","0","4"]],"ts":"1747170448900","checksum":-802117803,"seqId":54226343827,"prevSeqId":54226343586}]}
{"arg":{"channel":"books","instId":"BTC-USDT"},"action":"update","data":[{"asks":[["104428","0.04730224","0","2"],["104431.6","0.00152861","0","1"],["104431.7","0.24","0","1"],["104431.8","0.2552894","0","2"],["104434.7","0.08967851","0","1"],["104435.2","0.09773569","0","1"],["104436.8","0.0996705","0","1"],["104437.1","0.20954006","0","1"],["104440.2","0.31093278","0","2"],["104442.1","0.8360355","0","4"],["104443.4","0.23529806","0","1"],["104443.6","0.03829939","0","1"],["104445.2","0.25946161","0","1"],["104445.6","0.77866876","0","1"],["104445.7","0.80510178","0","2"],["104449.3","0.26200198","0","1"],["104457","0.17996783","0","3"],["104458","0.001","0","1"],["104459","0","0","0"],["104460","0.00220843","0","3"],["104479","0.25999999","0","4"],["104480","0.13220842","0","5"],["104481","0.07","0","2"],["104482","0.035","0","1"],["104537.2","0.12","0","1"],["104563.8","0.00001","0","1"],["104610","0","0","0"],["104610.2","0","0","0"],["104612","0","0","0"],["104614.7","0","0","0"],["104615.1","0","0","0"],["104615.3","0","0","0"],["104615.5","0","0","0"],["104617.6","0","0","0"],["104618.5","0","0","0"],["104620","0","0","0"],["104620.5","0","0","0"],["104622.1","0","0","0"]],"bids":[["104426","0.28855633","0","14"],["104424.1","0","0","0"],["104420.1","0.0000125","0","1"],["104419.5","0.00030064","0","1"],["104419","0","0","0"],["104418.5","0.00478684","0","1"],["104415.7","0.1775509","0","2"],["104414.3","0.09880014","0","1"],["104413.7","0.1023003","0","1"],["104412.7","0.16291786","0","1"],["104410.7","0.15373903","0","1"],["104408.6","0.2392446","0","4"],["104408.4","0.259995","0","1"],["104405.9","0","0","0"],["104405.7","0.27065406","0","1"],["104405","0.00478685","0","1"],["104402.7","0.24710552","0","1"],["104402.4","0","0","0"],["104401.8","0.25820636","0","1"],["104401.3","0.1388194","0","1"],["104331.5","0","0","0"],["104331.1","0","0","0"],["104331","0","0","0"],["104330.8","0","0","0"],["104330.4","0","0","0"],["104330","0","0","0"],["104329.9","0","0","0"],["104329.8","0","0","0"]],"ts":"1747170449000","checksum":-878398629,"seqId":54226343892,"prevSeqId":54226343827}]}
{"arg":{"channel":"books","instId":"BTC-USDT"},"action":"update","data":[{"asks":[["104426.1","0.28608422","0","12"],["104428","0.10254305","0","3"],["104428.1","0.06524195","0","3"],["104430.6","0.00152861","0","1"],["104430.7","0.19242972","0","1"],["104431.6","0","0","0"],["104431.8","0.26566108","0","2"],["104432.6","0.03321119","0","1"],["104434.6","0.09686599","0","1"],["104434.7","0","0","0"],["104435.1","0.08916637","0","1"],["104435.2","0","0","0"],["104436","0.08596622","0","1"],["104436.2","0","0","0"],["104436.7","0.09809606","0","1"],["104436.8","0","0","0"],["104437.1","0.27702829","0","2"],["104439.5","0.15288183","0","1"],["104439.7","0","0","0"],["104440.1","0.37244754","0","4"],["104440.2","0","0","0"],["104441.7","0","0","0"],["104442.9","0.15486127","0","1"],["104443.1","0","0","0"],["104443.3","0.25795201","0","1"],["104443.4","0","0","0"],["104445.1","0.24887548","0","1"],["104445.2","0","0","0"],["104445.6","1.05239762","0","2"],["104445.7","0.56595","0","1"],["104447.6","0.14360989","0","2"],["104449.2","0.29713671","0","2"],["104449.3","0","0","0"],["104450","0.00030006","0","2"],["104455.2","0.00056666","0","1"],["104456.1","0","0","0"],["104610","0.29270107","0","3"]],"bids":[["104426","0.26187633","0","13"],["104424.5","0","0","0"],["104421.3","0.03074699","0","1"],["104418.5","0","0","0"],["104417.5","0.0047868","0","1"],["104415.7","0","0","0"],["104415.6","0.11135913","0","2"],["104415.5","0.08812823","0","1"],["104414.3","0","0","0"],["104414.2","0.09725767","0","1"],["104414.1","0","0","0"],["104413.7","0","0","0"],["104413.6","0.10202773","0","2"],["104412.7","0","0","0"],["104412.6","0.16371245","0","1"],["104412.2","0","0","0"],["104412","0.14728545","0","1"],["104410.7","0","0","0"],["104410.6","0.16660605","0","1"],["104410.2","0.03988961","0","1"],["104408.6","0.23668953","0","4"],["104408.4","0","0","0"],["104408.3","0.26047012","0","2"],["104408.1","0","0","0"],["104407.9","0.14904408","0","2"],["104405.7","0","0","0"],["104405.6","0.25214564","0","1"],["104404.9","0.3435911","0","2"],["104402.7","0","0","0"],["104402.6","0.26671922","0","1"],["104401.8","0","0","0"],["104401.7","0.26646923","0","1"],["104401.3","0","0","0"],["104400.1","0.13882191","0","1"],["104384.3","0","0","0"],["104383.9","0","0","0"],["104383.8","0.00016733","0","2"],["104377.2","0.00011481","0","2"],["104372.5","0.00058698","0","2"],["104361.5","0.44720381","0","1"],["104352.5","0.00005069","0","1"],["104349.2","0","0","0"],["104343.4","0.00087378","0","3"],["104331.5","0.02179229","0","2"],["104331.1","0.01151984","0","2"],["104331","0.01099581","0","1"],["104330.8","0.00005735","0","1"],["104330.4","0.000015","0","1"]],"ts":"1747170449100","checksum":952626444,"seqId":54226344030,"prevSeqId":54226343892}]}
{"arg":{"channel":"books","instId":"BTC-USDT"},"action":"update","data":[{"asks":[["104426.1","0.29757622","0","13"],["104435.4","0","0","0"],["104436","0","0","0"],["104436.1","0.09092561","0","1"],["104436.7","0.09831188","0","1"],["104439.5","0","0","0"],["104439.6","0.15562299","0","1"],["104445","0.04185417","0","2"],["104447.6","0.00478798","0","1"],["104449.1","0.13895146","0","2"],["104449.2","0.28164757","0","2"],["104456","0.002","0","2"],["104457","0.17896783","0","2"],["104458","0","0","0"],["104478","0.26","0","4"],["104479","0.12999999","0","2"],["104480","0.00220843","0","3"]],"bids":[["104425.4","0.02372182","0","1"],["104421.3","0","0","0"],["104417.5","0.00478694","0","1"],["104415.6","0.19763383","0","3"],["104415.5","0","0","0"],["104414.2","0.09397102","0","1"],["104412.1","0.16261292","0","1"],["104412","0","0","0"],["104401.7","0.26046149","0","1"],["104400.8","0.13882116","0","1"],["104400.1","0","0","0"],["104330","0.00356554","0","4"]],"ts":"1747170449200","checksum":601681249,"seqId":54226344101,"prevSeqId":54226344030}]}
{"arg":{"channel":"books","instId":"BTC-USDT"},"action":"update","data":[{"asks":[["104426.1","0.28157622","0","12"],["104434.6","0","0","0"],["104434.7","0.09288468","0","1"],["104439.3","0.0194513","0","1"],["104440.1","0.21238125","0","3"],["104440.2","0.1624681","0","1"],["104442.1","0.84082357","0","5"],["104442.9","0","0","0"],["104443","0.16440111","0","1"],["104443.3","0","0","0"],["104443.4","0.25861885","0","1"],["104445.6","0.77866876","0","1"],["104445.7","0.81898872","0","2"],["104452","0","0","0"],["104478","0.33","0","6"],["104479","0.16499999","0","3"],["104480","0.00221843","0","4"],["104481","0","0","0"],["104482","0","0","0"],["104510","0.00028006","0","1"],["104610.2","0.027","0","1"]],"bids":[["104417.6","0.00478694","0","1"],["104417.5","0","0","0"],["104413.7","0.09652204","0","1"],["104413.6","0.000015","0","1"],["104412.7","0.16463845","0","1"],["104412.6","0","0","0"],["104408.6","0.21955062","0","4"],["104408.4","0.23110961","0","1"],["104408.3","0.00017567","0","1"],["104408","0.1503659","0","1"],["104407.9","0.00002454","0","1"],["104402.7","0.25385774","0","1"],["104402.6","0","0","0"],["104381.8","1.37104","0","1"],["104350.5","2.51745916","0","5"],["104331","0","0","0"],["104330.8","0","0","0"],["104330.4","0","0","0"],["104330","0","0","0"]],"ts":"1747170449300","checksum":715338276,"seqId":54226344170,"prevSeqId":54226344101}]}
{"arg":{"channel":"books","instId":"BTC-USDT"},"action":"update","data":[{"asks":[["104428","0.20636248","0","2"],["104431.6","0.36908178","0","1"],["104432.6","0","0","0"],["104432.8","0.03321111","0","1"],["104434.6","0.10085637","0","1"],["104434.7","0","0","0"],["104435.9","0.03424552","0","2"],["104440.1","0.36484532","0","4"],["104440.2","0","0","0"],["104442.3","0","0","0"],["104442.9","0.16663871","0","1"],["104443","0","0","0"],["104443.3","0.25049942","0","1"],["104443.4","0","0","0"],["104445.6","1.03589595","0","2"],["104445.7","0.56595","0","1"],["104447.3","0.13882308","0","1"],["104449.1","0.0001303","0","1"],["104456","0","0","0"],["104457","0.17996783","0","3"],["104458","0.001","0","1"],["104478","0","0","0"],["104479","0.32999999","0","6"],["104480","0.16721842","0","7"],["104612","0.00011471","0","1"]],"bids":[["104425.4","0","0","0"],["104422.2","0","0","0"],["104421.5","0.03074694","0","1"],["104420.1","0","0","0"],["104419.5","0","0","0"],["104419.2","0.00030064","0","1"],["104419.1","0","0","0"],["104417.6","0","0","0"],["104417.5","0.00478699","0","1"],["104415","0.07979187","0","1"],["104413.7","0","0","0"],["104413.6","0.09037274","0","2"],["104412.7","0","0","0"],["104412.6","0.16352647","0","1"],["104412.5","0","0","0"],["104411.2","0","0","0"],["104408.6","0.11389533","0","3"],["104408.4","0","0","0"],["104408.3","0.23836168","0","1"],["104408","0","0","0"],["104407.9","0.14683883","0","2"],["104402.7","0","0","0"],["104402.6","0.24463109","0","1"],["104400.8","0","0","0"],["104399.6","0","0","0"],["104399.5","0.55500476","0","2"],["104331","0.01099581","0","1"],["104330.8","0.00005735","0","1"],["104330.4","0.000015","0","1"],["104330","0.00356554","0","4"],["104329.9","0.00001038","0","1"],["104329.8","0.07302275","0","4"],["104329.6","0.00001647","0","1"],["104329.4","0.0002877","0","1"],["104329.1","0.00006852","0","2"],["104329","0.00063224","0","1"]],"ts":"1747170449400","checksum":-923179865,"seqId":54226344236,"prevSeqId":54226344170}]}
{"arg":{"channel":"books","instId":"BTC-USDT"},"action":"update","data":[{"asks":[["104432.8","0","0","0"],["104442.9","0","0","0"],["104443","0.16700771","0","1"],["104445.8","0.04183884","0","1"],["104514.9","0","0","0"],["104517","0.0478518","0","1"],["104518.1","0.831818","0","1"],["104523.3","0","0","0"],["104614.7","2.88986","0","1"],["104615.1","0.77866876","0","1"]],"bids":[["104424.6","0.02973238","0","3"],["104421.5","0","0","0"],["104419.2","0","0","0"],["104418.3","0.00030064","0","1"],["104418.2","0.03441468","0","2"],["104417.5","0","0","0"],["104412.2","0.19242972","0","1"],["104410.7","0.77866876","0","1"],["104408.6","0.22060806","0","4"],["104408","0.16115374","0","1"],["104407.9","0.00002454","0","1"],["104393.6","0.0000125","0","1"],["104391.5","0.0000125","0","1"],["104390.5","0.19244222","0","2"],["104385.3","0.00020455","0","3"],["104329.4","0","0","0"],["104329.1","0","0","0"],["104329","0","0","0"]],"ts":"1747170449500","checksum":1819310204,"seqId":54226344331,"prevSeqId":54226344236}]}
{"arg":{"channel":"books","instId":"BTC-USDT"},"action":"update","data":[{"asks":[["104491.9","0.39357714","0","5"],["104494","0.01436422","0","1"],["104495.1","0.00957615","0","1"],["104500.3","0.00958615","0","2"],["104614.7","0","0","0"],["104615.1","0","0","0"]],"bids":[],"ts":"1747170449600","checksum":1819310204,"seqId":54226344351,"prevSeqId":54226344331}]}
{"arg":{"channel":"books","instId":"BTC-USDT"},"action":"update","data":[{"asks":[["104436.7","0.09832188","0","2"],["104438.4","0","0","0"],["104440","0.00508691","0","3"],["104447.3","0","0","0"],["104449.1","0.13895077","0","2"],["104479","0.33","0","6"],["104614.7","2.88986","0","1"],["104615.1","0.77866876","0","1"]],"bids":[["104414.8","0","0","0"],["104408.4","0.00478685","0","1"],["104405","0","0","0"],["104401.3","0.13882047","0","1"],["104399.5","0.41618168","0","1"]],"ts":"1747170449700","checksum":-1170921066,"seqId":54226344412,"prevSeqId":54226344351}]}
{"arg":{"channel":"books","instId":"BTC-USDT"},"action":"update","data":[{"asks":[["104440","0.00030006","0","2"],["104441.1","0.00478685","0","1"],["104446.5","0","0","0"],["104457","0.17796783","0","1"],["104458","0","0","0"],["104459","0.002","0","2"],["104460","0.00320843","0","4"],["104479","0","0","0"],["104480","0.00221843","0","4"],["104481","0.33","0","6"],["104482","0.16499999","0","3"],["104615.1","0","0","0"]],"bids":[["104426","0.26342927","0","14"]],"ts":"1747170449800","checksum":-391320402,"seqId":54226344489,"prevSeqId":54226344412}]}
{"arg":{"channel":"books","instId":"BTC-USDT"},"action":"update","data":[{"asks":[["104426.1","0.27008422","0","11"],["104434.6","0","0","0"],["104434.7","0.10031998","0","1"],["104435.1","0","0","0"],["104435.2","0.09458944","0","1"],["104437.1","0.28295207","0","2"],["104440.1","0.05209157","0","2"],["104440.2","0.32187667","0","2"],["104443.3","0","0","0"],["104443.4","0.25168935","0","1"],["104445.1","0","0","0"],["104445.2","0.237668","0","1"],["104445.6","0.77866876","0","1"],["104445.7","0.83961169","0","2"],["104614.7","0","0","0"]],"bids":[["104415.7","0.09734465","0","1"],["104415.6","0.09584822","0","2"],["104415","0.21733267","0","2"],["104413.7","0.10094399","0","1"],["104413.6","0.000015","0","1"],["104412.7","0.15460778","0","1"],["104412.6","0","0","0"],["104410.8","0.56114653","0","2"],["104410.7","0.93412773","0","2"],["104410.6","0","0","0"],["104408.6","0.0008379","0","2"],["104408.4","0.26573804","0","2"],["104408.3","0","0","0"],["104405.7","0.26501202","0","1"],["104405.6","0","0","0"],["104402.7","0.25270781","0","1"],["104402.6","0","0","0"],["104341.4","0","0","0"],["104331.1","0.000018","0","1"],["104329.4","0.0002877","0","1"]],"ts":"1747170449900","checksum":-896071656,"seqId":54226344578,"prevSeqId":54226344489}]}
{"arg":{"channel":"books","instId":"BTC-USDT"},"action":"update","data":[{"asks":[["104430.5","0.00152861","0","1"],["104430.6","0","0","0"],["104441.1","0","0","0"],["104442.9","0.00478685","0","1"],["104449.1","0.0001303","0","1"],["104451.4","0.13881773","0","1"],["104457","0.17996783","0","3"],["104458","0.001","0","1"],["104459","0","0","0"],["104460","0.00220843","0","3"],["104479","0.33","0","6"],["104480","0.16721842","0","7"],["104481","0","0","0"],["104482","0","0","0"]],"bids":[["104426","0.26343927","0","15"],["104424.1","0.05797151","0","1"],["104419.5","0.00478699","0","1"],["104419","0.00030064","0","1"],["104418.3","0","0","0"],["104418.2","0.02962768","0","1"],["104410.3","0.00483685","0","2"],["104408.4","0.26095119","0","1"],["104403.5","0.13881773","0","1"],["104401.3","0","0","0"],["104399.6","0.36908178","0","1"],["104386.4","0.00287405","0","1"],["104344.8","0","0","0"],["104330.3","0.00173904","0","1"],["104329.9","0","0","0"],["104329.8","0","0","0"],["104329.6","0","0","0"],["104329.4","0","0","0"]],"ts":"1747170450000","checksum":1162936299,"seqId":54226344638,"prevSeqId":54226344578}]}
