{"arg":{"channel":"books","instId":"BTC-USDT"},"action":"update","data":[{"asks":[["104576.5","0","0","0"],["104576.7","0","0","0"],["104578","0","0","0"],["104578.6","0.0238615","0","1"],["104578.7","0.0731","0","2"],["104580","0.00220843","0","3"],["104580.5","0","0","0"],["104584","0.0816","0","1"],["104584.3","0.00044","0","1"],["104585.8","0","0","0"],["104586","0","0","0"],["104586.1","0","0","0"],["104586.2","0","0","0"],["104586.6","0","0","0"],["104587","0","0","0"],["104587.6","0","0","0"],["104587.7","0.00068735","0","2"],["104588.2","0","0","0"],["104589.2","0","0","0"],["104589.5","0.09201195","0","1"],["104590","0.09613468","0","3"],["104590.4","0","0","0"],["104590.8","0","0","0"],["104590.9","0.09537238","0","1"],["104591.1","0.01","0","2"],["104591.5","0.09325932","0","1"],["104591.6","0.00365958","0","2"],["104592.1","0.00478099","0","1"],["104593.3","0.37054255","0","1"],["104594.4","0.14388296","0","1"],["104594.5","0","0","0"],["104594.8","0.00093","0","1"],["104595","0.31717538","0","2"],["104596.6","0.4154129","0","2"],["104597","0.05317087","0","1"],["104597.1","0","0","0"],["104597.8","0.14679842","0","1"],["104598.2","0.24182448","0","1"],["104599.4","0","0","0"],["104600","0.25965295","0","6"],["104600.5","0.26827464","0","1"],["104600.7","0.129","0","4"],["104602.9","0.00477988","0","1"],["104603.4","0.01","0","1"],["104604","0.26590174","0","1"],["104609.6","0","0","0"],["104612.1","0.13860407","0","1"],["104616","0","0","0"],["104617","0","0","0"],["104619","0.002","0","2"],["104620","0.00320843","0","4"],["104629.2","0.09562","0","1"],["104637","0.234","0","1"],["104638","0","0","0"],["104640","0.38420842","0","11"],["104641","0.16499999","0","3"],["104646.3","0.00056666","0","1"],["104658.2","0","0","0"],["104663.5","0","0","0"],["104666.9","6.39798611","0","2"],["104682.9","0.35324587","0","4"],["104742.8","0.00001611","0","1"],["104743.1","0.00011716","0","4"],["104743.5","0.234","0","1"],["104744.3","0.00005567","0","1"],["104744.7","0.00029761","0","1"],["104744.8","0.0000112","0","1"]],"bids":[["104578.5","1.36092366","0","18"],["104578.4","0.29193486","0","1"],["104578","0.0816","0","1"],["104577","0.03235407","0","1"],["104576.6","0.00009","0","1"],["104576.5","0.24","0","1"],["104576.4","0.09046329","0","8"],["104576.2","0","0","0"],["104576.1","0","0","0"],["104575.2","0.0323007","0","1"],["104575","0","0","0"],["104573.9","0","0","0"],["104571.9","0.00001","0","1"],["104571.8","0.06663065","0","1"],["104570.5","0.09812567","0","1"],["104570.4","0.08808978","0","1"],["104570.1","0.00477988","0","1"],["104569.3","0.00115191","0","1"],["104569","0.09850104","0","1"],["104568.5","0.15056773","0","2"],["104567.9","0.00001","0","1"],["104567.5","0.14940696","0","1"],["104567.4","0.01152254","0","2"],["104567.1","0","0","0"],["104566.9","0.16356694","0","1"],["104565.8","0.14344588","0","1"],["104565.7","0","0","0"],["104565.5","0.15616825","0","1"],["104565.1","0","0","0"],["104564.1","0","0","0"],["104563.9","0.13861407","0","2"],["104563.6","0.071712","0","1"],["104563.2","0.23617062","0","1"],["104562.8","0.16288358","0","1"],["104562.1","0","0","0"],["104560.8","0.48379028","0","3"],["104560.2","0","0","0"],["104560.1","0.38863185","0","1"],["104559.8","0","0","0"],["104559.5","0","0","0"],["104557.5","0.24228506","0","1"],["104557.1","0","0","0"],["104556.5","0.24098953","0","1"],["104556","0.00001","0","1"],["104554.1","0.19242972","0","1"],["104553.2","0","0","0"],["104552","0.00383585","0","2"],["104453.1","0","0","0"],["104419.4","0","0","0"],["104418.9","0","0","0"],["104418.4","0","0","0"],["104418.1","0","0","0"]],"ts":"1747170023500","checksum":702114856,"seqId":54226046387,"prevSeqId":54226045990}]}
{"arg":{"channel":"books","instId":"BTC-USDT"},"action":"update","data":[{"asks":[["104578.6","0.0239515","0","2"],["104578.7","0.002","0","1"],["104587.7","0.00001","0","1"],["104588.3","0.00067735","0","1"],["104588.4","0.30495409","0","2"],["104589.2","0.77866876","0","1"],["104589.5","0","0","0"],["104590","0.00029006","0","2"],["104590.2","0.09850505","0","1"],["104590.7","0.09077202","0","1"],["104590.9","0","0","0"],["104591.5","0","0","0"],["104591.7","0.08583603","0","1"],["104592.3","0.09295078","0","1"],["104594.4","0","0","0"],["104595","0","0","0"],["104595.2","0.18029235","0","2"],["104595.7","0.31288115","0","2"],["104597.8","0","0","0"],["104598.2","0","0","0"],["104598.6","0.2638008","0","4"],["104598.9","0","0","0"],["104599","0.2411034","0","1"],["104600","0.00698629","0","5"],["104600.5","0.00477988","0","1"],["104600.7","0.37934424","0","5"],["104601.2","0.44342662","0","2"],["104602.2","0.10408","0","1"],["104602.9","0","0","0"],["104604","0","0","0"],["104604.8","0.25540345","0","1"],["104609.6","0.13860761","0","1"],["104612.1","0","0","0"],["104617","0.002","0","2"],["104618","0.001","0","1"],["104619","0","0","0"],["104620","0.00220843","0","3"],["104623","0","0","0"],["104631.3","0","0","0"],["104633.4","0.653934","0","2"],["104642.8","0","0","0"],["104643.7","0.00175266","0","1"],["104663.5","6.38746715","0","1"],["104666.9","0.01051896","0","1"]],"bids":[["104578.5","0.60957133","0","18"],["104576.7","0.00291134","0","1"],["104576.6","0.21994824","0","2"],["104576.5","0.24521633","0","2"],["104576.4","0.07608227","0","6"],["104572.4","0.00115191","0","1"],["104571.8","0.24083755","0","2"],["104571.2","0.19273845","0","2"],["104570.5","0","0","0"],["104570.4","0","0","0"],["104570.1","0","0","0"],["104569.8","0.08999279","0","1"],["104569.3","0","0","0"],["104569.2","0.09309008","0","1"],["104569","0","0","0"],["104568.7","0.00477988","0","1"],["104568.5","0.05244735","0","1"],["104568.2","0.16635719","0","1"],["104567.7","0.15857701","0","1"],["104567.5","0","0","0"],["104566.9","0","0","0"],["104566.2","0.16169213","0","1"],["104565.8","0.28677421","0","2"],["104565.5","0","0","0"],["104564","0.25121208","0","1"],["104563.9","0.00001","0","1"],["104563.6","0.22567908","0","2"],["104563.2","0","0","0"],["104562.8","0","0","0"],["104562.1","0.13860761","0","1"],["104561.2","0.25826845","0","1"],["104560.8","0.65284164","0","4"],["104558.2","0.2504507","0","1"],["104557.5","0","0","0"],["104557.3","0.29662527","0","3"],["104556.5","0","0","0"],["104464.3","0.00063717","0","1"],["104462.4","0.00001501","0","1"],["104457.2","0.25639742","0","2"],["104455.6","0","0","0"],["104420","0","0","0"]],"ts":"1747170023600","checksum":63037296,"seqId":54226046554,"prevSeqId":54226046387}]}
{"arg":{"channel":"books","instId":"BTC-USDT"},"action":"update","data":[{"asks":[["104580","0.08380843","0","4"],["104586.2","0.03127563","0","1"],["104586.3","0.19242972","0","1"],["104588.4","0.50934171","0","3"],["104589.2","0.8749035","0","2"],["104589.4","0","0","0"],["104589.7","0.09450031","0","1"],["104590.2","0","0","0"],["104590.5","0.02256561","0","1"],["104590.6","0.08648514","0","1"],["104590.7","0","0","0"],["104591.2","0.09117583","0","2"],["104591.7","0","0","0"],["104592.3","0","0","0"],["104593.3","0.57440922","0","2"],["104594.1","0.15144314","0","1"],["104594.7","0.31327345","0","2"],["104595.2","0.02812301","0","1"],["104595.6","0.01912993","0","2"],["104595.7","0","0","0"],["104597","0","0","0"],["104597.5","0.19772448","0","2"],["104597.9","0.24560057","0","1"],["104598.6","0.11177788","0","3"],["104598.9","0.00477988","0","1"],["104599","0","0","0"],["104599.7","0.25817119","0","1"],["104600.2","0.24806501","0","1"],["104600.5","0","0","0"],["104600.7","0.129","0","4"],["104601.2","0.1778392","0","1"],["104603.4","0","0","0"],["104603.7","0.25200459","0","1"],["104604.8","0","0","0"],["104615.7","0","0","0"],["104616","0.002","0","2"],["104616.9","0.00013708","0","1"],["104617","0.001","0","1"],["104618","0","0","0"],["104663.5","6.39010945","0","1"],["104684.3","0","0","0"],["104686.4","0.00009403","0","1"],["104744.8","0","0","0"]],"bids":[["104578.5","0.58606694","0","18"],["104577","0","0","0"],["104576.7","0","0","0"],["104576.6","0.14978298","0","1"],["104576.5","0.00521633","0","1"],["104575.5","0.00290959","0","1"],["104572.4","0","0","0"],["104572.1","0.00115191","0","1"],["104571.8","0.21274575","0","2"],["104571.2","0","0","0"],["104570.2","0.09256745","0","1"],["104570.1","0.09093963","0","1"],["104569.8","0","0","0"],["104569.2","0","0","0"],["104568.7","0.09163542","0","1"],["104568.2","0.09566811","0","1"],["104567.7","0","0","0"],["104567.4","0.00001501","0","1"],["104567.2","0.15664691","0","1"],["104566.6","0.14241208","0","1"],["104566.3","0.00477988","0","1"],["104566.2","0","0","0"],["104565.8","0.30552345","0","2"],["104565.2","0.16175535","0","1"],["104564.7","0.05430645","0","1"],["104564","0","0","0"],["104563.6","0.071712","0","1"],["104562.9","0.23696248","0","1"],["104562.5","0.16325642","0","3"],["104562.1","0","0","0"],["104561.2","0","0","0"],["104560.4","0.13860965","0","1"],["104560.2","0.26756711","0","1"],["104558.2","0","0","0"],["104557.3","0.052","0","2"],["104557.2","0.26476611","0","1"],["104556.2","0.24087648","0","1"],["104479.6","0.00009807","0","1"],["104476.6","0","0","0"],["104427.4","0.00095593","0","1"],["104425.1","0","0","0"],["104420.5","0","0","0"],["104420.3","0","0","0"]],"ts":"1747170023700","checksum":1674392562,"seqId":54226046686,"prevSeqId":54226046554}]}
{"arg":{"channel":"books","instId":"BTC-USDT"},"action":"update","data":[{"asks":[["104578.6","0.02388457","0","2"],["104583.9","0.24","0","1"],["104589.2","0.77866876","0","1"],["104589.7","0","0","0"],["104590.6","0","0","0"],["104591.2","0.002","0","1"],["104593.3","0.57020169","0","2"],["104594.1","0","0","0"],["104594.7","0","0","0"],["104597.5","0.036","0","1"],["104597.9","0","0","0"],["104599.7","0","0","0"],["104600.2","0","0","0"],["104603.7","0","0","0"],["104616","0","0","0"],["104617","0.002","0","2"],["104618","0.001","0","1"],["104640","0.38420843","0","11"],["104648.2","0.47514723","0","2"],["104743.5","0","0","0"],["104744.8","0.0000112","0","1"],["104746","0.03","0","1"],["104746.1","0.00453577","0","1"],["104747","0.77866876","0","1"],["104747.2","0.00001055","0","1"],["104748","0.00108568","0","1"],["104748.9","0.03","0","1"],["104749.5","0.000015","0","1"]],"bids":[["104578.5","0.56247255","0","17"],["104576.4","0.07899073","0","7"],["104575.5","0","0","0"],["104571.8","0.22042332","0","2"],["104570.2","0","0","0"],["104570.1","0","0","0"],["104568.7","0","0","0"],["104568.2","0","0","0"],["104567.9","0.011529","0","2"],["104567.2","0","0","0"],["104566.6","0","0","0"],["104566.1","0.25680186","0","1"],["104565.8","0","0","0"],["104565.2","0","0","0"],["104562.9","0","0","0"],["104562.5","0.01","0","2"],["104560.2","0","0","0"],["104557.2","0","0","0"],["104556.2","0","0","0"],["104420.5","0.03","0","1"],["104420.3","0.03","0","1"],["104420","0.00276552","0","3"],["104419.4","0.00003046","0","1"],["104418.9","0.00005586","0","1"],["104418.4","0.0001","0","1"],["104418.1","0.00004752","0","1"],["104417.6","0.01089593","0","1"],["104417.4","0.00012018","0","1"],["104417.1","0.00005919","0","1"],["104417","0.002","0","1"],["104416.6","0.00019387","0","5"]],"ts":"1747170023800","checksum":-492977073,"seqId":54226046865,"prevSeqId":54226046686}]}
{"arg":{"channel":"books","instId":"BTC-USDT"},"action":"update","data":[{"asks":[["104588.9","0.09065218","0","1"],["104589.4","0.09887521","0","1"],["104590.4","0.09555408","0","1"],["104591","0.09937205","0","1"],["104593.3","0.57882021","0","2"],["104593.9","0.15196756","0","1"],["104594.4","0.32501759","0","2"],["104597.3","0.32736088","0","2"],["104597.6","0.26009411","0","1"],["104598.9","0","0","0"],["104599.4","0.2613489","0","1"],["104599.9","0.25172653","0","1"],["104600.5","0.00477988","0","1"],["104603.5","0.33240297","0","2"],["104609.6","0","0","0"],["104612.1","0.13860611","0","1"],["104617","0","0","0"],["104618","0","0","0"],["104619","0.002","0","2"],["104620","0.00320843","0","4"],["104743.5","0.234","0","1"],["104744.7","0","0","0"],["104744.8","0","0","0"],["104746","0","0","0"],["104746.1","0","0","0"],["104747","0","0","0"],["104747.2","0","0","0"],["104748","0","0","0"],["104748.9","0","0","0"],["104749.5","0","0","0"]],"bids":[["104578.5","0.61824989","0","18"],["104577.1","0.03235406","0","1"],["104576.4","0.07804073","0","5"],["104571.8","0.2160783","0","2"],["104569.9","0.18099256","0","2"],["104568.6","0.03459435","0","3"],["104568.5","0.09115264","0","1"],["104567.9","0.10795498","0","3"],["104566.9","0.15847584","0","1"],["104566.4","0.16287763","0","1"],["104566.3","0","0","0"],["104566.1","0.30085923","0","2"],["104565","0.19242972","0","1"],["104564.9","0.22281736","0","2"],["104563.2","0.13860611","0","1"],["104562.6","0.2323531","0","1"],["104562.3","0.16024677","0","1"],["104560.4","0","0","0"],["104559.9","0.29009142","0","4"],["104556.9","0.243942","0","2"],["104556","0.26129798","0","2"],["104418.1","0","0","0"],["104417.6","0","0","0"],["104417.4","0","0","0"],["104417.1","0","0","0"],["104417","0","0","0"],["104416.6","0","0","0"]],"ts":"1747170023900","checksum":-580734696,"seqId":54226046931,"prevSeqId":54226046865}]}
{"arg":{"channel":"books","instId":"BTC-USDT"},"action":"update","data":[{"asks":[["104578.6","0.02389457","0","3"],["104616.9","0","0","0"],["104618.9","0.00013709","0","1"]],"bids":[["104577.2","0.00291231","0","1"],["104576.4","0.07513227","0","4"],["104418.4","0","0","0"]],"ts":"1747170024000","checksum":-739969249,"seqId":54226046938,"prevSeqId":54226046931}]}
{"arg":{"channel":"books","instId":"BTC-USDT"},"action":"update","data":[{"asks":[["104599.3","0.00477988","0","1"],["104600.5","0","0","0"],["104609.6","0.13860823","0","1"],["104612.1","0","0","0"],["104620.1","0","0","0"],["104622.7","0.23456666","0","2"],["104646.3","0","0","0"],["104648.9","0.00056666","0","1"],["104744.7","0.00029761","0","1"]],"bids":[["104578.5","0.61881655","0","19"],["104577.2","0","0","0"],["104576.7","0.00291239","0","1"],["104576.4","0.07456561","0","3"],["104568.6","0.02981447","0","2"],["104567","0.00477988","0","1"],["104563.2","0","0","0"],["104560.9","0.13860823","0","1"],["104553.8","0.00011867","0","1"],["104552.3","0.00056666","0","1"],["104551.1","0.05505123","0","1"],["104550.2","0","0","0"],["104547.7","0.00956045","0","1"],["104546.5","0","0","0"],["104457.5","0.00083754","0","1"],["104457.2","0.25555987","0","1"],["104420","0","0","0"],["104419.4","0","0","0"],["104418.9","0","0","0"]],"ts":"1747170024100","checksum":16525945,"seqId":54226047091,"prevSeqId":54226046938}]}
{"arg":{"channel":"books","instId":"BTC-USDT"},"action":"update","data":[{"asks":[["104578.6","0.01381357","0","3"],["104580.8","0.002","0","1"],["104588.9","0","0","0"],["104589","0.09364904","0","1"],["104589.4","0","0","0"],["104589.5","0.10103175","0","1"],["104590.4","0.09498669","0","1"],["104591","0","0","0"],["104591.1","0.10505056","0","3"],["104593.3","0.57940552","0","3"],["104593.9","0.1471102","0","1"],["104594.4","0","0","0"],["104594.5","0.32940624","0","2"],["104597.3","0.33162313","0","2"],["104597.6","0","0","0"],["104597.7","0.25158493","0","1"],["104599.3","0","0","0"],["104599.4","0.00477988","0","1"],["104599.5","0.50580233","0","2"],["104599.9","0","0","0"],["104600","0.27131794","0","6"],["104603.5","0.071707","0","1"],["104603.6","0.26742079","0","2"],["104609.6","0.13860827","0","1"],["104616.9","0.00013709","0","1"],["104618.9","0","0","0"],["104688.9","0.00001","0","1"],["104701.7","0","0","0"],["104744.8","0.0000112","0","1"],["104746","0.03","0","1"],["104746.1","0.00453577","0","1"]],"bids":[["104576.7","0","0","0"],["104576.6","0.15269636","0","2"],["104572.1","0","0","0"],["104571.8","0.20887543","0","2"],["104570.1","0.00115191","0","1"],["104570","0.18355194","0","3"],["104569.9","0.09694298","0","1"],["104569.4","0.002","0","1"],["104568.6","0.12569263","0","3"],["104568.5","0","0","0"],["104568","0.09316408","0","1"],["104567.9","0.011529","0","2"],["104567.2","0.00477988","0","1"],["104567","0.16077776","0","1"],["104566.9","0","0","0"],["104566.4","0.16335657","0","1"],["104565","0.35290876","0","2"],["104564.9","0.07298372","0","1"],["104562.7","0.2311691","0","1"],["104562.6","0","0","0"],["104562.3","0.16408589","0","1"],["104560.9","0.13860827","0","1"],["104560.8","0.48379028","0","3"],["104560","0.32147038","0","4"],["104559.9","0.05201","0","3"],["104557","0.24531478","0","1"],["104556.9","0.002015","0","2"],["104556.1","0.63872235","0","2"],["104556","0.00001","0","1"],["104422.5","0","0","0"]],"ts":"1747170024200","checksum":-1125092475,"seqId":54226047319,"prevSeqId":54226047091}]}
{"arg":{"channel":"books","instId":"BTC-USDT"},"action":"update","data":[{"asks":[["104578.6","0","0","0"],["104578.7","0","0","0"],["104579.7","0","0","0"],["104580","0","0","0"],["104580.8","0","0","0"],["104581.8","0","0","0"],["104582","0","0","0"],["104582.6","0","0","0"],["104583.7","0","0","0"],["104583.9","0","0","0"],["104584","0","0","0"],["104584.3","0","0","0"],["104585.9","0","0","0"],["104586.2","0","0","0"],["104586.3","0","0","0"],["104587.7","0","0","0"],["104587.8","0","0","0"],["104588.3","0","0","0"],["104588.4","0","0","0"],["104588.5","0","0","0"],["104589","0","0","0"],["104589.2","0","0","0"],["104589.5","0","0","0"],["104589.6","0","0","0"],["104589.7","0.04549978","0","1"],["104590.1","0","0","0"],["104590.4","0","0","0"],["104590.5","0","0","0"],["104591.1","0.01","0","2"],["104591.6","0","0","0"],["104592","0","0","0"],["104592.1","0","0","0"],["104593.3","0.002","0","1"],["104593.5","0","0","0"],["104593.9","0","0","0"],["104594.5","0","0","0"],["104594.6","0","0","0"],["104594.8","0","0","0"],["104595","0.10824967","0","2"],["104595.6","0.00001","0","1"],["104596.5","0.00067735","0","1"],["104596.6","0","0","0"],["104597.3","0","0","0"],["104597.5","0","0","0"],["104597.7","0","0","0"],["104598.4","0","0","0"],["104598.6","0","0","0"],["104599.4","0","0","0"],["104599.5","0","0","0"],["104600","0.00220843","0","3"],["104600.7","0","0","0"],["104601.3","0","0","0"],["104601.4","0.036","0","1"],["104601.7","0.01911879","0","1"],["104602.1","0.036","0","1"],["104602.2","0","0","0"],["104602.3","0","0","0"],["104602.4","0","0","0"],["104603.4","0.03748854","0","1"],["104603.5","0","0","0"],["104603.6","0.00001","0","1"],["104604.3","0.35737958","0","2"],["104605.3","0","0","0"],["104605.8","0","0","0"],["104605.9","0","0","0"],["104606.6","0","0","0"],["104607.4","0.061248","0","2"],["104607.5","0.01001","0","2"],["104608.4","0.00477988","0","1"],["104608.5","0","0","0"],["104608.6","0.033","0","1"],["104609.2","0.1778392","0","1"],["104609.6","0","0","0"],["104610","0.23429006","0","3"],["104610.1","0.18070691","0","2"],["104610.3","0","0","0"],["104610.6","0","0","0"],["104612.3","0.04","0","1"],["104613","0.00001501","0","1"],["104614.4","0.20392526","0","2"],["104615.3","0.0382361","0","1"],["104616.3","0","0","0"],["104617.7","0.1778392","0","1"],["104619","0","0","0"],["104619.3","0.00287","0","1"],["104620","0.00220843","0","3"],["104621.9","0.13859135","0","1"],["104624","0.002","0","2"],["104624.1","0.11163078","0","2"],["104624.2","0","0","0"],["104624.9","0","0","0"],["104625","0.001","0","1"],["104625.7","0.35247023","0","1"],["104625.8","0","0","0"],["104626.1","0","0","0"],["104626.4","0","0","0"],["104627.7","0.00711203","0","1"],["104629.1","0.04544403","0","1"],["104629.2","0","0","0"],["104629.7","0","0","0"],["104633.4","0.553934","0","1"],["104636.7","0","0","0"],["104637.7","0.56647105","0","2"],["104640","0.05420843","0","5"],["104641","0","0","0"],["104641.1","0","0","0"],["104642.9","0","0","0"],["104643","0","0","0"],["104643.4","0.47254317","0","1"],["104645","0.32999999","0","6"],["104646","0.16499999","0","3"],["104646.4","0","0","0"],["104648.2","0.47510595","0","1"],["104648.5","0.01433037","0","1"],["104650.3","0.02866734","0","1"],["104650.4","0","0","0"],["104650.9","0","0","0"],["104654.7","0","0","0"],["104657.1","1.09143275","0","1"],["104658.8","0.38863185","0","1"],["104662.9","0","0","0"],["104663.5","0","0","0"],["104666.9","0","0","0"],["104668.5","0","0","0"],["104676.4","0.0477789","0","1"],["104679.8","0.93932622","0","2"],["104686","0.00009103","0","1"],["104686.4","0","0","0"],["104699","0","0","0"],["104700.9","0.02866074","0","1"],["104703.1","0.39750714","0","1"],["104706.2","0.02141196","0","2"],["104706.7","0.0013452","0","1"],["104712","0.24489674","0","2"],["104716.4","0.01089674","0","1"],["104719.8","0.01089605","0","1"],["104720","0.00232339","0","7"],["104727.6","0.0026904","0","1"],["104747","0.77866876","0","1"],["104747.2","0.00001055","0","1"],["104748","0.00108568","0","1"],["104748.9","0.03","0","1"],["104749.5","0.000015","0","1"],["104749.6","0.00002296","0","1"],["104749.9","0.00021362","0","1"],["104750","0.0294814","0","38"],["104750.5","0.07299861","0","2"],["104750.7","0.00049233","0","7"],["104751.9","0.00001969","0","1"],["104753.2","0.0000358","0","1"],["104753.3","2.3905","0","1"],["104754","0.234","0","1"],["104754.2","0.00089983","0","1"],["104754.7","0.00001","0","1"],["104755","0.00001787","0","1"],["104755.1","0.00010283","0","1"],["104756","0.00001103","0","1"],["104756.8","0.160623","0","1"],["104757.5","0.77866876","0","1"],["104757.6","0.00001017","0","1"],["104757.7","0.00002193","0","1"],["104758","0.00013459","0","1"],["104758.5","0.00003192","0","3"],["104758.6","0.00094804","0","1"],["104758.7","0.00028146","0","4"],["104758.8","0.06976784","0","6"],["104759.3","0.00001392","0","1"],["104760","0.01036163","0","9"],["104760.3","0.00001006","0","1"],["104760.4","0.00478119","0","1"],["104760.5","0.00005057","0","1"],["104760.9","0.00001723","0","1"],["104761.2","0.00001067","0","1"],["104761.3","0.00791791","0","1"],["104761.6","0.00004877","0","1"],["104761.9","0.00001531","0","1"],["104762","0.0000153","0","1"],["104762.2","0.00003969","0","2"],["104762.5","0.00003652","0","1"],["104762.7","0.00001","0","1"],["104763.1","0.00007489","0","6"],["104763.4","0.00055348","0","1"],["104763.6","0.00006891","0","5"],["104763.7","0.00001015","0","1"],["104764.2","0.00023688","0","1"],["104764.7","0.00011932","0","1"],["104766.5","0.07298372","0","1"],["104766.6","0.00531755","0","3"],["104767.6","0.00005059","0","1"]],"bids":[["104587.8","0.37794367","0","10"],["104587.6","0.32206858","0","4"],["104586.7","0.08956","0","1"],["104586.2","0.35469528","0","6"],["104586.1","0.353898","0","15"],["104586","0.0816","0","1"],["104585.8","0.13540726","0","5"],["104584","0.0816","0","1"],["104582.1","0.00955961","0","1"],["104580.3","0.00115191","0","1"],["104580.2","0.27084387","0","1"],["104580","0.00001","0","1"],["104579.9","0.00009","0","1"],["104578.7","0.0075","0","1"],["104578.6","0.24","0","1"],["104578.5","0.3315236","0","6"],["104576.7","0.00477988","0","1"],["104576.6","0.102071","0","1"],["104576.4","0.05251","0","3"],["104576.1","0.28109592","0","2"],["104575.8","0.00001","0","1"],["104575.2","0","0","0"],["104574.1","0.14059135","0","2"],["104572.3","0","0","0"],["104571.8","0.21144439","0","2"],["104571.1","0.00098","0","1"],["104570.1","0","0","0"],["104570","0.08189006","0","3"],["104569.9","0","0","0"],["104568.6","0.02930447","0","1"],["104568.1","0.00005","0","1"],["104568","0","0","0"],["104567.8","0","0","0"],["104567.2","0","0","0"],["104567","0","0","0"],["104566.4","0","0","0"],["104565.9","0.00098","0","1"],["104565","0.19242972","0","1"],["104563.3","0","0","0"],["104563.1","0.052","0","2"],["104562.7","0","0","0"],["104562.3","0","0","0"],["104562","0","0","0"],["104560.9","0","0","0"],["104560.8","0.66162948","0","4"],["104560.7","0.00191","0","1"],["104560","0.00220843","0","3"],["104559.3","0.00382558","0","1"],["104558.1","0","0","0"],["104558","0","0","0"],["104557","0","0","0"],["104556.1","0.38030304","0","1"],["104555.9","0.02867883","0","1"],["104555.4","0.07515","0","2"],["104554.4","0","0","0"],["104554","0.03478075","0","2"],["104552.9","0","0","0"],["104552","0.00001","0","1"],["104551.9","0.02868556","0","1"],["104551.1","0","0","0"],["104547.6","0","0","0"],["104544.1","0.00479075","0","2"],["104542.3","0.01434493","0","1"],["104542.1","0","0","0"],["104541.6","0","0","0"],["104539.9","0","0","0"],["104539.1","0","0","0"],["104534.9","0.0481978","0","1"],["104534.4","0.14665636","0","2"],["104534.3","0","0","0"],["104534","0.48324487","0","1"],["104531.3","0.01778474","0","1"],["104530.7","0","0","0"],["104530.6","0.00287","0","1"],["104529.8","0.04779804","0","1"],["104529","0","0","0"],["104526.7","0.01892131","0","1"],["104525.7","0","0","0"],["104524.1","0","0","0"],["104518","0","0","0"],["104515.5","0","0","0"],["104509.5","0","0","0"],["104491.1","0.01912318","0","1"],["104487.9","0.2298549","0","3"],["104487","0.47439916","0","1"],["104484.5","0.02870138","0","2"],["104482.1","0.0152","0","2"],["104482","0.0304","0","4"],["104471.2","0","0","0"],["104456.7","0.77866876","0","1"],["104455.5","0","0","0"],["104455.4","0.12","0","1"],["104455.3","0","0","0"],["104453.4","0.0013452","0","1"],["104452","0","0","0"],["104443","0.0026904","0","1"],["104425.4","0","0","0"]],"ts":"1747170024300","checksum":-1873937388,"seqId":54226048186,"prevSeqId":54226047319}]}
{"arg":{"channel":"books","instId":"BTC-USDT"},"action":"update","data":[{"asks":[["104587.9","0","0","0"],["104589.3","0","0","0"],["104589.7","0","0","0"],["104590","0","0","0"],["104591.1","0.0809723","0","3"],["104592","0.0816","0","1"],["104594","0.0816","0","1"],["104595","0.06824967","0","1"],["104595.2","0","0","0"],["104596.5","0.06824967","0","1"],["104596.6","0.19242972","0","1"],["104596.7","0","0","0"],["104596.8","0","0","0"],["104598.6","0.04","0","1"],["104599.2","0.02915628","0","1"],["104599.3","0.0026234","0","1"],["104600","0.00288578","0","4"],["104600.1","0.32056439","0","1"],["104600.6","0","0","0"],["104600.8","0.09804896","0","1"],["104601.2","0.27693641","0","2"],["104601.7","0","0","0"],["104602.2","0.08997361","0","1"],["104602.8","0.77866876","0","1"],["104603","0","0","0"],["104603.6","0.30224358","0","3"],["104604.3","0.0000125","0","1"],["104605.2","0.072","0","2"],["104605.7","0.16111512","0","1"],["104606.2","0.1656471","0","1"],["104606.3","0.16758774","0","1"],["104607.2","0.05474469","0","1"],["104607.5","0.00001","0","1"],["104608","0.02812301","0","1"],["104608.4","0","0","0"],["104608.6","0.063","0","2"],["104609.4","0.036","0","1"],["104609.5","0.2312627","0","2"],["104610.1","0.23545011","0","3"],["104610.6","0.3556784","0","2"],["104611.2","0.23766789","0","1"],["104611.8","0.25329611","0","1"],["104613.5","0.10408","0","1"],["104613.8","0.34059972","0","1"],["104613.9","0.26864","0","1"],["104614.4","0","0","0"],["104616.9","0.10421709","0","2"],["104620.2","0.13859328","0","1"],["104620.5","0.05592442","0","1"],["104621.9","0","0","0"],["104624","0","0","0"],["104625","0.002","0","2"],["104626","0.001","0","1"],["104627.7","0","0","0"],["104628.8","0","0","0"],["104630.2","0.00711203","0","1"],["104630.6","0.45563367","0","2"],["104632.1","0","0","0"],["104635.8","1.37356282","0","1"],["104639.2","0","0","0"],["104641.1","0.09830625","0","1"],["104641.6","0.00047806","0","1"],["104643.4","0","0","0"],["104643.7","0","0","0"],["104644.4","0","0","0"],["104645","0","0","0"],["104646","0.32999999","0","6"],["104647","0.16499999","0","3"],["104648.2","0.47514723","0","2"],["104648.6","0","0","0"],["104650.4","0.20869684","0","1"],["104654.9","0.46162111","0","1"],["104655.6","0.00175266","0","1"],["104655.8","0.77071","0","1"],["104656.3","0.0008017","0","1"],["104656.5","0.02868429","0","1"],["104660.9","0.27524805","0","1"],["104662.2","0","0","0"],["104663.6","0","0","0"],["104665.3","0.00080339","0","1"],["104666.2","0","0","0"],["104666.3","0","0","0"],["104667.7","0","0","0"],["104667.8","0.13879618","0","1"],["104670.6","0","0","0"],["104670.8","0.8534245","0","2"],["104683.6","0.01051756","0","1"],["104686.5","0.01053257","0","2"],["104687.5","0.08648149","0","1"],["104689.2","0.01051756","0","1"],["104690.2","0","0","0"],["104693","0.01051756","0","1"],["104693.1","0.71588339","0","4"],["104696.9","0.08963044","0","1"],["104703.1","0","0","0"],["104706.1","0.01369842","0","1"],["104712.8","0","0","0"],["104721.9","0","0","0"],["104732.4","0.01401683","0","1"],["104740.9","0","0","0"],["104751.5","0.01448136","0","1"],["104761.9","0","0","0"],["104762","0","0","0"],["104762.2","0","0","0"],["104762.5","0","0","0"],["104762.7","0","0","0"],["104763.1","0","0","0"],["104763.4","0","0","0"],["104763.6","0","0","0"],["104763.7","0","0","0"],["104764.2","0","0","0"],["104764.7","0","0","0"],["104766.5","0","0","0"],["104766.6","0","0","0"],["104767.6","0","0","0"]],"bids":[["104591","0.69212194","0","16"],["104590.5","0.08956","0","1"],["104590.1","0.06929732","0","1"],["104590","0.00001","0","1"],["104589.9","0.05494026","0","3"],["104589.2","0.08697061","0","5"],["104588","0.0816","0","1"],["104587.9","0.00521603","0","1"],["104587.8","0.052","0","2"],["104587.6","0","0","0"],["104586.8","0.02970531","0","1"],["104586.7","0","0","0"],["104586.2","0","0","0"],["104586.1","0.09426552","0","2"],["104585.8","0.052","0","2"],["104581.8","0.00115191","0","1"],["104581.7","0.1850154","0","2"],["104581.4","0.012","0","1"],["104580.7","0.02930447","0","1"],["104580.3","0","0","0"],["104580","0.00029006","0","2"],["104579.8","0.09585658","0","1"],["104578.8","0.16646904","0","1"],["104578.7","0","0","0"],["104578.4","0.36363886","0","2"],["104578.2","0.14874575","0","1"],["104577.9","0.00001501","0","1"],["104577.2","0.00477977","0","1"],["104576.7","0.1505536","0","1"],["104576.5","0","0","0"],["104576.3","0.00357506","0","1"],["104576.1","0.12611581","0","1"],["104574.1","0.002","0","1"],["104572.1","0.13859328","0","1"],["104572","0.25966271","0","2"],["104571.8","0","0","0"],["104571.7","0.30155373","0","2"],["104568.8","0.24000446","0","1"],["104568.6","0","0","0"],["104566.1","0.26750316","0","2"],["104565.9","0.00809203","0","2"],["104564.6","0.03","0","1"],["104564.5","0.02868385","0","1"],["104563.6","0","0","0"],["104562.9","0.03","0","1"],["104560.4","0.03","0","1"],["104559.3","0","0","0"],["104554.9","0.01016913","0","1"],["104554.8","0.0542","0","3"],["104554","0.06778075","0","3"],["104553.8","0","0","0"],["104551.9","0","0","0"],["104550.5","0","0","0"],["104549","0.46418494","0","1"],["104547.5","0.58728","0","1"],["104546.3","0.093","0","3"],["104537","0.0022","0","1"],["104536.9","0","0","0"],["104535.5","0.00047806","0","1"],["104534.7","0.00094847","0","1"],["104534.5","0.01677865","0","1"],["104529.3","0.43953684","0","1"],["104525.9","0","0","0"],["104516.8","0","0","0"],["104513.9","0","0","0"],["104506.8","0.27932","0","1"],["104491.6","0","0","0"],["104486.1","0.11235666","0","4"],["104480","0.07066151","0","5"],["104474.7","0.00063695","0","1"],["104473.9","0","0","0"],["104467.4","0.00083731","0","1"],["104465","1.42797","0","1"],["104464.6","0","0","0"],["104464.3","0","0","0"],["104457.5","0","0","0"],["104437.7","0","0","0"],["104436.1","0.00478119","0","1"],["104423.5","0","0","0"],["104423","0","0","0"],["104422.9","0","0","0"],["104422.8","0","0","0"],["104422.7","0","0","0"],["104421.8","0","0","0"],["104421.7","0","0","0"],["104421","0","0","0"],["104420.5","0","0","0"],["104420.3","0","0","0"]],"ts":"1747170024400","checksum":1141482554,"seqId":54226048876,"prevSeqId":54226048186}]}
{"arg":{"channel":"books","instId":"BTC-USDT"},"action":"update","data":[{"asks":[["104591.1","0.0810623","0","4"],["104595","0","0","0"],["104596","0.0816","0","1"],["104598.9","0.00044","0","1"],["104599.2","0","0","0"],["104600.8","0","0","0"],["104601","0.02915579","0","1"],["104601.2","0.1778392","0","1"],["104601.3","0.09547221","0","1"],["104602.2","0","0","0"],["104602.8","0.87480315","0","2"],["104603.6","0.17592839","0","2"],["104604.2","0.00093","0","1"],["104605.7","0","0","0"],["104605.8","0.02256561","0","1"],["104606.2","0","0","0"],["104606.3","0.14931133","0","1"],["104607.2","0","0","0"],["104607.6","0.04","0","1"],["104609.1","0.14895295","0","1"],["104609.3","0.00477956","0","1"],["104609.4","0.03693","0","2"],["104609.5","0.0000125","0","1"],["104610.1","0.2325824","0","2"],["104611.2","0","0","0"],["104611.3","0.24426725","0","1"],["104611.8","0","0","0"],["104612.8","0.03","0","1"],["104614.6","0.00191","0","1"],["104615.3","0.28962757","0","2"],["104616.9","0","0","0"],["104619.9","0.00191","0","1"],["104620.2","0","0","0"],["104621.9","0.13859207","0","1"],["104624.9","0.00840847","0","1"],["104628.7","0.00013709","0","1"],["104629.1","0","0","0"],["104630.6","0.22945347","0","1"],["104633.4","0","0","0"],["104641.8","0.09561","0","1"],["104644.5","0.0149663","0","2"],["104644.9","0.09561","0","1"],["104648.1","0.0015523","0","1"],["104648.2","0.47510595","0","1"],["104655.6","0","0","0"],["104656.2","0.00175266","0","1"],["104686","0","0","0"],["104695.6","0.011","0","1"],["104703.1","0.17563583","0","2"],["104704.6","0.00126362","0","1"],["104707","0.00001","0","1"],["104759.3","0","0","0"],["104760","0","0","0"],["104760.3","0","0","0"],["104760.4","0","0","0"],["104760.5","0","0","0"],["104760.9","0","0","0"],["104761.2","0","0","0"],["104761.3","0","0","0"],["104761.6","0","0","0"]],"bids":[["104591","0.79324694","0","19"],["104590.6","0.07822919","0","1"],["104590.5","0","0","0"],["104590.1","0.00293689","0","1"],["104589.9","0.052","0","2"],["104589.6","0.00011836","0","1"],["104589.2","0.07549561","0","4"],["104588.6","0.07298372","0","1"],["104586.1","0.06456","0","1"],["104585.9","0.012","0","1"],["104583.6","0.04019831","0","1"],["104583.2","0.00051","0","1"],["104582.2","0.00115191","0","1"],["104581.8","0.09777341","0","1"],["104581.7","0","0","0"],["104581.4","0","0","0"],["104580.3","0.08765331","0","1"],["104580.2","0.37931392","0","2"],["104579.9","0","0","0"],["104579.8","0","0","0"],["104578.8","0","0","0"],["104578.4","0.40226209","0","3"],["104578.2","0","0","0"],["104577.9","0.00099501","0","2"],["104577.2","0","0","0"],["104577.1","0","0","0"],["104576.9","0.19720928","0","2"],["104576.8","0.36839118","0","2"],["104576.7","0","0","0"],["104576.4","0.052","0","2"],["104576.1","0","0","0"],["104576","0.1216","0","2"],["104574.1","0.15855798","0","2"],["104573.4","0.13859207","0","1"],["104572.7","0.00098","0","1"],["104572.1","0","0","0"],["104572","0.25579766","0","3"],["104571.8","0.24691563","0","1"],["104571.7","0.036","0","1"],["104571.1","0","0","0"],["104568.8","0","0","0"],["104567.8","0.24992676","0","1"],["104566.1","0.15786191","0","1"],["104565.9","0.00711203","0","1"],["104562.4","0.052","0","2"],["104560.9","0.00011866","0","1"],["104560.4","0.06","0","2"],["104546.3","0.063","0","2"],["104534.9","0","0","0"],["104511.9","0","0","0"],["104480.9","0.00010933","0","1"],["104479.6","0","0","0"],["104478.3","0.229486","0","1"],["104477.8","0.00063691","0","1"],["104474.7","0","0","0"],["104465.4","0.12","0","1"],["104447.3","0","0","0"],["104427.4","0.0009559","0","1"]],"ts":"1747170024500","checksum":-1111460359,"seqId":54226049072,"prevSeqId":54226048876}]}
{"arg":{"channel":"books","instId":"BTC-USDT"},"action":"update","data":[{"asks":[["104591.1","0.00979212","0","3"],["104600","0.00220843","0","3"],["104600.1","0","0","0"],["104601","0","0","0"],["104601.1","0.00068985","0","2"],["104601.2","0.49927662","0","2"],["104601.3","0","0","0"],["104603.1","0.0291552","0","1"],["104603.4","0","0","0"],["104603.9","0.02915496","0","1"],["104606.3","0","0","0"],["104610.1","0.1778392","0","1"],["104611","0.071704","0","1"],["104611.3","0","0","0"],["104612.1","0.05474217","0","1"],["104620.5","0","0","0"],["104621.9","0","0","0"],["104623.9","0.00171","0","1"],["104624","0.1385899","0","1"],["104624.7","0","0","0"],["104625.6","0.05592172","0","1"],["104638.6","0","0","0"],["104641.1","0.28496948","0","2"],["104642.8","0.553885","0","1"],["104645.9","0.1","0","1"],["104655","1.00001501","0","2"],["104659.5","0.04749957","0","1"],["104660.8","0.00004128","0","1"],["104695.2","0.07744593","0","2"],["104702.5","0.00010632","0","1"],["104723.4","0.01401505","0","1"],["104758.6","0","0","0"],["104758.7","0","0","0"],["104758.8","0","0","0"]],"bids":[["104591","0.79611488","0","20"],["104590.1","0","0","0"],["104588.8","0.00293857","0","1"],["104588.7","0.03185425","0","1"],["104586.1","0.05973594","0","2"],["104584.1","0.00115191","0","1"],["104583.6","0.04019834","0","1"],["104582.2","0","0","0"],["104581.8","0","0","0"],["104580.2","0.27084387","0","1"],["104578.5","0.32913305","0","5"],["104576.8","0.19926131","0","1"],["104575.5","0.1385899","0","1"],["104573.4","0","0","0"],["104571.8","0","0","0"],["104560.9","0","0","0"],["104560.4","0.123","0","4"],["104557.4","0.04054581","0","1"],["104554.9","0","0","0"],["104554","0.03778075","0","2"],["104547.4","0","0","0"],["104546.3","0","0","0"],["104524.7","0.33393224","0","2"],["104521.3","0.554528","0","1"],["104480.9","0","0","0"],["104430.8","0.00095585","0","1"],["104427.4","0","0","0"],["104426.7","0","0","0"],["104423.5","0.01448485","0","1"],["104423","0.00071959","0","4"],["104422.9","0.01089593","0","1"],["104422.8","0.00094847","0","1"],["104422.7","0.01089657","0","1"]],"ts":"1747170024600","checksum":1304805460,"seqId":54226049167,"prevSeqId":54226049072}]}
{"arg":{"channel":"books","instId":"BTC-USDT"},"action":"update","data":[{"asks":[["104591.1","0.08089212","0","4"],["104595.9","0.24","0","1"],["104601","0.00067735","0","1"],["104601.1","0.03335486","0","2"],["104601.3","0.10070991","0","1"],["104602.5","0.00350449","0","2"],["104603.1","0","0","0"],["104606.3","0.15775515","0","1"],["104609.3","0","0","0"],["104610.8","0.03748854","0","1"],["104610.9","0.00477954","0","1"],["104611.3","0.24816334","0","1"],["104613.8","0.22140803","0","1"],["104615.8","0","0","0"],["104621.9","0.13859205","0","1"],["104624","0","0","0"],["104625","0","0","0"],["104626","0","0","0"],["104628","0.002","0","2"],["104629","0.001","0","1"],["104634.7","0.54401","0","1"],["104646","0","0","0"],["104647","0","0","0"],["104649","0.33","0","6"],["104650","0.16532023","0","5"],["104655","0.00001501","0","1"],["104757.6","0","0","0"],["104757.7","0","0","0"],["104758","0","0","0"],["104758.5","0","0","0"]],"bids":[["104591","0.79850514","0","21"],["104590.6","0.11139769","0","2"],["104588.8","0","0","0"],["104588.1","0.00293813","0","1"],["104587.8","0.08170502","0","3"],["104586.8","0","0","0"],["104586.1","0.10377928","0","1"],["104584.1","0","0","0"],["104582.2","0.00115191","0","1"],["104581.8","0.09616234","0","1"],["104578.7","0.00477954","0","1"],["104578.6","0","0","0"],["104578.5","0.08913305","0","4"],["104576.9","0.19242972","0","1"],["104576.8","0.45332519","0","3"],["104575.5","0","0","0"],["104573.4","0.13859205","0","1"],["104572","0.25644434","0","3"],["104571.8","0.24907124","0","1"],["104566.2","0.00011865","0","1"],["104559.4","0","0","0"],["104488","0.01069397","0","2"],["104422.7","0","0","0"]],"ts":"1747170024700","checksum":-273646664,"seqId":54226049262,"prevSeqId":54226049167}]}
{"arg":{"channel":"books","instId":"BTC-USDT"},"action":"update","data":[{"asks":[["104602.8","0.77866876","0","1"],["104604.6","0.00478052","0","1"],["104606.2","0.05148955","0","1"],["104609.1","0","0","0"],["104613.8","0.14599059","0","1"],["104614.5","0.00478052","0","1"],["104615.3","0.0382361","0","1"],["104635.5","0.04987941","0","1"],["104702.5","0","0","0"],["104702.7","0.01068894","0","2"],["104755","0.00092688","0","2"],["104756.8","0","0","0"],["104757.5","0","0","0"]],"bids":[["104580.3","0","0","0"],["104580.2","0.17371793","0","1"],["104576.8","0.36756115","0","2"],["104574.1","0.002","0","1"],["104572","0.19602625","0","2"],["104567.8","0","0","0"],["104567.5","0.00191","0","1"],["104562.2","0.00191","0","1"],["104560.7","0","0","0"],["104555.4","0.07324","0","1"],["104554","0.00478075","0","1"],["104541.3","0.04545869","0","1"],["104536.8","0","0","0"],["104488.1","0.00009782","0","1"],["104488","0.01059676","0","1"],["104435.9","0.00095583","0","1"],["104430.8","0","0","0"]],"ts":"1747170024800","checksum":2112125389,"seqId":54226049294,"prevSeqId":54226049262}]}
{"arg":{"channel":"books","instId":"BTC-USDT"},"action":"update","data":[{"asks":[["104591.1","0.31578235","0","7"],["104598.9","0.03378307","0","2"],["104600.2","0.09490178","0","1"],["104601.3","0.47424269","0","1"],["104605.2","0.23525934","0","3"],["104606.2","0","0","0"],["104606.3","0","0","0"],["104609.1","0.0047792","0","1"],["104610.2","0.26010828","0","1"],["104610.9","0","0","0"],["104611.3","0","0","0"],["104612.1","0","0","0"],["104619","0.13859511","0","1"],["104621.9","0","0","0"],["104633.1","0","0","0"],["104635.8","0","0","0"],["104641.8","0","0","0"],["104643.8","0.07298372","0","1"],["104644.9","0","0","0"],["104649.2","0.00004963","0","1"],["104650.4","0.0702105","0","1"],["104654.9","0","0","0"],["104655.6","0.80791607","0","1"],["104657.1","0","0","0"],["104657.2","0","0","0"],["104660","0.00270473","0","4"],["104703.1","0.32119504","0","1"],["104756.8","0.160623","0","1"],["104757.5","0.77866876","0","1"],["104757.6","0.00001017","0","1"],["104757.7","0.00002193","0","1"],["104758","0.00013459","0","1"],["104758.5","0.00003192","0","3"],["104758.6","0.00094804","0","1"]],"bids":[["104591","0.66176874","0","19"],["104588.7","0","0","0"],["104588.1","0","0","0"],["104587.8","0.052","0","2"],["104586.2","0.00292766","0","1"],["104586.1","0.13563434","0","2"],["104582.2","0","0","0"],["104581.8","0","0","0"],["104580.8","0.00115191","0","1"],["104580.7","0.12653309","0","2"],["104578.7","0","0","0"],["104577","0.0047792","0","1"],["104576.8","0.19926131","0","1"],["104576.4","0.09062397","0","3"],["104575.7","0.14860342","0","1"],["104573.4","0","0","0"],["104572","0.15974405","0","2"],["104571.8","0","0","0"],["104570.7","0.25911956","0","1"],["104570.1","0.13859511","0","1"],["104567.9","0.00001","0","1"],["104539.8","0","0","0"],["104531.3","0","0","0"],["104508.5","0.12530463","0","1"],["104508.4","0.07298372","0","1"],["104422.7","0.01089657","0","1"],["104421.8","0.77866876","0","1"],["104421.7","0.07298372","0","1"]],"ts":"1747170024900","checksum":-669063894,"seqId":54226049362,"prevSeqId":54226049294}]}
{"arg":{"channel":"books","instId":"BTC-USDT"},"action":"update","data":[{"asks":[["104591.1","0.31258235","0","6"],["104635.5","0.14548941","0","2"],["104638.7","0.09561","0","1"],["104640.4","0.68561056","0","1"],["104640.5","1.39061572","0","1"],["104641.1","0","0","0"],["104670.8","1.5239802","0","1"],["104671.8","2.56870161","0","1"],["104703.1","0","0","0"],["104758.5","0","0","0"],["104758.6","0","0","0"]],"bids":[["104591","0.58467874","0","18"],["104576.9","0","0","0"],["104572","0.22771192","0","3"],["104549","0.81702149","0","2"],["104547.3","1.36344194","0","1"],["104540.8","0.38911502","0","1"],["104519.9","1.0251804","0","2"],["104515.9","2.48268775","0","1"],["104421.7","0","0","0"]],"ts":"1747170025000","checksum":-878624522,"seqId":54226049384,"prevSeqId":54226049362}]}
{"arg":{"channel":"books","instId":"BTC-USDT"},"action":"update","data":[{"asks":[["104591.1","0.31259235","0","7"],["104622.7","0.234","0","1"],["104637.8","0.77923542","0","2"],["104648.9","0","0","0"],["104664","0.00056666","0","1"],["104667.8","0.31852136","0","2"]],"bids":[["104591","0.5852454","0","19"],["104578.5","0.08856639","0","3"],["104564.8","0.00056666","0","1"],["104552.3","0","0","0"]],"ts":"1747170025100","checksum":1765817478,"seqId":54226049398,"prevSeqId":54226049384}]}
{"arg":{"channel":"books","instId":"BTC-USDT"},"action":"update","data":[{"asks":[["104658.7","0.09555","0","1"],["104661.7","0.14332","0","1"],["104664.5","0.09554","0","1"],["104668.9","0.11465","0","1"],["104670.7","0.20197693","0","2"],["104757.5","0","0","0"],["104757.6","0","0","0"],["104757.7","0","0","0"],["104758","0","0","0"]],"bids":[["104591","0.58285514","0","18"],["104549.6","0.00956027","0","1"],["104547.7","0","0","0"]],"ts":"1747170025200","checksum":-543592662,"seqId":54226049410,"prevSeqId":54226049398}]}
{"arg":{"channel":"books","instId":"BTC-USDT"},"action":"update","data":[{"asks":[["104601.3","0","0","0"],["104603.6","0.35629241","0","3"],["104607.9","0.46855451","0","1"],["104608.6","0.11774395","0","3"],["104693.1","0.18733838","0","3"],["104710.9","0.00001","0","1"],["104756.8","0","0","0"]],"bids":[["104576.9","0.19242972","0","1"],["104421.8","0","0","0"]],"ts":"1747170025300","checksum":-1045669560,"seqId":54226049423,"prevSeqId":54226049410}]}
{"arg":{"channel":"books","instId":"BTC-USDT"},"action":"update","data":[{"asks":[["104591.1","0.18979381","0","6"],["104596.8","0.03334372","0","1"],["104600.2","0","0","0"],["104600.5","0.00067735","0","1"],["104600.6","0.09686262","0","1"],["104601","0","0","0"],["104601.1","0.0000125","0","1"],["104601.8","0.06074901","0","1"],["104602.9","0.02256561","0","1"],["104603","0.01911888","0","1"],["104605.2","0.072","0","2"],["104605.6","0.15662226","0","1"],["104605.8","0","0","0"],["104610.2","0","0","0"],["104610.6","0.5958916","0","3"],["104667.8","0.20907365","0","1"],["104755","0","0","0"],["104755.1","0","0","0"],["104756","0","0","0"]],"bids":[["104589.2","0.07456561","0","3"],["104581.2","0.00115191","0","1"],["104581.1","0.09082549","0","1"],["104580.8","0","0","0"],["104580.7","0.02930447","0","1"],["104576.1","0.16606708","0","1"],["104575.7","0","0","0"],["104572","0.22376317","0","3"],["104571.1","0.24595706","0","1"],["104570.7","0","0","0"],["104422.7","0","0","0"]],"ts":"1747170025400","checksum":1638213362,"seqId":54226049464,"prevSeqId":54226049423}]}
{"arg":{"channel":"books","instId":"BTC-USDT"},"action":"update","data":[{"asks":[["104670.8","2.93829869","0","2"],["104673.6","6.32913217","0","1"],["104679.8","0.01051593","0","1"],["104696.9","0","0","0"]],"bids":[],"ts":"1747170025500","checksum":1638213362,"seqId":54226049469,"prevSeqId":54226049464}]}
{"arg":{"channel":"books","instId":"BTC-USDT"},"action":"update","data":[{"asks":[["104600.1","0.09937058","0","1"],["104601.5","0.09769448","0","1"],["104602.2","0.09291952","0","1"],["104605","0.16262174","0","1"],["104605.6","0.30627616","0","2"],["104608.4","0.15693212","0","1"],["104608.8","0.22796556","0","1"],["104611.1","0.26788478","0","1"],["104614.7","0.24890585","0","1"],["104703","0.01090629","0","2"],["104750.7","0","0","0"],["104751.5","0","0","0"],["104751.9","0","0","0"],["104753.2","0","0","0"],["104753.3","0","0","0"],["104754","0","0","0"],["104754.2","0","0","0"],["104754.7","0","0","0"]],"bids":[["104587.9","0.00815857","0","2"],["104586.2","0","0","0"],["104581","0.08801989","0","1"],["104579.7","0.09774265","0","1"],["104579.1","0.09443788","0","1"],["104578.1","0.15969418","0","1"],["104577.5","0.14777456","0","1"],["104573.8","0.23147731","0","1"],["104573.4","0.16696696","0","1"],["104568.1","0.26101517","0","2"],["104567.2","0.25128602","0","1"],["104424.7","0","0","0"],["104424.3","0","0","0"],["104424","0","0","0"],["104423.5","0","0","0"],["104423","0","0","0"],["104422.9","0","0","0"],["104422.8","0","0","0"]],"ts":"1747170025600","checksum":345044799,"seqId":54226049495,"prevSeqId":54226049469}]}
{"arg":{"channel":"books","instId":"BTC-USDT"},"action":"update","data":[{"asks":[["104596.5","0","0","0"],["104600","0.00288578","0","4"],["104600.5","0","0","0"],["104613.8","0.20384768","0","2"],["104750.7","0.00049233","0","7"],["104751.5","0.01448136","0","1"]],"bids":[["104580.2","0.3002941","0","2"],["104576.8","0.32235887","0","2"],["104572","0.36943613","0","2"]],"ts":"1747170025700","checksum":-559948958,"seqId":54226049511,"prevSeqId":54226049495}]}
{"arg":{"channel":"books","instId":"BTC-USDT"},"action":"update","data":[{"asks":[],"bids":[["104587.9","0.00521603","0","1"],["104586.2","0.00293993","0","1"],["104509","0.0025","0","1"],["104425","0","0","0"]],"ts":"1747170025800","checksum":-94437542,"seqId":54226049514,"prevSeqId":54226049511}]}
{"arg":{"channel":"books","instId":"BTC-USDT"},"action":"update","data":[{"asks":[["104601.8","0","0","0"],["104602.2","0.14016943","0","2"],["104751.9","0.00001969","0","1"]],"bids":[["104591","0.58377514","0","19"],["104488.6","0.00010316","0","1"],["104488.1","0","0","0"],["104436.2","0.00095585","0","1"],["104435.9","0","0","0"]],"ts":"1747170025900","checksum":2057343341,"seqId":54226049527,"prevSeqId":54226049514}]}
{"arg":{"channel":"books","instId":"BTC-USDT"},"action":"update","data":[{"asks":[["104693.6","0","0","0"],["104753.2","0.0000358","0","1"]],"bids":[["104591","0.58263542","0","18"],["104587.9","0.00815585","0","2"],["104586.2","0","0","0"],["104425","0.0025","0","1"]],"ts":"1747170026000","checksum":1243257328,"seqId":54226049534,"prevSeqId":54226049527}]}
{"arg":{"channel":"books","instId":"BTC-USDT"},"action":"update","data":[{"asks":[["104608.5","0.0047792","0","1"],["104609.1","0","0","0"],["104619","0","0","0"],["104620.2","0.13859458","0","1"],["104628.7","0","0","0"],["104629.9","0.000137","0","1"],["104637.8","0.77866876","0","1"],["104639.6","2.43940666","0","2"],["104648.1","0","0","0"],["104664","0","0","0"],["104665.9","0.00056666","0","1"],["104731.9","0.00095481","0","1"]],"bids":[["104588.1","0.00293981","0","1"],["104587.9","0.00521603","0","1"],["104577","0","0","0"],["104576.9","0.19720892","0","2"],["104574.1","0.78066876","0","2"],["104572.2","0.38863185","0","1"],["104572.1","0.13859458","0","1"],["104570.1","0","0","0"],["104551.4","0.00956011","0","1"],["104549.6","0","0","0"],["104530","0.00028006","0","1"],["104470.4","0.00083731","0","1"],["104467.4","0","0","0"],["104425","0","0","0"]],"ts":"1747170026100","checksum":1385764378,"seqId":54226049600,"prevSeqId":54226049534}]}
{"arg":{"channel":"books","instId":"BTC-USDT"},"action":"update","data":[{"asks":[["104591.1","0.07750416","0","5"],["104595.9","0","0","0"],["104596.8","0","0","0"],["104599.9","0.02374569","0","1"],["104600","0.00220843","0","3"],["104600.1","0","0","0"],["104600.6","0","0","0"],["104600.9","0.09676017","0","1"],["104601.1","0.00068985","0","2"],["104601.2","0.32143742","0","1"],["104601.4","0.13100493","0","2"],["104601.5","0","0","0"],["104602.2","0.04724991","0","1"],["104602.3","0.08929724","0","1"],["104603","0.09330732","0","1"],["104605","0","0","0"],["104605.6","0","0","0"],["104605.8","0.15485204","0","1"],["104606.4","0.3214851","0","2"],["104607.4","0.05977788","0","1"],["104608.4","0","0","0"],["104608.5","0","0","0"],["104608.8","0","0","0"],["104609.1","0.01911773","0","1"],["104609.2","0.33780404","0","2"],["104609.6","0.23747228","0","1"],["104610.1","0","0","0"],["104610.5","0.0047792","0","1"],["104610.6","0.3556784","0","2"],["104611.1","0","0","0"],["104611.4","0.26619558","0","1"],["104611.9","0.25308846","0","1"],["104612.3","0","0","0"],["104614.6","0.04191","0","2"],["104614.7","0","0","0"],["104615.5","0.26722839","0","2"],["104615.6","0.1778392","0","1"],["104615.9","0.00286746","0","1"],["104620.2","0","0","0"],["104622.6","0.13859084","0","1"],["104624.5","0.1778392","0","1"],["104624.9","0","0","0"],["104635.5","0.04987941","0","1"],["104638.7","0","0","0"],["104648.9","0.00155231","0","1"],["104699.8","0.04643937","0","2"],["104702.7","0.01059656","0","1"],["104753.3","2.3905","0","1"],["104754","0.234","0","1"]],"bids":[["104591","0.67219542","0","19"],["104589.7","0.00294408","0","1"],["104588.1","0","0","0"],["104587.8","0.07600289","0","3"],["104582","0.00115191","0","1"],["104581.9","0.09118148","0","1"],["104581.8","0.08955325","0","1"],["104581.2","0","0","0"],["104581.1","0","0","0"],["104581","0","0","0"],["104580.5","0.09524516","0","1"],["104580.2","0.26168763","0","2"],["104579.9","0.09013035","0","1"],["104579.7","0","0","0"],["104579.1","0","0","0"],["104578.9","0.15979572","0","1"],["104578.6","0.0047792","0","1"],["104578.4","0.36363886","0","2"],["104578.3","0.15487898","0","1"],["104578.1","0","0","0"],["104577.5","0","0","0"],["104576.9","0.35820956","0","2"],["104576.8","0.69874023","0","1"],["104576.1","0","0","0"],["104574.6","0.23174691","0","1"],["104574.2","0.29928849","0","2"],["104573.8","0","0","0"],["104573.4","0","0","0"],["104572.1","0","0","0"],["104572","0.25669883","0","3"],["104571.9","0.24369858","0","2"],["104571.1","0","0","0"],["104568.9","0.24261672","0","1"],["104568.1","0.00005","0","1"],["104568","0.2343966","0","1"],["104567.2","0","0","0"],["104555.9","0.03345912","0","2"],["104544.1","0.00001","0","1"],["104529.7","0.1913","0","1"],["104490.8","0.00010051","0","1"],["104488.6","0","0","0"],["104438.5","0.00095585","0","1"],["104436.2","0","0","0"]],"ts":"1747170026200","checksum":-1594325806,"seqId":54226049770,"prevSeqId":54226049600}]}
{"arg":{"channel":"books","instId":"BTC-USDT"},"action":"update","data":[{"asks":[["104600.8","0.00067735","0","1"],["104601.1","0.0000125","0","1"],["104609.5","0.0047917","0","2"],["104610.5","0","0","0"],["104621.9","0.13859227","0","1"],["104622.6","0","0","0"],["104638.7","0.09561","0","1"],["104641.8","0.09561","0","1"],["104753.3","0","0","0"],["104754","0","0","0"]],"bids":[["104589.7","0","0","0"],["104588.7","0.00294658","0","1"],["104579.8","0.00001","0","1"],["104578.6","0","0","0"],["104577","0.0047792","0","1"],["104574.2","0.16069765","0","1"],["104573.4","0.13859227","0","1"],["104425.7","0","0","0"],["104425.3","0","0","0"]],"ts":"1747170026300","checksum":-1944831799,"seqId":54226049796,"prevSeqId":54226049770}]}
{"arg":{"channel":"books","instId":"BTC-USDT"},"action":"update","data":[{"asks":[["104609.5","0.0000125","0","1"],["104610.5","0.0047792","0","1"],["104647.9","0.62814455","0","1"],["104648.2","0","0","0"],["104670.8","1.5239802","0","1"],["104673.6","0","0","0"],["104677","6.29401203","0","1"],["104679.8","0.91393873","0","2"],["104753.2","0","0","0"]],"bids":[["104588.7","0","0","0"],["104588.1","0.00294449","0","1"],["104578.5","0.09334559","0","4"],["104577","0","0","0"],["104576.8","0.42933373","0","1"],["104574.1","0.002","0","1"],["104425.7","0.007986","0","1"]],"ts":"1747170026400","checksum":-1176288059,"seqId":54226049832,"prevSeqId":54226049796}]}
{"arg":{"channel":"books","instId":"BTC-USDT"},"action":"update","data":[{"asks":[["104670.8","2.727403","0","2"],["104673.6","6.33420855","0","1"],["104677","0","0","0"]],"bids":[["104576.8","0.60926764","0","2"],["104572.3","0.77866876","0","1"],["104454.3","0.16061","0","1"],["104425.9","0","0","0"],["104425.7","0","0","0"]],"ts":"1747170026500","checksum":-1176288059,"seqId":54226049841,"prevSeqId":54226049832}]}
{"arg":{"channel":"books","instId":"BTC-USDT"},"action":"update","data":[{"asks":[["104634.6","0.00004128","0","1"],["104649","0.32999999","0","6"],["104660.8","0","0","0"],["104679.8","0.01051593","0","1"],["104699.2","0.0000912","0","1"],["104699.8","0.04634752","0","1"],["104751.9","0","0","0"]],"bids":[["104583.8","0.00001","0","1"],["104582.2","0.00115191","0","1"],["104582","0","0","0"],["104566.2","0","0","0"],["104540.1","0.00012868","0","2"],["104491.2","0.0001025","0","1"],["104490.8","0","0","0"],["104438.9","0.00095584","0","1"],["104438.5","0","0","0"]],"ts":"1747170026600","checksum":-328539482,"seqId":54226049903,"prevSeqId":54226049841}]}
{"arg":{"channel":"books","instId":"BTC-USDT"},"action":"update","data":[{"asks":[["104595.9","0.24","0","1"],["104600.8","0.0976069","0","1"],["104600.9","0","0","0"],["104601.1","0.00068985","0","2"],["104601.3","0.10175513","0","1"],["104601.4","0.036","0","1"],["104602.9","0.12144076","0","2"],["104603","0","0","0"],["104603.6","0.17592839","0","2"],["104606.3","0.32109852","0","2"],["104606.4","0","0","0"],["104607.9","0","0","0"],["104609.5","0.22940488","0","2"],["104609.6","0","0","0"],["104610.5","0","0","0"],["104611.3","0.24569312","0","2"],["104611.4","0","0","0"],["104611.8","0.26257621","0","1"],["104611.9","0","0","0"],["104613.8","0.40973638","0","1"],["104614.3","0.4713836","0","1"],["104615.4","0.26114779","0","1"],["104615.5","0.00001","0","1"],["104621.9","0","0","0"],["104622.6","0.13859029","0","1"],["104693.1","0.02111249","0","2"],["104751.9","0.00001969","0","1"]],"bids":[["104581.9","0","0","0"],["104581.8","0.18970733","0","2"],["104580.5","0","0","0"],["104580.4","0.08928647","0","1"],["104579.9","0","0","0"],["104579.8","0.09415907","0","2"],["104579","0.0047792","0","1"],["104578.9","0","0","0"],["104578.8","0.16011696","0","1"],["104578.5","0.08856639","0","3"],["104576.9","0.19242972","0","1"],["104576.8","0.77143187","0","3"],["104574.6","0","0","0"],["104574.5","0.24329793","0","1"],["104574.3","0.13859029","0","1"],["104573.4","0","0","0"],["104572","0.11816552","0","2"],["104571.9","0.00001","0","1"],["104568.9","0","0","0"],["104568.8","0.27146562","0","1"],["104568","0","0","0"],["104567.9","0.25179748","0","2"],["104425.9","0.0001","0","1"],["104425.7","0.007986","0","1"]],"ts":"1747170026700","checksum":822543969,"seqId":54226049962,"prevSeqId":54226049903}]}
{"arg":{"channel":"books","instId":"BTC-USDT"},"action":"update","data":[{"asks":[["104600.7","0.00067735","0","1"],["104601.1","0.0000125","0","1"],["104603.6","0.30232271","0","3"],["104623.9","0","0","0"],["104634.8","0.02868312","0","1"],["104751.9","0","0","0"]],"bids":[["104572","0.27057076","0","3"],["104571.8","0.25581397","0","1"],["104529.6","0","0","0"]],"ts":"1747170026800","checksum":-501567744,"seqId":54226049971,"prevSeqId":54226049962}]}
{"arg":{"channel":"books","instId":"BTC-USDT"},"action":"update","data":[{"asks":[["104596.9","0.0315","0","1"],["104597.1","0.03155586","0","1"],["104599.9","0","0","0"],["104609","0.0047792","0","1"],["104611.3","0.24091392","0","1"],["104620.7","0.1385929","0","1"],["104622.6","0","0","0"],["104750.7","0","0","0"],["104751.5","0","0","0"]],"bids":[["104591","0.67238542","0","20"],["104588.1","0.00296402","0","1"],["104587.8","0.052","0","2"],["104581.5","0.04964392","0","1"],["104579","0","0","0"],["104577","0.0047792","0","1"],["104574.3","0","0","0"],["104572.4","0.1385929","0","1"],["104557.5","0.16404348","0","1"],["104557.4","0","0","0"],["104425.7","0","0","0"]],"ts":"1747170026900","checksum":-566396012,"seqId":54226049999,"prevSeqId":54226049971}]}
{"arg":{"channel":"books","instId":"BTC-USDT"},"action":"update","data":[{"asks":[["104591.1","0.08047471","0","6"],["104624.1","0.00955578","0","1"],["104636.5","0.102066","0","1"],["104750.5","0","0","0"]],"bids":[["104576.9","0","0","0"],["104425.7","0.007986","0","1"]],"ts":"1747170027000","checksum":1771551556,"seqId":54226050017,"prevSeqId":54226049999}]}
{"arg":{"channel":"books","instId":"BTC-USDT"},"action":"update","data":[{"asks":[["104591.1","0.22456494","0","8"],["104595.4","0.03155636","0","1"],["104599.9","0.09516078","0","1"],["104600.4","0.0964849","0","1"],["104600.7","0","0","0"],["104600.8","0","0","0"],["104601.1","0.00068985","0","2"],["104601.3","0","0","0"],["104601.4","0.12919987","0","2"],["104602","0.09436462","0","1"],["104602.3","0","0","0"],["104602.9","0.02256561","0","1"],["104603.6","0.33966756","0","3"],["104603.7","0.01911869","0","1"],["104603.9","0","0","0"],["104604.9","0.14818811","0","1"],["104605.4","0.30316442","0","2"],["104605.8","0","0","0"],["104606.3","0","0","0"],["104607.9","0.0047792","0","1"],["104608.3","0.15433794","0","1"],["104608.6","0.34565051","0","4"],["104609","0","0","0"],["104609.1","0","0","0"],["104609.2","0.1778392","0","1"],["104609.5","0.0000125","0","1"],["104610.4","0.25210359","0","1"],["104610.9","0.24956529","0","1"],["104611.3","0","0","0"],["104611.8","0","0","0"],["104614.5","0.25953749","0","2"],["104615.4","0","0","0"],["104619","0.13859502","0","1"],["104620.7","0","0","0"],["104639.6","2.43884","0","1"],["104641.5","0.00056666","0","1"],["104665.9","0","0","0"],["104667.8","0.20964031","0","2"],["104750.5","0.07299861","0","2"]],"bids":[["104591","0.56682542","0","18"],["104589.9","0.036","0","1"],["104589.2","0.05856561","0","2"],["104588.1","0","0","0"],["104587.8","0.036","0","1"],["104586.2","0.00295997","0","1"],["104586.1","0.0755755","0","1"],["104585.8","0.036","0","1"],["104584.3","0.02400371","0","1"],["104581.8","0","0","0"],["104581.5","0","0","0"],["104580.9","0.18463026","0","2"],["104580.4","0","0","0"],["104580.2","0.29263018","0","2"],["104579.8","0.00001","0","1"],["104579.5","0.09714298","0","1"],["104578.9","0.09322492","0","1"],["104578.8","0","0","0"],["104578.3","0","0","0"],["104577.9","0.17139482","0","3"],["104577.4","0.15194839","0","1"],["104577","0","0","0"],["104576.8","0.35755235","0","2"],["104576.1","0.0047792","0","1"],["104575.9","0.1533626","0","1"],["104574.5","0","0","0"],["104574.2","0","0","0"],["104573.6","0.24510532","0","1"],["104573.3","0.22139569","0","2"],["104572.4","0","0","0"],["104572.3","0","0","0"],["104572.2","0","0","0"],["104572","0.33710717","0","3"],["104571.8","0","0","0"],["104571","0.13859502","0","1"],["104570.9","0.24259536","0","1"],["104568.8","0","0","0"],["104567.9","0.24684665","0","2"],["104567","0.25560912","0","1"],["104526.7","0","0","0"],["104425.3","0.1913","0","1"],["104425","0.0025","0","1"],["104424.7","0.00001169","0","1"]],"ts":"1747170027100","checksum":-1663921082,"seqId":54226050198,"prevSeqId":54226050017}]}
{"arg":{"channel":"books","instId":"BTC-USDT"},"action":"update","data":[{"asks":[["104591.1","0.22349023","0","7"],["104599.8","0.00067735","0","1"],["104601.1","0.0000125","0","1"],["104608.6","0.11774395","0","3"],["104608.7","0.25488316","0","1"],["104627","0.002","0","2"],["104628","0.001","0","1"],["104629","0","0","0"],["104648","0.33","0","6"],["104649","0.16499999","0","3"],["104650","0.00032024","0","2"],["104749.9","0","0","0"],["104750","0","0","0"],["104750.5","0","0","0"]],"bids":[["104583.3","0.00115191","0","1"],["104582.2","0","0","0"],["104573.7","0.24341624","0","1"],["104573.6","0","0","0"],["104573.1","0.04569316","0","1"],["104562.5","0.005","0","1"],["104553.3","0.18739913","0","2"],["104551.4","0","0","0"],["104550","0.00533024","0","4"]],"ts":"1747170027200","checksum":1062834804,"seqId":54226050228,"prevSeqId":54226050198}]}
{"arg":{"channel":"books","instId":"BTC-USDT"},"action":"update","data":[{"asks":[["104591.1","0.22491762","0","8"],["104607.9","0","0","0"],["104608.6","0.37163053","0","4"],["104608.7","0","0","0"],["104609.1","0.00477921","0","1"],["104619","0","0","0"],["104620.2","0.13859413","0","1"],["104627","0","0","0"],["104628","0.002","0","2"],["104629","0.001","0","1"],["104648","0","0","0"],["104648.5","0","0","0"],["104649","0.32999999","0","6"],["104650","0.16532023","0","5"],["104700.9","0","0","0"],["104736.4","0.00004783","0","1"],["104749.9","0.00021362","0","1"],["104750","0.0294814","0","38"],["104750.5","0.07299861","0","2"],["104750.7","0.00049233","0","7"]],"bids":[["104577","0.00477921","0","1"],["104576.9","0.19242972","0","1"],["104576.1","0","0","0"],["104573.7","0","0","0"],["104573.6","0.23954581","0","1"],["104572.1","0.13859413","0","1"],["104571","0","0","0"],["104542.3","0","0","0"],["104491.2","0.00010204","0","1"],["104484.5","0.00001","0","1"]],"ts":"1747170027300","checksum":794622902,"seqId":54226050282,"prevSeqId":54226050228}]}
{"arg":{"channel":"books","instId":"BTC-USDT"},"action":"update","data":[{"asks":[["104591.1","0.22634501","0","9"],["104650.4","0.36143419","0","2"],["104652","1","0","1"],["104682.9","0.06391669","0","3"],["104750.7","0","0","0"]],"bids":[],"ts":"1747170027400","checksum":225637579,"seqId":54226050286,"prevSeqId":54226050282}]}
{"arg":{"channel":"books","instId":"BTC-USDT"},"action":"update","data":[{"asks":[["104593.2","0.005","0","1"],["104605.7","0.005","0","1"],["104650.4","0.0702105","0","1"],["104652","0","0","0"],["104740","0.00268458","0","3"],["104750.5","0","0","0"]],"bids":[["104572.4","0.005","0","1"],["104559.9","0.05701","0","4"],["104424.7","0","0","0"]],"ts":"1747170027500","checksum":-1585640248,"seqId":54226050293,"prevSeqId":54226050286}]}
{"arg":{"channel":"books","instId":"BTC-USDT"},"action":"update","data":[{"asks":[["104607.2","0.00477921","0","1"],["104609.1","0","0","0"],["104638.7","0","0","0"],["104641.8","0","0","0"],["104658.7","0","0","0"],["104661.7","0","0","0"],["104664.5","0","0","0"],["104668.9","0","0","0"],["104669","0","0","0"],["104670.7","0.01089693","0","1"],["104695.2","0.01051593","0","1"],["104750.5","0.07299861","0","2"],["104750.7","0.00049233","0","7"],["104751.5","0.01448136","0","1"],["104751.9","0.00001969","0","1"],["104753.2","0.0000358","0","1"],["104753.3","2.3905","0","1"],["104754.2","0.00089983","0","1"]],"bids":[["104577","0","0","0"],["104574.2","0.00477921","0","1"],["104565.1","0.00776272","0","1"],["104557.5","0","0","0"]],"ts":"1747170027600","checksum":-1585640248,"seqId":54226050316,"prevSeqId":54226050293}]}
{"arg":{"channel":"books","instId":"BTC-USDT"},"action":"update","data":[{"asks":[["104591.1","0.70034501","0","11"],["104599.6","0.00068735","0","2"],["104599.7","0.09385","0","1"],["104599.8","0","0","0"],["104599.9","0","0","0"],["104600.2","0.09668859","0","1"],["104600.4","0","0","0"],["104601.1","0.0954287","0","2"],["104601.4","0.036","0","1"],["104601.7","0.08822612","0","1"],["104602","0","0","0"],["104603.6","0.40889276","0","3"],["104604.6","0.14965168","0","2"],["104604.9","0","0","0"],["104605.2","0.37984711","0","4"],["104605.4","0","0","0"],["104608","0.17546889","0","2"],["104608.3","0","0","0"],["104608.4","0.23137697","0","1"],["104608.6","0.11774395","0","3"],["104610","0.27252802","0","4"],["104610.2","0.25314788","0","1"],["104610.4","0","0","0"],["104610.7","0.24665999","0","1"],["104610.9","0","0","0"],["104614.2","0.26544924","0","1"],["104614.5","0.00478052","0","1"],["104615.3","0","0","0"],["104627","0.002","0","2"],["104628","0.001","0","1"],["104629","0","0","0"],["104648","0.33","0","6"],["104649","0.16499999","0","3"],["104650","0.00032024","0","2"],["104667.8","0.00056666","0","1"],["104682.9","0.20504292","0","4"],["104754","0.234","0","1"],["104754.7","0.00001","0","1"]],"bids":[["104585.9","0.03600333","0","2"],["104580.9","0","0","0"],["104580.7","0.11961527","0","2"],["104580.6","0.09507046","0","1"],["104580.2","0.24361536","0","2"],["104579.5","0","0","0"],["104579.2","0.09065641","0","1"],["104578.9","0","0","0"],["104578.7","0.10163981","0","1"],["104577.9","0.00099501","0","2"],["104577.7","0.15703712","0","1"],["104577.4","0","0","0"],["104577.1","0.15031201","0","1"],["104576.8","0.36121523","0","2"],["104575.9","0","0","0"],["104575.7","0.16803484","0","1"],["104573.6","0","0","0"],["104573.4","0.22801513","0","1"],["104573.3","0.07298372","0","1"],["104573.1","0","0","0"],["104573","0.15803829","0","1"],["104572","0.18667949","0","3"],["104570.9","0","0","0"],["104570.7","0.27105546","0","1"],["104567.9","0.00001","0","1"],["104567.7","0.24361554","0","1"],["104567","0","0","0"],["104566.8","0.25054874","0","1"],["104566.7","0.24634951","0","1"],["104566.1","0","0","0"],["104425.3","0","0","0"],["104425","0","0","0"]],"ts":"1747170027700","checksum":-2101985045,"seqId":54226050407,"prevSeqId":54226050316}]}
{"arg":{"channel":"books","instId":"BTC-USDT"},"action":"update","data":[{"asks":[["104591.1","0.70020257","0","11"],["104606.4","0.00477921","0","1"],["104607.2","0","0","0"],["104619","0.13859505","0","1"],["104620.2","0","0","0"],["104640.4","0","0","0"],["104640.5","0","0","0"],["104671.8","0","0","0"],["104755","0.00001787","0","1"],["104755.1","0.00010283","0","1"],["104756","0.00001103","0","1"]],"bids":[["104591","0.45625542","0","16"],["104588.6","0","0","0"],["104585.9","0.012","0","1"],["104576.9","0","0","0"],["104572.1","0","0","0"],["104572","0.25943188","0","2"],["104570.8","0.13859505","0","1"],["104549","0.46418494","0","1"],["104547.3","0","0","0"],["104519.9","0.33362505","0","1"],["104515.9","0","0","0"],["104425.3","0.1913","0","1"],["104425","0.0025","0","1"],["104424.7","0.00001169","0","1"],["104424.3","0.00156669","0","1"]],"ts":"1747170027800","checksum":707535990,"seqId":54226050452,"prevSeqId":54226050407}]}
{"arg":{"channel":"books","instId":"BTC-USDT"},"action":"update","data":[{"asks":[["104627","0","0","0"],["104628","0.002","0","2"],["104629","0.001","0","1"],["104636.9","1.3735103","0","1"],["104638.7","0.09561","0","1"],["104641.8","0.09561","0","1"],["104648","0","0","0"],["104649","0.32999999","0","6"],["104650","0.16532023","0","5"],["104666.8","0.10643629","0","2"],["104668.3","2.47144907","0","1"],["104751.4","0.00090865","0","1"],["104754.7","0","0","0"],["104755","0","0","0"],["104755.1","0","0","0"],["104756","0","0","0"]],"bids":[["104590.6","0.07822919","0","1"],["104583.3","0","0","0"],["104582.2","0.00115191","0","1"],["104574.1","0.04769273","0","2"],["104548.5","1.4332721","0","1"],["104543","0.48324487","0","1"],["104534","0","0","0"],["104519.9","1.03779347","0","2"],["104517.1","3.10579286","0","3"],["104496","0.47439916","0","1"],["104487","0","0","0"],["104424.3","0","0","0"]],"ts":"1747170027900","checksum":1443024205,"seqId":54226050487,"prevSeqId":54226050452}]}
{"arg":{"channel":"books","instId":"BTC-USDT"},"action":"update","data":[{"asks":[["104661.9","0.14332","0","1"],["104754.2","0","0","0"]],"bids":[["104591","0.45338748","0","15"],["104553.9","0.1807072","0","2"],["104534.4","0","0","0"],["104526.3","0.00001","0","1"],["104487.9","0.09848362","0","2"]],"ts":"1747170028000","checksum":-915980598,"seqId":54226050529,"prevSeqId":54226050487}]}
{"arg":{"channel":"books","instId":"BTC-USDT"},"action":"update","data":[{"asks":[["104606.4","0","0","0"],["104607.2","0.00477921","0","1"],["104641.5","0","0","0"],["104643.4","0.00056666","0","1"],["104667.8","0","0","0"],["104669","0.06693","0","1"],["104669.7","0.00056666","0","1"],["104695.2","0.07744593","0","2"],["104754","0","0","0"]],"bids":[["104575.5","0.00477921","0","1"],["104574.2","0","0","0"],["104555.2","0.00955976","0","1"],["104553.3","0.1778392","0","1"],["104424.7","0","0","0"]],"ts":"1747170028100","checksum":-915980598,"seqId":54226050544,"prevSeqId":54226050529}]}
{"arg":{"channel":"books","instId":"BTC-USDT"},"action":"update","data":[{"asks":[["104618.9","0.13859503","0","1"],["104619","0","0","0"],["104627","0.002","0","2"],["104628","0.001","0","1"],["104629","0","0","0"],["104648","0.33","0","6"],["104649","0.16499999","0","3"],["104650","0.00032024","0","2"],["104753.3","0","0","0"]],"bids":[["104570.9","0.13859503","0","1"],["104570.8","0","0","0"],["104540.5","0.02868312","0","1"],["104491.8","0.00009862","0","1"],["104491.2","0","0","0"],["104425","0","0","0"]],"ts":"1747170028200","checksum":-915980598,"seqId":54226050573,"prevSeqId":54226050544}]}
{"arg":{"channel":"books","instId":"BTC-USDT"},"action":"update","data":[{"asks":[["104607.2","0","0","0"],["104607.3","0.19720893","0","2"],["104618.9","0","0","0"],["104619","0.13859498","0","1"],["104658.5","0.09555","0","1"],["104669.9","0.11465","0","1"],["104673.5","0.19107","0","1"],["104751.9","0","0","0"],["104753.2","0","0","0"]],"bids":[["104591","0.45356748","0","16"],["104575.8","0.00478921","0","2"],["104575.5","0","0","0"],["104571.8","0.13859498","0","1"],["104570.9","0","0","0"],["104425","0.0025","0","1"]],"ts":"1747170028300","checksum":414185163,"seqId":54226050585,"prevSeqId":54226050573}]}
{"arg":{"channel":"books","instId":"BTC-USDT"},"action":"update","data":[{"asks":[["104607.3","0.19242972","0","1"],["104607.9","0.00477921","0","1"],["104619","0.13859566","0","1"],["104751.5","0","0","0"]],"bids":[["104586.2","0","0","0"],["104585.9","0.01495778","0","2"],["104576.1","0.00477921","0","1"],["104575.8","0.00001","0","1"],["104571.8","0","0","0"],["104570.8","0.13859566","0","1"]],"ts":"1747170028400","checksum":-1520840447,"seqId":54226050612,"prevSeqId":54226050585}]}
{"arg":{"channel":"books","instId":"BTC-USDT"},"action":"update","data":[{"asks":[["104641.1","0.29727884","0","1"],["104679.8","0.34943225","0","2"],["104698.7","0.00009107","0","1"],["104699.2","0","0","0"],["104751.4","0","0","0"]],"bids":[["104585.9","0.012","0","1"],["104584.4","0.0029637","0","1"],["104425","0","0","0"]],"ts":"1747170028500","checksum":-1791723222,"seqId":54226050621,"prevSeqId":54226050612}]}
{"arg":{"channel":"books","instId":"BTC-USDT"},"action":"update","data":[{"asks":[["104591.1","0.69998745","0","11"],["104607.8","0.00477921","0","1"],["104607.9","0","0","0"],["104619","0","0","0"],["104620.2","0.1385946","0","1"],["104627","0","0","0"],["104628","0.002","0","2"],["104629","0.001","0","1"],["104648","0","0","0"],["104649","0.32999999","0","6"],["104650","0.16532023","0","5"],["104751.5","0.01448136","0","1"]],"bids":[["104576.2","0.00477921","0","1"],["104576.1","0","0","0"],["104571.8","0.13859498","0","1"],["104570.8","0","0","0"]],"ts":"1747170028600","checksum":-1211651130,"seqId":54226050662,"prevSeqId":54226050621}]}
{"arg":{"channel":"books","instId":"BTC-USDT"},"action":"update","data":[{"asks":[["104607.8","0","0","0"],["104607.9","0.00477921","0","1"]],"bids":[["104585.9","0.01496271","0","2"],["104584.4","0","0","0"],["104576.9","0.19242972","0","1"],["104576.2","0","0","0"],["104576.1","0.00477921","0","1"]],"ts":"1747170028700","checksum":-970942718,"seqId":54226050679,"prevSeqId":54226050662}]}
{"arg":{"channel":"books","instId":"BTC-USDT"},"action":"update","data":[{"asks":[["104591.1","0.46598745","0","10"],["104625.8","0.00847042","0","1"],["104720.9","0","0","0"],["104751.4","0.00090952","0","1"],["104751.5","0","0","0"]],"bids":[["104585.9","0.01496379","0","2"],["104485.7","0.02112349","0","3"],["104475.1","0","0","0"],["104425","0.0025","0","1"]],"ts":"1747170028800","checksum":-328636782,"seqId":54226050692,"prevSeqId":54226050679}]}
{"arg":{"channel":"books","instId":"BTC-USDT"},"action":"update","data":[{"asks":[["104699.3","0.02408273","0","2"]],"bids":[["104491.2","0.01148422","0","1"],["104425","0","0","0"]],"ts":"1747170028900","checksum":-328636782,"seqId":54226050694,"prevSeqId":54226050692}]}
{"arg":{"channel":"books","instId":"BTC-USDT"},"action":"update","data":[{"asks":[["104591.1","0.22598745","0","9"],["104599.6","0.00001","0","1"],["104599.7","0","0","0"],["104599.8","0.00067735","0","1"],["104599.9","0.09129372","0","1"],["104600.2","0","0","0"],["104600.4","0.10054944","0","1"],["104601.1","0.0000125","0","1"],["104601.4","0.1269997","0","2"],["104601.7","0","0","0"],["104602","0.09541827","0","1"],["104603.6","0.34432464","0","3"],["104604.6","0.00478052","0","1"],["104604.9","0.15171886","0","1"],["104605.2","0.072","0","2"],["104605.4","0.30456075","0","2"],["104607.9","0","0","0"],["104608","0.02812301","0","1"],["104608.2","0.16471365","0","1"],["104608.4","0","0","0"],["104608.5","0.00477921","0","1"],["104608.6","0.36750606","0","4"],["104610.2","0","0","0"],["104610.4","0.26275028","0","1"],["104610.7","0","0","0"],["104610.9","0.25374276","0","1"],["104614.2","0","0","0"],["104614.5","0.25266307","0","2"],["104750.7","0","0","0"],["104751.4","0","0","0"]],"bids":[["104591","0.30527384","0","15"],["104580.9","0.18697897","0","2"],["104580.7","0.02930447","0","1"],["104580.6","0","0","0"],["104580.2","0.29300953","0","2"],["104579.5","0.10005146","0","1"],["104579.2","0","0","0"],["104578.9","0.09458131","0","1"],["104578.7","0","0","0"],["104577.9","0.15854922","0","3"],["104577.7","0","0","0"],["104577.4","0.16179361","0","1"],["104577.1","0","0","0"],["104577","0.00477921","0","1"],["104576.8","0.31432111","0","2"],["104576.1","0","0","0"],["104575.9","0.15762604","0","1"],["104575.7","0","0","0"],["104573.6","0.25403775","0","1"],["104573.4","0","0","0"],["104573.2","0.16539133","0","1"],["104573","0","0","0"],["104572","0.38407678","0","3"],["104570.9","0.25628941","0","1"],["104570.7","0","0","0"],["104567.9","0.25762796","0","2"],["104567.7","0","0","0"],["104567","0.26642853","0","1"],["104566.8","0","0","0"],["104566.7","0","0","0"],["104484.4","0.00173748","0","1"],["104425","0.0025","0","1"],["104424.7","0.00001169","0","1"]],"ts":"1747170029000","checksum":-1550590631,"seqId":54226050779,"prevSeqId":54226050694}]}
{"arg":{"channel":"books","instId":"BTC-USDT"},"action":"update","data":[{"asks":[["104643.4","0","0","0"],["104645.3","0.00056666","0","1"],["104669.7","0","0","0"],["104671.6","0.01946666","0","2"],["104750.7","0.00049233","0","7"]],"bids":[["104586.1","0.07854005","0","2"],["104585.9","0.012","0","1"]],"ts":"1747170029100","checksum":-1430589252,"seqId":54226050786,"prevSeqId":54226050779}]}
{"arg":{"channel":"books","instId":"BTC-USDT"},"action":"update","data":[{"asks":[["104634.6","0","0","0"],["104676.3","0.00004128","0","1"]],"bids":[["104581","0.00011863","0","1"],["104557","0.0095596","0","1"],["104555.2","0","0","0"],["104541.3","0","0","0"],["104540.1","0.00001","0","1"]],"ts":"1747170029200","checksum":1526300338,"seqId":54226050804,"prevSeqId":54226050786}]}
{"arg":{"channel":"books","instId":"BTC-USDT"},"action":"update","data":[{"asks":[["104606.4","0.00477925","0","1"],["104608.5","0","0","0"],["104620.2","0.13859361","0","1"]],"bids":[["104591","0.30509384","0","14"],["104582.2","0","0","0"],["104581.1","0.00115191","0","1"],["104577","0","0","0"],["104574.2","0.00477925","0","1"],["104572.1","0.13859361","0","1"],["104571.8","0","0","0"],["104539.1","0.05007721","0","1"],["104424.7","0","0","0"]],"ts":"1747170029300","checksum":1446595170,"seqId":54226050820,"prevSeqId":54226050804}]}
{"arg":{"channel":"books","instId":"BTC-USDT"},"action":"update","data":[{"asks":[["104591.1","0.22519389","0","9"],["104599.6","0.02257561","0","2"],["104602.9","0","0","0"],["104606.4","0","0","0"],["104608.5","0.00477926","0","1"],["104751.5","0.01448136","0","1"]],"bids":[["104577","0.00477926","0","1"],["104574.2","0","0","0"]],"ts":"1747170029400","checksum":1815152294,"seqId":54226050836,"prevSeqId":54226050820}]}
{"arg":{"channel":"books","instId":"BTC-USDT"},"action":"update","data":[{"asks":[["104647","1","0","1"],["104668.2","0.8745309","0","1"],["104679.8","0.01051593","0","1"],["104687.5","0","0","0"],["104751.5","0","0","0"]],"bids":[["104586.1","0.07854003","0","2"],["104545.8","0.42343203","0","2"],["104498.5","0.21733678","0","2"]],"ts":"1747170029500","checksum":-991574263,"seqId":54226050853,"prevSeqId":54226050836}]}
{"arg":{"channel":"books","instId":"BTC-USDT"},"action":"update","data":[{"asks":[["104606.4","0.00477926","0","1"],["104608.5","0","0","0"]],"bids":[["104591","0.30485281","0","15"],["104577","0","0","0"],["104574.2","0.00477926","0","1"]],"ts":"1747170029800","checksum":-707173919,"seqId":54226050868,"prevSeqId":54226050853}]}
{"arg":{"channel":"books","instId":"BTC-USDT"},"action":"update","data":[{"asks":[["104645.3","0","0","0"],["104645.9","0","0","0"],["104647","0","0","0"],["104647.3","0.00057666","0","2"],["104671.6","0.0189","0","1"],["104673.6","6.33477521","0","2"],["104751.5","0.01448136","0","1"],["104751.9","0.00001969","0","1"],["104753.2","0.0000358","0","1"]],"bids":[["104558.9","0.00955942","0","1"],["104557","0","0","0"]],"ts":"1747170030100","checksum":-707173919,"seqId":54226050877,"prevSeqId":54226050868}]}
{"arg":{"channel":"books","instId":"BTC-USDT"},"action":"update","data":[{"asks":[],"bids":[["104576.8","0.60355983","0","1"],["104573.7","0.77866876","0","1"],["104536.8","0.00951982","0","1"],["104534.4","0.00935844","0","1"],["104532.5","0.00719441","0","1"],["104526.3","0","0","0"],["104502.1","0","0","0"],["104497.7","0","0","0"],["104494.4","0.00956237","0","1"],["104425","0","0","0"]],"ts":"1747170030200","checksum":-707173919,"seqId":54226050889,"prevSeqId":54226050877}]}
{"arg":{"channel":"books","instId":"BTC-USDT"},"action":"update","data":[{"asks":[["104591.1","0.22134501","0","8"],["104608.2","0","0","0"],["104608.3","0.1504794","0","1"],["104620.2","0.13859458","0","1"],["104751.4","0.00090664","0","1"],["104753.2","0","0","0"]],"bids":[["104573.3","0.23094022","0","2"],["104573.2","0","0","0"],["104572.1","0","0","0"],["104571.8","0.13859471","0","1"],["104562.5","0","0","0"],["104550","0.00033024","0","3"],["104425","0.0025","0","1"],["104424.7","0.00001169","0","1"]],"ts":"1747170030300","checksum":-1702950588,"seqId":54226050910,"prevSeqId":54226050889}]}
{"arg":{"channel":"books","instId":"BTC-USDT"},"action":"update","data":[{"asks":[["104605.7","0.01","0","2"]],"bids":[["104570","0.08689006","0","4"]],"ts":"1747170030400","checksum":-1702950588,"seqId":54226050912,"prevSeqId":54226050910}]}
{"arg":{"channel":"books","instId":"BTC-USDT"},"action":"update","data":[{"asks":[["104593.2","0.01","0","2"],["104605.6","0.00477926","0","1"],["104606.4","0","0","0"],["104608.2","0.16385169","0","1"],["104608.3","0","0","0"],["104627","0.002","0","2"],["104628","0.001","0","1"],["104629","0","0","0"],["104648","0.33","0","6"],["104649","0.16499999","0","3"],["104650","0.00032024","0","2"],["104751.9","0","0","0"]],"bids":[["104586.2","0.00296447","0","1"],["104586.1","0.0755755","0","1"],["104583.6","0","0","0"],["104583.4","0.02414361","0","1"],["104582.2","0.00115191","0","1"],["104581.1","0","0","0"],["104574.2","0","0","0"],["104573.8","0.00477926","0","1"],["104573.3","0.07298372","0","1"],["104573.2","0.1461883","0","1"],["104557.5","0.005","0","1"],["104549","0.8351024","0","2"],["104425.3","0","0","0"],["104425","0","0","0"],["104424.7","0","0","0"]],"ts":"1747170030500","checksum":-176183266,"seqId":54226050949,"prevSeqId":54226050912}]}
{"arg":{"channel":"books","instId":"BTC-USDT"},"action":"update","data":[{"asks":[["104605.6","0","0","0"],["104607.9","0.00477926","0","1"],["104620.2","0","0","0"],["104621.9","0.13859237","0","1"]],"bids":[["104576.1","0.00477926","0","1"],["104573.8","0","0","0"],["104573.7","0.91726113","0","2"],["104571.8","0","0","0"],["104425.3","0.1913","0","1"]],"ts":"1747170030600","checksum":-176183266,"seqId":54226050963,"prevSeqId":54226050949}]}
{"arg":{"channel":"books","instId":"BTC-USDT"},"action":"update","data":[{"asks":[["104620.2","0.13859374","0","1"],["104621.9","0","0","0"],["104625.8","0","0","0"],["104751.9","0.00001969","0","1"]],"bids":[["104573.7","0.77866876","0","1"],["104572.1","0.13859374","0","1"],["104425.3","0","0","0"]],"ts":"1747170030700","checksum":-176183266,"seqId":54226050970,"prevSeqId":54226050963}]}
{"arg":{"channel":"books","instId":"BTC-USDT"},"action":"update","data":[{"asks":[["104607.9","0","0","0"],["104609.1","0.00477926","0","1"],["104620.2","0","0","0"],["104620.7","0.13859293","0","1"],["104627","0","0","0"],["104628","0.002","0","2"],["104629","0.001","0","1"],["104648","0","0","0"],["104649","0.32999999","0","6"],["104650","0.16532023","0","5"],["104753.2","0.0000358","0","1"]],"bids":[["104591","0.30413281","0","14"],["104577","0.00477926","0","1"],["104576.8","0.40348847","0","1"],["104576.1","0","0","0"],["104573.7","0","0","0"],["104572.2","0.13859299","0","1"],["104572.1","0","0","0"],["104425.3","0.1913","0","1"]],"ts":"1747170030800","checksum":2083543484,"seqId":54226051007,"prevSeqId":54226050970}]}
{"arg":{"channel":"books","instId":"BTC-USDT"},"action":"update","data":[{"asks":[["104627","0.002","0","2"],["104628","0.001","0","1"],["104629","0","0","0"],["104648","0.33","0","6"],["104649","0.16499999","0","3"],["104650","0.00032024","0","2"],["104753.2","0","0","0"]],"bids":[["104576.9","0","0","0"],["104425","0.0025","0","1"]],"ts":"1747170030900","checksum":2083543484,"seqId":54226051027,"prevSeqId":54226051007}]}
{"arg":{"channel":"books","instId":"BTC-USDT"},"action":"update","data":[{"asks":[["104608.4","0.00477926","0","1"],["104609.1","0","0","0"],["104636.9","0","0","0"],["104648","0.23","0","4"],["104649","0.21499999","0","4"],["104650","0.05032024","0","3"],["104668.2","0.13309618","0","1"],["104668.3","0","0","0"],["104696.9","0.08510539","0","1"],["104753.2","0.0000358","0","1"]],"bids":[["104577","0","0","0"],["104576.8","0.40826773","0","2"],["104549","0.46418494","0","1"],["104548.5","0","0","0"],["104519.9","0.33362505","0","1"],["104517.1","0.58106157","0","2"],["104424.7","0.00001169","0","1"],["104424.3","0.00156669","0","1"]],"ts":"1747170031000","checksum":2083543484,"seqId":54226051080,"prevSeqId":54226051027}]}
{"arg":{"channel":"books","instId":"BTC-USDT"},"action":"update","data":[{"asks":[["104607.3","0.19720898","0","2"],["104608.4","0","0","0"],["104619","0.13859487","0","1"],["104620.7","0","0","0"],["104634.5","0.00056666","0","1"],["104637","1.62963077","0","2"],["104647","1","0","1"],["104647.3","0.00001","0","1"],["104648","0.33","0","6"],["104649","0.16499999","0","3"],["104650","0.00032024","0","2"],["104651.4","0.00056666","0","1"],["104668.4","2.53836376","0","1"],["104673.6","6.33420855","0","1"],["104751.5","0","0","0"],["104751.9","0","0","0"],["104753.2","0","0","0"]],"bids":[["104576.8","0.40348847","0","1"],["104575.5","0.00477926","0","1"],["104574.1","0.04825939","0","3"],["104572.2","0","0","0"],["104571","0.138595","0","1"],["104564.8","0","0","0"],["104560.7","0.00955926","0","1"],["104558.9","0","0","0"],["104548.3","1.60567774","0","2"],["104519.9","1.0489811","0","2"],["104517","2.5945232","0","2"]],"ts":"1747170031100","checksum":2083543484,"seqId":54226051141,"prevSeqId":54226051080}]}
{"arg":{"channel":"books","instId":"BTC-USDT"},"action":"update","data":[{"asks":[["104607.3","0.19242972","0","1"],["104607.9","0.00477926","0","1"],["104619","0","0","0"],["104620.2","0.13859461","0","1"],["104751.4","0","0","0"]],"bids":[["104576.1","0.00477926","0","1"],["104575.5","0","0","0"],["104571.8","0.13859461","0","1"],["104571","0","0","0"]],"ts":"1747170031200","checksum":2083543484,"seqId":54226051153,"prevSeqId":54226051141}]}
{"arg":{"channel":"books","instId":"BTC-USDT"},"action":"update","data":[{"asks":[["104607.5","0.00478926","0","2"],["104607.9","0","0","0"],["104619","0.13859499","0","1"],["104620.2","0","0","0"],["104751.4","0.00090664","0","1"]],"bids":[["104591","0.30493281","0","15"],["104576.1","0","0","0"],["104575.5","0.00477926","0","1"],["104571.8","0","0","0"],["104571","0.13859499","0","1"]],"ts":"1747170031300","checksum":360773280,"seqId":54226051163,"prevSeqId":54226051153}]}
{"arg":{"channel":"books","instId":"BTC-USDT"},"action":"update","data":[{"asks":[["104751.4","0","0","0"],["104751.5","0.01448136","0","1"]],"bids":[],"ts":"1747170031400","checksum":360773280,"seqId":54226051165,"prevSeqId":54226051163}]}
{"arg":{"channel":"books","instId":"BTC-USDT"},"action":"update","data":[{"asks":[["104591.1","0.46098931","0","11"],["104595.8","0.00067735","0","1"],["104599.6","0.12450891","0","3"],["104599.8","0","0","0"],["104599.9","0","0","0"],["104600.1","0.0995806","0","1"],["104600.4","0","0","0"],["104601.1","0.09435107","0","2"],["104601.4","0.036","0","1"],["104601.7","0.08933291","0","1"],["104602","0","0","0"],["104603.6","0.42137421","0","3"],["104604.6","0.15631682","0","2"],["104604.9","0","0","0"],["104605.1","0.30260026","0","2"],["104605.4","0","0","0"],["104605.6","0.00477926","0","1"],["104607.5","0.00001","0","1"],["104608","0.18811287","0","2"],["104608.2","0","0","0"],["104608.3","0.25391949","0","1"],["104608.6","0.11774395","0","3"],["104610.1","0.24047609","0","1"],["104610.4","0","0","0"],["104610.6","0.59803578","0","3"],["104610.9","0","0","0"],["104614.2","0.23713667","0","1"],["104614.5","0.00478052","0","1"],["104619","0.13859517","0","1"],["104751.9","0.00001969","0","1"]],"bids":[["104586.2","0","0","0"],["104586.1","0.07854647","0","2"],["104580.9","0","0","0"],["104580.6","0.19414388","0","2"],["104580.2","0.24226209","0","2"],["104579.5","0","0","0"],["104579.2","0.08985216","0","1"],["104578.9","0","0","0"],["104578.6","0.09100995","0","1"],["104577.9","0.00099501","0","2"],["104577.6","0.16396033","0","1"],["104577.4","0","0","0"],["104577.1","0.14576654","0","1"],["104576.8","0.34422307","0","2"],["104575.9","0","0","0"],["104575.6","0.15973068","0","1"],["104575.5","0","0","0"],["104573.6","0","0","0"],["104573.4","0.00477926","0","1"],["104573.3","0.32900355","0","2"],["104573.2","0","0","0"],["104573","0.16371261","0","1"],["104572","0.29912159","0","3"],["104571","0","0","0"],["104570.9","0","0","0"],["104570.6","0.24929469","0","1"],["104570.1","0.13859605","0","1"],["104567.9","0.00001","0","1"],["104567.6","0.24285618","0","1"],["104567","0","0","0"],["104566.7","0.24758438","0","1"],["104549","0.83347233","0","2"]],"ts":"1747170031500","checksum":-1820859737,"seqId":54226051287,"prevSeqId":54226051165}]}
{"arg":{"channel":"books","instId":"BTC-USDT"},"action":"update","data":[{"asks":[["104591.1","0.57136931","0","12"],["104593.5","0.02888713","0","1"],["104593.9","0.19781203","0","1"],["104595.4","0","0","0"],["104595.8","0.3893092","0","2"],["104596","0.10416561","0","2"],["104597.1","0","0","0"],["104599.6","0.00001","0","1"],["104600.1","0","0","0"],["104601.1","0.00068985","0","2"],["104601.7","0","0","0"],["104602","0.00477927","0","1"],["104603.6","0.32985488","0","3"],["104604.6","0.00478052","0","1"],["104605.1","0","0","0"],["104605.6","0","0","0"],["104608","0.02812301","0","1"],["104608.3","0","0","0"],["104610.1","0","0","0"],["104610.6","0.3556784","0","2"],["104614.2","0","0","0"],["104614.5","0.14338131","0","2"],["104619","0","0","0"],["104645.9","0.02083819","0","1"],["104647.6","0.01970158","0","1"],["104751.4","0.00090586","0","1"],["104753.2","0.0000358","0","1"],["104753.3","2.3905","0","1"],["104754.2","0.00089983","0","1"],["104754.7","0.00001","0","1"]],"bids":[["104591","0.12282739","0","11"],["104590.6","0","0","0"],["104589.9","0","0","0"],["104589.2","0.02256561","0","1"],["104587.8","0","0","0"],["104586.1","0.052716","0","1"],["104585.8","0","0","0"],["104584.3","0","0","0"],["104583.4","0","0","0"],["104582.2","0","0","0"],["104581.1","0.02414413","0","1"],["104580.9","0.00296763","0","1"],["104580.6","0","0","0"],["104580.3","0.00115191","0","1"],["104580.2","0.17371793","0","1"],["104579.2","0","0","0"],["104578.6","0","0","0"],["104578.5","0.07256639","0","2"],["104578.4","0.29193486","0","1"],["104577.6","0","0","0"],["104577.1","0","0","0"],["104576.8","0.26128502","0","2"],["104576.6","0","0","0"],["104576.4","0.07462397","0","2"],["104575.6","0","0","0"],["104573.4","0","0","0"],["104573.3","0.07298372","0","1"],["104573","0","0","0"],["104572","0.34515434","0","3"],["104570.6","0","0","0"],["104570.1","0","0","0"],["104569.5","0.00477927","0","1"],["104567.6","0","0","0"],["104566.9","0.13860079","0","1"],["104566.8","0.24574768","0","2"],["104566.7","0","0","0"],["104565","0","0","0"],["104560.8","0.2298392","0","3"],["104560.3","0","0","0"],["104560.1","0","0","0"],["104553.9","0.1778392","0","1"],["104535","0.002868","0","1"],["104529.7","0","0","0"],["104440.1","0.00095583","0","1"],["104438.9","0","0","0"],["104424","0.01401013","0","1"],["104423.5","0.01448485","0","1"],["104423","0.00071959","0","4"],["104422.9","0.01089593","0","1"],["104422.8","0.00094847","0","1"],["104422.7","0.01089657","0","1"],["104421.8","0.77866876","0","1"],["104421.7","0.07298372","0","1"],["104421.4","0.0001842","0","1"],["104421","0.00003591","0","3"],["104420.5","0.03","0","1"],["104420.3","0.03","0","1"],["104420","0.00276552","0","3"],["104419.4","0.00003046","0","1"],["104418.9","0.00005586","0","1"],["104418.4","0.0001","0","1"],["104418.1","0.00004752","0","1"]],"ts":"1747170031600","checksum":1448359949,"seqId":54226051615,"prevSeqId":54226051287}]}
{"arg":{"channel":"books","instId":"BTC-USDT"},"action":"update","data":[{"asks":[["104591.1","0.81136931","0","13"],["104593.9","0.28697786","0","2"],["104594.7","0.02628359","0","1"],["104595.7","0.00067735","0","1"],["104595.8","0.38863185","0","1"],["104595.9","0","0","0"],["104599.2","0.095126","0","1"],["104599.7","0.09386847","0","1"],["104601.1","0.0000125","0","1"],["104601.3","0.08966594","0","1"],["104602","0","0","0"],["104602.2","0.08473845","0","2"],["104603.3","0.00477928","0","1"],["104603.6","0.42109758","0","3"],["104604.7","0.32176196","0","2"],["104607.9","0.24233759","0","1"],["104609.7","0.92033008","0","2"],["104610.2","0.26133178","0","1"],["104610.8","0","0","0"],["104613.8","0.65705827","0","2"],["104614.2","0.13860149","0","1"],["104614.5","0.00478052","0","1"],["104731.9","0","0","0"],["104751.5","0","0","0"],["104751.9","0","0","0"],["104753.2","0","0","0"],["104753.3","0","0","0"],["104754.2","0","0","0"],["104754.7","0","0","0"]],"bids":[["104591","0.24552739","0","13"],["104589.2","0","0","0"],["104586.7","0.0833349","0","1"],["104586.6","0.102063","0","1"],["104586.1","0","0","0"],["104583.3","0.00296973","0","1"],["104583.1","0.02790326","0","1"],["104582.1","0.08125761","0","2"],["104580.9","0","0","0"],["104580.2","0.33628941","0","3"],["104578.8","0.09789952","0","1"],["104578.2","0.09725447","0","1"],["104577.2","0.15669301","0","1"],["104576.8","0.28722176","0","2"],["104575.2","0.15880831","0","1"],["104572.9","0.2485717","0","1"],["104572.6","0.16001372","0","1"],["104572","0.26501696","0","3"],["104570.2","0.23907231","0","1"],["104570.1","0.00477928","0","1"],["104569.5","0","0","0"],["104567.2","0.25711126","0","1"],["104566.9","0","0","0"],["104566.8","0.22328005","0","2"],["104566.3","0.2600147","0","1"],["104565","0.13860149","0","1"],["104529.7","0.1913","0","1"],["104454.5","0.01089655","0","1"],["104422.7","0","0","0"],["104421.8","0","0","0"],["104421.7","0","0","0"],["104421.4","0","0","0"],["104421","0","0","0"],["104420.5","0","0","0"],["104420.3","0","0","0"],["104420","0","0","0"],["104419.4","0","0","0"],["104418.9","0","0","0"],["104418.4","0","0","0"],["104418.1","0","0","0"]],"ts":"1747170031700","checksum":-172908226,"seqId":54226051836,"prevSeqId":54226051615}]}
{"arg":{"channel":"books","instId":"BTC-USDT"},"action":"update","data":[{"asks":[["104599.2","0","0","0"],["104599.3","0.10132384","0","2"],["104600.7","0.09480254","0","1"],["104603.3","0","0","0"],["104603.6","0.33382925","0","3"],["104604.2","0.15596374","0","2"],["104604.5","0.00477928","0","1"],["104604.7","0.16801745","0","1"],["104604.8","0.16019793","0","1"],["104607.6","0.19566159","0","2"],["104607.9","0","0","0"],["104608","0.28545262","0","2"],["104610.2","0","0","0"],["104610.3","0.26194239","0","1"],["104614.2","0","0","0"],["104615.5","0.1386107","0","2"],["104751.4","0.00090541","0","1"],["104751.5","0.01448136","0","1"]],"bids":[["104589.2","0.02256561","0","1"],["104588.1","0.02604481","0","1"],["104580.8","0.00115191","0","1"],["104580.3","0.29308299","0","1"],["104580.2","0.17774262","0","2"],["104578.3","0.09654832","0","1"],["104578.2","0","0","0"],["104577.3","0.15735653","0","1"],["104577.2","0","0","0"],["104576.7","0.14793501","0","1"],["104573","0.2571139","0","1"],["104572.9","0","0","0"],["104572.8","0.00477928","0","1"],["104572.6","0.14689056","0","1"],["104570.1","0","0","0"],["104567.3","0.40911779","0","2"],["104567.2","0","0","0"],["104565","0","0","0"],["104529.7","0","0","0"],["104440.1","0","0","0"],["104438.9","0.00095584","0","1"],["104422.9","0","0","0"],["104422.8","0","0","0"]],"ts":"1747170031800","checksum":-1292964236,"seqId":54226051894,"prevSeqId":54226051836}]}
{"arg":{"channel":"books","instId":"BTC-USDT"},"action":"update","data":[{"asks":[["104591.1","0.57136931","0","12"],["104604.5","0","0","0"],["104605.6","0.00477928","0","1"],["104648","0","0","0"],["104649","0.32999999","0","6"],["104650","0.16532023","0","5"],["104751.4","0","0","0"],["104751.9","0.00001969","0","1"],["104753.2","0.0000358","0","1"]],"bids":[["104583.9","0.00297097","0","1"],["104583.3","0","0","0"],["104573.4","0.00477928","0","1"],["104572.8","0","0","0"],["104572","0.34892435","0","2"],["104567.4","0.19244473","0","2"],["104561","0.38863185","0","1"],["104560.9","0.77866876","0","1"],["104538.8","0.00001","0","1"],["104529.7","0.1913","0","1"],["104424.3","0","0","0"],["104424","0","0","0"],["104423.5","0","0","0"],["104423","0","0","0"]],"ts":"1747170031900","checksum":2093853398,"seqId":54226051931,"prevSeqId":54226051894}]}
{"arg":{"channel":"books","instId":"BTC-USDT"},"action":"update","data":[{"asks":[["104591.1","0.33736931","0","11"],["104605.6","0","0","0"],["104607.2","0.00477928","0","1"],["104615.5","0.00001","0","1"],["104617.6","0.13859941","0","1"],["104627","0","0","0"],["104628","0.002","0","2"],["104629","0.001","0","1"],["104699.3","0.02503784","0","3"],["104753.2","0","0","0"]],"bids":[["104574.2","0.00477928","0","1"],["104573.4","0","0","0"],["104567.5","0.14050941","0","2"],["104567.3","0.27051709","0","1"]],"ts":"1747170032000","checksum":541411072,"seqId":54226051946,"prevSeqId":54226051931}]}
{"arg":{"channel":"books","instId":"BTC-USDT"},"action":"update","data":[{"asks":[["104591.1","0.57136931","0","12"],["104598.3","0.01911962","0","1"],["104599.7","0.09589771","0","1"],["104601.3","0.10034788","0","1"],["104603.7","0","0","0"],["104604.7","0.1650187","0","1"],["104606.4","0.00477928","0","1"],["104607.2","0","0","0"],["104609.7","0.93805001","0","2"],["104613.8","0.67080896","0","2"],["104634.5","0","0","0"],["104639.2","0.00056666","0","1"],["104651.4","0","0","0"],["104656","0.00175273","0","1"],["104656.1","0.00056666","0","1"],["104656.2","0","0","0"]],"bids":[["104584.1","0.00297119","0","1"],["104583.9","0","0","0"],["104581","0","0","0"],["104580.8","0","0","0"],["104580.4","0.00115191","0","1"],["104580.2","0.18064783","0","2"],["104578.8","0.09781217","0","1"],["104575.2","0.15413701","0","1"],["104570.2","0.2594516","0","1"],["104570.1","0.13859716","0","1"],["104567.5","0.00191","0","1"],["104566.8","0.10839825","0","1"],["104566.3","0.25043691","0","1"],["104561.4","0.00955919","0","1"],["104560.7","0","0","0"]],"ts":"1747170032100","checksum":-108233628,"seqId":54226052026,"prevSeqId":54226051946}]}
{"arg":{"channel":"books","instId":"BTC-USDT"},"action":"update","data":[{"asks":[["104597.8","0.07298372","0","1"],["104599.2","0.09537449","0","1"],["104599.3","0.0026234","0","1"],["104604.7","0.32531631","0","2"],["104604.8","0","0","0"],["104606.4","0","0","0"],["104607.2","0.00477928","0","1"],["104608","0.02812301","0","1"],["104610.2","0.26143645","0","1"],["104610.3","0","0","0"],["104617.6","0.13859674","0","1"],["104627","0.002","0","2"],["104628","0.001","0","1"],["104629","0","0","0"],["104648","0.33","0","6"],["104649","0.16499999","0","3"],["104650","0.00032024","0","2"],["104698.7","0","0","0"],["104699.2","0.00009132","0","1"],["104751.5","0","0","0"],["104751.9","0","0","0"]],"bids":[["104591","0.24472739","0","12"],["104585.9","0","0","0"],["104580.3","0.2177569","0","1"],["104578.3","0","0","0"],["104578.2","0.09776018","0","1"],["104577.3","0","0","0"],["104577.2","0.14929315","0","1"],["104575.3","0.00477928","0","1"],["104574.2","0","0","0"],["104573","0","0","0"],["104570.1","0","0","0"],["104567.5","0.14050726","0","2"],["104567.3","0","0","0"],["104567.2","0.24266074","0","1"],["104491.8","0","0","0"],["104491.3","0.00010156","0","1"],["104424.3","0.00156669","0","1"],["104424","0.01401013","0","1"],["104423.5","0.01448485","0","1"]],"ts":"1747170032200","checksum":2097877607,"seqId":54226052089,"prevSeqId":54226052026}]}
{"arg":{"channel":"books","instId":"BTC-USDT"},"action":"update","data":[{"asks":[["104599.2","0","0","0"],["104599.3","0.10022769","0","2"],["104604.5","0.00477928","0","1"],["104604.7","0.1650187","0","1"],["104604.8","0.15282104","0","1"],["104607.2","0","0","0"],["104608","0.27801867","0","2"],["104610.2","0","0","0"],["104610.3","0.26783566","0","1"],["104617.5","0.13859932","0","1"],["104617.6","0","0","0"],["104626","0.002","0","2"],["104627","0.001","0","1"],["104628","0","0","0"]],"bids":[["104582.1","0.09325761","0","3"],["104578.3","0.09859046","0","1"],["104578.2","0","0","0"],["104577.3","0.17033731","0","1"],["104577.2","0","0","0"],["104575.3","0","0","0"],["104573","0.23571664","0","1"],["104572.8","0.00477928","0","1"],["104567.3","0.26221176","0","1"],["104567.2","0","0","0"],["104423.5","0","0","0"]],"ts":"1747170032300","checksum":-894801847,"seqId":54226052141,"prevSeqId":54226052089}]}
{"arg":{"channel":"books","instId":"BTC-USDT"},"action":"update","data":[{"asks":[],"bids":[["104491.8","0.00009615","0","1"],["104491.3","0","0","0"]],"ts":"1747170032400","checksum":-894801847,"seqId":54226052150,"prevSeqId":54226052141}]}
{"arg":{"channel":"books","instId":"BTC-USDT"},"action":"update","data":[{"asks":[["104591.1","0.33736931","0","11"],["104593.9","0.09496288","0","1"],["104595.7","0","0","0"],["104595.8","0","0","0"],["104596.6","0","0","0"],["104599.2","0.00067735","0","1"],["104599.7","0","0","0"],["104601.3","0","0","0"],["104604.5","0","0","0"],["104604.7","0","0","0"],["104605.6","0.00477928","0","1"],["104609.7","0.67560716","0","1"],["104613.8","0.40973638","0","1"],["104668.2","0.87796828","0","2"],["104682.9","0.06391669","0","3"],["104696.9","0","0","0"],["104751.5","0.01448136","0","1"],["104751.9","0.00001969","0","1"],["104753.2","0.0000358","0","1"],["104753.3","2.3905","0","1"],["104754.2","0.00089983","0","1"],["104754.7","0.00001","0","1"]],"bids":[["104580.2","0.08727783","0","1"],["104578.8","0","0","0"],["104575.2","0","0","0"],["104573.4","0.00477928","0","1"],["104572.8","0","0","0"],["104570.2","0","0","0"],["104566.3","0","0","0"],["104561.1","0.49151197","0","1"],["104423.5","0.01448485","0","1"],["104423","0.00071959","0","4"],["104422.9","0.01089593","0","1"]],"ts":"1747170032600","checksum":1115121858,"seqId":54226052204,"prevSeqId":54226052150}]}
{"arg":{"channel":"books","instId":"BTC-USDT"},"action":"update","data":[{"asks":[["104593.9","0","0","0"],["104599.2","0","0","0"],["104599.3","0.00330075","0","2"],["104599.4","0.10219274","0","1"],["104599.9","0.09808959","0","1"],["104600.7","0","0","0"],["104600.9","0.09488349","0","1"],["104601.5","0.10028377","0","1"],["104603.6","0.41690205","0","3"],["104604.2","0.00093","0","1"],["104604.4","0.14729577","0","1"],["104604.8","0","0","0"],["104604.9","0.32099331","0","2"],["104605.6","0","0","0"],["104606.4","0.00477928","0","1"],["104607.6","0.04","0","1"],["104607.8","0.15059007","0","1"],["104608","0.02812301","0","1"],["104608.1","0.24007658","0","1"],["104609.9","0.26919332","0","1"],["104610.3","0","0","0"],["104610.4","0.27022891","0","1"],["104614","0.26505455","0","1"],["104617.5","0","0","0"],["104619","0.1385966","0","1"],["104626","0","0","0"],["104627","0.002","0","2"],["104628","0.001","0","1"],["104648","0","0","0"],["104649","0.32999999","0","6"],["104650","0.16532023","0","5"],["104751.9","0","0","0"],["104753.2","0","0","0"],["104753.3","0","0","0"],["104754.2","0","0","0"],["104754.7","0","0","0"]],"bids":[["104591","0.28157739","0","14"],["104580.8","0.00115191","0","1"],["104580.4","0.18531916","0","2"],["104580.3","0.22291264","0","2"],["104580.2","0","0","0"],["104579","0.09458675","0","1"],["104578.4","0.38252916","0","2"],["104578.3","0","0","0"],["104577.4","0.16638932","0","1"],["104577.3","0","0","0"],["104576.9","0.15622901","0","1"],["104576.8","0.29091705","0","2"],["104576.7","0","0","0"],["104575.4","0.20275427","0","2"],["104574.2","0.00477928","0","1"],["104573.4","0","0","0"],["104573.1","0.23917504","0","1"],["104573","0","0","0"],["104572.8","0.16211273","0","1"],["104572.6","0","0","0"],["104572","0.27608392","0","3"],["104570.4","0.39011328","0","2"],["104567.5","0.00191","0","1"],["104567.4","0.440052","0","3"],["104567.3","0","0","0"],["104566.5","0.24318712","0","1"],["104422.9","0","0","0"]],"ts":"1747170032700","checksum":897378619,"seqId":54226052339,"prevSeqId":54226052204}]}
{"arg":{"channel":"books","instId":"BTC-USDT"},"action":"update","data":[{"asks":[["104593.1","0.1515543","0","2"],["104596.8","0.19242972","0","1"],["104606.4","0","0","0"],["104607.9","0.00477928","0","1"],["104626","0.002","0","2"],["104627","0.001","0","1"],["104628","0","0","0"],["104647","0","0","0"],["104648","0.16","0","2"],["104649","0.24999999","0","5"],["104650","0.08532024","0","4"],["104682.9","0.02149395","0","2"],["104750.7","0","0","0"],["104751.5","0","0","0"]],"bids":[["104576.4","0.07940325","0","3"],["104574.2","0","0","0"],["104422.9","0.01089593","0","1"]],"ts":"1747170032800","checksum":2120591078,"seqId":54226052373,"prevSeqId":54226052339}]}
{"arg":{"channel":"books","instId":"BTC-USDT"},"action":"update","data":[{"asks":[["104607.5","0.00478928","0","2"],["104607.9","0","0","0"],["104617.6","0.13859733","0","1"],["104619","0","0","0"],["104625","0.002","0","2"],["104626","0.001","0","1"],["104627","0","0","0"],["104646","0.16","0","2"],["104647","0.07999999","0","1"],["104648","0","0","0"],["104649","0.17","0","4"]],"bids":[["104576.4","0.07462397","0","2"],["104575.5","0.00477928","0","1"],["104570.4","0.25151668","0","1"],["104570.1","0.13859711","0","1"],["104423","0","0","0"],["104422.9","0","0","0"]],"ts":"1747170032900","checksum":2120591078,"seqId":54226052405,"prevSeqId":54226052373}]}
{"arg":{"channel":"books","instId":"BTC-USDT"},"action":"update","data":[{"asks":[["104591.1","0.57136931","0","12"],["104599.2","0.00067735","0","1"],["104599.3","0.10184794","0","2"],["104599.4","0","0","0"],["104599.7","0.09324279","0","1"],["104599.9","0","0","0"],["104600.7","0.09094208","0","1"],["104600.9","0","0","0"],["104601.3","0.0946086","0","1"],["104601.5","0","0","0"],["104603.6","0.41228943","0","3"],["104604.2","0.14846057","0","2"],["104604.4","0","0","0"],["104604.7","0.15279559","0","1"],["104604.8","0.1693315","0","1"],["104604.9","0","0","0"],["104607.2","0.00477935","0","1"],["104607.5","0.00001","0","1"],["104607.6","0.19832317","0","2"],["104607.8","0","0","0"],["104608","0.25702409","0","2"],["104608.1","0","0","0"],["104609.7","0.91910496","0","2"],["104609.9","0","0","0"],["104610.3","0.24769159","0","1"],["104610.4","0","0","0"],["104613.8","0.66201903","0","2"],["104614","0","0","0"],["104750.7","0.00049233","0","7"],["104751.5","0.01448136","0","1"],["104751.9","0.00001969","0","1"]],"bids":[["104591","0.24557739","0","13"],["104580.8","0","0","0"],["104580.4","0.00115191","0","1"],["104580.3","0.27806068","0","2"],["104580.2","0.18442791","0","2"],["104579","0","0","0"],["104578.8","0.09081626","0","1"],["104578.4","0.29193486","0","1"],["104578.3","0.09684307","0","1"],["104577.4","0","0","0"],["104577.3","0.16330992","0","1"],["104576.9","0","0","0"],["104576.8","0.36375105","0","2"],["104576.7","0.14725972","0","1"],["104575.5","0","0","0"],["104575.4","0.036","0","1"],["104575.2","0.16580699","0","1"],["104574.2","0.00477935","0","1"],["104573.1","0","0","0"],["104573","0.25336287","0","1"],["104572.8","0","0","0"],["104572.6","0.16231625","0","1"],["104572","0.36019503","0","3"],["104570.4","0","0","0"],["104570.2","0.2699308","0","1"],["104570.1","0","0","0"],["104567.5","0.14050721","0","2"],["104567.4","0.19244473","0","2"],["104567.3","0.25804622","0","1"],["104566.5","0","0","0"],["104566.3","0.26248204","0","1"],["104424","0","0","0"],["104423.5","0","0","0"]],"ts":"1747170033000","checksum":2139822027,"seqId":54226052477,"prevSeqId":54226052405}]}
{"arg":{"channel":"books","instId":"BTC-USDT"},"action":"update","data":[{"asks":[["104599.2","0","0","0"],["104599.3","0.09830845","0","2"],["104599.6","0.00068735","0","2"],["104604.8","0.16392787","0","1"],["104610.3","0.24441436","0","1"],["104625","0","0","0"],["104626","0.002","0","2"],["104627","0.001","0","1"],["104638.7","0.09617666","0","2"],["104639.2","0","0","0"],["104646","0","0","0"],["104647","0","0","0"],["104648","0.26","0","4"],["104649","0.19999999","0","4"],["104650","0.03532024","0","3"],["104655.6","0.80848273","0","2"],["104656.1","0","0","0"],["104753.2","0.0000358","0","1"],["104753.3","2.3905","0","1"],["104754","0.234","0","1"],["104754.2","0.00089983","0","1"]],"bids":[["104578.3","0.09778351","0","1"],["104577.3","0.16268469","0","1"],["104567.3","0.25674828","0","1"],["104562.2","0.01146912","0","2"],["104561.4","0","0","0"],["104424","0.01401013","0","1"]],"ts":"1747170033100","checksum":-1516407694,"seqId":54226052522,"prevSeqId":54226052477}]}
{"arg":{"channel":"books","instId":"BTC-USDT"},"action":"update","data":[{"asks":[["104656","0","0","0"],["104656.2","0.00175273","0","1"],["104751.4","0.0009034","0","1"],["104754.2","0","0","0"]],"bids":[],"ts":"1747170033200","checksum":-1516407694,"seqId":54226052548,"prevSeqId":54226052522}]}
{"arg":{"channel":"books","instId":"BTC-USDT"},"action":"update","data":[{"asks":[["104599.2","0.00067735","0","1"],["104599.3","0.09412727","0","2"],["104599.6","0.00001","0","1"],["104599.7","0.09021806","0","1"],["104600.7","0.08960351","0","1"],["104601.3","0.09129339","0","1"],["104603.6","0.41629816","0","3"],["104604.2","0.14743035","0","2"],["104604.7","0.16995296","0","1"],["104604.8","0.16720397","0","1"],["104607.6","0.19616615","0","2"],["104608","0.25854393","0","2"],["104609.7","0.93203076","0","2"],["104610.3","0.24346572","0","1"],["104613.8","0.64283719","0","2"],["104648","0.33","0","6"],["104649","0.16499999","0","3"],["104650","0.00032024","0","2"],["104754","0","0","0"]],"bids":[["104580.3","0.28086067","0","2"],["104580.2","0.18725153","0","2"],["104578.8","0.09529201","0","1"],["104578.3","0.09992819","0","1"],["104577.3","0.16225872","0","1"],["104576.8","0.35967994","0","2"],["104576.7","0.15295807","0","1"],["104575.2","0.16317238","0","1"],["104573","0.23810367","0","1"],["104572.6","0.16094136","0","1"],["104572","0.36012654","0","3"],["104570.2","0.26593116","0","1"],["104567.3","0.26181755","0","1"],["104566.3","0.23624233","0","1"]],"ts":"1747170033300","checksum":2022999684,"seqId":54226052613,"prevSeqId":54226052548}]}
{"arg":{"channel":"books","instId":"BTC-USDT"},"action":"update","data":[{"asks":[["104591.1","0.57131327","0","12"],["104599.7","0.08920822","0","1"],["104601.3","0.09263431","0","1"],["104604.7","0.15377162","0","1"],["104609.7","0.93299449","0","2"],["104613.8","0.66386934","0","2"],["104617.6","0","0","0"],["104619","0.1385964","0","1"]],"bids":[["104580.2","0.19062857","0","2"],["104578.8","0.0979006","0","1"],["104575.2","0.15484546","0","1"],["104570.3","0.1385964","0","1"],["104570.2","0.26135353","0","1"],["104567.5","0.00191","0","1"],["104566.3","0.26186341","0","1"],["104424","0","0","0"]],"ts":"1747170033400","checksum":-941806928,"seqId":54226052695,"prevSeqId":54226052613}]}
{"arg":{"channel":"books","instId":"BTC-USDT"},"action":"update","data":[{"asks":[["104617.6","0.1385973","0","1"],["104619","0","0","0"]],"bids":[["104570.3","0","0","0"],["104567.6","0.13859722","0","1"]],"ts":"1747170033500","checksum":-941806928,"seqId":54226052717,"prevSeqId":54226052695}]}
{"arg":{"channel":"books","instId":"BTC-USDT"},"action":"update","data":[{"asks":[["104591.1","0.81131327","0","13"],["104626.1","0.0085473","0","1"],["104753.3","0","0","0"]],"bids":[["104567.7","0.13859762","0","1"],["104567.6","0","0","0"],["104566.8","0.18512195","0","2"],["104534.6","0.01091535","0","1"],["104424.3","0","0","0"]],"ts":"1747170033600","checksum":-1933842708,"seqId":54226052725,"prevSeqId":54226052717}]}
{"arg":{"channel":"books","instId":"BTC-USDT"},"action":"update","data":[{"asks":[["104591.1","0.57731327","0","12"]],"bids":[["104591","0.24472739","0","12"]],"ts":"1747170033700","checksum":-2035164567,"seqId":54226052731,"prevSeqId":54226052725}]}
{"arg":{"channel":"books","instId":"BTC-USDT"},"action":"update","data":[{"asks":[["104599.2","0","0","0"],["104599.3","0.0026234","0","1"],["104599.4","0.10246334","0","1"],["104599.7","0","0","0"],["104599.9","0.09795611","0","2"],["104600.7","0","0","0"],["104600.9","0.0877148","0","1"],["104601.3","0","0","0"],["104601.5","0.09533322","0","1"],["104603.6","0.17592839","0","2"],["104604.2","0.00093","0","1"],["104604.4","0.14407273","0","1"],["104604.7","0","0","0"],["104604.8","0","0","0"],["104604.9","0.30713977","0","2"],["104607.6","0.04","0","1"],["104607.7","0.16030693","0","1"],["104608","0.02812301","0","1"],["104608.1","0.23029778","0","1"],["104609.7","0.67560716","0","1"],["104609.9","0.25131398","0","1"],["104610.3","0","0","0"],["104610.4","0.27241732","0","1"],["104613.8","0.40973638","0","1"],["104614","0.23633027","0","1"],["104617.6","0","0","0"],["104619","0.13859587","0","1"],["104751.4","0","0","0"],["104751.5","0","0","0"],["104751.9","0","0","0"],["104753.2","0","0","0"]],"bids":[["104591","0.28072739","0","13"],["104580.4","0.19283088","0","3"],["104580.3","0.1342189","0","1"],["104580.2","0","0","0"],["104579","0.09900575","0","1"],["104578.8","0","0","0"],["104578.4","0.38731493","0","2"],["104578.3","0","0","0"],["104577.4","0.15098459","0","1"],["104577.3","0","0","0"],["104576.9","0.14350897","0","1"],["104576.8","0.11340917","0","1"],["104576.7","0","0","0"],["104575.4","0.20413212","0","2"],["104575.2","0","0","0"],["104573.1","0.24229282","0","1"],["104573","0","0","0"],["104572.7","0.16290126","0","2"],["104572.6","0","0","0"],["104572","0.21897342","0","2"],["104570.3","0.13859675","0","1"],["104570.2","0","0","0"],["104567.7","0","0","0"],["104567.4","0.46431176","0","3"],["104567.3","0","0","0"],["104566.8","0.10839825","0","1"],["104566.5","0.26499825","0","1"],["104566.3","0","0","0"],["104424.3","0.00156669","0","1"],["104424","0.01401013","0","1"],["104423.5","0.01448485","0","1"],["104423","0.00071959","0","4"],["104422.9","0.01089593","0","1"],["104422.8","0.00094847","0","1"]],"ts":"1747170033800","checksum":-662067384,"seqId":54226052791,"prevSeqId":54226052731}]}
{"arg":{"channel":"books","instId":"BTC-USDT"},"action":"update","data":[{"asks":[["104599.3","0.00330075","0","2"],["104599.9","0.09727876","0","1"],["104603.6","0.40777002","0","3"],["104619","0.13859636","0","1"]],"bids":[["104580.8","0.00115191","0","1"],["104580.4","0.19167897","0","2"],["104580.3","0.22105266","0","2"],["104576.8","0.31683116","0","2"],["104572","0.28336189","0","3"],["104570.5","0.13859636","0","1"],["104570.4","0.2593622","0","1"],["104570.3","0","0","0"],["104557.1","0.412973","0","1"],["104514.1","0","0","0"],["104512.4","0","0","0"],["104422.8","0","0","0"]],"ts":"1747170033900","checksum":1397215145,"seqId":54226052812,"prevSeqId":54226052791}]}
{"arg":{"channel":"books","instId":"BTC-USDT"},"action":"update","data":[{"asks":[["104617.6","0.13859771","0","1"],["104619","0","0","0"],["104637","0.234","0","1"],["104668.2","0.13309618","0","1"],["104668.4","0","0","0"],["104679.8","0.06590451","0","2"],["104751.4","0.0009034","0","1"]],"bids":[["104570.5","0","0","0"],["104567.5","0.14050771","0","2"],["104549","0.46418494","0","1"],["104548.3","0.1778392","0","1"],["104519.9","0.33362505","0","1"],["104517","0.03249981","0","1"],["104422.8","0.00094847","0","1"]],"ts":"1747170034000","checksum":1397215145,"seqId":54226052829,"prevSeqId":54226052812}]}
{"arg":{"channel":"books","instId":"BTC-USDT"},"action":"update","data":[{"asks":[["104632.2","0.00056666","0","1"],["104635.7","1.71356231","0","1"],["104635.8","1.41420855","0","1"],["104637.6","0","0","0"],["104638.7","0.09561","0","1"],["104649.1","0.77923542","0","2"],["104655.6","0.80791607","0","1"],["104667.2","2.49099484","0","2"],["104750.7","0","0","0"],["104751.4","0","0","0"]],"bids":[["104575.5","0.00477933","0","1"],["104574.2","0","0","0"],["104567.5","0.14050722","0","2"],["104562.9","0.03955906","0","2"],["104562.2","0.00191","0","1"],["104544.2","1.37513746","0","1"],["104512.9","2.52274558","0","1"],["104422.9","0","0","0"],["104422.8","0","0","0"]],"ts":"1747170034100","checksum":1397215145,"seqId":54226052851,"prevSeqId":54226052829}]}
{"arg":{"channel":"books","instId":"BTC-USDT"},"action":"update","data":[{"asks":[["104606.4","0.00477933","0","1"],["104607.2","0","0","0"],["104607.7","0","0","0"],["104607.8","0.15372761","0","1"],["104617.6","0.13859751","0","1"],["104699.2","0","0","0"],["104750.7","0.00049233","0","7"]],"bids":[["104591","0.28330739","0","14"],["104575.5","0","0","0"],["104574.2","0.00477933","0","1"],["104572.8","0.14572234","0","1"],["104572.7","0.00098","0","1"],["104567.5","0.14050751","0","2"],["104423","0","0","0"]],"ts":"1747170034200","checksum":343137924,"seqId":54226052879,"prevSeqId":54226052851}]}
{"arg":{"channel":"books","instId":"BTC-USDT"},"action":"update","data":[{"asks":[["104600.8","0.08949671","0","1"],["104600.9","0","0","0"],["104604.3","0.1425774","0","2"],["104604.4","0","0","0"],["104605.6","0.00477935","0","1"],["104606.4","0","0","0"],["104607.7","0.14564405","0","1"],["104607.8","0","0","0"],["104751.5","0.01448136","0","1"]],"bids":[["104591","0.24730739","0","13"],["104589.2","0","0","0"],["104580.4","0.09948663","0","1"],["104580.3","0.31639209","0","3"],["104576.9","0","0","0"],["104576.8","0.4771868","0","3"],["104574.2","0","0","0"],["104573.4","0.00477935","0","1"],["104572.8","0","0","0"],["104572.7","0.16221489","0","2"],["104566.8","0.18606239","0","2"],["104538.8","0","0","0"],["104423","0.00071959","0","4"],["104422.9","0.01089593","0","1"],["104422.8","0.00094847","0","1"],["104422.7","0.01089657","0","1"]],"ts":"1747170034300","checksum":1410371657,"seqId":54226052903,"prevSeqId":54226052879}]}
{"arg":{"channel":"books","instId":"BTC-USDT"},"action":"update","data":[{"asks":[["104599.2","0.00067735","0","1"],["104599.3","0.0970582","0","2"],["104599.4","0","0","0"],["104599.8","0.09305604","0","1"],["104599.9","0","0","0"],["104600.8","0.08735446","0","1"],["104601.4","0.1257988","0","2"],["104601.5","0","0","0"],["104603.6","0.41064466","0","3"],["104604.3","0.15883905","0","2"],["104604.8","0.31481902","0","2"],["104604.9","0","0","0"],["104605.6","0","0","0"],["104606.4","0.00477935","0","1"],["104607.6","0.18773144","0","2"],["104607.7","0","0","0"],["104608","0.25814534","0","2"],["104608.1","0","0","0"],["104609.8","0.62827691","0","2"],["104609.9","0","0","0"],["104610.3","0.26992703","0","1"],["104610.4","0","0","0"],["104613.9","0.53571099","0","2"],["104614","0","0","0"],["104617.6","0.13859916","0","1"],["104751.9","0.00001969","0","1"],["104753.2","0.0000358","0","1"],["104753.3","2.3905","0","1"],["104754","0.234","0","1"],["104754.2","0.00089983","0","1"]],"bids":[["104590.4","0.02256561","0","1"],["104580.8","0","0","0"],["104580.4","0.00115191","0","1"],["104580.3","0.41351734","0","4"],["104579","0","0","0"],["104578.9","0.09945455","0","1"],["104578.4","0.29193486","0","1"],["104578.3","0.09365824","0","1"],["104577.4","0","0","0"],["104577.3","0.15189152","0","1"],["104576.8","0.45767113","0","3"],["104575.4","0.036","0","1"],["104575.3","0.14943563","0","1"],["104574.2","0.00477935","0","1"],["104573.4","0","0","0"],["104573.1","0","0","0"],["104573","0.25501311","0","1"],["104572.7","0.00098","0","1"],["104572.6","0.14818405","0","1"],["104572","0.3482721","0","3"],["104570.4","0","0","0"],["104570.3","0.24454907","0","1"],["104567.4","0.19244473","0","2"],["104567.3","0.24368456","0","1"],["104566.8","0.10839825","0","1"],["104566.5","0","0","0"],["104566.4","0.25280104","0","1"],["104423","0","0","0"],["104422.9","0","0","0"],["104422.8","0","0","0"],["104422.7","0","0","0"]],"ts":"1747170034400","checksum":948240970,"seqId":54226053050,"prevSeqId":54226052903}]}
{"arg":{"channel":"books","instId":"BTC-USDT"},"action":"update","data":[{"asks":[["104698.7","0.00009339","0","1"],["104754.2","0","0","0"]],"bids":[],"ts":"1747170034500","checksum":948240970,"seqId":54226053051,"prevSeqId":54226053050}]}
{"arg":{"channel":"books","instId":"BTC-USDT"},"action":"update","data":[{"asks":[["104591.1","0.33731327","0","11"],["104676.3","0","0","0"],["104754.2","0.00089983","0","1"]],"bids":[["104545.8","0.82100945","0","3"],["104514.1","0.99131327","0","1"],["104423.5","0","0","0"]],"ts":"1747170034600","checksum":1582773194,"seqId":54226053088,"prevSeqId":54226053051}]}
{"arg":{"channel":"books","instId":"BTC-USDT"},"action":"update","data":[{"asks":[["104599.2","0","0","0"],["104599.8","0","0","0"],["104599.9","0.00067735","0","1"],["104604.8","0.16358764","0","1"],["104606.4","0","0","0"],["104607.2","0.00477934","0","1"],["104607.6","0.04","0","1"],["104607.7","0.15177154","0","1"],["104609.8","0.38863185","0","1"],["104676.3","0.00004128","0","1"],["104751.4","0.00090786","0","1"],["104754","0","0","0"],["104754.2","0","0","0"]],"bids":[["104581.2","0.00011863","0","1"],["104580.3","0.31845858","0","3"],["104575.3","0","0","0"],["104572.7","0.14955631","0","2"],["104572.6","0","0","0"],["104570.3","0","0","0"],["104423.5","0.01448485","0","1"],["104423","0.00071959","0","4"]],"ts":"1747170034700","checksum":1178197617,"seqId":54226053107,"prevSeqId":54226053088}]}
{"arg":{"channel":"books","instId":"BTC-USDT"},"action":"update","data":[{"asks":[["104591.1","0.23520542","0","11"],["104597.8","0","0","0"],["104599.3","0.0026234","0","1"],["104599.5","0.1020846","0","1"],["104599.9","0","0","0"],["104600.8","0","0","0"],["104601","0.08707193","0","2"],["104601.4","0.036","0","1"],["104601.6","0.09864441","0","1"],["104603.6","0.17592839","0","2"],["104604.3","0.0000125","0","1"],["104604.5","0.14285704","0","1"],["104604.8","0","0","0"],["104605","0.1604247","0","1"],["104607.7","0","0","0"],["104607.8","0.15801929","0","1"],["104608","0.02812301","0","1"],["104608.2","0.24319817","0","1"],["104610.3","0","0","0"],["104610.5","0.27061253","0","1"],["104613.9","0.26864","0","1"],["104614.1","0.25300976","0","1"],["104676.3","0","0","0"],["104753.2","0","0","0"],["104753.3","0","0","0"]],"bids":[["104580.5","0.08838384","0","1"],["104580.3","0.1342189","0","1"],["104579.1","0.09405389","0","1"],["104578.9","0","0","0"],["104578.5","0.16377854","0","3"],["104578.3","0","0","0"],["104577.5","0.15508996","0","1"],["104577.3","0","0","0"],["104577","0.15967485","0","1"],["104576.8","0.18958252","0","1"],["104575.5","0.00477934","0","1"],["104574.2","0","0","0"],["104573.2","0.25073712","0","1"],["104573","0","0","0"],["104572.8","0.14848612","0","1"],["104572.7","0.00098","0","1"],["104572","0.21897342","0","2"],["104570.1","0.13859711","0","1"],["104567.5","0.24087104","0","2"],["104567.3","0","0","0"],["104566.6","0.24381826","0","1"],["104566.4","0","0","0"],["104423.5","0","0","0"],["104423","0","0","0"]],"ts":"1747170034800","checksum":-1543256718,"seqId":54226053165,"prevSeqId":54226053107}]}
{"arg":{"channel":"books","instId":"BTC-USDT"},"action":"update","data":[{"asks":[["104599.4","0.00067735","0","1"],["104601","0.08639458","0","1"],["104603.6","0.36657461","0","3"],["104607.2","0","0","0"],["104608.1","0.00477934","0","1"],["104617.6","0","0","0"],["104619","0.13859551","0","1"],["104648","0.23","0","4"],["104649","0.21499999","0","4"],["104650","0.05032024","0","3"],["104751.9","0","0","0"]],"bids":[["104580.8","0.00115191","0","1"],["104580.4","0","0","0"],["104580.3","0.21954833","0","2"],["104576.5","0.00477934","0","1"],["104575.5","0","0","0"],["104572","0.2734902","0","3"],["104570.1","0.13859688","0","1"]],"ts":"1747170034900","checksum":-1715073792,"seqId":54226053215,"prevSeqId":54226053165}]}
{"arg":{"channel":"books","instId":"BTC-USDT"},"action":"update","data":[{"asks":[["104608.1","0","0","0"],["104609.1","0.00477934","0","1"],["104648","0.33","0","6"],["104649","0.16499999","0","3"],["104650","0.00032024","0","2"],["104676.3","0.00004128","0","1"],["104751.5","0","0","0"]],"bids":[["104586.1","0.00297845","0","1"],["104584.1","0","0","0"],["104577.1","0.00477934","0","1"],["104576.5","0","0","0"]],"ts":"1747170035000","checksum":506925425,"seqId":54226053229,"prevSeqId":54226053215}]}
{"arg":{"channel":"books","instId":"BTC-USDT"},"action":"update","data":[{"asks":[["104596.9","0","0","0"],["104599.4","0","0","0"],["104600.9","0.00067735","0","1"],["104632.2","0","0","0"],["104632.9","0.00056666","0","1"],["104649.1","0.77866876","0","1"],["104649.8","0.00276666","0","2"],["104751.5","0.01448136","0","1"]],"bids":[["104586.1","0","0","0"],["104584.1","0.0029783","0","1"],["104563.6","0.00955899","0","1"],["104562.9","0.03","0","1"],["104424","0","0","0"]],"ts":"1747170035100","checksum":-1087239633,"seqId":54226053240,"prevSeqId":54226053229}]}
{"arg":{"channel":"books","instId":"BTC-USDT"},"action":"update","data":[{"asks":[["104591.2","0","0","0"],["104593.3","0","0","0"],["104602.3","0.045","0","1"],["104615","0.002","0","1"],["104619","0.13859503","0","1"],["104625","0.002","0","2"],["104626","0.001","0","1"],["104627","0","0","0"],["104627.5","0.002","0","1"],["104646","0.33","0","6"],["104647","0.16499999","0","3"],["104648","0","0","0"],["104648.9","0","0","0"],["104649","0","0","0"],["104751.4","0","0","0"],["104751.9","0.00001969","0","1"]],"bids":[["104591","0.24472739","0","12"],["104588.7","0.002","0","1"],["104581.2","0","0","0"],["104576.8","0.29551703","0","2"],["104576.2","0.002","0","1"],["104574.1","0.04625939","0","2"],["104570.1","0.13859503","0","1"],["104569.4","0","0","0"],["104561.6","0","0","0"],["104556.9","0.000015","0","1"],["104424","0.01401013","0","1"]],"ts":"1747170035200","checksum":1780171397,"seqId":54226053289,"prevSeqId":54226053240}]}
{"arg":{"channel":"books","instId":"BTC-USDT"},"action":"update","data":[{"asks":[["104591.1","0.11250542","0","9"],["104593.1","0","0","0"],["104596","0.0816","0","1"],["104646","0.26","0","4"],["104647","0.12999999","0","2"],["104648","0.07","0","2"],["104649","0.035","0","1"],["104751.4","0.0009076","0","1"],["104751.5","0","0","0"],["104751.9","0","0","0"]],"bids":[["104581.2","0.00011863","0","1"],["104578.1","0.19242972","0","1"],["104576.8","0.59088717","0","1"],["104573.5","0.77866876","0","1"],["104573.4","0.38863185","0","1"],["104425","0","0","0"],["104424.7","0","0","0"],["104424.3","0","0","0"],["104424","0","0","0"]],"ts":"1747170035300","checksum":-1849806456,"seqId":54226053344,"prevSeqId":54226053289}]}
{"arg":{"channel":"books","instId":"BTC-USDT"},"action":"update","data":[{"asks":[["104593.5","0","0","0"],["104596.8","0","0","0"],["104599.5","0","0","0"],["104600.1","0.00067735","0","1"],["104600.2","0.09025929","0","1"],["104600.4","0.05159776","0","1"],["104600.9","0","0","0"],["104601","0","0","0"],["104601.2","0.12061487","0","1"],["104601.6","0","0","0"],["104601.7","0.09766819","0","1"],["104602.3","0.14412592","0","2"],["104602.8","0","0","0"],["104603.6","0.24867691","0","3"],["104604.5","0","0","0"],["104605","0","0","0"],["104605.2","0.23402374","0","3"],["104605.7","0.16426247","0","3"],["104607.8","0","0","0"],["104607.9","0.0047793","0","1"],["104608.2","0","0","0"],["104608.5","0.15258448","0","1"],["104608.9","0.25937029","0","1"],["104609.1","0","0","0"],["104610.5","0","0","0"],["104611.2","0.26311651","0","1"],["104614.1","0","0","0"],["104614.8","0.26109892","0","1"],["104619","0","0","0"],["104621.8","0.13859245","0","1"],["104625","0","0","0"],["104626","0","0","0"],["104627","0.002","0","2"],["104628","0.001","0","1"],["104645.9","0","0","0"],["104646","0","0","0"],["104647","1","0","1"],["104647.6","0","0","0"],["104648","0","0","0"],["104649","0.32999999","0","6"],["104650","0.16532023","0","5"],["104751.5","0.01448136","0","1"],["104751.9","0.00001969","0","1"],["104753.2","0.0000358","0","1"],["104753.3","2.3905","0","1"],["104754","0.234","0","1"],["104754.2","0.00089983","0","1"],["104754.7","0.00001","0","1"],["104755","0.00001787","0","1"],["104755.1","0.00010283","0","1"]],"bids":[["104591","0.25029739","0","13"],["104586.8","0.00297902","0","1"],["104586.6","0.17504672","0","2"],["104584.8","0.03297246","0","1"],["104584.1","0","0","0"],["104582.2","0.00115191","0","1"],["104581.2","0.08796132","0","2"],["104581.1","0","0","0"],["104580.8","0","0","0"],["104580.5","0","0","0"],["104580.3","0.31423563","0","1"],["104579.8","0.09984599","0","2"],["104579.2","0.09262086","0","1"],["104579.1","0","0","0"],["104578.5","0.07256639","0","2"],["104578.2","0.15010518","0","1"],["104577.7","0.15176316","0","1"],["104577.5","0","0","0"],["104577.1","0","0","0"],["104577","0","0","0"],["104576.3","0.00835436","0","2"],["104573.9","0.23541108","0","1"],["104573.6","0.13859245","0","1"],["104573.5","0.93143308","0","2"],["104573.2","0","0","0"],["104572.8","0","0","0"],["104572","0.31574519","0","3"],["104570.1","0","0","0"],["104568.2","0.24676128","0","1"],["104567.8","0.002868","0","1"],["104567.5","0.00191","0","1"],["104567.3","0.25323284","0","1"],["104566.6","0","0","0"],["104535","0","0","0"],["104425","0.0025","0","1"],["104424.7","0.00001169","0","1"]],"ts":"1747170035400","checksum":-745321132,"seqId":54226053502,"prevSeqId":54226053344}]}
{"arg":{"channel":"books","instId":"BTC-USDT"},"action":"update","data":[{"asks":[["104591.1","0.23520542","0","11"],["104597.9","0.02256561","0","1"],["104598.5","0.00067735","0","1"],["104598.8","0.11586239","0","1"],["104599.6","0.09456107","0","2"],["104600.1","0","0","0"],["104600.2","0","0","0"],["104601","0.09004003","0","1"],["104601.2","0","0","0"],["104601.6","0.09515528","0","1"],["104601.7","0","0","0"],["104602.3","0.045","0","1"],["104603.6","0.36264043","0","2"],["104604.5","0.14796232","0","1"],["104605.1","0.16350491","0","1"],["104605.2","0.072","0","2"],["104605.7","0.01","0","2"],["104607.2","0.00477916","0","1"],["104607.9","0.15031188","0","1"],["104608.3","0.25991822","0","1"],["104608.5","0","0","0"],["104608.9","0","0","0"],["104610.6","0.60296757","0","3"],["104611.2","0","0","0"],["104614.1","0.24539921","0","1"],["104614.8","0","0","0"],["104626","0.002","0","2"],["104626.1","0","0","0"],["104627","0.001","0","1"],["104628","0","0","0"],["104647","0","0","0"],["104648","0.26","0","4"],["104649","0.19999999","0","4"],["104650","0.03532024","0","3"],["104751.4","0","0","0"]],"bids":[["104582.2","0","0","0"],["104581.2","0.00011863","0","1"],["104580.8","0.00115191","0","1"],["104580.5","0.09508793","0","1"],["104580.3","0.27220769","0","2"],["104579.8","0.00001","0","1"],["104579.2","0","0","0"],["104579.1","0.10022216","0","1"],["104578.6","0.09487481","0","1"],["104578.2","0","0","0"],["104577.7","0","0","0"],["104577.6","0.15241421","0","1"],["104577","0.15639443","0","1"],["104576.3","0.00357506","0","1"],["104574.2","0.00477916","0","1"],["104573.9","0","0","0"],["104573.5","0.77866876","0","1"],["104573.3","0.3262111","0","2"],["104572.9","0.15223403","0","1"],["104572","0.24490649","0","3"],["104568.2","0","0","0"],["104567.6","0.2609971","0","1"],["104567.3","0","0","0"],["104566.6","0.25829881","0","1"],["104539.1","0","0","0"],["104425","0","0","0"],["104424.7","0","0","0"]],"ts":"1747170035500","checksum":89583551,"seqId":54226053581,"prevSeqId":54226053502}]}
{"arg":{"channel":"books","instId":"BTC-USDT"},"action":"update","data":[{"asks":[["104595.9","0.02778968","0","1"],["104597.7","0.00067735","0","1"],["104597.8","0.24","0","1"],["104598.5","0","0","0"],["104598.8","0.39168892","0","2"],["104598.9","0.00044","0","1"],["104603","0.77866876","0","1"],["104626","0","0","0"],["104627","0.002","0","2"],["104628","0.001","0","1"],["104667.1","0.91639463","0","1"],["104668.2","0","0","0"],["104670.8","1.5239802","0","1"],["104754.7","0","0","0"],["104755","0","0","0"],["104755.1","0","0","0"]],"bids":[["104591","0.25347739","0","14"],["104586.9","0.19278644","0","1"],["104586.8","0.24","0","1"],["104586.7","0.00298463","0","1"],["104566.8","0.18345253","0","2"],["104537","0.05044849","0","2"],["104425.3","0","0","0"]],"ts":"1747170035600","checksum":-700217125,"seqId":54226053603,"prevSeqId":54226053581}]}
{"arg":{"channel":"books","instId":"BTC-USDT"},"action":"update","data":[{"asks":[["104600.1","0.10111186","0","1"],["104605.1","0.32002726","0","2"],["104610.1","0.25881784","0","1"],["104620.7","0.13859315","0","1"],["104621.8","0","0","0"],["104626","0.002","0","2"],["104627","0.001","0","1"],["104628","0","0","0"],["104754","0","0","0"],["104754.2","0","0","0"]],"bids":[["104586.9","0.12078812","0","1"],["104586.8","0","0","0"],["104580.6","0.08984752","0","1"],["104578.1","0","0","0"],["104575.6","0.151305","0","1"],["104573.6","0","0","0"],["104573","0.13859315","0","1"],["104572","0.31634833","0","2"],["104570.6","0.26935892","0","1"],["104425.7","0","0","0"]],"ts":"1747170035700","checksum":-1553426476,"seqId":54226053637,"prevSeqId":54226053603}]}
{"arg":{"channel":"books","instId":"BTC-USDT"},"action":"update","data":[{"asks":[["104595.8","0.19242972","0","1"],["104596.5","0.00021936","0","1"],["104605.6","0.0047792","0","1"],["104607.2","0","0","0"],["104619.1","0.3381717","0","2"],["104620.7","0","0","0"],["104753.3","0","0","0"]],"bids":[["104586.7","0","0","0"],["104586.1","0.00298032","0","1"],["104576.8","0.34776587","0","1"],["104574.2","0","0","0"],["104573.5","0","0","0"],["104573.4","0.0047792","0","1"],["104573","0","0","0"],["104571.8","0.13859476","0","1"],["104425.7","0.007986","0","1"],["104425.3","0.1913","0","1"]],"ts":"1747170035800","checksum":-2066822179,"seqId":54226053654,"prevSeqId":54226053637}]}
{"arg":{"channel":"books","instId":"BTC-USDT"},"action":"update","data":[{"asks":[["104591.1","0.48520542","0","13"],["104599.3","0.09702651","0","2"],["104599.6","0.00001","0","1"],["104599.8","0.09994034","0","1"],["104600.1","0","0","0"],["104600.8","0.09628687","0","1"],["104601","0","0","0"],["104601.4","0.13441908","0","2"],["104601.6","0","0","0"],["104602.9","0.0047792","0","1"],["104603.6","0.13045822","0","2"],["104604.3","0.15322708","0","2"],["104604.5","0","0","0"],["104604.8","0.33213018","0","2"],["104605.1","0","0","0"],["104605.6","0","0","0"],["104607.6","0.2000187","0","2"],["104607.9","0","0","0"],["104608","0.26483063","0","2"],["104608.3","0","0","0"],["104609.8","0.65273777","0","2"],["104610.1","0","0","0"],["104610.3","0.26139433","0","1"],["104610.6","0.3556784","0","2"],["104613.9","0.52212135","0","2"],["104614.1","0","0","0"],["104617.6","0.13859728","0","1"],["104619.1","0.19957694","0","1"],["104626","0","0","0"],["104627","0.002","0","2"],["104628","0.001","0","1"],["104648","0","0","0"],["104649","0.32999999","0","6"],["104650","0.16532023","0","5"],["104652.6","0.02083819","0","1"],["104652.9","0.01970158","0","1"],["104696.9","0.05106875","0","1"],["104753.3","2.3905","0","1"],["104754","0.234","0","1"]],"bids":[["104591","0.24790739","0","13"],["104586.1","0","0","0"],["104584.8","0","0","0"],["104584.2","0.00297855","0","1"],["104581.6","0.02352197","0","1"],["104580.6","0.1342189","0","1"],["104580.5","0","0","0"],["104580.3","0.19017994","0","2"],["104579.1","0","0","0"],["104578.9","0.09372183","0","1"],["104578.6","0","0","0"],["104578.3","0.10111141","0","1"],["104577.6","0","0","0"],["104577.3","0.16567703","0","1"],["104577","0","0","0"],["104576.8","0.29408649","0","2"],["104575.6","0","0","0"],["104575.3","0.15076223","0","1"],["104573.4","0","0","0"],["104573.3","0.07298372","0","1"],["104573","0.23146389","0","1"],["104572.9","0","0","0"],["104572.6","0.16261468","0","1"],["104572","0.21923327","0","2"],["104571.8","0","0","0"],["104570.6","0.0047792","0","1"],["104570.3","0.26047463","0","1"],["104567.6","0","0","0"],["104567.5","0.14050728","0","2"],["104567.3","0.24611658","0","1"],["104566.8","0.10839825","0","1"],["104566.6","0","0","0"],["104566.4","0.23648964","0","1"],["104425","0.0025","0","1"],["104424.7","0.00001169","0","1"]],"ts":"1747170035900","checksum":-41264525,"seqId":54226053817,"prevSeqId":54226053654}]}
{"arg":{"channel":"books","instId":"BTC-USDT"},"action":"update","data":[{"asks":[["104591.1","0.25120542","0","12"],["104595.7","0.28617407","0","1"],["104597.6","0.00067735","0","1"],["104597.7","0.38863185","0","1"],["104599.3","0.0026234","0","1"],["104599.5","0.09019196","0","1"],["104599.8","0","0","0"],["104600","0.10070746","0","4"],["104600.8","0","0","0"],["104600.9","0.08822663","0","1"],["104601.4","0.036","0","1"],["104601.6","0.09194542","0","1"],["104602.9","0","0","0"],["104603.6","0.42537211","0","3"],["104604.1","0.0047792","0","1"],["104604.3","0.0000125","0","1"],["104604.4","0.15564546","0","1"],["104604.8","0","0","0"],["104605","0.31049181","0","2"],["104607.6","0.04","0","1"],["104607.8","0.15688701","0","1"],["104608","0.02812301","0","1"],["104608.2","0.25852081","0","1"],["104609.8","0.38863185","0","1"],["104610","0.53500529","0","5"],["104610.3","0","0","0"],["104610.5","0.24993288","0","1"],["104613.9","0.26864","0","1"],["104614.1","0.25726211","0","1"],["104750.5","0","0","0"],["104750.7","0","0","0"],["104751.5","0","0","0"],["104751.9","0","0","0"],["104753.2","0","0","0"],["104753.3","0","0","0"],["104754","0","0","0"]],"bids":[["104580.6","0.27786991","0","2"],["104580.5","0.09503878","0","1"],["104580.4","0.0945286","0","1"],["104580.3","0","0","0"],["104579.1","0.08894324","0","1"],["104578.9","0","0","0"],["104578.5","0.16748667","0","3"],["104578.3","0","0","0"],["104577.5","0.16133034","0","1"],["104577.3","0","0","0"],["104576.9","0.16208729","0","1"],["104576.8","0.30221881","0","2"],["104575.5","0.16089506","0","1"],["104575.3","0","0","0"],["104573.2","0.25464479","0","1"],["104573","0","0","0"],["104572.8","0.14908793","0","1"],["104572.6","0","0","0"],["104572.1","0.0047792","0","1"],["104572","0.36082109","0","3"],["104570.6","0","0","0"],["104570.5","0.26859291","0","1"],["104570.3","0","0","0"],["104567.5","0.40121845","0","3"],["104567.3","0","0","0"],["104566.6","0.26110027","0","1"],["104566.4","0","0","0"]],"ts":"1747170036000","checksum":2091460798,"seqId":54226053892,"prevSeqId":54226053817}]}
{"arg":{"channel":"books","instId":"BTC-USDT"},"action":"update","data":[{"asks":[["104595.6","0.00068735","0","2"],["104597.6","0","0","0"],["104598.3","0.02123322","0","3"],["104604.1","0","0","0"],["104604.9","0.0047792","0","1"],["104617.6","0","0","0"],["104619","0.13859662","0","1"],["104632.9","0","0","0"],["104633.4","0.00056666","0","1"],["104649.8","0.0022","0","1"],["104650.3","0.029234","0","2"],["104750.5","0.07299861","0","2"]],"bids":[["104584.2","0.00297561","0","1"],["104581.2","0","0","0"],["104580.9","0.00011863","0","1"],["104573.3","0.07776292","0","2"],["104572.1","0","0","0"],["104570.2","0.13859653","0","1"],["104567.5","0.26262117","0","2"],["104564.3","0.00955893","0","1"],["104563.6","0","0","0"],["104519.9","1.15528508","0","2"],["104517.5","2.91637","0","1"],["104424.7","0","0","0"]],"ts":"1747170036100","checksum":358259422,"seqId":54226053946,"prevSeqId":54226053892}]}
{"arg":{"channel":"books","instId":"BTC-USDT"},"action":"update","data":[{"asks":[["104591.1","0.48520542","0","13"],["104604.9","0","0","0"],["104605.6","0.0047792","0","1"]],"bids":[["104573.4","0.0047792","0","1"],["104573.3","0.07298372","0","1"],["104425","0","0","0"]],"ts":"1747170036200","checksum":-1804840660,"seqId":54226053953,"prevSeqId":54226053946}]}
{"arg":{"channel":"books","instId":"BTC-USDT"},"action":"update","data":[{"asks":[["104591.1","0.25120542","0","12"],["104599.5","0.09300867","0","1"],["104600","0.09167413","0","4"],["104600.9","0.08981297","0","1"],["104601.6","0.09078233","0","1"],["104603.6","0.42185865","0","3"],["104604.4","0.15154218","0","1"],["104605","0.30657814","0","2"],["104605.6","0","0","0"],["104607.8","0.15936513","0","1"],["104607.9","0.0047792","0","1"],["104608.2","0.25234812","0","1"],["104610","0.54210745","0","5"],["104610.5","0.24907143","0","1"],["104614.1","0.23666429","0","1"],["104619","0.13859613","0","1"]],"bids":[["104580.9","0","0","0"],["104580.6","0.27679771","0","2"],["104580.5","0.09812104","0","1"],["104580.4","0.08861725","0","1"],["104579.1","0.09634046","0","1"],["104578.5","0.16883268","0","3"],["104577.5","0.15184223","0","1"],["104576.9","0.15852719","0","1"],["104576.8","0.30568437","0","2"],["104576.4","0.07940317","0","3"],["104575.5","0.16269926","0","1"],["104573.4","0","0","0"],["104573.2","0.2284438","0","1"],["104572.8","0.15936337","0","1"],["104572","0.35035919","0","3"],["104570.6","0.13859613","0","1"],["104570.5","0.23952098","0","1"],["104570.2","0","0","0"],["104567.8","0","0","0"],["104567.5","0.25682085","0","2"],["104566.6","0.2664502","0","1"],["104549.2","0.002868","0","1"],["104425","0.0025","0","1"],["104424.7","0.00001169","0","1"]],"ts":"1747170036300","checksum":1825935375,"seqId":54226054037,"prevSeqId":54226053953}]}
{"arg":{"channel":"books","instId":"BTC-USDT"},"action":"update","data":[{"asks":[],"bids":[["104570.6","0.13859494","0","1"]],"ts":"1747170036400","checksum":1825935375,"seqId":54226054045,"prevSeqId":54226054037}]}
{"arg":{"channel":"books","instId":"BTC-USDT"},"action":"update","data":[{"asks":[["104607.9","0","0","0"],["104608.5","0.0047792","0","1"],["104647","1","0","1"],["104750.5","0","0","0"]],"bids":[["104581.7","0.00011863","0","1"],["104576.5","0.0047792","0","1"],["104576.4","0.07462397","0","2"],["104425","0","0","0"],["104424.7","0","0","0"]],"ts":"1747170036500","checksum":-1568251248,"seqId":54226054052,"prevSeqId":54226054045}]}
{"arg":{"channel":"books","instId":"BTC-USDT"},"action":"update","data":[{"asks":[["104591.1","0.23520542","0","11"],["104595.5","0.00067735","0","1"],["104595.6","0.24001","0","2"],["104595.7","0.21397087","0","1"],["104597.8","0","0","0"],["104600.9","0","0","0"],["104601","0.0906933","0","1"],["104604.4","0","0","0"],["104604.5","0.15394045","0","1"],["104607.8","0","0","0"],["104607.9","0.15066196","0","1"],["104608.5","0","0","0"],["104609.1","0.0047792","0","1"],["104619","0","0","0"],["104620.2","0.13859414","0","1"]],"bids":[["104591","0.24472739","0","12"],["104585","0.00297661","0","1"],["104584.9","0.02560684","0","1"],["104584.2","0","0","0"],["104582.2","0.00115191","0","1"],["104580.8","0","0","0"],["104580.5","0.19094532","0","2"],["104580.4","0","0","0"],["104577","0.16245353","0","2"],["104576.9","0","0","0"],["104576.5","0","0","0"],["104576.4","0.036","0","1"],["104572.9","0.15337266","0","1"],["104572.8","0","0","0"],["104572.1","0.13859414","0","1"],["104570.6","0","0","0"],["104566.8","0.18589793","0","2"],["104425","0.0025","0","1"]],"ts":"1747170036600","checksum":-1772447595,"seqId":54226054095,"prevSeqId":54226054052}]}
{"arg":{"channel":"books","instId":"BTC-USDT"},"action":"update","data":[{"asks":[["104627","0","0","0"],["104628","0.002","0","2"],["104629","0.001","0","1"],["104635.8","0","0","0"],["104667.1","0.16909918","0","1"],["104667.2","0.00001","0","1"],["104750.5","0.07299861","0","2"]],"bids":[["104545.8","0.42343203","0","2"],["104544.2","0","0","0"],["104512.9","0","0","0"],["104424.7","0.00001169","0","1"],["104424.3","0.00156669","0","1"]],"ts":"1747170036800","checksum":-1772447595,"seqId":54226054170,"prevSeqId":54226054095}]}
{"arg":{"channel":"books","instId":"BTC-USDT"},"action":"update","data":[{"asks":[["104620.2","0","0","0"],["104621.9","0.13859175","0","1"],["104635.8","1.37850473","0","1"],["104667.2","2.45302306","0","2"],["104670.8","0","0","0"],["104673.6","0","0","0"],["104677","6.78387106","0","1"]],"bids":[["104586.1","0.00298372","0","1"],["104585","0","0","0"],["104576.8","0.66319505","0","1"],["104574.2","0.13859175","0","1"],["104573.4","0.77866876","0","1"],["104572.2","0.38863185","0","1"],["104572.1","0","0","0"],["104565.1","0","0","0"],["104560.9","0.78771837","0","2"],["104546.8","1.36071314","0","1"],["104515.4","2.4696631","0","1"],["104514.1","0","0","0"],["104474.2","0.00072803","0","5"],["104424.7","0","0","0"],["104424.3","0","0","0"]],"ts":"1747170036900","checksum":766700459,"seqId":54226054227,"prevSeqId":54226054170}]}
{"arg":{"channel":"books","instId":"BTC-USDT"},"action":"update","data":[{"asks":[["104594.7","0","0","0"],["104598","0.02593062","0","1"],["104609.1","0","0","0"],["104610.4","0.0047792","0","1"]],"bids":[["104588","0.08458459","0","2"],["104586.1","0","0","0"],["104582.2","0","0","0"],["104580.8","0.00115191","0","1"],["104578.6","0.0047792","0","1"],["104577","0.15767433","0","1"],["104574.2","0","0","0"],["104573.5","0.1385919","0","1"],["104477.6","0","0","0"],["104424.7","0.00001169","0","1"]],"ts":"1747170037000","checksum":558947833,"seqId":54226054246,"prevSeqId":54226054227}]}
{"arg":{"channel":"books","instId":"BTC-USDT"},"action":"update","data":[{"asks":[["104591.1","0.11570542","0","10"],["104599.5","0","0","0"],["104600","0.00220843","0","3"],["104600.2","0.09447129","0","1"],["104600.7","0.09927391","0","1"],["104601","0","0","0"],["104601.6","0.08960913","0","1"],["104602.3","0.13345355","0","2"],["104603.6","0.2963123","0","3"],["104604.5","0","0","0"],["104605","0","0","0"],["104605.1","0.15571548","0","1"],["104605.7","0.31040945","0","4"],["104607.9","0","0","0"],["104608.2","0","0","0"],["104608.5","0.16555945","0","1"],["104608.9","0.25536133","0","1"],["104609.6","0.00477924","0","1"],["104610","0.27252802","0","4"],["104610.4","0","0","0"],["104610.5","0","0","0"],["104610.7","0.27080889","0","1"],["104611.2","0.26784186","0","1"],["104614.1","0","0","0"],["104614.8","0.26699841","0","1"],["104620.7","0.13859259","0","1"],["104621.9","0","0","0"],["104633.4","0","0","0"],["104634.1","0.00056666","0","1"],["104650.3","0.02866734","0","1"],["104651","0.00056666","0","1"],["104675.9","0","0","0"],["104679.9","3.06096","0","1"],["104681.9","0","0","0"],["104682.9","0.01089693","0","1"],["104685.2","0","0","0"],["104688.8","0","0","0"],["104691.5","0","0","0"],["104693.3","0","0","0"],["104696.6","0","0","0"],["104698.7","0","0","0"],["104706.3","0.01051503","0","1"],["104716.9","0","0","0"],["104724.8","0.229489","0","1"],["104750.7","0.00049233","0","7"],["104751.5","0.01448136","0","1"],["104751.9","0.00001969","0","1"],["104753.2","0.0000358","0","1"],["104753.3","2.3905","0","1"],["104754","0.234","0","1"],["104754.2","0.00089983","0","1"],["104754.7","0.00001","0","1"]],"bids":[["104591","0.24790739","0","13"],["104588.2","0.00477929","0","1"],["104588","0.0816","0","1"],["104582.2","0.00115191","0","1"],["104581.2","0.09992077","0","1"],["104581.1","0.09458274","0","1"],["104580.8","0","0","0"],["104580.6","0.27157351","0","2"],["104580.5","0","0","0"],["104579.8","0.09441919","0","2"],["104579.2","0.10004711","0","1"],["104579.1","0","0","0"],["104578.6","0","0","0"],["104578.5","0.07256639","0","2"],["104578.2","0.1582984","0","1"],["104578","0.08637924","0","2"],["104577.6","0.15715235","0","1"],["104577.5","0","0","0"],["104577","0","0","0"],["104576.2","0.15880618","0","2"],["104575.5","0","0","0"],["104573.9","0.2383464","0","1"],["104573.5","0.16322058","0","1"],["104573.2","0","0","0"],["104572.9","0","0","0"],["104572.3","0.13859293","0","1"],["104572","0.31536181","0","3"],["104571.2","0.25600902","0","1"],["104570.5","0","0","0"],["104568.2","0.24846941","0","1"],["104567.5","0.00191","0","1"],["104567.3","0.24433387","0","1"],["104566.8","0.10839825","0","1"],["104566.6","0","0","0"],["104565.1","0.00955885","0","1"],["104564.3","0","0","0"],["104478.4","0.17909507","0","1"],["104425","0","0","0"],["104424.7","0","0","0"]],"ts":"1747170037100","checksum":-1746814684,"seqId":54226054352,"prevSeqId":54226054246}]}
{"arg":{"channel":"books","instId":"BTC-USDT"},"action":"update","data":[{"asks":[["104591.1","0","0","0"],["104592","0.19969","0","4"],["104600.2","0","0","0"],["104600.7","0","0","0"],["104601.1","0.09925952","0","2"],["104601.6","0.09119213","0","1"],["104602.3","0.045","0","1"],["104602.6","0.09623649","0","1"],["104603.2","0.09279896","0","2"],["104603.6","0.13045822","0","2"],["104605.1","0","0","0"],["104605.7","0.01","0","2"],["104606.1","0.15442078","0","1"],["104606.6","0.32042924","0","2"],["104608.5","0","0","0"],["104608.9","0","0","0"],["104609.4","0.20092605","0","3"],["104609.6","0","0","0"],["104609.8","0.63219662","0","2"],["104610.5","0.00477923","0","1"],["104610.7","0","0","0"],["104611.2","0","0","0"],["104611.6","0.24045016","0","1"],["104612.1","0.25323367","0","1"],["104613.8","0.20276591","0","1"],["104614.3","0","0","0"],["104614.8","0","0","0"],["104615.7","0.25823574","0","1"],["104619","0.13859497","0","1"],["104619.7","0.01","0","1"],["104620.7","0","0","0"],["104630.6","0.34339763","0","2"],["104631.7","0.47490247","0","1"],["104647","0","0","0"],["104698.7","0.0000916","0","1"],["104755","0.00001787","0","1"],["104755.1","0.00010283","0","1"]],"bids":[["104591.9","0.87299017","0","14"],["104591.2","0.22454738","0","1"],["104591.1","0.38429458","0","1"],["104591","0.04067666","0","5"],["104588.8","0.0047793","0","1"],["104588.2","0","0","0"],["104588.1","0","0","0"],["104582.1","0.27621529","0","5"],["104581.2","0","0","0"],["104581.1","0","0","0"],["104580.7","0.12633514","0","2"],["104580.6","0.1342189","0","1"],["104580.1","0.09789192","0","1"],["104579.8","0.00001","0","1"],["104579.2","0","0","0"],["104579.1","0.16807104","0","1"],["104578.6","0.16294758","0","2"],["104578.2","0","0","0"],["104578.1","0.19242972","0","1"],["104578","0.0816","0","1"],["104577.6","0","0","0"],["104577.1","0.16337511","0","1"],["104576.8","0.47393357","0","1"],["104576.2","0.002","0","1"],["104574.8","0.25077343","0","1"],["104574.4","0.15857016","0","1"],["104573.9","0","0","0"],["104573.5","0","0","0"],["104572.3","0","0","0"],["104572.1","0.25690843","0","1"],["104572","0.21837293","0","2"],["104571.2","0","0","0"],["104570.1","0.13859622","0","1"],["104569.1","0.26307886","0","1"],["104568.2","0.24520402","0","1"],["104567.3","0","0","0"],["104565.4","0.00382536","0","1"],["104425.9","0","0","0"],["104425.7","0","0","0"],["104425.3","0","0","0"]],"ts":"1747170037200","checksum":1587869327,"seqId":54226054502,"prevSeqId":54226054352}]}
{"arg":{"channel":"books","instId":"BTC-USDT"},"action":"update","data":[{"asks":[["104592","0.19649","0","3"],["104598.6","0","0","0"],["104601.8","0.04","0","1"],["104602.5","0.00001501","0","1"],["104603.6","0.30192983","0","3"],["104609.4","0.03693","0","2"],["104609.5","0.15321971","0","2"],["104610.5","0","0","0"],["104611","0","0","0"],["104611.5","0.00478923","0","2"],["104619","0","0","0"],["104621.9","0.13859186","0","1"],["104627","0.002","0","2"],["104628","0.001","0","1"],["104629","0","0","0"],["104630.6","0.22945347","0","1"],["104631.7","0","0","0"],["104648","0.32999999","0","6"],["104649","0.16499999","0","3"],["104650","0.44963116","0","3"],["104652.6","0","0","0"],["104656.2","0","0","0"],["104658.4","0.00175274","0","1"],["104666.9","0.01051706","0","1"],["104668.9","0.01051706","0","1"],["104670.6","0.01051706","0","1"],["104671.6","0.02941706","0","2"],["104673.6","6.79255001","0","1"],["104673.9","0.01051706","0","1"],["104675.7","0.01051706","0","1"],["104675.8","0","0","0"],["104677","0","0","0"],["104678.8","0.01051706","0","1"],["104679.7","0.01051706","0","1"],["104679.8","0.05538858","0","1"],["104680.8","0.01051706","0","1"],["104680.9","0","0","0"],["104682.1","0.01051706","0","1"],["104682.3","0","0","0"],["104683.7","0","0","0"],["104684.4","0.24451706","0","2"],["104685.9","0","0","0"],["104686.4","0.01051706","0","1"],["104687.6","0.07300824","0","2"],["104689.1","0.01051706","0","1"],["104689.9","0","0","0"],["104691.4","0","0","0"],["104693.2","1.26566632","0","2"],["104695.2","0.06693","0","1"],["104696.5","0","0","0"],["104699.9","0","0","0"],["104702.9","0","0","0"],["104751.4","0.0009047","0","1"],["104756","0.00001103","0","1"]],"bids":[["104591.2","0.16237816","0","1"],["104588.8","0.00298679","0","1"],["104580.6","0.30384361","0","2"],["104579.2","0.00477923","0","1"],["104578.6","0.15816835","0","1"],["104576.8","0.65563787","0","2"],["104574.5","0.16683449","0","1"],["104574.4","0","0","0"],["104574.1","0.18485125","0","3"],["104572","0.35376155","0","3"],["104570.1","0","0","0"],["104566.8","0.13839825","0","2"],["104492.5","0.00009612","0","1"],["104491.8","0","0","0"],["104478.7","0.00063683","0","1"],["104477.8","0","0","0"],["104471","0.00083719","0","1"],["104470.4","0","0","0"],["104440.1","0.00095583","0","1"],["104438.9","0","0","0"]],"ts":"1747170037300","checksum":643393099,"seqId":54226054601,"prevSeqId":54226054502}]}
{"arg":{"channel":"books","instId":"BTC-USDT"},"action":"update","data":[{"asks":[["104611.5","0.00478928","0","2"],["104612.6","0.071695","0","1"],["104620.7","0.1385929","0","1"],["104621.9","0","0","0"],["104626","0.002","0","2"],["104627","0.001","0","1"],["104628","0","0","0"],["104647","0.23","0","4"],["104648","0.21499999","0","4"],["104649","0.05","0","1"],["104661.8","0.01059655","0","1"],["104664","0.01059655","0","1"],["104666.7","0.01059655","0","1"],["104668.8","0.01059655","0","1"],["104670.2","0.13059655","0","2"],["104673.4","0.01059655","0","1"],["104675.1","0.01060655","0","2"],["104678.7","0.01059655","0","1"],["104679.8","0.06598513","0","2"],["104680.7","0.01059655","0","1"],["104684.3","0.01059655","0","1"],["104689.1","0.02103412","0","2"],["104693.1","0.03170904","0","3"],["104698.7","0","0","0"],["104699.3","0.02513015","0","4"],["104704.9","0.01139655","0","2"],["104711.9","0.01059655","0","1"],["104751.4","0","0","0"],["104751.9","0","0","0"],["104753.2","0","0","0"],["104753.3","0","0","0"],["104754","0","0","0"],["104754.2","0","0","0"],["104754.7","0","0","0"],["104755","0","0","0"],["104755.1","0","0","0"],["104756","0","0","0"]],"bids":[["104588.8","0.00298736","0","1"],["104579.2","0.00477928","0","1"],["104578.1","0","0","0"],["104574.1","0.04625939","0","2"],["104572.3","0.1385929","0","1"],["104571","0.06","0","2"],["104566.9","0.063","0","2"],["104566.8","0.16839825","0","3"],["104562.9","0","0","0"],["104560.4","0.093","0","3"],["104493.4","0.00009614","0","1"],["104492.5","0","0","0"],["104441.1","0.00097601","0","2"],["104440.1","0","0","0"]],"ts":"1747170037400","checksum":332554150,"seqId":54226054666,"prevSeqId":54226054601}]}
{"arg":{"channel":"books","instId":"BTC-USDT"},"action":"update","data":[{"asks":[["104592","0.19969","0","4"],["104609.4","0.19583333","0","3"],["104609.5","0.0000125","0","1"],["104619","0.13859537","0","1"],["104620.7","0","0","0"],["104676.3","0","0","0"],["104678.8","0.01055834","0","2"],["104751.8","0.00090893","0","1"]],"bids":[["104574.5","0","0","0"],["104574.4","0.14639361","0","1"],["104572.3","0","0","0"],["104571.1","0.13859537","0","1"],["104564.6","0","0","0"],["104560.4","0.033","0","1"],["104425.9","0.0001","0","1"]],"ts":"1747170037500","checksum":-875842544,"seqId":54226054691,"prevSeqId":54226054666}]}
{"arg":{"channel":"books","instId":"BTC-USDT"},"action":"update","data":[{"asks":[["104592","0.31919","0","5"],["104600.6","0.09507865","0","1"],["104601.1","0.09702078","0","2"],["104601.6","0","0","0"],["104602.1","0.12167043","0","2"],["104602.6","0","0","0"],["104602.7","0.08786467","0","1"],["104603.2","0.0000125","0","1"],["104603.6","0.29766199","0","3"],["104605.6","0.15689537","0","1"],["104606.1","0.30372851","0","2"],["104606.6","0","0","0"],["104609","0.16611318","0","1"],["104609.3","0.23280526","0","1"],["104609.4","0.03693","0","2"],["104609.8","0.38863185","0","1"],["104611.1","0.25645012","0","1"],["104611.6","0.24401912","0","1"],["104612.1","0","0","0"],["104615.2","0.26056436","0","1"],["104615.7","0","0","0"],["104619","0","0","0"],["104620.2","0.13859457","0","1"],["104696.9","0.07585392","0","2"],["104751.5","0","0","0"],["104751.8","0","0","0"]],"bids":[["104591","0.03974666","0","3"],["104582.1","0.09325761","0","3"],["104581.6","0.21423258","0","3"],["104580.7","0.02930447","0","1"],["104580.6","0.27359635","0","2"],["104580.2","0.09805961","0","1"],["104580.1","0","0","0"],["104579.6","0.09215266","0","1"],["104579.1","0","0","0"],["104578.6","0.16849026","0","1"],["104578.1","0.15703423","0","1"],["104577.1","0","0","0"],["104576.6","0.15114033","0","1"],["104574.8","0","0","0"],["104574.4","0","0","0"],["104574.3","0.25409265","0","1"],["104574","0.23000252","0","2"],["104572.1","0","0","0"],["104572","0.486788","0","3"],["104571.8","0.13859457","0","1"],["104571.6","0.26031005","0","1"],["104571.1","0","0","0"],["104569.1","0","0","0"],["104568.6","0.24256357","0","1"],["104568.2","0","0","0"],["104567.7","0.26583241","0","1"],["104560.4","0","0","0"],["104549","0.81333471","0","2"],["104519.9","1.79347651","0","1"],["104425.7","0.007986","0","1"]],"ts":"1747170037600","checksum":992702798,"seqId":54226054768,"prevSeqId":54226054691}]}
{"arg":{"channel":"books","instId":"BTC-USDT"},"action":"update","data":[{"asks":[["104592","0.19649","0","3"],["104595.7","0","0","0"],["104600.6","0","0","0"],["104601.1","0.10123058","0","2"],["104601.6","0.08906565","0","1"],["104602.1","0.036","0","1"],["104602.6","0.09111051","0","1"],["104602.7","0","0","0"],["104603.2","0.10006573","0","2"],["104603.6","0.29408725","0","3"],["104605.6","0","0","0"],["104606.1","0.14751004","0","1"],["104606.6","0.30119806","0","2"],["104609","0","0","0"],["104609.3","0","0","0"],["104609.5","0.15294535","0","2"],["104609.8","0.63349719","0","2"],["104611.1","0","0","0"],["104611.6","0.25278447","0","1"],["104612.1","0.25417074","0","1"],["104615.2","0","0","0"],["104615.7","0.23418428","0","1"],["104673.6","6.76743741","0","1"],["104751.5","0.01448136","0","1"],["104751.9","0.00001969","0","1"],["104753.2","0.0000358","0","1"]],"bids":[["104582.3","0.00115191","0","1"],["104582.2","0.39091765","0","1"],["104582.1","0.2867977","0","5"],["104581.6","0.02352197","0","1"],["104580.7","0.12393891","0","2"],["104580.6","0","0","0"],["104580.2","0","0","0"],["104580.1","0.10058175","0","1"],["104579.6","0","0","0"],["104579.1","0.17056813","0","1"],["104578.6","0.14535615","0","1"],["104578.1","0","0","0"],["104577.1","0.14870151","0","1"],["104576.6","0","0","0"],["104574.8","0.25324453","0","1"],["104574.5","0.16338076","0","1"],["104574.3","0","0","0"],["104574","0.0816","0","1"],["104572.1","0.25968762","0","1"],["104572","0.40998713","0","3"],["104571.6","0","0","0"],["104569.1","0.25059467","0","1"],["104568.6","0","0","0"],["104568.2","0.26210847","0","1"],["104567.7","0","0","0"]],"ts":"1747170037700","checksum":139831122,"seqId":54226054844,"prevSeqId":54226054768}]}
{"arg":{"channel":"books","instId":"BTC-USDT"},"action":"update","data":[{"asks":[["104594.1","0.02871715","0","1"],["104595.5","0","0","0"],["104597.6","0.00067735","0","1"],["104598","0","0","0"],["104602.2","0.03748854","0","1"],["104602.5","0.09513904","0","2"],["104602.6","0","0","0"],["104606","0.15589952","0","1"],["104606.1","0","0","0"],["104609.4","0.196347","0","3"],["104609.5","0.0000125","0","1"],["104610.5","0.0047792","0","1"],["104611.5","0.00001","0","1"],["104627.1","0.00859547","0","1"],["104753.2","0","0","0"]],"bids":[["104582.1","0.19423669","0","4"],["104582","0.09036092","0","1"],["104579.2","0","0","0"],["104578.6","0.0047792","0","1"],["104578.5","0.22061131","0","3"],["104574.5","0","0","0"],["104574.4","0.15159179","0","1"]],"ts":"1747170037800","checksum":545244675,"seqId":54226054874,"prevSeqId":54226054844}]}
{"arg":{"channel":"books","instId":"BTC-USDT"},"action":"update","data":[{"asks":[["104592","0.19172387","0","3"],["104602.3","0","0","0"],["104602.5","0.00001501","0","1"],["104606","0","0","0"],["104609.3","0.00477919","0","1"],["104610.5","0","0","0"],["104753.2","0.0000358","0","1"],["104753.3","2.3905","0","1"]],"bids":[["104582","0","0","0"],["104578.6","0","0","0"],["104578.5","0.07256639","0","2"],["104577.2","0.00477919","0","1"],["104425.3","0.1913","0","1"]],"ts":"1747170037900","checksum":237254029,"seqId":54226054885,"prevSeqId":54226054874}]}
{"arg":{"channel":"books","instId":"BTC-USDT"},"action":"update","data":[{"asks":[["104602.6","0.09219976","0","1"],["104606.1","0.15348887","0","1"],["104609.3","0","0","0"],["104610.5","0.00477928","0","1"],["104753.2","0","0","0"],["104753.3","0","0","0"]],"bids":[["104582.1","0.29070449","0","5"],["104578.7","0.00477928","0","1"],["104578.6","0.15523295","0","1"],["104577.2","0","0","0"],["104425.3","0","0","0"]],"ts":"1747170038000","checksum":-539245288,"seqId":54226054894,"prevSeqId":54226054885}]}
{"arg":{"channel":"books","instId":"BTC-USDT"},"action":"update","data":[{"asks":[["104593.2","0.005","0","1"],["104605.7","0.005","0","1"],["104634.1","0","0","0"],["104636.9","0.00056666","0","1"],["104651","0","0","0"],["104654.2","0.00056666","0","1"],["104678.6","0.00004128","0","1"],["104678.8","0.01051706","0","1"],["104751.9","0","0","0"]],"bids":[["104591.9","0.87355683","0","15"],["104591","0.036","0","1"],["104581.7","0","0","0"],["104578.7","0","0","0"],["104578.5","0.07734567","0","3"],["104574.6","0.00056666","0","1"],["104574.1","0.04569273","0","1"],["104572.4","0","0","0"],["104572.3","0.13859376","0","1"],["104571.8","0","0","0"],["104565.9","0.01667081","0","2"],["104565.1","0","0","0"],["104559.9","0.05201","0","3"],["104425.3","0.1913","0","1"],["104425","0.0025","0","1"],["104424.7","0.00001169","0","1"]],"ts":"1747170038100","checksum":1663304440,"seqId":54226054925,"prevSeqId":54226054894}]}
{"arg":{"channel":"books","instId":"BTC-USDT"},"action":"update","data":[{"asks":[["104609.9","0.00477928","0","1"],["104610.5","0","0","0"],["104648","1.21499999","0","5"]],"bids":[["104578.5","0.07256639","0","2"],["104578.1","0.00477928","0","1"],["104493.4","0","0","0"],["104493.3","0.19252647","0","2"],["104441.1","0.00002018","0","1"],["104441","0.01155249","0","2"]],"ts":"1747170038200","checksum":1663304440,"seqId":54226054941,"prevSeqId":54226054925}]}
{"arg":{"channel":"books","instId":"BTC-USDT"},"action":"update","data":[{"asks":[["104592","0.19173387","0","4"],["104598.3","0.0201767","0","2"],["104599.5","0.02499998","0","1"],["104604.8","0.03749996","0","1"],["104624","0.002","0","2"],["104625","0.001","0","1"],["104626","0","0","0"],["104627","0","0","0"],["104645","0.07","0","2"],["104646","0.295","0","5"],["104647","0.12999999","0","2"],["104648","1","0","1"],["104649","0","0","0"],["104750.5","0","0","0"],["104750.7","0","0","0"],["104751.5","0","0","0"]],"bids":[["104523.1","0.00951336","0","1"],["104520.8","0.00935028","0","1"],["104502","0","0","0"],["104499.6","0.00956237","0","1"],["104424.7","0","0","0"]],"ts":"1747170038300","checksum":-69587796,"seqId":54226054973,"prevSeqId":54226054941}]}
{"arg":{"channel":"books","instId":"BTC-USDT"},"action":"update","data":[{"asks":[["104598.3","0.01911962","0","1"],["104699.3","0.02503784","0","3"],["104699.9","0.0000928","0","1"],["104750","0","0","0"]],"bids":[["104493.3","0.19242972","0","1"],["104492.7","0.00009835","0","1"],["104441","0.01059666","0","1"],["104440.3","0.00095583","0","1"],["104425.3","0","0","0"],["104425","0","0","0"]],"ts":"1747170038400","checksum":-2063771500,"seqId":54226054980,"prevSeqId":54226054973}]}
{"arg":{"channel":"books","instId":"BTC-USDT"},"action":"update","data":[{"asks":[["104594.1","0.03371715","0","2"],["104595.4","0.00067735","0","1"],["104595.5","0.28617707","0","1"],["104597.6","0","0","0"],["104606.6","0.30619806","0","3"],["104609.6","0.00477927","0","1"],["104609.9","0","0","0"],["104619","0.13859493","0","1"],["104620.2","0","0","0"],["104648","0","0","0"]],"bids":[["104588.8","0.00298973","0","1"],["104578.1","0","0","0"],["104577.2","0.00477927","0","1"],["104576.8","0.47393357","0","1"],["104573.4","0","0","0"],["104572.4","0.005","0","1"],["104572.3","0","0","0"],["104571.1","0.13859516","0","1"],["104559.9","0.05701","0","4"],["104517.3","0.0000201","0","1"],["104495.1","0","0","0"]],"ts":"1747170038500","checksum":-1058607371,"seqId":54226055006,"prevSeqId":54226054980}]}
{"arg":{"channel":"books","instId":"BTC-USDT"},"action":"update","data":[{"asks":[["104595.3","0.00067735","0","1"],["104595.4","0.24","0","1"],["104595.5","0.21397387","0","1"],["104595.6","0.00001","0","1"],["104601.1","0.09481563","0","2"],["104601.6","0.09175872","0","1"],["104602.5","0.09696067","0","2"],["104602.6","0","0","0"],["104603.2","0.09109512","0","2"],["104603.6","0.31692401","0","3"],["104606","0.16292978","0","1"],["104606.1","0","0","0"],["104606.6","0.3294009","0","3"],["104609.4","0.18662045","0","3"],["104609.6","0.0047793","0","1"],["104609.8","0.6268048","0","2"],["104611.6","0.25535334","0","1"],["104612.1","0.27152121","0","1"],["104615.7","0.25893806","0","1"],["104619","0","0","0"],["104620.2","0.13859457","0","1"],["104667.1","0.89653386","0","2"],["104673.6","0","0","0"],["104677","6.76743741","0","1"]],"bids":[["104591.9","0.87770683","0","16"],["104588.8","0.00298894","0","1"],["104582.2","0.35819895","0","2"],["104582.1","0.18461918","0","4"],["104582","0.09195333","0","1"],["104580.7","0.11813906","0","2"],["104580.1","0.10114797","0","1"],["104579.1","0.15897816","0","1"],["104578.6","0","0","0"],["104578.5","0.21558935","0","3"],["104578.1","0.0047793","0","1"],["104577.2","0","0","0"],["104577.1","0.16990382","0","1"],["104576.8","0.43031047","0","2"],["104574.8","0.26028099","0","1"],["104574.4","0.16195769","0","1"],["104572.1","0.24541954","0","1"],["104572","0.40555498","0","3"],["104571.8","0.13859457","0","1"],["104571.1","0","0","0"],["104569.1","0.24644644","0","1"],["104568.2","0.25148229","0","1"],["104514.1","0.23448959","0","1"],["104425.7","0","0","0"]],"ts":"1747170038600","checksum":-1857981480,"seqId":54226055100,"prevSeqId":54226055006}]}
{"arg":{"channel":"books","instId":"BTC-USDT"},"action":"update","data":[{"asks":[["104619","0.13859488","0","1"],["104620.2","0","0","0"],["104624","0","0","0"],["104625","0","0","0"],["104626","0.002","0","2"],["104627","0.001","0","1"],["104645","0","0","0"],["104646","0","0","0"],["104647","0.22999999","0","4"],["104648","0.21499999","0","4"],["104648.3","0.38863185","0","1"],["104649","0.05","0","1"],["104664.9","0.412964","0","1"],["104673.6","6.75799319","0","1"],["104677","0","0","0"],["104726.4","0.01110779","0","2"],["104727.9","0","0","0"]],"bids":[["104576.8","0.68455923","0","1"],["104572.3","0.77866876","0","1"],["104571.8","0","0","0"],["104571.1","0.13859498","0","1"],["104425.9","0","0","0"]],"ts":"1747170038700","checksum":-1857981480,"seqId":54226055145,"prevSeqId":54226055100}]}
{"arg":{"channel":"books","instId":"BTC-USDT"},"action":"update","data":[{"asks":[["104592","0.19493387","0","5"],["104615.4","0.01","0","1"],["104619.7","0","0","0"]],"bids":[["104585.7","0.012","0","1"],["104583.2","0.00166191","0","2"],["104582.3","0","0","0"],["104582.1","0.17261918","0","3"]],"ts":"1747170038800","checksum":-30470296,"seqId":54226055154,"prevSeqId":54226055145}]}
{"arg":{"channel":"books","instId":"BTC-USDT"},"action":"update","data":[{"asks":[],"bids":[["104571.1","0","0","0"],["104570.1","0.13859592","0","1"]],"ts":"1747170038900","checksum":-30470296,"seqId":54226055156,"prevSeqId":54226055154}]}
{"arg":{"channel":"books","instId":"BTC-USDT"},"action":"update","data":[{"asks":[["104592","0.19173387","0","4"],["104619","0","0","0"],["104620.2","0.13859451","0","1"]],"bids":[["104588.8","0.00477929","0","1"],["104572.1","0.38401405","0","2"],["104570.1","0","0","0"],["104425.9","0.0001","0","1"]],"ts":"1747170039000","checksum":-1368130123,"seqId":54226055170,"prevSeqId":54226055156}]}
{"arg":{"channel":"books","instId":"BTC-USDT"},"action":"update","data":[{"asks":[["104592","0.19493387","0","5"],["104595.5","0","0","0"],["104609.1","0.0047793","0","1"],["104609.6","0","0","0"],["104620.2","0.13859441","0","1"],["104636.9","0","0","0"],["104638","0.00056666","0","1"],["104654.2","0","0","0"],["104655.3","0.00056666","0","1"],["104750","0.0294814","0","38"]],"bids":[["104588.8","0.0047793","0","1"],["104578.1","0","0","0"],["104577.2","0.0047793","0","1"],["104572.1","0.38401395","0","2"],["104566.6","0.00955872","0","1"],["104565.9","0.00711203","0","1"],["104425.9","0","0","0"]],"ts":"1747170039100","checksum":1187669799,"seqId":54226055200,"prevSeqId":54226055170}]}
{"arg":{"channel":"books","instId":"BTC-USDT"},"action":"update","data":[{"asks":[["104592","0.19173387","0","4"],["104595.3","0","0","0"],["104597.6","0.00067735","0","1"],["104609.1","0","0","0"],["104611.5","0.0047893","0","2"],["104620.2","0.13859378","0","1"],["104673.6","0","0","0"],["104680.4","6.75799319","0","1"],["104750.5","0.07299861","0","2"]],"bids":[["104588.8","0.00298931","0","1"],["104582.3","0.00011863","0","1"],["104578.6","0.0047793","0","1"],["104577.2","0","0","0"],["104572.4","0.14359378","0","2"],["104572.1","0.24541954","0","1"],["104544","0.48324487","0","1"],["104543","0","0","0"],["104497","0.47439916","0","1"],["104496","0","0","0"],["104426","0","0","0"]],"ts":"1747170039200","checksum":-19340804,"seqId":54226055260,"prevSeqId":54226055200}]}
{"arg":{"channel":"books","instId":"BTC-USDT"},"action":"update","data":[{"asks":[["104678.6","0","0","0"],["104693.1","0.02119311","0","2"],["104695.1","0","0","0"],["104696.7","0","0","0"],["104706.7","0","0","0"],["104727.6","0","0","0"],["104750.7","0.00049233","0","7"],["104751.5","0.01448136","0","1"],["104751.9","0.00001969","0","1"],["104753.2","0.0000358","0","1"],["104753.3","2.3905","0","1"]],"bids":[["104588.8","0.00477927","0","1"],["104453.4","0","0","0"],["104443","0","0","0"],["104426","0.0025","0","1"],["104425.9","0.0001","0","1"]],"ts":"1747170039300","checksum":-1962884677,"seqId":54226055283,"prevSeqId":54226055260}]}
{"arg":{"channel":"books","instId":"BTC-USDT"},"action":"update","data":[{"asks":[["104602.5","0.10049128","0","3"],["104610.5","0.0047793","0","1"],["104611.5","0.00001","0","1"],["104753.3","0","0","0"]],"bids":[["104591.9","0.88123388","0","17"],["104588.8","0.00298862","0","1"]],"ts":"1747170039400","checksum":930759713,"seqId":54226055305,"prevSeqId":54226055283}]}
{"arg":{"channel":"books","instId":"BTC-USDT"},"action":"update","data":[{"asks":[["104648","1.21499999","0","5"],["104678.6","0.00004128","0","1"],["104684.2","0.01051706","0","1"],["104686.3","0.01051706","0","1"],["104688.1","0.01051706","0","1"],["104750.7","0","0","0"],["104751.5","0","0","0"],["104751.9","0","0","0"],["104753.2","0","0","0"]],"bids":[["104591.9","0.88131388","0","18"]],"ts":"1747170039500","checksum":-2139445870,"seqId":54226055324,"prevSeqId":54226055305}]}
{"arg":{"channel":"books","instId":"BTC-USDT"},"action":"update","data":[{"asks":[["104592","0.19493387","0","5"],["104595.4","0","0","0"],["104602.5","0.00354562","0","2"],["104602.6","0.09163825","0","1"],["104606","0","0","0"],["104606.1","0.14753136","0","1"],["104610.5","0","0","0"],["104611.5","0.0047893","0","2"],["104635.8","0","0","0"],["104660.9","0.41432619","0","2"],["104667.1","0.16909918","0","1"],["104667.2","0.00001","0","1"],["104677","6.75799319","0","1"],["104680.4","0","0","0"],["104693.1","0.73452349","0","3"],["104750.7","0.00049233","0","7"],["104751.5","0.01448136","0","1"]],"bids":[["104582.1","0.26903156","0","4"],["104582","0","0","0"],["104579.2","0.0047793","0","1"],["104578.6","0.15096781","0","1"],["104578.5","0.07256639","0","2"],["104549","0.46418494","0","1"],["104546.8","0","0","0"],["104519.9","1.19699424","0","1"],["104515.4","0","0","0"],["104492.7","0","0","0"],["104492.5","0.00009672","0","1"],["104440.3","0","0","0"],["104440.1","0.00095583","0","1"],["104425.7","0.007986","0","1"],["104425.3","0.1913","0","1"]],"ts":"1747170039600","checksum":432835747,"seqId":54226055361,"prevSeqId":54226055324}]}
{"arg":{"channel":"books","instId":"BTC-USDT"},"action":"update","data":[{"asks":[["104635.8","1.41316452","0","1"],["104667.2","2.4969521","0","2"],["104673.6","6.75799319","0","1"],["104677","0","0","0"],["104715.4","0.00172123","0","2"],["104739.2","0.0026904","0","1"],["104750.7","0","0","0"],["104751.5","0","0","0"]],"bids":[["104549","0.83238092","0","2"],["104546.9","1.42420049","0","1"],["104515.5","2.57354278","0","1"],["104466.5","0.0013452","0","1"],["104456.1","0.0026904","0","1"],["104426","0","0","0"],["104425.9","0","0","0"],["104425.7","0","0","0"],["104425.3","0","0","0"]],"ts":"1747170039700","checksum":432835747,"seqId":54226055374,"prevSeqId":54226055361}]}
{"arg":{"channel":"books","instId":"BTC-USDT"},"action":"update","data":[{"asks":[["104620.2","0.13859458","0","1"]],"bids":[["104591.9","0.88144467","0","19"],["104572.4","0.005","0","1"],["104571.8","0.13859458","0","1"],["104426.2","0","0","0"]],"ts":"1747170039900","checksum":-1613771676,"seqId":54226055430,"prevSeqId":54226055374}]}
{"arg":{"channel":"books","instId":"BTC-USDT"},"action":"update","data":[{"asks":[["104592","0.19173387","0","4"]],"bids":[["104591.9","0.88145467","0","20"]],"ts":"1747170040000","checksum":1986275922,"seqId":54226055434,"prevSeqId":54226055430}]}
{"arg":{"channel":"books","instId":"BTC-USDT"},"action":"update","data":[{"asks":[["104592","0.19493387","0","5"],["104620.2","0.13859456","0","1"],["104638","0","0","0"],["104639.1","0.00056666","0","1"],["104655.3","0","0","0"],["104656.4","0.00056666","0","1"],["104693.1","0.72392693","0","2"],["104702.7","0","0","0"],["104709.4","0","0","0"],["104710.5","0.01059656","0","1"],["104722.4","0.01059656","0","1"],["104750.7","0.00049233","0","7"],["104751.5","0.01448136","0","1"]],"bids":[["104581.6","0","0","0"],["104579.3","0.0047793","0","1"],["104579.2","0.05551119","0","1"],["104567.4","0.20200337","0","3"],["104566.6","0","0","0"],["104491.7","0","0","0"],["104486.5","0","0","0"],["104479.2","0","0","0"],["104472","0.77866876","0","1"],["104468.5","0.07177","0","1"],["104426.2","0.00001731","0","1"],["104426","0.0025","0","1"],["104425.9","0.0001","0","1"],["104425.7","0.007986","0","1"]],"ts":"1747170040100","checksum":1883909820,"seqId":54226055548,"prevSeqId":54226055434}]}
{"arg":{"channel":"books","instId":"BTC-USDT"},"action":"update","data":[{"asks":[["104608.5","0.0047793","0","1"],["104611.5","0.00001","0","1"],["104751.5","0","0","0"]],"bids":[["104579.3","0","0","0"],["104576.9","0.0047793","0","1"],["104492.7","0.00009883","0","1"],["104492.5","0","0","0"],["104440.3","0.00095583","0","1"],["104440.1","0","0","0"]],"ts":"1747170040200","checksum":1883909820,"seqId":54226055562,"prevSeqId":54226055548}]}
{"arg":{"channel":"books","instId":"BTC-USDT"},"action":"update","data":[{"asks":[["104711.8","0.01059655","0","1"],["104750.7","0","0","0"]],"bids":[],"ts":"1747170040300","checksum":1883909820,"seqId":54226055565,"prevSeqId":54226055562}]}
{"arg":{"channel":"books","instId":"BTC-USDT"},"action":"update","data":[{"asks":[["104592","0.31443387","0","6"],["104600.7","0.08940738","0","1"],["104601.1","0.0000125","0","1"],["104601.2","0.0959348","0","1"],["104601.6","0","0","0"],["104602.1","0.12907452","0","2"],["104602.6","0","0","0"],["104602.7","0.09412287","0","1"],["104603.2","0.0000125","0","1"],["104603.6","0.31606285","0","3"],["104605.6","0.15822854","0","1"],["104606.1","0","0","0"],["104606.2","0.3262316","0","2"],["104606.6","0.005","0","1"],["104609","0.15369053","0","1"],["104609.4","0.27296356","0","3"],["104609.8","0.38863185","0","1"],["104611.2","0.24963242","0","1"],["104611.6","0","0","0"],["104611.7","0.2434362","0","1"],["104612.1","0","0","0"],["104615.2","0.25442017","0","1"],["104615.7","0","0","0"],["104620.2","0.13859451","0","1"],["104749.9","0","0","0"],["104750","0","0","0"],["104750.5","0","0","0"]],"bids":[["104582.2","0.3668324","0","2"],["104582.1","0.08125761","0","2"],["104581.7","0.10112271","0","1"],["104581.6","0.09627389","0","1"],["104580.7","0.02930447","0","1"],["104580.2","0.08855816","0","1"],["104580.1","0","0","0"],["104579.7","0.09640585","0","1"],["104579.1","0","0","0"],["104578.7","0.14927903","0","1"],["104578.6","0","0","0"],["104578.1","0.1524479","0","1"],["104577.1","0","0","0"],["104576.8","0.49647263","0","1"],["104576.7","0.15610675","0","1"],["104574.8","0","0","0"],["104574.4","0.25679303","0","1"],["104574","0.24253479","0","2"],["104572.1","0.13859451","0","1"],["104572","0.37825337","0","3"],["104571.8","0","0","0"],["104571.7","0.30030551","0","2"],["104569.1","0","0","0"],["104568.7","0.27165436","0","1"],["104568.2","0","0","0"],["104567.7","0.25613426","0","1"],["104425.7","0","0","0"]],"ts":"1747170040400","checksum":1309136602,"seqId":54226055636,"prevSeqId":54226055565}]}
{"arg":{"channel":"books","instId":"BTC-USDT"},"action":"update","data":[{"asks":[["104592","0.19488784","0","5"],["104600.7","0","0","0"],["104601.1","0.08986267","0","2"],["104601.2","0","0","0"],["104601.6","0.0923523","0","1"],["104602.1","0.036","0","1"],["104602.6","0.09576931","0","1"],["104602.7","0","0","0"],["104603.2","0.08986384","0","2"],["104603.6","0.31434467","0","3"],["104605.6","0","0","0"],["104606.1","0.15679636","0","1"],["104606.2","0","0","0"],["104606.6","0.32693652","0","3"],["104608.5","0","0","0"],["104608.9","0.0047793","0","1"],["104609","0","0","0"],["104609.4","0.1999275","0","3"],["104609.8","0.63488751","0","2"],["104611.2","0","0","0"],["104611.6","0.2712752","0","1"],["104611.7","0","0","0"],["104612.1","0.25638595","0","1"],["104615.2","0","0","0"],["104615.7","0.24493471","0","1"],["104749.9","0.00021362","0","1"],["104750","0.0294814","0","38"],["104750.5","0.07299861","0","2"]],"bids":[["104582.2","0.36659573","0","2"],["104582.1","0.26853739","0","4"],["104581.7","0","0","0"],["104581.6","0","0","0"],["104580.7","0.12612527","0","2"],["104580.2","0","0","0"],["104580.1","0.0931614","0","1"],["104579.7","0","0","0"],["104579.1","0.15056129","0","1"],["104578.7","0","0","0"],["104578.6","0.15547535","0","1"],["104578.1","0","0","0"],["104577.1","0.14829236","0","1"],["104576.7","0","0","0"],["104574.8","0.25165173","0","1"],["104574.4","0.16337449","0","1"],["104574","0.0816","0","1"],["104572.1","0.40327314","0","2"],["104572","0.37267369","0","3"],["104571.7","0.036","0","1"],["104569.1","0.25303127","0","1"],["104568.7","0","0","0"],["104568.2","0.26432967","0","1"],["104567.7","0","0","0"],["104425.7","0.007986","0","1"],["104425.3","0.1913","0","1"]],"ts":"1747170040500","checksum":-123683474,"seqId":54226055697,"prevSeqId":54226055636}]}
{"arg":{"channel":"books","instId":"BTC-USDT"},"action":"update","data":[{"asks":[["104592","0.31438784","0","6"],["104595.6","0.00068735","0","2"],["104595.7","0.24","0","1"],["104597.6","0","0","0"],["104602.5","0.09881882","0","3"],["104602.6","0","0","0"],["104606","0.14346047","0","1"],["104606.1","0","0","0"],["104608.9","0","0","0"],["104610.5","0.0047793","0","1"],["104619","0.13859499","0","1"],["104620.2","0","0","0"],["104750.7","0.00049233","0","7"]],"bids":[["104582.1","0.1715376","0","3"],["104582","0.09576937","0","1"],["104578.6","0.0047793","0","1"],["104578.5","0.22771623","0","3"],["104576.9","0","0","0"],["104572.1","0.26467863","0","1"],["104571.1","0.13859499","0","1"],["104425.3","0","0","0"]],"ts":"1747170040600","checksum":1060817985,"seqId":54226055724,"prevSeqId":54226055697}]}
{"arg":{"channel":"books","instId":"BTC-USDT"},"action":"update","data":[{"asks":[["104600.7","0.10068312","0","1"],["104601.1","0.0000125","0","1"],["104601.2","0.09699855","0","1"],["104601.6","0","0","0"],["104602.1","0.12783059","0","2"],["104602.5","0.00354562","0","2"],["104602.7","0.09408568","0","1"],["104603.2","0.0000125","0","1"],["104603.6","0.31692504","0","3"],["104605.6","0.15936175","0","1"],["104606","0","0","0"],["104606.2","0.32797236","0","2"],["104606.6","0.005","0","1"],["104609","0.16386825","0","1"],["104609.4","0.28064614","0","3"],["104609.8","0.38863185","0","1"],["104610.4","0.0047793","0","1"],["104610.5","0","0","0"],["104611.2","0.25439226","0","1"],["104611.6","0","0","0"],["104611.7","0.26902109","0","1"],["104612.1","0","0","0"],["104615.2","0.2539462","0","1"],["104615.7","0","0","0"],["104619","0","0","0"],["104620.2","0.13859461","0","1"],["104667.1","0.90971257","0","2"],["104749.9","0","0","0"],["104750","0","0","0"],["104750.5","0","0","0"],["104750.7","0","0","0"]],"bids":[["104582.2","0.36858603","0","2"],["104582.1","0.08125761","0","2"],["104582","0","0","0"],["104581.7","0.09137612","0","1"],["104581.6","0.08643761","0","1"],["104580.7","0.02930447","0","1"],["104580.2","0.08966414","0","1"],["104580.1","0","0","0"],["104579.7","0.08936203","0","1"],["104579.1","0","0","0"],["104578.7","0.17000911","0","1"],["104578.5","0.07256639","0","2"],["104578.1","0.15830466","0","1"],["104577.1","0","0","0"],["104576.7","0.16104217","0","1"],["104574.8","0","0","0"],["104574.4","0.26008442","0","1"],["104574","0.24008863","0","2"],["104572.1","0","0","0"],["104572","0.48994053","0","3"],["104571.8","0.13859461","0","1"],["104571.7","0.27726042","0","2"],["104571.1","0","0","0"],["104569.1","0","0","0"],["104568.7","0.26659628","0","1"],["104568.2","0","0","0"],["104567.7","0.26179908","0","1"],["104519.9","1.81943279","0","2"],["104425.7","0","0","0"]],"ts":"1747170040700","checksum":-49692367,"seqId":54226055794,"prevSeqId":54226055724}]}
{"arg":{"channel":"books","instId":"BTC-USDT"},"action":"update","data":[{"asks":[["104592","0.19488784","0","5"],["104600.7","0","0","0"],["104601.1","0.09603299","0","2"],["104601.2","0","0","0"],["104601.6","0.09986218","0","1"],["104602.1","0.036","0","1"],["104602.5","0.08929063","0","3"],["104602.7","0","0","0"],["104603.2","0.09167496","0","2"],["104603.6","0.31018094","0","3"],["104605.6","0","0","0"],["104606","0.14334188","0","1"],["104606.2","0","0","0"],["104606.6","0.32651188","0","3"],["104609","0","0","0"],["104609.4","0.18271326","0","3"],["104609.8","0.63781538","0","2"],["104610.4","0","0","0"],["104610.5","0.0047793","0","1"],["104611.2","0","0","0"],["104611.6","0.26247379","0","1"],["104611.7","0","0","0"],["104612.1","0.23840502","0","1"],["104615.2","0","0","0"],["104615.7","0.24747296","0","1"],["104749.9","0.00021362","0","1"],["104750","0.0294814","0","38"],["104750.5","0.07299861","0","2"],["104750.7","0.00049233","0","7"]],"bids":[["104582.2","0.36670163","0","2"],["104582.1","0.17312523","0","3"],["104582","0.09765438","0","1"],["104581.7","0","0","0"],["104581.6","0","0","0"],["104580.7","0.12395689","0","2"],["104580.2","0","0","0"],["104580.1","0.0957923","0","1"],["104579.7","0","0","0"],["104579.1","0.15551753","0","1"],["104578.7","0","0","0"],["104578.5","0.21595448","0","3"],["104578.1","0","0","0"],["104577.1","0.15989343","0","1"],["104576.7","0","0","0"],["104574.8","0.25575077","0","1"],["104574.4","0.15878242","0","1"],["104574","0.0816","0","1"],["104572.1","0.24841026","0","1"],["104572","0.41376075","0","3"],["104571.7","0.036","0","1"],["104569.1","0.2732132","0","1"],["104568.7","0","0","0"],["104568.2","0.24250998","0","1"],["104567.7","0","0","0"],["104425.7","0.007986","0","1"]],"ts":"1747170040800","checksum":-714264677,"seqId":54226055878,"prevSeqId":54226055794}]}
{"arg":{"channel":"books","instId":"BTC-USDT"},"action":"update","data":[{"asks":[["104608.5","0.0047793","0","1"],["104610.5","0","0","0"],["104620.2","0.13859372","0","1"]],"bids":[["104578.6","0","0","0"],["104576.9","0.0047793","0","1"],["104572.4","0.14359372","0","2"],["104571.8","0","0","0"],["104425.3","0.1913","0","1"]],"ts":"1747170040900","checksum":-714264677,"seqId":54226055896,"prevSeqId":54226055878}]}
{"arg":{"channel":"books","instId":"BTC-USDT"},"action":"update","data":[{"asks":[["104592","0.19168784","0","4"],["104602.5","0.00354562","0","2"],["104602.6","0.0951671","0","1"],["104606","0","0","0"],["104606.1","0.14509177","0","1"],["104750.7","0","0","0"]],"bids":[["104591.9","0.88144467","0","19"],["104582.1","0.2659746","0","4"],["104582","0","0","0"],["104578.6","0.15003376","0","1"],["104578.5","0.07256639","0","2"]],"ts":"1747170041000","checksum":-882576291,"seqId":54226055906,"prevSeqId":54226055896}]}
{"arg":{"channel":"books","instId":"BTC-USDT"},"action":"update","data":[{"asks":[["104593.2","0","0","0"],["104605.7","0","0","0"],["104609.4","0.03693","0","2"],["104609.5","0.15573162","0","2"],["104639.1","0","0","0"],["104639.2","0.00056666","0","1"],["104656.4","0","0","0"],["104656.5","0.02925095","0","2"],["104750.7","0.00049233","0","7"],["104751.5","0.01448136","0","1"],["104751.9","0.00001969","0","1"]],"bids":[["104574.5","0.1503463","0","1"],["104574.4","0","0","0"],["104570","0.08189006","0","3"],["104568.2","0.25206855","0","2"],["104567.4","0.19244473","0","2"],["104557.5","0","0","0"],["104425","0.0025","0","1"]],"ts":"1747170041100","checksum":1130373056,"seqId":54226055920,"prevSeqId":54226055906}]}
{"arg":{"channel":"books","instId":"BTC-USDT"},"action":"update","data":[{"asks":[["104592","0.31438784","0","6"],["104600.7","0.10109716","0","1"],["104601.1","0.0000125","0","1"],["104601.2","0.09713515","0","1"],["104601.6","0","0","0"],["104602.1","0.12325962","0","2"],["104602.5","0.00001501","0","1"],["104602.6","0","0","0"],["104602.7","0.09201694","0","1"],["104603.2","0.0000125","0","1"],["104603.6","0.31265888","0","3"],["104605.6","0.15602982","0","1"],["104606.1","0","0","0"],["104606.2","0.32208374","0","2"],["104606.6","0.005","0","1"],["104609","0.15201093","0","1"],["104609.4","0.29048914","0","3"],["104609.5","0.0000125","0","1"],["104609.8","0.38863185","0","1"],["104611.2","0.26600877","0","1"],["104611.6","0","0","0"],["104611.7","0.25660167","0","1"],["104612.1","0","0","0"],["104615.2","0.26034935","0","1"],["104615.7","0","0","0"],["104750.7","0","0","0"],["104751.5","0","0","0"],["104751.9","0","0","0"]],"bids":[["104588.8","0.00477921","0","1"],["104582.2","0.37363303","0","2"],["104582.1","0.08125761","0","2"],["104581.7","0.09427654","0","1"],["104581.6","0.09634279","0","1"],["104580.7","0.02930447","0","1"],["104580.2","0.09948502","0","1"],["104580.1","0","0","0"],["104579.7","0.10056317","0","1"],["104579.1","0","0","0"],["104578.7","0.16401047","0","1"],["104578.6","0","0","0"],["104578.1","0.15207832","0","1"],["104577.1","0","0","0"],["104576.7","0.15478692","0","1"],["104574.8","0","0","0"],["104574.5","0","0","0"],["104574.4","0.23945703","0","1"],["104574","0.24150209","0","2"],["104572.1","0","0","0"],["104572","0.36667133","0","3"],["104571.7","0.28019643","0","2"],["104569.1","0","0","0"],["104568.7","0.23897146","0","1"],["104568.2","0.00955857","0","1"],["104567.7","0.26338168","0","1"],["104425.3","0","0","0"],["104425","0","0","0"]],"ts":"1747170041200","checksum":-44125121,"seqId":54226055991,"prevSeqId":54226055920}]}
{"arg":{"channel":"books","instId":"BTC-USDT"},"action":"update","data":[{"asks":[["104620.2","0","0","0"],["104620.7","0.13859313","0","1"],["104648","0.21499999","0","4"]],"bids":[],"ts":"1747170041300","checksum":-44125121,"seqId":54226055998,"prevSeqId":54226055991}]}
{"arg":{"channel":"books","instId":"BTC-USDT"},"action":"update","data":[{"asks":[["104592","0.36638784","0","8"],["104594.1","0.03871715","0","3"],["104595.5","0.00067735","0","1"],["104595.6","0.28598087","0","2"],["104600.6","0.09270353","0","1"],["104600.7","0","0","0"],["104601.1","0.09308236","0","2"],["104601.2","0","0","0"],["104602","0.0957957","0","1"],["104602.1","0.036","0","1"],["104602.6","0.09944676","0","1"],["104602.7","0","0","0"],["104603.6","0.13045822","0","2"],["104605.5","0.1561355","0","1"],["104605.6","0","0","0"],["104606.1","0.32506117","0","2"],["104606.2","0","0","0"],["104606.6","0.01","0","2"],["104608.5","0","0","0"],["104608.9","0.16911383","0","2"],["104609","0","0","0"],["104609.3","0.22886691","0","1"],["104609.4","0.03693","0","2"],["104611.1","0.24397387","0","1"],["104611.2","0","0","0"],["104611.6","0.26348888","0","1"],["104611.7","0","0","0"],["104613.8","0.30010402","0","2"],["104615.1","0.24681652","0","1"],["104615.2","0","0","0"],["104617.6","0.13859681","0","1"],["104620.7","0","0","0"],["104624","0.002","0","2"],["104625","0.001","0","1"],["104626","0","0","0"],["104627","0","0","0"],["104646","0.33","0","6"],["104647","0.16499999","0","3"],["104648","0","0","0"],["104649","0","0","0"]],"bids":[["104591.9","0.69996467","0","17"],["104590.4","0","0","0"],["104588.8","0","0","0"],["104588.1","0.00299277","0","1"],["104583.2","0.00051","0","1"],["104582.3","0.00115191","0","1"],["104582.2","0.17947789","0","1"],["104581.7","0","0","0"],["104581.6","0.09629032","0","1"],["104581.5","0.09497985","0","1"],["104580.2","0","0","0"],["104580.1","0.09792477","0","1"],["104579.7","0","0","0"],["104579.6","0.09694293","0","1"],["104578.7","0","0","0"],["104578.6","0.16830488","0","1"],["104578.1","0","0","0"],["104578","0.23375844","0","2"],["104576.8","0.14628245","0","1"],["104576.7","0","0","0"],["104576.6","0.16568106","0","1"],["104574.4","0","0","0"],["104574.3","0.24874919","0","1"],["104574","0.0816","0","1"],["104573.9","0.14781075","0","1"],["104572.4","0.005","0","1"],["104572.3","0","0","0"],["104572.2","0","0","0"],["104572","0.21837293","0","2"],["104571.7","0.036","0","1"],["104571.6","0.26573396","0","1"],["104570","0.08689006","0","4"],["104568.7","0","0","0"],["104568.6","0.24977769","0","1"],["104567.7","0","0","0"],["104567.6","0.23627825","0","1"],["104567.5","0.14050754","0","2"],["104557.5","0.005","0","1"],["104443.6","0.01089633","0","1"],["104425.3","0.1913","0","1"]],"ts":"1747170041400","checksum":-1822976529,"seqId":54226056124,"prevSeqId":54226055998}]}
{"arg":{"channel":"books","instId":"BTC-USDT"},"action":"update","data":[{"asks":[["104603.6","0.31508381","0","3"],["104607.5","0.0047893","0","2"],["104608.9","0.16433453","0","1"],["104654.6","0.02083819","0","1"],["104750.5","0","0","0"]],"bids":[["104591.9","0.68301323","0","17"],["104588.1","0","0","0"],["104586.1","0.0047793","0","1"],["104582.2","0.3735865","0","2"],["104576.9","0","0","0"],["104576.8","0.29666944","0","2"],["104575.5","0.0047793","0","1"],["104572","0.48458162","0","3"]],"ts":"1747170041500","checksum":-1757599930,"seqId":54226056142,"prevSeqId":54226056124}]}
{"arg":{"channel":"books","instId":"BTC-USDT"},"action":"update","data":[{"asks":[["104592","0.60638784","0","9"],["104593.9","0.24","0","1"],["104645","0.07","0","2"],["104646","0.295","0","5"],["104647","0.12999999","0","2"],["104749.9","0","0","0"],["104750","0","0","0"]],"bids":[],"ts":"1747170041600","checksum":377292730,"seqId":54226056158,"prevSeqId":54226056142}]}
{"arg":{"channel":"books","instId":"BTC-USDT"},"action":"update","data":[{"asks":[["104607.5","0.00001","0","1"],["104608.5","0.0047793","0","1"],["104661.7","0.01089645","0","1"],["104664.7","0.01089645","0","1"],["104667","0","0","0"],["104667.8","0.01089645","0","1"],["104669.4","0","0","0"],["104670.5","0.01089645","0","1"],["104670.7","0","0","0"],["104673.3","0.01089645","0","1"],["104673.5","1.464386","0","2"],["104674","0","0","0"],["104674.9","0.01089645","0","1"],["104679.6","0.01089645","0","1"],["104682.9","0","0","0"],["104686.7","0","0","0"],["104691.3","0","0","0"],["104691.5","0.01089645","0","1"],["104693.1","0.01059655","0","1"],["104696.9","0","0","0"],["104702.5","0.01089645","0","1"],["104703.4","0","0","0"],["104708.7","0.01089645","0","1"],["104713.9","0","0","0"],["104716.3","0.01089645","0","1"],["104720.6","0","0","0"],["104720.7","0","0","0"],["104722.3","0.01089645","0","1"],["104726.3","0.01089645","0","1"],["104727.7","0","0","0"],["104727.8","0","0","0"]],"bids":[["104582.6","0.00115191","0","1"],["104582.5","0.00011863","0","1"],["104582.3","0","0","0"],["104576.5","0.0047793","0","1"],["104575.5","0","0","0"],["104425.3","0","0","0"]],"ts":"1747170041700","checksum":1441871954,"seqId":54226056198,"prevSeqId":54226056158}]}
{"arg":{"channel":"books","instId":"BTC-USDT"},"action":"update","data":[{"asks":[["104592","0.60162171","0","9"],["104608.5","0","0","0"],["104609.9","0.0047793","0","1"]],"bids":[["104578.1","0.0047793","0","1"],["104576.5","0","0","0"]],"ts":"1747170041800","checksum":-373143221,"seqId":54226056204,"prevSeqId":54226056198}]}
{"arg":{"channel":"books","instId":"BTC-USDT"},"action":"update","data":[{"asks":[],"bids":[["104591.9","1.06730781","0","18"],["104591.2","0.03748332","0","1"],["104591.1","0","0","0"],["104582.6","0","0","0"],["104582.3","0.00115191","0","1"],["104425.3","0.1913","0","1"]],"ts":"1747170041900","checksum":-729882780,"seqId":54226056210,"prevSeqId":54226056204}]}
{"arg":{"channel":"books","instId":"BTC-USDT"},"action":"update","data":[{"asks":[["104617.6","0.13859806","0","1"]],"bids":[["104568.7","0.13859806","0","1"],["104567.5","0.00191","0","1"],["104425.3","0","0","0"]],"ts":"1747170042000","checksum":-729882780,"seqId":54226056221,"prevSeqId":54226056210}]}
{"arg":{"channel":"books","instId":"BTC-USDT"},"action":"update","data":[{"asks":[["104602.5","0.0035335","0","2"],["104609.9","0","0","0"],["104610.5","0.0047793","0","1"],["104639.2","0","0","0"],["104639.3","0.00057666","0","2"],["104656.5","0.02868429","0","1"],["104656.6","0.00056666","0","1"],["104704.8","0.09087023","0","2"],["104711.7","0.01059655","0","1"],["104716.8","0","0","0"],["104723.6","0","0","0"],["104749.9","0.00021362","0","1"]],"bids":[["104587.6","0.00363222","0","1"],["104586.7","0.00477938","0","1"],["104586.1","0","0","0"],["104582.5","0","0","0"],["104578.7","0.0047793","0","1"],["104578.1","0","0","0"],["104569","0.0095585","0","1"],["104568.2","0","0","0"]],"ts":"1747170042100","checksum":1043480479,"seqId":54226056242,"prevSeqId":54226056221}]}
{"arg":{"channel":"books","instId":"BTC-USDT"},"action":"update","data":[{"asks":[],"bids":[["104570.1","0.13859716","0","1"],["104568.7","0","0","0"]],"ts":"1747170042200","checksum":1043480479,"seqId":54226056244,"prevSeqId":54226056242}]}
{"arg":{"channel":"books","instId":"BTC-USDT"},"action":"update","data":[{"asks":[["104592","0.34562171","0","7"],["104593.9","0","0","0"],["104602.6","0","0","0"],["104602.7","0.08950327","0","1"],["104609.2","0.1878392","0","2"],["104610.5","0","0","0"],["104611.5","0.0047893","0","2"],["104613.8","0.20276591","0","1"],["104615.1","0","0","0"],["104615.2","0.26601495","0","1"],["104615.4","0","0","0"],["104617.6","0","0","0"],["104619","0.13859551","0","1"],["104750","0.0294814","0","38"],["104750.5","0.07299861","0","2"],["104750.7","0.00049233","0","7"]],"bids":[["104587.6","0","0","0"],["104587","0.00477932","0","1"],["104586.7","0","0","0"],["104580.2","0.09145357","0","1"],["104580.1","0","0","0"],["104579.3","0.0047793","0","1"],["104578.7","0","0","0"],["104576.8","0.5114717","0","1"],["104572.1","0.77866876","0","1"],["104571.1","0.13859579","0","1"],["104570.1","0","0","0"],["104567.7","0.26580772","0","1"],["104567.6","0","0","0"]],"ts":"1747170042300","checksum":847211916,"seqId":54226056288,"prevSeqId":54226056244}]}
{"arg":{"channel":"books","instId":"BTC-USDT"},"action":"update","data":[{"asks":[["104594.1","0.01","0","2"],["104596.8","0.02400628","0","1"],["104602.5","0.00001501","0","1"],["104611.5","0.00001","0","1"],["104612.1","0.0047793","0","1"],["104619","0.13859502","0","1"],["104635.8","0","0","0"],["104647","1.12999999","0","3"],["104667.1","0.16909918","0","1"],["104667.2","0.00001","0","1"],["104750.7","0","0","0"]],"bids":[["104588","0.08637929","0","2"],["104587","0","0","0"],["104579.7","0.0047793","0","1"],["104579.3","0","0","0"],["104572.2","0.38863185","0","1"],["104571.1","0.13859506","0","1"],["104549","0.46418494","0","1"],["104546.9","0","0","0"],["104519.9","1.19699424","0","1"],["104515.5","0","0","0"],["104425.3","0.1913","0","1"],["104425","0.0025","0","1"]],"ts":"1747170042400","checksum":1373688291,"seqId":54226056324,"prevSeqId":54226056288}]}
{"arg":{"channel":"books","instId":"BTC-USDT"},"action":"update","data":[{"asks":[["104592","0.30962171","0","6"],["104600.6","0","0","0"],["104600.7","0.0899697","0","1"],["104601.1","0.0000125","0","1"],["104601.2","0.09742131","0","1"],["104602","0","0","0"],["104602.1","0.13204171","0","2"],["104602.7","0","0","0"],["104602.8","0.09720298","0","1"],["104603.6","0.31154733","0","3"],["104605.5","0","0","0"],["104605.6","0.14282937","0","1"],["104606.1","0","0","0"],["104606.2","0.32657903","0","2"],["104608.9","0","0","0"],["104609","0.16661242","0","1"],["104609.3","0","0","0"],["104609.4","0.29638672","0","3"],["104611.1","0","0","0"],["104611.2","0.26308866","0","1"],["104611.6","0","0","0"],["104611.7","0.2485196","0","1"],["104615.2","0","0","0"],["104615.3","0.25405974","0","1"],["104635.8","1.42525774","0","1"],["104647","0.12999999","0","2"],["104667.2","2.53677232","0","2"]],"bids":[["104591.9","1.06729781","0","17"],["104588.8","0.00299402","0","1"],["104588","0.0816","0","1"],["104582.2","0.36592265","0","2"],["104581.7","0.09160907","0","1"],["104581.6","0.09672752","0","1"],["104581.5","0","0","0"],["104580.3","0.09260061","0","1"],["104580.2","0","0","0"],["104579.7","0.10382056","0","2"],["104579.6","0","0","0"],["104578.7","0.14924761","0","1"],["104578.6","0.19242972","0","1"],["104578.1","0.14704965","0","1"],["104578","0.0816","0","1"],["104576.7","0.15500763","0","1"],["104576.6","0","0","0"],["104574.4","0.25682471","0","1"],["104574.3","0","0","0"],["104574","0.23721359","0","2"],["104573.9","0","0","0"],["104572","0.48682926","0","3"],["104571.7","0.27422197","0","2"],["104571.6","0","0","0"],["104568.7","0.25919178","0","1"],["104568.6","0","0","0"],["104567.8","0.26187083","0","1"],["104567.7","0","0","0"],["104549","0.82572543","0","2"],["104546.9","1.40201553","0","1"],["104519.9","1.78846315","0","2"],["104515.5","2.47031063","0","1"],["104425.3","0","0","0"],["104425","0","0","0"]],"ts":"1747170042500","checksum":-2024156649,"seqId":54226056399,"prevSeqId":54226056324}]}
{"arg":{"channel":"books","instId":"BTC-USDT"},"action":"update","data":[{"asks":[["104594.3","0.02791444","0","1"],["104596.8","0","0","0"],["104609.3","0.0047793","0","1"],["104612.1","0","0","0"],["104613.8","0.2952174","0","2"],["104617.6","0.13859768","0","1"],["104619","0","0","0"]],"bids":[["104591.9","0.99515072","0","15"],["104591.2","0","0","0"],["104588.8","0","0","0"],["104586.9","0","0","0"],["104586.1","0.00299075","0","1"],["104579.7","0.09904126","0","1"],["104578.6","0","0","0"],["104576.9","0.0047793","0","1"],["104576.8","0.31651623","0","1"],["104572.2","0","0","0"],["104572.1","0","0","0"],["104571.1","0","0","0"],["104568.8","0.13859768","0","1"],["104567.4","0.00001501","0","1"],["104549","0.46418494","0","1"],["104546.9","0","0","0"],["104519.9","1.19699424","0","1"],["104515.5","0","0","0"],["104425.3","0.1913","0","1"],["104425","0.0025","0","1"],["104424.7","0.00001169","0","1"],["104424.3","0.00156669","0","1"],["104424","0.01401013","0","1"],["104423.5","0.01448485","0","1"]],"ts":"1747170042600","checksum":-373146584,"seqId":54226056450,"prevSeqId":54226056399}]}
{"arg":{"channel":"books","instId":"BTC-USDT"},"action":"update","data":[{"asks":[["104592","0.59562171","0","9"],["104600.6","0.10158041","0","1"],["104600.7","0","0","0"],["104601.1","0.0999235","0","2"],["104601.2","0","0","0"],["104602","0.08888657","0","1"],["104602.1","0.036","0","1"],["104602.6","0.0995643","0","1"],["104602.8","0","0","0"],["104603.6","0.31433921","0","3"],["104605.5","0.16036391","0","1"],["104605.6","0","0","0"],["104606.1","0.31835077","0","2"],["104606.2","0","0","0"],["104608.9","0.15788579","0","1"],["104609","0","0","0"],["104609.3","0.2571171","0","2"],["104609.4","0.03693","0","2"],["104611.1","0.23979061","0","1"],["104611.2","0","0","0"],["104611.6","0.25514357","0","1"],["104611.7","0","0","0"],["104615.1","0.25340444","0","1"],["104615.3","0","0","0"],["104624","0","0","0"],["104625","0.002","0","2"],["104626","0.001","0","1"],["104645","0.16","0","2"],["104646","0.14999999","0","3"],["104647","0.135","0","3"],["104648","0.05","0","1"],["104667.1","0.92165835","0","2"],["104696.9","0.08223766","0","1"],["104750","0","0","0"],["104750.5","0","0","0"]],"bids":[["104591.9","0.7556199","0","13"],["104591","0","0","0"],["104588.1","0.02604481","0","1"],["104586.7","0.12218027","0","1"],["104586.1","0","0","0"],["104585.8","0.0047794","0","1"],["104582.2","0.36346697","0","2"],["104581.7","0","0","0"],["104581.6","0.09302543","0","1"],["104581.5","0.08800299","0","1"],["104580.3","0","0","0"],["104580.1","0.08889688","0","1"],["104579.7","0","0","0"],["104579.6","0.09533025","0","1"],["104578.7","0","0","0"],["104578.6","0.15288242","0","1"],["104578.1","0","0","0"],["104578","0.23633145","0","2"],["104576.8","0.3027133","0","2"],["104576.7","0","0","0"],["104576.6","0.15923237","0","1"],["104574.4","0","0","0"],["104574.3","0.25996749","0","1"],["104574","0.0816","0","1"],["104573.9","0.16318734","0","1"],["104572","0.35869775","0","3"],["104571.7","0.036","0","1"],["104571.6","0.25654177","0","1"],["104568.8","0","0","0"],["104568.7","0","0","0"],["104568.6","0.26806342","0","1"],["104567.8","0","0","0"],["104567.7","0.13859924","0","1"],["104567.6","0.25114083","0","1"],["104561.1","0","0","0"],["104561","0","0","0"],["104560.9","0.00904961","0","1"]],"ts":"1747170042700","checksum":-1053675585,"seqId":54226056588,"prevSeqId":54226056450}]}
