{"event":"subscribe","arg":{"channel":"books","instId":"BTC-USDT"},"connId":"b3bc796d"}
{"arg":{"channel":"books","instId":"BTC-USDT"},"action":"snapshot","data":[{"asks":[["104587.4","1.39004518","0","25"],["104587.9","0.19708607","0","1"],["104588","0.0816","0","1"],["104588.1","0.34403187","0","3"],["104589","0.00521575","0","1"],["104589.1","0.31209701","0","3"],["104590","0.08161","0","2"],["104590.5","0.01","0","1"],["104592","0.0816","0","1"],["104593","0.10222359","0","1"],["104593.1","0.09132517","0","1"],["104593.4","0.00045735","0","1"],["104593.5","0.32857751","0","1"],["104593.6","0.02835963","0","1"],["104593.7","0.34403187","0","3"],["104593.8","0.09258399","0","1"],["104594","0.0816","0","1"],["104594.5","0.0947145","0","1"],["104595.2","0.00044","0","1"],["104595.6","0.02638937","0","1"],["104596","0.0816","0","1"],["104596.7","0.26","0","1"],["104596.8","0.28609701","0","3"],["104597.3","0.15999682","0","1"],["104597.7","0.0414895","0","1"],["104598","0.16633272","0","1"],["104598.6","0.15568199","0","1"],["104599","0.0494528","0","1"],["104599.6","0.42737181","0","2"],["104599.7","0.00477949","0","1"],["104599.8","0.97109848","0","2"],["104600","0.00029006","0","2"],["104600.5","0.00092","0","1"],["104600.7","0.15486989","0","1"],["104601","0.25791497","0","1"],["104602","0.38863185","0","1"],["104602.1","0.0596449","0","6"],["104602.6","0.00001501","0","1"],["104603.2","0.38709995","0","2"],["104603.6","0.00001","0","1"],["104604","0.0816","0","1"],["104604.1","0.24935784","0","2"],["104604.3","0.06171282","0","2"],["104604.9","0.05716201","0","1"],["104605.7","0.00092","0","1"],["104606","0.0816","0","1"],["104606.1","0.04","0","1"],["104607","0.24454973","0","1"],["104607.5","0.00001","0","1"],["104608","0.0816","0","1"],["104608.4","0.01790803","0","1"],["104609.5","0.071683","0","1"],["104609.7","0.27207564","0","1"],["104610","0.00029006","0","2"],["104610.1","0.04","0","1"],["104610.6","0.11367","0","1"],["104611.5","0.00001","0","1"],["104612.4","0.17764565","0","1"],["104612.5","0.38863185","0","1"],["104612.6","0.234","0","1"],["104612.7","0.036","0","1"],["104613.1","0.00001501","0","1"],["104613.5","0.0095567","0","1"],["104613.8","0.3565571","0","1"],["104614","0.17764565","0","1"],["104614.8","0.07298372","0","1"],["104615.5","0.19243972","0","2"],["104615.6","0.005","0","1"],["104616","0.81866876","0","2"],["104616.8","0.002","0","1"],["104616.9","0.05209701","0","2"],["104617.2","0.03240191","0","1"],["104617.8","0.005","0","1"],["104618.1","0.00286756","0","1"],["104618.6","0.07486756","0","3"],["104618.9","0.33351445","0","1"],["104619.2","0.55401","0","1"],["104619.3","0.00191","0","1"],["104619.5","0.00001","0","1"],["104619.7","0.17764565","0","1"],["104619.8","0.05209701","0","2"],["104620","0.00220843","0","3"],["104621.2","0.17764565","0","1"],["104621.6","0.17764565","0","1"],["104622.7","0.099","0","3"],["104622.8","0.03","0","1"],["104623.3","0.05209701","0","2"],["104623.4","0.00001","0","1"],["104623.6","0.00001501","0","1"],["104624","0.18051565","0","2"],["104624.5","0.58823686","0","2"],["104624.6","0.00191","0","1"],["104624.8","0.0002293","0","1"],["104625.1","0.23158","0","1"],["104625.2","0.106311","0","1"],["104625.6","0.38863185","0","1"],["104625.8","0.02443456","0","1"],["104626.2","0.19242972","0","1"],["104626.6","0.77866876","0","1"],["104627.3","0.00013649","0","1"],["104627.4","0.2996223","0","5"],["104628.1","0.00978002","0","2"],["104628.2","0.09561","0","1"],["104628.7","0.26274137","0","1"],["104629","0.00479878","0","1"],["104630","0.00029006","0","2"],["104630.3","0.005","0","1"],["104630.4","0.00478002","0","1"],["104630.6","0.0560742","0","2"],["104631.3","0.09561","0","1"],["104631.4","0.00001","0","1"],["104631.8","0.17764565","0","1"],["104632","0.002","0","2"],["104633","0.001","0","1"],["104634.1","0.00001501","0","1"],["104634.8","0.00287","0","1"],["104635.2","0.0470407","0","1"],["104635.4","0.00001","0","1"],["104636.2","0.38863185","0","1"],["104636.9","0.19242972","0","1"],["104637.3","0.76604457","0","1"],["104637.4","0.77866876","0","1"],["104637.9","0.234","0","1"],["104638","0.02228315","0","1"],["104638.8","0.68171","0","1"],["104639.2","0.60523","0","1"],["104639.3","0.00001","0","1"],["104639.6","0.02867021","0","1"],["104639.7","0.00047806","0","1"],["104639.9","0.03178785","0","3"],["104640","0.00220843","0","3"],["104640.9","0.07627088","0","7"],["104641","0.13677189","0","1"],["104641.2","0.44541213","0","1"],["104642.2","0.1","0","1"],["104643.3","0.00001","0","1"],["104644.5","0.01059595","0","1"],["104644.6","0.028699","0","2"],["104645.8","0.00287","0","1"],["104645.9","0.6439767","0","2"],["104646.1","0.05208545","0","2"],["104646.4","0.02868011","0","1"],["104647.3","0.00001","0","1"],["104647.7","0.38863185","0","1"],["104647.9","0.77866876","0","1"],["104648","0.0022","0","1"],["104648.1","0.19242972","0","1"],["104648.7","0.05208545","0","2"],["104648.9","0.17764565","0","1"],["104649.2","0.05208545","0","2"],["104649.5","0.20093017","0","5"],["104649.8","0.0163748","0","1"],["104650","0.00033024","0","3"],["104650.1","0.05208545","0","2"],["104650.6","0.52112299","0","2"],["104650.7","1.38201127","0","1"],["104651.3","0.00001","0","1"],["104652","0.49439815","0","1"],["104652.1","0.14333","0","1"],["104652.8","0.00004962","0","1"],["104652.9","0.11466","0","1"],["104653","0.01089582","0","1"],["104653.1","0.28608545","0","3"],["104653.3","0.06693","0","1"],["104654","0.26","0","4"],["104654.4","0.00056666","0","1"],["104655","0.18208544","0","4"],["104655.1","0.000015","0","1"],["104655.2","0.00001","0","1"],["104656","0.07","0","2"],["104656.3","0.6444615","0","2"],["104656.4","0.07298372","0","1"],["104656.5","0.412898","0","1"],["104657","0.035","0","1"],["104658.7","0.19242972","0","1"],["104659.1","0.38863185","0","1"],["104659.2","0.00001","0","1"],["104659.3","0.77866876","0","1"],["104660","0.00226621","0","5"],["104660.9","0.01051752","0","1"],["104661","0.830682","0","1"],["104662.1","0.0520575","0","2"],["104662.9","0.01432828","0","1"],["104663.2","0.00001","0","1"],["104663.9","0.00017476","0","1"],["104664.1","0.57799236","0","4"],["104665.6","0.00001501","0","1"],["104665.8","0.0477837","0","1"],["104666.3","0.00001501","0","1"],["104666.6","0.000173","0","1"],["104666.7","0.01600824","0","1"],["104666.9","0.69448","0","1"],["104667.2","0.00001","0","1"],["104668","0.03651527","0","2"],["104668.6","0.04599247","0","1"],["104668.8","0.01602074","0","2"],["104668.9","0.0083931","0","1"],["104669.4","0.00002836","0","1"],["104669.5","0.40803663","0","1"],["104669.6","0.38943355","0","2"],["104669.8","0.77866876","0","1"],["104669.9","0.19242972","0","1"],["104670","0.00029298","0","2"],["104670.1","0.09554","0","1"],["104670.2","0.00004299","0","1"],["104670.4","0.00005581","0","1"],["104671.2","0.00001","0","1"],["104672.1","0.00001729","0","1"],["104672.3","0.00156543","0","1"],["104673.9","0.07298372","0","1"],["104674","0.0004963","0","1"],["104674.8","0.00261577","0","1"],["104675.1","0.00001","0","1"],["104676.1","0.00001501","0","1"],["104676.3","0.19107","0","1"],["104676.8","0.00007302","0","1"],["104677.8","0.03","0","1"],["104678.9","0.02141248","0","2"],["104679.1","0.00001","0","1"],["104679.4","0.0003312","0","2"],["104679.5","0.06692","0","1"],["104680","0.0039764","0","6"],["104680.5","0.38863185","0","1"],["104680.7","0.77866876","0","1"],["104680.8","0.19242972","0","1"],["104681","0.00002601","0","1"],["104682","0.81456586","0","2"],["104682.1","2.44604024","0","1"],["104683","0.234","0","1"],["104683.1","0.00001","0","1"],["104684.2","0.00001089","0","1"],["104684.9","0.0001","0","1"],["104686.6","0.000015","0","1"],["104686.9","0.01051752","0","1"],["104687","0.04868161","0","1"],["104687.1","0.00001","0","1"],["104687.2","0.0730312","0","2"],["104687.6","0.00002452","0","1"],["104687.9","0.01059538","0","1"],["104688","0.04","0","1"],["104688.9","0.00001","0","1"],["104689.9","0.00046084","0","1"],["104690","0.00087998","0","2"],["104690.9","0.00002206","0","1"],["104691.1","0.00006067","0","1"],["104692.2","0.08642471","0","1"],["104692.3","0.00002986","0","2"],["104692.5","0.85747891","0","1"],["104692.8","0.19242972","0","1"],["104692.9","0.38885747","0","2"],["104693","0.77866876","0","1"],["104693.5","0.234","0","1"],["104694.2","0.06971","0","1"],["104694.8","0.00006","0","1"],["104695","0.00001","0","1"],["104695.6","0.50001233","0","2"],["104696","0.97264328","0","1"],["104696.2","0.00002469","0","1"],["104696.8","0.00001006","0","1"],["104696.9","0.00059433","0","2"],["104697.1","0.00001501","0","1"],["104697.5","0.01056839","0","1"],["104697.6","0.01059597","0","1"],["104698.4","0.01357245","0","1"],["104698.7","0.00001009","0","1"],["104699","0.00001","0","1"],["104699.8","0.01059538","0","1"],["104699.9","0.01070972","0","6"],["104700","0.02357275","0","21"],["104700.9","0.00004378","0","1"],["104702.1","0.00008552","0","1"],["104703","0.00001","0","1"],["104703.2","0.00001007","0","1"],["104703.3","0.02103208","0","2"],["104703.4","0.58153691","0","2"],["104703.5","0.77866876","0","1"],["104703.6","0.0794","0","1"],["104703.9","0.07163","0","1"],["104704","0.234","0","1"],["104704.2","0.01912019","0","1"],["104704.3","0.09617448","0","2"],["104704.8","0.01051349","0","1"],["104704.9","0.0008","0","1"],["104705","0.0573","0","1"],["104705.8","0.05879918","0","4"],["104706.4","0.03","0","1"],["104706.5","0.06885887","0","3"],["104706.7","0.07298372","0","1"],["104706.8","0.03715102","0","1"],["104707","0.00001","0","1"],["104707.6","0.000015","0","1"],["104707.7","0.00002016","0","1"],["104708.5","0.00003293","0","1"],["104708.7","0.00012012","0","1"],["104709.6","0.00009506","0","1"],["104709.8","0.01070501","0","3"],["104709.9","0.01051349","0","1"],["104710","0.00290434","0","4"],["104710.2","0.01890377","0","2"],["104710.3","0.02110942","0","2"],["104710.4","0.01051349","0","1"],["104710.5","0.00005029","0","2"],["104710.6","0.03072744","0","6"],["104710.9","0.00055673","0","2"],["104711.2","0.00004846","0","1"],["104711.4","0.01051349","0","1"],["104711.5","0.00001231","0","1"],["104712.2","0.00095499","0","1"],["104712.8","0.01051349","0","1"],["104712.9","0.02102698","0","2"],["104713","0.0025","0","1"],["104713.1","0.00041774","0","1"],["104713.4","0.00199216","0","5"],["104714.2","0.00001434","0","1"],["104714.4","0.34604013","0","1"],["104714.5","0.264","0","2"],["104714.6","0.77866876","0","1"],["104714.8","0.0000185","0","1"],["104715","0.229473","0","1"],["104715.4","0.00037603","0","1"],["104715.5","0.01051349","0","1"],["104715.6","0.01051349","0","1"],["104716.2","0.01059597","0","1"],["104716.3","0.00080376","0","1"],["104717","0.01051349","0","1"],["104717.1","0.01051349","0","1"],["104717.2","0.12","0","1"],["104717.6","0.04734024","0","1"],["104717.7","0.07298372","0","1"],["104718","0.12","0","1"],["104718.1","0.000015","0","1"],["104718.6","0.01052964","0","2"],["104718.7","0.06001679","0","3"],["104718.9","0.00001","0","1"],["104719","0.12","0","1"],["104719.7","0.00016808","0","1"],["104719.8","0.01051349","0","1"],["104719.9","0.01065319","0","2"],["104720","0.00232339","0","7"],["104720.4","0.00002219","0","1"],["104721.8","3.01997","0","1"],["104722.2","0.00027824","0","7"],["104722.3","1.04131","0","1"],["104723","0.02865442","0","1"],["104723.2","0.00017476","0","1"],["104724.2","0.00001526","0","1"],["104725","0.23429668","0","3"],["104725.4","0.77866876","0","1"],["104725.9","0.00014362","0","5"],["104726.4","0.00021134","0","1"],["104726.7","0.01051349","0","1"],["104726.8","0.00141996","0","3"],["104727.7","0.01089585","0","1"],["104728.3","0.00001564","0","1"],["104728.6","0.00001501","0","1"],["104729.8","0.00002514","0","2"],["104730","0.00041646","0","4"],["104730.6","0.01400575","0","1"],["104730.9","0.0105135","0","1"],["104731","0.06968","0","1"],["104731.2","0.0217917","0","2"],["104732.3","0.00010831","0","1"],["104732.7","0.4","0","1"],["104732.8","0.00209352","0","1"],["104733.3","0.07315672","0","2"],["104733.8","0.0105135","0","1"],["104733.9","0.0022","0","1"],["104734.3","0.0217917","0","2"],["104734.4","0.00212424","0","1"],["104734.8","0.00001","0","1"],["104734.9","0.00001009","0","1"],["104735.5","0.33757281","0","2"],["104735.8","0.00023574","0","1"],["104735.9","0.00002557","0","1"],["104736.4","0.01064462","0","2"],["104736.5","0.77866876","0","1"],["104736.8","0.00001014","0","1"],["104737","0.03230388","0","3"],["104737.3","0.01059679","0","1"],["104737.5","0.01051303","0","1"],["104739.1","0.00001501","0","1"],["104739.2","0.01089655","0","1"],["104739.3","0.01059679","0","1"],["104739.6","0.00023506","0","1"],["104739.7","0.00001107","0","1"],["104739.9","0.0013452","0","1"],["104740","0.00219843","0","2"],["104740.3","0.00005155","0","1"],["104740.5","0.00006468","0","1"],["104740.6","0.0217917","0","2"],["104740.7","0.03","0","1"],["104740.9","0.0579344","0","1"],["104741.4","0.02119358","0","2"],["104741.9","0.00008643","0","1"],["104742.2","0.0217917","0","2"],["104742.8","0.00002611","0","2"],["104743.1","0.00011716","0","4"],["104743.2","0.01059679","0","1"],["104743.3","0.01059679","0","1"],["104744.3","0.00005567","0","1"]],"bids":[["104587.3","0.01387","0","4"],["104587.2","0.002","0","1"],["104586.8","0.00955918","0","1"],["104584","0.0816","0","1"],["104582","0.0816","0","1"],["104581.4","0.02697419","0","1"],["104580.3","0.00056666","0","1"],["104580","0.00220843","0","3"],["104579.8","0.00001","0","1"],["104579.5","0.00051","0","1"],["104579.1","0.02697478","0","1"],["104577.7","0.00477969","0","1"],["104577.6","0.00262394","0","1"],["104576.9","0.002511","0","1"],["104575.8","0.00001","0","1"],["104575.6","0.03536059","0","1"],["104575.5","0.04126067","0","1"],["104574.2","0.00098","0","1"],["104573.5","0.10047403","0","2"],["104573.3","0.09207981","0","1"],["104572.7","0.02258324","0","1"],["104572.3","0.00137191","0","1"],["104572.2","0.0436728","0","1"],["104572.1","0.09990525","0","1"],["104572","0.09440838","0","1"],["104571.9","0.00001","0","1"],["104571.1","0.15415565","0","1"],["104571","0.361818","0","2"],["104570.9","0.0005","0","1"],["104570.8","0.38863185","0","1"],["104570.6","0.234","0","1"],["104570","0.00029006","0","2"],["104569.8","0.15215971","0","1"],["104569.7","0.0006199","0","1"],["104569.6","0.000126","0","1"],["104569.5","0.00001501","0","1"],["104569.2","0.04785593","0","1"],["104569","0.00098","0","1"],["104568.5","0.26760975","0","2"],["104568.2","0.00477949","0","1"],["104568.1","0.17764565","0","1"],["104567.9","0.00001","0","1"],["104566.6","0.00482005","0","1"],["104566.1","0.24257947","0","1"],["104566","0.31311414","0","3"],["104565.7","0.2184483","0","2"],["104565.6","0.17764565","0","1"],["104565","0.05893484","0","1"],["104564.4","0.01031435","0","1"],["104563.9","0.00001","0","1"],["104563.1","0.00119649","0","1"],["104561.9","0.17764565","0","1"],["104561.8","0.123","0","4"],["104561.1","0.75971771","0","2"],["104560.6","0.03578612","0","2"],["104560.1","0.234","0","1"],["104560","0.00220843","0","3"],["104559.9","0.00001","0","1"],["104559.5","0.23595906","0","1"],["104559.3","0.00928176","0","1"],["104559","0.00001501","0","1"],["104557.7","0.02199655","0","1"],["104556.8","0.38863185","0","1"],["104556.7","0.37007537","0","2"],["104556.5","0.04101773","0","1"],["104556.4","0.77866876","0","1"],["104556","0.13042521","0","3"],["104555.9","0.17764565","0","1"],["104553.5","0.13861595","0","1"],["104553.4","0.17764565","0","1"],["104552.7","0.07311","0","1"],["104552.5","0.01434341","0","1"],["104552","0.00001","0","1"],["104551.3","0.00001","0","1"],["104550.8","0.00056666","0","1"],["104550","0.0004255","0","3"],["104549.7","0.31703783","0","2"],["104549.6","0.234","0","1"],["104548.9","0.412921","0","2"],["104548.5","0.00003001","0","2"],["104548.2","0.32511","0","1"],["104547.9","0.05749488","0","1"],["104547.4","0.00478069","0","1"],["104547.1","0.07298372","0","1"],["104546.2","0.033","0","1"],["104545.6","0.19242972","0","1"],["104545.5","0.98159185","0","2"],["104545.4","0.67907131","0","2"],["104545.3","0.77866876","0","1"],["104544.1","0.00001","0","1"],["104542.5","0.67114","0","1"],["104541.5","0.00001","0","1"],["104541.4","0.0001","0","1"],["104541","0.53010867","0","2"],["104540.8","1.37885341","0","1"],["104540.7","0.00478002","0","1"],["104540","0.00221843","0","4"],["104539.3","0.01898252","0","1"],["104539.1","0.234","0","1"],["104538.5","0.0477941","0","1"],["104538","0.000015","0","1"],["104536.1","0.00001","0","1"],["104535","0.00047806","0","1"],["104534.9","0.36251537","0","2"],["104534.8","0.77866876","0","1"],["104534.7","0.00094847","0","1"],["104533.3","0.000173","0","1"],["104532.5","0.00951381","0","1"],["104532.1","0.00001","0","1"],["104532","0.19242972","0","1"],["104531.6","0.05006861","0","1"],["104530.5","0.0022","0","1"],["104530","0.00028006","0","1"],["104529.8","0.29201386","0","1"],["104528.9","0.17764565","0","1"],["104528.7","0.00951674","0","1"],["104528.2","0.00001","0","1"],["104528.1","0.29193486","0","1"],["104527.8","0.00951615","0","1"],["104527.5","0.000015","0","1"],["104527.3","0.01452354","0","1"],["104526.6","0.38863185","0","1"],["104526.4","0.00933508","0","1"],["104526.1","0.01051604","0","1"],["104525.8","0.07175","0","1"],["104525.3","0.00001024","0","1"],["104524.8","0.01051604","0","1"],["104524.6","0.32881143","0","2"],["104524.5","0.00364282","0","1"],["104524.2","0.00001","0","1"],["104524","0.00839718","0","1"],["104523.7","0.03920743","0","2"],["104523.4","0.00717113","0","1"],["104522.9","0.00287","0","1"],["104521.4","0.01075081","0","2"],["104521.3","0.01051604","0","1"],["104520.9","0.07298372","0","1"],["104520.5","0.01059593","0","1"],["104520.4","0.01051604","0","1"],["104520.2","0.00001","0","1"],["104520.1","0.77866876","0","1"],["104520","0.00220843","0","3"],["104518.8","0.46208143","0","1"],["104518.3","0.01051604","0","1"],["104517","0.000015","0","1"],["104516.5","0.01059634","0","1"],["104516.4","0.002868","0","1"],["104516.2","0.00001","0","1"],["104516","0.2551","0","1"],["104515.1","0.01059634","0","1"],["104515","0.02119186","0","2"],["104514.9","0.02103208","0","2"],["104514.3","0.05856411","0","1"],["104514.2","0.01051604","0","1"],["104513.6","0.01059634","0","1"],["104513.5","0.01059593","0","1"],["104513.4","0.0074527","0","1"],["104513.3","0.00007315","0","1"],["104512.7","0.01051752","0","1"],["104512.6","0.01059593","0","1"],["104512.4","0.00287","0","1"],["104512.3","0.00001","0","1"],["104512.2","0.0001","0","1"],["104512","0.00001","0","1"],["104511.3","0.01051752","0","1"],["104511.2","0.01059634","0","1"],["104511.1","0.02141188","0","2"],["104511","0.07298372","0","1"],["104510","0.00028006","0","1"],["104509.8","0.01059593","0","1"],["104509.7","0.02111238","0","2"],["104509.6","0.6704275","0","3"],["104509.5","0.77866876","0","1"],["104509.4","2.48144123","0","1"],["104507.9","0.01089584","0","1"],["104507.8","0.01051752","0","1"],["104507.7","2.63633","0","1"],["104506.5","0.00001501","0","1"],["104506.4","0.01051752","0","1"],["104506.3","0.02111386","0","2"],["104506.2","0.00173748","0","1"],["104506.1","0.01051604","0","1"],["104504.8","0.01089584","0","1"],["104504.7","0.01059634","0","1"],["104504.3","0.00001","0","1"],["104503.9","0.00041816","0","1"],["104503.5","0.01051752","0","1"],["104503.4","0.01089581","0","1"],["104503.3","0.02554817","0","1"],["104502.2","0.00001","0","1"],["104500.9","0.02179168","0","2"],["104500.8","0.02103504","0","2"],["104500.7","0.02119268","0","2"],["104500.6","0.01059593","0","1"],["104500.3","0.02868682","0","1"],["104500","0.00364009","0","10"],["104499","0.00005062","0","1"],["104498","0.01059634","0","1"],["104497.9","0.01148347","0","1"],["104497.7","0.554653","0","1"],["104496.4","0.00001","0","1"],["104496.2","0.000015","0","1"],["104496.1","0.01089584","0","1"],["104496","0.49593297","0","3"],["104495.8","0.0022","0","1"],["104495.7","0.0008","0","1"],["104495.5","0.07298372","0","1"],["104494.9","0.85999838","0","2"],["104494.3","0.03","0","1"],["104494","0.47439916","0","1"],["104493.3","0.08878906","0","1"],["104492.4","0.00001","0","1"],["104491.9","0.0008326","0","1"],["104491","0.12","0","1"],["104490.8","0.01089581","0","1"],["104490.7","0.07182","0","1"],["104490.2","0.00003686","0","1"],["104490.1","0.06","0","2"],["104490","0.00028006","0","1"],["104489.5","0.01069202","0","2"],["104489.4","0.01470182","0","1"],["104488.5","0.00001","0","1"],["104488.2","0.31911036","0","1"],["104487.7","0.038","0","5"],["104487.5","0.0076","0","1"],["104487.1","0.01059593","0","1"],["104487","0.03","0","1"],["104486.1","0.00017476","0","1"],["104485.7","0.00008603","0","1"],["104485.5","0.000025","0","2"],["104484.5","0.01060593","0","2"],["104484.4","0.77866876","0","1"],["104483.8","0.01089584","0","1"],["104483.7","0.00902","0","1"],["104483.3","0.32368454","0","2"],["104482.6","0.00001","0","1"],["104481","0.00123","0","1"],["104480.5","0.00063693","0","1"],["104480.4","0.01089581","0","1"],["104480.2","0.01059593","0","1"],["104480","0.00220843","0","3"],["104479.8","0.07298372","0","1"],["104479.1","0.01059593","0","1"],["104479","0.94264479","0","1"],["104477.9","0.00974584","0","1"],["104477.5","0.3118","0","2"],["104476.7","0.01059634","0","1"],["104476.6","0.14","0","1"],["104476.4","0.04634752","0","1"],["104475","0.00001501","0","1"],["104474.7","0.01059588","0","1"],["104474.5","0.0013452","0","1"],["104474.4","0.29193486","0","1"],["104474.2","1.42797","0","1"],["104473.7","0.02179165","0","2"],["104473.6","0.78006388","0","2"],["104472.6","0.00001","0","1"],["104472.3","0.02312888","0","1"],["104472.2","0.0579344","0","1"],["104470","0.00028006","0","1"],["104467.3","0.00003136","0","1"],["104466.8","0.02179168","0","2"],["104466.7","0.02119222","0","2"],["104466.6","0.000173","0","1"],["104466.5","0.01089581","0","1"],["104466.4","0.00453941","0","1"],["104464.9","0.00083737","0","1"],["104464.5","0.000015","0","1"],["104464.2","0.00049361","0","3"],["104463.2","0.0026904","0","1"],["104462","0.05","0","1"],["104461.9","2.99074","0","1"],["104460.7","0.77867876","0","2"],["104460.6","0.01089581","0","1"],["104460","0.00219843","0","2"],["104459.4","0.02179168","0","2"],["104459.3","0.07298372","0","1"],["104459","0.00010262","0","1"],["104458.3","0.01077302","0","1"],["104457.4","0.01232","0","1"],["104457.1","0.0001","0","1"],["104455.9","0.832312","0","1"],["104454.2","0.229454","0","1"],["104454","0.00001501","0","1"],["104452.7","0.00001","0","1"],["104452.4","0.02179168","0","2"],["104452.3","0.01888181","0","2"],["104451.1","2.1676","0","2"],["104450.7","0.07298372","0","1"],["104450.3","2.42039","0","1"],["104450","0.0433496","0","3"],["104449.9","0.77866876","0","1"],["104449.1","0.02179168","0","2"],["104449","0.01715522","0","1"],["104447.6","0.00001846","0","1"],["104446.9","0.03","0","1"],["104446.8","0.00001783","0","1"],["104445.9","0.160551","0","1"],["104444.9","0.05793435","0","1"],["104444.4","0.0001114","0","2"],["104443.9","0.000015","0","1"],["104443.7","0.00008121","0","1"],["104440.8","0.00001","0","1"],["104440.2","0.0047804","0","1"],["104440","0.00422253","0","5"],["104438.1","0.80866146","0","1"],["104438","1.89365455","0","1"],["104437.5","0.02321488","0","2"],["104437.4","0.77866876","0","1"],["104436.1","0.00095587","0","1"],["104436","0.01146569","0","1"],["104435.8","0.51975372","0","3"],["104435.3","0.0001","0","1"],["104432.7","0.00008755","0","1"],["104431.6","0.0718","0","1"],["104430.7","0.00007949","0","1"],["104430","0.00028006","0","1"],["104429.6","0.00122607","0","4"],["104428.9","0.00001","0","1"],["104426.8","0.00237476","0","2"],["104425.9","0.0001","0","1"],["104425.3","0.1913","0","1"],["104424.7","0.00001169","0","1"],["104423","0.00070727","0","3"],["104422.8","0.00094847","0","1"],["104421.8","0.77866876","0","1"],["104421.7","0.07298372","0","1"],["104420","0.00219843","0","2"],["104419.4","0.00003046","0","1"],["104419.3","0.0095608","0","2"],["104418.4","0.0001","0","1"],["104417.1","0.00005919","0","1"],["104417","0.00001","0","1"],["104413","0.00001","0","1"],["104411.6","0.00006","0","1"],["104410.5","0.0001841","0","1"],["104410","0.00038875","0","3"],["104409.8","0.00095776","0","1"],["104409.4","0.77866876","0","1"],["104409.3","3.17177","0","1"],["104408.6","0.0008379","0","2"],["104407.9","0.00002454","0","1"],["104407.2","0.00001147","0","1"],["104405.9","0.00118054","0","1"],["104405.8","0.00001051","0","1"],["104405.3","0.03","0","1"],["104405.1","0.00002566","0","1"],["104404.1","0.00005489","0","1"],["104404","0.0000956","0","1"],["104403.9","0.00050129","0","4"],["104402.9","0.00001373","0","1"],["104402.2","0.00003809","0","1"],["104401.1","0.00001","0","1"],["104401","0.00023525","0","1"],["104400.6","0.07183","0","1"],["104400.1","0.03","0","1"],["104400","0.11098801","0","36"],["104399.9","0.0351225","0","10"],["104399.4","0.00041858","0","1"],["104398.8","0.77869352","0","2"],["104398.1","0.07298372","0","1"],["104395.8","0.00001704","0","1"],["104395.5","0.00968","0","1"],["104394.6","0.00005067","0","1"],["104394","0.1205","0","1"],["104391.9","0.001841","0","1"],["104391.6","0.000015","0","1"],["104391.4","0.5999","0","1"],["104391.2","0.0008","0","1"],["104390","0.00069308","0","3"],["104389.2","0.00001","0","1"],["104388.8","0.00292077","0","2"],["104388.3","0.77866876","0","1"],["104388.2","0.03","0","1"],["104387","0.00030165","0","1"],["104386.9","0.00093383","0","2"],["104386.8","0.00005522","0","1"],["104386.7","0.00012605","0","2"],["104386.3","0.00041848","0","2"],["104386.2","0.00003798","0","1"],["104385.9","0.00022924","0","1"],["104385.7","0.00503516","0","4"],["104385.5","0.00014367","0","3"],["104385.3","0.00018205","0","1"],["104384.9","0.00003456","0","1"],["104384.8","0.00006878","0","4"],["104384.7","0.00016998","0","7"],["104384.5","0.03","0","1"],["104384.4","0.00304391","0","2"],["104383.8","0.00016733","0","2"],["104383.7","0.00001855","0","1"],["104383.4","0.07298372","0","1"],["104383.3","0.00090892","0","2"],["104383.2","0.00001016","0","1"],["104382.9","0.00162841","0","7"],["104382.8","2.65237537","0","2"],["104382.5","0.03","0","1"],["104382.3","0.00052775","0","2"],["104382.2","0.00483056","0","1"],["104381.4","0.00003468","0","1"]],"ts":"1747168594509","checksum":-2009528603,"seqId":54225024254,"prevSeqId":-1}]}
{"arg":{"channel":"books","instId":"BTC-USDT"},"action":"update","data":[{"asks":[["104587.4","1.6779244","0","28"],["104587.8","0.19242972","0","1"],["104587.9","0.42198868","0","3"],["104588.4","0.47805627","0","1"],["104591.5","0.00045735","0","1"],["104593","0","0","0"],["104593.1","0","0","0"],["104593.4","0","0","0"],["104593.8","0","0","0"],["104594.5","0","0","0"],["104595.6","0","0","0"],["104597.3","0","0","0"],["104598","0","0","0"],["104598.6","0","0","0"],["104598.9","0.00477949","0","1"],["104599.6","0.69643643","0","3"],["104599.7","0","0","0"],["104600.2","0.17764565","0","1"],["104600.7","0","0","0"],["104601","0","0","0"],["104603.1","0.13861614","0","1"],["104603.2","0.1742301","0","2"],["104604.1","0.00008819","0","1"],["104604.9","0","0","0"],["104607","0","0","0"],["104608.6","0.072","0","2"],["104610.9","0.00191","0","1"],["104612.7","0.099","0","3"],["104616.2","0.00191","0","1"],["104618.1","0","0","0"],["104618.6","0.04186756","0","2"],["104619.3","0.02228315","0","1"],["104621.6","0","0","0"],["104622.7","0.036","0","1"],["104624.6","0","0","0"],["104630","0.00229006","0","4"],["104631","0.001","0","1"],["104632","0","0","0"],["104633","0","0","0"],["104638","0","0","0"],["104639.2","0.6067475","0","2"],["104641.3","0.0015175","0","1"],["104642.3","0.0015175","0","1"],["104652","0.82439815","0","7"],["104653","0.17589581","0","4"],["104654","0","0","0"],["104654.4","0.09611666","0","2"],["104655","0.05208545","0","2"],["104656","0","0","0"],["104657","0","0","0"],["104668.1","0.07925","0","1"],["104670.1","0","0","0"],["104676.3","0","0","0"],["104683.8","5.93878499","0","1"],["104692.8","0","0","0"],["104694.7","0.00009224","0","1"],["104701.4","0.0579344","0","1"],["104703.6","0","0","0"],["104740.9","0","0","0"],["104744.7","0.00029761","0","1"],["104744.8","0.0000112","0","1"],["104745.5","0.02119358","0","2"],["104745.6","0.0347717","0","3"],["104746","1.89471219","0","1"],["104747","0.77866876","0","1"],["104747.2","0.00001055","0","1"],["104748","0.00108568","0","1"],["104748.6","0.01447816","0","1"],["104749","0.01059679","0","1"],["104749.1","0.01059679","0","1"],["104749.6","0.00003796","0","2"]],"bids":[["104586.9","0.00001","0","1"],["104584","0","0","0"],["104581.4","0","0","0"],["104579.1","0","0","0"],["104577.7","0","0","0"],["104576","0.0269756","0","1"],["104575.6","0.05430317","0","2"],["104573.5","0.008","0","1"],["104573.3","0","0","0"],["104572.7","0","0","0"],["104572.1","0","0","0"],["104572","0","0","0"],["104571.1","0","0","0"],["104571","0.35542535","0","3"],["104570.7","0.071683","0","1"],["104570.6","0","0","0"],["104569.8","0","0","0"],["104569.3","0.02258324","0","1"],["104568.5","0.106311","0","1"],["104568.2","0","0","0"],["104566.8","0.1657026","0","1"],["104566.5","0.20099721","0","1"],["104566.1","0.00477949","0","1"],["104566","0.10785743","0","3"],["104565.7","0.06124373","0","1"],["104565.6","0","0","0"],["104565","0","0","0"],["104564.4","0.25958989","0","2"],["104563.8","0.00191","0","1"],["104561.1","0.49226576","0","1"],["104560.6","0.02867754","0","1"],["104559.5","0.24286873","0","1"],["104559.3","0","0","0"],["104558.5","0.00191","0","1"],["104557.9","0.24478934","0","1"],["104556.1","0.00710858","0","1"],["104553.5","0.13861614","0","1"],["104552.5","0","0","0"],["104551.5","0.05893484","0","1"],["104548.3","0.17764565","0","1"],["104547.4","0","0","0"],["104540.7","0.00479252","0","2"],["104538.5","0","0","0"],["104532.4","0.0000125","0","1"],["104528.6","0.234","0","1"],["104527.1","0.0143469","0","1"],["104526.5","0.0477996","0","1"],["104519.3","0.1205","0","1"],["104518.8","0","0","0"],["104516.4","0","0","0"],["104513.5","0.04059593","0","2"],["104509.4","2.51144123","0","2"],["104506.3","0.03047663","0","3"],["104503.9","0.46247897","0","2"],["104480.4","0.01376381","0","2"],["104435.8","0.19348372","0","2"],["104405.9","0","0","0"],["104394","0","0","0"],["104381.2","0.00001042","0","1"],["104380.9","0.00013167","0","2"],["104380.7","0.00001015","0","1"],["104380.6","0.00001095","0","1"],["104380.4","0.00001008","0","1"]],"ts":"1747168594609","checksum":-698505866,"seqId":54225024661,"prevSeqId":54225024254}]}
{"arg":{"channel":"books","instId":"BTC-USDT"},"action":"update","data":[{"asks":[["104587.4","1.54795714","0","29"],["104587.8","0","0","0"],["104587.9","0.39362751","0","2"],["104589.5","0.0263909","0","1"],["104591.5","0","0","0"],["104593.4","0.00045735","0","1"],["104593.6","0","0","0"],["104593.7","0.43924327","0","4"],["104593.8","0.09871006","0","1"],["104594.5","0.09799169","0","1"],["104595.2","0.0911971","0","2"],["104598","0.14376128","0","1"],["104598.7","0.1649537","0","1"],["104599.3","0.15115613","0","1"],["104599.6","0.6295709","0","3"],["104601.5","0.14640874","0","1"],["104601.8","0.24242897","0","1"],["104603.1","0","0","0"],["104603.2","0.35324049","0","1"],["104603.7","0.25050495","0","1"],["104604.8","0.27230537","0","1"],["104605.9","0.13861314","0","1"],["104607.7","0.25322654","0","1"],["104612.7","0.165","0","5"],["104618.6","0.00286756","0","1"],["104622.8","0","0","0"],["104625","0.09561","0","1"],["104631.3","0","0","0"],["104644.4","0.01059554","0","1"],["104683.8","0","0","0"],["104690.5","5.93878499","0","1"],["104692.2","0","0","0"],["104700.8","0.08950187","0","1"],["104745.6","0","0","0"],["104746","0","0","0"],["104747","0","0","0"],["104747.2","0","0","0"],["104748","0","0","0"],["104748.6","0","0","0"],["104749","0","0","0"],["104749.1","0","0","0"],["104749.6","0","0","0"]],"bids":[["104587.3","0.115861","0","5"],["104586.9","0","0","0"],["104579","0.01761962","0","1"],["104575.9","0.00477981","0","1"],["104575.6","0","0","0"],["104574.4","0.00137191","0","1"],["104574.3","0.1169808","0","1"],["104574.2","0.0995562","0","2"],["104574","0.08789692","0","1"],["104572.8","0.09216563","0","1"],["104572.7","0.09213061","0","1"],["104572.3","0","0","0"],["104571.8","0.15849795","0","1"],["104570.7","0","0","0"],["104570.5","0.15931281","0","1"],["104569.2","0.152546","0","1"],["104566.8","0.57039233","0","2"],["104566.5","0.16147686","0","1"],["104564.4","0.01031435","0","1"],["104564.2","0.24844892","0","1"],["104563.9","0.04786836","0","2"],["104561.8","0.38424688","0","5"],["104560.2","0.2627087","0","1"],["104559.5","0","0","0"],["104557.9","0","0","0"],["104557.8","0.13861314","0","1"],["104556.5","0","0","0"],["104553.5","0","0","0"],["104550.5","0.04102009","0","1"],["104489.5","0.01059634","0","1"],["104488.6","0.00009935","0","1"],["104381.4","0","0","0"],["104381.2","0","0","0"],["104380.9","0","0","0"],["104380.7","0","0","0"],["104380.6","0","0","0"],["104380.4","0","0","0"]],"ts":"1747168594709","checksum":470588597,"seqId":54225024905,"prevSeqId":54225024661}]}
{"arg":{"channel":"books","instId":"BTC-USDT"},"action":"update","data":[{"asks":[["104587.4","1.78195714","0","30"],["104587.8","0.19242972","0","1"],["104589.5","0","0","0"],["104590","0.10800079","0","3"],["104591.9","0.00045735","0","1"],["104592.2","0.09982909","0","1"],["104592.5","0.071683","0","1"],["104593.4","0","0","0"],["104593.5","0.45197895","0","2"],["104593.6","0.09563846","0","1"],["104593.7","0.34403187","0","3"],["104593.8","0","0","0"],["104594.5","0","0","0"],["104595.2","0.00044","0","1"],["104597.7","0.19227313","0","2"],["104598","0","0","0"],["104598.7","0","0","0"],["104599.3","0","0","0"],["104600.1","0.24347516","0","1"],["104601.5","0","0","0"],["104601.8","0","0","0"],["104602","0.62637415","0","2"],["104602.4","0.05716341","0","1"],["104603.2","0.45608395","0","3"],["104603.7","0","0","0"],["104603.9","0.13861528","0","1"],["104604.8","0","0","0"],["104605.9","0","0","0"],["104606.1","0.30323022","0","2"],["104607.7","0","0","0"],["104609.5","0","0","0"],["104609.7","0.60520933","0","2"],["104612","1","0","1"],["104650.7","0","0","0"],["104682","0.01051752","0","1"],["104682.1","0","0","0"],["104745.6","0.0347717","0","3"],["104746","2.12871219","0","2"],["104747","0.77866876","0","1"],["104747.2","0.00001055","0","1"],["104748","0.00108568","0","1"],["104748.6","0.01447816","0","1"],["104749","0.01059679","0","1"]],"bids":[["104586.8","0","0","0"],["104582","0","0","0"],["104579","0","0","0"],["104575.5","0","0","0"],["104574.8","0.00956028","0","1"],["104574.4","0","0","0"],["104574.3","0.07034091","0","2"],["104574.2","0.00098","0","1"],["104574","0","0","0"],["104572.8","0","0","0"],["104572.7","0.00137191","0","1"],["104571.8","0","0","0"],["104571.7","0.04126217","0","1"],["104571.2","0.09846477","0","1"],["104571.1","0.1002141","0","1"],["104571","0.38758408","0","3"],["104570.5","0","0","0"],["104570.2","0.16107981","0","1"],["104569.2","0","0","0"],["104568.7","0.071683","0","1"],["104566.8","0.22477337","0","1"],["104566.5","0","0","0"],["104565.1","0.23153292","0","1"],["104564.2","0","0","0"],["104563.9","0.00001","0","1"],["104562.5","0.23880645","0","1"],["104561.8","0.123","0","4"],["104560.6","0","0","0"],["104560.2","0.25510101","0","1"],["104558.6","0.25764028","0","1"],["104557.8","0","0","0"],["104556.1","0.14572386","0","2"],["104548.6","0.02868084","0","1"],["104540.8","0","0","0"],["104540.7","0.00478002","0","1"],["104519.3","0","0","0"],["104509.4","0.03","0","1"],["104496","0.37593297","0","2"],["104394","0.1205","0","1"],["104381.4","0.00003468","0","1"],["104381.2","0.00001042","0","1"],["104380.9","0.00013167","0","2"],["104380.7","0.00001015","0","1"],["104380.6","0.00001095","0","1"]],"ts":"1747168594809","checksum":1134711642,"seqId":54225025110,"prevSeqId":54225024905}]}
{"arg":{"channel":"books","instId":"BTC-USDT"},"action":"update","data":[{"asks":[["104589.1","0.05209701","0","2"],["104590","0.08161","0","2"],["104592","0.10996007","0","2"],["104592.2","0","0","0"],["104592.7","0.10170827","0","1"],["104593.5","0.32857751","0","1"],["104593.6","0","0","0"],["104593.9","0.02638979","0","1"],["104594.1","0.09031858","0","1"],["104596.7","0","0","0"],["104597.7","0.0414895","0","1"],["104598.2","0.17061723","0","1"],["104600.1","0","0","0"],["104600.5","0.24095456","0","2"],["104602","0.38863185","0","1"],["104602.5","0.24065202","0","1"],["104603.2","0.15121865","0","1"],["104603.7","0.24498623","0","1"],["104603.9","0","0","0"],["104605.9","0.13861233","0","1"],["104606.1","0.04","0","1"],["104606.6","0.2330935","0","1"],["104622.7","0","0","0"],["104627","0.002","0","2"],["104628","0.001","0","1"],["104630","0.00029006","0","2"],["104631","0","0","0"],["104633.3","1.41420525","0","1"],["104649","0.16","0","2"],["104650","0.08033023","0","4"],["104651","0.07","0","2"],["104652","0.62939815","0","4"],["104653","0.06089582","0","2"],["104657.7","0.1911","0","1"],["104664.7","2.61286565","0","1"],["104680.4","5.93878499","0","1"],["104686.2","0.04776","0","1"],["104690.5","0","0","0"],["104705.8","0.01104918","0","3"],["104711.4","0.05686101","0","2"],["104744.8","0","0","0"],["104745.5","0","0","0"],["104745.6","0","0","0"],["104746","0","0","0"],["104747","0","0","0"],["104747.2","0","0","0"],["104748","0","0","0"],["104748.6","0","0","0"],["104749","0","0","0"]],"bids":[["104587.3","0.12863704","0","6"],["104578.3","0.02697501","0","1"],["104575.9","0","0","0"],["104574.9","0.00477983","0","1"],["104574.3","0","0","0"],["104573.6","0.05892166","0","1"],["104572.7","0","0","0"],["104572.2","0","0","0"],["104571.8","0.00137191","0","1"],["104571.7","0.10004235","0","1"],["104571.6","0.09932569","0","1"],["104571.2","0","0","0"],["104571.1","0","0","0"],["104571","0.29599343","0","3"],["104570.8","0","0","0"],["104570.7","0.16050818","0","1"],["104570.2","0","0","0"],["104568.8","0.38863185","0","1"],["104565.5","0.24466776","0","1"],["104565.1","0","0","0"],["104564.4","0.05398715","0","2"],["104563","0.2608786","0","1"],["104562.5","0","0","0"],["104560.7","0.25932278","0","1"],["104560.2","0","0","0"],["104559.1","0.23432869","0","1"],["104558.6","0","0","0"],["104557.8","0.13861233","0","1"],["104556.1","0.00710858","0","1"],["104540.8","1.38834446","0","1"],["104526.1","0","0","0"],["104524.8","0","0","0"],["104523.7","0.02869139","0","1"],["104521.3","0","0","0"],["104520.4","0","0","0"],["104518.3","0","0","0"],["104514.9","0","0","0"],["104514.2","0","0","0"],["104511.1","0.01089584","0","1"],["104509.7","0.01059634","0","1"],["104509.4","2.57676227","0","2"],["104506.1","0","0","0"],["104380.4","0.00001008","0","1"],["104380","0.00259964","0","5"],["104379.8","0.00003579","0","1"],["104379.7","0.00117685","0","7"],["104379.6","0.00015483","0","1"],["104379","0.00213643","0","19"],["104378.8","0.00014788","0","2"]],"ts":"1747168594909","checksum":-1600944516,"seqId":54225025432,"prevSeqId":54225025110}]}
{"arg":{"channel":"books","instId":"BTC-USDT"},"action":"update","data":[{"asks":[["104591.9","0","0","0"],["104592","0.10996006","0","2"],["104592.7","0","0","0"],["104593.4","0.00045735","0","1"],["104593.6","0.09041728","0","1"],["104593.7","0.43708486","0","4"],["104594.1","0","0","0"],["104594.4","0.09368039","0","1"],["104595.1","0.0950798","0","1"],["104597.9","0.1471022","0","1"],["104598.2","0","0","0"],["104598.6","0.15594651","0","1"],["104599.2","0.15576283","0","1"],["104600.5","0.00092","0","1"],["104601.4","0.15292368","0","1"],["104601.6","0.23129252","0","1"],["104602.5","0","0","0"],["104603.2","0.3577932","0","2"],["104603.6","0.27003525","0","2"],["104603.7","0","0","0"],["104604.7","0.24352803","0","1"],["104605.9","0","0","0"],["104606.6","0","0","0"],["104607.6","0.23803763","0","1"],["104607.9","0.13861163","0","1"],["104649","0.23","0","4"],["104650","0.11533023","0","5"],["104651","0","0","0"],["104652","0.59439815","0","3"],["104653.3","6.00571499","0","2"],["104654.9","0.01051752","0","1"],["104656.2","0.01051752","0","1"],["104658.6","0.01051752","0","1"],["104659.3","0.78918628","0","2"],["104662","0.01051752","0","1"],["104664","0.01051752","0","1"],["104665.7","0.01051752","0","1"],["104666.6","0.01069052","0","2"],["104680.4","0","0","0"],["104698.3","0.08849335","0","1"],["104700.8","0","0","0"],["104741.9","0","0","0"],["104742.2","0","0","0"],["104742.8","0","0","0"],["104743.1","0","0","0"],["104743.2","0","0","0"],["104743.3","0","0","0"],["104744.3","0","0","0"],["104744.7","0","0","0"]],"bids":[["104587.3","0.12485704","0","5"],["104582","0.0816","0","1"],["104576","0","0","0"],["104574.9","0","0","0"],["104574.2","0.00235191","0","2"],["104574.1","0.09636241","0","1"],["104573.9","0.09648103","0","1"],["104573.6","0","0","0"],["104572.8","0.0412617","0","1"],["104572.7","0.10016216","0","1"],["104572.6","0.09682516","0","1"],["104571.8","0","0","0"],["104571.7","0.16569308","0","1"],["104571.6","0","0","0"],["104570.7","0","0","0"],["104570.4","0.14853064","0","1"],["104569.1","0.16023866","0","1"],["104568.1","0.2255021","0","2"],["104566.8","0.40316211","0","2"],["104566.6","0.2574509","0","2"],["104566.4","0.14811021","0","1"],["104566","0.06","0","2"],["104565.5","0","0","0"],["104564.1","0.24796096","0","1"],["104563","0","0","0"],["104561.7","0.26294126","0","1"],["104560.7","0","0","0"],["104560.1","0.49717733","0","2"],["104559.1","0","0","0"],["104543.3","0.00478069","0","1"],["104533","0.00062325","0","1"],["104532","0.19305297","0","2"],["104519.3","0.1205","0","1"],["104394","0","0","0"],["104379.6","0","0","0"],["104379","0","0","0"],["104378.8","0","0","0"]],"ts":"1747168595009","checksum":1219568542,"seqId":54225025615,"prevSeqId":54225025432}]}
{"arg":{"channel":"books","instId":"BTC-USDT"},"action":"update","data":[{"asks":[["104587.4","1.80970037","0","32"],["104601.4","0.15993119","0","2"],["104601.6","0","0","0"],["104601.7","0.24005518","0","1"],["104602.1","0.05243619","0","3"],["104603.5","0.13861563","0","1"],["104607.9","0","0","0"],["104616.3","0.0002293","0","1"],["104624.8","0","0","0"],["104649","0.33","0","6"],["104650","0.16533023","0","6"],["104651.7","0.00056666","0","1"],["104652","0.49439815","0","1"],["104653","0.01089582","0","1"],["104654.4","0.09555","0","1"],["104741.4","0","0","0"]],"bids":[["104580.3","0","0","0"],["104577.7","0.00477979","0","1"],["104574.3","0.00137191","0","1"],["104574.2","0.13270774","0","2"],["104566.7","0.25511141","0","1"],["104566.6","0.00482005","0","1"],["104563.2","0.00056666","0","1"],["104557.8","0","0","0"],["104556","0.26904084","0","4"],["104550.8","0","0","0"],["104527.9","0.00056666","0","1"],["104524.2","0.00005783","0","2"],["104519.3","0","0","0"],["104506.2","0","0","0"],["104497.9","0","0","0"],["104476.5","0.00001","0","1"],["104468.6","0.00001","0","1"],["104409.8","0","0","0"],["104402.3","0.00118057","0","1"],["104394","0.1205","0","1"],["104379.8","0","0","0"],["104379.7","0","0","0"]],"ts":"1747168595109","checksum":-1180255224,"seqId":54225025669,"prevSeqId":54225025615}]}
{"arg":{"channel":"books","instId":"BTC-USDT"},"action":"update","data":[{"asks":[["104591.9","0.00045735","0","1"],["104592.6","0.01797486","0","1"],["104593.4","0","0","0"],["104593.6","0","0","0"],["104593.7","0.34403187","0","3"],["104594.4","0","0","0"],["104595.1","0","0","0"],["104597.6","0.00477949","0","1"],["104597.9","0","0","0"],["104598.6","0","0","0"],["104598.9","0","0","0"],["104599","0","0","0"],["104599.2","0","0","0"],["104600.9","0.25499955","0","1"],["104601.4","0.00700751","0","1"],["104601.7","0","0","0"],["104602","0.39909002","0","2"],["104602.9","0.32498165","0","2"],["104603.2","0.28690255","0","1"],["104603.5","0","0","0"],["104603.6","0.00001","0","1"],["104604.7","0","0","0"],["104607.6","0","0","0"],["104607.9","0.13861181","0","1"],["104615.6","0","0","0"],["104621.9","0.09561","0","1"],["104627","0","0","0"],["104628","0","0","0"],["104628.1","0.00478002","0","1"],["104628.2","0","0","0"],["104629","0.00679878","0","3"],["104630","0.00129006","0","3"],["104639.2","0.60523","0","1"],["104641.3","0","0","0"],["104642.3","0","0","0"],["104644.3","0.02119092","0","2"],["104649","0","0","0"],["104650","0.00033024","0","3"],["104650.6","0.53164051","0","3"],["104651","0.33","0","6"],["104652","0.65939814","0","4"],["104652.8","0.01056714","0","2"],["104654.3","0.01051752","0","1"],["104656.1","0.01051752","0","1"],["104657.7","0.20161752","0","2"],["104668.8","0.01600824","0","1"],["104741.4","0.02119358","0","2"],["104741.9","0.00008643","0","1"],["104742.2","0.0217917","0","2"],["104742.8","0.00002611","0","2"],["104743.1","0.00011716","0","4"],["104743.2","0.01059679","0","1"],["104743.3","0.01059679","0","1"],["104744.3","0.00005567","0","1"],["104744.7","0.00029761","0","1"]],"bids":[["104587.3","0.01786604","0","3"],["104586.9","0.00001","0","1"],["104584","0.0816","0","1"],["104580.2","0.0269745","0","1"],["104577.7","0","0","0"],["104575.9","0.00477979","0","1"],["104574.3","0","0","0"],["104574.2","0.07182391","0","3"],["104574.1","0","0","0"],["104573.9","0","0","0"],["104573.4","0.00137191","0","1"],["104572.7","0","0","0"],["104572.6","0","0","0"],["104571.7","0","0","0"],["104571","0.28517565","0","2"],["104570.4","0","0","0"],["104569.1","0","0","0"],["104568.4","0.16106916","0","1"],["104566.8","0.20310127","0","1"],["104566.7","0","0","0"],["104566.4","0","0","0"],["104565.9","0.25445728","0","1"],["104564.1","0","0","0"],["104563.4","0.25147778","0","1"],["104561.7","0","0","0"],["104560.1","0.234","0","1"],["104558.3","0.13861181","0","1"],["104556","0.13042521","0","3"],["104524.6","0.3182155","0","1"],["104521.4","0.00015488","0","1"],["104520.5","0","0","0"],["104519.3","0.1205","0","1"],["104515","0","0","0"],["104513.5","0.03","0","1"],["104512.6","0","0","0"],["104509.8","0","0","0"],["104500.6","0","0","0"],["104495.8","0.01271752","0","2"],["104494.1","0.01051752","0","1"],["104489","0.00173755","0","1"],["104487.1","0","0","0"],["104480.2","0","0","0"],["104477.9","0.02123152","0","2"],["104472.3","0","0","0"],["104472.2","0","0","0"],["104452.2","0.0579344","0","1"],["104443.2","0.01400777","0","1"],["104416.5","0.01400906","0","1"],["104402.3","0","0","0"],["104394","0","0","0"],["104392.1","0.00095792","0","1"],["104379.8","0.00003579","0","1"],["104379.7","0.00117685","0","7"],["104379.6","0.00015483","0","1"],["104379","0.00213643","0","19"],["104378.8","0.00014788","0","2"],["104378.7","0.00002991","0","2"],["104378.2","0.0000647","0","1"],["104377.7","0.00031738","0","2"]],"ts":"1747168595209","checksum":1650995337,"seqId":54225026034,"prevSeqId":54225025669}]}
{"arg":{"channel":"books","instId":"BTC-USDT"},"action":"update","data":[{"asks":[["104584.1","1.37739349","0","14"],["104584.3","0.29193486","0","1"],["104586","0.0816","0","1"],["104586.7","0.39270282","0","1"],["104586.8","0.77866876","0","1"],["104587.2","0.00045735","0","1"],["104587.3","0.50409","0","4"],["104587.4","0.37921298","0","7"],["104587.9","0","0","0"],["104588","0.43706426","0","2"],["104588.4","0","0","0"],["104589.7","0.0137947","0","1"],["104590.5","0","0","0"],["104590.6","0.09099189","0","1"],["104591.1","0.09038731","0","1"],["104591.4","0.08608576","0","1"],["104591.9","0.00044","0","1"],["104592.2","0.09361681","0","1"],["104593.5","0.24641042","0","2"],["104593.7","0.05209701","0","2"],["104594.9","0.15295388","0","1"],["104595.2","0","0","0"],["104595.6","0.15754626","0","1"],["104596.6","0.16389739","0","1"],["104597.2","0.00092","0","1"],["104598.4","0.15060904","0","1"],["104598.7","0.25496861","0","1"],["104600.5","0","0","0"],["104600.6","0.2384756","0","1"],["104600.9","0","0","0"],["104602.1","0.29709646","0","4"],["104602.4","0.05808341","0","2"],["104602.9","0.0571631","0","1"],["104603.2","0.21384093","0","2"],["104604.7","0.23860987","0","1"],["104605.7","0","0","0"],["104606.6","0.11375","0","1"],["104607.6","0.00191","0","1"],["104608","0","0","0"],["104610.9","0","0","0"],["104611.4","0.04","0","1"],["104612.9","0.00191","0","1"],["104616","0.77866876","0","1"],["104616.2","0","0","0"],["104629","0.00479878","0","1"],["104630","0.00229006","0","4"],["104630.6","0.4730285","0","3"],["104631","0.001","0","1"],["104635.6","0.01434207","0","1"],["104636.7","0.00956138","0","1"],["104641.9","0.00956138","0","1"],["104642.2","0","0","0"],["104651","0.07","0","2"],["104652","0.78939815","0","6"],["104653","0.14089581","0","3"],["104660.9","1.2432657","0","2"],["104664.1","0.5419431","0","3"],["104697.5","0.06334032","0","2"],["104739.6","0","0","0"],["104739.7","0","0","0"],["104739.9","0","0","0"],["104740","0","0","0"],["104740.3","0","0","0"],["104740.5","0","0","0"],["104740.6","0","0","0"],["104740.7","0","0","0"],["104741.4","0","0","0"],["104741.9","0","0","0"],["104742.2","0","0","0"],["104742.8","0","0","0"],["104743.1","0","0","0"],["104743.2","0","0","0"],["104743.3","0","0","0"],["104744.3","0","0","0"],["104744.7","0","0","0"]],"bids":[["104587.3","0","0","0"],["104587.2","0","0","0"],["104586.9","0","0","0"],["104583.9","0.00001","0","1"],["104579.5","0","0","0"],["104576.9","0","0","0"],["104576.2","0.00051","0","1"],["104575.9","0","0","0"],["104574.9","0.00477988","0","1"],["104574.2","0.01477851","0","1"],["104573.6","0.00251108","0","1"],["104573.4","0","0","0"],["104571.2","0.00137191","0","1"],["104571.1","0.09955497","0","1"],["104571","0.40784633","0","3"],["104570.9","0.09315549","0","3"],["104570.1","0.09161035","0","1"],["104569.7","0.09063048","0","2"],["104569.3","0","0","0"],["104569.1","0.16417635","0","1"],["104569","0","0","0"],["104568.4","0","0","0"],["104567.4","0.14996529","0","1"],["104566.8","0.30150152","0","2"],["104566.1","0.17065474","0","2"],["104565.9","0.03440653","0","1"],["104565.7","0.06222373","0","2"],["104563.8","0","0","0"],["104563.7","0.24861083","0","1"],["104563.4","0.15250876","0","1"],["104561.1","0.92793701","0","3"],["104560.5","0.00191","0","1"],["104559.1","0.27113047","0","1"],["104558.5","0","0","0"],["104557.5","0.00382565","0","1"],["104557.2","0.26078007","0","1"],["104555.2","0.00191","0","1"],["104545.6","1.49890848","0","2"],["104545.4","0.00017476","0","1"],["104527.3","0","0","0"],["104509.6","1.75073149","0","2"],["104496.2","0.01053252","0","2"],["104480.5","0","0","0"],["104479.2","0.00063712","0","1"],["104474.5","0.75787332","0","2"],["104464.9","0","0","0"],["104463.3","0.00083748","0","1"],["104446","0.01089568","0","1"],["104401.6","0.00118057","0","1"],["104378.8","0","0","0"],["104378.7","0","0","0"],["104378.2","0","0","0"],["104377.7","0","0","0"]],"ts":"1747168595309","checksum":1101125240,"seqId":54225026384,"prevSeqId":54225026034}]}
{"arg":{"channel":"books","instId":"BTC-USDT"},"action":"update","data":[{"asks":[["104587.3","0.27009","0","3"],["104587.4","0.3721044","0","6"],["104592.2","0","0","0"],["104598.7","0","0","0"],["104599.4","0.00710858","0","1"],["104604.7","0","0","0"],["104610.6","0","0","0"],["104613.1","0.00479585","0","2"],["104613.5","0.00955669","0","1"],["104619.3","0","0","0"],["104623.9","0.00013667","0","1"],["104627.3","0","0","0"],["104630.4","0","0","0"],["104632.6","0.02228315","0","1"],["104638.9","0.1","0","1"],["104660","0.00221843","0","4"],["104691.9","0.00080394","0","1"],["104716.3","0","0","0"],["104739.6","0.00023506","0","1"],["104739.7","0.00001107","0","1"],["104739.9","0.0013452","0","1"]],"bids":[["104583.9","0","0","0"],["104574.9","0.00477982","0","1"],["104569.7","0.0006199","0","1"],["104563.7","0","0","0"],["104557.2","0","0","0"],["104401.6","0","0","0"],["104401.2","0.00118057","0","1"],["104378.8","0.00014788","0","2"],["104378.7","0.00002991","0","2"],["104378.2","0.0000647","0","1"]],"ts":"1747168595409","checksum":75278202,"seqId":54225026433,"prevSeqId":54225026384}]}
{"arg":{"channel":"books","instId":"BTC-USDT"},"action":"update","data":[{"asks":[["104584.1","0.49170385","0","11"],["104584.2","0.19319766","0","1"],["104586.7","0","0","0"],["104586.8","0","0","0"],["104587.3","0.27","0","2"],["104587.4","0.1381044","0","5"],["104587.8","0","0","0"],["104588","0.30385789","0","2"],["104590.6","0","0","0"],["104591.4","0","0","0"],["104592","0.0816","0","1"],["104592.2","0.08899685","0","1"],["104592.6","0","0","0"],["104593","0.09674011","0","1"],["104593.8","0.09735424","0","1"],["104593.9","0","0","0"],["104594.9","0","0","0"],["104595.3","0.02638943","0","1"],["104595.6","0","0","0"],["104596.5","0.14471549","0","1"],["104597.2","0.17096387","0","2"],["104597.6","0","0","0"],["104598.4","0","0","0"],["104600","0.15674746","0","3"],["104600.1","0.00477964","0","1"],["104600.3","0.27720151","0","2"],["104600.6","0","0","0"],["104602.2","0.26263044","0","1"],["104606.3","0.26720189","0","1"],["104607.9","0","0","0"],["104610","0.13889696","0","3"],["104625.8","0","0","0"],["104632.6","0","0","0"],["104640.2","0.02443456","0","1"],["104645.8","0.02515315","0","2"],["104740","0.00219843","0","2"],["104740.3","0.00005155","0","1"],["104740.5","0.00006468","0","1"],["104740.6","0.0217917","0","2"]],"bids":[["104584","0.15354","0","4"],["104582.3","0.02697395","0","1"],["104578.3","0.02799569","0","2"],["104574.9","0","0","0"],["104574.2","0.13091031","0","2"],["104573.6","0.00388299","0","2"],["104573.5","0.242","0","2"],["104572.7","0.09106611","0","1"],["104572.5","0.09525039","0","1"],["104571.3","0.09338876","0","1"],["104571.2","0","0","0"],["104571.1","0.03440653","0","1"],["104571","0.5875624","0","2"],["104570.9","0.00148","0","2"],["104569","0.14668675","0","1"],["104568.2","0.00477964","0","1"],["104568.1","0.17764565","0","1"],["104567.7","0.16509593","0","1"],["104567.5","0.19242972","0","1"],["104567.4","0","0","0"],["104566.9","0.77866876","0","1"],["104566.8","0.37519936","0","2"],["104566.1","0","0","0"],["104565.9","0","0","0"],["104565.3","0.24688783","0","1"],["104565","0.16356067","0","1"],["104563.4","0","0","0"],["104562.7","0.2714203","0","1"],["104562","0.1386069","0","1"],["104561.1","0.68002597","0","2"],["104558.8","0.24041351","0","1"],["104558.3","0","0","0"],["104542.7","0.002868","0","1"],["104521.4","0","0","0"],["104516.6","0.00015488","0","1"],["104513.4","0","0","0"],["104488.6","0","0","0"],["104484.6","0.00011053","0","1"],["104480.4","0.01089581","0","1"],["104460.4","0.0579344","0","1"],["104452.2","0","0","0"],["104436.1","0","0","0"],["104432.8","0.00095592","0","1"],["104379.8","0","0","0"],["104379.7","0","0","0"],["104379.6","0","0","0"],["104379","0","0","0"],["104378.8","0","0","0"],["104378.7","0","0","0"],["104378.2","0","0","0"]],"ts":"1747168595509","checksum":1417640375,"seqId":54225026586,"prevSeqId":54225026433}]}
{"arg":{"channel":"books","instId":"BTC-USDT"},"action":"update","data":[{"asks":[["104584.1","0.65580035","0","15"],["104589.7","0","0","0"],["104591.1","0","0","0"],["104592.2","0","0","0"],["104592.3","0.10147078","0","1"],["104592.4","0.09393359","0","1"],["104593","0","0","0"],["104593.1","0.0899153","0","1"],["104596.5","0","0","0"],["104596.6","0.14717087","0","1"],["104597.2","0.00092","0","1"],["104597.3","0.15219772","0","1"],["104597.9","0.16609264","0","1"],["104600","0.00029006","0","2"],["104600.1","0.15481348","0","2"],["104602.1","0.05243619","0","3"],["104602.2","0","0","0"],["104602.3","0.24408177","0","1"],["104603.4","0.25173005","0","1"],["104607.7","0.0137947","0","1"],["104633.5","0.01912336","0","1"],["104633.7","0.00004964","0","1"],["104644.4","0.01109194","0","2"],["104652.8","0.01051752","0","1"],["104674","0","0","0"],["104740.3","0","0","0"],["104740.5","0","0","0"],["104740.6","0","0","0"]],"bids":[["104578.3","0.03003539","0","4"],["104576.3","0.00477973","0","1"],["104574.3","0.00137191","0","1"],["104573.6","0.00251108","0","1"],["104572.8","0.13353719","0","2"],["104572.7","0","0","0"],["104572.6","0.0880407","0","1"],["104572.5","0","0","0"],["104571.4","0.09125858","0","1"],["104570.4","0.16212052","0","1"],["104570.1","0","0","0"],["104569.1","0.14561987","0","1"],["104569","0","0","0"],["104567.8","0.14998275","0","1"],["104567.7","0","0","0"],["104567.5","0","0","0"],["104565.1","0.15006265","0","1"],["104565","0","0","0"],["104562.8","0.24887534","0","1"],["104562.7","0","0","0"],["104560.4","0.2676791","0","1"],["104559.1","0","0","0"],["104535.1","0.00066769","0","1"],["104496.3","0.01051785","0","1"],["104494.9","0.87051623","0","3"],["104493.3","0.09930691","0","2"],["104491.1","0.01051785","0","1"],["104489.1","0.01051785","0","1"],["104484.6","0.01062838","0","2"],["104380.7","0","0","0"],["104380.6","0","0","0"],["104380.4","0","0","0"],["104380","0","0","0"]],"ts":"1747168595609","checksum":-500969726,"seqId":54225026646,"prevSeqId":54225026586}]}
{"arg":{"channel":"books","instId":"BTC-USDT"},"action":"update","data":[{"asks":[["104584.9","0.03440653","0","1"],["104587.4","0.1105524","0","4"],["104607.7","0","0","0"],["104699.9","0.13070972","0","7"],["104700","0.02356275","0","20"]],"bids":[["104578.3","0.03105441","0","5"],["104573.7","0.008","0","1"],["104573.5","0.234","0","1"],["104380.9","0","0","0"]],"ts":"1747168595709","checksum":-1859122787,"seqId":54225026656,"prevSeqId":54225026646}]}
{"arg":{"channel":"books","instId":"BTC-USDT"},"action":"update","data":[{"asks":[["104584.1","0.93020232","0","17"],["104587.9","0.19242972","0","1"],["104653.3","0.06693","0","1"],["104663.5","5.85836207","0","1"],["104719","0","0","0"],["104740","0","0","0"]],"bids":[["104578.3","0.03207509","0","6"],["104576.3","0.26477973","0","2"],["104571","0.59104588","0","3"]],"ts":"1747168595809","checksum":1687491649,"seqId":54225026672,"prevSeqId":54225026656}]}
{"arg":{"channel":"books","instId":"BTC-USDT"},"action":"update","data":[{"asks":[["104592.3","0","0","0"],["104592.4","0.09293823","0","1"],["104592.5","0.1622419","0","2"],["104593.1","0","0","0"],["104593.2","0.09677145","0","1"],["104593.4","0.02835967","0","1"],["104593.8","0","0","0"],["104593.9","0.09716211","0","1"],["104596.6","0","0","0"],["104596.7","0.14372518","0","1"],["104597.3","0","0","0"],["104597.4","0.17726914","0","2"],["104597.9","0","0","0"],["104598","0.166639","0","1"],["104600.1","0.00477964","0","1"],["104600.2","0.33734055","0","2"],["104600.3","0.03824062","0","1"],["104600.4","0.23198448","0","1"],["104602.3","0","0","0"],["104602.4","0.25529215","0","2"],["104603.2","0.24960169","0","2"],["104603.4","0","0","0"],["104603.5","0.25498453","0","1"],["104605","0.005","0","1"],["104606.3","0","0","0"],["104606.4","0.24143966","0","1"],["104608.3","0.13861024","0","1"],["104610","0.00029006","0","2"],["104617.5","0.005","0","1"],["104660.1","5.85836207","0","1"],["104663.5","0","0","0"],["104739.6","0","0","0"],["104739.7","0","0","0"],["104739.9","0","0","0"]],"bids":[["104584","0.08242888","0","3"],["104581.8","0.005","0","1"],["104578.3","0.03309577","0","7"],["104576.4","0.1334811","0","2"],["104576.3","0.00477973","0","1"],["104574.3","0","0","0"],["104574.2","0","0","0"],["104573.6","0.00388299","0","2"],["104572.9","0.08967078","0","1"],["104572.8","0.0412617","0","1"],["104572.7","0.0910121","0","1"],["104572.6","0","0","0"],["104571.5","0.09724059","0","1"],["104571.4","0.0882058","0","1"],["104571.3","0","0","0"],["104571","0.40279458","0","2"],["104570.5","0.15859721","0","1"],["104570.4","0","0","0"],["104569.3","0.005","0","1"],["104569.2","0.15797632","0","1"],["104569.1","0","0","0"],["104567.9","0.16504576","0","2"],["104567.8","0","0","0"],["104566.9","0","0","0"],["104566.8","0.31779242","0","2"],["104565.4","0.25812171","0","1"],["104565.3","0","0","0"],["104565.2","0.15095156","0","1"],["104565.1","0","0","0"],["104562.9","0.25141059","0","1"],["104562.8","0","0","0"],["104562","0","0","0"],["104560.5","0.25553328","0","2"],["104560.4","0","0","0"],["104559","0.13862525","0","2"],["104558.9","0.23996107","0","1"],["104558.8","0","0","0"],["104380.9","0.00013167","0","2"],["104380.7","0.00001015","0","1"]],"ts":"1747168595909","checksum":-1269061044,"seqId":54225026769,"prevSeqId":54225026672}]}
{"arg":{"channel":"books","instId":"BTC-USDT"},"action":"update","data":[{"asks":[["104584.1","0.95112149","0","18"],["104592.4","0","0","0"],["104592.5","0.16773834","0","2"],["104592.6","0.09125409","0","1"],["104593.2","0","0","0"],["104593.3","0.09327178","0","1"],["104593.5","0.27946522","0","2"],["104593.9","0","0","0"],["104594","0.18010666","0","2"],["104596.7","0","0","0"],["104596.8","0.43646536","0","4"],["104597.4","0.02638892","0","1"],["104597.5","0.15790546","0","1"],["104598","0","0","0"],["104598.1","0.15613769","0","1"],["104600.2","0.33780718","0","2"],["104600.4","0","0","0"],["104600.5","0.23054346","0","1"],["104602.4","0.00092","0","1"],["104602.5","0.25751817","0","1"],["104603.2","0.29319197","0","2"],["104603.5","0","0","0"],["104603.6","0.25268139","0","2"],["104605.9","0.138613","0","1"],["104606.4","0","0","0"],["104606.5","0.2454435","0","1"],["104608.3","0","0","0"],["104610.8","0.00478084","0","1"],["104628.1","0","0","0"],["104739.6","0.00023506","0","1"]],"bids":[["104584","0.15352888","0","4"],["104583","0.00877742","0","1"],["104576.5","0.00477981","0","1"],["104576.4","0.13784963","0","1"],["104576.3","0","0","0"],["104573.6","0.00251108","0","1"],["104573.1","0.00137191","0","1"],["104573","0.09646404","0","1"],["104572.9","0","0","0"],["104572.8","0.13329148","0","2"],["104572.7","0","0","0"],["104571.6","0.09575185","0","1"],["104571.5","0.0892273","0","1"],["104571.4","0","0","0"],["104571","0.38110995","0","3"],["104570.6","0.16739382","0","1"],["104570.5","0","0","0"],["104569.3","0.16005733","0","2"],["104569.2","0","0","0"],["104568","0.1676081","0","1"],["104567.9","0.00001","0","1"],["104566.8","0.31560406","0","2"],["104565.5","0.24419252","0","1"],["104565.4","0","0","0"],["104565.2","0.16080376","0","1"],["104563","0.24409922","0","1"],["104562.9","0","0","0"],["104560.6","0.24619757","0","1"],["104560.5","0.00191","0","1"],["104559","0.24974274","0","2"],["104558.9","0","0","0"],["104557.8","0.138613","0","1"],["104380.9","0","0","0"],["104380.7","0","0","0"]],"ts":"1747168596009","checksum":-2081216434,"seqId":54225026942,"prevSeqId":54225026769}]}
{"arg":{"channel":"books","instId":"BTC-USDT"},"action":"update","data":[{"asks":[["104584.1","0.93020232","0","17"],["104587.9","0","0","0"],["104592.5","0.071683","0","1"],["104592.6","0.10080402","0","1"],["104592.7","0.08992325","0","1"],["104593.3","0","0","0"],["104593.4","0.09459953","0","1"],["104593.5","0.2801507","0","2"],["104594","0.0816","0","1"],["104594.1","0.09284053","0","1"],["104596.8","0.28609701","0","3"],["104596.9","0.15947908","0","1"],["104597.5","0","0","0"],["104597.6","0.15674577","0","1"],["104598.1","0","0","0"],["104598.2","0.15489722","0","1"],["104600.1","0","0","0"],["104600.2","0.17764565","0","1"],["104600.4","0.16510066","0","1"],["104600.5","0.00700751","0","1"],["104600.6","0.23565837","0","1"],["104601.4","0","0","0"],["104601.9","0.00477964","0","1"],["104602.5","0","0","0"],["104602.6","0.26334819","0","2"],["104603.2","0.23452315","0","2"],["104603.6","0.00001","0","1"],["104603.7","0.25802136","0","1"],["104605.9","0","0","0"],["104606.3","0.04452912","0","1"],["104606.5","0.13861158","0","1"],["104606.6","0.35383933","0","2"],["104615","0.0002293","0","1"],["104616.3","0","0","0"],["104618.6","0","0","0"],["104623.2","0.00013668","0","1"],["104623.9","0","0","0"],["104628","0.002","0","2"],["104629","0.00579878","0","2"],["104630","0.00029006","0","2"],["104631","0","0","0"],["104650","0.33033023","0","9"],["104651","0.16499999","0","3"],["104651.7","0","0","0"],["104652","0.49439815","0","1"],["104652.6","0.00056666","0","1"],["104653","0.01089582","0","1"],["104691.8","0.00009736","0","1"],["104694.7","0","0","0"],["104739.6","0","0","0"]],"bids":[["104584","0.16482641","0","5"],["104576.4","0.13339735","0","2"],["104573.6","0.00388299","0","2"],["104573.1","0.09868569","0","1"],["104573","0","0","0"],["104572.9","0.0859003","0","1"],["104572.8","0.0412617","0","1"],["104571.7","0.09493823","0","1"],["104571.6","0.09580778","0","1"],["104571.5","0","0","0"],["104571","0.60495729","0","2"],["104570.7","0.15619533","0","1"],["104570.6","0","0","0"],["104569.4","0.15262951","0","2"],["104569.3","0.005","0","1"],["104568.2","0","0","0"],["104568.1","0.32827498","0","2"],["104568","0","0","0"],["104566.9","0.77866876","0","1"],["104566.8","0.25353522","0","2"],["104565.6","0.2579597","0","1"],["104565.5","0","0","0"],["104565.4","0.15524463","0","1"],["104565.2","0","0","0"],["104563.2","0","0","0"],["104563.1","0.25741066","0","2"],["104563","0","0","0"],["104560.7","0.2545601","0","1"],["104560.6","0","0","0"],["104559.1","0.23955818","0","1"],["104559","0.00001501","0","1"],["104558.5","0.00056666","0","1"],["104527.9","0","0","0"],["104521","0.00056666","0","1"],["104495","0.0105958","0","1"],["104484.7","0.01070438","0","2"],["104484.6","0.01051785","0","1"],["104479.2","0","0","0"],["104478","0.00063716","0","1"],["104466.9","0.0105958","0","1"],["104464.6","0.00001","0","1"],["104464.3","0.0105958","0","1"],["104463.3","0","0","0"],["104462.9","0.00001","0","1"],["104462.1","0.00083751","0","1"],["104382.8","0","0","0"],["104382.5","0","0","0"],["104382.3","0","0","0"],["104382.2","0","0","0"],["104381.4","0","0","0"],["104381.2","0","0","0"]],"ts":"1747168596109","checksum":-1996957895,"seqId":54225027121,"prevSeqId":54225026942}]}
{"arg":{"channel":"books","instId":"BTC-USDT"},"action":"update","data":[{"asks":[["104584.1","0.9604298","0","21"],["104599.5","0.00477964","0","1"],["104601.9","0","0","0"],["104606","0.22021199","0","2"],["104606.5","0","0","0"],["104627","0.002","0","2"],["104628","0.001","0","1"],["104629","0.00479878","0","1"],["104649","0.26","0","4"],["104650","0.20033023","0","7"],["104650.6","0.11557632","0","2"],["104651","0.035","0","1"],["104739.3","0","0","0"]],"bids":[["104569.4","0.14784987","0","1"],["104567","0.00477964","0","1"],["104557.8","0.13861199","0","1"],["104382.9","0","0","0"]],"ts":"1747168596209","checksum":1414896656,"seqId":54225027184,"prevSeqId":54225027121}]}
{"arg":{"channel":"books","instId":"BTC-USDT"},"action":"update","data":[{"asks":[["104584.1","0.93863132","0","19"],["104589","0.19764547","0","2"],["104606","0.0816","0","1"],["104608.3","0.13861041","0","1"],["104636.1","0.02179136","0","2"],["104638.7","0.01089568","0","1"],["104656.3","0","0","0"],["104660.1","0","0","0"],["104663.5","5.80356302","0","1"],["104739.1","0","0","0"],["104739.2","0","0","0"]],"bids":[["104571","0.40337999","0","2"],["104566.9","0","0","0"],["104559.2","0.13861041","0","1"],["104557.8","0","0","0"],["104541.5","0.00076456","0","2"],["104539.3","0.06783469","0","2"],["104504","0.17407458","0","1"],["104503.3","0","0","0"],["104466.9","0.03231788","0","2"],["104382.9","0.00162841","0","7"]],"ts":"1747168596309","checksum":-125455945,"seqId":54225027220,"prevSeqId":54225027184}]}
{"arg":{"channel":"books","instId":"BTC-USDT"},"action":"update","data":[{"asks":[["104584.1","0.95650268","0","20"],["104649","0.1","0","2"],["104650","0.05033024","0","4"],["104651","0.07","0","2"],["104652","0.68939815","0","4"],["104653","0.09089581","0","2"],["104660.1","5.80356302","0","1"],["104663.5","0","0","0"]],"bids":[["104571","0.59155812","0","3"],["104566.9","0.77866876","0","1"],["104382.9","0","0","0"]],"ts":"1747168596409","checksum":906617925,"seqId":54225027277,"prevSeqId":54225027220}]}
{"arg":{"channel":"books","instId":"BTC-USDT"},"action":"update","data":[{"asks":[["104584.1","0.84592268","0","19"],["104649","0.33","0","6"],["104650","0.16533023","0","6"],["104651","0","0","0"],["104652","0.49439815","0","1"],["104653","0.01089582","0","1"],["104739.1","0.00001501","0","1"]],"bids":[],"ts":"1747168596509","checksum":1655701826,"seqId":54225027295,"prevSeqId":54225027277}]}
{"arg":{"channel":"books","instId":"BTC-USDT"},"action":"update","data":[{"asks":[["104584.1","0.96632407","0","21"],["104595.8","0.01722393","0","1"],["104608.3","0.13861104","0","1"],["104698.4","0","0","0"],["104729.4","0.01356899","0","1"],["104739.1","0","0","0"]],"bids":[["104575.9","0.01771458","0","1"],["104566.9","0","0","0"],["104489","0","0","0"],["104477.9","0.00974584","0","1"],["104392.1","0","0","0"],["104382.9","0.00162841","0","7"],["104382.8","2.65237537","0","2"]],"ts":"1747168596609","checksum":-1286867848,"seqId":54225027313,"prevSeqId":54225027295}]}
{"arg":{"channel":"books","instId":"BTC-USDT"},"action":"update","data":[{"asks":[["104584.1","0.96827557","0","21"],["104592.2","0.09976401","0","1"],["104592.3","0.09086305","0","1"],["104592.6","0","0","0"],["104592.7","0","0","0"],["104593","0.13033104","0","2"],["104593.4","0","0","0"],["104593.5","0.32671872","0","2"],["104593.7","0.14022939","0","3"],["104594.1","0","0","0"],["104596.5","0.14623044","0","1"],["104596.9","0","0","0"],["104597.2","0.15567095","0","2"],["104597.4","0","0","0"],["104597.6","0","0","0"],["104597.7","0.04626914","0","2"],["104597.8","0.15795443","0","1"],["104598.2","0","0","0"],["104599.5","0","0","0"],["104600","0.16076048","0","3"],["104600.2","0.40676905","0","2"],["104600.4","0","0","0"],["104600.6","0","0","0"],["104602.2","0.24414297","0","1"],["104602.6","0.00001501","0","1"],["104603.3","0.25474642","0","1"],["104603.7","0","0","0"],["104606.2","0.24806582","0","1"],["104606.5","0.13861146","0","1"],["104606.6","0.11375","0","1"],["104608.3","0","0","0"],["104627","0","0","0"],["104628","0.002","0","2"],["104629","0.00579878","0","2"],["104649","0","0","0"],["104650","0.33032023","0","8"],["104651","0.16499999","0","3"],["104712.2","0","0","0"],["104739.1","0.00001501","0","1"],["104739.2","0.01089655","0","1"],["104739.3","0.01059679","0","1"],["104739.6","0.00023506","0","1"],["104739.7","0.00001107","0","1"],["104739.9","0.0013452","0","1"]],"bids":[["104584","0.01213753","0","3"],["104580","0.08380843","0","4"],["104576.5","0","0","0"],["104576.4","0.08916749","0","1"],["104576","0.00477978","0","1"],["104573.6","0.00251108","0","1"],["104573.5","0","0","0"],["104573.1","0","0","0"],["104572.9","0.00137191","0","1"],["104572.7","0.09229967","0","1"],["104572.5","0.08737008","0","1"],["104571.7","0","0","0"],["104571.6","0","0","0"],["104571.3","0.10216503","0","1"],["104571.2","0.09147363","0","1"],["104571","0.37406392","0","3"],["104570.7","0","0","0"],["104570.3","0.15587275","0","1"],["104569.4","0","0","0"],["104569","0.15148317","0","1"],["104568.8","0","0","0"],["104568.1","0.17764565","0","1"],["104567.7","0.14895203","0","1"],["104567","0","0","0"],["104566.8","0.12232801","0","1"],["104566.1","0.00477964","0","1"],["104565.6","0","0","0"],["104565.4","0","0","0"],["104565.2","0.22950011","0","1"],["104565","0.16714353","0","1"],["104563.1","0.00119649","0","1"],["104562.7","0.2513835","0","1"],["104560.7","0","0","0"],["104560.3","0.24901653","0","1"],["104559.2","0","0","0"],["104559.1","0","0","0"],["104558.7","0.24966267","0","1"],["104557.8","0.13861152","0","1"],["104518.4","0.19242972","0","1"],["104452.2","0.00173816","0","1"],["104441.4","0.01148969","0","1"],["104383.3","0","0","0"],["104383.2","0","0","0"],["104382.9","0","0","0"],["104382.8","0","0","0"]],"ts":"1747168596709","checksum":620174347,"seqId":54225027417,"prevSeqId":54225027313}]}
{"arg":{"channel":"books","instId":"BTC-USDT"},"action":"update","data":[{"asks":[["104580.3","0.61035068","0","9"],["104581.8","0.52888127","0","4"],["104581.9","1.95307091","0","14"],["104582","0.0816","0","1"],["104582.3","0.27","0","2"],["104582.4","0.28609701","0","3"],["104584","0.01","0","1"],["104584.1","0.53895872","0","6"],["104584.2","0","0","0"],["104587.2","0.77912611","0","2"],["104587.3","0","0","0"],["104588","0.38949168","0","3"],["104588.8","0.09959202","0","1"],["104588.9","0.09031884","0","1"],["104589.6","0.09322644","0","1"],["104590.3","0.10026398","0","1"],["104592.2","0","0","0"],["104592.3","0","0","0"],["104593","0.03405496","0","1"],["104593.1","0.15926813","0","1"],["104593.5","0.17234784","0","1"],["104593.7","0.05209701","0","2"],["104593.8","0.16298646","0","1"],["104594.4","0.16935223","0","1"],["104595.9","0.00477964","0","1"],["104596.5","0","0","0"],["104596.6","0.1625878","0","1"],["104596.8","0.51620705","0","4"],["104597.2","0.00092","0","1"],["104597.7","0.0414895","0","1"],["104597.8","0","0","0"],["104598.8","0.2589934","0","1"],["104599.4","0","0","0"],["104599.9","0.24889673","0","1"],["104600","0.00029006","0","2"],["104600.2","0.17764565","0","1"],["104601","0.072","0","2"],["104602.2","0","0","0"],["104602.8","0.2570442","0","1"],["104603.1","0.13861581","0","1"],["104603.2","0.06125045","0","1"],["104603.3","0","0","0"],["104604","0","0","0"],["104605.2","0.033","0","1"],["104606","0","0","0"],["104606.2","0","0","0"],["104606.5","0","0","0"],["104606.6","0","0","0"],["104608.6","0.039","0","1"],["104610.1","0.04710858","0","2"],["104612.2","0.00286766","0","1"],["104612.7","0.132","0","4"],["104624","0.18251565","0","4"],["104625","0.09661","0","2"],["104628","0","0","0"],["104629","0.00479878","0","1"],["104646","0.26","0","4"],["104647","0.12999999","0","2"],["104650","0.07032024","0","4"],["104650.6","0.3967119","0","3"],["104651","0.035","0","1"],["104655","0.01600824","0","1"],["104656.4","0.67223652","0","2"],["104660.1","0","0","0"],["104662.1","0.01600824","0","1"],["104666.8","2.41354928","0","1"],["104666.9","6.49804302","0","2"],["104669.5","0","0","0"],["104673.8","0.02268285","0","1"],["104680.4","0.4079269","0","1"],["104682.9","0.08456427","0","1"],["104692.8","0.00095517","0","1"],["104694.7","0.0913655","0","1"],["104698.3","0","0","0"],["104703.4","0.01059593","0","1"],["104707","0","0","0"],["104714.4","0","0","0"],["104717.6","0","0","0"],["104736.8","0","0","0"],["104737","0","0","0"],["104737.3","0","0","0"],["104737.5","0","0","0"],["104739.1","0","0","0"],["104739.2","0","0","0"],["104739.3","0","0","0"],["104739.6","0","0","0"],["104739.7","0","0","0"],["104739.9","0","0","0"]],"bids":[["104584","0","0","0"],["104583","0","0","0"],["104582.3","0","0","0"],["104582","0","0","0"],["104581.8","0","0","0"],["104580.2","0.0980745","0","2"],["104579.8","0","0","0"],["104578","0.0816","0","1"],["104576.4","0","0","0"],["104576","0","0","0"],["104575.8","0","0","0"],["104573.6","0","0","0"],["104572.9","0.01237851","0","1"],["104572.7","0","0","0"],["104572.5","0","0","0"],["104571.4","0.00251113","0","1"],["104571.3","0","0","0"],["104571.2","0","0","0"],["104571.1","0","0","0"],["104571","0.11756822","0","2"],["104570.3","0","0","0"],["104569.8","0.00137191","0","1"],["104569.5","0.05595085","0","2"],["104569.3","0.10726033","0","2"],["104569.1","0.08915511","0","1"],["104569","0","0","0"],["104568.7","0","0","0"],["104568.1","0","0","0"],["104567.9","0.09342581","0","2"],["104567.8","0.0928834","0","1"],["104567.7","0","0","0"],["104566.9","0.16045912","0","1"],["104566.8","0.27194341","0","2"],["104566.1","0","0","0"],["104565.6","0.15175474","0","1"],["104565.2","0","0","0"],["104565","0","0","0"],["104564.3","0.17015305","0","1"],["104563.1","0","0","0"],["104562.9","0.00477964","0","1"],["104562.7","0","0","0"],["104561.6","0.15721144","0","1"],["104560.3","0","0","0"],["104558.7","0","0","0"],["104557.8","0","0","0"],["104557.5","0","0","0"],["104556.9","0.25665821","0","1"],["104556.7","0.17764565","0","1"],["104556.5","0.19242972","0","1"],["104556.4","1.0442026","0","2"],["104556","0.00001","0","1"],["104555.3","0.00382573","0","1"],["104553.5","0.13861581","0","1"],["104542.7","0","0","0"],["104541.5","0.00001","0","1"],["104530.5","0","0","0"],["104527.4","0.0022","0","1"],["104519.3","0","0","0"],["104518.5","0.14153108","0","1"],["104516.8","0.002868","0","1"],["104504","0","0","0"],["104503.9","0.00041816","0","1"],["104501","0.02890389","0","1"],["104499","0.00079951","0","2"],["104497.8","0.62008625","0","1"],["104496","0.000015","0","1"],["104495.8","0.01051752","0","1"],["104492.7","0.0022","0","1"],["104462","1.23382953","0","2"],["104460.7","0.77866876","0","1"],["104456","0.32507481","0","1"],["104446.7","0.01448065","0","1"],["104426.8","0.00017476","0","1"],["104405.9","0.0022","0","1"],["104394","0.1205","0","1"],["104383.3","0.00090892","0","2"],["104383.2","0.00001016","0","1"],["104382.9","0.00162841","0","7"],["104382.8","2.65237537","0","2"],["104382.5","0.03","0","1"],["104382.3","0.00052775","0","2"],["104382.2","0.00483056","0","1"],["104381.4","0.00003468","0","1"],["104381.2","0.00001042","0","1"]],"ts":"1747168596809","checksum":1263896947,"seqId":54225028051,"prevSeqId":54225027417}]}
{"arg":{"channel":"books","instId":"BTC-USDT"},"action":"update","data":[{"asks":[["104580.3","0.88345548","0","14"],["104581.8","0.67711397","0","1"],["104581.9","0.31218701","0","4"],["104584.1","0.05210701","0","3"],["104587.1","0.00045735","0","1"],["104587.2","0.77866876","0","1"],["104588.1","0.34447187","0","4"],["104588.7","0.09031097","0","1"],["104588.8","0.09693088","0","1"],["104588.9","0","0","0"],["104589.4","0.09810156","0","1"],["104589.6","0","0","0"],["104590.2","0.09611519","0","1"],["104590.3","0","0","0"],["104591.9","0","0","0"],["104592.1","0.00001501","0","1"],["104592.9","0.1457461","0","1"],["104593.1","0","0","0"],["104593.4","0.00092","0","1"],["104593.7","0.20745271","0","3"],["104593.8","0","0","0"],["104594.3","0.16467004","0","1"],["104594.4","0","0","0"],["104595.9","0","0","0"],["104596.4","0.1593676","0","1"],["104596.6","0","0","0"],["104596.7","0.24410799","0","1"],["104596.8","0.28609701","0","3"],["104597.2","0","0","0"],["104597.6","0.00477972","0","1"],["104598.6","0.00092","0","1"],["104598.7","0.25353699","0","1"],["104598.8","0","0","0"],["104599.8","1.24199801","0","3"],["104599.9","0","0","0"],["104602.4","0","0","0"],["104602.7","0.24290131","0","1"],["104602.8","0.1137","0","1"],["104603.1","0","0","0"],["104603.2","0.12396082","0","1"],["104603.8","0.00191","0","1"],["104604.2","0.13861547","0","1"],["104605.2","0.099","0","3"],["104607.6","0.04","0","1"],["104608.6","0","0","0"],["104609.1","0.00191","0","1"],["104611.4","0","0","0"],["104611.8","0.00286771","0","1"],["104612.2","0","0","0"],["104612.7","0.102","0","3"],["104612.8","0.00287","0","1"],["104612.9","0","0","0"],["104621.8","0.00013674","0","1"],["104622.3","0.17764565","0","1"],["104623.2","0","0","0"],["104624","0.18051565","0","2"],["104625","0.09561","0","1"],["104626","0.002","0","2"],["104627","0.001","0","1"],["104636.9","0.29242972","0","2"],["104638.9","0","0","0"],["104639.7","0","0","0"],["104645.8","0.02228315","0","1"],["104646","0","0","0"],["104647","0.1","0","2"],["104648","0.2122","0","4"],["104648.9","0","0","0"],["104649","0.07999999","0","1"],["104653.1","0.25000824","0","2"],["104660.9","2.80861153","0","3"],["104663.5","5.80356302","0","1"],["104666.8","0.67248038","0","1"],["104666.9","0.69448","0","1"],["104684.9","0.03506648","0","2"],["104692.5","0","0","0"],["104706.8","0","0","0"],["104729.4","0","0","0"],["104736.8","0.00001014","0","1"]],"bids":[["104579.9","0.00001","0","1"],["104576.2","0","0","0"],["104575.9","0","0","0"],["104573.7","0","0","0"],["104572.4","0.00051","0","1"],["104571.4","0","0","0"],["104571.1","0.00137191","0","1"],["104571","0.24811113","0","2"],["104570.9","0.0005","0","1"],["104569.8","0.00251117","0","1"],["104569.3","0.005","0","1"],["104569.2","0.09836642","0","1"],["104569.1","0","0","0"],["104568.9","0.08608022","0","1"],["104567.9","0.42304838","0","3"],["104567.8","0.0905927","0","1"],["104567.7","0.09059048","0","1"],["104567.1","0.00098","0","1"],["104566.9","0","0","0"],["104566.8","0.43971008","0","3"],["104565.7","0.06124373","0","1"],["104565.6","0","0","0"],["104564.5","0.00477972","0","1"],["104564.3","0","0","0"],["104564.2","0.16953179","0","1"],["104563.1","0.071684","0","1"],["104562.9","0","0","0"],["104561.9","0.17862565","0","2"],["104561.7","0.24830632","0","1"],["104561.6","0","0","0"],["104561.4","0.15622863","0","1"],["104560.5","0","0","0"],["104559.2","0.25701633","0","1"],["104556.9","0","0","0"],["104556.8","0.6407436","0","2"],["104556.7","0.17955565","0","2"],["104556.4","0.97031364","0","2"],["104556","0.13862547","0","2"],["104555.3","0","0","0"],["104555.2","0.2338265","0","1"],["104553.5","0","0","0"],["104552.9","0.17764565","0","1"],["104551.4","0.00191","0","1"],["104535.1","0","0","0"],["104535","0","0","0"],["104533","0","0","0"],["104532","0.19242972","0","1"],["104527.9","0.0004781","0","1"],["104519.3","0.1205","0","1"],["104499","0.00005062","0","1"],["104478","0","0","0"],["104474.8","0.00063722","0","1"],["104462.1","0","0","0"],["104460.4","0","0","0"],["104458.4","0.00083759","0","1"],["104394","0","0","0"],["104380.9","0.00013167","0","2"],["104380.7","0.00001015","0","1"]],"ts":"1747168596909","checksum":1178956055,"seqId":54225028349,"prevSeqId":54225028051}]}
{"arg":{"channel":"books","instId":"BTC-USDT"},"action":"update","data":[{"asks":[["104580.3","0.88354548","0","15"],["104581.9","0.31209701","0","3"],["104593.5","0.3728899","0","2"],["104595.7","0.00477972","0","1"],["104597.6","0","0","0"],["104605.2","0.129","0","4"],["104612.7","0.072","0","2"],["104621.8","0","0","0"],["104624","0.18251565","0","4"],["104625","0.09661","0","2"],["104626","0","0","0"],["104627","0","0","0"],["104632.6","0.0004781","0","1"],["104635.1","0.1","0","1"],["104636.9","0.19242972","0","1"],["104645","0.07","0","2"],["104646","0.295","0","5"],["104647","0.12999999","0","2"],["104648","0.0022","0","1"],["104649","0","0","0"],["104650","0.00032024","0","2"],["104651","0","0","0"],["104660.9","1.2432657","0","2"],["104663.5","0","0","0"],["104666.8","2.32948923","0","2"],["104670.2","5.80360601","0","2"],["104691.8","0","0","0"],["104737","0.03230388","0","3"],["104737.3","0.01059679","0","1"],["104737.5","0.01051303","0","1"]],"bids":[["104580.2","0.0981645","0","3"],["104579.9","0","0","0"],["104571","0.33470739","0","3"],["104565.4","0.16175888","0","1"],["104564.5","0","0","0"],["104563.2","0.00477972","0","1"],["104516.6","0","0","0"],["104515.2","0.00015488","0","1"],["104493.3","0.06824061","0","2"],["104491","0","0","0"],["104484.7","0.0105958","0","1"],["104481.1","0.00011975","0","1"],["104457.3","0.0579344","0","1"],["104432.8","0","0","0"],["104430.1","0.00095595","0","1"],["104380.7","0","0","0"]],"ts":"1747168597009","checksum":372518000,"seqId":54225028441,"prevSeqId":54225028349}]}
{"arg":{"channel":"books","instId":"BTC-USDT"},"action":"update","data":[{"asks":[["104580.3","0.88388466","0","16"],["104588.7","0","0","0"],["104588.8","0.09167817","0","1"],["104588.9","0.08949963","0","1"],["104589.4","0","0","0"],["104589.6","0.09516194","0","1"],["104590.2","0","0","0"],["104590.4","0.09041835","0","1"],["104591.6","0.00001","0","1"],["104592.9","0","0","0"],["104593.1","0.16361723","0","1"],["104593.5","0.33549846","0","2"],["104593.7","0.05209701","0","2"],["104593.8","0.15934085","0","1"],["104594.3","0","0","0"],["104594.4","0.17090177","0","1"],["104596.4","0","0","0"],["104596.6","0.16631725","0","1"],["104596.7","0","0","0"],["104596.9","0.26164417","0","1"],["104598.7","0","0","0"],["104598.8","0.25723776","0","1"],["104599.4","0.00700751","0","1"],["104599.8","0.97109848","0","2"],["104599.9","0.25216388","0","1"],["104600.5","0","0","0"],["104602.1","0.05209701","0","2"],["104602.7","0","0","0"],["104602.9","0.31888229","0","2"],["104604.2","0","0","0"],["104605.1","0.13861423","0","1"],["104611.5","0.0002393","0","2"],["104612.7","0.036","0","1"],["104615","0","0","0"],["104618.8","0.00013677","0","1"],["104645","0","0","0"],["104646","0.26","0","4"],["104647","0.19999999","0","4"],["104648","0.0372","0","2"],["104650","0.0008869","0","3"],["104652.6","0","0","0"],["104660.9","2.80861153","0","3"],["104663.5","5.80356302","0","1"],["104666.8","0.67248038","0","1"],["104670.2","0.00004299","0","1"],["104689.5","0.01357416","0","1"],["104692.9","1.18280886","0","3"],["104737.3","0","0","0"],["104737.5","0","0","0"]],"bids":[["104576","0.0206302","0","1"],["104575.9","0.01743535","0","1"],["104572.9","0","0","0"],["104571","0.35345326","0","3"],["104569.3","0.09922539","0","2"],["104569.2","0","0","0"],["104569.1","0.09654222","0","1"],["104568.9","0","0","0"],["104567.9","0.61526225","0","5"],["104567.8","0","0","0"],["104567.7","0","0","0"],["104566.9","0.15323833","0","1"],["104566.8","0.27194341","0","2"],["104565.6","0.14986186","0","1"],["104565.4","0","0","0"],["104564.3","0.14828811","0","1"],["104564.2","0","0","0"],["104561.9","0.44039834","0","3"],["104561.7","0","0","0"],["104561.6","0.15564629","0","1"],["104561.4","0","0","0"],["104559.3","0.25879634","0","1"],["104559.2","0","0","0"],["104558.5","0","0","0"],["104556.9","0.38819052","0","2"],["104556.8","0.38863185","0","1"],["104556","0.00001","0","1"],["104555.4","0.25674948","0","1"],["104555.2","0","0","0"],["104553.6","0.00056666","0","1"],["104535.1","0.00004444","0","1"],["104533","0.00004444","0","1"],["104532","0.19247416","0","2"],["104521","0","0","0"],["104515.2","0","0","0"],["104515.1","0.011163","0","2"],["104513.7","0.00015489","0","1"],["104458","0.0579344","0","1"],["104457.3","0","0","0"],["104453.1","0.00001","0","1"],["104380.9","0","0","0"]],"ts":"1747168597109","checksum":1289812938,"seqId":54225028589,"prevSeqId":54225028441}]}
{"arg":{"channel":"books","instId":"BTC-USDT"},"action":"update","data":[{"asks":[["104580.3","0.62961462","0","15"],["104581.8","0.67757132","0","2"],["104587.1","0","0","0"],["104605.1","0","0","0"],["104606","0.13861262","0","1"],["104624","0.18051565","0","2"],["104625","0.09561","0","1"],["104626","0.002","0","2"],["104627","0.001","0","1"],["104646","0","0","0"],["104647","0.17","0","4"],["104648","0.2472","0","5"],["104649","0.07999999","0","1"],["104737","0","0","0"]],"bids":[["104557.8","0.13861262","0","1"],["104556.9","0.24957629","0","1"],["104504.9","0.01051823","0","1"],["104503.6","0.01051823","0","1"],["104501.1","0.02103646","0","2"],["104500.1","0.01051823","0","1"],["104498.1","0.01051823","0","1"],["104496.4","0.01052823","0","2"],["104495.1","0.01051823","0","1"],["104493.4","0.01051823","0","1"],["104491.2","0.01051823","0","1"],["104489.6","0.01051823","0","1"],["104487.1","0.01051823","0","1"],["104452.2","0","0","0"],["104383.4","0","0","0"],["104383.3","0","0","0"],["104383.2","0","0","0"],["104382.9","0","0","0"],["104382.8","0","0","0"],["104382.5","0","0","0"],["104382.3","0","0","0"],["104382.2","0","0","0"],["104381.4","0","0","0"],["104381.2","0","0","0"]],"ts":"1747168597209","checksum":-260037681,"seqId":54225028630,"prevSeqId":54225028589}]}
{"arg":{"channel":"books","instId":"BTC-USDT"},"action":"update","data":[{"asks":[["104584.1","0.05209701","0","2"],["104687.5","0.00009167","0","1"],["104736.8","0","0","0"]],"bids":[["104535","0.46923818","0","1"],["104506.5","0.01053324","0","2"],["104505","0.01051823","0","1"],["104503.5","0.0721442","0","3"],["104501.2","0.02103646","0","2"],["104501","0","0","0"],["104500.2","0.01051823","0","1"],["104498","0.02111457","0","2"],["104496.6","0.01051823","0","1"],["104496.5","0.01051823","0","1"],["104494.5","0.01051823","0","1"],["104494.4","0.01051823","0","1"],["104441.4","0","0","0"],["104384.8","0","0","0"],["104384.7","0","0","0"],["104384.5","0","0","0"],["104384.4","0","0","0"],["104383.8","0","0","0"],["104383.7","0","0","0"]],"ts":"1747168597309","checksum":-1823291025,"seqId":54225028679,"prevSeqId":54225028630}]}
{"arg":{"channel":"books","instId":"BTC-USDT"},"action":"update","data":[{"asks":[["104580.3","0.63833262","0","16"],["104588.9","0","0","0"],["104589","0.28926059","0","3"],["104594.4","0","0","0"],["104594.5","0.15526475","0","1"],["104599.9","0","0","0"],["104600","0.25810363","0","3"],["104736.8","0.00001014","0","1"],["104737","0.03230388","0","3"]],"bids":[["104580.2","0.0987545","0","4"],["104571.2","0.008","0","1"],["104568","0.0943802","0","1"],["104567.9","0.5127971","0","4"],["104567","0.16413193","0","1"],["104566.9","0","0","0"],["104557","0.24335558","0","1"],["104556.9","0","0","0"],["104385.3","0","0","0"],["104384.9","0","0","0"]],"ts":"1747168597409","checksum":884892091,"seqId":54225028695,"prevSeqId":54225028679}]}
{"arg":{"channel":"books","instId":"BTC-USDT"},"action":"update","data":[{"asks":[["104580.3","0.52775262","0","15"],["104694.1","0.09075474","0","1"],["104694.7","0","0","0"]],"bids":[["104489.6","0.01225571","0","2"],["104478.8","0.01148558","0","1"],["104401.2","0","0","0"],["104392.7","0.00095792","0","1"],["104385.5","0","0","0"]],"ts":"1747168597509","checksum":-990446227,"seqId":54225028707,"prevSeqId":54225028695}]}
{"arg":{"channel":"books","instId":"BTC-USDT"},"action":"update","data":[{"asks":[["104606","0.13861206","0","1"]],"bids":[["104557.8","0.13861206","0","1"],["104448.7","0.12","0","1"],["104385.7","0","0","0"]],"ts":"1747168597609","checksum":-990446227,"seqId":54225028720,"prevSeqId":54225028707}]}
{"arg":{"channel":"books","instId":"BTC-USDT"},"action":"update","data":[{"asks":[["104606","0","0","0"],["104607.5","0.13862154","0","2"],["104622","0.002","0","2"],["104623","0.001","0","1"],["104626","0","0","0"],["104627","0","0","0"],["104633.3","0","0","0"],["104641","0.21887191","0","2"],["104644","0.26","0","4"],["104645","0.19999999","0","4"],["104646","0.035","0","1"],["104647","0","0","0"],["104648","0.0022","0","1"],["104649","0","0","0"],["104664.7","0","0","0"],["104737.3","0.01059679","0","1"],["104737.5","0.01051303","0","1"]],"bids":[["104540.8","0","0","0"],["104509.4","0.03","0","1"],["104385.7","0.00503516","0","4"]],"ts":"1747168597709","checksum":-990446227,"seqId":54225028767,"prevSeqId":54225028720}]}
{"arg":{"channel":"books","instId":"BTC-USDT"},"action":"update","data":[{"asks":[["104588.8","0","0","0"],["104588.9","0.09723221","0","1"],["104589.6","0","0","0"],["104589.7","0.08803698","0","1"],["104593.1","0","0","0"],["104593.2","0.15116194","0","1"],["104593.8","0","0","0"],["104593.9","0.15432769","0","1"],["104598.8","0","0","0"],["104598.9","0.24761828","0","1"],["104630.6","0.0560742","0","2"],["104632.7","1.43583742","0","1"],["104656.4","2.33839882","0","3"],["104656.7","5.80356302","0","1"],["104660.9","0.43777645","0","2"],["104663.5","0","0","0"],["104737.5","0","0","0"]],"bids":[["104576","0.09605142","0","2"],["104572.9","0.26","0","1"],["104569.4","0.10012086","0","1"],["104569.3","0.005","0","1"],["104569.2","0.09608353","0","1"],["104569.1","0","0","0"],["104565.7","0.21424921","0","2"],["104565.6","0","0","0"],["104564.4","0.20715371","0","3"],["104564.3","0","0","0"],["104559.3","0","0","0"],["104545.6","1.08240514","0","2"],["104540.2","1.41720633","0","1"],["104509.6","1.07865797","0","2"],["104508.9","2.55422789","0","1"],["104385.7","0","0","0"]],"ts":"1747168597809","checksum":-1617489855,"seqId":54225028806,"prevSeqId":54225028767}]}
{"arg":{"channel":"books","instId":"BTC-USDT"},"action":"update","data":[{"asks":[["104581.8","0.67711397","0","1"],["104582.3","0.26","0","1"],["104582.4","0.05209701","0","2"],["104587.1","0.00045735","0","1"],["104589","0.19764547","0","2"],["104589.1","0.15055782","0","3"],["104590.4","0","0","0"],["104590.5","0.09978596","0","1"],["104593.5","0.36905722","0","2"],["104594.5","0","0","0"],["104594.6","0.16258373","0","1"],["104596.6","0","0","0"],["104596.7","0.15826371","0","1"],["104596.9","0","0","0"],["104597","0.23555059","0","1"],["104600","0.00029006","0","2"],["104600.1","0.25412081","0","1"],["104602.9","0.0571631","0","1"],["104603","0.26096616","0","1"],["104630.6","0.48541348","0","3"],["104644","0.33","0","6"],["104645","0.16499999","0","3"],["104646","0","0","0"],["104656.4","2.356163","0","3"],["104656.7","0","0","0"],["104660.1","5.86277695","0","1"],["104660.9","1.14629575","0","3"],["104664.1","3.08169867","0","4"],["104737","0","0","0"],["104737.3","0","0","0"]],"bids":[["104580.2","0.11042577","0","5"],["104568.1","0.09244364","0","1"],["104568","0.08836937","0","1"],["104567.9","0.42304838","0","3"],["104567.1","0.1530548","0","2"],["104567","0","0","0"],["104562","0.23571058","0","1"],["104561.9","0.17862565","0","2"],["104561.7","0.14651294","0","1"],["104561.6","0","0","0"],["104559.4","0.24202171","0","1"],["104557.1","0.26375408","0","1"],["104557","0","0","0"],["104555.5","0.25409415","0","1"],["104555.4","0","0","0"],["104541","0.0468638","0","1"],["104540.3","0.49603493","0","1"],["104539.3","0","0","0"],["104534","0.48324487","0","1"],["104509.6","1.71140878","0","3"],["104494","0","0","0"],["104487","0.50439916","0","2"],["104386.2","0","0","0"],["104385.9","0","0","0"]],"ts":"1747168597909","checksum":-729824959,"seqId":54225028862,"prevSeqId":54225028806}]}
{"arg":{"channel":"books","instId":"BTC-USDT"},"action":"update","data":[{"asks":[["104580.3","0.47065262","0","15"],["104581.8","0.23005265","0","1"],["104581.9","0.05209701","0","2"],["104582.3","0","0","0"],["104587.1","0","0","0"],["104587.2","0","0","0"],["104587.3","0.00045735","0","1"],["104595.7","0","0","0"],["104596.7","0.16304343","0","2"],["104737","0.03230388","0","3"],["104737.3","0.01059679","0","1"],["104737.5","0.01051303","0","1"]],"bids":[["104564.5","0.00477972","0","1"],["104563.2","0","0","0"],["104559.5","0.13861036","0","1"],["104557.8","0","0","0"],["104535.1","0.59536348","0","2"],["104534.9","0","0","0"],["104401.6","0.00118057","0","1"]],"ts":"1747168598009","checksum":1524722398,"seqId":54225028884,"prevSeqId":54225028862}]}
{"arg":{"channel":"books","instId":"BTC-USDT"},"action":"update","data":[{"asks":[["104580.3","0.44924996","0","14"],["104584.9","0","0","0"],["104587.7","0.00001","0","1"],["104588","0.30385789","0","2"],["104588.9","0","0","0"],["104589","0.00521575","0","1"],["104589.1","0.05209701","0","2"],["104589.5","0.09988112","0","1"],["104589.7","0.09854786","0","1"],["104590.3","0.0965377","0","1"],["104590.5","0","0","0"],["104591.1","0.0882987","0","1"],["104593","0","0","0"],["104593.2","0","0","0"],["104593.5","0.41162033","0","2"],["104593.8","0.15802589","0","1"],["104593.9","0","0","0"],["104594.5","0.14990254","0","1"],["104594.6","0","0","0"],["104595.2","0.15230148","0","1"],["104595.6","0.00001","0","1"],["104596.2","0.02542069","0","1"],["104596.7","0","0","0"],["104597","0","0","0"],["104597.3","0.1511218","0","1"],["104597.6","0.24603076","0","2"],["104598.3","0.00700751","0","1"],["104598.9","0","0","0"],["104599.4","0","0","0"],["104599.5","0.25269348","0","1"],["104600.1","0","0","0"],["104600.7","0.26653874","0","1"],["104603","0","0","0"],["104603.2","0.20293883","0","2"],["104603.6","0.24934518","0","2"],["104607.5","0.00001","0","1"],["104608.3","0.13860977","0","1"],["104610.5","0.0002293","0","1"],["104611.5","0.00001","0","1"],["104617.8","0","0","0"],["104622","0","0","0"],["104623","0","0","0"],["104624","0.18251565","0","4"],["104625","0.09661","0","2"],["104630.3","0","0","0"],["104630.6","0.0560742","0","2"],["104632.7","0","0","0"],["104641","0.13677189","0","1"],["104644","0","0","0"],["104645","0.07","0","2"],["104646","0.295","0","5"],["104647","0.12999999","0","2"],["104649","0.00056666","0","1"],["104650","0.00032024","0","2"],["104660.9","0.43777645","0","2"],["104664.1","0.5419431","0","3"]],"bids":[["104580.2","0.29692577","0","6"],["104573","0.00137191","0","1"],["104571.1","0","0","0"],["104571","0.35634105","0","3"],["104570","0.0910239","0","3"],["104569.8","0.09833888","0","2"],["104569.4","0","0","0"],["104569.2","0","0","0"],["104568.7","0.09740038","0","1"],["104568.6","0.09309373","0","1"],["104568.1","0","0","0"],["104568","0","0","0"],["104567.7","0.16879013","0","1"],["104567.1","0.00098","0","1"],["104566.8","0.28957774","0","2"],["104566.3","0.15867042","0","1"],["104565.8","0.00477972","0","1"],["104565.7","0.06124373","0","1"],["104565","0.16160667","0","1"],["104564.5","0","0","0"],["104564.4","0.05398715","0","2"],["104562.6","0.25348314","0","1"],["104562.3","0.14778958","0","1"],["104562","0","0","0"],["104561.7","0","0","0"],["104560.2","0.1386101","0","1"],["104560","0.23991177","0","4"],["104559.5","0","0","0"],["104559.4","0","0","0"],["104557.7","0.27609317","0","2"],["104557.1","0","0","0"],["104556.1","0.26247264","0","2"],["104555.5","0","0","0"],["104553.6","0","0","0"],["104552.6","0.00056666","0","1"],["104515.1","0.01059634","0","1"],["104514","0.00056666","0","1"],["104474.8","0","0","0"],["104474.3","0.00063719","0","1"],["104458","0","0","0"],["104457.3","0.0579344","0","1"],["104430.1","0","0","0"],["104429","0.00095595","0","1"],["104401.6","0","0","0"],["104401.2","0.00118057","0","1"],["104386.2","0.00003798","0","1"]],"ts":"1747168598109","checksum":-588823762,"seqId":54225029021,"prevSeqId":54225028884}]}
{"arg":{"channel":"books","instId":"BTC-USDT"},"action":"update","data":[{"asks":[["104580.3","0.45614996","0","15"],["104584.5","0.03440653","0","1"],["104597.2","0.00477972","0","1"],["104597.6","0.24125104","0","1"],["104607.5","0.1386199","0","2"],["104608.3","0","0","0"],["104737.5","0","0","0"]],"bids":[["104580.2","0.3208212","0","7"],["104574.9","0.03584315","0","1"],["104565.8","0","0","0"],["104565.1","0.00477972","0","1"],["104560.2","0","0","0"],["104557.8","0.13861036","0","1"],["104386.2","0","0","0"]],"ts":"1747168598209","checksum":104266641,"seqId":54225029037,"prevSeqId":54225029021}]}
{"arg":{"channel":"books","instId":"BTC-USDT"},"action":"update","data":[{"asks":[["104580.3","0.46614996","0","16"],["104588","0.41753709","0","3"],["104589.3","0.19242972","0","1"],["104596.1","0.00477972","0","1"],["104597.2","0","0","0"],["104606.2","0.13861163","0","1"],["104607.5","0.00001","0","1"],["104630.6","0.47604171","0","3"],["104632.9","1.40459819","0","1"],["104660.9","1.16252813","0","3"],["104664.3","2.59386349","0","1"],["104736.5","0","0","0"],["104736.8","0","0","0"],["104737","0","0","0"],["104737.3","0","0","0"]],"bids":[["104576","0.0206302","0","1"],["104573","0","0","0"],["104572.9","0","0","0"],["104571.1","0.00137191","0","1"],["104565.1","0","0","0"],["104564.5","0.00477972","0","1"],["104538","0.00076212","0","2"],["104386.2","0.00003798","0","1"]],"ts":"1747168598309","checksum":-721029366,"seqId":54225029061,"prevSeqId":54225029037}]}
{"arg":{"channel":"books","instId":"BTC-USDT"},"action":"update","data":[{"asks":[["104580.3","0.46615996","0","17"],["104587.8","0.62179995","0","1"],["104587.9","0.77866876","0","1"],["104588","0.0816","0","1"],["104593.4","0.03499104","0","2"],["104595.7","0.00477972","0","1"],["104596.1","0","0","0"],["104602.9","0","0","0"],["104606","0.13861304","0","1"],["104606.2","0","0","0"],["104622","0.002","0","2"],["104623","0.001","0","1"],["104624","0.18051565","0","2"],["104625","0.09561","0","1"],["104641","0.21887191","0","2"],["104644","0.26","0","4"],["104645","0.19999999","0","4"],["104646","0.035","0","1"],["104647","0","0","0"],["104735.8","0","0","0"],["104735.9","0","0","0"],["104736.4","0","0","0"]],"bids":[["104575.9","0","0","0"],["104571","0.24811113","0","2"],["104567.9","0.00001","0","1"],["104564.5","0","0","0"],["104563.2","0.00477972","0","1"],["104557.8","0.13861304","0","1"],["104385.9","0.00022924","0","1"]],"ts":"1747168598409","checksum":-1999314581,"seqId":54225029129,"prevSeqId":54225029061}]}
{"arg":{"channel":"books","instId":"BTC-USDT"},"action":"update","data":[{"asks":[["104595.1","0.00477972","0","1"],["104595.7","0","0","0"],["104606","0.13861306","0","1"],["104644","0.33","0","6"],["104645","0.16499999","0","3"],["104646","0","0","0"],["104735.8","0.00023574","0","1"]],"bids":[["104575.8","0.01765872","0","1"],["104571","0.38042562","0","4"],["104567.8","0.38863185","0","1"],["104563.2","0","0","0"],["104562.7","0.00477972","0","1"],["104557.8","0.13861311","0","1"],["104556.4","1.07528601","0","3"],["104386.2","0","0","0"],["104385.9","0","0","0"]],"ts":"1747168598509","checksum":42282851,"seqId":54225029162,"prevSeqId":54225029129}]}
{"arg":{"channel":"books","instId":"BTC-USDT"},"action":"update","data":[{"asks":[["104595.1","0","0","0"],["104597.2","0.00477972","0","1"],["104606","0.13861218","0","1"]],"bids":[["104565.1","0.00477972","0","1"],["104562.7","0","0","0"],["104557.8","0.13861218","0","1"],["104526.5","0","0","0"],["104513.6","0.05840184","0","2"],["104386.2","0.00003798","0","1"]],"ts":"1747168598709","checksum":42282851,"seqId":54225029187,"prevSeqId":54225029162}]}
{"arg":{"channel":"books","instId":"BTC-USDT"},"action":"update","data":[{"asks":[["104580.3","0.72615996","0","18"],["104581.7","0.26","0","1"],["104735.8","0","0","0"]],"bids":[["104496.1","0.01164774","0","2"]],"ts":"1747168598809","checksum":-1997493165,"seqId":54225029190,"prevSeqId":54225029187}]}
{"arg":{"channel":"books","instId":"BTC-USDT"},"action":"update","data":[{"asks":[["104592.5","0.076683","0","2"],["104597.2","0","0","0"],["104598.2","0.00477972","0","1"],["104605","0.01","0","2"],["104606","0","0","0"],["104608.3","0.13860959","0","1"]],"bids":[["104578","0.0866","0","2"],["104566.1","0.00477972","0","1"],["104565.5","0.005","0","1"],["104565.1","0","0","0"],["104560.2","0.13860959","0","1"],["104557.8","0","0","0"],["104386.2","0","0","0"]],"ts":"1747168598909","checksum":559435845,"seqId":54225029204,"prevSeqId":54225029190}]}
{"arg":{"channel":"books","instId":"BTC-USDT"},"action":"update","data":[{"asks":[["104607.5","0.13862072","0","2"],["104608.3","0","0","0"],["104735.8","0.00023574","0","1"]],"bids":[["104560.2","0","0","0"],["104557.8","0.13861072","0","1"]],"ts":"1747168599009","checksum":559435845,"seqId":54225029208,"prevSeqId":54225029204}]}
{"arg":{"channel":"books","instId":"BTC-USDT"},"action":"update","data":[{"asks":[["104587.8","0.38969932","0","1"],["104587.9","0","0","0"],["104595.9","0.00477972","0","1"],["104597.2","0.00700751","0","1"],["104598.2","0","0","0"],["104598.3","0","0","0"],["104609.4","0.0002293","0","1"],["104610.5","0","0","0"],["104622","0","0","0"],["104623","0","0","0"],["104624","0.18251565","0","4"],["104625","0.09661","0","2"],["104641","0.13677189","0","1"],["104644","0","0","0"],["104645","0.07","0","2"],["104646","0.295","0","5"],["104647","0.12999999","0","2"],["104648","0.00276666","0","2"],["104649","0","0","0"],["104687.5","0","0","0"],["104735.9","0.00002557","0","1"],["104736.4","0.01064462","0","2"],["104736.5","0.77866876","0","1"],["104736.8","0.00001014","0","1"]],"bids":[["104566.1","0","0","0"],["104563.2","0.00477972","0","1"],["104552.6","0","0","0"],["104551.5","0.0595015","0","2"],["104514","0","0","0"],["104513","0.00056666","0","1"],["104386.2","0.00003798","0","1"]],"ts":"1747168599109","checksum":1914735135,"seqId":54225029254,"prevSeqId":54225029208}]}
{"arg":{"channel":"books","instId":"BTC-USDT"},"action":"update","data":[{"asks":[["104587.3","0","0","0"],["104589","0.0056731","0","2"],["104737","0.03230388","0","3"]],"bids":[["104557.8","0.13861036","0","1"]],"ts":"1747168599209","checksum":593359871,"seqId":54225029260,"prevSeqId":54225029254}]}
{"arg":{"channel":"books","instId":"BTC-USDT"},"action":"update","data":[{"asks":[["104580.3","0.46615996","0","17"],["104587.6","0.62344016","0","1"],["104587.7","0.77867876","0","2"],["104587.8","0","0","0"]],"bids":[],"ts":"1747168599309","checksum":1563889488,"seqId":54225029266,"prevSeqId":54225029260}]}
{"arg":{"channel":"books","instId":"BTC-USDT"},"action":"update","data":[{"asks":[],"bids":[["104575.8","0","0","0"],["104385.9","0.00022924","0","1"]],"ts":"1747168599509","checksum":788245209,"seqId":54225029270,"prevSeqId":54225029266}]}
{"arg":{"channel":"books","instId":"BTC-USDT"},"action":"update","data":[{"asks":[["104633.5","0","0","0"],["104737.3","0.01059679","0","1"]],"bids":[],"ts":"1747168599609","checksum":788245209,"seqId":54225029275,"prevSeqId":54225029270}]}
{"arg":{"channel":"books","instId":"BTC-USDT"},"action":"update","data":[{"asks":[["104581.7","0","0","0"],["104595.9","0","0","0"],["104596.7","0.00477972","0","1"],["104622","0.002","0","2"],["104623","0.001","0","1"],["104624","0.18051565","0","2"],["104625","0.09561","0","1"],["104641","0.23987191","0","2"],["104644","0.33","0","6"],["104645","0.16499999","0","3"],["104646","0","0","0"],["104647","0","0","0"]],"bids":[["104564.5","0.00477972","0","1"],["104563.2","0","0","0"],["104557.9","0.13861132","0","1"],["104557.8","0","0","0"]],"ts":"1747168599709","checksum":-1083833925,"seqId":54225029307,"prevSeqId":54225029275}]}
{"arg":{"channel":"books","instId":"BTC-USDT"},"action":"update","data":[{"asks":[["104580.3","0.72615996","0","18"],["104581.7","0.26","0","1"],["104630.9","0.00312928","0","1"],["104635.6","0","0","0"],["104737.3","0","0","0"]],"bids":[],"ts":"1747168599809","checksum":-882475670,"seqId":54225029311,"prevSeqId":54225029307}]}
{"arg":{"channel":"books","instId":"BTC-USDT"},"action":"update","data":[{"asks":[["104595.9","0.00477972","0","1"],["104596.7","0","0","0"],["104633","0.00322928","0","1"],["104636.7","0","0","0"],["104641.9","0","0","0"],["104666.6","0.02120875","0","3"],["104737.3","0.01059679","0","1"]],"bids":[["104580.2","0.32847901","0","7"],["104571","0.28251766","0","3"],["104567.8","0","0","0"],["104564.5","0","0","0"],["104563.2","0.00477972","0","1"],["104558","0.19242972","0","1"],["104556.5","0","0","0"],["104385.7","0.00503516","0","4"]],"ts":"1747168599909","checksum":-1699518930,"seqId":54225029328,"prevSeqId":54225029311}]}
{"arg":{"channel":"books","instId":"BTC-USDT"},"action":"update","data":[{"asks":[["104587.3","0.00043482","0","1"],["104589","0.00521575","0","1"],["104593.9","0.00477972","0","1"],["104595.9","0","0","0"],["104606","0.1386122","0","1"],["104607.5","0.00001","0","1"],["104634","0.00956203","0","1"],["104639.2","0.61479203","0","2"],["104736.8","0","0","0"],["104737","0","0","0"],["104737.3","0","0","0"]],"bids":[["104580.2","0.32686058","0","7"],["104563.2","0","0","0"],["104562.4","0.00477972","0","1"],["104558.1","0.1386122","0","1"],["104557.9","0","0","0"]],"ts":"1747168600009","checksum":-2116998205,"seqId":54225029346,"prevSeqId":54225029328}]}
{"arg":{"channel":"books","instId":"BTC-USDT"},"action":"update","data":[{"asks":[["104580.3","0.64948996","0","17"],["104589.1","0.14833469","0","3"],["104589.2","0.09023979","0","1"],["104589.5","0","0","0"],["104589.7","0","0","0"],["104589.9","0.09719848","0","1"],["104590.3","0","0","0"],["104590.7","0.09557116","0","1"],["104591.1","0","0","0"],["104593.4","0.19679413","0","3"],["104593.5","0.37263296","0","2"],["104593.8","0","0","0"],["104593.9","0","0","0"],["104594.1","0.15915605","0","1"],["104594.5","0","0","0"],["104594.6","0.00477972","0","1"],["104594.7","0.16772343","0","1"],["104595.2","0","0","0"],["104596.1","0.00700751","0","1"],["104596.2","0","0","0"],["104596.9","0.15014849","0","1"],["104597.2","0.2385994","0","1"],["104597.3","0","0","0"],["104597.6","0","0","0"],["104598.4","0.05681315","0","1"],["104599.1","0.2708367","0","1"],["104599.5","0","0","0"],["104600.2","0.44200558","0","2"],["104600.7","0","0","0"],["104602","0.39918562","0","3"],["104603.2","0.38606105","0","2"],["104603.6","0.00001","0","1"],["104609","0.0002293","0","1"],["104609.4","0","0","0"],["104622","0","0","0"],["104623","0","0","0"],["104624","0.18251565","0","4"],["104625","0.09661","0","2"],["104644","0","0","0"],["104645","0.07","0","2"],["104646","0.295","0","5"],["104647","0.12999999","0","2"],["104648","0.0022","0","1"],["104648.3","0.00056666","0","1"],["104736.8","0.00001014","0","1"],["104737","0.03230388","0","3"],["104737.3","0.01059679","0","1"]],"bids":[["104580.2","0.14036058","0","6"],["104571","0.27869566","0","4"],["104570","0.00029006","0","2"],["104569.8","0.00251117","0","1"],["104569.6","0.09236994","0","2"],["104569.4","0.09320439","0","1"],["104568.7","0","0","0"],["104568.6","0","0","0"],["104568.2","0.19054348","0","2"],["104567.7","0","0","0"],["104567.2","0.15421034","0","1"],["104566.8","0.36359993","0","2"],["104566.3","0","0","0"],["104565.9","0.14802914","0","1"],["104565","0","0","0"],["104564.6","0.16249153","0","1"],["104562.6","0","0","0"],["104562.4","0","0","0"],["104562.3","0.00477972","0","1"],["104562.2","0.24799313","0","1"],["104561.9","0.32991916","0","3"],["104560","0.00220843","0","3"],["104559.6","0.25711713","0","1"],["104558.1","0","0","0"],["104558","0","0","0"],["104557.8","0.13861264","0","1"],["104557.7","0.02199655","0","1"],["104557.2","0.26718856","0","1"],["104556.9","0.19242972","0","1"],["104556.4","0.97031364","0","2"],["104556.1","0.00710858","0","1"],["104555.7","0.2398385","0","1"],["104551.5","0.05893484","0","1"],["104550","0.00099216","0","4"],["104513","0","0","0"],["104510.8","0.00056666","0","1"],["104385.9","0","0","0"],["104385.7","0","0","0"]],"ts":"1747168600109","checksum":-347615370,"seqId":54225029478,"prevSeqId":54225029346}]}
{"arg":{"channel":"books","instId":"BTC-USDT"},"action":"update","data":[{"asks":[["104593.9","0.00477972","0","1"],["104594.6","0","0","0"],["104641","0.13677189","0","1"]],"bids":[],"ts":"1747168600209","checksum":-347615370,"seqId":54225029481,"prevSeqId":54225029478}]}
{"arg":{"channel":"books","instId":"BTC-USDT"},"action":"update","data":[{"asks":[["104606","0.13861306","0","1"]],"bids":[["104571","0.37621028","0","3"],["104567.3","0.38863185","0","1"],["104513.7","0","0","0"]],"ts":"1747168600309","checksum":649716876,"seqId":54225029497,"prevSeqId":54225029481}]}
{"arg":{"channel":"books","instId":"BTC-USDT"},"action":"update","data":[{"asks":[["104634","0","0","0"],["104639.2","0.60523","0","1"],["104737.5","0.01051303","0","1"]],"bids":[],"ts":"1747168600409","checksum":649716876,"seqId":54225029501,"prevSeqId":54225029497}]}
{"arg":{"channel":"books","instId":"BTC-USDT"},"action":"update","data":[{"asks":[["104580.3","0.76006996","0","18"],["104588.7","0.08971434","0","1"],["104588.8","0.09379518","0","1"],["104589.1","0.05209701","0","2"],["104589.2","0","0","0"],["104589.5","0.09712926","0","1"],["104589.9","0","0","0"],["104590.2","0.09914392","0","1"],["104590.7","0","0","0"],["104592.9","0.00477972","0","1"],["104593","0.14527001","0","1"],["104593.4","0.03499104","0","2"],["104593.5","0.32632106","0","2"],["104593.7","0.20440263","0","3"],["104593.9","0","0","0"],["104594.1","0","0","0"],["104594.3","0.14999765","0","1"],["104594.7","0","0","0"],["104596.5","0.15766193","0","1"],["104596.7","0.25837451","0","1"],["104596.9","0","0","0"],["104597.2","0","0","0"],["104598.7","0.27089807","0","1"],["104599.1","0","0","0"],["104599.8","1.24336805","0","3"],["104600.2","0.17764565","0","1"],["104602.7","0.25466904","0","1"],["104603.2","0.12396082","0","1"],["104604.2","0.13861484","0","1"],["104606","0","0","0"],["104622","0.002","0","2"],["104623","0.001","0","1"],["104624","0.18051565","0","2"],["104625","0.09561","0","1"],["104644","0.33","0","6"],["104645","0.16499999","0","3"],["104646","0","0","0"],["104647","0","0","0"],["104737","0","0","0"],["104737.3","0","0","0"],["104737.5","0","0","0"]],"bids":[["104580.2","0.06926058","0","5"],["104576","0.0816","0","1"],["104571.1","0","0","0"],["104571","0.23012375","0","4"],["104569.6","0.00149791","0","2"],["104569.4","0","0","0"],["104569.2","0.09147761","0","1"],["104569","0.09003649","0","1"],["104568.2","0","0","0"],["104567.8","0.09688176","0","1"],["104567.7","0.08989994","0","1"],["104567.3","0","0","0"],["104567.2","0","0","0"],["104566.8","0.43669175","0","3"],["104565.9","0","0","0"],["104565.5","0.15740905","0","2"],["104564.6","0","0","0"],["104564.2","0.15678031","0","1"],["104562.3","0","0","0"],["104562.2","0","0","0"],["104561.9","0.17862565","0","2"],["104561.7","0.25788541","0","1"],["104561.5","0.15650163","0","1"],["104561.2","0.00477972","0","1"],["104559.6","0","0","0"],["104559.2","0.23811948","0","1"],["104557.8","0","0","0"],["104557.2","0","0","0"],["104556.8","0.66033558","0","2"],["104556","0.13862549","0","2"],["104555.7","0","0","0"],["104555.2","0.24452429","0","1"],["104519.3","0","0","0"],["104513.7","0.00015489","0","1"],["104394","0.1205","0","1"],["104385.9","0.00022924","0","1"],["104385.7","0.00503516","0","4"]],"ts":"1747168600509","checksum":951490944,"seqId":54225029618,"prevSeqId":54225029501}]}
{"arg":{"channel":"books","instId":"BTC-USDT"},"action":"update","data":[{"asks":[["104592.9","0","0","0"],["104595.2","0.00477972","0","1"],["104604.2","0","0","0"],["104605.1","0.1386136","0","1"],["104609.7","0.27207564","0","1"],["104612","0","0","0"],["104630.6","0.0560742","0","2"],["104632.9","0","0","0"],["104660.9","0.43777645","0","2"],["104664.3","0","0","0"],["104687.9","0.01068687","0","2"],["104737","0.03230388","0","3"],["104737.3","0.01059679","0","1"],["104737.5","0.01051303","0","1"]],"bids":[["104576.1","0.05063254","0","1"],["104571.1","0.00137191","0","1"],["104569.6","0.000126","0","1"],["104562","0.00477972","0","1"],["104561.2","0","0","0"],["104557","0.1386136","0","1"],["104556.4","1.0718642","0","3"],["104556","0.00001","0","1"],["104540.3","0.07109717","0","1"],["104540.2","0","0","0"],["104519.3","0.1205","0","1"],["104509.6","1.07865797","0","2"],["104508.9","0","0","0"],["104394","0","0","0"],["104385.7","0","0","0"]],"ts":"1747168600609","checksum":343835041,"seqId":54225029656,"prevSeqId":54225029618}]}
{"arg":{"channel":"books","instId":"BTC-USDT"},"action":"update","data":[{"asks":[["104580.3","0.64947995","0","17"],["104594.2","0.00477972","0","1"],["104595.2","0","0","0"],["104605.1","0","0","0"],["104606","0.13861291","0","1"],["104632.7","1.38401504","0","1"],["104634","0.00956203","0","1"],["104639.2","0.61479203","0","2"],["104664.1","3.10341994","0","4"],["104737.3","0","0","0"],["104737.5","0","0","0"]],"bids":[["104571","0.33370987","0","3"],["104568.5","0","0","0"],["104567.9","0.38864185","0","2"],["104557.8","0.13861307","0","1"],["104557","0","0","0"],["104555.7","0.106317","0","1"],["104550","0.0008869","0","3"],["104539.9","1.40354886","0","1"],["104509.6","1.68708848","0","3"],["104508.5","2.47316025","0","1"],["104500","0.00374535","0","11"],["104386.2","0","0","0"],["104385.9","0","0","0"]],"ts":"1747168600709","checksum":616107140,"seqId":54225029697,"prevSeqId":54225029656}]}
{"arg":{"channel":"books","instId":"BTC-USDT"},"action":"update","data":[{"asks":[["104580.3","0.64945993","0","17"],["104596.7","0.23752966","0","1"],["104605.1","0.13861406","0","1"],["104606","0","0","0"]],"bids":[["104580.2","0.06962058","0","6"],["104561.7","0.25400242","0","1"],["104557.8","0","0","0"],["104557","0.13861406","0","1"]],"ts":"1747168600809","checksum":-1634739030,"seqId":54225029724,"prevSeqId":54225029697}]}
{"arg":{"channel":"books","instId":"BTC-USDT"},"action":"update","data":[{"asks":[["104596.7","0","0","0"],["104596.8","0.51685951","0","4"],["104605.1","0","0","0"],["104607.5","0.13862157","0","2"],["104737.3","0.01059679","0","1"],["104737.5","0.01051303","0","1"]],"bids":[["104575.4","0.0179243","0","1"],["104561.8","0.38022979","0","5"],["104561.7","0","0","0"],["104557.8","0.13861174","0","1"],["104557","0","0","0"]],"ts":"1747168600909","checksum":-1819535183,"seqId":54225029735,"prevSeqId":54225029724}]}
{"arg":{"channel":"books","instId":"BTC-USDT"},"action":"update","data":[{"asks":[["104584.5","0","0","0"],["104594.2","0","0","0"],["104595","0.00700751","0","1"],["104595.2","0.00477972","0","1"],["104596.1","0","0","0"],["104738.9","0.160579","0","1"]],"bids":[],"ts":"1747168601009","checksum":-2035420631,"seqId":54225029741,"prevSeqId":54225029735}]}
{"arg":{"channel":"books","instId":"BTC-USDT"},"action":"update","data":[{"asks":[["104584","0.04440653","0","2"],["104607.7","0.0002293","0","1"],["104609","0","0","0"],["104646.9","0.00056666","0","1"],["104648.3","0","0","0"]],"bids":[["104550","0.00032024","0","2"],["104548.7","0.00056666","0","1"],["104510.8","0","0","0"],["104509.5","0.77923542","0","2"]],"ts":"1747168601109","checksum":-558403564,"seqId":54225029750,"prevSeqId":54225029741}]}
{"arg":{"channel":"books","instId":"BTC-USDT"},"action":"update","data":[{"asks":[["104643","0.17","0","4"],["104644","0.245","0","4"],["104645","0.07999999","0","1"],["104699.1","0.12","0","1"],["104737.5","0","0","0"],["104738.9","0","0","0"]],"bids":[["104580.2","0.06981058","0","7"]],"ts":"1747168601309","checksum":-1310085304,"seqId":54225029760,"prevSeqId":54225029750}]}
{"arg":{"channel":"books","instId":"BTC-USDT"},"action":"update","data":[{"asks":[["104621","0.002","0","2"],["104622","0.001","0","1"],["104623","0","0","0"],["104630.6","0.46890593","0","3"],["104643","0.33","0","6"],["104644","0.16499999","0","3"],["104645","0","0","0"],["104660.9","1.15281213","0","3"],["104718","0","0","0"],["104737.5","0.01051303","0","1"],["104738.9","0.160579","0","1"]],"bids":[["104541","0","0","0"],["104386.2","0.00003798","0","1"]],"ts":"1747168601409","checksum":-1310085304,"seqId":54225029773,"prevSeqId":54225029760}]}
{"arg":{"channel":"books","instId":"BTC-USDT"},"action":"update","data":[{"asks":[["104620","0.00420843","0","5"],["104621","0.001","0","1"],["104622","0","0","0"],["104642","0.33","0","6"],["104643","0.16499999","0","3"],["104644","0","0","0"],["104739.1","0.00001501","0","1"]],"bids":[["104538.9","0.04845753","0","1"],["104386.2","0","0","0"]],"ts":"1747168601509","checksum":-1310085304,"seqId":54225029795,"prevSeqId":54225029773}]}
{"arg":{"channel":"books","instId":"BTC-USDT"},"action":"update","data":[{"asks":[["104595.2","0","0","0"],["104596.7","0.00477972","0","1"],["104607.5","0.1386216","0","2"],["104612","1","0","1"],["104739.1","0","0","0"]],"bids":[["104564.5","0.00477972","0","1"],["104562","0","0","0"]],"ts":"1747168601609","checksum":-1310085304,"seqId":54225029806,"prevSeqId":54225029795}]}
{"arg":{"channel":"books","instId":"BTC-USDT"},"action":"update","data":[{"asks":[["104620","0.00220843","0","3"],["104621","0.002","0","2"],["104622","0.001","0","1"],["104642","0.26","0","4"],["104643","0.19999999","0","4"],["104644","0.035","0","1"],["104737.5","0","0","0"],["104738.9","0","0","0"]],"bids":[],"ts":"1747168601709","checksum":-1310085304,"seqId":54225029833,"prevSeqId":54225029806}]}
{"arg":{"channel":"books","instId":"BTC-USDT"},"action":"update","data":[{"asks":[["104580.3","0.67905993","0","18"],["104588.7","0","0","0"],["104588.8","0","0","0"],["104589","0.09788","0","2"],["104589.1","0.14171978","0","3"],["104589.5","0","0","0"],["104589.8","0.09521708","0","1"],["104590.2","0","0","0"],["104590.5","0.08978099","0","1"],["104593","0","0","0"],["104593.3","0.16035505","0","1"],["104593.5","0.38177509","0","2"],["104593.7","0.05209701","0","2"],["104594","0.24608843","0","2"],["104594.3","0","0","0"],["104594.6","0.16897817","0","1"],["104595.9","0.00477972","0","1"],["104596.5","0","0","0"],["104596.7","0","0","0"],["104596.8","0.44472526","0","4"],["104597","0.25400626","0","1"],["104598.7","0","0","0"],["104599","0.25959216","0","1"],["104599.8","0.97109848","0","2"],["104600.1","0.26064234","0","1"],["104602.7","0","0","0"],["104603","0.25929134","0","1"],["104607.5","0.13862157","0","2"],["104642","0","0","0"],["104643","0.32999999","0","6"],["104644","0.16499999","0","3"],["104737.5","0.01051303","0","1"],["104738.9","0.160579","0","1"]],"bids":[["104580.2","0.11702515","0","8"],["104574.9","0","0","0"],["104571","0.35225561","0","4"],["104569.5","0.15413539","0","3"],["104569.3","0.09167487","0","2"],["104569.2","0","0","0"],["104569","0","0","0"],["104568.1","0.09694102","0","1"],["104568","0.09353001","0","1"],["104567.8","0","0","0"],["104567.7","0","0","0"],["104567.1","0.15402082","0","2"],["104566.8","0.37060568","0","2"],["104565.8","0.16355853","0","1"],["104565.5","0.005","0","1"],["104564.5","0.16456285","0","1"],["104564.2","0","0","0"],["104563.2","0.00477972","0","1"],["104562","0.24538876","0","1"],["104561.8","0.28264966","0","5"],["104561.5","0","0","0"],["104559.5","0.24609944","0","1"],["104559.2","0","0","0"],["104557.8","0.13861192","0","1"],["104557.1","0.25040076","0","1"],["104556.8","0.38863185","0","1"],["104555.5","0.25596187","0","1"],["104555.2","0","0","0"],["104386.2","0.00003798","0","1"]],"ts":"1747168601809","checksum":-1392186250,"seqId":54225029933,"prevSeqId":54225029833}]}
{"arg":{"channel":"books","instId":"BTC-USDT"},"action":"update","data":[{"asks":[["104580.3","0.44505993","0","17"]],"bids":[],"ts":"1747168601909","checksum":-1229570330,"seqId":54225029938,"prevSeqId":54225029933}]}
{"arg":{"channel":"books","instId":"BTC-USDT"},"action":"update","data":[{"asks":[["104580.3","0.4464412","0","18"],["104595.9","0","0","0"],["104596.9","0.00477972","0","1"]],"bids":[["104564.6","0.00477972","0","1"],["104563.2","0","0","0"]],"ts":"1747168602009","checksum":-658347563,"seqId":54225029943,"prevSeqId":54225029938}]}
{"arg":{"channel":"books","instId":"BTC-USDT"},"action":"update","data":[{"asks":[["104593.9","0.00700751","0","1"],["104595","0","0","0"],["104606.4","0.0002293","0","1"],["104607.5","0.13862159","0","2"],["104607.7","0","0","0"],["104645.7","0.00056666","0","1"],["104646.9","0","0","0"],["104687.8","0.00009121","0","1"],["104687.9","0.01059538","0","1"],["104738.9","0","0","0"]],"bids":[["104563.5","0.07298372","0","1"],["104548.7","0","0","0"],["104547.4","0.00056666","0","1"],["104509.5","0.77866876","0","1"],["104508.2","0.00056666","0","1"],["104386.3","0","0","0"],["104386.2","0","0","0"]],"ts":"1747168602109","checksum":-658347563,"seqId":54225029967,"prevSeqId":54225029943}]}
{"arg":{"channel":"books","instId":"BTC-USDT"},"action":"update","data":[{"asks":[["104580.3","0.6804412","0","19"],["104594.5","0.00477972","0","1"],["104596.9","0","0","0"],["104606","0.13861198","0","1"],["104607.5","0.00001","0","1"],["104737.5","0","0","0"]],"bids":[["104564.6","0","0","0"],["104562.1","0.00477972","0","1"],["104557.8","0.13861198","0","1"]],"ts":"1747168602209","checksum":-1787233984,"seqId":54225029988,"prevSeqId":54225029967}]}
{"arg":{"channel":"books","instId":"BTC-USDT"},"action":"update","data":[{"asks":[["104606","0","0","0"],["104607.5","0.13862159","0","2"],["104737.5","0.01051303","0","1"]],"bids":[["104576.1","0","0","0"],["104571","0.31784908","0","3"],["104559.6","0.13861036","0","1"],["104557.8","0","0","0"],["104539.9","0","0","0"],["104508.5","0","0","0"],["104386.3","0.00041848","0","2"],["104386.2","0.00003798","0","1"],["104385.9","0.00022924","0","1"]],"ts":"1747168602309","checksum":-172750156,"seqId":54225029996,"prevSeqId":54225029988}]}
{"arg":{"channel":"books","instId":"BTC-USDT"},"action":"update","data":[{"asks":[["104591.6","0.02520094","0","2"],["104593.2","0.00477972","0","1"],["104594.5","0","0","0"],["104595.3","0","0","0"],["104605.1","0.13861372","0","1"],["104607.5","0.00001","0","1"],["104609.7","0.53855771","0","2"],["104620","0.00420843","0","5"],["104621","0.001","0","1"],["104622","0","0","0"],["104641","0.28650349","0","2"],["104642","0.33","0","6"],["104643","0.16499999","0","3"],["104644","0","0","0"],["104687.8","0","0","0"],["104691.8","0.00010206","0","1"],["104738.9","0.160579","0","1"]],"bids":[["104571.1","0","0","0"],["104571","0.17638595","0","2"],["104569.6","0.00149791","0","2"],["104567.9","0.00001","0","1"],["104562.1","0","0","0"],["104560.2","0.00477972","0","1"],["104559.6","0","0","0"],["104557.2","0.13861372","0","1"],["104519.3","0","0","0"],["104509.6","1.07865797","0","2"],["104481.1","0","0","0"],["104478","0.00009927","0","1"],["104429","0","0","0"],["104425.4","0.00095595","0","1"],["104394","0.1205","0","1"],["104385.7","0.00503516","0","4"]],"ts":"1747168602409","checksum":1337441173,"seqId":54225030058,"prevSeqId":54225029996}]}
{"arg":{"channel":"books","instId":"BTC-USDT"},"action":"update","data":[{"asks":[["104580.3","0.7910212","0","20"],["104589","0.10130583","0","2"],["104589.1","0.14975318","0","3"],["104589.8","0.08680434","0","1"],["104590.5","0.09804431","0","1"],["104593.2","0","0","0"],["104593.3","0.14394533","0","1"],["104593.5","0.36221327","0","2"],["104594","0.23606545","0","2"],["104594.6","0.16009396","0","1"],["104595.7","0.00477972","0","1"],["104596.8","0.43941557","0","4"],["104597","0.2394065","0","1"],["104599","0.25134854","0","1"],["104600.1","0.24844969","0","1"],["104603","0.26747564","0","1"],["104605.1","0","0","0"],["104606","0.13861281","0","1"],["104620","0.00220843","0","3"],["104621","0.002","0","2"],["104622","0.001","0","1"],["104642","0","0","0"],["104643","0.32999999","0","6"],["104644","0.16499999","0","3"],["104738.9","0","0","0"]],"bids":[["104571.2","0.00937191","0","2"],["104571.1","0.2887302","0","1"],["104571","0.04","0","1"],["104569.6","0.000126","0","1"],["104569.5","0.15676419","0","3"],["104569.3","0.10000711","0","2"],["104568.1","0.48884386","0","2"],["104568","0.09332804","0","1"],["104567.1","0.16042037","0","2"],["104566.8","0.31320014","0","2"],["104565.8","0.15532765","0","1"],["104564.5","0.1510432","0","1"],["104562","0.2476098","0","2"],["104561.8","0.28554389","0","5"],["104560.2","0","0","0"],["104559.5","0.25968341","0","1"],["104557.8","0.13861281","0","1"],["104557.2","0","0","0"],["104557.1","0.27148639","0","1"],["104555.5","0.26535878","0","1"],["104540.6","0.50311341","0","1"],["104540.5","1.39159662","0","1"],["104540.3","0","0","0"],["104519.3","0.1205","0","1"],["104509.6","1.7009901","0","3"],["104509.1","2.51893232","0","1"],["104500.3","0","0","0"],["104468.3","0.02869558","0","1"],["104394","0","0","0"],["104385.9","0","0","0"],["104385.7","0","0","0"]],"ts":"1747168602509","checksum":-35562682,"seqId":54225030227,"prevSeqId":54225030058}]}
{"arg":{"channel":"books","instId":"BTC-USDT"},"action":"update","data":[{"asks":[["104580.3","0.4464412","0","18"],["104606","0","0","0"],["104607.5","0.13862158","0","2"],["104738.9","0.160579","0","1"]],"bids":[["104576.1","0.04525688","0","1"],["104570.7","0.03440653","0","1"],["104563.6","0.00477972","0","1"],["104562","0.24283008","0","1"],["104525.8","0","0","0"],["104386.3","0","0","0"],["104386.2","0","0","0"]],"ts":"1747168602609","checksum":1379458401,"seqId":54225030238,"prevSeqId":54225030227}]}
{"arg":{"channel":"books","instId":"BTC-USDT"},"action":"update","data":[{"asks":[],"bids":[["104563.6","0","0","0"],["104562.1","0.00477972","0","1"],["104559.6","0.13861069","0","1"],["104557.8","0","0","0"]],"ts":"1747168602709","checksum":1379458401,"seqId":54225030244,"prevSeqId":54225030238}]}
{"arg":{"channel":"books","instId":"BTC-USDT"},"action":"update","data":[{"asks":[["104580.3","0.44162546","0","18"],["104581.7","0","0","0"],["104581.8","0.12248527","0","1"],["104581.9","0.036","0","1"],["104582.4","0.036","0","1"],["104584","0.01","0","1"],["104584.3","0","0","0"],["104587.6","0.21699379","0","1"],["104587.7","0.00001","0","1"],["104589","0.00521575","0","1"],["104589.1","0.05209701","0","2"],["104589.3","0","0","0"],["104589.5","0.09716593","0","1"],["104589.7","0.09973462","0","1"],["104589.8","0","0","0"],["104590.3","0.09742068","0","1"],["104590.5","0","0","0"],["104591.1","0.09227506","0","1"],["104591.6","0.00001","0","1"],["104593.3","0","0","0"],["104593.5","0.17234784","0","1"],["104593.8","0.15220138","0","1"],["104594","0.0816","0","1"],["104594.5","0.15620588","0","1"],["104594.6","0","0","0"],["104594.8","0.02373874","0","1"],["104595.2","0.16533721","0","1"],["104595.7","0","0","0"],["104596.8","0.28609701","0","3"],["104597","0","0","0"],["104597.3","0.16604918","0","1"],["104597.6","0.25499038","0","2"],["104599","0","0","0"],["104599.5","0.25289541","0","1"],["104600.1","0","0","0"],["104600.7","0.2559242","0","1"],["104603","0","0","0"],["104607.5","0.00001","0","1"],["104608.3","0.13860909","0","1"],["104738.9","0","0","0"]],"bids":[["104580.2","0.45882515","0","11"],["104576.1","0.11759977","0","2"],["104573","0.00137191","0","1"],["104572.9","0.26","0","1"],["104571.2","0.008","0","1"],["104571.1","0.52085752","0","2"],["104570","0.0986096","0","3"],["104569.8","0.10003657","0","2"],["104569.5","0.05595085","0","2"],["104569.3","0.005","0","1"],["104568.7","0.09096273","0","1"],["104568.6","0.09123624","0","1"],["104568.1","0.38863185","0","1"],["104568","0","0","0"],["104567.7","0.14935161","0","1"],["104567.1","0.00098","0","1"],["104566.9","0.77866876","0","1"],["104566.3","0.15007316","0","1"],["104565.8","0","0","0"],["104565","0.16248978","0","1"],["104564.6","0.00477972","0","1"],["104564.5","0","0","0"],["104562.6","0.23547303","0","1"],["104562.3","0.15016247","0","1"],["104562.1","0","0","0"],["104562","0","0","0"],["104561.8","0.123","0","4"],["104560.2","0.13860909","0","1"],["104559.6","0","0","0"],["104559.5","0","0","0"],["104557.7","0.29093566","0","2"],["104557.1","0","0","0"],["104555.5","0","0","0"],["104386.9","0","0","0"],["104386.8","0","0","0"],["104386.7","0","0","0"]],"ts":"1747168602809","checksum":1080751034,"seqId":54225030344,"prevSeqId":54225030244}]}
{"arg":{"channel":"books","instId":"BTC-USDT"},"action":"update","data":[{"asks":[["104580.3","0.44161545","0","18"],["104587.6","0.30584846","0","2"],["104593.5","0.42415084","0","2"],["104597.2","0.00477972","0","1"],["104597.6","0.25021066","0","1"],["104603.2","0.20554532","0","2"],["104603.6","0.25280486","0","2"],["104608.3","0","0","0"],["104609.6","0.1386082","0","1"],["104611.6","0.00286776","0","1"],["104611.8","0","0","0"],["104621","0","0","0"],["104622","0","0","0"],["104623","0.002","0","2"],["104624","0.18151565","0","3"],["104641","0.13677189","0","1"],["104643","0","0","0"],["104644","0","0","0"],["104645","0.33","0","6"],["104646","0.16499999","0","3"]],"bids":[["104580.2","0.33932515","0","10"],["104571.1","0.51443592","0","2"],["104565.1","0.00477972","0","1"],["104564.6","0","0","0"],["104561.2","0.1386082","0","1"],["104560.2","0","0","0"],["104560","0.25993097","0","4"],["104557.2","0.002868","0","1"],["104556.1","0.25601901","0","2"],["104516.8","0","0","0"]],"ts":"1747168602909","checksum":-119518820,"seqId":54225030401,"prevSeqId":54225030344}]}
{"arg":{"channel":"books","instId":"BTC-USDT"},"action":"update","data":[{"asks":[["104586","0.11600653","0","2"],["104596.7","0.00477972","0","1"],["104597.2","0","0","0"],["104621","0.002","0","2"],["104622","0.001","0","1"],["104623","0","0","0"],["104624","0.18051565","0","2"],["104643","0.33","0","6"],["104644","0.16499999","0","3"],["104645","0","0","0"],["104646","0","0","0"],["104737.5","0","0","0"]],"bids":[["104565.1","0","0","0"],["104564.5","0.00477972","0","1"]],"ts":"1747168603009","checksum":216927817,"seqId":54225030434,"prevSeqId":54225030401}]}
{"arg":{"channel":"books","instId":"BTC-USDT"},"action":"update","data":[{"asks":[["104580.3","0.43289745","0","17"],["104586","0.0816","0","1"],["104589.1","0.24452673","0","3"],["104592.8","0.00700751","0","1"],["104593.9","0","0","0"],["104595.9","0.00477972","0","1"],["104596.7","0","0","0"],["104604.3","0.05971282","0","1"],["104605.1","0.0002293","0","1"],["104606.4","0","0","0"],["104609.6","0.13860806","0","1"],["104616.8","0","0","0"],["104620","0.00420843","0","5"],["104621","0.001","0","1"],["104622","0","0","0"],["104642","0.26","0","4"],["104643","0.19999999","0","4"],["104644","0.035","0","1"],["104644.4","0.0116586","0","3"],["104645.7","0","0","0"],["104691.8","0","0","0"],["104737.5","0.01051303","0","1"],["104738.9","0.160579","0","1"],["104739.1","0.00001501","0","1"]],"bids":[["104580.2","0.35028215","0","11"],["104571.1","0.2887302","0","1"],["104566.9","0","0","0"],["104564.5","0","0","0"],["104563.6","0.00477972","0","1"],["104561.2","0.13860806","0","1"],["104547.4","0","0","0"],["104546.1","0.00056666","0","1"],["104508.2","0","0","0"],["104506.9","0.00056666","0","1"],["104479.2","0.00009786","0","1"],["104478","0","0","0"],["104426.9","0.00095595","0","1"],["104425.4","0","0","0"],["104386.9","0.00093383","0","2"]],"ts":"1747168603109","checksum":-560470740,"seqId":54225030489,"prevSeqId":54225030434}]}
{"arg":{"channel":"books","instId":"BTC-USDT"},"action":"update","data":[{"asks":[["104589.1","0.05209701","0","2"],["104620","0.00220843","0","3"],["104621","0.002","0","2"],["104622","0.001","0","1"],["104642","0","0","0"],["104643","0.32999999","0","6"],["104644","0.16499999","0","3"]],"bids":[["104557.2","0","0","0"],["104541.4","0.002968","0","2"],["104386.8","0.00005522","0","1"]],"ts":"1747168603209","checksum":168936891,"seqId":54225030528,"prevSeqId":54225030489}]}
{"arg":{"channel":"books","instId":"BTC-USDT"},"action":"update","data":[{"asks":[["104580.3","0","0","0"],["104581.8","0","0","0"],["104581.9","0","0","0"],["104582","0","0","0"],["104582.4","0","0","0"],["104584.1","0","0","0"],["104586","0","0","0"],["104587.3","0.01753662","0","1"],["104587.4","0.05845539","0","2"],["104587.6","0.02471513","0","1"],["104588","0","0","0"],["104588.1","0","0","0"],["104589.1","0","0","0"],["104589.5","0","0","0"],["104589.7","0","0","0"],["104590","0.00001","0","1"],["104590.3","0","0","0"],["104591.1","0","0","0"],["104591.8","0.00044","0","1"],["104592","0","0","0"],["104592.8","0","0","0"],["104593.3","0.00045735","0","1"],["104593.4","0.03407104","0","1"],["104593.5","0.1788813","0","2"],["104593.7","0.01609701","0","1"],["104593.8","0","0","0"],["104594","0","0","0"],["104594.5","0.00700751","0","1"],["104595.2","0","0","0"],["104595.4","0.01911993","0","1"],["104595.9","0","0","0"],["104596","0","0","0"],["104596.8","0.05209701","0","2"],["104597.1","0.00092","0","1"],["104597.2","0.07298372","0","1"],["104597.3","0","0","0"],["104597.6","0","0","0"],["104598.6","0","0","0"],["104599.5","0","0","0"],["104599.6","0.42737181","0","2"],["104599.8","0.19242972","0","1"],["104600.7","0","0","0"],["104601.3","0.234","0","1"],["104602.1","0.11180983","0","3"],["104602.3","0.00092","0","1"],["104602.7","0.00477972","0","1"],["104603.2","0.15018694","0","2"],["104603.6","0.00001","0","1"],["104603.8","0","0","0"],["104604.3","0","0","0"],["104606.3","0.31287796","0","2"],["104607.5","0.00192","0","2"],["104609.1","0","0","0"],["104609.6","0","0","0"],["104609.7","0.27207564","0","1"],["104610.1","0.04","0","1"],["104610.3","0.25374916","0","1"],["104611.9","0.13860575","0","1"],["104612","0","0","0"],["104612.8","0.00478","0","2"],["104613.5","0","0","0"],["104621","0","0","0"],["104622","0","0","0"],["104624","0.18251565","0","4"],["104625","0.09661","0","2"],["104625.4","0.00955566","0","1"],["104639.6","0","0","0"],["104640.2","0","0","0"],["104643","0","0","0"],["104644","0","0","0"],["104645.8","0","0","0"],["104646","0.32999999","0","6"],["104647","0.16499999","0","3"],["104650.6","0.38619438","0","2"],["104651.5","0.02866698","0","1"],["104652.8","0","0","0"],["104654.3","0","0","0"],["104654.9","0","0","0"],["104656.1","0","0","0"],["104656.2","0","0","0"],["104656.4","0.67223652","0","2"],["104657.7","0.1911","0","1"],["104658.6","0","0","0"],["104659.3","0.77866876","0","1"],["104660.1","0","0","0"],["104660.9","1.14229461","0","2"],["104662","0","0","0"],["104664","0","0","0"],["104665.7","0","0","0"],["104665.8","0","0","0"],["104666.6","0.000173","0","1"],["104673.5","1.82801439","0","1"],["104673.6","6.01777182","0","1"],["104673.8","0","0","0"],["104677.7","0.0477783","0","1"],["104678.9","0.01089496","0","1"],["104682","0","0","0"],["104686.9","0","0","0"],["104701.4","0","0","0"],["104704.3","0.03824013","0","1"],["104708.6","0.00001","0","1"],["104734.8","0.0579444","0","2"],["104737.4","0.05793435","0","1"],["104739.2","0.01089655","0","1"],["104739.3","0.01059679","0","1"],["104739.6","0.00023506","0","1"],["104739.7","0.00001107","0","1"],["104739.9","0.0013452","0","1"],["104740","0.00219843","0","2"],["104740.3","0.00005155","0","1"],["104740.5","0.00006468","0","1"],["104740.6","0.0217917","0","2"],["104740.7","0.03","0","1"],["104741.4","0.02119358","0","2"],["104741.9","0.00008643","0","1"],["104742.2","0.0217917","0","2"],["104742.8","0.00002611","0","2"],["104743.1","0.00011716","0","4"],["104743.2","0.01059679","0","1"],["104743.3","0.01059679","0","1"],["104744.3","0.00005567","0","1"],["104744.7","0.00029761","0","1"],["104744.8","0.0000112","0","1"],["104745.5","0.02119358","0","2"],["104745.6","0.0347717","0","3"],["104746","2.12871219","0","2"],["104747","0.77866876","0","1"],["104747.2","0.00001055","0","1"],["104748","0.00108568","0","1"],["104748.6","0.01447816","0","1"],["104749","0.01059679","0","1"],["104749.1","0.01059679","0","1"],["104749.6","0.00003796","0","2"],["104749.9","0.00021362","0","1"],["104750","0.0294814","0","38"],["104750.3","0.0026904","0","1"],["104750.4","0.01050945","0","1"],["104750.5","0.0835954","0","3"]],"bids":[["104583.9","0.91275426","0","10"],["104582.1","0.02470849","0","1"],["104582","0.0816","0","1"],["104581.9","0.43800975","0","1"],["104580.3","0.00137191","0","1"],["104580.2","0.62502514","0","12"],["104579.8","0.03440653","0","1"],["104576.1","0.25337678","0","2"],["104575.8","0.00001","0","1"],["104573","0","0","0"],["104572.8","0","0","0"],["104572.4","0","0","0"],["104571.8","0.15814294","0","2"],["104571.1","0.4691567","0","3"],["104570.8","0.00098","0","1"],["104570.7","0","0","0"],["104570","0.00029006","0","2"],["104569.8","0","0","0"],["104568.7","0","0","0"],["104568.6","0","0","0"],["104568.2","0.77866876","0","1"],["104567.7","0","0","0"],["104567.1","0","0","0"],["104566.8","0.46602586","0","2"],["104566.3","0","0","0"],["104565.6","0.00098","0","1"],["104565","0","0","0"],["104563.6","0","0","0"],["104563.2","0.13860575","0","1"],["104562.8","0.26229983","0","1"],["104562.6","0","0","0"],["104562.3","0","0","0"],["104561.9","0.17764565","0","1"],["104561.2","0","0","0"],["104560.4","0.00191","0","1"],["104560","0.00220843","0","3"],["104557.7","0.02199655","0","1"],["104557.4","0.00382565","0","1"],["104556.7","0.17764565","0","1"],["104556.1","0.00710858","0","1"],["104555.1","0.00191","0","1"],["104551.4","0","0","0"],["104526.3","0.04779965","0","1"],["104517.8","0.0177493","0","1"],["104513.6","0.01059634","0","1"],["104386.9","0","0","0"],["104386.8","0","0","0"]],"ts":"1747168603309","checksum":744140429,"seqId":54225030952,"prevSeqId":54225030528}]}
{"arg":{"channel":"books","instId":"BTC-USDT"},"action":"update","data":[{"asks":[["104584","0.48808307","0","2"],["104587.3","0","0","0"],["104587.4","0.00019123","0","1"],["104587.6","0","0","0"],["104592.4","0.0230049","0","1"],["104593.1","0.00045735","0","1"],["104593.2","0.09278872","0","1"],["104593.3","0.16316633","0","1"],["104593.4","0.10130447","0","1"],["104593.5","0","0","0"],["104593.7","0","0","0"],["104594","0.09164449","0","1"],["104594.8","0.09756549","0","1"],["104595.8","0","0","0"],["104596.8","0.036","0","1"],["104597.2","0","0","0"],["104597.5","0.14836901","0","1"],["104597.7","0","0","0"],["104598.2","0.15386168","0","1"],["104598.4","0","0","0"],["104598.8","0.05826416","0","1"],["104598.9","0.15476407","0","1"],["104599.6","0.41424927","0","3"],["104600.3","0","0","0"],["104600.8","0.02518874","0","1"],["104601","0.21774257","0","3"],["104601.3","0.49361242","0","2"],["104602","0.01055377","0","2"],["104602.7","0","0","0"],["104602.8","0","0","0"],["104603.2","0.70173456","0","3"],["104604.4","0.24097121","0","1"],["104605.4","0.77866876","0","1"],["104606","0.00477972","0","1"],["104606.1","0.0814895","0","2"],["104606.3","0","0","0"],["104606.5","0.11408","0","1"],["104607.2","0.03823914","0","1"],["104607.3","0.24334477","0","1"],["104608.4","0.0638915","0","2"],["104609.5","0.30379852","0","1"],["104609.7","0","0","0"],["104610.2","0.11408","0","1"],["104610.3","0","0","0"],["104611.9","0","0","0"],["104615.4","0.13860025","0","1"],["104618.8","0","0","0"],["104622.2","0.00013706","0","1"],["104625.1","0.23868858","0","2"],["104630.6","0.0560742","0","2"],["104632.7","0","0","0"],["104635.1","0","0","0"],["104638.8","0.78171","0","2"],["104660.9","0.42725893","0","1"],["104664.1","0.5419431","0","3"],["104673.5","0","0","0"],["104673.6","0","0","0"],["104687.1","6.01778182","0","2"],["104689.4","0.00009431","0","1"],["104703.4","0.42854523","0","2"]],"bids":[["104583.9","1.05024278","0","14"],["104581.9","0.3854071","0","2"],["104580.3","0.38863185","0","1"],["104580.2","0.57752737","0","10"],["104578.8","0.0436728","0","1"],["104576.3","0.00137191","0","1"],["104576.2","0.19307078","0","1"],["104576.1","0.00051","0","1"],["104575.6","0.002868","0","1"],["104575.2","0.06124373","0","1"],["104575","0.07298372","0","1"],["104573.7","0.09093681","0","1"],["104573.5","0.09264306","0","1"],["104573","0.00477972","0","1"],["104572.4","0.09066545","0","1"],["104572.3","0.0905317","0","1"],["104571.8","0.00251112","0","1"],["104571.4","0.15396222","0","1"],["104571.1","0.46437698","0","2"],["104570","0.15166197","0","3"],["104568.7","0.14899507","0","1"],["104568.3","0.19242972","0","1"],["104566.9","0.13860025","0","1"],["104566.8","0.31906106","0","2"],["104566.3","0.23924521","0","1"],["104566","0.21556849","0","3"],["104565.7","0","0","0"],["104564.4","0.01031435","0","1"],["104563.7","0.27030927","0","1"],["104563.2","0","0","0"],["104562.8","0","0","0"],["104561.4","0.24502567","0","1"],["104559.8","0.24034674","0","1"],["104541.4","0.0001","0","1"],["104540.6","0","0","0"],["104540.5","0","0","0"],["104509.6","1.07865797","0","2"],["104509.1","0","0","0"],["104478","0.00063721","0","1"],["104474.3","0","0","0"],["104462.1","0.00083755","0","1"],["104458.4","0","0","0"],["104395.5","0","0","0"],["104394.6","0","0","0"],["104392.7","0","0","0"],["104391.9","0","0","0"],["104391.6","0","0","0"],["104391.4","0","0","0"],["104391.2","0","0","0"],["104390","0","0","0"],["104389.2","0","0","0"],["104388.8","0","0","0"],["104388.3","0","0","0"],["104388.2","0","0","0"],["104387","0","0","0"]],"ts":"1747168603409","checksum":1750901671,"seqId":54225031291,"prevSeqId":54225030952}]}
{"arg":{"channel":"books","instId":"BTC-USDT"},"action":"update","data":[{"asks":[["104584","0.47817307","0","2"],["104584.1","0.41072782","0","1"],["104586.9","0.01","0","1"],["104598","0.02518941","0","1"],["104602.3","0.02465705","0","2"],["104610.2","0","0","0"],["104615.4","0","0","0"],["104616.8","0.13859872","0","1"],["104617.2","0","0","0"],["104623.2","0.04267709","0","1"],["104637.8","1.39247133","0","1"],["104666.8","1.32768419","0","2"],["104669.2","2.46421286","0","1"],["104687.1","0.00001","0","1"],["104689.4","0","0","0"],["104692.9","1.18290028","0","4"],["104693.9","6.01777182","0","1"],["104750","0","0","0"],["104750.3","0","0","0"],["104750.4","0","0","0"],["104750.5","0","0","0"]],"bids":[["104583.9","0.94253078","0","14"],["104575.6","0","0","0"],["104568.8","0.13859872","0","1"],["104566.9","0","0","0"],["104553","0.00015483","0","1"],["104540.2","1.43646013","0","1"],["104523.8","0.01452354","0","1"],["104513.7","0","0","0"],["104508.8","2.64850588","0","1"],["104483.4","0.00010163","0","1"],["104479.2","0","0","0"],["104430.8","0.00095594","0","1"],["104426.9","0","0","0"],["104398.1","0","0","0"],["104395.8","0","0","0"]],"ts":"1747168603509","checksum":-197447523,"seqId":54225031338,"prevSeqId":54225031291}]}
{"arg":{"channel":"books","instId":"BTC-USDT"},"action":"update","data":[{"asks":[["104592.4","0.0250049","0","2"],["104596.7","0.03440653","0","1"],["104598","0","0","0"],["104600.8","0","0","0"],["104603.3","0.02373682","0","1"],["104604.9","0.002","0","1"],["104606","0","0","0"],["104608.3","0.00477965","0","1"],["104610.4","0.0459826","0","1"],["104616.8","0","0","0"],["104618.8","0.13859739","0","1"],["104621.9","0","0","0"],["104624","0.18051565","0","2"],["104625","0.09761","0","3"],["104626","0.001","0","1"],["104646","0","0","0"],["104647","0.32999999","0","6"],["104648","0.16719999","0","4"],["104657.7","0","0","0"],["104678.8","0.01051786","0","1"],["104680","0.01449426","0","7"],["104682.8","0.01051786","0","1"],["104684.8","0.01051786","0","1"],["104686.9","0.01051786","0","1"],["104689.4","0.01051786","0","1"],["104748.6","0","0","0"],["104749","0","0","0"],["104749.1","0","0","0"],["104749.6","0","0","0"],["104749.9","0","0","0"]],"bids":[["104583.9","0.99688858","0","16"],["104581.6","0.002","0","1"],["104580.2","0.5658561","0","9"],["104579.8","0","0","0"],["104578.3","0.03003373","0","4"],["104576.3","0.00615156","0","2"],["104573","0","0","0"],["104569.6","0.13872339","0","2"],["104569.1","0.002","0","1"],["104568.8","0","0","0"],["104538","0.000015","0","1"],["104496.1","0.01089584","0","1"],["104398.1","0.07298372","0","1"]],"ts":"1747168603609","checksum":957030773,"seqId":54225031394,"prevSeqId":54225031338}]}
{"arg":{"channel":"books","instId":"BTC-USDT"},"action":"update","data":[{"asks":[["104592.1","0","0","0"],["104592.4","0.002","0","1"],["104597.9","0.02518944","0","1"],["104599.9","0.02518895","0","1"],["104602.3","0.00092","0","1"],["104603.1","0.00477965","0","1"],["104608.3","0","0","0"],["104608.4","0.01790803","0","1"],["104625","0.002","0","2"],["104654.4","0","0","0"],["104677","6.03387753","0","1"],["104693.9","0","0","0"]],"bids":[["104580.3","0","0","0"],["104580.2","0.5548991","0","8"],["104578.3","0.02697501","0","1"],["104576.3","0.00137191","0","1"],["104571.5","0.00477965","0","1"]],"ts":"1747168603709","checksum":-1893110950,"seqId":54225031420,"prevSeqId":54225031394}]}
{"arg":{"channel":"books","instId":"BTC-USDT"},"action":"update","data":[{"asks":[["104592.5","0.005","0","1"],["104595.4","0","0","0"],["104596.7","0","0","0"],["104600.2","0.24933565","0","2"],["104600.7","0.05352558","0","2"],["104603.1","0","0","0"],["104606.4","0.00477965","0","1"],["104607.6","0","0","0"],["104610.8","0.04478084","0","2"],["104618.8","0","0","0"],["104619.6","0.13859406","0","1"],["104650.6","0.1050588","0","1"],["104652.1","0","0","0"],["104652.9","0","0","0"],["104657.5","0.14332","0","1"],["104658.8","0.11466","0","1"],["104664.8","0.09554","0","1"],["104744.7","0.00120281","0","2"],["104748.6","0.01447816","0","1"]],"bids":[["104583.9","1.25688858","0","17"],["104581.9","0.16258536","0","1"],["104580.2","0.2943391","0","4"],["104576.3","0","0","0"],["104573.9","0.00477965","0","1"],["104573.8","0.00137191","0","1"],["104572.9","0","0","0"],["104571.5","0.13859406","0","1"],["104569.6","0.00723458","0","2"],["104568.3","0","0","0"],["104568.2","0.97109848","0","2"],["104556.1","0","0","0"],["104522.9","0.0206193","0","2"],["104517.8","0","0","0"],["104484.6","0.0684522","0","2"],["104444.9","0","0","0"],["104395.8","0.00001704","0","1"],["104395.5","0.00968","0","1"],["104394.6","0.00005067","0","1"],["104392.7","0.00095792","0","1"]],"ts":"1747168603809","checksum":-1812899104,"seqId":54225031515,"prevSeqId":54225031420}]}
{"arg":{"channel":"books","instId":"BTC-USDT"},"action":"update","data":[{"asks":[["104584","0.47818307","0","3"],["104618.8","0.13859709","0","1"],["104619.6","0","0","0"],["104628.2","0.09562","0","1"],["104630.6","0.07761125","0","3"],["104630.9","0","0","0"],["104631.3","0.09562","0","1"],["104633","0","0","0"],["104634","0","0","0"],["104639.2","0.60523","0","1"],["104665.5","0.19108","0","1"]],"bids":[["104583.9","0.99449815","0","15"],["104581.9","0.25827217","0","2"],["104580.3","0.38863185","0","1"],["104576.3","0.00137191","0","1"],["104573.8","0","0","0"],["104571.5","0","0","0"],["104569.6","0.14583167","0","3"],["104522.9","0.00287","0","1"]],"ts":"1747168603909","checksum":-1653913003,"seqId":54225031547,"prevSeqId":54225031515}]}
{"arg":{"channel":"books","instId":"BTC-USDT"},"action":"update","data":[{"asks":[["104593.1","0","0","0"],["104593.3","0","0","0"],["104595.9","0.02518992","0","1"],["104596.7","0.00045735","0","1"],["104599.9","0","0","0"],["104604.8","0.00477964","0","1"],["104606.4","0","0","0"],["104614.7","0.13860053","0","1"],["104618.8","0","0","0"],["104630.8","0.0000125","0","1"],["104632.9","0.0000125","0","1"],["104634","0.0000125","0","1"],["104639.2","0.6052425","0","2"],["104748","0","0","0"],["104748.6","0","0","0"]],"bids":[["104573.9","0","0","0"],["104572.5","0.00477964","0","1"],["104569.6","0.00723458","0","2"],["104566.9","0.13859972","0","1"],["104541.5","0.00078549","0","2"],["104392.7","0","0","0"]],"ts":"1747168604009","checksum":67582268,"seqId":54225031598,"prevSeqId":54225031547}]}
{"arg":{"channel":"books","instId":"BTC-USDT"},"action":"update","data":[{"asks":[["104588","0.0816","0","1"],["104593.1","0.00045735","0","1"],["104593.3","0.1600973","0","1"],["104596.4","0.03440653","0","1"],["104596.7","0","0","0"],["104599.5","0.38863185","0","1"],["104600.7","0.01911905","0","1"],["104601","0.27378268","0","4"],["104603.2","0.7065142","0","4"],["104604.8","0","0","0"],["104605.1","0","0","0"],["104610.4","0","0","0"],["104613.7","0.13860199","0","1"],["104614.7","0","0","0"],["104615","0.0002293","0","1"],["104644.4","0.01109194","0","2"],["104654.3","0.00056666","0","1"],["104670.2","6.03392052","0","2"],["104677","0","0","0"],["104692.2","0.00009292","0","1"],["104692.9","1.18280886","0","3"],["104746","0","0","0"],["104747","0","0","0"],["104747.2","0","0","0"]],"bids":[["104579.1","0.05568174","0","1"],["104578.3","0","0","0"],["104572.5","0","0","0"],["104571.8","0","0","0"],["104571.5","0.00477964","0","1"],["104570.9","0.00301114","0","2"],["104566.9","0","0","0"],["104566.1","0.13860199","0","1"],["104556","0.00057666","0","2"],["104546.1","0","0","0"],["104516.8","0.00056666","0","1"],["104506.9","0","0","0"],["104484.5","0.01070273","0","3"],["104483.4","0","0","0"],["104431.7","0.00095591","0","1"],["104430.8","0","0","0"],["104392.7","0.00095792","0","1"],["104391.9","0.001841","0","1"],["104391.6","0.000015","0","1"]],"ts":"1747168604109","checksum":-1354882393,"seqId":54225031657,"prevSeqId":54225031598}]}
{"arg":{"channel":"books","instId":"BTC-USDT"},"action":"update","data":[{"asks":[["104584","0.47806915","0","3"],["104586.9","0","0","0"],["104587.9","0.02828273","0","1"],["104602.2","0.00477964","0","1"],["104603.2","0.70173456","0","3"],["104612.5","0.52723516","0","2"],["104613.7","0","0","0"],["104624","0.18251565","0","4"],["104625","0.001","0","1"],["104626","0","0","0"],["104647","0","0","0"],["104648","0.0022","0","1"],["104649","0.33","0","6"],["104650","0.16532023","0","5"],["104746","2.12871219","0","2"]],"bids":[["104583.9","0.97141262","0","15"],["104581.9","0.16258536","0","1"],["104580.3","0","0","0"],["104571.5","0","0","0"],["104571.1","0.2887302","0","1"],["104570.1","0.00477964","0","1"],["104568.2","0","0","0"],["104566.1","0","0","0"],["104563.8","0.13860247","0","1"],["104391.4","0.5999","0","1"],["104391.2","0.0008","0","1"]],"ts":"1747168604209","checksum":1129257746,"seqId":54225031762,"prevSeqId":54225031657}]}
{"event":"subscribe","arg":{"channel":"books","instId":"BTC-USDT"},"connId":"a171c985"}
